ts_event,ts_recv,r_type,publisher,instrument_id,action,side,depth,price,size,flags,ts_in_delta,sequence,symbol,order_id,bid_px_00,bid_sz_00,bid_ct_00,ask_px_00,ask_sz_00,ask_ct_00,bid_px_01,bid_sz_01,bid_ct_01,ask_px_01,ask_sz_01,ask_ct_01,bid_px_02,bid_sz_02,bid_ct_02,ask_px_02,ask_sz_02,ask_ct_02,bid_px_03,bid_sz_03,bid_ct_03,ask_px_03,ask_sz_03,ask_ct_03,bid_px_04,bid_sz_04,bid_ct_04,ask_px_04,ask_sz_04,ask_ct_04,bid_px_05,bid_sz_05,bid_ct_05,ask_px_05,ask_sz_05,ask_ct_05,bid_px_06,bid_sz_06,bid_ct_06,ask_px_06,ask_sz_06,ask_ct_06,bid_px_07,bid_sz_07,bid_ct_07,ask_px_07,ask_sz_07,ask_ct_07,bid_px_08,bid_sz_08,bid_ct_08,ask_px_08,ask_sz_08,ask_ct_08,bid_px_09,bid_sz_09,bid_ct_09,ask_px_09,ask_sz_09,ask_ct_09
2025-07-17T13:49:46.535572067Z,2025-07-17T13:49:46.535737854Z,160,2,1108,A,A,0,18.23,100,130,165787,76393138,ARL,92510841,13.26,2,1,14.2,2,1,13.25,11,1,14.59,100,1,12.99,100,1,14.83,100,1,12.73,100,1,14.87,100,1,12.67,100,1,14.95,700,1,12.47,100,1,14.99,700,1,12.46,100,1,15.07,700,1,12.43,700,1,15.09,100,1,12.42,700,1,15.14,700,1,12.37,700,1,15.16,100,1
2025-07-17T13:56:11.001642441Z,2025-07-17T13:56:11.001810226Z,160,2,1108,A,B,0,13.28,1,128,167785,89819278,ARL,107702381,13.28,1,1,14.2,2,1,13.26,2,1,14.59,100,1,13.25,11,1,14.83,100,1,12.99,100,1,14.87,100,1,12.73,100,1,14.95,700,1,12.67,100,1,14.99,700,1,12.47,100,1,15.07,700,1,12.46,100,1,15.09,100,1,12.43,700,1,15.14,700,1,12.42,700,1,15.16,100,1
2025-07-17T13:56:11.005384065Z,2025-07-17T13:56:11.005550129Z,160,2,1108,A,B,0,13.28,10,130,166064,89819705,ARL,107702861,13.28,11,2,14.2,2,1,13.26,2,1,14.59,100,1,13.25,11,1,14.83,100,1,12.99,100,1,14.87,100,1,12.73,100,1,14.95,700,1,12.67,100,1,14.99,700,1,12.47,100,1,15.07,700,1,12.46,100,1,15.09,100,1,12.43,700,1,15.14,700,1,12.42,700,1,15.16,100,1
2025-07-17T13:56:11.005385425Z,2025-07-17T13:56:11.005550669Z,160,2,1108,A,A,0,13.94,10,130,165244,89819706,ARL,107702865,13.28,11,2,13.94,10,1,13.26,2,1,14.2,2,1,13.25,11,1,14.59,100,1,12.99,100,1,14.83,100,1,12.73,100,1,14.87,100,1,12.67,100,1,14.95,700,1,12.47,100,1,14.99,700,1,12.46,100,1,15.07,700,1,12.43,700,1,15.09,100,1,12.42,700,1,15.14,700,1
2025-07-17T13:56:11.013654317Z,2025-07-17T13:56:11.013819857Z,160,2,1108,C,A,0,15.26,100,0,165540,89820163,ARL,92510729,13.28,11,2,13.94,10,1,13.26,2,1,14.2,2,1,13.25,11,1,14.59,100,1,12.99,100,1,14.83,100,1,12.73,100,1,14.87,100,1,12.67,100,1,14.95,700,1,12.47,100,1,14.99,700,1,12.46,100,1,15.07,700,1,12.43,700,1,15.09,100,1,12.42,700,1,15.14,700,1
2025-07-17T13:56:11.013654317Z,2025-07-17T13:56:11.013819857Z,160,2,1108,A,A,0,14.84,100,130,165540,89820163,ARL,107703205,13.28,11,2,13.94,10,1,13.26,2,1,14.2,2,1,13.25,11,1,14.59,100,1,12.99,100,1,14.83,100,1,12.73,100,1,14.84,100,1,12.67,100,1,14.87,100,1,12.47,100,1,14.95,700,1,12.46,100,1,14.99,700,1,12.43,700,1,15.07,700,1,12.42,700,1,15.09,100,1
2025-07-17T13:56:11.026515306Z,2025-07-17T13:56:11.026680779Z,160,2,1108,C,A,0,15.26,100,0,165473,89820408,ARL,92510725,13.28,11,2,13.94,10,1,13.26,2,1,14.2,2,1,13.25,11,1,14.59,100,1,12.99,100,1,14.83,100,1,12.73,100,1,14.84,100,1,12.67,100,1,14.87,100,1,12.47,100,1,14.95,700,1,12.46,100,1,14.99,700,1,12.43,700,1,15.07,700,1,12.42,700,1,15.09,100,1
2025-07-17T13:56:11.026515306Z,2025-07-17T13:56:11.026680779Z,160,2,1108,A,A,0,14.84,100,130,165473,89820408,ARL,107703433,13.28,11,2,13.94,10,1,13.26,2,1,14.2,2,1,13.25,11,1,14.59,100,1,12.99,100,1,14.83,100,1,12.73,100,1,14.84,200,2,12.67,100,1,14.87,100,1,12.47,100,1,14.95,700,1,12.46,100,1,14.99,700,1,12.43,700,1,15.07,700,1,12.42,700,1,15.09,100,1
2025-07-17T13:56:11.101751649Z,2025-07-17T13:56:11.101916770Z,160,2,1108,C,B,0,13.28,1,130,165121,89823845,ARL,107702381,13.28,10,1,13.94,10,1,13.26,2,1,14.2,2,1,13.25,11,1,14.59,100,1,12.99,100,1,14.83,100,1,12.73,100,1,14.84,200,2,12.67,100,1,14.87,100,1,12.47,100,1,14.95,700,1,12.46,100,1,14.99,700,1,12.43,700,1,15.07,700,1,12.42,700,1,15.09,100,1
2025-07-17T13:56:19.511590204Z,2025-07-17T13:56:19.511755342Z,160,2,1108,C,B,0,13.28,10,130,165138,90148349,ARL,107702861,13.26,2,1,13.94,10,1,13.25,11,1,14.2,2,1,12.99,100,1,14.59,100,1,12.73,100,1,14.83,100,1,12.67,100,1,14.84,200,2,12.47,100,1,14.87,100,1,12.46,100,1,14.95,700,1,12.43,700,1,14.99,700,1,12.42,700,1,15.07,700,1,12.37,700,1,15.09,100,1
2025-07-17T13:56:22.511968820Z,2025-07-17T13:56:22.512134723Z,160,2,1108,C,A,0,13.94,10,130,165903,90281309,ARL,107702865,13.26,2,1,14.2,2,1,13.25,11,1,14.59,100,1,12.99,100,1,14.83,100,1,12.73,100,1,14.84,200,2,12.67,100,1,14.87,100,1,12.47,100,1,14.95,700,1,12.46,100,1,14.99,700,1,12.43,700,1,15.07,700,1,12.42,700,1,15.09,100,1,12.37,700,1,15.14,700,1
2025-07-17T13:56:22.516990420Z,2025-07-17T13:56:22.517155918Z,160,2,1108,C,A,0,14.84,100,0,165498,90281853,ARL,107703205,13.26,2,1,14.2,2,1,13.25,11,1,14.59,100,1,12.99,100,1,14.83,100,1,12.73,100,1,14.84,100,1,12.67,100,1,14.87,100,1,12.47,100,1,14.95,700,1,12.46,100,1,14.99,700,1,12.43,700,1,15.07,700,1,12.42,700,1,15.09,100,1,12.37,700,1,15.14,700,1
2025-07-17T13:56:22.516990420Z,2025-07-17T13:56:22.517155918Z,160,2,1108,A,A,0,15.26,100,130,165498,90281853,ARL,108217045,13.26,2,1,14.2,2,1,13.25,11,1,14.59,100,1,12.99,100,1,14.83,100,1,12.73,100,1,14.84,100,1,12.67,100,1,14.87,100,1,12.47,100,1,14.95,700,1,12.46,100,1,14.99,700,1,12.43,700,1,15.07,700,1,12.42,700,1,15.09,100,1,12.37,700,1,15.14,700,1
2025-07-17T13:56:22.517362170Z,2025-07-17T13:56:22.517527654Z,160,2,1108,C,A,0,14.84,100,0,165484,90281893,ARL,107703433,13.26,2,1,14.2,2,1,13.25,11,1,14.59,100,1,12.99,100,1,14.83,100,1,12.73,100,1,14.87,100,1,12.67,100,1,14.95,700,1,12.47,100,1,14.99,700,1,12.46,100,1,15.07,700,1,12.43,700,1,15.09,100,1,12.42,700,1,15.14,700,1,12.37,700,1,15.16,100,1
2025-07-17T13:56:22.517362170Z,2025-07-17T13:56:22.517527654Z,160,2,1108,A,A,0,15.26,100,130,165484,90281893,ARL,108217173,13.26,2,1,14.2,2,1,13.25,11,1,14.59,100,1,12.99,100,1,14.83,100,1,12.73,100,1,14.87,100,1,12.67,100,1,14.95,700,1,12.47,100,1,14.99,700,1,12.46,100,1,15.07,700,1,12.43,700,1,15.09,100,1,12.42,700,1,15.14,700,1,12.37,700,1,15.16,100,1
2025-07-17T13:56:40.757635216Z,2025-07-17T13:56:40.757800894Z,160,2,1108,C,A,0,14.2,2,0,165678,90866180,ARL,84628773,13.26,2,1,14.59,100,1,13.25,11,1,14.83,100,1,12.99,100,1,14.87,100,1,12.73,100,1,14.95,700,1,12.67,100,1,14.99,700,1,12.47,100,1,15.07,700,1,12.46,100,1,15.09,100,1,12.43,700,1,15.14,700,1,12.42,700,1,15.16,100,1,12.37,700,1,15.26,200,2
2025-07-17T13:56:40.757635216Z,2025-07-17T13:56:40.757800894Z,160,2,1108,A,A,0,14.36,2,130,165678,90866180,ARL,108872153,13.26,2,1,14.36,2,1,13.25,11,1,14.59,100,1,12.99,100,1,14.83,100,1,12.73,100,1,14.87,100,1,12.67,100,1,14.95,700,1,12.47,100,1,14.99,700,1,12.46,100,1,15.07,700,1,12.43,700,1,15.09,100,1,12.42,700,1,15.14,700,1,12.37,700,1,15.16,100,1
2025-07-17T13:57:40.141855674Z,2025-07-17T13:57:40.142022323Z,160,2,1108,C,B,0,13.26,2,0,166649,92821039,ARL,87750309,13.25,11,1,14.36,2,1,12.99,100,1,14.59,100,1,12.73,100,1,14.83,100,1,12.67,100,1,14.87,100,1,12.47,100,1,14.95,700,1,12.46,100,1,14.99,700,1,12.43,700,1,15.07,700,1,12.42,700,1,15.09,100,1,12.37,700,1,15.14,700,1,12.36,200,2,15.16,100,1
2025-07-17T13:57:40.141855674Z,2025-07-17T13:57:40.142022323Z,160,2,1108,A,B,0,13.12,2,128,166649,92821039,ARL,111169049,13.25,11,1,14.36,2,1,13.12,2,1,14.59,100,1,12.99,100,1,14.83,100,1,12.73,100,1,14.87,100,1,12.67,100,1,14.95,700,1,12.47,100,1,14.99,700,1,12.46,100,1,15.07,700,1,12.43,700,1,15.09,100,1,12.42,700,1,15.14,700,1,12.37,700,1,15.16,100,1
2025-07-17T13:57:44.947591620Z,2025-07-17T13:57:44.947757237Z,160,2,1108,C,A,0,14.36,2,0,165617,92961696,ARL,108872153,13.25,11,1,14.59,100,1,13.12,2,1,14.83,100,1,12.99,100,1,14.87,100,1,12.73,100,1,14.95,700,1,12.67,100,1,14.99,700,1,12.47,100,1,15.07,700,1,12.46,100,1,15.09,100,1,12.43,700,1,15.14,700,1,12.42,700,1,15.16,100,1,12.37,700,1,15.26,200,2
2025-07-17T13:57:44.947591620Z,2025-07-17T13:57:44.947757237Z,160,2,1108,A,A,0,14.5,2,130,165617,92961696,ARL,111347121,13.25,11,1,14.5,2,1,13.12,2,1,14.59,100,1,12.99,100,1,14.83,100,1,12.73,100,1,14.87,100,1,12.67,100,1,14.95,700,1,12.47,100,1,14.99,700,1,12.46,100,1,15.07,700,1,12.43,700,1,15.09,100,1,12.42,700,1,15.14,700,1,12.37,700,1,15.16,100,1
2025-07-17T13:59:50.477745739Z,2025-07-17T13:59:50.477911158Z,160,2,1108,C,B,0,13.25,11,130,165419,96389796,ARL,44586753,13.12,2,1,14.5,2,1,12.99,100,1,14.59,100,1,12.73,100,1,14.83,100,1,12.67,100,1,14.87,100,1,12.47,100,1,14.95,700,1,12.46,100,1,14.99,700,1,12.43,700,1,15.07,700,1,12.42,700,1,15.09,100,1,12.37,700,1,15.14,700,1,12.36,200,2,15.16,100,1
2025-07-17T13:59:50.479411482Z,2025-07-17T13:59:50.479576984Z,160,2,1108,C,B,0,12.36,100,0,165502,96389821,ARL,43787977,13.12,2,1,14.5,2,1,12.99,100,1,14.59,100,1,12.73,100,1,14.83,100,1,12.67,100,1,14.87,100,1,12.47,100,1,14.95,700,1,12.46,100,1,14.99,700,1,12.43,700,1,15.07,700,1,12.42,700,1,15.09,100,1,12.37,700,1,15.14,700,1,12.36,100,1,15.16,100,1
2025-07-17T13:59:50.479411482Z,2025-07-17T13:59:50.479576984Z,160,2,1108,A,B,0,12.51,100,130,165502,96389821,ARL,115474337,13.12,2,1,14.5,2,1,12.99,100,1,14.59,100,1,12.73,100,1,14.83,100,1,12.67,100,1,14.87,100,1,12.51,100,1,14.95,700,1,12.47,100,1,14.99,700,1,12.46,100,1,15.07,700,1,12.43,700,1,15.09,100,1,12.42,700,1,15.14,700,1,12.37,700,1,15.16,100,1
2025-07-17T13:59:50.480698233Z,2025-07-17T13:59:50.480863637Z,160,2,1108,C,B,0,12.36,100,0,165404,96389845,ARL,43781537,13.12,2,1,14.5,2,1,12.99,100,1,14.59,100,1,12.73,100,1,14.83,100,1,12.67,100,1,14.87,100,1,12.51,100,1,14.95,700,1,12.47,100,1,14.99,700,1,12.46,100,1,15.07,700,1,12.43,700,1,15.09,100,1,12.42,700,1,15.14,700,1,12.37,700,1,15.16,100,1
2025-07-17T13:59:50.480698233Z,2025-07-17T13:59:50.480863637Z,160,2,1108,A,B,0,12.51,100,130,165404,96389845,ARL,115474357,13.12,2,1,14.5,2,1,12.99,100,1,14.59,100,1,12.73,100,1,14.83,100,1,12.67,100,1,14.87,100,1,12.51,200,2,14.95,700,1,12.47,100,1,14.99,700,1,12.46,100,1,15.07,700,1,12.43,700,1,15.09,100,1,12.42,700,1,15.14,700,1,12.37,700,1,15.16,100,1
2025-07-17T14:00:00.062872132Z,2025-07-17T14:00:00.063037446Z,160,2,1108,A,B,0,13.11,100,130,165314,96673952,ARL,115813253,13.12,2,1,14.5,2,1,13.11,100,1,14.59,100,1,12.99,100,1,14.83,100,1,12.73,100,1,14.87,100,1,12.67,100,1,14.95,700,1,12.51,200,2,14.99,700,1,12.47,100,1,15.07,700,1,12.46,100,1,15.09,100,1,12.43,700,1,15.14,700,1,12.42,700,1,15.16,100,1
2025-07-17T14:00:00.062890891Z,2025-07-17T14:00:00.063056200Z,160,2,1108,A,A,0,14.51,100,130,165309,96673954,ARL,115813261,13.12,2,1,14.5,2,1,13.11,100,1,14.51,100,1,12.99,100,1,14.59,100,1,12.73,100,1,14.83,100,1,12.67,100,1,14.87,100,1,12.51,200,2,14.95,700,1,12.47,100,1,14.99,700,1,12.46,100,1,15.07,700,1,12.43,700,1,15.09,100,1,12.42,700,1,15.14,700,1
2025-07-17T14:02:01.157819863Z,2025-07-17T14:02:01.157985602Z,160,2,1108,C,B,0,13.12,2,0,165739,101310413,ARL,111169049,13.11,100,1,14.5,2,1,12.99,100,1,14.51,100,1,12.73,100,1,14.59,100,1,12.67,100,1,14.83,100,1,12.51,200,2,14.87,100,1,12.47,100,1,14.95,700,1,12.46,100,1,14.99,700,1,12.43,700,1,15.07,700,1,12.42,700,1,15.09,100,1,12.37,700,1,15.14,700,1
2025-07-17T14:02:01.157819863Z,2025-07-17T14:02:01.157985602Z,160,2,1108,A,B,0,13.26,2,130,165739,101310413,ARL,121098337,13.26,2,1,14.5,2,1,13.11,100,1,14.51,100,1,12.99,100,1,14.59,100,1,12.73,100,1,14.83,100,1,12.67,100,1,14.87,100,1,12.51,200,2,14.95,700,1,12.47,100,1,14.99,700,1,12.46,100,1,15.07,700,1,12.43,700,1,15.09,100,1,12.42,700,1,15.14,700,1
2025-07-17T14:02:01.157820985Z,2025-07-17T14:02:01.157986499Z,160,2,1108,C,A,0,14.5,2,0,165514,101310414,ARL,111347121,13.26,2,1,14.51,100,1,13.11,100,1,14.59,100,1,12.99,100,1,14.83,100,1,12.73,100,1,14.87,100,1,12.67,100,1,14.95,700,1,12.51,200,2,14.99,700,1,12.47,100,1,15.07,700,1,12.46,100,1,15.09,100,1,12.43,700,1,15.14,700,1,12.42,700,1,15.16,100,1
2025-07-17T14:02:01.157820985Z,2025-07-17T14:02:01.157986499Z,160,2,1108,A,A,0,14.36,2,130,165514,101310414,ARL,121098341,13.26,2,1,14.36,2,1,13.11,100,1,14.51,100,1,12.99,100,1,14.59,100,1,12.73,100,1,14.83,100,1,12.67,100,1,14.87,100,1,12.51,200,2,14.95,700,1,12.47,100,1,14.99,700,1,12.46,100,1,15.07,700,1,12.43,700,1,15.09,100,1,12.42,700,1,15.14,700,1
2025-07-17T14:02:01.283363185Z,2025-07-17T14:02:01.283528838Z,160,2,1108,C,B,0,13.11,100,0,165653,101317376,ARL,115813253,13.26,2,1,14.36,2,1,12.99,100,1,14.51,100,1,12.73,100,1,14.59,100,1,12.67,100,1,14.83,100,1,12.51,200,2,14.87,100,1,12.47,100,1,14.95,700,1,12.46,100,1,14.99,700,1,12.43,700,1,15.07,700,1,12.42,700,1,15.09,100,1,12.37,700,1,15.14,700,1
2025-07-17T14:02:01.283363185Z,2025-07-17T14:02:01.283528838Z,160,2,1108,A,B,0,13.25,100,130,165653,101317376,ARL,121107957,13.26,2,1,14.36,2,1,13.25,100,1,14.51,100,1,12.99,100,1,14.59,100,1,12.73,100,1,14.83,100,1,12.67,100,1,14.87,100,1,12.51,200,2,14.95,700,1,12.47,100,1,14.99,700,1,12.46,100,1,15.07,700,1,12.43,700,1,15.09,100,1,12.42,700,1,15.14,700,1
2025-07-17T14:02:01.283378637Z,2025-07-17T14:02:01.283544588Z,160,2,1108,C,A,0,14.51,100,0,165951,101317377,ARL,115813261,13.26,2,1,14.36,2,1,13.25,100,1,14.59,100,1,12.99,100,1,14.83,100,1,12.73,100,1,14.87,100,1,12.67,100,1,14.95,700,1,12.51,200,2,14.99,700,1,12.47,100,1,15.07,700,1,12.46,100,1,15.09,100,1,12.43,700,1,15.14,700,1,12.42,700,1,15.16,100,1
2025-07-17T14:02:01.283378637Z,2025-07-17T14:02:01.283544588Z,160,2,1108,A,A,0,14.37,100,130,165951,101317377,ARL,121107961,13.26,2,1,14.36,2,1,13.25,100,1,14.37,100,1,12.99,100,1,14.59,100,1,12.73,100,1,14.83,100,1,12.67,100,1,14.87,100,1,12.51,200,2,14.95,700,1,12.47,100,1,14.99,700,1,12.46,100,1,15.07,700,1,12.43,700,1,15.09,100,1,12.42,700,1,15.14,700,1
2025-07-17T14:04:21.248740930Z,2025-07-17T14:04:21.248906318Z,160,2,1108,A,A,0,14.35,1,130,165388,106336852,ARL,126872197,13.26,2,1,14.35,1,1,13.25,100,1,14.36,2,1,12.99,100,1,14.37,100,1,12.73,100,1,14.59,100,1,12.67,100,1,14.83,100,1,12.51,200,2,14.87,100,1,12.47,100,1,14.95,700,1,12.46,100,1,14.99,700,1,12.43,700,1,15.07,700,1,12.42,700,1,15.09,100,1
2025-07-17T14:04:21.250160548Z,2025-07-17T14:04:21.250325900Z,160,2,1108,C,B,0,12.51,100,0,165352,106336976,ARL,115474357,13.26,2,1,14.35,1,1,13.25,100,1,14.36,2,1,12.99,100,1,14.37,100,1,12.73,100,1,14.59,100,1,12.67,100,1,14.83,100,1,12.51,100,1,14.87,100,1,12.47,100,1,14.95,700,1,12.46,100,1,14.99,700,1,12.43,700,1,15.07,700,1,12.42,700,1,15.09,100,1
2025-07-17T14:04:21.250160548Z,2025-07-17T14:04:21.250325900Z,160,2,1108,A,B,0,12.36,100,130,165352,106336976,ARL,126872345,13.26,2,1,14.35,1,1,13.25,100,1,14.36,2,1,12.99,100,1,14.37,100,1,12.73,100,1,14.59,100,1,12.67,100,1,14.83,100,1,12.51,100,1,14.87,100,1,12.47,100,1,14.95,700,1,12.46,100,1,14.99,700,1,12.43,700,1,15.07,700,1,12.42,700,1,15.09,100,1
2025-07-17T14:04:21.250632048Z,2025-07-17T14:04:21.250797741Z,160,2,1108,C,B,0,12.51,100,0,165693,106337002,ARL,115474337,13.26,2,1,14.35,1,1,13.25,100,1,14.36,2,1,12.99,100,1,14.37,100,1,12.73,100,1,14.59,100,1,12.67,100,1,14.83,100,1,12.47,100,1,14.87,100,1,12.46,100,1,14.95,700,1,12.43,700,1,14.99,700,1,12.42,700,1,15.07,700,1,12.37,700,1,15.09,100,1
2025-07-17T14:04:21.250632048Z,2025-07-17T14:04:21.250797741Z,160,2,1108,A,B,0,12.36,100,130,165693,106337002,ARL,126872361,13.26,2,1,14.35,1,1,13.25,100,1,14.36,2,1,12.99,100,1,14.37,100,1,12.73,100,1,14.59,100,1,12.67,100,1,14.83,100,1,12.47,100,1,14.87,100,1,12.46,100,1,14.95,700,1,12.43,700,1,14.99,700,1,12.42,700,1,15.07,700,1,12.37,700,1,15.09,100,1
2025-07-17T14:04:21.350041949Z,2025-07-17T14:04:21.350207939Z,160,2,1108,C,A,0,14.35,1,128,165990,106339204,ARL,126872197,13.26,2,1,14.36,2,1,13.25,100,1,14.37,100,1,12.99,100,1,14.59,100,1,12.73,100,1,14.83,100,1,12.67,100,1,14.87,100,1,12.47,100,1,14.95,700,1,12.46,100,1,14.99,700,1,12.43,700,1,15.07,700,1,12.42,700,1,15.09,100,1,12.37,700,1,15.14,700,1
2025-07-17T14:04:54.699761263Z,2025-07-17T14:04:54.699926747Z,160,2,1108,C,A,0,15.46,100,0,165484,107313441,ARL,92510753,13.26,2,1,14.36,2,1,13.25,100,1,14.37,100,1,12.99,100,1,14.59,100,1,12.73,100,1,14.83,100,1,12.67,100,1,14.87,100,1,12.47,100,1,14.95,700,1,12.46,100,1,14.99,700,1,12.43,700,1,15.07,700,1,12.42,700,1,15.09,100,1,12.37,700,1,15.14,700,1
2025-07-17T14:04:54.699761263Z,2025-07-17T14:04:54.699926747Z,160,2,1108,A,A,0,15.34,100,130,165484,107313441,ARL,127999501,13.26,2,1,14.36,2,1,13.25,100,1,14.37,100,1,12.99,100,1,14.59,100,1,12.73,100,1,14.83,100,1,12.67,100,1,14.87,100,1,12.47,100,1,14.95,700,1,12.46,100,1,14.99,700,1,12.43,700,1,15.07,700,1,12.42,700,1,15.09,100,1,12.37,700,1,15.14,700,1
2025-07-17T14:05:10.258689253Z,2025-07-17T14:05:10.258855609Z,160,2,1108,A,A,0,14.08,1,130,166356,107833096,ARL,128570149,13.26,2,1,14.08,1,1,13.25,100,1,14.36,2,1,12.99,100,1,14.37,100,1,12.73,100,1,14.59,100,1,12.67,100,1,14.83,100,1,12.47,100,1,14.87,100,1,12.46,100,1,14.95,700,1,12.43,700,1,14.99,700,1,12.42,700,1,15.07,700,1,12.37,700,1,15.09,100,1
2025-07-17T14:05:10.259348471Z,2025-07-17T14:05:10.259513876Z,160,2,1108,C,A,0,15.26,100,0,165405,107833168,ARL,108217173,13.26,2,1,14.08,1,1,13.25,100,1,14.36,2,1,12.99,100,1,14.37,100,1,12.73,100,1,14.59,100,1,12.67,100,1,14.83,100,1,12.47,100,1,14.87,100,1,12.46,100,1,14.95,700,1,12.43,700,1,14.99,700,1,12.42,700,1,15.07,700,1,12.37,700,1,15.09,100,1
2025-07-17T14:05:10.259348471Z,2025-07-17T14:05:10.259513876Z,160,2,1108,A,A,0,14.98,100,130,165405,107833168,ARL,128570229,13.26,2,1,14.08,1,1,13.25,100,1,14.36,2,1,12.99,100,1,14.37,100,1,12.73,100,1,14.59,100,1,12.67,100,1,14.83,100,1,12.47,100,1,14.87,100,1,12.46,100,1,14.95,700,1,12.43,700,1,14.98,100,1,12.42,700,1,14.99,700,1,12.37,700,1,15.07,700,1
2025-07-17T14:05:10.259729446Z,2025-07-17T14:05:10.259895236Z,160,2,1108,C,A,0,15.26,100,0,165790,107833188,ARL,108217045,13.26,2,1,14.08,1,1,13.25,100,1,14.36,2,1,12.99,100,1,14.37,100,1,12.73,100,1,14.59,100,1,12.67,100,1,14.83,100,1,12.47,100,1,14.87,100,1,12.46,100,1,14.95,700,1,12.43,700,1,14.98,100,1,12.42,700,1,14.99,700,1,12.37,700,1,15.07,700,1
2025-07-17T14:05:10.259729446Z,2025-07-17T14:05:10.259895236Z,160,2,1108,A,A,0,14.98,100,130,165790,107833188,ARL,128570237,13.26,2,1,14.08,1,1,13.25,100,1,14.36,2,1,12.99,100,1,14.37,100,1,12.73,100,1,14.59,100,1,12.67,100,1,14.83,100,1,12.47,100,1,14.87,100,1,12.46,100,1,14.95,700,1,12.43,700,1,14.98,200,2,12.42,700,1,14.99,700,1,12.37,700,1,15.07,700,1
2025-07-17T14:05:10.262295631Z,2025-07-17T14:05:10.262461863Z,160,2,1108,C,A,0,14.37,100,0,166232,107833310,ARL,121107961,13.26,2,1,14.08,1,1,13.25,100,1,14.36,2,1,12.99,100,1,14.59,100,1,12.73,100,1,14.83,100,1,12.67,100,1,14.87,100,1,12.47,100,1,14.95,700,1,12.46,100,1,14.98,200,2,12.43,700,1,14.99,700,1,12.42,700,1,15.07,700,1,12.37,700,1,15.09,100,1
2025-07-17T14:05:10.262295631Z,2025-07-17T14:05:10.262461863Z,160,2,1108,A,A,0,14.09,100,130,166232,107833310,ARL,128570317,13.26,2,1,14.08,1,1,13.25,100,1,14.09,100,1,12.99,100,1,14.36,2,1,12.73,100,1,14.59,100,1,12.67,100,1,14.83,100,1,12.47,100,1,14.87,100,1,12.46,100,1,14.95,700,1,12.43,700,1,14.98,200,2,12.42,700,1,14.99,700,1,12.37,700,1,15.07,700,1
2025-07-17T14:05:10.262701351Z,2025-07-17T14:05:10.262866527Z,160,2,1108,C,A,0,14.08,1,130,165176,107833359,ARL,128570149,13.26,2,1,14.09,100,1,13.25,100,1,14.36,2,1,12.99,100,1,14.59,100,1,12.73,100,1,14.83,100,1,12.67,100,1,14.87,100,1,12.47,100,1,14.95,700,1,12.46,100,1,14.98,200,2,12.43,700,1,14.99,700,1,12.42,700,1,15.07,700,1,12.37,700,1,15.09,100,1
2025-07-17T14:05:10.263022539Z,2025-07-17T14:05:10.263188035Z,160,2,1108,C,A,0,15.34,100,0,165496,107833371,ARL,127999501,13.26,2,1,14.09,100,1,13.25,100,1,14.36,2,1,12.99,100,1,14.59,100,1,12.73,100,1,14.83,100,1,12.67,100,1,14.87,100,1,12.47,100,1,14.95,700,1,12.46,100,1,14.98,200,2,12.43,700,1,14.99,700,1,12.42,700,1,15.07,700,1,12.37,700,1,15.09,100,1
2025-07-17T14:05:10.263022539Z,2025-07-17T14:05:10.263188035Z,160,2,1108,A,A,0,15.18,100,130,165496,107833371,ARL,128570417,13.26,2,1,14.09,100,1,13.25,100,1,14.36,2,1,12.99,100,1,14.59,100,1,12.73,100,1,14.83,100,1,12.67,100,1,14.87,100,1,12.47,100,1,14.95,700,1,12.46,100,1,14.98,200,2,12.43,700,1,14.99,700,1,12.42,700,1,15.07,700,1,12.37,700,1,15.09,100,1
2025-07-17T14:05:10.264329670Z,2025-07-17T14:05:10.264495078Z,160,2,1108,C,A,0,15.36,100,0,165408,107833404,ARL,92510761,13.26,2,1,14.09,100,1,13.25,100,1,14.36,2,1,12.99,100,1,14.59,100,1,12.73,100,1,14.83,100,1,12.67,100,1,14.87,100,1,12.47,100,1,14.95,700,1,12.46,100,1,14.98,200,2,12.43,700,1,14.99,700,1,12.42,700,1,15.07,700,1,12.37,700,1,15.09,100,1
2025-07-17T14:05:10.264329670Z,2025-07-17T14:05:10.264495078Z,160,2,1108,A,A,0,15.08,100,130,165408,107833404,ARL,128570449,13.26,2,1,14.09,100,1,13.25,100,1,14.36,2,1,12.99,100,1,14.59,100,1,12.73,100,1,14.83,100,1,12.67,100,1,14.87,100,1,12.47,100,1,14.95,700,1,12.46,100,1,14.98,200,2,12.43,700,1,14.99,700,1,12.42,700,1,15.07,700,1,12.37,700,1,15.08,100,1
2025-07-17T14:05:10.264425026Z,2025-07-17T14:05:10.264590318Z,160,2,1108,C,A,0,15.09,100,130,165292,107833406,ARL,84650629,13.26,2,1,14.09,100,1,13.25,100,1,14.36,2,1,12.99,100,1,14.59,100,1,12.73,100,1,14.83,100,1,12.67,100,1,14.87,100,1,12.47,100,1,14.95,700,1,12.46,100,1,14.98,200,2,12.43,700,1,14.99,700,1,12.42,700,1,15.07,700,1,12.37,700,1,15.08,100,1
2025-07-17T14:05:10.264550510Z,2025-07-17T14:05:10.264715723Z,160,2,1108,A,A,0,14.89,100,130,165213,107833407,ARL,128570453,13.26,2,1,14.09,100,1,13.25,100,1,14.36,2,1,12.99,100,1,14.59,100,1,12.73,100,1,14.83,100,1,12.67,100,1,14.87,100,1,12.47,100,1,14.89,100,1,12.46,100,1,14.95,700,1,12.43,700,1,14.98,200,2,12.42,700,1,14.99,700,1,12.37,700,1,15.07,700,1
2025-07-17T14:05:10.269777131Z,2025-07-17T14:05:10.269943051Z,160,2,1108,C,A,0,14.59,100,128,165920,107833716,ARL,84629329,13.26,2,1,14.09,100,1,13.25,100,1,14.36,2,1,12.99,100,1,14.83,100,1,12.73,100,1,14.87,100,1,12.67,100,1,14.89,100,1,12.47,100,1,14.95,700,1,12.46,100,1,14.98,200,2,12.43,700,1,14.99,700,1,12.42,700,1,15.07,700,1,12.37,700,1,15.08,100,1
2025-07-17T14:05:10.269832842Z,2025-07-17T14:05:10.269997960Z,160,2,1108,A,A,0,14.37,100,130,165118,107833720,ARL,128570621,13.26,2,1,14.09,100,1,13.25,100,1,14.36,2,1,12.99,100,1,14.37,100,1,12.73,100,1,14.83,100,1,12.67,100,1,14.87,100,1,12.47,100,1,14.89,100,1,12.46,100,1,14.95,700,1,12.43,700,1,14.98,200,2,12.42,700,1,14.99,700,1,12.37,700,1,15.07,700,1
2025-07-17T14:05:10.271699633Z,2025-07-17T14:05:10.271865423Z,160,2,1108,C,A,0,18.23,100,0,165790,107833881,ARL,92510841,13.26,2,1,14.09,100,1,13.25,100,1,14.36,2,1,12.99,100,1,14.37,100,1,12.73,100,1,14.83,100,1,12.67,100,1,14.87,100,1,12.47,100,1,14.89,100,1,12.46,100,1,14.95,700,1,12.43,700,1,14.98,200,2,12.42,700,1,14.99,700,1,12.37,700,1,15.07,700,1
2025-07-17T14:05:10.271699633Z,2025-07-17T14:05:10.271865423Z,160,2,1108,A,A,0,17.9,100,130,165790,107833881,ARL,128570685,13.26,2,1,14.09,100,1,13.25,100,1,14.36,2,1,12.99,100,1,14.37,100,1,12.73,100,1,14.83,100,1,12.67,100,1,14.87,100,1,12.47,100,1,14.89,100,1,12.46,100,1,14.95,700,1,12.43,700,1,14.98,200,2,12.42,700,1,14.99,700,1,12.37,700,1,15.07,700,1
2025-07-17T14:05:10.276155439Z,2025-07-17T14:05:10.276320920Z,160,2,1108,C,A,0,16.51,100,0,165481,107834635,ARL,92510813,13.26,2,1,14.09,100,1,13.25,100,1,14.36,2,1,12.99,100,1,14.37,100,1,12.73,100,1,14.83,100,1,12.67,100,1,14.87,100,1,12.47,100,1,14.89,100,1,12.46,100,1,14.95,700,1,12.43,700,1,14.98,200,2,12.42,700,1,14.99,700,1,12.37,700,1,15.07,700,1
2025-07-17T14:05:10.276155439Z,2025-07-17T14:05:10.276320920Z,160,2,1108,A,A,0,16.21,100,130,165481,107834635,ARL,128570977,13.26,2,1,14.09,100,1,13.25,100,1,14.36,2,1,12.99,100,1,14.37,100,1,12.73,100,1,14.83,100,1,12.67,100,1,14.87,100,1,12.47,100,1,14.89,100,1,12.46,100,1,14.95,700,1,12.43,700,1,14.98,200,2,12.42,700,1,14.99,700,1,12.37,700,1,15.07,700,1
2025-07-17T14:05:10.342817229Z,2025-07-17T14:05:10.342982797Z,160,2,1108,C,A,0,15.31,100,0,165568,107837761,ARL,84630849,13.26,2,1,14.09,100,1,13.25,100,1,14.36,2,1,12.99,100,1,14.37,100,1,12.73,100,1,14.83,100,1,12.67,100,1,14.87,100,1,12.47,100,1,14.89,100,1,12.46,100,1,14.95,700,1,12.43,700,1,14.98,200,2,12.42,700,1,14.99,700,1,12.37,700,1,15.07,700,1
2025-07-17T14:05:10.342817229Z,2025-07-17T14:05:10.342982797Z,160,2,1108,A,A,0,15.08,100,130,165568,107837761,ARL,128573957,13.26,2,1,14.09,100,1,13.25,100,1,14.36,2,1,12.99,100,1,14.37,100,1,12.73,100,1,14.83,100,1,12.67,100,1,14.87,100,1,12.47,100,1,14.89,100,1,12.46,100,1,14.95,700,1,12.43,700,1,14.98,200,2,12.42,700,1,14.99,700,1,12.37,700,1,15.07,700,1
2025-07-17T14:05:31.418575692Z,2025-07-17T14:05:31.418741362Z,160,2,1108,C,A,0,14.36,2,0,165670,108664911,ARL,121098341,13.26,2,1,14.09,100,1,13.25,100,1,14.37,100,1,12.99,100,1,14.83,100,1,12.73,100,1,14.87,100,1,12.67,100,1,14.89,100,1,12.47,100,1,14.95,700,1,12.46,100,1,14.98,200,2,12.43,700,1,14.99,700,1,12.42,700,1,15.07,700,1,12.37,700,1,15.08,200,2
2025-07-17T14:05:31.418575692Z,2025-07-17T14:05:31.418741362Z,160,2,1108,A,A,0,14.26,2,130,165670,108664911,ARL,129518753,13.26,2,1,14.09,100,1,13.25,100,1,14.26,2,1,12.99,100,1,14.37,100,1,12.73,100,1,14.83,100,1,12.67,100,1,14.87,100,1,12.47,100,1,14.89,100,1,12.46,100,1,14.95,700,1,12.43,700,1,14.98,200,2,12.42,700,1,14.99,700,1,12.37,700,1,15.07,700,1
2025-07-17T14:06:01.385840471Z,2025-07-17T14:06:01.386006059Z,160,2,1108,C,B,0,13.26,2,0,165588,109685525,ARL,121098337,13.25,100,1,14.09,100,1,12.99,100,1,14.26,2,1,12.73,100,1,14.37,100,1,12.67,100,1,14.83,100,1,12.47,100,1,14.87,100,1,12.46,100,1,14.89,100,1,12.43,700,1,14.95,700,1,12.42,700,1,14.98,200,2,12.37,700,1,14.99,700,1,12.36,200,2,15.07,700,1
2025-07-17T14:06:01.385840471Z,2025-07-17T14:06:01.386006059Z,160,2,1108,A,B,0,13.15,2,130,165588,109685525,ARL,130693973,13.25,100,1,14.09,100,1,13.15,2,1,14.26,2,1,12.99,100,1,14.37,100,1,12.73,100,1,14.83,100,1,12.67,100,1,14.87,100,1,12.47,100,1,14.89,100,1,12.46,100,1,14.95,700,1,12.43,700,1,14.98,200,2,12.42,700,1,14.99,700,1,12.37,700,1,15.07,700,1
2025-07-17T14:13:11.346212166Z,2025-07-17T14:13:11.346377890Z,160,2,1108,C,A,0,15.18,100,0,165724,123937587,ARL,128570417,13.25,100,1,14.09,100,1,13.15,2,1,14.26,2,1,12.99,100,1,14.37,100,1,12.73,100,1,14.83,100,1,12.67,100,1,14.87,100,1,12.47,100,1,14.89,100,1,12.46,100,1,14.95,700,1,12.43,700,1,14.98,200,2,12.42,700,1,14.99,700,1,12.37,700,1,15.07,700,1
2025-07-17T14:13:11.346212166Z,2025-07-17T14:13:11.346377890Z,160,2,1108,A,A,0,15.09,100,130,165724,123937587,ARL,146955361,13.25,100,1,14.09,100,1,13.15,2,1,14.26,2,1,12.99,100,1,14.37,100,1,12.73,100,1,14.83,100,1,12.67,100,1,14.87,100,1,12.47,100,1,14.89,100,1,12.46,100,1,14.95,700,1,12.43,700,1,14.98,200,2,12.42,700,1,14.99,700,1,12.37,700,1,15.07,700,1
2025-07-17T14:13:11.358751092Z,2025-07-17T14:13:11.358916626Z,160,2,1108,C,A,0,14.37,100,130,165534,123938202,ARL,128570621,13.25,100,1,14.09,100,1,13.15,2,1,14.26,2,1,12.99,100,1,14.83,100,1,12.73,100,1,14.87,100,1,12.67,100,1,14.89,100,1,12.47,100,1,14.95,700,1,12.46,100,1,14.98,200,2,12.43,700,1,14.99,700,1,12.42,700,1,15.07,700,1,12.37,700,1,15.08,200,2
2025-07-17T14:13:11.358802966Z,2025-07-17T14:13:11.358968656Z,160,2,1108,A,A,0,14.28,100,130,165690,123938203,ARL,146956357,13.25,100,1,14.09,100,1,13.15,2,1,14.26,2,1,12.99,100,1,14.28,100,1,12.73,100,1,14.83,100,1,12.67,100,1,14.87,100,1,12.47,100,1,14.89,100,1,12.46,100,1,14.95,700,1,12.43,700,1,14.98,200,2,12.42,700,1,14.99,700,1,12.37,700,1,15.07,700,1
2025-07-17T14:13:11.392923396Z,2025-07-17T14:13:11.393088913Z,160,2,1108,C,A,0,15.73,100,0,165517,123939815,ARL,84629953,13.25,100,1,14.09,100,1,13.15,2,1,14.26,2,1,12.99,100,1,14.28,100,1,12.73,100,1,14.83,100,1,12.67,100,1,14.87,100,1,12.47,100,1,14.89,100,1,12.46,100,1,14.95,700,1,12.43,700,1,14.98,200,2,12.42,700,1,14.99,700,1,12.37,700,1,15.07,700,1
2025-07-17T14:13:11.392923396Z,2025-07-17T14:13:11.393088913Z,160,2,1108,A,A,0,15.4,100,130,165517,123939815,ARL,146959177,13.25,100,1,14.09,100,1,13.15,2,1,14.26,2,1,12.99,100,1,14.28,100,1,12.73,100,1,14.83,100,1,12.67,100,1,14.87,100,1,12.47,100,1,14.89,100,1,12.46,100,1,14.95,700,1,12.43,700,1,14.98,200,2,12.42,700,1,14.99,700,1,12.37,700,1,15.07,700,1
2025-07-17T14:13:11.423316840Z,2025-07-17T14:13:11.423482323Z,160,2,1108,A,A,0,14.56,100,130,165483,123940437,ARL,146960005,13.25,100,1,14.09,100,1,13.15,2,1,14.26,2,1,12.99,100,1,14.28,100,1,12.73,100,1,14.56,100,1,12.67,100,1,14.83,100,1,12.47,100,1,14.87,100,1,12.46,100,1,14.89,100,1,12.43,700,1,14.95,700,1,12.42,700,1,14.98,200,2,12.37,700,1,14.99,700,1
2025-07-17T14:13:11.423317922Z,2025-07-17T14:13:11.423483431Z,160,2,1108,C,A,0,14.87,100,130,165509,123940438,ARL,84708037,13.25,100,1,14.09,100,1,13.15,2,1,14.26,2,1,12.99,100,1,14.28,100,1,12.73,100,1,14.56,100,1,12.67,100,1,14.83,100,1,12.47,100,1,14.89,100,1,12.46,100,1,14.95,700,1,12.43,700,1,14.98,200,2,12.42,700,1,14.99,700,1,12.37,700,1,15.07,700,1
2025-07-17T14:13:11.555642984Z,2025-07-17T14:13:11.555808541Z,160,2,1108,A,A,0,14.84,100,130,165557,123942727,ARL,146962993,13.25,100,1,14.09,100,1,13.15,2,1,14.26,2,1,12.99,100,1,14.28,100,1,12.73,100,1,14.56,100,1,12.67,100,1,14.83,100,1,12.47,100,1,14.84,100,1,12.46,100,1,14.89,100,1,12.43,700,1,14.95,700,1,12.42,700,1,14.98,200,2,12.37,700,1,14.99,700,1
2025-07-17T14:13:11.555663413Z,2025-07-17T14:13:11.555828856Z,160,2,1108,C,A,0,15.16,100,130,165443,123942728,ARL,84668677,13.25,100,1,14.09,100,1,13.15,2,1,14.26,2,1,12.99,100,1,14.28,100,1,12.73,100,1,14.56,100,1,12.67,100,1,14.83,100,1,12.47,100,1,14.84,100,1,12.46,100,1,14.89,100,1,12.43,700,1,14.95,700,1,12.42,700,1,14.98,200,2,12.37,700,1,14.99,700,1
2025-07-17T14:13:19.230817808Z,2025-07-17T14:13:19.230983072Z,160,2,1108,A,A,0,14.91,700,130,165264,124169794,ARL,147217629,13.25,100,1,14.09,100,1,13.15,2,1,14.26,2,1,12.99,100,1,14.28,100,1,12.73,100,1,14.56,100,1,12.67,100,1,14.83,100,1,12.47,100,1,14.84,100,1,12.46,100,1,14.89,100,1,12.43,700,1,14.91,700,1,12.42,700,1,14.95,700,1,12.37,700,1,14.98,200,2
2025-07-17T14:13:19.231613044Z,2025-07-17T14:13:19.231778755Z,160,2,1108,C,A,0,15.14,700,130,165711,124169802,ARL,84628829,13.25,100,1,14.09,100,1,13.15,2,1,14.26,2,1,12.99,100,1,14.28,100,1,12.73,100,1,14.56,100,1,12.67,100,1,14.83,100,1,12.47,100,1,14.84,100,1,12.46,100,1,14.89,100,1,12.43,700,1,14.91,700,1,12.42,700,1,14.95,700,1,12.37,700,1,14.98,200,2
2025-07-17T14:22:28.338009329Z,2025-07-17T14:22:28.338174848Z,160,2,1108,A,A,0,14,1,130,165519,142657338,ARL,168073025,13.25,100,1,14,1,1,13.15,2,1,14.09,100,1,12.99,100,1,14.26,2,1,12.73,100,1,14.28,100,1,12.67,100,1,14.56,100,1,12.47,100,1,14.83,100,1,12.46,100,1,14.84,100,1,12.43,700,1,14.89,100,1,12.42,700,1,14.91,700,1,12.37,700,1,14.95,700,1
2025-07-17T14:22:29.993845812Z,2025-07-17T14:22:29.994011311Z,160,2,1108,C,A,0,14.09,100,0,165499,142715813,ARL,128570317,13.25,100,1,14,1,1,13.15,2,1,14.26,2,1,12.99,100,1,14.28,100,1,12.73,100,1,14.56,100,1,12.67,100,1,14.83,100,1,12.47,100,1,14.84,100,1,12.46,100,1,14.89,100,1,12.43,700,1,14.91,700,1,12.42,700,1,14.95,700,1,12.37,700,1,14.98,200,2
2025-07-17T14:22:29.993845812Z,2025-07-17T14:22:29.994011311Z,160,2,1108,A,A,0,14.01,100,130,165499,142715813,ARL,168141389,13.25,100,1,14,1,1,13.15,2,1,14.01,100,1,12.99,100,1,14.26,2,1,12.73,100,1,14.28,100,1,12.67,100,1,14.56,100,1,12.47,100,1,14.83,100,1,12.46,100,1,14.84,100,1,12.43,700,1,14.89,100,1,12.42,700,1,14.91,700,1,12.37,700,1,14.95,700,1
2025-07-17T14:32:58.232963791Z,2025-07-17T14:32:58.233129156Z,160,2,1108,C,B,0,13.25,100,130,165365,162140358,ARL,121107957,13.15,2,1,14,1,1,12.99,100,1,14.01,100,1,12.73,100,1,14.26,2,1,12.67,100,1,14.28,100,1,12.47,100,1,14.56,100,1,12.46,100,1,14.83,100,1,12.43,700,1,14.84,100,1,12.42,700,1,14.89,100,1,12.37,700,1,14.91,700,1,12.36,200,2,14.95,700,1
2025-07-17T14:32:58.713850212Z,2025-07-17T14:32:58.714015555Z,160,2,1108,A,B,0,13.14,100,130,165343,162149922,ARL,190326921,13.15,2,1,14,1,1,13.14,100,1,14.01,100,1,12.99,100,1,14.26,2,1,12.73,100,1,14.28,100,1,12.67,100,1,14.56,100,1,12.47,100,1,14.83,100,1,12.46,100,1,14.84,100,1,12.43,700,1,14.89,100,1,12.42,700,1,14.91,700,1,12.37,700,1,14.95,700,1
2025-07-17T14:34:48.346179643Z,2025-07-17T14:34:48.346344959Z,160,2,1108,C,A,0,14,1,130,165316,164925706,ARL,168073025,13.15,2,1,14.01,100,1,13.14,100,1,14.26,2,1,12.99,100,1,14.28,100,1,12.73,100,1,14.56,100,1,12.67,100,1,14.83,100,1,12.47,100,1,14.84,100,1,12.46,100,1,14.89,100,1,12.43,700,1,14.91,700,1,12.42,700,1,14.95,700,1,12.37,700,1,14.98,200,2
2025-07-17T14:47:30.547915870Z,2025-07-17T14:47:30.548081358Z,160,2,1108,A,B,0,13.38,33,130,165488,183466992,ARL,215999733,13.38,33,1,14.01,100,1,13.15,2,1,14.26,2,1,13.14,100,1,14.28,100,1,12.99,100,1,14.56,100,1,12.73,100,1,14.83,100,1,12.67,100,1,14.84,100,1,12.47,100,1,14.89,100,1,12.46,100,1,14.91,700,1,12.43,700,1,14.95,700,1,12.42,700,1,14.98,200,2
2025-07-17T14:47:30.548180936Z,2025-07-17T14:47:30.548346701Z,160,2,1108,C,B,0,13.14,100,0,165765,183466994,ARL,190326921,13.38,33,1,14.01,100,1,13.15,2,1,14.26,2,1,12.99,100,1,14.28,100,1,12.73,100,1,14.56,100,1,12.67,100,1,14.83,100,1,12.47,100,1,14.84,100,1,12.46,100,1,14.89,100,1,12.43,700,1,14.91,700,1,12.42,700,1,14.95,700,1,12.37,700,1,14.98,200,2
2025-07-17T14:47:30.548180936Z,2025-07-17T14:47:30.548346701Z,160,2,1108,A,B,0,13.37,100,130,165765,183466994,ARL,215999737,13.38,33,1,14.01,100,1,13.37,100,1,14.26,2,1,13.15,2,1,14.28,100,1,12.99,100,1,14.56,100,1,12.73,100,1,14.83,100,1,12.67,100,1,14.84,100,1,12.47,100,1,14.89,100,1,12.46,100,1,14.91,700,1,12.43,700,1,14.95,700,1,12.42,700,1,14.98,200,2
2025-07-17T14:47:30.548666035Z,2025-07-17T14:47:30.548831608Z,160,2,1108,C,B,0,12.36,100,0,165573,183467001,ARL,126872345,13.38,33,1,14.01,100,1,13.37,100,1,14.26,2,1,13.15,2,1,14.28,100,1,12.99,100,1,14.56,100,1,12.73,100,1,14.83,100,1,12.67,100,1,14.84,100,1,12.47,100,1,14.89,100,1,12.46,100,1,14.91,700,1,12.43,700,1,14.95,700,1,12.42,700,1,14.98,200,2
2025-07-17T14:47:30.548666035Z,2025-07-17T14:47:30.548831608Z,160,2,1108,A,B,0,12.48,100,130,165573,183467001,ARL,215999741,13.38,33,1,14.01,100,1,13.37,100,1,14.26,2,1,13.15,2,1,14.28,100,1,12.99,100,1,14.56,100,1,12.73,100,1,14.83,100,1,12.67,100,1,14.84,100,1,12.48,100,1,14.89,100,1,12.47,100,1,14.91,700,1,12.46,100,1,14.95,700,1,12.43,700,1,14.98,200,2
2025-07-17T14:47:30.548925394Z,2025-07-17T14:47:30.549090785Z,160,2,1108,C,B,0,12.23,100,0,165391,183467002,ARL,43317473,13.38,33,1,14.01,100,1,13.37,100,1,14.26,2,1,13.15,2,1,14.28,100,1,12.99,100,1,14.56,100,1,12.73,100,1,14.83,100,1,12.67,100,1,14.84,100,1,12.48,100,1,14.89,100,1,12.47,100,1,14.91,700,1,12.46,100,1,14.95,700,1,12.43,700,1,14.98,200,2
2025-07-17T14:47:30.548925394Z,2025-07-17T14:47:30.549090785Z,160,2,1108,A,B,0,12.33,100,130,165391,183467002,ARL,215999753,13.38,33,1,14.01,100,1,13.37,100,1,14.26,2,1,13.15,2,1,14.28,100,1,12.99,100,1,14.56,100,1,12.73,100,1,14.83,100,1,12.67,100,1,14.84,100,1,12.48,100,1,14.89,100,1,12.47,100,1,14.91,700,1,12.46,100,1,14.95,700,1,12.43,700,1,14.98,200,2
2025-07-17T14:47:30.549175659Z,2025-07-17T14:47:30.549341156Z,160,2,1108,C,B,0,12.36,100,0,165497,183467004,ARL,126872361,13.38,33,1,14.01,100,1,13.37,100,1,14.26,2,1,13.15,2,1,14.28,100,1,12.99,100,1,14.56,100,1,12.73,100,1,14.83,100,1,12.67,100,1,14.84,100,1,12.48,100,1,14.89,100,1,12.47,100,1,14.91,700,1,12.46,100,1,14.95,700,1,12.43,700,1,14.98,200,2
2025-07-17T14:47:30.549175659Z,2025-07-17T14:47:30.549341156Z,160,2,1108,A,B,0,12.48,100,130,165497,183467004,ARL,215999761,13.38,33,1,14.01,100,1,13.37,100,1,14.26,2,1,13.15,2,1,14.28,100,1,12.99,100,1,14.56,100,1,12.73,100,1,14.83,100,1,12.67,100,1,14.84,100,1,12.48,200,2,14.89,100,1,12.47,100,1,14.91,700,1,12.46,100,1,14.95,700,1,12.43,700,1,14.98,200,2
2025-07-17T14:47:30.571220121Z,2025-07-17T14:47:30.571385383Z,160,2,1108,C,B,0,12.99,100,130,165262,183468111,ARL,43805737,13.38,33,1,14.01,100,1,13.37,100,1,14.26,2,1,13.15,2,1,14.28,100,1,12.73,100,1,14.56,100,1,12.67,100,1,14.83,100,1,12.48,200,2,14.84,100,1,12.47,100,1,14.89,100,1,12.46,100,1,14.91,700,1,12.43,700,1,14.95,700,1,12.42,700,1,14.98,200,2
2025-07-17T14:47:30.571271737Z,2025-07-17T14:47:30.571436944Z,160,2,1108,A,B,0,13.1,100,130,165207,183468112,ARL,216001413,13.38,33,1,14.01,100,1,13.37,100,1,14.26,2,1,13.15,2,1,14.28,100,1,13.1,100,1,14.56,100,1,12.73,100,1,14.83,100,1,12.67,100,1,14.84,100,1,12.48,200,2,14.89,100,1,12.47,100,1,14.91,700,1,12.46,100,1,14.95,700,1,12.43,700,1,14.98,200,2
2025-07-17T14:47:37.384441232Z,2025-07-17T14:47:37.384610677Z,160,2,1108,A,B,0,12.5,700,130,169445,183649796,ARL,216223005,13.38,33,1,14.01,100,1,13.37,100,1,14.26,2,1,13.15,2,1,14.28,100,1,13.1,100,1,14.56,100,1,12.73,100,1,14.83,100,1,12.67,100,1,14.84,100,1,12.5,700,1,14.89,100,1,12.48,200,2,14.91,700,1,12.47,100,1,14.95,700,1,12.46,100,1,14.98,200,2
2025-07-17T14:47:37.385234288Z,2025-07-17T14:47:37.385400265Z,160,2,1108,C,B,0,12.26,700,130,165977,183649801,ARL,44570585,13.38,33,1,14.01,100,1,13.37,100,1,14.26,2,1,13.15,2,1,14.28,100,1,13.1,100,1,14.56,100,1,12.73,100,1,14.83,100,1,12.67,100,1,14.84,100,1,12.5,700,1,14.89,100,1,12.48,200,2,14.91,700,1,12.47,100,1,14.95,700,1,12.46,100,1,14.98,200,2
2025-07-17T14:52:02.610343819Z,2025-07-17T14:52:02.610509102Z,160,2,1108,A,A,0,13.71,1,130,165283,189559141,ARL,223347833,13.38,33,1,13.71,1,1,13.37,100,1,14.01,100,1,13.15,2,1,14.26,2,1,13.1,100,1,14.28,100,1,12.73,100,1,14.56,100,1,12.67,100,1,14.83,100,1,12.5,700,1,14.84,100,1,12.48,200,2,14.89,100,1,12.47,100,1,14.91,700,1,12.46,100,1,14.95,700,1
2025-07-17T14:52:02.611536221Z,2025-07-17T14:52:02.611701408Z,160,2,1108,C,A,0,13.71,1,130,165187,189559156,ARL,223347833,13.38,33,1,14.01,100,1,13.37,100,1,14.26,2,1,13.15,2,1,14.28,100,1,13.1,100,1,14.56,100,1,12.73,100,1,14.83,100,1,12.67,100,1,14.84,100,1,12.5,700,1,14.89,100,1,12.48,200,2,14.91,700,1,12.47,100,1,14.95,700,1,12.46,100,1,14.98,200,2
2025-07-17T15:00:11.560513555Z,2025-07-17T15:00:11.560678862Z,160,2,1108,C,B,0,13.38,33,130,165307,200140364,ARL,215999733,13.37,100,1,14.01,100,1,13.15,2,1,14.26,2,1,13.1,100,1,14.28,100,1,12.73,100,1,14.56,100,1,12.67,100,1,14.83,100,1,12.5,700,1,14.84,100,1,12.48,200,2,14.89,100,1,12.47,100,1,14.91,700,1,12.46,100,1,14.95,700,1,12.43,700,1,14.98,200,2
2025-07-17T15:00:11.562887948Z,2025-07-17T15:00:11.563053782Z,160,2,1108,C,B,0,12.48,100,0,165834,200140389,ARL,215999761,13.37,100,1,14.01,100,1,13.15,2,1,14.26,2,1,13.1,100,1,14.28,100,1,12.73,100,1,14.56,100,1,12.67,100,1,14.83,100,1,12.5,700,1,14.84,100,1,12.48,100,1,14.89,100,1,12.47,100,1,14.91,700,1,12.46,100,1,14.95,700,1,12.43,700,1,14.98,200,2
2025-07-17T15:00:11.562887948Z,2025-07-17T15:00:11.563053782Z,160,2,1108,A,B,0,12.65,100,130,165834,200140389,ARL,236179089,13.37,100,1,14.01,100,1,13.15,2,1,14.26,2,1,13.1,100,1,14.28,100,1,12.73,100,1,14.56,100,1,12.67,100,1,14.83,100,1,12.65,100,1,14.84,100,1,12.5,700,1,14.89,100,1,12.48,100,1,14.91,700,1,12.47,100,1,14.95,700,1,12.46,100,1,14.98,200,2
2025-07-17T15:00:12.536052536Z,2025-07-17T15:00:12.536218524Z,160,2,1108,C,B,0,12.48,100,0,165988,200161810,ARL,215999741,13.37,100,1,14.01,100,1,13.15,2,1,14.26,2,1,13.1,100,1,14.28,100,1,12.73,100,1,14.56,100,1,12.67,100,1,14.83,100,1,12.65,100,1,14.84,100,1,12.5,700,1,14.89,100,1,12.47,100,1,14.91,700,1,12.46,100,1,14.95,700,1,12.43,700,1,14.98,200,2
2025-07-17T15:00:12.536052536Z,2025-07-17T15:00:12.536218524Z,160,2,1108,A,B,0,12.65,100,130,165988,200161810,ARL,236206261,13.37,100,1,14.01,100,1,13.15,2,1,14.26,2,1,13.1,100,1,14.28,100,1,12.73,100,1,14.56,100,1,12.67,100,1,14.83,100,1,12.65,200,2,14.84,100,1,12.5,700,1,14.89,100,1,12.47,100,1,14.91,700,1,12.46,100,1,14.95,700,1,12.43,700,1,14.98,200,2
2025-07-17T15:01:11.658624662Z,2025-07-17T15:01:11.658789910Z,160,2,1108,A,A,0,13.98,10,130,165248,201616674,ARL,237940713,13.37,100,1,13.98,10,1,13.15,2,1,14.01,100,1,13.1,100,1,14.26,2,1,12.73,100,1,14.28,100,1,12.67,100,1,14.56,100,1,12.65,200,2,14.83,100,1,12.5,700,1,14.84,100,1,12.47,100,1,14.89,100,1,12.46,100,1,14.91,700,1,12.43,700,1,14.95,700,1
2025-07-17T15:01:12.948220412Z,2025-07-17T15:01:12.948386121Z,160,2,1108,C,A,0,14.01,100,0,165709,201642675,ARL,168141389,13.37,100,1,13.98,10,1,13.15,2,1,14.26,2,1,13.1,100,1,14.28,100,1,12.73,100,1,14.56,100,1,12.67,100,1,14.83,100,1,12.65,200,2,14.84,100,1,12.5,700,1,14.89,100,1,12.47,100,1,14.91,700,1,12.46,100,1,14.95,700,1,12.43,700,1,14.98,200,2
2025-07-17T15:01:12.948220412Z,2025-07-17T15:01:12.948386121Z,160,2,1108,A,A,0,13.99,100,130,165709,201642675,ARL,237978541,13.37,100,1,13.98,10,1,13.15,2,1,13.99,100,1,13.1,100,1,14.26,2,1,12.73,100,1,14.28,100,1,12.67,100,1,14.56,100,1,12.65,200,2,14.83,100,1,12.5,700,1,14.84,100,1,12.47,100,1,14.89,100,1,12.46,100,1,14.91,700,1,12.43,700,1,14.95,700,1
2025-07-17T15:01:12.948959226Z,2025-07-17T15:01:12.949124493Z,160,2,1108,C,A,0,14.83,100,130,165267,201642712,ARL,84628793,13.37,100,1,13.98,10,1,13.15,2,1,13.99,100,1,13.1,100,1,14.26,2,1,12.73,100,1,14.28,100,1,12.67,100,1,14.56,100,1,12.65,200,2,14.84,100,1,12.5,700,1,14.89,100,1,12.47,100,1,14.91,700,1,12.46,100,1,14.95,700,1,12.43,700,1,14.98,200,2
2025-07-17T15:01:12.949317198Z,2025-07-17T15:01:12.949484115Z,160,2,1108,A,A,0,14.61,100,130,166917,201642747,ARL,237978629,13.37,100,1,13.98,10,1,13.15,2,1,13.99,100,1,13.1,100,1,14.26,2,1,12.73,100,1,14.28,100,1,12.67,100,1,14.56,100,1,12.65,200,2,14.61,100,1,12.5,700,1,14.84,100,1,12.47,100,1,14.89,100,1,12.46,100,1,14.91,700,1,12.43,700,1,14.95,700,1
2025-07-17T15:01:26.963746832Z,2025-07-17T15:01:26.963916368Z,160,2,1108,C,A,0,13.98,10,128,169536,201984003,ARL,237940713,13.37,100,1,13.99,100,1,13.15,2,1,14.26,2,1,13.1,100,1,14.28,100,1,12.73,100,1,14.56,100,1,12.67,100,1,14.61,100,1,12.65,200,2,14.84,100,1,12.5,700,1,14.89,100,1,12.47,100,1,14.91,700,1,12.46,100,1,14.95,700,1,12.43,700,1,14.98,200,2
2025-07-17T15:01:37.513147090Z,2025-07-17T15:01:37.513312432Z,160,2,1108,A,A,0,13.98,10,130,165342,202186180,ARL,238668633,13.37,100,1,13.98,10,1,13.15,2,1,13.99,100,1,13.1,100,1,14.26,2,1,12.73,100,1,14.28,100,1,12.67,100,1,14.56,100,1,12.65,200,2,14.61,100,1,12.5,700,1,14.84,100,1,12.47,100,1,14.89,100,1,12.46,100,1,14.91,700,1,12.43,700,1,14.95,700,1
2025-07-17T15:05:36.047029298Z,2025-07-17T15:05:36.047202557Z,160,2,1108,C,A,0,13.98,10,128,173259,207097179,ARL,238668633,13.37,100,1,13.99,100,1,13.15,2,1,14.26,2,1,13.1,100,1,14.28,100,1,12.73,100,1,14.56,100,1,12.67,100,1,14.61,100,1,12.65,200,2,14.84,100,1,12.5,700,1,14.89,100,1,12.47,100,1,14.91,700,1,12.46,100,1,14.95,700,1,12.43,700,1,14.98,200,2
2025-07-17T15:10:34.469700487Z,2025-07-17T15:10:34.469866273Z,160,2,1108,C,A,0,14.26,2,0,165786,213735006,ARL,129518753,13.37,100,1,13.99,100,1,13.15,2,1,14.28,100,1,13.1,100,1,14.56,100,1,12.73,100,1,14.61,100,1,12.67,100,1,14.84,100,1,12.65,200,2,14.89,100,1,12.5,700,1,14.91,700,1,12.47,100,1,14.95,700,1,12.46,100,1,14.98,200,2,12.43,700,1,14.99,700,1
2025-07-17T15:10:34.469700487Z,2025-07-17T15:10:34.469866273Z,160,2,1108,A,A,0,14.17,2,130,165786,213735006,ARL,252720897,13.37,100,1,13.99,100,1,13.15,2,1,14.17,2,1,13.1,100,1,14.28,100,1,12.73,100,1,14.56,100,1,12.67,100,1,14.61,100,1,12.65,200,2,14.84,100,1,12.5,700,1,14.89,100,1,12.47,100,1,14.91,700,1,12.46,100,1,14.95,700,1,12.43,700,1,14.98,200,2
2025-07-17T15:12:52.735249178Z,2025-07-17T15:12:52.735414592Z,160,2,1108,A,A,0,14.03,100,130,165414,216651092,ARL,256325129,13.37,100,1,13.99,100,1,13.15,2,1,14.03,100,1,13.1,100,1,14.17,2,1,12.73,100,1,14.28,100,1,12.67,100,1,14.56,100,1,12.65,200,2,14.61,100,1,12.5,700,1,14.84,100,1,12.47,100,1,14.89,100,1,12.46,100,1,14.91,700,1,12.43,700,1,14.95,700,1
2025-07-17T15:13:06.511687613Z,2025-07-17T15:13:06.511853457Z,160,2,1108,A,A,0,13.98,10,130,165844,216995105,ARL,256739841,13.37,100,1,13.98,10,1,13.15,2,1,13.99,100,1,13.1,100,1,14.03,100,1,12.73,100,1,14.17,2,1,12.67,100,1,14.28,100,1,12.65,200,2,14.56,100,1,12.5,700,1,14.61,100,1,12.47,100,1,14.84,100,1,12.46,100,1,14.89,100,1,12.43,700,1,14.91,700,1
2025-07-17T15:13:08.653923821Z,2025-07-17T15:13:08.654089411Z,160,2,1108,A,A,0,14.01,100,130,165590,217058300,ARL,256818881,13.37,100,1,13.98,10,1,13.15,2,1,13.99,100,1,13.1,100,1,14.01,100,1,12.73,100,1,14.03,100,1,12.67,100,1,14.17,2,1,12.65,200,2,14.28,100,1,12.5,700,1,14.56,100,1,12.47,100,1,14.61,100,1,12.46,100,1,14.84,100,1,12.43,700,1,14.89,100,1
2025-07-17T15:13:08.661521116Z,2025-07-17T15:13:08.661686458Z,160,2,1108,C,A,0,14.03,100,130,165342,217058550,ARL,256325129,13.37,100,1,13.98,10,1,13.15,2,1,13.99,100,1,13.1,100,1,14.01,100,1,12.73,100,1,14.17,2,1,12.67,100,1,14.28,100,1,12.65,200,2,14.56,100,1,12.5,700,1,14.61,100,1,12.47,100,1,14.84,100,1,12.46,100,1,14.89,100,1,12.43,700,1,14.91,700,1
2025-07-17T15:14:00.440563034Z,2025-07-17T15:14:00.440728359Z,160,2,1108,C,A,0,13.98,10,130,165325,218096891,ARL,256739841,13.37,100,1,13.99,100,1,13.15,2,1,14.01,100,1,13.1,100,1,14.17,2,1,12.73,100,1,14.28,100,1,12.67,100,1,14.56,100,1,12.65,200,2,14.61,100,1,12.5,700,1,14.84,100,1,12.47,100,1,14.89,100,1,12.46,100,1,14.91,700,1,12.43,700,1,14.95,700,1
2025-07-17T15:14:52.381974473Z,2025-07-17T15:14:52.382139830Z,160,2,1108,A,A,0,13.98,10,130,165357,219204095,ARL,259546169,13.37,100,1,13.98,10,1,13.15,2,1,13.99,100,1,13.1,100,1,14.01,100,1,12.73,100,1,14.17,2,1,12.67,100,1,14.28,100,1,12.65,200,2,14.56,100,1,12.5,700,1,14.61,100,1,12.47,100,1,14.84,100,1,12.46,100,1,14.89,100,1,12.43,700,1,14.91,700,1
2025-07-17T15:14:56.683144163Z,2025-07-17T15:14:56.683309707Z,160,2,1108,C,A,0,14.01,100,130,165544,219317677,ARL,256818881,13.37,100,1,13.98,10,1,13.15,2,1,13.99,100,1,13.1,100,1,14.17,2,1,12.73,100,1,14.28,100,1,12.67,100,1,14.56,100,1,12.65,200,2,14.61,100,1,12.5,700,1,14.84,100,1,12.47,100,1,14.89,100,1,12.46,100,1,14.91,700,1,12.43,700,1,14.95,700,1
2025-07-17T15:15:11.660953613Z,2025-07-17T15:15:11.661118778Z,160,2,1108,A,A,0,14.02,100,130,165165,219726276,ARL,260184621,13.37,100,1,13.98,10,1,13.15,2,1,13.99,100,1,13.1,100,1,14.02,100,1,12.73,100,1,14.17,2,1,12.67,100,1,14.28,100,1,12.65,200,2,14.56,100,1,12.5,700,1,14.61,100,1,12.47,100,1,14.84,100,1,12.46,100,1,14.89,100,1,12.43,700,1,14.91,700,1
2025-07-17T15:15:32.408694312Z,2025-07-17T15:15:32.408863263Z,160,2,1108,C,A,0,13.98,10,128,168951,220152194,ARL,259546169,13.37,100,1,13.99,100,1,13.15,2,1,14.02,100,1,13.1,100,1,14.17,2,1,12.73,100,1,14.28,100,1,12.67,100,1,14.56,100,1,12.65,200,2,14.61,100,1,12.5,700,1,14.84,100,1,12.47,100,1,14.89,100,1,12.46,100,1,14.91,700,1,12.43,700,1,14.95,700,1
2025-07-17T15:16:31.607077080Z,2025-07-17T15:16:31.607242914Z,160,2,1108,A,A,0,14,100,130,165834,221423516,ARL,262279553,13.37,100,1,13.99,100,1,13.15,2,1,14,100,1,13.1,100,1,14.02,100,1,12.73,100,1,14.17,2,1,12.67,100,1,14.28,100,1,12.65,200,2,14.56,100,1,12.5,700,1,14.61,100,1,12.47,100,1,14.84,100,1,12.46,100,1,14.89,100,1,12.43,700,1,14.91,700,1
2025-07-17T15:16:31.614205345Z,2025-07-17T15:16:31.614370696Z,160,2,1108,C,A,0,14.02,100,130,165351,221423706,ARL,260184621,13.37,100,1,13.99,100,1,13.15,2,1,14,100,1,13.1,100,1,14.17,2,1,12.73,100,1,14.28,100,1,12.67,100,1,14.56,100,1,12.65,200,2,14.61,100,1,12.5,700,1,14.84,100,1,12.47,100,1,14.89,100,1,12.46,100,1,14.91,700,1,12.43,700,1,14.95,700,1
2025-07-17T15:16:39.373301585Z,2025-07-17T15:16:39.373467449Z,160,2,1108,A,A,0,13.98,10,130,165864,221549244,ARL,262432821,13.37,100,1,13.98,10,1,13.15,2,1,13.99,100,1,13.1,100,1,14,100,1,12.73,100,1,14.17,2,1,12.67,100,1,14.28,100,1,12.65,200,2,14.56,100,1,12.5,700,1,14.61,100,1,12.47,100,1,14.84,100,1,12.46,100,1,14.89,100,1,12.43,700,1,14.91,700,1
2025-07-17T15:17:50.916157330Z,2025-07-17T15:17:50.916325497Z,160,2,1108,C,A,0,13.98,10,130,168167,223060323,ARL,262432821,13.37,100,1,13.99,100,1,13.15,2,1,14,100,1,13.1,100,1,14.17,2,1,12.73,100,1,14.28,100,1,12.67,100,1,14.56,100,1,12.65,200,2,14.61,100,1,12.5,700,1,14.84,100,1,12.47,100,1,14.89,100,1,12.46,100,1,14.91,700,1,12.43,700,1,14.95,700,1
2025-07-17T15:17:51.938301087Z,2025-07-17T15:17:51.938467389Z,160,2,1108,C,A,0,14,100,130,166302,223092013,ARL,262279553,13.37,100,1,13.99,100,1,13.15,2,1,14.17,2,1,13.1,100,1,14.28,100,1,12.73,100,1,14.56,100,1,12.67,100,1,14.61,100,1,12.65,200,2,14.84,100,1,12.5,700,1,14.89,100,1,12.47,100,1,14.91,700,1,12.46,100,1,14.95,700,1,12.43,700,1,14.98,200,2
2025-07-17T15:17:55.957258362Z,2025-07-17T15:17:55.957423821Z,160,2,1108,A,A,0,14.01,100,130,165459,223181022,ARL,264420961,13.37,100,1,13.99,100,1,13.15,2,1,14.01,100,1,13.1,100,1,14.17,2,1,12.73,100,1,14.28,100,1,12.67,100,1,14.56,100,1,12.65,200,2,14.61,100,1,12.5,700,1,14.84,100,1,12.47,100,1,14.89,100,1,12.46,100,1,14.91,700,1,12.43,700,1,14.95,700,1
2025-07-17T15:19:23.618215364Z,2025-07-17T15:19:23.618380576Z,160,2,1108,C,A,0,14.01,100,130,165212,224925658,ARL,264420961,13.37,100,1,13.99,100,1,13.15,2,1,14.17,2,1,13.1,100,1,14.28,100,1,12.73,100,1,14.56,100,1,12.67,100,1,14.61,100,1,12.65,200,2,14.84,100,1,12.5,700,1,14.89,100,1,12.47,100,1,14.91,700,1,12.46,100,1,14.95,700,1,12.43,700,1,14.98,200,2
2025-07-17T15:19:27.663625107Z,2025-07-17T15:19:27.663790911Z,160,2,1108,A,A,0,14.03,100,130,165804,224999109,ARL,266714557,13.37,100,1,13.99,100,1,13.15,2,1,14.03,100,1,13.1,100,1,14.17,2,1,12.73,100,1,14.28,100,1,12.67,100,1,14.56,100,1,12.65,200,2,14.61,100,1,12.5,700,1,14.84,100,1,12.47,100,1,14.89,100,1,12.46,100,1,14.91,700,1,12.43,700,1,14.95,700,1
2025-07-17T15:20:46.704980311Z,2025-07-17T15:20:46.705145876Z,160,2,1108,A,A,0,14.01,100,130,165565,226851430,ARL,269075833,13.37,100,1,13.99,100,1,13.15,2,1,14.01,100,1,13.1,100,1,14.03,100,1,12.73,100,1,14.17,2,1,12.67,100,1,14.28,100,1,12.65,200,2,14.56,100,1,12.5,700,1,14.61,100,1,12.47,100,1,14.84,100,1,12.46,100,1,14.89,100,1,12.43,700,1,14.91,700,1
2025-07-17T15:20:46.716532886Z,2025-07-17T15:20:46.716698477Z,160,2,1108,C,A,0,14.03,100,130,165591,226851533,ARL,266714557,13.37,100,1,13.99,100,1,13.15,2,1,14.01,100,1,13.1,100,1,14.17,2,1,12.73,100,1,14.28,100,1,12.67,100,1,14.56,100,1,12.65,200,2,14.61,100,1,12.5,700,1,14.84,100,1,12.47,100,1,14.89,100,1,12.46,100,1,14.91,700,1,12.43,700,1,14.95,700,1
2025-07-17T15:23:00.249796874Z,2025-07-17T15:23:00.249962772Z,160,2,1108,C,B,0,13.15,2,0,165898,229397485,ARL,130693973,13.37,100,1,13.99,100,1,13.1,100,1,14.01,100,1,12.73,100,1,14.17,2,1,12.67,100,1,14.28,100,1,12.65,200,2,14.56,100,1,12.5,700,1,14.61,100,1,12.47,100,1,14.84,100,1,12.46,100,1,14.89,100,1,12.43,700,1,14.91,700,1,12.42,700,1,14.95,700,1
2025-07-17T15:23:00.249796874Z,2025-07-17T15:23:00.249962772Z,160,2,1108,A,B,0,13.23,2,130,165898,229397485,ARL,272263853,13.37,100,1,13.99,100,1,13.23,2,1,14.01,100,1,13.1,100,1,14.17,2,1,12.73,100,1,14.28,100,1,12.67,100,1,14.56,100,1,12.65,200,2,14.61,100,1,12.5,700,1,14.84,100,1,12.47,100,1,14.89,100,1,12.46,100,1,14.91,700,1,12.43,700,1,14.95,700,1
2025-07-17T15:26:04.665993515Z,2025-07-17T15:26:04.666158860Z,160,2,1108,C,A,0,14.17,2,0,165345,232977340,ARL,252720897,13.37,100,1,13.99,100,1,13.23,2,1,14.01,100,1,13.1,100,1,14.28,100,1,12.73,100,1,14.56,100,1,12.67,100,1,14.61,100,1,12.65,200,2,14.84,100,1,12.5,700,1,14.89,100,1,12.47,100,1,14.91,700,1,12.46,100,1,14.95,700,1,12.43,700,1,14.98,200,2
2025-07-17T15:26:04.665993515Z,2025-07-17T15:26:04.666158860Z,160,2,1108,A,A,0,14.09,2,130,165345,232977340,ARL,276751517,13.37,100,1,13.99,100,1,13.23,2,1,14.01,100,1,13.1,100,1,14.09,2,1,12.73,100,1,14.28,100,1,12.67,100,1,14.56,100,1,12.65,200,2,14.61,100,1,12.5,700,1,14.84,100,1,12.47,100,1,14.89,100,1,12.46,100,1,14.91,700,1,12.43,700,1,14.95,700,1
2025-07-17T15:28:38.882820591Z,2025-07-17T15:28:38.882985923Z,160,2,1108,A,A,0,13.99,100,130,165332,235874491,ARL,280387693,13.37,100,1,13.99,200,2,13.23,2,1,14.01,100,1,13.1,100,1,14.09,2,1,12.73,100,1,14.28,100,1,12.67,100,1,14.56,100,1,12.65,200,2,14.61,100,1,12.5,700,1,14.84,100,1,12.47,100,1,14.89,100,1,12.46,100,1,14.91,700,1,12.43,700,1,14.95,700,1
2025-07-17T15:28:38.890623989Z,2025-07-17T15:28:38.890789214Z,160,2,1108,C,A,0,14.01,100,130,165225,235874556,ARL,269075833,13.37,100,1,13.99,200,2,13.23,2,1,14.09,2,1,13.1,100,1,14.28,100,1,12.73,100,1,14.56,100,1,12.67,100,1,14.61,100,1,12.65,200,2,14.84,100,1,12.5,700,1,14.89,100,1,12.47,100,1,14.91,700,1,12.46,100,1,14.95,700,1,12.43,700,1,14.98,200,2
2025-07-17T15:28:44.820769301Z,2025-07-17T15:28:44.820934614Z,160,2,1108,C,A,0,13.99,100,130,165313,235961324,ARL,280387693,13.37,100,1,13.99,100,1,13.23,2,1,14.09,2,1,13.1,100,1,14.28,100,1,12.73,100,1,14.56,100,1,12.67,100,1,14.61,100,1,12.65,200,2,14.84,100,1,12.5,700,1,14.89,100,1,12.47,100,1,14.91,700,1,12.46,100,1,14.95,700,1,12.43,700,1,14.98,200,2
2025-07-17T15:28:48.918645728Z,2025-07-17T15:28:48.918811203Z,160,2,1108,A,A,0,14.01,100,130,165475,236028551,ARL,280580873,13.37,100,1,13.99,100,1,13.23,2,1,14.01,100,1,13.1,100,1,14.09,2,1,12.73,100,1,14.28,100,1,12.67,100,1,14.56,100,1,12.65,200,2,14.61,100,1,12.5,700,1,14.84,100,1,12.47,100,1,14.89,100,1,12.46,100,1,14.91,700,1,12.43,700,1,14.95,700,1
2025-07-17T15:30:23.573067851Z,2025-07-17T15:30:23.573233259Z,160,2,1108,A,A,0,13.82,10,130,165408,237754758,ARL,282775557,13.37,100,1,13.82,10,1,13.23,2,1,13.99,100,1,13.1,100,1,14.01,100,1,12.73,100,1,14.09,2,1,12.67,100,1,14.28,100,1,12.65,200,2,14.56,100,1,12.5,700,1,14.61,100,1,12.47,100,1,14.84,100,1,12.46,100,1,14.89,100,1,12.43,700,1,14.91,700,1
2025-07-17T15:30:23.573362522Z,2025-07-17T15:30:23.573528359Z,160,2,1108,C,A,0,14.98,100,0,165837,237754762,ARL,128570237,13.37,100,1,13.82,10,1,13.23,2,1,13.99,100,1,13.1,100,1,14.01,100,1,12.73,100,1,14.09,2,1,12.67,100,1,14.28,100,1,12.65,200,2,14.56,100,1,12.5,700,1,14.61,100,1,12.47,100,1,14.84,100,1,12.46,100,1,14.89,100,1,12.43,700,1,14.91,700,1
2025-07-17T15:30:23.573362522Z,2025-07-17T15:30:23.573528359Z,160,2,1108,A,A,0,14.72,100,130,165837,237754762,ARL,282775561,13.37,100,1,13.82,10,1,13.23,2,1,13.99,100,1,13.1,100,1,14.01,100,1,12.73,100,1,14.09,2,1,12.67,100,1,14.28,100,1,12.65,200,2,14.56,100,1,12.5,700,1,14.61,100,1,12.47,100,1,14.72,100,1,12.46,100,1,14.84,100,1,12.43,700,1,14.89,100,1
2025-07-17T15:30:23.574688647Z,2025-07-17T15:30:23.574854165Z,160,2,1108,C,A,0,14.98,100,0,165518,237754776,ARL,128570229,13.37,100,1,13.82,10,1,13.23,2,1,13.99,100,1,13.1,100,1,14.01,100,1,12.73,100,1,14.09,2,1,12.67,100,1,14.28,100,1,12.65,200,2,14.56,100,1,12.5,700,1,14.61,100,1,12.47,100,1,14.72,100,1,12.46,100,1,14.84,100,1,12.43,700,1,14.89,100,1
2025-07-17T15:30:23.574688647Z,2025-07-17T15:30:23.574854165Z,160,2,1108,A,A,0,14.72,100,130,165518,237754776,ARL,282775577,13.37,100,1,13.82,10,1,13.23,2,1,13.99,100,1,13.1,100,1,14.01,100,1,12.73,100,1,14.09,2,1,12.67,100,1,14.28,100,1,12.65,200,2,14.56,100,1,12.5,700,1,14.61,100,1,12.47,100,1,14.72,200,2,12.46,100,1,14.84,100,1,12.43,700,1,14.89,100,1
2025-07-17T15:30:23.585025490Z,2025-07-17T15:30:23.585191081Z,160,2,1108,A,A,0,13.84,100,130,165591,237755075,ARL,282775973,13.37,100,1,13.82,10,1,13.23,2,1,13.84,100,1,13.1,100,1,13.99,100,1,12.73,100,1,14.01,100,1,12.67,100,1,14.09,2,1,12.65,200,2,14.28,100,1,12.5,700,1,14.56,100,1,12.47,100,1,14.61,100,1,12.46,100,1,14.72,200,2,12.43,700,1,14.84,100,1
2025-07-17T15:30:23.585795327Z,2025-07-17T15:30:23.585960886Z,160,2,1108,C,A,0,15.09,100,0,165559,237755081,ARL,146955361,13.37,100,1,13.82,10,1,13.23,2,1,13.84,100,1,13.1,100,1,13.99,100,1,12.73,100,1,14.01,100,1,12.67,100,1,14.09,2,1,12.65,200,2,14.28,100,1,12.5,700,1,14.56,100,1,12.47,100,1,14.61,100,1,12.46,100,1,14.72,200,2,12.43,700,1,14.84,100,1
2025-07-17T15:30:23.585795327Z,2025-07-17T15:30:23.585960886Z,160,2,1108,A,A,0,14.91,100,130,165559,237755081,ARL,282776009,13.37,100,1,13.82,10,1,13.23,2,1,13.84,100,1,13.1,100,1,13.99,100,1,12.73,100,1,14.01,100,1,12.67,100,1,14.09,2,1,12.65,200,2,14.28,100,1,12.5,700,1,14.56,100,1,12.47,100,1,14.61,100,1,12.46,100,1,14.72,200,2,12.43,700,1,14.84,100,1
2025-07-17T15:30:23.586553674Z,2025-07-17T15:30:23.586719371Z,160,2,1108,C,A,0,14.89,100,0,165697,237755086,ARL,128570453,13.37,100,1,13.82,10,1,13.23,2,1,13.84,100,1,13.1,100,1,13.99,100,1,12.73,100,1,14.01,100,1,12.67,100,1,14.09,2,1,12.65,200,2,14.28,100,1,12.5,700,1,14.56,100,1,12.47,100,1,14.61,100,1,12.46,100,1,14.72,200,2,12.43,700,1,14.84,100,1
2025-07-17T15:30:23.586553674Z,2025-07-17T15:30:23.586719371Z,160,2,1108,A,A,0,14.65,100,130,165697,237755086,ARL,282776013,13.37,100,1,13.82,10,1,13.23,2,1,13.84,100,1,13.1,100,1,13.99,100,1,12.73,100,1,14.01,100,1,12.67,100,1,14.09,2,1,12.65,200,2,14.28,100,1,12.5,700,1,14.56,100,1,12.47,100,1,14.61,100,1,12.46,100,1,14.65,100,1,12.43,700,1,14.72,200,2
2025-07-17T15:30:23.586596452Z,2025-07-17T15:30:23.586762105Z,160,2,1108,C,A,0,15.64,100,0,165653,237755087,ARL,84628833,13.37,100,1,13.82,10,1,13.23,2,1,13.84,100,1,13.1,100,1,13.99,100,1,12.73,100,1,14.01,100,1,12.67,100,1,14.09,2,1,12.65,200,2,14.28,100,1,12.5,700,1,14.56,100,1,12.47,100,1,14.61,100,1,12.46,100,1,14.65,100,1,12.43,700,1,14.72,200,2
2025-07-17T15:30:23.586596452Z,2025-07-17T15:30:23.586762105Z,160,2,1108,A,A,0,15.23,100,130,165653,237755087,ARL,282776017,13.37,100,1,13.82,10,1,13.23,2,1,13.84,100,1,13.1,100,1,13.99,100,1,12.73,100,1,14.01,100,1,12.67,100,1,14.09,2,1,12.65,200,2,14.28,100,1,12.5,700,1,14.56,100,1,12.47,100,1,14.61,100,1,12.46,100,1,14.65,100,1,12.43,700,1,14.72,200,2
2025-07-17T15:30:23.587267064Z,2025-07-17T15:30:23.587432517Z,160,2,1108,C,A,0,17.9,100,0,165453,237755097,ARL,128570685,13.37,100,1,13.82,10,1,13.23,2,1,13.84,100,1,13.1,100,1,13.99,100,1,12.73,100,1,14.01,100,1,12.67,100,1,14.09,2,1,12.65,200,2,14.28,100,1,12.5,700,1,14.56,100,1,12.47,100,1,14.61,100,1,12.46,100,1,14.65,100,1,12.43,700,1,14.72,200,2
2025-07-17T15:30:23.587267064Z,2025-07-17T15:30:23.587432517Z,160,2,1108,A,A,0,17.58,100,130,165453,237755097,ARL,282776025,13.37,100,1,13.82,10,1,13.23,2,1,13.84,100,1,13.1,100,1,13.99,100,1,12.73,100,1,14.01,100,1,12.67,100,1,14.09,2,1,12.65,200,2,14.28,100,1,12.5,700,1,14.56,100,1,12.47,100,1,14.61,100,1,12.46,100,1,14.65,100,1,12.43,700,1,14.72,200,2
2025-07-17T15:30:23.587416236Z,2025-07-17T15:30:23.587581881Z,160,2,1108,C,A,0,15.08,100,0,165645,237755098,ARL,128570449,13.37,100,1,13.82,10,1,13.23,2,1,13.84,100,1,13.1,100,1,13.99,100,1,12.73,100,1,14.01,100,1,12.67,100,1,14.09,2,1,12.65,200,2,14.28,100,1,12.5,700,1,14.56,100,1,12.47,100,1,14.61,100,1,12.46,100,1,14.65,100,1,12.43,700,1,14.72,200,2
2025-07-17T15:30:23.587416236Z,2025-07-17T15:30:23.587581881Z,160,2,1108,A,A,0,14.81,100,130,165645,237755098,ARL,282776029,13.37,100,1,13.82,10,1,13.23,2,1,13.84,100,1,13.1,100,1,13.99,100,1,12.73,100,1,14.01,100,1,12.67,100,1,14.09,2,1,12.65,200,2,14.28,100,1,12.5,700,1,14.56,100,1,12.47,100,1,14.61,100,1,12.46,100,1,14.65,100,1,12.43,700,1,14.72,200,2
2025-07-17T15:30:23.587445922Z,2025-07-17T15:30:23.587611440Z,160,2,1108,C,A,0,16.21,100,0,165518,237755099,ARL,128570977,13.37,100,1,13.82,10,1,13.23,2,1,13.84,100,1,13.1,100,1,13.99,100,1,12.73,100,1,14.01,100,1,12.67,100,1,14.09,2,1,12.65,200,2,14.28,100,1,12.5,700,1,14.56,100,1,12.47,100,1,14.61,100,1,12.46,100,1,14.65,100,1,12.43,700,1,14.72,200,2
2025-07-17T15:30:23.587445922Z,2025-07-17T15:30:23.587611440Z,160,2,1108,A,A,0,15.92,100,130,165518,237755099,ARL,282776033,13.37,100,1,13.82,10,1,13.23,2,1,13.84,100,1,13.1,100,1,13.99,100,1,12.73,100,1,14.01,100,1,12.67,100,1,14.09,2,1,12.65,200,2,14.28,100,1,12.5,700,1,14.56,100,1,12.47,100,1,14.61,100,1,12.46,100,1,14.65,100,1,12.43,700,1,14.72,200,2
2025-07-17T15:30:23.590096343Z,2025-07-17T15:30:23.590261792Z,160,2,1108,C,A,0,15.08,100,0,165449,237755128,ARL,128573957,13.37,100,1,13.82,10,1,13.23,2,1,13.84,100,1,13.1,100,1,13.99,100,1,12.73,100,1,14.01,100,1,12.67,100,1,14.09,2,1,12.65,200,2,14.28,100,1,12.5,700,1,14.56,100,1,12.47,100,1,14.61,100,1,12.46,100,1,14.65,100,1,12.43,700,1,14.72,200,2
2025-07-17T15:30:23.590096343Z,2025-07-17T15:30:23.590261792Z,160,2,1108,A,A,0,14.81,100,130,165449,237755128,ARL,282776089,13.37,100,1,13.82,10,1,13.23,2,1,13.84,100,1,13.1,100,1,13.99,100,1,12.73,100,1,14.01,100,1,12.67,100,1,14.09,2,1,12.65,200,2,14.28,100,1,12.5,700,1,14.56,100,1,12.47,100,1,14.61,100,1,12.46,100,1,14.65,100,1,12.43,700,1,14.72,200,2
2025-07-17T15:30:23.591793735Z,2025-07-17T15:30:23.591959120Z,160,2,1108,C,A,0,14.01,100,130,165385,237755138,ARL,280580873,13.37,100,1,13.82,10,1,13.23,2,1,13.84,100,1,13.1,100,1,13.99,100,1,12.73,100,1,14.09,2,1,12.67,100,1,14.28,100,1,12.65,200,2,14.56,100,1,12.5,700,1,14.61,100,1,12.47,100,1,14.65,100,1,12.46,100,1,14.72,200,2,12.43,700,1,14.81,200,2
2025-07-17T15:30:23.602827102Z,2025-07-17T15:30:23.602992439Z,160,2,1108,C,A,0,14.28,100,130,165337,237755229,ARL,146956357,13.37,100,1,13.82,10,1,13.23,2,1,13.84,100,1,13.1,100,1,13.99,100,1,12.73,100,1,14.09,2,1,12.67,100,1,14.56,100,1,12.65,200,2,14.61,100,1,12.5,700,1,14.65,100,1,12.47,100,1,14.72,200,2,12.46,100,1,14.81,200,2,12.43,700,1,14.84,100,1
2025-07-17T15:30:23.602881129Z,2025-07-17T15:30:23.603046460Z,160,2,1108,A,A,0,14.12,100,130,165331,237755230,ARL,282776285,13.37,100,1,13.82,10,1,13.23,2,1,13.84,100,1,13.1,100,1,13.99,100,1,12.73,100,1,14.09,2,1,12.67,100,1,14.12,100,1,12.65,200,2,14.56,100,1,12.5,700,1,14.61,100,1,12.47,100,1,14.65,100,1,12.46,100,1,14.72,200,2,12.43,700,1,14.81,200,2
2025-07-17T15:30:23.628555135Z,2025-07-17T15:30:23.628720816Z,160,2,1108,A,A,0,15.78,100,130,165681,237755415,ARL,282776733,13.37,100,1,13.82,10,1,13.23,2,1,13.84,100,1,13.1,100,1,13.99,100,1,12.73,100,1,14.09,2,1,12.67,100,1,14.12,100,1,12.65,200,2,14.56,100,1,12.5,700,1,14.61,100,1,12.47,100,1,14.65,100,1,12.46,100,1,14.72,200,2,12.43,700,1,14.81,200,2
2025-07-17T15:30:23.628567293Z,2025-07-17T15:30:23.628732597Z,160,2,1108,C,A,0,16.2,100,130,165304,237755416,ARL,84628765,13.37,100,1,13.82,10,1,13.23,2,1,13.84,100,1,13.1,100,1,13.99,100,1,12.73,100,1,14.09,2,1,12.67,100,1,14.12,100,1,12.65,200,2,14.56,100,1,12.5,700,1,14.61,100,1,12.47,100,1,14.65,100,1,12.46,100,1,14.72,200,2,12.43,700,1,14.81,200,2
2025-07-17T15:30:23.951957017Z,2025-07-17T15:30:23.952122580Z,160,2,1108,C,A,0,13.99,100,0,165563,237759683,ARL,237978541,13.37,100,1,13.82,10,1,13.23,2,1,13.84,100,1,13.1,100,1,14.09,2,1,12.73,100,1,14.12,100,1,12.67,100,1,14.56,100,1,12.65,200,2,14.61,100,1,12.5,700,1,14.65,100,1,12.47,100,1,14.72,200,2,12.46,100,1,14.81,200,2,12.43,700,1,14.84,100,1
2025-07-17T15:30:23.951957017Z,2025-07-17T15:30:23.952122580Z,160,2,1108,A,A,0,13.83,100,130,165563,237759683,ARL,282781741,13.37,100,1,13.82,10,1,13.23,2,1,13.83,100,1,13.1,100,1,13.84,100,1,12.73,100,1,14.09,2,1,12.67,100,1,14.12,100,1,12.65,200,2,14.56,100,1,12.5,700,1,14.61,100,1,12.47,100,1,14.65,100,1,12.46,100,1,14.72,200,2,12.43,700,1,14.81,200,2
2025-07-17T15:30:24.768909757Z,2025-07-17T15:30:24.769074814Z,160,2,1108,C,A,0,13.82,10,130,165057,237771822,ARL,282775557,13.37,100,1,13.83,100,1,13.23,2,1,13.84,100,1,13.1,100,1,14.09,2,1,12.73,100,1,14.12,100,1,12.67,100,1,14.56,100,1,12.65,200,2,14.61,100,1,12.5,700,1,14.65,100,1,12.47,100,1,14.72,200,2,12.46,100,1,14.81,200,2,12.43,700,1,14.84,100,1
2025-07-17T15:30:28.617171810Z,2025-07-17T15:30:28.617337198Z,160,2,1108,A,A,0,14.53,700,130,165388,237840336,ARL,282881853,13.37,100,1,13.83,100,1,13.23,2,1,13.84,100,1,13.1,100,1,14.09,2,1,12.73,100,1,14.12,100,1,12.67,100,1,14.53,700,1,12.65,200,2,14.56,100,1,12.5,700,1,14.61,100,1,12.47,100,1,14.65,100,1,12.46,100,1,14.72,200,2,12.43,700,1,14.81,200,2
2025-07-17T15:30:28.617221981Z,2025-07-17T15:30:28.617387294Z,160,2,1108,C,A,0,15.07,700,130,165313,237840337,ARL,92510741,13.37,100,1,13.83,100,1,13.23,2,1,13.84,100,1,13.1,100,1,14.09,2,1,12.73,100,1,14.12,100,1,12.67,100,1,14.53,700,1,12.65,200,2,14.56,100,1,12.5,700,1,14.61,100,1,12.47,100,1,14.65,100,1,12.46,100,1,14.72,200,2,12.43,700,1,14.81,200,2
2025-07-17T15:30:30.767048606Z,2025-07-17T15:30:30.767213907Z,160,2,1108,A,A,0,14.6,700,130,165301,237873135,ARL,282920685,13.37,100,1,13.83,100,1,13.23,2,1,13.84,100,1,13.1,100,1,14.09,2,1,12.73,100,1,14.12,100,1,12.67,100,1,14.53,700,1,12.65,200,2,14.56,100,1,12.5,700,1,14.6,700,1,12.47,100,1,14.61,100,1,12.46,100,1,14.65,100,1,12.43,700,1,14.72,200,2
2025-07-17T15:30:30.767101317Z,2025-07-17T15:30:30.767267001Z,160,2,1108,C,A,0,14.99,700,130,165684,237873136,ARL,84628757,13.37,100,1,13.83,100,1,13.23,2,1,13.84,100,1,13.1,100,1,14.09,2,1,12.73,100,1,14.12,100,1,12.67,100,1,14.53,700,1,12.65,200,2,14.56,100,1,12.5,700,1,14.6,700,1,12.47,100,1,14.61,100,1,12.46,100,1,14.65,100,1,12.43,700,1,14.72,200,2
2025-07-17T15:30:33.016821395Z,2025-07-17T15:30:33.016987097Z,160,2,1108,A,A,0,14.56,700,130,165702,237915946,ARL,282969973,13.37,100,1,13.83,100,1,13.23,2,1,13.84,100,1,13.1,100,1,14.09,2,1,12.73,100,1,14.12,100,1,12.67,100,1,14.53,700,1,12.65,200,2,14.56,800,2,12.5,700,1,14.6,700,1,12.47,100,1,14.61,100,1,12.46,100,1,14.65,100,1,12.43,700,1,14.72,200,2
2025-07-17T15:30:33.017218657Z,2025-07-17T15:30:33.017384279Z,160,2,1108,C,A,0,14.95,700,130,165622,237915951,ARL,84628797,13.37,100,1,13.83,100,1,13.23,2,1,13.84,100,1,13.1,100,1,14.09,2,1,12.73,100,1,14.12,100,1,12.67,100,1,14.53,700,1,12.65,200,2,14.56,800,2,12.5,700,1,14.6,700,1,12.47,100,1,14.61,100,1,12.46,100,1,14.65,100,1,12.43,700,1,14.72,200,2
2025-07-17T15:30:49.985741094Z,2025-07-17T15:30:49.985906754Z,160,2,1108,C,A,0,14.09,2,0,165660,238230724,ARL,276751517,13.37,100,1,13.83,100,1,13.23,2,1,13.84,100,1,13.1,100,1,14.12,100,1,12.73,100,1,14.53,700,1,12.67,100,1,14.56,800,2,12.65,200,2,14.6,700,1,12.5,700,1,14.61,100,1,12.47,100,1,14.65,100,1,12.46,100,1,14.72,200,2,12.43,700,1,14.81,200,2
2025-07-17T15:30:49.985741094Z,2025-07-17T15:30:49.985906754Z,160,2,1108,A,A,0,14.02,2,130,165660,238230724,ARL,283348193,13.37,100,1,13.83,100,1,13.23,2,1,13.84,100,1,13.1,100,1,14.02,2,1,12.73,100,1,14.12,100,1,12.67,100,1,14.53,700,1,12.65,200,2,14.56,800,2,12.5,700,1,14.6,700,1,12.47,100,1,14.61,100,1,12.46,100,1,14.65,100,1,12.43,700,1,14.72,200,2
2025-07-17T15:30:59.996351383Z,2025-07-17T15:30:59.996516554Z,160,2,1108,C,A,0,13.83,100,130,165171,238442318,ARL,282781741,13.37,100,1,13.84,100,1,13.23,2,1,14.02,2,1,13.1,100,1,14.12,100,1,12.73,100,1,14.53,700,1,12.67,100,1,14.56,800,2,12.65,200,2,14.6,700,1,12.5,700,1,14.61,100,1,12.47,100,1,14.65,100,1,12.46,100,1,14.72,200,2,12.43,700,1,14.81,200,2
2025-07-17T15:31:00.002038446Z,2025-07-17T15:31:00.002203922Z,160,2,1108,C,A,0,13.84,100,130,165476,238442443,ARL,282775973,13.37,100,1,14.02,2,1,13.23,2,1,14.12,100,1,13.1,100,1,14.53,700,1,12.73,100,1,14.56,800,2,12.67,100,1,14.6,700,1,12.65,200,2,14.61,100,1,12.5,700,1,14.65,100,1,12.47,100,1,14.72,200,2,12.46,100,1,14.81,200,2,12.43,700,1,14.84,100,1
2025-07-17T15:31:00.002313250Z,2025-07-17T15:31:00.002478393Z,160,2,1108,C,A,0,14.53,700,130,165143,238442461,ARL,282881853,13.37,100,1,14.02,2,1,13.23,2,1,14.12,100,1,13.1,100,1,14.56,800,2,12.73,100,1,14.6,700,1,12.67,100,1,14.61,100,1,12.65,200,2,14.65,100,1,12.5,700,1,14.72,200,2,12.47,100,1,14.81,200,2,12.46,100,1,14.84,100,1,12.43,700,1,14.91,800,2
2025-07-17T15:31:00.002359969Z,2025-07-17T15:31:00.002525213Z,160,2,1108,A,A,0,14.68,700,130,165244,238442467,ARL,283592941,13.37,100,1,14.02,2,1,13.23,2,1,14.12,100,1,13.1,100,1,14.56,800,2,12.73,100,1,14.6,700,1,12.67,100,1,14.61,100,1,12.65,200,2,14.65,100,1,12.5,700,1,14.68,700,1,12.47,100,1,14.72,200,2,12.46,100,1,14.81,200,2,12.43,700,1,14.84,100,1
2025-07-17T15:31:00.002772683Z,2025-07-17T15:31:00.002938332Z,160,2,1108,C,A,0,14.72,100,0,165649,238442486,ARL,282775577,13.37,100,1,14.02,2,1,13.23,2,1,14.12,100,1,13.1,100,1,14.56,800,2,12.73,100,1,14.6,700,1,12.67,100,1,14.61,100,1,12.65,200,2,14.65,100,1,12.5,700,1,14.68,700,1,12.47,100,1,14.72,100,1,12.46,100,1,14.81,200,2,12.43,700,1,14.84,100,1
2025-07-17T15:31:00.002772683Z,2025-07-17T15:31:00.002938332Z,160,2,1108,A,A,0,14.97,100,130,165649,238442486,ARL,283592993,13.37,100,1,14.02,2,1,13.23,2,1,14.12,100,1,13.1,100,1,14.56,800,2,12.73,100,1,14.6,700,1,12.67,100,1,14.61,100,1,12.65,200,2,14.65,100,1,12.5,700,1,14.68,700,1,12.47,100,1,14.72,100,1,12.46,100,1,14.81,200,2,12.43,700,1,14.84,100,1
2025-07-17T15:31:00.002788190Z,2025-07-17T15:31:00.002953704Z,160,2,1108,C,A,0,14.91,100,0,165514,238442490,ARL,282776009,13.37,100,1,14.02,2,1,13.23,2,1,14.12,100,1,13.1,100,1,14.56,800,2,12.73,100,1,14.6,700,1,12.67,100,1,14.61,100,1,12.65,200,2,14.65,100,1,12.5,700,1,14.68,700,1,12.47,100,1,14.72,100,1,12.46,100,1,14.81,200,2,12.43,700,1,14.84,100,1
2025-07-17T15:31:00.002788190Z,2025-07-17T15:31:00.002953704Z,160,2,1108,A,A,0,14.96,100,130,165514,238442490,ARL,283592997,13.37,100,1,14.02,2,1,13.23,2,1,14.12,100,1,13.1,100,1,14.56,800,2,12.73,100,1,14.6,700,1,12.67,100,1,14.61,100,1,12.65,200,2,14.65,100,1,12.5,700,1,14.68,700,1,12.47,100,1,14.72,100,1,12.46,100,1,14.81,200,2,12.43,700,1,14.84,100,1
2025-07-17T15:31:00.003202003Z,2025-07-17T15:31:00.003368272Z,160,2,1108,C,A,0,14.72,100,0,166269,238442510,ARL,282775561,13.37,100,1,14.02,2,1,13.23,2,1,14.12,100,1,13.1,100,1,14.56,800,2,12.73,100,1,14.6,700,1,12.67,100,1,14.61,100,1,12.65,200,2,14.65,100,1,12.5,700,1,14.68,700,1,12.47,100,1,14.81,200,2,12.46,100,1,14.84,100,1,12.43,700,1,14.91,700,1
2025-07-17T15:31:00.003202003Z,2025-07-17T15:31:00.003368272Z,160,2,1108,A,A,0,14.97,100,130,166269,238442510,ARL,283593041,13.37,100,1,14.02,2,1,13.23,2,1,14.12,100,1,13.1,100,1,14.56,800,2,12.73,100,1,14.6,700,1,12.67,100,1,14.61,100,1,12.65,200,2,14.65,100,1,12.5,700,1,14.68,700,1,12.47,100,1,14.81,200,2,12.46,100,1,14.84,100,1,12.43,700,1,14.91,700,1
2025-07-17T15:31:00.006618398Z,2025-07-17T15:31:00.006784947Z,160,2,1108,C,A,0,14.65,100,130,166549,238442608,ARL,282776013,13.37,100,1,14.02,2,1,13.23,2,1,14.12,100,1,13.1,100,1,14.56,800,2,12.73,100,1,14.6,700,1,12.67,100,1,14.61,100,1,12.65,200,2,14.68,700,1,12.5,700,1,14.81,200,2,12.47,100,1,14.84,100,1,12.46,100,1,14.91,700,1,12.43,700,1,14.96,100,1
2025-07-17T15:31:00.006784814Z,2025-07-17T15:31:00.006950491Z,160,2,1108,A,A,0,14.79,100,130,165677,238442616,ARL,283593313,13.37,100,1,14.02,2,1,13.23,2,1,14.12,100,1,13.1,100,1,14.56,800,2,12.73,100,1,14.6,700,1,12.67,100,1,14.61,100,1,12.65,200,2,14.68,700,1,12.5,700,1,14.79,100,1,12.47,100,1,14.81,200,2,12.46,100,1,14.84,100,1,12.43,700,1,14.91,700,1
2025-07-17T15:31:00.017594312Z,2025-07-17T15:31:00.017759891Z,160,2,1108,C,A,0,17.58,100,0,165579,238443214,ARL,282776025,13.37,100,1,14.02,2,1,13.23,2,1,14.12,100,1,13.1,100,1,14.56,800,2,12.73,100,1,14.6,700,1,12.67,100,1,14.61,100,1,12.65,200,2,14.68,700,1,12.5,700,1,14.79,100,1,12.47,100,1,14.81,200,2,12.46,100,1,14.84,100,1,12.43,700,1,14.91,700,1
2025-07-17T15:31:00.017594312Z,2025-07-17T15:31:00.017759891Z,160,2,1108,A,A,0,17.76,100,130,165579,238443214,ARL,283594173,13.37,100,1,14.02,2,1,13.23,2,1,14.12,100,1,13.1,100,1,14.56,800,2,12.73,100,1,14.6,700,1,12.67,100,1,14.61,100,1,12.65,200,2,14.68,700,1,12.5,700,1,14.79,100,1,12.47,100,1,14.81,200,2,12.46,100,1,14.84,100,1,12.43,700,1,14.91,700,1
2025-07-17T15:31:00.028729168Z,2025-07-17T15:31:00.028894478Z,160,2,1108,C,A,0,14.12,100,130,165310,238443996,ARL,282776285,13.37,100,1,14.02,2,1,13.23,2,1,14.56,800,2,13.1,100,1,14.6,700,1,12.73,100,1,14.61,100,1,12.67,100,1,14.68,700,1,12.65,200,2,14.79,100,1,12.5,700,1,14.81,200,2,12.47,100,1,14.84,100,1,12.46,100,1,14.91,700,1,12.43,700,1,14.96,100,1
2025-07-17T15:31:00.028782030Z,2025-07-17T15:31:00.028947312Z,160,2,1108,A,A,0,14.26,100,130,165282,238443998,ARL,283595181,13.37,100,1,14.02,2,1,13.23,2,1,14.26,100,1,13.1,100,1,14.56,800,2,12.73,100,1,14.6,700,1,12.67,100,1,14.61,100,1,12.65,200,2,14.68,700,1,12.5,700,1,14.79,100,1,12.47,100,1,14.81,200,2,12.46,100,1,14.84,100,1,12.43,700,1,14.91,700,1
2025-07-17T15:31:00.052941898Z,2025-07-17T15:31:00.053107210Z,160,2,1108,C,A,0,14.96,100,0,165312,238444735,ARL,283592997,13.37,100,1,14.02,2,1,13.23,2,1,14.26,100,1,13.1,100,1,14.56,800,2,12.73,100,1,14.6,700,1,12.67,100,1,14.61,100,1,12.65,200,2,14.68,700,1,12.5,700,1,14.79,100,1,12.47,100,1,14.81,200,2,12.46,100,1,14.84,100,1,12.43,700,1,14.91,700,1
2025-07-17T15:31:00.052941898Z,2025-07-17T15:31:00.053107210Z,160,2,1108,A,A,0,15.06,100,130,165312,238444735,ARL,283596673,13.37,100,1,14.02,2,1,13.23,2,1,14.26,100,1,13.1,100,1,14.56,800,2,12.73,100,1,14.6,700,1,12.67,100,1,14.61,100,1,12.65,200,2,14.68,700,1,12.5,700,1,14.79,100,1,12.47,100,1,14.81,200,2,12.46,100,1,14.84,100,1,12.43,700,1,14.91,700,1
2025-07-17T15:31:00.054665340Z,2025-07-17T15:31:00.054830847Z,160,2,1108,C,A,0,14.81,100,0,165507,238444759,ARL,282776089,13.37,100,1,14.02,2,1,13.23,2,1,14.26,100,1,13.1,100,1,14.56,800,2,12.73,100,1,14.6,700,1,12.67,100,1,14.61,100,1,12.65,200,2,14.68,700,1,12.5,700,1,14.79,100,1,12.47,100,1,14.81,100,1,12.46,100,1,14.84,100,1,12.43,700,1,14.91,700,1
2025-07-17T15:31:00.054665340Z,2025-07-17T15:31:00.054830847Z,160,2,1108,A,A,0,14.96,100,130,165507,238444759,ARL,283596721,13.37,100,1,14.02,2,1,13.23,2,1,14.26,100,1,13.1,100,1,14.56,800,2,12.73,100,1,14.6,700,1,12.67,100,1,14.61,100,1,12.65,200,2,14.68,700,1,12.5,700,1,14.79,100,1,12.47,100,1,14.81,100,1,12.46,100,1,14.84,100,1,12.43,700,1,14.91,700,1
2025-07-17T15:31:00.071243665Z,2025-07-17T15:31:00.071409275Z,160,2,1108,C,A,0,14.81,100,0,165610,238444961,ARL,282776029,13.37,100,1,14.02,2,1,13.23,2,1,14.26,100,1,13.1,100,1,14.56,800,2,12.73,100,1,14.6,700,1,12.67,100,1,14.61,100,1,12.65,200,2,14.68,700,1,12.5,700,1,14.79,100,1,12.47,100,1,14.84,100,1,12.46,100,1,14.91,700,1,12.43,700,1,14.96,100,1
2025-07-17T15:31:00.071243665Z,2025-07-17T15:31:00.071409275Z,160,2,1108,A,A,0,14.96,100,130,165610,238444961,ARL,283596945,13.37,100,1,14.02,2,1,13.23,2,1,14.26,100,1,13.1,100,1,14.56,800,2,12.73,100,1,14.6,700,1,12.67,100,1,14.61,100,1,12.65,200,2,14.68,700,1,12.5,700,1,14.79,100,1,12.47,100,1,14.84,100,1,12.46,100,1,14.91,700,1,12.43,700,1,14.96,200,2
2025-07-17T15:31:00.243203860Z,2025-07-17T15:31:00.243369582Z,160,2,1108,C,A,0,15.92,100,0,165722,238447595,ARL,282776033,13.37,100,1,14.02,2,1,13.23,2,1,14.26,100,1,13.1,100,1,14.56,800,2,12.73,100,1,14.6,700,1,12.67,100,1,14.61,100,1,12.65,200,2,14.68,700,1,12.5,700,1,14.79,100,1,12.47,100,1,14.84,100,1,12.46,100,1,14.91,700,1,12.43,700,1,14.96,200,2
2025-07-17T15:31:00.243203860Z,2025-07-17T15:31:00.243369582Z,160,2,1108,A,A,0,16.08,100,130,165722,238447595,ARL,283599609,13.37,100,1,14.02,2,1,13.23,2,1,14.26,100,1,13.1,100,1,14.56,800,2,12.73,100,1,14.6,700,1,12.67,100,1,14.61,100,1,12.65,200,2,14.68,700,1,12.5,700,1,14.79,100,1,12.47,100,1,14.84,100,1,12.46,100,1,14.91,700,1,12.43,700,1,14.96,200,2
2025-07-17T15:31:00.347663441Z,2025-07-17T15:31:00.347828545Z,160,2,1108,A,A,0,14.03,100,130,165104,238450791,ARL,283604173,13.37,100,1,14.02,2,1,13.23,2,1,14.03,100,1,13.1,100,1,14.26,100,1,12.73,100,1,14.56,800,2,12.67,100,1,14.6,700,1,12.65,200,2,14.61,100,1,12.5,700,1,14.68,700,1,12.47,100,1,14.79,100,1,12.46,100,1,14.84,100,1,12.43,700,1,14.91,700,1
2025-07-17T15:31:04.014425425Z,2025-07-17T15:31:04.014590575Z,160,2,1108,A,A,0,14,100,130,165150,238529875,ARL,283694233,13.37,100,1,14,100,1,13.23,2,1,14.02,2,1,13.1,100,1,14.03,100,1,12.73,100,1,14.26,100,1,12.67,100,1,14.56,800,2,12.65,200,2,14.6,700,1,12.5,700,1,14.61,100,1,12.47,100,1,14.68,700,1,12.46,100,1,14.79,100,1,12.43,700,1,14.84,100,1
2025-07-17T15:31:04.124411850Z,2025-07-17T15:31:04.124577845Z,160,2,1108,C,A,0,14.03,100,0,165995,238531822,ARL,283604173,13.37,100,1,14,100,1,13.23,2,1,14.02,2,1,13.1,100,1,14.26,100,1,12.73,100,1,14.56,800,2,12.67,100,1,14.6,700,1,12.65,200,2,14.61,100,1,12.5,700,1,14.68,700,1,12.47,100,1,14.79,100,1,12.46,100,1,14.84,100,1,12.43,700,1,14.91,700,1
2025-07-17T15:31:04.124411850Z,2025-07-17T15:31:04.124577845Z,160,2,1108,A,A,0,14.01,100,130,165995,238531822,ARL,283695933,13.37,100,1,14,100,1,13.23,2,1,14.01,100,1,13.1,100,1,14.02,2,1,12.73,100,1,14.26,100,1,12.67,100,1,14.56,800,2,12.65,200,2,14.6,700,1,12.5,700,1,14.61,100,1,12.47,100,1,14.68,700,1,12.46,100,1,14.79,100,1,12.43,700,1,14.84,100,1
2025-07-17T15:32:28.644335983Z,2025-07-17T15:32:28.644506279Z,160,2,1108,A,B,0,13.55,10,128,170296,239938946,ARL,285545121,13.55,10,1,14,100,1,13.37,100,1,14.01,100,1,13.23,2,1,14.02,2,1,13.1,100,1,14.26,100,1,12.73,100,1,14.56,800,2,12.67,100,1,14.6,700,1,12.65,200,2,14.61,100,1,12.5,700,1,14.68,700,1,12.47,100,1,14.79,100,1,12.46,100,1,14.84,100,1
2025-07-17T15:32:28.653073176Z,2025-07-17T15:32:28.653238729Z,160,2,1108,C,B,0,13.37,100,0,165553,239940048,ARL,215999737,13.55,10,1,14,100,1,13.23,2,1,14.01,100,1,13.1,100,1,14.02,2,1,12.73,100,1,14.26,100,1,12.67,100,1,14.56,800,2,12.65,200,2,14.6,700,1,12.5,700,1,14.61,100,1,12.47,100,1,14.68,700,1,12.46,100,1,14.79,100,1,12.43,700,1,14.84,100,1
2025-07-17T15:32:28.653073176Z,2025-07-17T15:32:28.653238729Z,160,2,1108,A,B,0,13.54,100,130,165553,239940048,ARL,285545885,13.55,10,1,14,100,1,13.54,100,1,14.01,100,1,13.23,2,1,14.02,2,1,13.1,100,1,14.26,100,1,12.73,100,1,14.56,800,2,12.67,100,1,14.6,700,1,12.65,200,2,14.61,100,1,12.5,700,1,14.68,700,1,12.47,100,1,14.79,100,1,12.46,100,1,14.84,100,1
2025-07-17T15:32:28.653812889Z,2025-07-17T15:32:28.653978501Z,160,2,1108,C,B,0,12.33,100,0,165612,239940096,ARL,215999753,13.55,10,1,14,100,1,13.54,100,1,14.01,100,1,13.23,2,1,14.02,2,1,13.1,100,1,14.26,100,1,12.73,100,1,14.56,800,2,12.67,100,1,14.6,700,1,12.65,200,2,14.61,100,1,12.5,700,1,14.68,700,1,12.47,100,1,14.79,100,1,12.46,100,1,14.84,100,1
2025-07-17T15:32:28.653812889Z,2025-07-17T15:32:28.653978501Z,160,2,1108,A,B,0,12.49,100,130,165612,239940096,ARL,285545945,13.55,10,1,14,100,1,13.54,100,1,14.01,100,1,13.23,2,1,14.02,2,1,13.1,100,1,14.26,100,1,12.73,100,1,14.56,800,2,12.67,100,1,14.6,700,1,12.65,200,2,14.61,100,1,12.5,700,1,14.68,700,1,12.49,100,1,14.79,100,1,12.47,100,1,14.84,100,1
2025-07-17T15:32:28.653815154Z,2025-07-17T15:32:28.653980648Z,160,2,1108,C,B,0,12.67,100,130,165494,239940097,ARL,43663229,13.55,10,1,14,100,1,13.54,100,1,14.01,100,1,13.23,2,1,14.02,2,1,13.1,100,1,14.26,100,1,12.73,100,1,14.56,800,2,12.65,200,2,14.6,700,1,12.5,700,1,14.61,100,1,12.49,100,1,14.68,700,1,12.47,100,1,14.79,100,1,12.46,100,1,14.84,100,1
2025-07-17T15:32:28.654171723Z,2025-07-17T15:32:28.654336987Z,160,2,1108,A,B,0,12.94,100,130,165264,239940109,ARL,285545953,13.55,10,1,14,100,1,13.54,100,1,14.01,100,1,13.23,2,1,14.02,2,1,13.1,100,1,14.26,100,1,12.94,100,1,14.56,800,2,12.73,100,1,14.6,700,1,12.65,200,2,14.61,100,1,12.5,700,1,14.68,700,1,12.49,100,1,14.79,100,1,12.47,100,1,14.84,100,1
2025-07-17T15:32:28.656908386Z,2025-07-17T15:32:28.657073743Z,160,2,1108,C,B,0,12.47,100,130,165357,239940358,ARL,43554133,13.55,10,1,14,100,1,13.54,100,1,14.01,100,1,13.23,2,1,14.02,2,1,13.1,100,1,14.26,100,1,12.94,100,1,14.56,800,2,12.73,100,1,14.6,700,1,12.65,200,2,14.61,100,1,12.5,700,1,14.68,700,1,12.49,100,1,14.79,100,1,12.46,100,1,14.84,100,1
2025-07-17T15:32:28.657008222Z,2025-07-17T15:32:28.657173856Z,160,2,1108,A,B,0,12.73,100,130,165634,239940359,ARL,285546061,13.55,10,1,14,100,1,13.54,100,1,14.01,100,1,13.23,2,1,14.02,2,1,13.1,100,1,14.26,100,1,12.94,100,1,14.56,800,2,12.73,200,2,14.6,700,1,12.65,200,2,14.61,100,1,12.5,700,1,14.68,700,1,12.49,100,1,14.79,100,1,12.46,100,1,14.84,100,1
2025-07-17T15:32:28.666909194Z,2025-07-17T15:32:28.667074437Z,160,2,1108,C,B,0,13.1,100,130,165243,239940810,ARL,216001413,13.55,10,1,14,100,1,13.54,100,1,14.01,100,1,13.23,2,1,14.02,2,1,12.94,100,1,14.26,100,1,12.73,200,2,14.56,800,2,12.65,200,2,14.6,700,1,12.5,700,1,14.61,100,1,12.49,100,1,14.68,700,1,12.46,100,1,14.79,100,1,12.43,700,1,14.84,100,1
2025-07-17T15:32:28.666961018Z,2025-07-17T15:32:28.667126637Z,160,2,1108,A,B,0,13.27,100,130,165619,239940813,ARL,285546673,13.55,10,1,14,100,1,13.54,100,1,14.01,100,1,13.27,100,1,14.02,2,1,13.23,2,1,14.26,100,1,12.94,100,1,14.56,800,2,12.73,200,2,14.6,700,1,12.65,200,2,14.61,100,1,12.5,700,1,14.68,700,1,12.49,100,1,14.79,100,1,12.46,100,1,14.84,100,1
2025-07-17T15:32:28.674279259Z,2025-07-17T15:32:28.674444711Z,160,2,1108,C,B,0,12.33,100,0,165452,239941057,ARL,43755813,13.55,10,1,14,100,1,13.54,100,1,14.01,100,1,13.27,100,1,14.02,2,1,13.23,2,1,14.26,100,1,12.94,100,1,14.56,800,2,12.73,200,2,14.6,700,1,12.65,200,2,14.61,100,1,12.5,700,1,14.68,700,1,12.49,100,1,14.79,100,1,12.46,100,1,14.84,100,1
2025-07-17T15:32:28.674279259Z,2025-07-17T15:32:28.674444711Z,160,2,1108,A,B,0,12.59,100,130,165452,239941057,ARL,285546893,13.55,10,1,14,100,1,13.54,100,1,14.01,100,1,13.27,100,1,14.02,2,1,13.23,2,1,14.26,100,1,12.94,100,1,14.56,800,2,12.73,200,2,14.6,700,1,12.65,200,2,14.61,100,1,12.59,100,1,14.68,700,1,12.5,700,1,14.79,100,1,12.49,100,1,14.84,100,1
2025-07-17T15:32:28.691099298Z,2025-07-17T15:32:28.691264796Z,160,2,1108,C,B,0,9.67,100,0,165498,239941825,ARL,44082961,13.55,10,1,14,100,1,13.54,100,1,14.01,100,1,13.27,100,1,14.02,2,1,13.23,2,1,14.26,100,1,12.94,100,1,14.56,800,2,12.73,200,2,14.6,700,1,12.65,200,2,14.61,100,1,12.59,100,1,14.68,700,1,12.5,700,1,14.79,100,1,12.49,100,1,14.84,100,1
2025-07-17T15:32:28.691099298Z,2025-07-17T15:32:28.691264796Z,160,2,1108,A,B,0,9.88,100,130,165498,239941825,ARL,285548137,13.55,10,1,14,100,1,13.54,100,1,14.01,100,1,13.27,100,1,14.02,2,1,13.23,2,1,14.26,100,1,12.94,100,1,14.56,800,2,12.73,200,2,14.6,700,1,12.65,200,2,14.61,100,1,12.59,100,1,14.68,700,1,12.5,700,1,14.79,100,1,12.49,100,1,14.84,100,1
2025-07-17T15:32:28.711329066Z,2025-07-17T15:32:28.711494526Z,160,2,1108,C,B,0,11.27,100,0,165460,239942732,ARL,43826785,13.55,10,1,14,100,1,13.54,100,1,14.01,100,1,13.27,100,1,14.02,2,1,13.23,2,1,14.26,100,1,12.94,100,1,14.56,800,2,12.73,200,2,14.6,700,1,12.65,200,2,14.61,100,1,12.59,100,1,14.68,700,1,12.5,700,1,14.79,100,1,12.49,100,1,14.84,100,1
2025-07-17T15:32:28.711329066Z,2025-07-17T15:32:28.711494526Z,160,2,1108,A,B,0,11.5,100,130,165460,239942732,ARL,285549537,13.55,10,1,14,100,1,13.54,100,1,14.01,100,1,13.27,100,1,14.02,2,1,13.23,2,1,14.26,100,1,12.94,100,1,14.56,800,2,12.73,200,2,14.6,700,1,12.65,200,2,14.61,100,1,12.59,100,1,14.68,700,1,12.5,700,1,14.79,100,1,12.49,100,1,14.84,100,1
2025-07-17T15:32:28.771830554Z,2025-07-17T15:32:28.771995987Z,160,2,1108,C,B,0,13.55,10,128,165433,239945992,ARL,285545121,13.54,100,1,14,100,1,13.27,100,1,14.01,100,1,13.23,2,1,14.02,2,1,12.94,100,1,14.26,100,1,12.73,200,2,14.56,800,2,12.65,200,2,14.6,700,1,12.59,100,1,14.61,100,1,12.5,700,1,14.68,700,1,12.49,100,1,14.79,100,1,12.46,100,1,14.84,100,1
2025-07-17T15:32:28.806765209Z,2025-07-17T15:32:28.806930722Z,160,2,1108,C,B,0,12.33,100,0,165513,239948319,ARL,44088633,13.54,100,1,14,100,1,13.27,100,1,14.01,100,1,13.23,2,1,14.02,2,1,12.94,100,1,14.26,100,1,12.73,200,2,14.56,800,2,12.65,200,2,14.6,700,1,12.59,100,1,14.61,100,1,12.5,700,1,14.68,700,1,12.49,100,1,14.79,100,1,12.46,100,1,14.84,100,1
2025-07-17T15:32:28.806765209Z,2025-07-17T15:32:28.806930722Z,160,2,1108,A,B,0,12.59,100,130,165513,239948319,ARL,285553901,13.54,100,1,14,100,1,13.27,100,1,14.01,100,1,13.23,2,1,14.02,2,1,12.94,100,1,14.26,100,1,12.73,200,2,14.56,800,2,12.65,200,2,14.6,700,1,12.59,200,2,14.61,100,1,12.5,700,1,14.68,700,1,12.49,100,1,14.79,100,1,12.46,100,1,14.84,100,1
2025-07-17T15:32:28.850122877Z,2025-07-17T15:32:28.850288215Z,160,2,1108,A,A,0,13.98,100,130,165338,239950805,ARL,285556869,13.54,100,1,13.98,100,1,13.27,100,1,14,100,1,13.23,2,1,14.01,100,1,12.94,100,1,14.02,2,1,12.73,200,2,14.26,100,1,12.65,200,2,14.56,800,2,12.59,200,2,14.6,700,1,12.5,700,1,14.61,100,1,12.49,100,1,14.68,700,1,12.46,100,1,14.79,100,1
2025-07-17T15:32:28.856973845Z,2025-07-17T15:32:28.857140107Z,160,2,1108,C,A,0,14,100,130,166262,239951361,ARL,283694233,13.54,100,1,13.98,100,1,13.27,100,1,14.01,100,1,13.23,2,1,14.02,2,1,12.94,100,1,14.26,100,1,12.73,200,2,14.56,800,2,12.65,200,2,14.6,700,1,12.59,200,2,14.61,100,1,12.5,700,1,14.68,700,1,12.49,100,1,14.79,100,1,12.46,100,1,14.84,100,1
2025-07-17T15:32:29.573469021Z,2025-07-17T15:32:29.573634202Z,160,2,1108,C,B,0,13.54,100,130,165181,239975997,ARL,285545885,13.27,100,1,13.98,100,1,13.23,2,1,14.01,100,1,12.94,100,1,14.02,2,1,12.73,200,2,14.26,100,1,12.65,200,2,14.56,800,2,12.59,200,2,14.6,700,1,12.5,700,1,14.61,100,1,12.49,100,1,14.68,700,1,12.46,100,1,14.79,100,1,12.43,700,1,14.84,100,1
2025-07-17T15:32:29.574202467Z,2025-07-17T15:32:29.574368326Z,160,2,1108,C,B,0,12.49,100,0,165859,239976004,ARL,285545945,13.27,100,1,13.98,100,1,13.23,2,1,14.01,100,1,12.94,100,1,14.02,2,1,12.73,200,2,14.26,100,1,12.65,200,2,14.56,800,2,12.59,200,2,14.6,700,1,12.5,700,1,14.61,100,1,12.46,100,1,14.68,700,1,12.43,700,1,14.79,100,1,12.42,700,1,14.84,100,1
2025-07-17T15:32:29.574202467Z,2025-07-17T15:32:29.574368326Z,160,2,1108,A,B,0,12.27,100,130,165859,239976004,ARL,285586089,13.27,100,1,13.98,100,1,13.23,2,1,14.01,100,1,12.94,100,1,14.02,2,1,12.73,200,2,14.26,100,1,12.65,200,2,14.56,800,2,12.59,200,2,14.6,700,1,12.5,700,1,14.61,100,1,12.46,100,1,14.68,700,1,12.43,700,1,14.79,100,1,12.42,700,1,14.84,100,1
2025-07-17T15:32:29.574206685Z,2025-07-17T15:32:29.574371866Z,160,2,1108,C,B,0,12.94,100,130,165181,239976005,ARL,285545953,13.27,100,1,13.98,100,1,13.23,2,1,14.01,100,1,12.73,200,2,14.02,2,1,12.65,200,2,14.26,100,1,12.59,200,2,14.56,800,2,12.5,700,1,14.6,700,1,12.46,100,1,14.61,100,1,12.43,700,1,14.68,700,1,12.42,700,1,14.79,100,1,12.37,700,1,14.84,100,1
2025-07-17T15:32:29.574556760Z,2025-07-17T15:32:29.574722141Z,160,2,1108,A,B,0,12.71,100,130,165381,239976069,ARL,285586093,13.27,100,1,13.98,100,1,13.23,2,1,14.01,100,1,12.73,200,2,14.02,2,1,12.71,100,1,14.26,100,1,12.65,200,2,14.56,800,2,12.59,200,2,14.6,700,1,12.5,700,1,14.61,100,1,12.46,100,1,14.68,700,1,12.43,700,1,14.79,100,1,12.42,700,1,14.84,100,1
2025-07-17T15:32:29.574968914Z,2025-07-17T15:32:29.575134655Z,160,2,1108,C,B,0,12.59,100,0,165741,239976143,ARL,285546893,13.27,100,1,13.98,100,1,13.23,2,1,14.01,100,1,12.73,200,2,14.02,2,1,12.71,100,1,14.26,100,1,12.65,200,2,14.56,800,2,12.59,100,1,14.6,700,1,12.5,700,1,14.61,100,1,12.46,100,1,14.68,700,1,12.43,700,1,14.79,100,1,12.42,700,1,14.84,100,1
2025-07-17T15:32:29.574968914Z,2025-07-17T15:32:29.575134655Z,160,2,1108,A,B,0,12.34,100,130,165741,239976143,ARL,285586113,13.27,100,1,13.98,100,1,13.23,2,1,14.01,100,1,12.73,200,2,14.02,2,1,12.71,100,1,14.26,100,1,12.65,200,2,14.56,800,2,12.59,100,1,14.6,700,1,12.5,700,1,14.61,100,1,12.46,100,1,14.68,700,1,12.43,700,1,14.79,100,1,12.42,700,1,14.84,100,1
2025-07-17T15:32:29.575384940Z,2025-07-17T15:32:29.575550333Z,160,2,1108,C,B,0,11.5,100,0,165393,239976173,ARL,285549537,13.27,100,1,13.98,100,1,13.23,2,1,14.01,100,1,12.73,200,2,14.02,2,1,12.71,100,1,14.26,100,1,12.65,200,2,14.56,800,2,12.59,100,1,14.6,700,1,12.5,700,1,14.61,100,1,12.46,100,1,14.68,700,1,12.43,700,1,14.79,100,1,12.42,700,1,14.84,100,1
2025-07-17T15:32:29.575384940Z,2025-07-17T15:32:29.575550333Z,160,2,1108,A,B,0,11.27,100,130,165393,239976173,ARL,285586145,13.27,100,1,13.98,100,1,13.23,2,1,14.01,100,1,12.73,200,2,14.02,2,1,12.71,100,1,14.26,100,1,12.65,200,2,14.56,800,2,12.59,100,1,14.6,700,1,12.5,700,1,14.61,100,1,12.46,100,1,14.68,700,1,12.43,700,1,14.79,100,1,12.42,700,1,14.84,100,1
2025-07-17T15:32:29.575655631Z,2025-07-17T15:32:29.575821091Z,160,2,1108,C,B,0,9.88,100,0,165460,239976183,ARL,285548137,13.27,100,1,13.98,100,1,13.23,2,1,14.01,100,1,12.73,200,2,14.02,2,1,12.71,100,1,14.26,100,1,12.65,200,2,14.56,800,2,12.59,100,1,14.6,700,1,12.5,700,1,14.61,100,1,12.46,100,1,14.68,700,1,12.43,700,1,14.79,100,1,12.42,700,1,14.84,100,1
2025-07-17T15:32:29.575655631Z,2025-07-17T15:32:29.575821091Z,160,2,1108,A,B,0,9.68,100,130,165460,239976183,ARL,285586157,13.27,100,1,13.98,100,1,13.23,2,1,14.01,100,1,12.73,200,2,14.02,2,1,12.71,100,1,14.26,100,1,12.65,200,2,14.56,800,2,12.59,100,1,14.6,700,1,12.5,700,1,14.61,100,1,12.46,100,1,14.68,700,1,12.43,700,1,14.79,100,1,12.42,700,1,14.84,100,1
2025-07-17T15:32:29.578151593Z,2025-07-17T15:32:29.578317238Z,160,2,1108,C,B,0,12.59,100,0,165645,239976225,ARL,285553901,13.27,100,1,13.98,100,1,13.23,2,1,14.01,100,1,12.73,200,2,14.02,2,1,12.71,100,1,14.26,100,1,12.65,200,2,14.56,800,2,12.5,700,1,14.6,700,1,12.46,100,1,14.61,100,1,12.43,700,1,14.68,700,1,12.42,700,1,14.79,100,1,12.37,700,1,14.84,100,1
2025-07-17T15:32:29.578151593Z,2025-07-17T15:32:29.578317238Z,160,2,1108,A,B,0,12.34,100,130,165645,239976225,ARL,285586189,13.27,100,1,13.98,100,1,13.23,2,1,14.01,100,1,12.73,200,2,14.02,2,1,12.71,100,1,14.26,100,1,12.65,200,2,14.56,800,2,12.5,700,1,14.6,700,1,12.46,100,1,14.61,100,1,12.43,700,1,14.68,700,1,12.42,700,1,14.79,100,1,12.37,700,1,14.84,100,1
2025-07-17T15:32:29.580767960Z,2025-07-17T15:32:29.580933155Z,160,2,1108,A,B,0,13.26,100,130,165195,239976262,ARL,285586221,13.27,100,1,13.98,100,1,13.26,100,1,14.01,100,1,13.23,2,1,14.02,2,1,12.73,200,2,14.26,100,1,12.71,100,1,14.56,800,2,12.65,200,2,14.6,700,1,12.5,700,1,14.61,100,1,12.46,100,1,14.68,700,1,12.43,700,1,14.79,100,1,12.42,700,1,14.84,100,1
2025-07-17T15:32:29.580786478Z,2025-07-17T15:32:29.580952045Z,160,2,1108,C,A,0,14.01,100,0,165567,239976263,ARL,283695933,13.27,100,1,13.98,100,1,13.26,100,1,14.02,2,1,13.23,2,1,14.26,100,1,12.73,200,2,14.56,800,2,12.71,100,1,14.6,700,1,12.65,200,2,14.61,100,1,12.5,700,1,14.68,700,1,12.46,100,1,14.79,100,1,12.43,700,1,14.84,100,1,12.42,700,1,14.91,700,1
2025-07-17T15:32:29.580786478Z,2025-07-17T15:32:29.580952045Z,160,2,1108,A,A,0,13.99,100,130,165567,239976263,ARL,285586225,13.27,100,1,13.98,100,1,13.26,100,1,13.99,100,1,13.23,2,1,14.02,2,1,12.73,200,2,14.26,100,1,12.71,100,1,14.56,800,2,12.65,200,2,14.6,700,1,12.5,700,1,14.61,100,1,12.46,100,1,14.68,700,1,12.43,700,1,14.79,100,1,12.42,700,1,14.84,100,1
2025-07-17T15:32:29.587027681Z,2025-07-17T15:32:29.587192852Z,160,2,1108,C,B,0,13.27,100,130,165171,239976327,ARL,285546673,13.26,100,1,13.98,100,1,13.23,2,1,13.99,100,1,12.73,200,2,14.02,2,1,12.71,100,1,14.26,100,1,12.65,200,2,14.56,800,2,12.5,700,1,14.6,700,1,12.46,100,1,14.61,100,1,12.43,700,1,14.68,700,1,12.42,700,1,14.79,100,1,12.37,700,1,14.84,100,1
2025-07-17T15:32:29.587081086Z,2025-07-17T15:32:29.587246470Z,160,2,1108,A,B,0,13.03,100,130,165384,239976336,ARL,285586293,13.26,100,1,13.98,100,1,13.23,2,1,13.99,100,1,13.03,100,1,14.02,2,1,12.73,200,2,14.26,100,1,12.71,100,1,14.56,800,2,12.65,200,2,14.6,700,1,12.5,700,1,14.61,100,1,12.46,100,1,14.68,700,1,12.43,700,1,14.79,100,1,12.42,700,1,14.84,100,1
2025-07-17T15:32:29.659513918Z,2025-07-17T15:32:29.659679280Z,160,2,1108,C,B,0,12.73,100,0,165362,239977574,ARL,285546061,13.26,100,1,13.98,100,1,13.23,2,1,13.99,100,1,13.03,100,1,14.02,2,1,12.73,100,1,14.26,100,1,12.71,100,1,14.56,800,2,12.65,200,2,14.6,700,1,12.5,700,1,14.61,100,1,12.46,100,1,14.68,700,1,12.43,700,1,14.79,100,1,12.42,700,1,14.84,100,1
2025-07-17T15:32:29.659513918Z,2025-07-17T15:32:29.659679280Z,160,2,1108,A,B,0,12.46,100,130,165362,239977574,ARL,285587281,13.26,100,1,13.98,100,1,13.23,2,1,13.99,100,1,13.03,100,1,14.02,2,1,12.73,100,1,14.26,100,1,12.71,100,1,14.56,800,2,12.65,200,2,14.6,700,1,12.5,700,1,14.61,100,1,12.46,200,2,14.68,700,1,12.43,700,1,14.79,100,1,12.42,700,1,14.84,100,1
2025-07-17T15:33:04.247990788Z,2025-07-17T15:33:04.248156868Z,160,2,1108,C,A,0,14.97,100,0,166080,240885845,ARL,283592993,13.26,100,1,13.98,100,1,13.23,2,1,13.99,100,1,13.03,100,1,14.02,2,1,12.73,100,1,14.26,100,1,12.71,100,1,14.56,800,2,12.65,200,2,14.6,700,1,12.5,700,1,14.61,100,1,12.46,200,2,14.68,700,1,12.43,700,1,14.79,100,1,12.42,700,1,14.84,100,1
2025-07-17T15:33:04.247990788Z,2025-07-17T15:33:04.248156868Z,160,2,1108,A,A,0,14.72,100,130,166080,240885845,ARL,286680573,13.26,100,1,13.98,100,1,13.23,2,1,13.99,100,1,13.03,100,1,14.02,2,1,12.73,100,1,14.26,100,1,12.71,100,1,14.56,800,2,12.65,200,2,14.6,700,1,12.5,700,1,14.61,100,1,12.46,200,2,14.68,700,1,12.43,700,1,14.72,100,1,12.42,700,1,14.79,100,1
2025-07-17T15:33:04.248023883Z,2025-07-17T15:33:04.248189408Z,160,2,1108,C,A,0,14.97,100,0,165525,240885847,ARL,283593041,13.26,100,1,13.98,100,1,13.23,2,1,13.99,100,1,13.03,100,1,14.02,2,1,12.73,100,1,14.26,100,1,12.71,100,1,14.56,800,2,12.65,200,2,14.6,700,1,12.5,700,1,14.61,100,1,12.46,200,2,14.68,700,1,12.43,700,1,14.72,100,1,12.42,700,1,14.79,100,1
2025-07-17T15:33:04.248023883Z,2025-07-17T15:33:04.248189408Z,160,2,1108,A,A,0,14.72,100,130,165525,240885847,ARL,286680577,13.26,100,1,13.98,100,1,13.23,2,1,13.99,100,1,13.03,100,1,14.02,2,1,12.73,100,1,14.26,100,1,12.71,100,1,14.56,800,2,12.65,200,2,14.6,700,1,12.5,700,1,14.61,100,1,12.46,200,2,14.68,700,1,12.43,700,1,14.72,200,2,12.42,700,1,14.79,100,1
2025-07-17T15:33:04.255546094Z,2025-07-17T15:33:04.255712050Z,160,2,1108,A,A,0,13.84,100,130,165956,240886132,ARL,286680685,13.26,100,1,13.84,100,1,13.23,2,1,13.98,100,1,13.03,100,1,13.99,100,1,12.73,100,1,14.02,2,1,12.71,100,1,14.26,100,1,12.65,200,2,14.56,800,2,12.5,700,1,14.6,700,1,12.46,200,2,14.61,100,1,12.43,700,1,14.68,700,1,12.42,700,1,14.72,200,2
2025-07-17T15:33:04.255612126Z,2025-07-17T15:33:04.255777981Z,160,2,1108,C,B,0,12.27,100,0,165855,240886133,ARL,285586089,13.26,100,1,13.84,100,1,13.23,2,1,13.98,100,1,13.03,100,1,13.99,100,1,12.73,100,1,14.02,2,1,12.71,100,1,14.26,100,1,12.65,200,2,14.56,800,2,12.5,700,1,14.6,700,1,12.46,200,2,14.61,100,1,12.43,700,1,14.68,700,1,12.42,700,1,14.72,200,2
2025-07-17T15:33:04.255612126Z,2025-07-17T15:33:04.255777981Z,160,2,1108,A,B,0,12.23,100,130,165855,240886133,ARL,286680693,13.26,100,1,13.84,100,1,13.23,2,1,13.98,100,1,13.03,100,1,13.99,100,1,12.73,100,1,14.02,2,1,12.71,100,1,14.26,100,1,12.65,200,2,14.56,800,2,12.5,700,1,14.6,700,1,12.46,200,2,14.61,100,1,12.43,700,1,14.68,700,1,12.42,700,1,14.72,200,2
2025-07-17T15:33:04.256272676Z,2025-07-17T15:33:04.256438228Z,160,2,1108,C,A,0,15.06,100,0,165552,240886147,ARL,283596673,13.26,100,1,13.84,100,1,13.23,2,1,13.98,100,1,13.03,100,1,13.99,100,1,12.73,100,1,14.02,2,1,12.71,100,1,14.26,100,1,12.65,200,2,14.56,800,2,12.5,700,1,14.6,700,1,12.46,200,2,14.61,100,1,12.43,700,1,14.68,700,1,12.42,700,1,14.72,200,2
2025-07-17T15:33:04.256272676Z,2025-07-17T15:33:04.256438228Z,160,2,1108,A,A,0,14.91,100,130,165552,240886147,ARL,286680721,13.26,100,1,13.84,100,1,13.23,2,1,13.98,100,1,13.03,100,1,13.99,100,1,12.73,100,1,14.02,2,1,12.71,100,1,14.26,100,1,12.65,200,2,14.56,800,2,12.5,700,1,14.6,700,1,12.46,200,2,14.61,100,1,12.43,700,1,14.68,700,1,12.42,700,1,14.72,200,2
2025-07-17T15:33:04.257914956Z,2025-07-17T15:33:04.258080504Z,160,2,1108,C,A,0,14.96,100,0,165548,240886188,ARL,283596945,13.26,100,1,13.84,100,1,13.23,2,1,13.98,100,1,13.03,100,1,13.99,100,1,12.73,100,1,14.02,2,1,12.71,100,1,14.26,100,1,12.65,200,2,14.56,800,2,12.5,700,1,14.6,700,1,12.46,200,2,14.61,100,1,12.43,700,1,14.68,700,1,12.42,700,1,14.72,200,2
2025-07-17T15:33:04.257914956Z,2025-07-17T15:33:04.258080504Z,160,2,1108,A,A,0,14.81,100,130,165548,240886188,ARL,286680741,13.26,100,1,13.84,100,1,13.23,2,1,13.98,100,1,13.03,100,1,13.99,100,1,12.73,100,1,14.02,2,1,12.71,100,1,14.26,100,1,12.65,200,2,14.56,800,2,12.5,700,1,14.6,700,1,12.46,200,2,14.61,100,1,12.43,700,1,14.68,700,1,12.42,700,1,14.72,200,2
2025-07-17T15:33:04.261518776Z,2025-07-17T15:33:04.261684319Z,160,2,1108,C,A,0,14.79,100,0,165543,240886271,ARL,283593313,13.26,100,1,13.84,100,1,13.23,2,1,13.98,100,1,13.03,100,1,13.99,100,1,12.73,100,1,14.02,2,1,12.71,100,1,14.26,100,1,12.65,200,2,14.56,800,2,12.5,700,1,14.6,700,1,12.46,200,2,14.61,100,1,12.43,700,1,14.68,700,1,12.42,700,1,14.72,200,2
2025-07-17T15:33:04.261518776Z,2025-07-17T15:33:04.261684319Z,160,2,1108,A,A,0,14.65,100,130,165543,240886271,ARL,286680905,13.26,100,1,13.84,100,1,13.23,2,1,13.98,100,1,13.03,100,1,13.99,100,1,12.73,100,1,14.02,2,1,12.71,100,1,14.26,100,1,12.65,200,2,14.56,800,2,12.5,700,1,14.6,700,1,12.46,200,2,14.61,100,1,12.43,700,1,14.65,100,1,12.42,700,1,14.68,700,1
2025-07-17T15:33:04.262845834Z,2025-07-17T15:33:04.263011314Z,160,2,1108,C,A,0,14.26,100,130,165480,240886294,ARL,283595181,13.26,100,1,13.84,100,1,13.23,2,1,13.98,100,1,13.03,100,1,13.99,100,1,12.73,100,1,14.02,2,1,12.71,100,1,14.56,800,2,12.65,200,2,14.6,700,1,12.5,700,1,14.61,100,1,12.46,200,2,14.65,100,1,12.43,700,1,14.68,700,1,12.42,700,1,14.72,200,2
2025-07-17T15:33:04.262887184Z,2025-07-17T15:33:04.263052660Z,160,2,1108,C,A,0,13.98,100,130,165476,240886296,ARL,285556869,13.26,100,1,13.84,100,1,13.23,2,1,13.99,100,1,13.03,100,1,14.02,2,1,12.73,100,1,14.56,800,2,12.71,100,1,14.6,700,1,12.65,200,2,14.61,100,1,12.5,700,1,14.65,100,1,12.46,200,2,14.68,700,1,12.43,700,1,14.72,200,2,12.42,700,1,14.81,100,1
2025-07-17T15:33:04.262899981Z,2025-07-17T15:33:04.263065252Z,160,2,1108,A,A,0,14.12,100,130,165271,240886297,ARL,286680917,13.26,100,1,13.84,100,1,13.23,2,1,13.99,100,1,13.03,100,1,14.02,2,1,12.73,100,1,14.12,100,1,12.71,100,1,14.56,800,2,12.65,200,2,14.6,700,1,12.5,700,1,14.61,100,1,12.46,200,2,14.65,100,1,12.43,700,1,14.68,700,1,12.42,700,1,14.72,200,2
2025-07-17T15:33:04.271046430Z,2025-07-17T15:33:04.271212113Z,160,2,1108,C,A,0,17.76,100,0,165683,240886583,ARL,283594173,13.26,100,1,13.84,100,1,13.23,2,1,13.99,100,1,13.03,100,1,14.02,2,1,12.73,100,1,14.12,100,1,12.71,100,1,14.56,800,2,12.65,200,2,14.6,700,1,12.5,700,1,14.61,100,1,12.46,200,2,14.65,100,1,12.43,700,1,14.68,700,1,12.42,700,1,14.72,200,2
2025-07-17T15:33:04.271046430Z,2025-07-17T15:33:04.271212113Z,160,2,1108,A,A,0,17.58,100,130,165683,240886583,ARL,286681057,13.26,100,1,13.84,100,1,13.23,2,1,13.99,100,1,13.03,100,1,14.02,2,1,12.73,100,1,14.12,100,1,12.71,100,1,14.56,800,2,12.65,200,2,14.6,700,1,12.5,700,1,14.61,100,1,12.46,200,2,14.65,100,1,12.43,700,1,14.68,700,1,12.42,700,1,14.72,200,2
2025-07-17T15:33:04.277715123Z,2025-07-17T15:33:04.277880725Z,160,2,1108,C,A,0,16.08,100,0,165602,240886720,ARL,283599609,13.26,100,1,13.84,100,1,13.23,2,1,13.99,100,1,13.03,100,1,14.02,2,1,12.73,100,1,14.12,100,1,12.71,100,1,14.56,800,2,12.65,200,2,14.6,700,1,12.5,700,1,14.61,100,1,12.46,200,2,14.65,100,1,12.43,700,1,14.68,700,1,12.42,700,1,14.72,200,2
2025-07-17T15:33:04.277715123Z,2025-07-17T15:33:04.277880725Z,160,2,1108,A,A,0,15.92,100,130,165602,240886720,ARL,286681229,13.26,100,1,13.84,100,1,13.23,2,1,13.99,100,1,13.03,100,1,14.02,2,1,12.73,100,1,14.12,100,1,12.71,100,1,14.56,800,2,12.65,200,2,14.6,700,1,12.5,700,1,14.61,100,1,12.46,200,2,14.65,100,1,12.43,700,1,14.68,700,1,12.42,700,1,14.72,200,2
2025-07-17T15:33:04.418674487Z,2025-07-17T15:33:04.418840148Z,160,2,1108,C,A,0,14.96,100,0,165661,240888774,ARL,283596721,13.26,100,1,13.84,100,1,13.23,2,1,13.99,100,1,13.03,100,1,14.02,2,1,12.73,100,1,14.12,100,1,12.71,100,1,14.56,800,2,12.65,200,2,14.6,700,1,12.5,700,1,14.61,100,1,12.46,200,2,14.65,100,1,12.43,700,1,14.68,700,1,12.42,700,1,14.72,200,2
2025-07-17T15:33:04.418674487Z,2025-07-17T15:33:04.418840148Z,160,2,1108,A,A,0,14.81,100,130,165661,240888774,ARL,286684005,13.26,100,1,13.84,100,1,13.23,2,1,13.99,100,1,13.03,100,1,14.02,2,1,12.73,100,1,14.12,100,1,12.71,100,1,14.56,800,2,12.65,200,2,14.6,700,1,12.5,700,1,14.61,100,1,12.46,200,2,14.65,100,1,12.43,700,1,14.68,700,1,12.42,700,1,14.72,200,2
2025-07-17T15:33:05.330688486Z,2025-07-17T15:33:05.330854217Z,160,2,1108,C,A,0,13.99,100,0,165731,240911093,ARL,285586225,13.26,100,1,13.84,100,1,13.23,2,1,14.02,2,1,13.03,100,1,14.12,100,1,12.73,100,1,14.56,800,2,12.71,100,1,14.6,700,1,12.65,200,2,14.61,100,1,12.5,700,1,14.65,100,1,12.46,200,2,14.68,700,1,12.43,700,1,14.72,200,2,12.42,700,1,14.81,200,2
2025-07-17T15:33:05.330688486Z,2025-07-17T15:33:05.330854217Z,160,2,1108,A,A,0,13.85,100,130,165731,240911093,ARL,286704785,13.26,100,1,13.84,100,1,13.23,2,1,13.85,100,1,13.03,100,1,14.02,2,1,12.73,100,1,14.12,100,1,12.71,100,1,14.56,800,2,12.65,200,2,14.6,700,1,12.5,700,1,14.61,100,1,12.46,200,2,14.65,100,1,12.43,700,1,14.68,700,1,12.42,700,1,14.72,200,2
2025-07-17T15:33:06.455814002Z,2025-07-17T15:33:06.455979270Z,160,2,1108,C,A,0,13.84,100,130,165268,240936407,ARL,286680685,13.26,100,1,13.85,100,1,13.23,2,1,14.02,2,1,13.03,100,1,14.12,100,1,12.73,100,1,14.56,800,2,12.71,100,1,14.6,700,1,12.65,200,2,14.61,100,1,12.5,700,1,14.65,100,1,12.46,200,2,14.68,700,1,12.43,700,1,14.72,200,2,12.42,700,1,14.81,200,2
2025-07-17T15:33:10.467840054Z,2025-07-17T15:33:10.468005342Z,160,2,1108,A,A,0,13.87,100,130,165288,241000095,ARL,286828253,13.26,100,1,13.85,100,1,13.23,2,1,13.87,100,1,13.03,100,1,14.02,2,1,12.73,100,1,14.12,100,1,12.71,100,1,14.56,800,2,12.65,200,2,14.6,700,1,12.5,700,1,14.61,100,1,12.46,200,2,14.65,100,1,12.43,700,1,14.68,700,1,12.42,700,1,14.72,200,2
2025-07-17T15:33:40.986420127Z,2025-07-17T15:33:40.986585803Z,160,2,1108,C,A,0,14.02,2,0,165676,241593788,ARL,283348193,13.26,100,1,13.85,100,1,13.23,2,1,13.87,100,1,13.03,100,1,14.12,100,1,12.73,100,1,14.56,800,2,12.71,100,1,14.6,700,1,12.65,200,2,14.61,100,1,12.5,700,1,14.65,100,1,12.46,200,2,14.68,700,1,12.43,700,1,14.72,200,2,12.42,700,1,14.81,200,2
2025-07-17T15:33:40.986420127Z,2025-07-17T15:33:40.986585803Z,160,2,1108,A,A,0,13.95,2,130,165676,241593788,ARL,287540393,13.26,100,1,13.85,100,1,13.23,2,1,13.87,100,1,13.03,100,1,13.95,2,1,12.73,100,1,14.12,100,1,12.71,100,1,14.56,800,2,12.65,200,2,14.6,700,1,12.5,700,1,14.61,100,1,12.46,200,2,14.65,100,1,12.43,700,1,14.68,700,1,12.42,700,1,14.72,200,2
2025-07-17T15:33:41.766018916Z,2025-07-17T15:33:41.766184571Z,160,2,1108,A,A,0,13.82,10,130,165655,241612289,ARL,287560109,13.26,100,1,13.82,10,1,13.23,2,1,13.85,100,1,13.03,100,1,13.87,100,1,12.73,100,1,13.95,2,1,12.71,100,1,14.12,100,1,12.65,200,2,14.56,800,2,12.5,700,1,14.6,700,1,12.46,200,2,14.61,100,1,12.43,700,1,14.65,100,1,12.42,700,1,14.68,700,1
2025-07-17T15:33:41.766100204Z,2025-07-17T15:33:41.766265703Z,160,2,1108,C,A,0,13.85,100,0,165499,241612294,ARL,286704785,13.26,100,1,13.82,10,1,13.23,2,1,13.87,100,1,13.03,100,1,13.95,2,1,12.73,100,1,14.12,100,1,12.71,100,1,14.56,800,2,12.65,200,2,14.6,700,1,12.5,700,1,14.61,100,1,12.46,200,2,14.65,100,1,12.43,700,1,14.68,700,1,12.42,700,1,14.72,200,2
2025-07-17T15:33:41.766100204Z,2025-07-17T15:33:41.766265703Z,160,2,1108,A,A,0,13.83,100,130,165499,241612294,ARL,287560121,13.26,100,1,13.82,10,1,13.23,2,1,13.83,100,1,13.03,100,1,13.87,100,1,12.73,100,1,13.95,2,1,12.71,100,1,14.12,100,1,12.65,200,2,14.56,800,2,12.5,700,1,14.6,700,1,12.46,200,2,14.61,100,1,12.43,700,1,14.65,100,1,12.42,700,1,14.68,700,1
2025-07-17T15:33:41.777239400Z,2025-07-17T15:33:41.777404666Z,160,2,1108,A,A,0,13.85,100,130,165266,241612426,ARL,287560333,13.26,100,1,13.82,10,1,13.23,2,1,13.83,100,1,13.03,100,1,13.85,100,1,12.73,100,1,13.87,100,1,12.71,100,1,13.95,2,1,12.65,200,2,14.12,100,1,12.5,700,1,14.56,800,2,12.46,200,2,14.6,700,1,12.43,700,1,14.61,100,1,12.42,700,1,14.65,100,1
2025-07-17T15:33:41.783955668Z,2025-07-17T15:33:41.784121031Z,160,2,1108,C,A,0,13.87,100,130,165363,241612450,ARL,286828253,13.26,100,1,13.82,10,1,13.23,2,1,13.83,100,1,13.03,100,1,13.85,100,1,12.73,100,1,13.95,2,1,12.71,100,1,14.12,100,1,12.65,200,2,14.56,800,2,12.5,700,1,14.6,700,1,12.46,200,2,14.61,100,1,12.43,700,1,14.65,100,1,12.42,700,1,14.68,700,1
2025-07-17T15:33:42.772976862Z,2025-07-17T15:33:42.773141775Z,160,2,1108,C,A,0,13.82,10,130,164913,241630390,ARL,287560109,13.26,100,1,13.83,100,1,13.23,2,1,13.85,100,1,13.03,100,1,13.95,2,1,12.73,100,1,14.12,100,1,12.71,100,1,14.56,800,2,12.65,200,2,14.6,700,1,12.5,700,1,14.61,100,1,12.46,200,2,14.65,100,1,12.43,700,1,14.68,700,1,12.42,700,1,14.72,200,2
2025-07-17T15:34:28.155608087Z,2025-07-17T15:34:28.155773560Z,160,2,1108,A,A,0,14.2,50,130,165473,242513312,ARL,288723725,13.26,100,1,13.83,100,1,13.23,2,1,13.85,100,1,13.03,100,1,13.95,2,1,12.73,100,1,14.12,100,1,12.71,100,1,14.2,50,1,12.65,200,2,14.56,800,2,12.5,700,1,14.6,700,1,12.46,200,2,14.61,100,1,12.43,700,1,14.65,100,1,12.42,700,1,14.68,700,1
2025-07-17T15:34:28.156649544Z,2025-07-17T15:34:28.156815057Z,160,2,1108,C,B,0,12.65,100,0,165513,242513329,ARL,236206261,13.26,100,1,13.83,100,1,13.23,2,1,13.85,100,1,13.03,100,1,13.95,2,1,12.73,100,1,14.12,100,1,12.71,100,1,14.2,50,1,12.65,100,1,14.56,800,2,12.5,700,1,14.6,700,1,12.46,200,2,14.61,100,1,12.43,700,1,14.65,100,1,12.42,700,1,14.68,700,1
2025-07-17T15:34:28.156649544Z,2025-07-17T15:34:28.156815057Z,160,2,1108,A,B,0,12.36,100,130,165513,242513329,ARL,288723813,13.26,100,1,13.83,100,1,13.23,2,1,13.85,100,1,13.03,100,1,13.95,2,1,12.73,100,1,14.12,100,1,12.71,100,1,14.2,50,1,12.65,100,1,14.56,800,2,12.5,700,1,14.6,700,1,12.46,200,2,14.61,100,1,12.43,700,1,14.65,100,1,12.42,700,1,14.68,700,1
2025-07-17T15:34:28.156719339Z,2025-07-17T15:34:28.156884900Z,160,2,1108,C,B,0,12.65,100,0,165561,242513330,ARL,236179089,13.26,100,1,13.83,100,1,13.23,2,1,13.85,100,1,13.03,100,1,13.95,2,1,12.73,100,1,14.12,100,1,12.71,100,1,14.2,50,1,12.5,700,1,14.56,800,2,12.46,200,2,14.6,700,1,12.43,700,1,14.61,100,1,12.42,700,1,14.65,100,1,12.37,700,1,14.68,700,1
2025-07-17T15:34:28.156719339Z,2025-07-17T15:34:28.156884900Z,160,2,1108,A,B,0,12.36,100,130,165561,242513330,ARL,288723817,13.26,100,1,13.83,100,1,13.23,2,1,13.85,100,1,13.03,100,1,13.95,2,1,12.73,100,1,14.12,100,1,12.71,100,1,14.2,50,1,12.5,700,1,14.56,800,2,12.46,200,2,14.6,700,1,12.43,700,1,14.61,100,1,12.42,700,1,14.65,100,1,12.37,700,1,14.68,700,1
2025-07-17T15:34:28.170575785Z,2025-07-17T15:34:28.170740864Z,160,2,1108,A,A,0,13.81,50,130,165079,242513651,ARL,288724173,13.26,100,1,13.81,50,1,13.23,2,1,13.83,100,1,13.03,100,1,13.85,100,1,12.73,100,1,13.95,2,1,12.71,100,1,14.12,100,1,12.5,700,1,14.2,50,1,12.46,200,2,14.56,800,2,12.43,700,1,14.6,700,1,12.42,700,1,14.61,100,1,12.37,700,1,14.65,100,1
2025-07-17T15:34:28.170626756Z,2025-07-17T15:34:28.170792211Z,160,2,1108,C,B,0,13.26,100,130,165455,242513653,ARL,285586221,13.23,2,1,13.81,50,1,13.03,100,1,13.83,100,1,12.73,100,1,13.85,100,1,12.71,100,1,13.95,2,1,12.5,700,1,14.12,100,1,12.46,200,2,14.2,50,1,12.43,700,1,14.56,800,2,12.42,700,1,14.6,700,1,12.37,700,1,14.61,100,1,12.36,200,2,14.65,100,1
2025-07-17T15:34:28.171272157Z,2025-07-17T15:34:28.171437442Z,160,2,1108,A,A,0,13.78,2,130,165285,242513665,ARL,288724201,13.23,2,1,13.78,2,1,13.03,100,1,13.81,50,1,12.73,100,1,13.83,100,1,12.71,100,1,13.85,100,1,12.5,700,1,13.95,2,1,12.46,200,2,14.12,100,1,12.43,700,1,14.2,50,1,12.42,700,1,14.56,800,2,12.37,700,1,14.6,700,1,12.36,200,2,14.61,100,1
2025-07-17T15:34:28.171892519Z,2025-07-17T15:34:28.172057926Z,160,2,1108,A,B,0,13.31,10,130,165407,242513691,ARL,288724225,13.31,10,1,13.78,2,1,13.23,2,1,13.81,50,1,13.03,100,1,13.83,100,1,12.73,100,1,13.85,100,1,12.71,100,1,13.95,2,1,12.5,700,1,14.12,100,1,12.46,200,2,14.2,50,1,12.43,700,1,14.56,800,2,12.42,700,1,14.6,700,1,12.37,700,1,14.61,100,1
2025-07-17T15:34:28.171893498Z,2025-07-17T15:34:28.172058708Z,160,2,1108,A,A,0,13.82,10,130,165210,242513692,ARL,288724229,13.31,10,1,13.78,2,1,13.23,2,1,13.81,50,1,13.03,100,1,13.82,10,1,12.73,100,1,13.83,100,1,12.71,100,1,13.85,100,1,12.5,700,1,13.95,2,1,12.46,200,2,14.12,100,1,12.43,700,1,14.2,50,1,12.42,700,1,14.56,800,2,12.37,700,1,14.6,700,1
2025-07-17T15:34:28.174846475Z,2025-07-17T15:34:28.175011712Z,160,2,1108,A,B,0,13.3,100,130,165237,242513742,ARL,288724429,13.31,10,1,13.78,2,1,13.3,100,1,13.81,50,1,13.23,2,1,13.82,10,1,13.03,100,1,13.83,100,1,12.73,100,1,13.85,100,1,12.71,100,1,13.95,2,1,12.5,700,1,14.12,100,1,12.46,200,2,14.2,50,1,12.43,700,1,14.56,800,2,12.42,700,1,14.6,700,1
2025-07-17T15:34:28.174864618Z,2025-07-17T15:34:28.175030125Z,160,2,1108,C,A,0,13.83,100,0,165507,242513743,ARL,287560121,13.31,10,1,13.78,2,1,13.3,100,1,13.81,50,1,13.23,2,1,13.82,10,1,13.03,100,1,13.85,100,1,12.73,100,1,13.95,2,1,12.71,100,1,14.12,100,1,12.5,700,1,14.2,50,1,12.46,200,2,14.56,800,2,12.43,700,1,14.6,700,1,12.42,700,1,14.61,100,1
2025-07-17T15:34:28.174864618Z,2025-07-17T15:34:28.175030125Z,160,2,1108,A,A,0,13.79,100,130,165507,242513743,ARL,288724433,13.31,10,1,13.78,2,1,13.3,100,1,13.79,100,1,13.23,2,1,13.81,50,1,13.03,100,1,13.82,10,1,12.73,100,1,13.85,100,1,12.71,100,1,13.95,2,1,12.5,700,1,14.12,100,1,12.46,200,2,14.2,50,1,12.43,700,1,14.56,800,2,12.42,700,1,14.6,700,1
2025-07-17T15:34:28.175164464Z,2025-07-17T15:34:28.175329569Z,160,2,1108,C,A,0,13.78,2,130,165105,242513747,ARL,288724201,13.31,10,1,13.79,100,1,13.3,100,1,13.81,50,1,13.23,2,1,13.82,10,1,13.03,100,1,13.85,100,1,12.73,100,1,13.95,2,1,12.71,100,1,14.12,100,1,12.5,700,1,14.2,50,1,12.46,200,2,14.56,800,2,12.43,700,1,14.6,700,1,12.42,700,1,14.61,100,1
2025-07-17T15:34:28.175586497Z,2025-07-17T15:34:28.175752130Z,160,2,1108,C,B,0,12.23,100,0,165633,242513748,ARL,286680693,13.31,10,1,13.79,100,1,13.3,100,1,13.81,50,1,13.23,2,1,13.82,10,1,13.03,100,1,13.85,100,1,12.73,100,1,13.95,2,1,12.71,100,1,14.12,100,1,12.5,700,1,14.2,50,1,12.46,200,2,14.56,800,2,12.43,700,1,14.6,700,1,12.42,700,1,14.61,100,1
2025-07-17T15:34:28.175586497Z,2025-07-17T15:34:28.175752130Z,160,2,1108,A,B,0,12.27,100,130,165633,242513748,ARL,288724485,13.31,10,1,13.79,100,1,13.3,100,1,13.81,50,1,13.23,2,1,13.82,10,1,13.03,100,1,13.85,100,1,12.73,100,1,13.95,2,1,12.71,100,1,14.12,100,1,12.5,700,1,14.2,50,1,12.46,200,2,14.56,800,2,12.43,700,1,14.6,700,1,12.42,700,1,14.61,100,1
2025-07-17T15:34:28.175602100Z,2025-07-17T15:34:28.175767666Z,160,2,1108,C,A,0,14.91,100,0,165566,242513749,ARL,286680721,13.31,10,1,13.79,100,1,13.3,100,1,13.81,50,1,13.23,2,1,13.82,10,1,13.03,100,1,13.85,100,1,12.73,100,1,13.95,2,1,12.71,100,1,14.12,100,1,12.5,700,1,14.2,50,1,12.46,200,2,14.56,800,2,12.43,700,1,14.6,700,1,12.42,700,1,14.61,100,1
2025-07-17T15:34:28.175602100Z,2025-07-17T15:34:28.175767666Z,160,2,1108,A,A,0,14.86,100,130,165566,242513749,ARL,288724489,13.31,10,1,13.79,100,1,13.3,100,1,13.81,50,1,13.23,2,1,13.82,10,1,13.03,100,1,13.85,100,1,12.73,100,1,13.95,2,1,12.71,100,1,14.12,100,1,12.5,700,1,14.2,50,1,12.46,200,2,14.56,800,2,12.43,700,1,14.6,700,1,12.42,700,1,14.61,100,1
2025-07-17T15:34:28.180191067Z,2025-07-17T15:34:28.180356536Z,160,2,1108,A,A,0,13.8,100,130,165469,242513781,ARL,288724565,13.31,10,1,13.79,100,1,13.3,100,1,13.8,100,1,13.23,2,1,13.81,50,1,13.03,100,1,13.82,10,1,12.73,100,1,13.85,100,1,12.71,100,1,13.95,2,1,12.5,700,1,14.12,100,1,12.46,200,2,14.2,50,1,12.43,700,1,14.56,800,2,12.42,700,1,14.6,700,1
2025-07-17T15:34:28.187072050Z,2025-07-17T15:34:28.187237384Z,160,2,1108,C,A,0,13.85,100,130,165334,242513907,ARL,287560333,13.31,10,1,13.79,100,1,13.3,100,1,13.8,100,1,13.23,2,1,13.81,50,1,13.03,100,1,13.82,10,1,12.73,100,1,13.95,2,1,12.71,100,1,14.12,100,1,12.5,700,1,14.2,50,1,12.46,200,2,14.56,800,2,12.43,700,1,14.6,700,1,12.42,700,1,14.61,100,1
2025-07-17T15:34:28.192104387Z,2025-07-17T15:34:28.192269421Z,160,2,1108,C,A,0,13.79,100,130,165034,242513974,ARL,288724433,13.31,10,1,13.8,100,1,13.3,100,1,13.81,50,1,13.23,2,1,13.82,10,1,13.03,100,1,13.95,2,1,12.73,100,1,14.12,100,1,12.71,100,1,14.2,50,1,12.5,700,1,14.56,800,2,12.46,200,2,14.6,700,1,12.43,700,1,14.61,100,1,12.42,700,1,14.65,100,1
2025-07-17T15:34:28.231436134Z,2025-07-17T15:34:28.231601320Z,160,2,1108,A,A,0,13.83,100,130,165186,242514372,ARL,288725173,13.31,10,1,13.8,100,1,13.3,100,1,13.81,50,1,13.23,2,1,13.82,10,1,13.03,100,1,13.83,100,1,12.73,100,1,13.95,2,1,12.71,100,1,14.12,100,1,12.5,700,1,14.2,50,1,12.46,200,2,14.56,800,2,12.43,700,1,14.6,700,1,12.42,700,1,14.61,100,1
2025-07-17T15:34:28.255958718Z,2025-07-17T15:34:28.256123809Z,160,2,1108,C,A,0,14.2,50,130,165091,242514761,ARL,288723725,13.31,10,1,13.8,100,1,13.3,100,1,13.81,50,1,13.23,2,1,13.82,10,1,13.03,100,1,13.83,100,1,12.73,100,1,13.95,2,1,12.71,100,1,14.12,100,1,12.5,700,1,14.56,800,2,12.46,200,2,14.6,700,1,12.43,700,1,14.61,100,1,12.42,700,1,14.65,100,1
2025-07-17T15:34:28.271110273Z,2025-07-17T15:34:28.271275449Z,160,2,1108,C,A,0,13.81,50,130,165176,242515164,ARL,288724173,13.31,10,1,13.8,100,1,13.3,100,1,13.82,10,1,13.23,2,1,13.83,100,1,13.03,100,1,13.95,2,1,12.73,100,1,14.12,100,1,12.71,100,1,14.56,800,2,12.5,700,1,14.6,700,1,12.46,200,2,14.61,100,1,12.43,700,1,14.65,100,1,12.42,700,1,14.68,700,1
2025-07-17T15:34:28.281052249Z,2025-07-17T15:34:28.281217370Z,160,2,1108,C,A,0,13.8,100,130,165121,242515254,ARL,288724565,13.31,10,1,13.82,10,1,13.3,100,1,13.83,100,1,13.23,2,1,13.95,2,1,13.03,100,1,14.12,100,1,12.73,100,1,14.56,800,2,12.71,100,1,14.6,700,1,12.5,700,1,14.61,100,1,12.46,200,2,14.65,100,1,12.43,700,1,14.68,700,1,12.42,700,1,14.72,200,2
2025-07-17T15:34:28.281780230Z,2025-07-17T15:34:28.281945481Z,160,2,1108,C,A,0,14.86,100,0,165251,242515263,ARL,288724489,13.31,10,1,13.82,10,1,13.3,100,1,13.83,100,1,13.23,2,1,13.95,2,1,13.03,100,1,14.12,100,1,12.73,100,1,14.56,800,2,12.71,100,1,14.6,700,1,12.5,700,1,14.61,100,1,12.46,200,2,14.65,100,1,12.43,700,1,14.68,700,1,12.42,700,1,14.72,200,2
2025-07-17T15:34:28.281780230Z,2025-07-17T15:34:28.281945481Z,160,2,1108,A,A,0,14.9,100,130,165251,242515263,ARL,288726085,13.31,10,1,13.82,10,1,13.3,100,1,13.83,100,1,13.23,2,1,13.95,2,1,13.03,100,1,14.12,100,1,12.73,100,1,14.56,800,2,12.71,100,1,14.6,700,1,12.5,700,1,14.61,100,1,12.46,200,2,14.65,100,1,12.43,700,1,14.68,700,1,12.42,700,1,14.72,200,2
2025-07-17T15:34:32.289244370Z,2025-07-17T15:34:32.289409612Z,160,2,1108,A,A,0,13.84,100,130,165242,242598225,ARL,288845417,13.31,10,1,13.82,10,1,13.3,100,1,13.83,100,1,13.23,2,1,13.84,100,1,13.03,100,1,13.95,2,1,12.73,100,1,14.12,100,1,12.71,100,1,14.56,800,2,12.5,700,1,14.6,700,1,12.46,200,2,14.61,100,1,12.43,700,1,14.65,100,1,12.42,700,1,14.68,700,1
2025-07-17T15:34:39.864526516Z,2025-07-17T15:34:39.864692027Z,160,2,1108,A,A,0,13.8,15,130,165511,242774235,ARL,289055901,13.31,10,1,13.8,15,1,13.3,100,1,13.82,10,1,13.23,2,1,13.83,100,1,13.03,100,1,13.84,100,1,12.73,100,1,13.95,2,1,12.71,100,1,14.12,100,1,12.5,700,1,14.56,800,2,12.46,200,2,14.6,700,1,12.43,700,1,14.61,100,1,12.42,700,1,14.65,100,1
2025-07-17T15:34:39.865171719Z,2025-07-17T15:34:39.865337932Z,160,2,1108,C,A,0,13.83,100,0,166213,242774299,ARL,288725173,13.31,10,1,13.8,15,1,13.3,100,1,13.82,10,1,13.23,2,1,13.84,100,1,13.03,100,1,13.95,2,1,12.73,100,1,14.12,100,1,12.71,100,1,14.56,800,2,12.5,700,1,14.6,700,1,12.46,200,2,14.61,100,1,12.43,700,1,14.65,100,1,12.42,700,1,14.68,700,1
2025-07-17T15:34:39.865171719Z,2025-07-17T15:34:39.865337932Z,160,2,1108,A,A,0,13.81,100,130,166213,242774299,ARL,289056097,13.31,10,1,13.8,15,1,13.3,100,1,13.81,100,1,13.23,2,1,13.82,10,1,13.03,100,1,13.84,100,1,12.73,100,1,13.95,2,1,12.71,100,1,14.12,100,1,12.5,700,1,14.56,800,2,12.46,200,2,14.6,700,1,12.43,700,1,14.61,100,1,12.42,700,1,14.65,100,1
2025-07-17T15:34:39.871441822Z,2025-07-17T15:34:39.871606986Z,160,2,1108,A,A,0,13.81,100,130,165164,242774468,ARL,289056353,13.31,10,1,13.8,15,1,13.3,100,1,13.81,200,2,13.23,2,1,13.82,10,1,13.03,100,1,13.84,100,1,12.73,100,1,13.95,2,1,12.71,100,1,14.12,100,1,12.5,700,1,14.56,800,2,12.46,200,2,14.6,700,1,12.43,700,1,14.61,100,1,12.42,700,1,14.65,100,1
2025-07-17T15:34:39.878479562Z,2025-07-17T15:34:39.878645012Z,160,2,1108,C,A,0,13.84,100,130,165450,242774619,ARL,288845417,13.31,10,1,13.8,15,1,13.3,100,1,13.81,200,2,13.23,2,1,13.82,10,1,13.03,100,1,13.95,2,1,12.73,100,1,14.12,100,1,12.71,100,1,14.56,800,2,12.5,700,1,14.6,700,1,12.46,200,2,14.61,100,1,12.43,700,1,14.65,100,1,12.42,700,1,14.68,700,1
2025-07-17T15:34:42.774024574Z,2025-07-17T15:34:42.774190041Z,160,2,1108,C,B,0,13.31,10,130,165467,242816556,ARL,288724225,13.3,100,1,13.8,15,1,13.23,2,1,13.81,200,2,13.03,100,1,13.82,10,1,12.73,100,1,13.95,2,1,12.71,100,1,14.12,100,1,12.5,700,1,14.56,800,2,12.46,200,2,14.6,700,1,12.43,700,1,14.61,100,1,12.42,700,1,14.65,100,1,12.37,700,1,14.68,700,1
2025-07-17T15:34:42.775139521Z,2025-07-17T15:34:42.775304741Z,160,2,1108,C,A,0,13.81,100,130,165220,242816563,ARL,289056353,13.3,100,1,13.8,15,1,13.23,2,1,13.81,100,1,13.03,100,1,13.82,10,1,12.73,100,1,13.95,2,1,12.71,100,1,14.12,100,1,12.5,700,1,14.56,800,2,12.46,200,2,14.6,700,1,12.43,700,1,14.61,100,1,12.42,700,1,14.65,100,1,12.37,700,1,14.68,700,1
2025-07-17T15:34:46.773922586Z,2025-07-17T15:34:46.774087945Z,160,2,1108,C,A,0,13.8,15,130,165359,242893860,ARL,289055901,13.3,100,1,13.81,100,1,13.23,2,1,13.82,10,1,13.03,100,1,13.95,2,1,12.73,100,1,14.12,100,1,12.71,100,1,14.56,800,2,12.5,700,1,14.6,700,1,12.46,200,2,14.61,100,1,12.43,700,1,14.65,100,1,12.42,700,1,14.68,700,1,12.37,700,1,14.72,200,2
2025-07-17T15:34:46.800789632Z,2025-07-17T15:34:46.800955057Z,160,2,1108,A,A,0,13.83,100,130,165425,242894153,ARL,289199221,13.3,100,1,13.81,100,1,13.23,2,1,13.82,10,1,13.03,100,1,13.83,100,1,12.73,100,1,13.95,2,1,12.71,100,1,14.12,100,1,12.5,700,1,14.56,800,2,12.46,200,2,14.6,700,1,12.43,700,1,14.61,100,1,12.42,700,1,14.65,100,1,12.37,700,1,14.68,700,1
2025-07-17T15:34:53.545665068Z,2025-07-17T15:34:53.545830704Z,160,2,1108,C,A,0,13.82,10,130,165636,243011340,ARL,288724229,13.3,100,1,13.81,100,1,13.23,2,1,13.83,100,1,13.03,100,1,13.95,2,1,12.73,100,1,14.12,100,1,12.71,100,1,14.56,800,2,12.5,700,1,14.6,700,1,12.46,200,2,14.61,100,1,12.43,700,1,14.65,100,1,12.42,700,1,14.68,700,1,12.37,700,1,14.72,200,2
2025-07-17T15:35:05.620598378Z,2025-07-17T15:35:05.620763928Z,160,2,1108,A,A,0,13.77,15,130,165550,243344672,ARL,289722397,13.3,100,1,13.77,15,1,13.23,2,1,13.81,100,1,13.03,100,1,13.83,100,1,12.73,100,1,13.95,2,1,12.71,100,1,14.12,100,1,12.5,700,1,14.56,800,2,12.46,200,2,14.6,700,1,12.43,700,1,14.61,100,1,12.42,700,1,14.65,100,1,12.37,700,1,14.68,700,1
2025-07-17T15:35:05.712409728Z,2025-07-17T15:35:05.712575243Z,160,2,1108,C,A,0,13.81,100,0,165515,243347940,ARL,289056097,13.3,100,1,13.77,15,1,13.23,2,1,13.83,100,1,13.03,100,1,13.95,2,1,12.73,100,1,14.12,100,1,12.71,100,1,14.56,800,2,12.5,700,1,14.6,700,1,12.46,200,2,14.61,100,1,12.43,700,1,14.65,100,1,12.42,700,1,14.68,700,1,12.37,700,1,14.72,200,2
2025-07-17T15:35:05.712409728Z,2025-07-17T15:35:05.712575243Z,160,2,1108,A,A,0,13.78,100,130,165515,243347940,ARL,289726281,13.3,100,1,13.77,15,1,13.23,2,1,13.78,100,1,13.03,100,1,13.83,100,1,12.73,100,1,13.95,2,1,12.71,100,1,14.12,100,1,12.5,700,1,14.56,800,2,12.46,200,2,14.6,700,1,12.43,700,1,14.61,100,1,12.42,700,1,14.65,100,1,12.37,700,1,14.68,700,1
2025-07-17T15:35:05.713150123Z,2025-07-17T15:35:05.713315450Z,160,2,1108,C,A,0,14.61,100,130,165327,243347987,ARL,237978629,13.3,100,1,13.77,15,1,13.23,2,1,13.78,100,1,13.03,100,1,13.83,100,1,12.73,100,1,13.95,2,1,12.71,100,1,14.12,100,1,12.5,700,1,14.56,800,2,12.46,200,2,14.6,700,1,12.43,700,1,14.65,100,1,12.42,700,1,14.68,700,1,12.37,700,1,14.72,200,2
2025-07-17T15:35:05.713157077Z,2025-07-17T15:35:05.713322577Z,160,2,1108,C,A,0,14.9,100,0,165500,243347988,ARL,288726085,13.3,100,1,13.77,15,1,13.23,2,1,13.78,100,1,13.03,100,1,13.83,100,1,12.73,100,1,13.95,2,1,12.71,100,1,14.12,100,1,12.5,700,1,14.56,800,2,12.46,200,2,14.6,700,1,12.43,700,1,14.65,100,1,12.42,700,1,14.68,700,1,12.37,700,1,14.72,200,2
2025-07-17T15:35:05.713157077Z,2025-07-17T15:35:05.713322577Z,160,2,1108,A,A,0,14.85,100,130,165500,243347988,ARL,289726349,13.3,100,1,13.77,15,1,13.23,2,1,13.78,100,1,13.03,100,1,13.83,100,1,12.73,100,1,13.95,2,1,12.71,100,1,14.12,100,1,12.5,700,1,14.56,800,2,12.46,200,2,14.6,700,1,12.43,700,1,14.65,100,1,12.42,700,1,14.68,700,1,12.37,700,1,14.72,200,2
2025-07-17T15:35:05.713508657Z,2025-07-17T15:35:05.713677091Z,160,2,1108,A,A,0,14.4,100,128,168434,243348032,ARL,289726421,13.3,100,1,13.77,15,1,13.23,2,1,13.78,100,1,13.03,100,1,13.83,100,1,12.73,100,1,13.95,2,1,12.71,100,1,14.12,100,1,12.5,700,1,14.4,100,1,12.46,200,2,14.56,800,2,12.43,700,1,14.6,700,1,12.42,700,1,14.65,100,1,12.37,700,1,14.68,700,1
2025-07-17T15:35:05.729398505Z,2025-07-17T15:35:05.729568877Z,160,2,1108,A,A,0,13.8,100,128,170372,243351264,ARL,289730309,13.3,100,1,13.77,15,1,13.23,2,1,13.78,100,1,13.03,100,1,13.8,100,1,12.73,100,1,13.83,100,1,12.71,100,1,13.95,2,1,12.5,700,1,14.12,100,1,12.46,200,2,14.4,100,1,12.43,700,1,14.56,800,2,12.42,700,1,14.6,700,1,12.37,700,1,14.65,100,1
2025-07-17T15:35:05.737802616Z,2025-07-17T15:35:05.737967956Z,160,2,1108,C,A,0,13.83,100,130,165340,243352644,ARL,289199221,13.3,100,1,13.77,15,1,13.23,2,1,13.78,100,1,13.03,100,1,13.8,100,1,12.73,100,1,13.95,2,1,12.71,100,1,14.12,100,1,12.5,700,1,14.4,100,1,12.46,200,2,14.56,800,2,12.43,700,1,14.6,700,1,12.42,700,1,14.65,100,1,12.37,700,1,14.68,700,1
2025-07-17T15:35:06.286407017Z,2025-07-17T15:35:06.286572335Z,160,2,1108,C,A,0,13.77,15,130,165318,243362628,ARL,289722397,13.3,100,1,13.78,100,1,13.23,2,1,13.8,100,1,13.03,100,1,13.95,2,1,12.73,100,1,14.12,100,1,12.71,100,1,14.4,100,1,12.5,700,1,14.56,800,2,12.46,200,2,14.6,700,1,12.43,700,1,14.65,100,1,12.42,700,1,14.68,700,1,12.37,700,1,14.72,200,2
2025-07-17T15:35:09.788115219Z,2025-07-17T15:35:09.788280931Z,160,2,1108,C,B,0,13.23,2,0,165712,243432828,ARL,272263853,13.3,100,1,13.78,100,1,13.03,100,1,13.8,100,1,12.73,100,1,13.95,2,1,12.71,100,1,14.12,100,1,12.5,700,1,14.4,100,1,12.46,200,2,14.56,800,2,12.43,700,1,14.6,700,1,12.42,700,1,14.65,100,1,12.37,700,1,14.68,700,1,12.36,200,2,14.72,200,2
2025-07-17T15:35:09.788115219Z,2025-07-17T15:35:09.788280931Z,160,2,1108,A,B,0,13.14,2,130,165712,243432828,ARL,289828293,13.3,100,1,13.78,100,1,13.14,2,1,13.8,100,1,13.03,100,1,13.95,2,1,12.73,100,1,14.12,100,1,12.71,100,1,14.4,100,1,12.5,700,1,14.56,800,2,12.46,200,2,14.6,700,1,12.43,700,1,14.65,100,1,12.42,700,1,14.68,700,1,12.37,700,1,14.72,200,2
2025-07-17T15:35:11.891701845Z,2025-07-17T15:35:11.891867009Z,160,2,1108,C,A,0,13.8,100,130,165164,243482295,ARL,289730309,13.3,100,1,13.78,100,1,13.14,2,1,13.95,2,1,13.03,100,1,14.12,100,1,12.73,100,1,14.4,100,1,12.71,100,1,14.56,800,2,12.5,700,1,14.6,700,1,12.46,200,2,14.65,100,1,12.43,700,1,14.68,700,1,12.42,700,1,14.72,200,2,12.37,700,1,14.81,200,2
2025-07-17T15:35:14.301481698Z,2025-07-17T15:35:14.301647013Z,160,2,1108,A,A,0,14.68,700,130,165315,243521615,ARL,289932801,13.3,100,1,13.78,100,1,13.14,2,1,13.95,2,1,13.03,100,1,14.12,100,1,12.73,100,1,14.4,100,1,12.71,100,1,14.56,800,2,12.5,700,1,14.6,700,1,12.46,200,2,14.65,100,1,12.43,700,1,14.68,1400,2,12.42,700,1,14.72,200,2,12.37,700,1,14.81,200,2
2025-07-17T15:35:14.302278179Z,2025-07-17T15:35:14.302443648Z,160,2,1108,C,A,0,14.91,700,130,165469,243521616,ARL,147217629,13.3,100,1,13.78,100,1,13.14,2,1,13.95,2,1,13.03,100,1,14.12,100,1,12.73,100,1,14.4,100,1,12.71,100,1,14.56,800,2,12.5,700,1,14.6,700,1,12.46,200,2,14.65,100,1,12.43,700,1,14.68,1400,2,12.42,700,1,14.72,200,2,12.37,700,1,14.81,200,2
2025-07-17T15:35:15.940479233Z,2025-07-17T15:35:15.940644416Z,160,2,1108,A,A,0,13.82,100,130,165183,243557058,ARL,289976125,13.3,100,1,13.78,100,1,13.14,2,1,13.82,100,1,13.03,100,1,13.95,2,1,12.73,100,1,14.12,100,1,12.71,100,1,14.4,100,1,12.5,700,1,14.56,800,2,12.46,200,2,14.6,700,1,12.43,700,1,14.65,100,1,12.42,700,1,14.68,1400,2,12.37,700,1,14.72,200,2
2025-07-17T15:35:23.746509184Z,2025-07-17T15:35:23.746674314Z,160,2,1108,A,A,0,13.8,100,130,165130,243692012,ARL,290159301,13.3,100,1,13.78,100,1,13.14,2,1,13.8,100,1,13.03,100,1,13.82,100,1,12.73,100,1,13.95,2,1,12.71,100,1,14.12,100,1,12.5,700,1,14.4,100,1,12.46,200,2,14.56,800,2,12.43,700,1,14.6,700,1,12.42,700,1,14.65,100,1,12.37,700,1,14.68,1400,2
2025-07-17T15:35:23.754453294Z,2025-07-17T15:35:23.754618546Z,160,2,1108,C,A,0,13.82,100,130,165252,243692501,ARL,289976125,13.3,100,1,13.78,100,1,13.14,2,1,13.8,100,1,13.03,100,1,13.95,2,1,12.73,100,1,14.12,100,1,12.71,100,1,14.4,100,1,12.5,700,1,14.56,800,2,12.46,200,2,14.6,700,1,12.43,700,1,14.65,100,1,12.42,700,1,14.68,1400,2,12.37,700,1,14.72,200,2
2025-07-17T15:35:39.056513985Z,2025-07-17T15:35:39.056679600Z,160,2,1108,C,A,0,13.8,100,130,165615,243992725,ARL,290159301,13.3,100,1,13.78,100,1,13.14,2,1,13.95,2,1,13.03,100,1,14.12,100,1,12.73,100,1,14.4,100,1,12.71,100,1,14.56,800,2,12.5,700,1,14.6,700,1,12.46,200,2,14.65,100,1,12.43,700,1,14.68,1400,2,12.42,700,1,14.72,200,2,12.37,700,1,14.81,200,2
2025-07-17T15:35:43.128644252Z,2025-07-17T15:35:43.128809717Z,160,2,1108,A,A,0,13.82,100,130,165465,244078096,ARL,290630573,13.3,100,1,13.78,100,1,13.14,2,1,13.82,100,1,13.03,100,1,13.95,2,1,12.73,100,1,14.12,100,1,12.71,100,1,14.4,100,1,12.5,700,1,14.56,800,2,12.46,200,2,14.6,700,1,12.43,700,1,14.65,100,1,12.42,700,1,14.68,1400,2,12.37,700,1,14.72,200,2
2025-07-17T15:36:30.043928872Z,2025-07-17T15:36:30.044094509Z,160,2,1108,A,A,0,13.8,100,130,165637,245013624,ARL,291778909,13.3,100,1,13.78,100,1,13.14,2,1,13.8,100,1,13.03,100,1,13.82,100,1,12.73,100,1,13.95,2,1,12.71,100,1,14.12,100,1,12.5,700,1,14.4,100,1,12.46,200,2,14.56,800,2,12.43,700,1,14.6,700,1,12.42,700,1,14.65,100,1,12.37,700,1,14.68,1400,2
2025-07-17T15:36:30.050880126Z,2025-07-17T15:36:30.051045453Z,160,2,1108,C,A,0,13.82,100,130,165327,245013914,ARL,290630573,13.3,100,1,13.78,100,1,13.14,2,1,13.8,100,1,13.03,100,1,13.95,2,1,12.73,100,1,14.12,100,1,12.71,100,1,14.4,100,1,12.5,700,1,14.56,800,2,12.46,200,2,14.6,700,1,12.43,700,1,14.65,100,1,12.42,700,1,14.68,1400,2,12.37,700,1,14.72,200,2
2025-07-17T15:36:34.297844579Z,2025-07-17T15:36:34.298010005Z,160,2,1108,C,B,0,13.3,100,130,165426,245144122,ARL,288724429,13.14,2,1,13.78,100,1,13.03,100,1,13.8,100,1,12.73,100,1,13.95,2,1,12.71,100,1,14.12,100,1,12.5,700,1,14.4,100,1,12.46,200,2,14.56,800,2,12.43,700,1,14.6,700,1,12.42,700,1,14.65,100,1,12.37,700,1,14.68,1400,2,12.36,200,2,14.72,200,2
2025-07-17T15:36:35.381165559Z,2025-07-17T15:36:35.381330809Z,160,2,1108,A,B,0,13.13,100,130,165250,245161447,ARL,291951937,13.14,2,1,13.78,100,1,13.13,100,1,13.8,100,1,13.03,100,1,13.95,2,1,12.73,100,1,14.12,100,1,12.71,100,1,14.4,100,1,12.5,700,1,14.56,800,2,12.46,200,2,14.6,700,1,12.43,700,1,14.65,100,1,12.42,700,1,14.68,1400,2,12.37,700,1,14.72,200,2
2025-07-17T15:36:35.532685683Z,2025-07-17T15:36:35.532851032Z,160,2,1108,A,B,0,13.27,10,130,165349,245174454,ARL,291964737,13.27,10,1,13.78,100,1,13.14,2,1,13.8,100,1,13.13,100,1,13.95,2,1,13.03,100,1,14.12,100,1,12.73,100,1,14.4,100,1,12.71,100,1,14.56,800,2,12.5,700,1,14.6,700,1,12.46,200,2,14.65,100,1,12.43,700,1,14.68,1400,2,12.42,700,1,14.72,200,2
2025-07-17T15:36:35.532761335Z,2025-07-17T15:36:35.532926951Z,160,2,1108,C,B,0,12.27,100,0,165616,245174461,ARL,288724485,13.27,10,1,13.78,100,1,13.14,2,1,13.8,100,1,13.13,100,1,13.95,2,1,13.03,100,1,14.12,100,1,12.73,100,1,14.4,100,1,12.71,100,1,14.56,800,2,12.5,700,1,14.6,700,1,12.46,200,2,14.65,100,1,12.43,700,1,14.68,1400,2,12.42,700,1,14.72,200,2
2025-07-17T15:36:35.532761335Z,2025-07-17T15:36:35.532926951Z,160,2,1108,A,B,0,12.23,100,130,165616,245174461,ARL,291964745,13.27,10,1,13.78,100,1,13.14,2,1,13.8,100,1,13.13,100,1,13.95,2,1,13.03,100,1,14.12,100,1,12.73,100,1,14.4,100,1,12.71,100,1,14.56,800,2,12.5,700,1,14.6,700,1,12.46,200,2,14.65,100,1,12.43,700,1,14.68,1400,2,12.42,700,1,14.72,200,2
2025-07-17T15:36:36.151966883Z,2025-07-17T15:36:36.152132527Z,160,2,1108,C,B,0,13.13,100,0,165644,245183955,ARL,291951937,13.27,10,1,13.78,100,1,13.14,2,1,13.8,100,1,13.03,100,1,13.95,2,1,12.73,100,1,14.12,100,1,12.71,100,1,14.4,100,1,12.5,700,1,14.56,800,2,12.46,200,2,14.6,700,1,12.43,700,1,14.65,100,1,12.42,700,1,14.68,1400,2,12.37,700,1,14.72,200,2
2025-07-17T15:36:36.151966883Z,2025-07-17T15:36:36.152132527Z,160,2,1108,A,B,0,13.26,100,130,165644,245183955,ARL,291975017,13.27,10,1,13.78,100,1,13.26,100,1,13.8,100,1,13.14,2,1,13.95,2,1,13.03,100,1,14.12,100,1,12.73,100,1,14.4,100,1,12.71,100,1,14.56,800,2,12.5,700,1,14.6,700,1,12.46,200,2,14.65,100,1,12.43,700,1,14.68,1400,2,12.42,700,1,14.72,200,2
2025-07-17T15:36:46.889749756Z,2025-07-17T15:36:46.889917278Z,160,2,1108,C,B,0,13.27,10,128,167522,245499598,ARL,291964737,13.26,100,1,13.78,100,1,13.14,2,1,13.8,100,1,13.03,100,1,13.95,2,1,12.73,100,1,14.12,100,1,12.71,100,1,14.4,100,1,12.5,700,1,14.56,800,2,12.46,200,2,14.6,700,1,12.43,700,1,14.65,100,1,12.42,700,1,14.68,1400,2,12.37,700,1,14.72,200,2
2025-07-17T15:36:46.986655137Z,2025-07-17T15:36:46.986820391Z,160,2,1108,C,A,0,13.8,100,130,165254,245503745,ARL,291778909,13.26,100,1,13.78,100,1,13.14,2,1,13.95,2,1,13.03,100,1,14.12,100,1,12.73,100,1,14.4,100,1,12.71,100,1,14.56,800,2,12.5,700,1,14.6,700,1,12.46,200,2,14.65,100,1,12.43,700,1,14.68,1400,2,12.42,700,1,14.72,200,2,12.37,700,1,14.81,200,2
2025-07-17T15:36:50.997269299Z,2025-07-17T15:36:50.997434689Z,160,2,1108,A,A,0,13.82,100,130,165390,245564901,ARL,292434813,13.26,100,1,13.78,100,1,13.14,2,1,13.82,100,1,13.03,100,1,13.95,2,1,12.73,100,1,14.12,100,1,12.71,100,1,14.4,100,1,12.5,700,1,14.56,800,2,12.46,200,2,14.6,700,1,12.43,700,1,14.65,100,1,12.42,700,1,14.68,1400,2,12.37,700,1,14.72,200,2
2025-07-17T15:37:40.389572053Z,2025-07-17T15:37:40.389737573Z,160,2,1108,C,B,0,13.14,2,0,165520,246491394,ARL,289828293,13.26,100,1,13.78,100,1,13.03,100,1,13.82,100,1,12.73,100,1,13.95,2,1,12.71,100,1,14.12,100,1,12.5,700,1,14.4,100,1,12.46,200,2,14.56,800,2,12.43,700,1,14.6,700,1,12.42,700,1,14.65,100,1,12.37,700,1,14.68,1400,2,12.36,200,2,14.72,200,2
2025-07-17T15:37:40.389572053Z,2025-07-17T15:37:40.389737573Z,160,2,1108,A,B,0,13.04,2,130,165520,246491394,ARL,293594281,13.26,100,1,13.78,100,1,13.04,2,1,13.82,100,1,13.03,100,1,13.95,2,1,12.73,100,1,14.12,100,1,12.71,100,1,14.4,100,1,12.5,700,1,14.56,800,2,12.46,200,2,14.6,700,1,12.43,700,1,14.65,100,1,12.42,700,1,14.68,1400,2,12.37,700,1,14.72,200,2
2025-07-17T15:39:27.069942913Z,2025-07-17T15:39:27.070109669Z,160,2,1108,A,A,0,13.8,100,128,166756,248436908,ARL,296059685,13.26,100,1,13.78,100,1,13.04,2,1,13.8,100,1,13.03,100,1,13.82,100,1,12.73,100,1,13.95,2,1,12.71,100,1,14.12,100,1,12.5,700,1,14.4,100,1,12.46,200,2,14.56,800,2,12.43,700,1,14.6,700,1,12.42,700,1,14.65,100,1,12.37,700,1,14.68,1400,2
2025-07-17T15:39:27.077400388Z,2025-07-17T15:39:27.077565902Z,160,2,1108,C,A,0,13.82,100,130,165514,248437548,ARL,292434813,13.26,100,1,13.78,100,1,13.04,2,1,13.8,100,1,13.03,100,1,13.95,2,1,12.73,100,1,14.12,100,1,12.71,100,1,14.4,100,1,12.5,700,1,14.56,800,2,12.46,200,2,14.6,700,1,12.43,700,1,14.65,100,1,12.42,700,1,14.68,1400,2,12.37,700,1,14.72,200,2
2025-07-17T15:39:30.509687817Z,2025-07-17T15:39:30.509853083Z,160,2,1108,A,A,0,13.76,15,130,165266,248491930,ARL,296136617,13.26,100,1,13.76,15,1,13.04,2,1,13.78,100,1,13.03,100,1,13.8,100,1,12.73,100,1,13.95,2,1,12.71,100,1,14.12,100,1,12.5,700,1,14.4,100,1,12.46,200,2,14.56,800,2,12.43,700,1,14.6,700,1,12.42,700,1,14.65,100,1,12.37,700,1,14.68,1400,2
2025-07-17T15:39:30.573052284Z,2025-07-17T15:39:30.573217843Z,160,2,1108,C,A,0,13.78,100,0,165559,248492793,ARL,289726281,13.26,100,1,13.76,15,1,13.04,2,1,13.8,100,1,13.03,100,1,13.95,2,1,12.73,100,1,14.12,100,1,12.71,100,1,14.4,100,1,12.5,700,1,14.56,800,2,12.46,200,2,14.6,700,1,12.43,700,1,14.65,100,1,12.42,700,1,14.68,1400,2,12.37,700,1,14.72,200,2
2025-07-17T15:39:30.573052284Z,2025-07-17T15:39:30.573217843Z,160,2,1108,A,A,0,13.77,100,130,165559,248492793,ARL,296137537,13.26,100,1,13.76,15,1,13.04,2,1,13.77,100,1,13.03,100,1,13.8,100,1,12.73,100,1,13.95,2,1,12.71,100,1,14.12,100,1,12.5,700,1,14.4,100,1,12.46,200,2,14.56,800,2,12.43,700,1,14.6,700,1,12.42,700,1,14.65,100,1,12.37,700,1,14.68,1400,2
2025-07-17T15:39:30.589004378Z,2025-07-17T15:39:30.589169820Z,160,2,1108,C,A,0,14.12,100,130,165442,248493012,ARL,286680917,13.26,100,1,13.76,15,1,13.04,2,1,13.77,100,1,13.03,100,1,13.8,100,1,12.73,100,1,13.95,2,1,12.71,100,1,14.4,100,1,12.5,700,1,14.56,800,2,12.46,200,2,14.6,700,1,12.43,700,1,14.65,100,1,12.42,700,1,14.68,1400,2,12.37,700,1,14.72,200,2
2025-07-17T15:39:30.589059301Z,2025-07-17T15:39:30.589224596Z,160,2,1108,A,A,0,14.05,100,130,165295,248493014,ARL,296137769,13.26,100,1,13.76,15,1,13.04,2,1,13.77,100,1,13.03,100,1,13.8,100,1,12.73,100,1,13.95,2,1,12.71,100,1,14.05,100,1,12.5,700,1,14.4,100,1,12.46,200,2,14.56,800,2,12.43,700,1,14.6,700,1,12.42,700,1,14.65,100,1,12.37,700,1,14.68,1400,2
2025-07-17T15:39:31.091844988Z,2025-07-17T15:39:31.092010369Z,160,2,1108,A,A,0,13.78,100,130,165381,248502203,ARL,296149845,13.26,100,1,13.76,15,1,13.04,2,1,13.77,100,1,13.03,100,1,13.78,100,1,12.73,100,1,13.8,100,1,12.71,100,1,13.95,2,1,12.5,700,1,14.05,100,1,12.46,200,2,14.4,100,1,12.43,700,1,14.56,800,2,12.42,700,1,14.6,700,1,12.37,700,1,14.65,100,1
2025-07-17T15:39:31.098691429Z,2025-07-17T15:39:31.098856641Z,160,2,1108,C,A,0,13.8,100,130,165212,248502510,ARL,296059685,13.26,100,1,13.76,15,1,13.04,2,1,13.77,100,1,13.03,100,1,13.78,100,1,12.73,100,1,13.95,2,1,12.71,100,1,14.05,100,1,12.5,700,1,14.4,100,1,12.46,200,2,14.56,800,2,12.43,700,1,14.6,700,1,12.42,700,1,14.65,100,1,12.37,700,1,14.68,1400,2
2025-07-17T15:39:40.690971606Z,2025-07-17T15:39:40.691151435Z,160,2,1108,A,A,0,13.73,15,128,179829,248666930,ARL,296365029,13.26,100,1,13.73,15,1,13.04,2,1,13.76,15,1,13.03,100,1,13.77,100,1,12.73,100,1,13.78,100,1,12.71,100,1,13.95,2,1,12.5,700,1,14.05,100,1,12.46,200,2,14.4,100,1,12.43,700,1,14.56,800,2,12.42,700,1,14.6,700,1,12.37,700,1,14.65,100,1
2025-07-17T15:39:40.696182148Z,2025-07-17T15:39:40.696349429Z,160,2,1108,C,A,0,13.77,100,0,167281,248669978,ARL,296137537,13.26,100,1,13.73,15,1,13.04,2,1,13.76,15,1,13.03,100,1,13.78,100,1,12.73,100,1,13.95,2,1,12.71,100,1,14.05,100,1,12.5,700,1,14.4,100,1,12.46,200,2,14.56,800,2,12.43,700,1,14.6,700,1,12.42,700,1,14.65,100,1,12.37,700,1,14.68,1400,2
2025-07-17T15:39:40.696182148Z,2025-07-17T15:39:40.696349429Z,160,2,1108,A,A,0,13.74,100,130,167281,248669978,ARL,296368281,13.26,100,1,13.73,15,1,13.04,2,1,13.74,100,1,13.03,100,1,13.76,15,1,12.73,100,1,13.78,100,1,12.71,100,1,13.95,2,1,12.5,700,1,14.05,100,1,12.46,200,2,14.4,100,1,12.43,700,1,14.56,800,2,12.42,700,1,14.6,700,1,12.37,700,1,14.65,100,1
2025-07-17T15:39:40.697247480Z,2025-07-17T15:39:40.697414147Z,160,2,1108,C,A,0,14.85,100,0,166667,248670386,ARL,289726349,13.26,100,1,13.73,15,1,13.04,2,1,13.74,100,1,13.03,100,1,13.76,15,1,12.73,100,1,13.78,100,1,12.71,100,1,13.95,2,1,12.5,700,1,14.05,100,1,12.46,200,2,14.4,100,1,12.43,700,1,14.56,800,2,12.42,700,1,14.6,700,1,12.37,700,1,14.65,100,1
2025-07-17T15:39:40.697247480Z,2025-07-17T15:39:40.697414147Z,160,2,1108,A,A,0,14.81,100,128,166667,248670386,ARL,296368709,13.26,100,1,13.73,15,1,13.04,2,1,13.74,100,1,13.03,100,1,13.76,15,1,12.73,100,1,13.78,100,1,12.71,100,1,13.95,2,1,12.5,700,1,14.05,100,1,12.46,200,2,14.4,100,1,12.43,700,1,14.56,800,2,12.42,700,1,14.6,700,1,12.37,700,1,14.65,100,1
2025-07-17T15:39:40.708645114Z,2025-07-17T15:39:40.708810377Z,160,2,1108,A,A,0,13.76,100,130,165263,248674504,ARL,296372577,13.26,100,1,13.73,15,1,13.04,2,1,13.74,100,1,13.03,100,1,13.76,115,2,12.73,100,1,13.78,100,1,12.71,100,1,13.95,2,1,12.5,700,1,14.05,100,1,12.46,200,2,14.4,100,1,12.43,700,1,14.56,800,2,12.42,700,1,14.6,700,1,12.37,700,1,14.65,100,1
2025-07-17T15:39:40.731266408Z,2025-07-17T15:39:40.731431547Z,160,2,1108,C,A,0,13.78,100,130,165139,248676672,ARL,296149845,13.26,100,1,13.73,15,1,13.04,2,1,13.74,100,1,13.03,100,1,13.76,115,2,12.73,100,1,13.95,2,1,12.71,100,1,14.05,100,1,12.5,700,1,14.4,100,1,12.46,200,2,14.56,800,2,12.43,700,1,14.6,700,1,12.42,700,1,14.65,100,1,12.37,700,1,14.68,1400,2
2025-07-17T15:39:40.907929975Z,2025-07-17T15:39:40.908095999Z,160,2,1108,C,A,0,15.4,100,0,166024,248685584,ARL,146959177,13.26,100,1,13.73,15,1,13.04,2,1,13.74,100,1,13.03,100,1,13.76,115,2,12.73,100,1,13.95,2,1,12.71,100,1,14.05,100,1,12.5,700,1,14.4,100,1,12.46,200,2,14.56,800,2,12.43,700,1,14.6,700,1,12.42,700,1,14.65,100,1,12.37,700,1,14.68,1400,2
2025-07-17T15:39:40.907929975Z,2025-07-17T15:39:40.908095999Z,160,2,1108,A,A,0,15.12,100,130,166024,248685584,ARL,296387089,13.26,100,1,13.73,15,1,13.04,2,1,13.74,100,1,13.03,100,1,13.76,115,2,12.73,100,1,13.95,2,1,12.71,100,1,14.05,100,1,12.5,700,1,14.4,100,1,12.46,200,2,14.56,800,2,12.43,700,1,14.6,700,1,12.42,700,1,14.65,100,1,12.37,700,1,14.68,1400,2
2025-07-17T15:39:41.085699437Z,2025-07-17T15:39:41.085864728Z,160,2,1108,A,A,0,14.56,100,130,165291,248688410,ARL,296391881,13.26,100,1,13.73,15,1,13.04,2,1,13.74,100,1,13.03,100,1,13.76,115,2,12.73,100,1,13.95,2,1,12.71,100,1,14.05,100,1,12.5,700,1,14.4,100,1,12.46,200,2,14.56,900,3,12.43,700,1,14.6,700,1,12.42,700,1,14.65,100,1,12.37,700,1,14.68,1400,2
2025-07-17T15:39:41.085711985Z,2025-07-17T15:39:41.085877317Z,160,2,1108,C,A,0,14.84,100,130,165332,248688411,ARL,146962993,13.26,100,1,13.73,15,1,13.04,2,1,13.74,100,1,13.03,100,1,13.76,115,2,12.73,100,1,13.95,2,1,12.71,100,1,14.05,100,1,12.5,700,1,14.4,100,1,12.46,200,2,14.56,900,3,12.43,700,1,14.6,700,1,12.42,700,1,14.65,100,1,12.37,700,1,14.68,1400,2
2025-07-17T15:39:43.773645905Z,2025-07-17T15:39:43.773811774Z,160,2,1108,C,A,0,14.72,100,0,165869,248737506,ARL,286680577,13.26,100,1,13.73,15,1,13.04,2,1,13.74,100,1,13.03,100,1,13.76,115,2,12.73,100,1,13.95,2,1,12.71,100,1,14.05,100,1,12.5,700,1,14.4,100,1,12.46,200,2,14.56,900,3,12.43,700,1,14.6,700,1,12.42,700,1,14.65,100,1,12.37,700,1,14.68,1400,2
2025-07-17T15:39:43.773645905Z,2025-07-17T15:39:43.773811774Z,160,2,1108,A,A,0,14.61,100,130,165869,248737506,ARL,296455037,13.26,100,1,13.73,15,1,13.04,2,1,13.74,100,1,13.03,100,1,13.76,115,2,12.73,100,1,13.95,2,1,12.71,100,1,14.05,100,1,12.5,700,1,14.4,100,1,12.46,200,2,14.56,900,3,12.43,700,1,14.6,700,1,12.42,700,1,14.61,100,1,12.37,700,1,14.65,100,1
2025-07-17T15:39:43.773738855Z,2025-07-17T15:39:43.773904473Z,160,2,1108,C,A,0,14.72,100,0,165618,248737508,ARL,286680573,13.26,100,1,13.73,15,1,13.04,2,1,13.74,100,1,13.03,100,1,13.76,115,2,12.73,100,1,13.95,2,1,12.71,100,1,14.05,100,1,12.5,700,1,14.4,100,1,12.46,200,2,14.56,900,3,12.43,700,1,14.6,700,1,12.42,700,1,14.61,100,1,12.37,700,1,14.65,100,1
2025-07-17T15:39:43.773738855Z,2025-07-17T15:39:43.773904473Z,160,2,1108,A,A,0,14.61,100,130,165618,248737508,ARL,296455041,13.26,100,1,13.73,15,1,13.04,2,1,13.74,100,1,13.03,100,1,13.76,115,2,12.73,100,1,13.95,2,1,12.71,100,1,14.05,100,1,12.5,700,1,14.4,100,1,12.46,200,2,14.56,900,3,12.43,700,1,14.6,700,1,12.42,700,1,14.61,200,2,12.37,700,1,14.65,100,1
2025-07-17T15:39:44.428505546Z,2025-07-17T15:39:44.428670900Z,160,2,1108,C,A,0,13.76,15,130,165354,248751670,ARL,296136617,13.26,100,1,13.73,15,1,13.04,2,1,13.74,100,1,13.03,100,1,13.76,100,1,12.73,100,1,13.95,2,1,12.71,100,1,14.05,100,1,12.5,700,1,14.4,100,1,12.46,200,2,14.56,900,3,12.43,700,1,14.6,700,1,12.42,700,1,14.61,200,2,12.37,700,1,14.65,100,1
2025-07-17T15:39:44.433372235Z,2025-07-17T15:39:44.433539292Z,160,2,1108,C,A,0,13.73,15,128,167057,248752483,ARL,296365029,13.26,100,1,13.74,100,1,13.04,2,1,13.76,100,1,13.03,100,1,13.95,2,1,12.73,100,1,14.05,100,1,12.71,100,1,14.4,100,1,12.5,700,1,14.56,900,3,12.46,200,2,14.6,700,1,12.43,700,1,14.61,200,2,12.42,700,1,14.65,100,1,12.37,700,1,14.68,1400,2
2025-07-17T15:39:44.435889060Z,2025-07-17T15:39:44.436054885Z,160,2,1108,C,A,0,13.74,100,130,165825,248752938,ARL,296368281,13.26,100,1,13.76,100,1,13.04,2,1,13.95,2,1,13.03,100,1,14.05,100,1,12.73,100,1,14.4,100,1,12.71,100,1,14.56,900,3,12.5,700,1,14.6,700,1,12.46,200,2,14.61,200,2,12.43,700,1,14.65,100,1,12.42,700,1,14.68,1400,2,12.37,700,1,14.81,300,3
2025-07-17T15:39:44.450073949Z,2025-07-17T15:39:44.450239090Z,160,2,1108,C,A,0,13.76,100,130,165141,248753643,ARL,296372577,13.26,100,1,13.95,2,1,13.04,2,1,14.05,100,1,13.03,100,1,14.4,100,1,12.73,100,1,14.56,900,3,12.71,100,1,14.6,700,1,12.5,700,1,14.61,200,2,12.46,200,2,14.65,100,1,12.43,700,1,14.68,1400,2,12.42,700,1,14.81,300,3,12.37,700,1,15.12,100,1
2025-07-17T15:39:44.450806746Z,2025-07-17T15:39:44.450972330Z,160,2,1108,C,A,0,14.81,100,0,165584,248753673,ARL,296368709,13.26,100,1,13.95,2,1,13.04,2,1,14.05,100,1,13.03,100,1,14.4,100,1,12.73,100,1,14.56,900,3,12.71,100,1,14.6,700,1,12.5,700,1,14.61,200,2,12.46,200,2,14.65,100,1,12.43,700,1,14.68,1400,2,12.42,700,1,14.81,200,2,12.37,700,1,15.12,100,1
2025-07-17T15:39:44.450806746Z,2025-07-17T15:39:44.450972330Z,160,2,1108,A,A,0,15.06,100,130,165584,248753673,ARL,296478965,13.26,100,1,13.95,2,1,13.04,2,1,14.05,100,1,13.03,100,1,14.4,100,1,12.73,100,1,14.56,900,3,12.71,100,1,14.6,700,1,12.5,700,1,14.61,200,2,12.46,200,2,14.65,100,1,12.43,700,1,14.68,1400,2,12.42,700,1,14.81,200,2,12.37,700,1,15.06,100,1
2025-07-17T15:39:44.450910591Z,2025-07-17T15:39:44.451075992Z,160,2,1108,C,A,0,13.95,2,0,165401,248753678,ARL,287540393,13.26,100,1,14.05,100,1,13.04,2,1,14.4,100,1,13.03,100,1,14.56,900,3,12.73,100,1,14.6,700,1,12.71,100,1,14.61,200,2,12.5,700,1,14.65,100,1,12.46,200,2,14.68,1400,2,12.43,700,1,14.81,200,2,12.42,700,1,15.06,100,1,12.37,700,1,15.12,100,1
2025-07-17T15:39:44.450910591Z,2025-07-17T15:39:44.451075992Z,160,2,1108,A,A,0,14.07,2,130,165401,248753678,ARL,296478973,13.26,100,1,14.05,100,1,13.04,2,1,14.07,2,1,13.03,100,1,14.4,100,1,12.73,100,1,14.56,900,3,12.71,100,1,14.6,700,1,12.5,700,1,14.61,200,2,12.46,200,2,14.65,100,1,12.43,700,1,14.68,1400,2,12.42,700,1,14.81,200,2,12.37,700,1,15.06,100,1
2025-07-17T15:39:44.454964327Z,2025-07-17T15:39:44.455130297Z,160,2,1108,C,A,0,14.81,100,0,165970,248753748,ARL,286680741,13.26,100,1,14.05,100,1,13.04,2,1,14.07,2,1,13.03,100,1,14.4,100,1,12.73,100,1,14.56,900,3,12.71,100,1,14.6,700,1,12.5,700,1,14.61,200,2,12.46,200,2,14.65,100,1,12.43,700,1,14.68,1400,2,12.42,700,1,14.81,100,1,12.37,700,1,15.06,100,1
2025-07-17T15:39:44.454964327Z,2025-07-17T15:39:44.455130297Z,160,2,1108,A,A,0,14.96,100,130,165970,248753748,ARL,296479053,13.26,100,1,14.05,100,1,13.04,2,1,14.07,2,1,13.03,100,1,14.4,100,1,12.73,100,1,14.56,900,3,12.71,100,1,14.6,700,1,12.5,700,1,14.61,200,2,12.46,200,2,14.65,100,1,12.43,700,1,14.68,1400,2,12.42,700,1,14.81,100,1,12.37,700,1,14.96,100,1
2025-07-17T15:39:44.456122660Z,2025-07-17T15:39:44.456288062Z,160,2,1108,C,A,0,14.65,100,130,165402,248753812,ARL,286680905,13.26,100,1,14.05,100,1,13.04,2,1,14.07,2,1,13.03,100,1,14.4,100,1,12.73,100,1,14.56,900,3,12.71,100,1,14.6,700,1,12.5,700,1,14.61,200,2,12.46,200,2,14.68,1400,2,12.43,700,1,14.81,100,1,12.42,700,1,14.96,100,1,12.37,700,1,15.06,100,1
2025-07-17T15:39:44.456211953Z,2025-07-17T15:39:44.456377500Z,160,2,1108,A,A,0,14.78,100,130,165547,248753815,ARL,296479285,13.26,100,1,14.05,100,1,13.04,2,1,14.07,2,1,13.03,100,1,14.4,100,1,12.73,100,1,14.56,900,3,12.71,100,1,14.6,700,1,12.5,700,1,14.61,200,2,12.46,200,2,14.68,1400,2,12.43,700,1,14.78,100,1,12.42,700,1,14.81,100,1,12.37,700,1,14.96,100,1
2025-07-17T15:39:44.461889886Z,2025-07-17T15:39:44.462055094Z,160,2,1108,C,A,0,14.05,100,130,165208,248753947,ARL,296137769,13.26,100,1,14.07,2,1,13.04,2,1,14.4,100,1,13.03,100,1,14.56,900,3,12.73,100,1,14.6,700,1,12.71,100,1,14.61,200,2,12.5,700,1,14.68,1400,2,12.46,200,2,14.78,100,1,12.43,700,1,14.81,100,1,12.42,700,1,14.96,100,1,12.37,700,1,15.06,100,1
2025-07-17T15:39:44.461943584Z,2025-07-17T15:39:44.462108809Z,160,2,1108,A,A,0,14.26,100,130,165225,248753952,ARL,296479425,13.26,100,1,14.07,2,1,13.04,2,1,14.26,100,1,13.03,100,1,14.4,100,1,12.73,100,1,14.56,900,3,12.71,100,1,14.6,700,1,12.5,700,1,14.61,200,2,12.46,200,2,14.68,1400,2,12.43,700,1,14.78,100,1,12.42,700,1,14.81,100,1,12.37,700,1,14.96,100,1
2025-07-17T15:39:44.478757958Z,2025-07-17T15:39:44.478923366Z,160,2,1108,C,A,0,17.58,100,0,165408,248754361,ARL,286681057,13.26,100,1,14.07,2,1,13.04,2,1,14.26,100,1,13.03,100,1,14.4,100,1,12.73,100,1,14.56,900,3,12.71,100,1,14.6,700,1,12.5,700,1,14.61,200,2,12.46,200,2,14.68,1400,2,12.43,700,1,14.78,100,1,12.42,700,1,14.81,100,1,12.37,700,1,14.96,100,1
2025-07-17T15:39:44.478757958Z,2025-07-17T15:39:44.478923366Z,160,2,1108,A,A,0,17.76,100,130,165408,248754361,ARL,296479893,13.26,100,1,14.07,2,1,13.04,2,1,14.26,100,1,13.03,100,1,14.4,100,1,12.73,100,1,14.56,900,3,12.71,100,1,14.6,700,1,12.5,700,1,14.61,200,2,12.46,200,2,14.68,1400,2,12.43,700,1,14.78,100,1,12.42,700,1,14.81,100,1,12.37,700,1,14.96,100,1
2025-07-17T15:39:44.490852860Z,2025-07-17T15:39:44.491018431Z,160,2,1108,C,A,0,15.92,100,0,165571,248754608,ARL,286681229,13.26,100,1,14.07,2,1,13.04,2,1,14.26,100,1,13.03,100,1,14.4,100,1,12.73,100,1,14.56,900,3,12.71,100,1,14.6,700,1,12.5,700,1,14.61,200,2,12.46,200,2,14.68,1400,2,12.43,700,1,14.78,100,1,12.42,700,1,14.81,100,1,12.37,700,1,14.96,100,1
2025-07-17T15:39:44.490852860Z,2025-07-17T15:39:44.491018431Z,160,2,1108,A,A,0,16.08,100,130,165571,248754608,ARL,296480097,13.26,100,1,14.07,2,1,13.04,2,1,14.26,100,1,13.03,100,1,14.4,100,1,12.73,100,1,14.56,900,3,12.71,100,1,14.6,700,1,12.5,700,1,14.61,200,2,12.46,200,2,14.68,1400,2,12.43,700,1,14.78,100,1,12.42,700,1,14.81,100,1,12.37,700,1,14.96,100,1
2025-07-17T15:39:44.593607433Z,2025-07-17T15:39:44.593773213Z,160,2,1108,C,A,0,14.81,100,0,165780,248756227,ARL,286684005,13.26,100,1,14.07,2,1,13.04,2,1,14.26,100,1,13.03,100,1,14.4,100,1,12.73,100,1,14.56,900,3,12.71,100,1,14.6,700,1,12.5,700,1,14.61,200,2,12.46,200,2,14.68,1400,2,12.43,700,1,14.78,100,1,12.42,700,1,14.96,100,1,12.37,700,1,15.06,100,1
2025-07-17T15:39:44.593607433Z,2025-07-17T15:39:44.593773213Z,160,2,1108,A,A,0,14.96,100,130,165780,248756227,ARL,296482509,13.26,100,1,14.07,2,1,13.04,2,1,14.26,100,1,13.03,100,1,14.4,100,1,12.73,100,1,14.56,900,3,12.71,100,1,14.6,700,1,12.5,700,1,14.61,200,2,12.46,200,2,14.68,1400,2,12.43,700,1,14.78,100,1,12.42,700,1,14.96,200,2,12.37,700,1,15.06,100,1
2025-07-17T15:39:44.859720946Z,2025-07-17T15:39:44.859886562Z,160,2,1108,C,A,0,14.61,100,0,165616,248760319,ARL,296455041,13.26,100,1,14.07,2,1,13.04,2,1,14.26,100,1,13.03,100,1,14.4,100,1,12.73,100,1,14.56,900,3,12.71,100,1,14.6,700,1,12.5,700,1,14.61,100,1,12.46,200,2,14.68,1400,2,12.43,700,1,14.78,100,1,12.42,700,1,14.96,200,2,12.37,700,1,15.06,100,1
2025-07-17T15:39:44.859720946Z,2025-07-17T15:39:44.859886562Z,160,2,1108,A,A,0,15.1,100,130,165616,248760319,ARL,296485621,13.26,100,1,14.07,2,1,13.04,2,1,14.26,100,1,13.03,100,1,14.4,100,1,12.73,100,1,14.56,900,3,12.71,100,1,14.6,700,1,12.5,700,1,14.61,100,1,12.46,200,2,14.68,1400,2,12.43,700,1,14.78,100,1,12.42,700,1,14.96,200,2,12.37,700,1,15.06,100,1
2025-07-17T15:39:44.859994671Z,2025-07-17T15:39:44.860160096Z,160,2,1108,A,A,0,14.08,100,130,165425,248760324,ARL,296485629,13.26,100,1,14.07,2,1,13.04,2,1,14.08,100,1,13.03,100,1,14.26,100,1,12.73,100,1,14.4,100,1,12.71,100,1,14.56,900,3,12.5,700,1,14.6,700,1,12.46,200,2,14.61,100,1,12.43,700,1,14.68,1400,2,12.42,700,1,14.78,100,1,12.37,700,1,14.96,200,2
2025-07-17T15:39:44.863513587Z,2025-07-17T15:39:44.863678795Z,160,2,1108,C,A,0,14.61,100,0,165208,248760417,ARL,296455037,13.26,100,1,14.07,2,1,13.04,2,1,14.08,100,1,13.03,100,1,14.26,100,1,12.73,100,1,14.4,100,1,12.71,100,1,14.56,900,3,12.5,700,1,14.6,700,1,12.46,200,2,14.68,1400,2,12.43,700,1,14.78,100,1,12.42,700,1,14.96,200,2,12.37,700,1,15.06,100,1
2025-07-17T15:39:44.863513587Z,2025-07-17T15:39:44.863678795Z,160,2,1108,A,A,0,15.1,100,130,165208,248760417,ARL,296485649,13.26,100,1,14.07,2,1,13.04,2,1,14.08,100,1,13.03,100,1,14.26,100,1,12.73,100,1,14.4,100,1,12.71,100,1,14.56,900,3,12.5,700,1,14.6,700,1,12.46,200,2,14.68,1400,2,12.43,700,1,14.78,100,1,12.42,700,1,14.96,200,2,12.37,700,1,15.06,100,1
2025-07-17T15:39:54.186842327Z,2025-07-17T15:39:54.187008224Z,160,2,1108,C,A,0,15.1,100,0,165897,248915116,ARL,296485649,13.26,100,1,14.07,2,1,13.04,2,1,14.08,100,1,13.03,100,1,14.26,100,1,12.73,100,1,14.4,100,1,12.71,100,1,14.56,900,3,12.5,700,1,14.6,700,1,12.46,200,2,14.68,1400,2,12.43,700,1,14.78,100,1,12.42,700,1,14.96,200,2,12.37,700,1,15.06,100,1
2025-07-17T15:39:54.186842327Z,2025-07-17T15:39:54.187008224Z,160,2,1108,A,A,0,14.88,100,130,165897,248915116,ARL,296679277,13.26,100,1,14.07,2,1,13.04,2,1,14.08,100,1,13.03,100,1,14.26,100,1,12.73,100,1,14.4,100,1,12.71,100,1,14.56,900,3,12.5,700,1,14.6,700,1,12.46,200,2,14.68,1400,2,12.43,700,1,14.78,100,1,12.42,700,1,14.88,100,1,12.37,700,1,14.96,200,2
2025-07-17T15:39:54.187391707Z,2025-07-17T15:39:54.187557412Z,160,2,1108,C,A,0,15.1,100,0,165705,248915126,ARL,296485621,13.26,100,1,14.07,2,1,13.04,2,1,14.08,100,1,13.03,100,1,14.26,100,1,12.73,100,1,14.4,100,1,12.71,100,1,14.56,900,3,12.5,700,1,14.6,700,1,12.46,200,2,14.68,1400,2,12.43,700,1,14.78,100,1,12.42,700,1,14.88,100,1,12.37,700,1,14.96,200,2
2025-07-17T15:39:54.187391707Z,2025-07-17T15:39:54.187557412Z,160,2,1108,A,A,0,14.88,100,130,165705,248915126,ARL,296679285,13.26,100,1,14.07,2,1,13.04,2,1,14.08,100,1,13.03,100,1,14.26,100,1,12.73,100,1,14.4,100,1,12.71,100,1,14.56,900,3,12.5,700,1,14.6,700,1,12.46,200,2,14.68,1400,2,12.43,700,1,14.78,100,1,12.42,700,1,14.88,200,2,12.37,700,1,14.96,200,2
2025-07-17T15:42:06.780337543Z,2025-07-17T15:42:06.780503054Z,160,2,1108,A,A,0,13.9,15,130,165511,251407709,ARL,299689753,13.26,100,1,13.9,15,1,13.04,2,1,14.07,2,1,13.03,100,1,14.08,100,1,12.73,100,1,14.26,100,1,12.71,100,1,14.4,100,1,12.5,700,1,14.56,900,3,12.46,200,2,14.6,700,1,12.43,700,1,14.68,1400,2,12.42,700,1,14.78,100,1,12.37,700,1,14.88,200,2
2025-07-17T15:42:06.780602350Z,2025-07-17T15:42:06.780767761Z,160,2,1108,C,A,0,14.08,100,0,165411,251407713,ARL,296485629,13.26,100,1,13.9,15,1,13.04,2,1,14.07,2,1,13.03,100,1,14.26,100,1,12.73,100,1,14.4,100,1,12.71,100,1,14.56,900,3,12.5,700,1,14.6,700,1,12.46,200,2,14.68,1400,2,12.43,700,1,14.78,100,1,12.42,700,1,14.88,200,2,12.37,700,1,14.96,200,2
2025-07-17T15:42:06.780602350Z,2025-07-17T15:42:06.780767761Z,160,2,1108,A,A,0,13.91,100,130,165411,251407713,ARL,299689769,13.26,100,1,13.9,15,1,13.04,2,1,13.91,100,1,13.03,100,1,14.07,2,1,12.73,100,1,14.26,100,1,12.71,100,1,14.4,100,1,12.5,700,1,14.56,900,3,12.46,200,2,14.6,700,1,12.43,700,1,14.68,1400,2,12.42,700,1,14.78,100,1,12.37,700,1,14.88,200,2
2025-07-17T15:42:06.781336642Z,2025-07-17T15:42:06.781502831Z,160,2,1108,C,A,0,15.06,100,0,166189,251407747,ARL,296478965,13.26,100,1,13.9,15,1,13.04,2,1,13.91,100,1,13.03,100,1,14.07,2,1,12.73,100,1,14.26,100,1,12.71,100,1,14.4,100,1,12.5,700,1,14.56,900,3,12.46,200,2,14.6,700,1,12.43,700,1,14.68,1400,2,12.42,700,1,14.78,100,1,12.37,700,1,14.88,200,2
2025-07-17T15:42:06.781336642Z,2025-07-17T15:42:06.781502831Z,160,2,1108,A,A,0,14.99,100,130,166189,251407747,ARL,299689857,13.26,100,1,13.9,15,1,13.04,2,1,13.91,100,1,13.03,100,1,14.07,2,1,12.73,100,1,14.26,100,1,12.71,100,1,14.4,100,1,12.5,700,1,14.56,900,3,12.46,200,2,14.6,700,1,12.43,700,1,14.68,1400,2,12.42,700,1,14.78,100,1,12.37,700,1,14.88,200,2
2025-07-17T15:42:06.795355762Z,2025-07-17T15:42:06.795521307Z,160,2,1108,C,A,0,14.26,100,130,165545,251408268,ARL,296479425,13.26,100,1,13.9,15,1,13.04,2,1,13.91,100,1,13.03,100,1,14.07,2,1,12.73,100,1,14.4,100,1,12.71,100,1,14.56,900,3,12.5,700,1,14.6,700,1,12.46,200,2,14.68,1400,2,12.43,700,1,14.78,100,1,12.42,700,1,14.88,200,2,12.37,700,1,14.96,200,2
2025-07-17T15:42:06.795408057Z,2025-07-17T15:42:06.795573392Z,160,2,1108,A,A,0,14.19,100,130,165335,251408269,ARL,299690593,13.26,100,1,13.9,15,1,13.04,2,1,13.91,100,1,13.03,100,1,14.07,2,1,12.73,100,1,14.19,100,1,12.71,100,1,14.4,100,1,12.5,700,1,14.56,900,3,12.46,200,2,14.6,700,1,12.43,700,1,14.68,1400,2,12.42,700,1,14.78,100,1,12.37,700,1,14.88,200,2
2025-07-17T15:42:16.263966448Z,2025-07-17T15:42:16.264132159Z,160,2,1108,C,A,0,14.88,100,0,165711,251574391,ARL,296679285,13.26,100,1,13.9,15,1,13.04,2,1,13.91,100,1,13.03,100,1,14.07,2,1,12.73,100,1,14.19,100,1,12.71,100,1,14.4,100,1,12.5,700,1,14.56,900,3,12.46,200,2,14.6,700,1,12.43,700,1,14.68,1400,2,12.42,700,1,14.78,100,1,12.37,700,1,14.88,100,1
2025-07-17T15:42:16.263966448Z,2025-07-17T15:42:16.264132159Z,160,2,1108,A,A,0,14.76,100,130,165711,251574391,ARL,299903169,13.26,100,1,13.9,15,1,13.04,2,1,13.91,100,1,13.03,100,1,14.07,2,1,12.73,100,1,14.19,100,1,12.71,100,1,14.4,100,1,12.5,700,1,14.56,900,3,12.46,200,2,14.6,700,1,12.43,700,1,14.68,1400,2,12.42,700,1,14.76,100,1,12.37,700,1,14.78,100,1
2025-07-17T15:42:17.356601231Z,2025-07-17T15:42:17.356766715Z,160,2,1108,A,A,0,13.83,15,130,165484,251593608,ARL,299923773,13.26,100,1,13.83,15,1,13.04,2,1,13.9,15,1,13.03,100,1,13.91,100,1,12.73,100,1,14.07,2,1,12.71,100,1,14.19,100,1,12.5,700,1,14.4,100,1,12.46,200,2,14.56,900,3,12.43,700,1,14.6,700,1,12.42,700,1,14.68,1400,2,12.37,700,1,14.76,100,1
2025-07-17T15:42:17.577308779Z,2025-07-17T15:42:17.577474246Z,160,2,1108,C,A,0,13.91,100,0,165467,251595553,ARL,299689769,13.26,100,1,13.83,15,1,13.04,2,1,13.9,15,1,13.03,100,1,14.07,2,1,12.73,100,1,14.19,100,1,12.71,100,1,14.4,100,1,12.5,700,1,14.56,900,3,12.46,200,2,14.6,700,1,12.43,700,1,14.68,1400,2,12.42,700,1,14.76,100,1,12.37,700,1,14.78,100,1
2025-07-17T15:42:17.577308779Z,2025-07-17T15:42:17.577474246Z,160,2,1108,A,A,0,13.84,100,130,165467,251595553,ARL,299926781,13.26,100,1,13.83,15,1,13.04,2,1,13.84,100,1,13.03,100,1,13.9,15,1,12.73,100,1,14.07,2,1,12.71,100,1,14.19,100,1,12.5,700,1,14.4,100,1,12.46,200,2,14.56,900,3,12.43,700,1,14.6,700,1,12.42,700,1,14.68,1400,2,12.37,700,1,14.76,100,1
2025-07-17T15:42:17.578053644Z,2025-07-17T15:42:17.578219175Z,160,2,1108,C,A,0,14.99,100,0,165531,251595563,ARL,299689857,13.26,100,1,13.83,15,1,13.04,2,1,13.84,100,1,13.03,100,1,13.9,15,1,12.73,100,1,14.07,2,1,12.71,100,1,14.19,100,1,12.5,700,1,14.4,100,1,12.46,200,2,14.56,900,3,12.43,700,1,14.6,700,1,12.42,700,1,14.68,1400,2,12.37,700,1,14.76,100,1
2025-07-17T15:42:17.578053644Z,2025-07-17T15:42:17.578219175Z,160,2,1108,A,A,0,14.91,100,130,165531,251595563,ARL,299926801,13.26,100,1,13.83,15,1,13.04,2,1,13.84,100,1,13.03,100,1,13.9,15,1,12.73,100,1,14.07,2,1,12.71,100,1,14.19,100,1,12.5,700,1,14.4,100,1,12.46,200,2,14.56,900,3,12.43,700,1,14.6,700,1,12.42,700,1,14.68,1400,2,12.37,700,1,14.76,100,1
2025-07-17T15:42:17.579177582Z,2025-07-17T15:42:17.579343189Z,160,2,1108,C,A,0,14.78,100,0,165607,251595571,ARL,296479285,13.26,100,1,13.83,15,1,13.04,2,1,13.84,100,1,13.03,100,1,13.9,15,1,12.73,100,1,14.07,2,1,12.71,100,1,14.19,100,1,12.5,700,1,14.4,100,1,12.46,200,2,14.56,900,3,12.43,700,1,14.6,700,1,12.42,700,1,14.68,1400,2,12.37,700,1,14.76,100,1
2025-07-17T15:42:17.579177582Z,2025-07-17T15:42:17.579343189Z,160,2,1108,A,A,0,14.64,100,130,165607,251595571,ARL,299926813,13.26,100,1,13.83,15,1,13.04,2,1,13.84,100,1,13.03,100,1,13.9,15,1,12.73,100,1,14.07,2,1,12.71,100,1,14.19,100,1,12.5,700,1,14.4,100,1,12.46,200,2,14.56,900,3,12.43,700,1,14.6,700,1,12.42,700,1,14.64,100,1,12.37,700,1,14.68,1400,2
2025-07-17T15:42:17.579843331Z,2025-07-17T15:42:17.580008869Z,160,2,1108,C,A,0,14.96,100,0,165538,251595576,ARL,296479053,13.26,100,1,13.83,15,1,13.04,2,1,13.84,100,1,13.03,100,1,13.9,15,1,12.73,100,1,14.07,2,1,12.71,100,1,14.19,100,1,12.5,700,1,14.4,100,1,12.46,200,2,14.56,900,3,12.43,700,1,14.6,700,1,12.42,700,1,14.64,100,1,12.37,700,1,14.68,1400,2
2025-07-17T15:42:17.579843331Z,2025-07-17T15:42:17.580008869Z,160,2,1108,A,A,0,14.81,100,130,165538,251595576,ARL,299926849,13.26,100,1,13.83,15,1,13.04,2,1,13.84,100,1,13.03,100,1,13.9,15,1,12.73,100,1,14.07,2,1,12.71,100,1,14.19,100,1,12.5,700,1,14.4,100,1,12.46,200,2,14.56,900,3,12.43,700,1,14.6,700,1,12.42,700,1,14.64,100,1,12.37,700,1,14.68,1400,2
2025-07-17T15:42:17.579870309Z,2025-07-17T15:42:17.580035793Z,160,2,1108,C,A,0,16.08,100,0,165484,251595577,ARL,296480097,13.26,100,1,13.83,15,1,13.04,2,1,13.84,100,1,13.03,100,1,13.9,15,1,12.73,100,1,14.07,2,1,12.71,100,1,14.19,100,1,12.5,700,1,14.4,100,1,12.46,200,2,14.56,900,3,12.43,700,1,14.6,700,1,12.42,700,1,14.64,100,1,12.37,700,1,14.68,1400,2
2025-07-17T15:42:17.579870309Z,2025-07-17T15:42:17.580035793Z,160,2,1108,A,A,0,15.92,100,130,165484,251595577,ARL,299926853,13.26,100,1,13.83,15,1,13.04,2,1,13.84,100,1,13.03,100,1,13.9,15,1,12.73,100,1,14.07,2,1,12.71,100,1,14.19,100,1,12.5,700,1,14.4,100,1,12.46,200,2,14.56,900,3,12.43,700,1,14.6,700,1,12.42,700,1,14.64,100,1,12.37,700,1,14.68,1400,2
2025-07-17T15:42:17.579895610Z,2025-07-17T15:42:17.580061097Z,160,2,1108,C,A,0,14.96,100,0,165487,251595578,ARL,296482509,13.26,100,1,13.83,15,1,13.04,2,1,13.84,100,1,13.03,100,1,13.9,15,1,12.73,100,1,14.07,2,1,12.71,100,1,14.19,100,1,12.5,700,1,14.4,100,1,12.46,200,2,14.56,900,3,12.43,700,1,14.6,700,1,12.42,700,1,14.64,100,1,12.37,700,1,14.68,1400,2
2025-07-17T15:42:17.579895610Z,2025-07-17T15:42:17.580061097Z,160,2,1108,A,A,0,14.81,100,130,165487,251595578,ARL,299926857,13.26,100,1,13.83,15,1,13.04,2,1,13.84,100,1,13.03,100,1,13.9,15,1,12.73,100,1,14.07,2,1,12.71,100,1,14.19,100,1,12.5,700,1,14.4,100,1,12.46,200,2,14.56,900,3,12.43,700,1,14.6,700,1,12.42,700,1,14.64,100,1,12.37,700,1,14.68,1400,2
2025-07-17T15:42:17.579928136Z,2025-07-17T15:42:17.580093535Z,160,2,1108,C,A,0,17.76,100,0,165399,251595580,ARL,296479893,13.26,100,1,13.83,15,1,13.04,2,1,13.84,100,1,13.03,100,1,13.9,15,1,12.73,100,1,14.07,2,1,12.71,100,1,14.19,100,1,12.5,700,1,14.4,100,1,12.46,200,2,14.56,900,3,12.43,700,1,14.6,700,1,12.42,700,1,14.64,100,1,12.37,700,1,14.68,1400,2
2025-07-17T15:42:17.579928136Z,2025-07-17T15:42:17.580093535Z,160,2,1108,A,A,0,17.58,100,130,165399,251595580,ARL,299926861,13.26,100,1,13.83,15,1,13.04,2,1,13.84,100,1,13.03,100,1,13.9,15,1,12.73,100,1,14.07,2,1,12.71,100,1,14.19,100,1,12.5,700,1,14.4,100,1,12.46,200,2,14.56,900,3,12.43,700,1,14.6,700,1,12.42,700,1,14.64,100,1,12.37,700,1,14.68,1400,2
2025-07-17T15:42:17.589098227Z,2025-07-17T15:42:17.589263550Z,160,2,1108,C,A,0,14.19,100,130,165323,251595691,ARL,299690593,13.26,100,1,13.83,15,1,13.04,2,1,13.84,100,1,13.03,100,1,13.9,15,1,12.73,100,1,14.07,2,1,12.71,100,1,14.4,100,1,12.5,700,1,14.56,900,3,12.46,200,2,14.6,700,1,12.43,700,1,14.64,100,1,12.42,700,1,14.68,1400,2,12.37,700,1,14.76,100,1
2025-07-17T15:42:17.589151325Z,2025-07-17T15:42:17.589316911Z,160,2,1108,A,A,0,14.12,100,130,165586,251595692,ARL,299926965,13.26,100,1,13.83,15,1,13.04,2,1,13.84,100,1,13.03,100,1,13.9,15,1,12.73,100,1,14.07,2,1,12.71,100,1,14.12,100,1,12.5,700,1,14.4,100,1,12.46,200,2,14.56,900,3,12.43,700,1,14.6,700,1,12.42,700,1,14.64,100,1,12.37,700,1,14.68,1400,2
2025-07-17T15:42:18.398054465Z,2025-07-17T15:42:18.398220000Z,160,2,1108,C,A,0,14.88,100,0,165535,251612478,ARL,296679277,13.26,100,1,13.83,15,1,13.04,2,1,13.84,100,1,13.03,100,1,13.9,15,1,12.73,100,1,14.07,2,1,12.71,100,1,14.12,100,1,12.5,700,1,14.4,100,1,12.46,200,2,14.56,900,3,12.43,700,1,14.6,700,1,12.42,700,1,14.64,100,1,12.37,700,1,14.68,1400,2
2025-07-17T15:42:18.398054465Z,2025-07-17T15:42:18.398220000Z,160,2,1108,A,A,0,14.73,100,130,165535,251612478,ARL,299945073,13.26,100,1,13.83,15,1,13.04,2,1,13.84,100,1,13.03,100,1,13.9,15,1,12.73,100,1,14.07,2,1,12.71,100,1,14.12,100,1,12.5,700,1,14.4,100,1,12.46,200,2,14.56,900,3,12.43,700,1,14.6,700,1,12.42,700,1,14.64,100,1,12.37,700,1,14.68,1400,2
2025-07-17T15:42:21.517706139Z,2025-07-17T15:42:21.517871714Z,160,2,1108,C,A,0,13.9,15,130,165575,251668179,ARL,299689753,13.26,100,1,13.83,15,1,13.04,2,1,13.84,100,1,13.03,100,1,14.07,2,1,12.73,100,1,14.12,100,1,12.71,100,1,14.4,100,1,12.5,700,1,14.56,900,3,12.46,200,2,14.6,700,1,12.43,700,1,14.64,100,1,12.42,700,1,14.68,1400,2,12.37,700,1,14.73,100,1
2025-07-17T15:42:22.522578675Z,2025-07-17T15:42:22.522744242Z,160,2,1108,A,A,0,13.79,15,130,165567,251690950,ARL,300042293,13.26,100,1,13.79,15,1,13.04,2,1,13.83,15,1,13.03,100,1,13.84,100,1,12.73,100,1,14.07,2,1,12.71,100,1,14.12,100,1,12.5,700,1,14.4,100,1,12.46,200,2,14.56,900,3,12.43,700,1,14.6,700,1,12.42,700,1,14.64,100,1,12.37,700,1,14.68,1400,2
2025-07-17T15:42:22.533515955Z,2025-07-17T15:42:22.533681479Z,160,2,1108,A,A,0,13.82,100,130,165524,251691033,ARL,300042385,13.26,100,1,13.79,15,1,13.04,2,1,13.82,100,1,13.03,100,1,13.83,15,1,12.73,100,1,13.84,100,1,12.71,100,1,14.07,2,1,12.5,700,1,14.12,100,1,12.46,200,2,14.4,100,1,12.43,700,1,14.56,900,3,12.42,700,1,14.6,700,1,12.37,700,1,14.64,100,1
2025-07-17T15:42:23.490079821Z,2025-07-17T15:42:23.490247121Z,160,2,1108,C,A,0,13.84,100,0,167300,251710173,ARL,299926781,13.26,100,1,13.79,15,1,13.04,2,1,13.82,100,1,13.03,100,1,13.83,15,1,12.73,100,1,14.07,2,1,12.71,100,1,14.12,100,1,12.5,700,1,14.4,100,1,12.46,200,2,14.56,900,3,12.43,700,1,14.6,700,1,12.42,700,1,14.64,100,1,12.37,700,1,14.68,1400,2
2025-07-17T15:42:23.490079821Z,2025-07-17T15:42:23.490247121Z,160,2,1108,A,A,0,13.8,100,128,167300,251710173,ARL,300061581,13.26,100,1,13.79,15,1,13.04,2,1,13.8,100,1,13.03,100,1,13.82,100,1,12.73,100,1,13.83,15,1,12.71,100,1,14.07,2,1,12.5,700,1,14.12,100,1,12.46,200,2,14.4,100,1,12.43,700,1,14.56,900,3,12.42,700,1,14.6,700,1,12.37,700,1,14.64,100,1
2025-07-17T15:42:23.491285065Z,2025-07-17T15:42:23.491451368Z,160,2,1108,C,A,0,14.91,100,0,166303,251710647,ARL,299926801,13.26,100,1,13.79,15,1,13.04,2,1,13.8,100,1,13.03,100,1,13.82,100,1,12.73,100,1,13.83,15,1,12.71,100,1,14.07,2,1,12.5,700,1,14.12,100,1,12.46,200,2,14.4,100,1,12.43,700,1,14.56,900,3,12.42,700,1,14.6,700,1,12.37,700,1,14.64,100,1
2025-07-17T15:42:23.491285065Z,2025-07-17T15:42:23.491451368Z,160,2,1108,A,A,0,14.87,100,128,166303,251710647,ARL,300061989,13.26,100,1,13.79,15,1,13.04,2,1,13.8,100,1,13.03,100,1,13.82,100,1,12.73,100,1,13.83,15,1,12.71,100,1,14.07,2,1,12.5,700,1,14.12,100,1,12.46,200,2,14.4,100,1,12.43,700,1,14.56,900,3,12.42,700,1,14.6,700,1,12.37,700,1,14.64,100,1
2025-07-17T15:42:23.588899941Z,2025-07-17T15:42:23.589065154Z,160,2,1108,C,A,0,13.79,15,130,165213,251718746,ARL,300042293,13.26,100,1,13.8,100,1,13.04,2,1,13.82,100,1,13.03,100,1,13.83,15,1,12.73,100,1,14.07,2,1,12.71,100,1,14.12,100,1,12.5,700,1,14.4,100,1,12.46,200,2,14.56,900,3,12.43,700,1,14.6,700,1,12.42,700,1,14.64,100,1,12.37,700,1,14.68,1400,2
2025-07-17T15:42:23.589055082Z,2025-07-17T15:42:23.589220778Z,160,2,1108,C,A,0,13.83,15,130,165696,251718767,ARL,299923773,13.26,100,1,13.8,100,1,13.04,2,1,13.82,100,1,13.03,100,1,14.07,2,1,12.73,100,1,14.12,100,1,12.71,100,1,14.4,100,1,12.5,700,1,14.56,900,3,12.46,200,2,14.6,700,1,12.43,700,1,14.64,100,1,12.42,700,1,14.68,1400,2,12.37,700,1,14.73,100,1
2025-07-17T15:42:34.003544527Z,2025-07-17T15:42:34.003710081Z,160,2,1108,C,A,0,13.8,100,130,165554,251901273,ARL,300061581,13.26,100,1,13.82,100,1,13.04,2,1,14.07,2,1,13.03,100,1,14.12,100,1,12.73,100,1,14.4,100,1,12.71,100,1,14.56,900,3,12.5,700,1,14.6,700,1,12.46,200,2,14.64,100,1,12.43,700,1,14.68,1400,2,12.42,700,1,14.73,100,1,12.37,700,1,14.76,100,1
2025-07-17T15:42:34.003783950Z,2025-07-17T15:42:34.003949340Z,160,2,1108,C,A,0,13.82,100,130,165390,251901275,ARL,300042385,13.26,100,1,14.07,2,1,13.04,2,1,14.12,100,1,13.03,100,1,14.4,100,1,12.73,100,1,14.56,900,3,12.71,100,1,14.6,700,1,12.5,700,1,14.64,100,1,12.46,200,2,14.68,1400,2,12.43,700,1,14.73,100,1,12.42,700,1,14.76,100,1,12.37,700,1,14.81,200,2
2025-07-17T15:42:34.004059450Z,2025-07-17T15:42:34.004225180Z,160,2,1108,C,A,0,14.73,100,0,165730,251901280,ARL,299945073,13.26,100,1,14.07,2,1,13.04,2,1,14.12,100,1,13.03,100,1,14.4,100,1,12.73,100,1,14.56,900,3,12.71,100,1,14.6,700,1,12.5,700,1,14.64,100,1,12.46,200,2,14.68,1400,2,12.43,700,1,14.76,100,1,12.42,700,1,14.81,200,2,12.37,700,1,14.87,100,1
2025-07-17T15:42:34.004059450Z,2025-07-17T15:42:34.004225180Z,160,2,1108,A,A,0,14.88,100,130,165730,251901280,ARL,300280745,13.26,100,1,14.07,2,1,13.04,2,1,14.12,100,1,13.03,100,1,14.4,100,1,12.73,100,1,14.56,900,3,12.71,100,1,14.6,700,1,12.5,700,1,14.64,100,1,12.46,200,2,14.68,1400,2,12.43,700,1,14.76,100,1,12.42,700,1,14.81,200,2,12.37,700,1,14.87,100,1
2025-07-17T15:42:34.004506043Z,2025-07-17T15:42:34.004671652Z,160,2,1108,C,A,0,14.87,100,0,165609,251901285,ARL,300061989,13.26,100,1,14.07,2,1,13.04,2,1,14.12,100,1,13.03,100,1,14.4,100,1,12.73,100,1,14.56,900,3,12.71,100,1,14.6,700,1,12.5,700,1,14.64,100,1,12.46,200,2,14.68,1400,2,12.43,700,1,14.76,100,1,12.42,700,1,14.81,200,2,12.37,700,1,14.88,100,1
2025-07-17T15:42:34.004506043Z,2025-07-17T15:42:34.004671652Z,160,2,1108,A,A,0,15.06,100,130,165609,251901285,ARL,300280757,13.26,100,1,14.07,2,1,13.04,2,1,14.12,100,1,13.03,100,1,14.4,100,1,12.73,100,1,14.56,900,3,12.71,100,1,14.6,700,1,12.5,700,1,14.64,100,1,12.46,200,2,14.68,1400,2,12.43,700,1,14.76,100,1,12.42,700,1,14.81,200,2,12.37,700,1,14.88,100,1
2025-07-17T15:42:34.004512153Z,2025-07-17T15:42:34.004677786Z,160,2,1108,C,A,0,14.76,100,0,165633,251901286,ARL,299903169,13.26,100,1,14.07,2,1,13.04,2,1,14.12,100,1,13.03,100,1,14.4,100,1,12.73,100,1,14.56,900,3,12.71,100,1,14.6,700,1,12.5,700,1,14.64,100,1,12.46,200,2,14.68,1400,2,12.43,700,1,14.81,200,2,12.42,700,1,14.88,100,1,12.37,700,1,15.06,100,1
2025-07-17T15:42:34.004512153Z,2025-07-17T15:42:34.004677786Z,160,2,1108,A,A,0,14.88,100,130,165633,251901286,ARL,300280761,13.26,100,1,14.07,2,1,13.04,2,1,14.12,100,1,13.03,100,1,14.4,100,1,12.73,100,1,14.56,900,3,12.71,100,1,14.6,700,1,12.5,700,1,14.64,100,1,12.46,200,2,14.68,1400,2,12.43,700,1,14.81,200,2,12.42,700,1,14.88,200,2,12.37,700,1,15.06,100,1
2025-07-17T15:42:34.005409139Z,2025-07-17T15:42:34.005574760Z,160,2,1108,C,A,0,15.92,100,0,165621,251901302,ARL,299926853,13.26,100,1,14.07,2,1,13.04,2,1,14.12,100,1,13.03,100,1,14.4,100,1,12.73,100,1,14.56,900,3,12.71,100,1,14.6,700,1,12.5,700,1,14.64,100,1,12.46,200,2,14.68,1400,2,12.43,700,1,14.81,200,2,12.42,700,1,14.88,200,2,12.37,700,1,15.06,100,1
2025-07-17T15:42:34.005409139Z,2025-07-17T15:42:34.005574760Z,160,2,1108,A,A,0,16.08,100,130,165621,251901302,ARL,300280773,13.26,100,1,14.07,2,1,13.04,2,1,14.12,100,1,13.03,100,1,14.4,100,1,12.73,100,1,14.56,900,3,12.71,100,1,14.6,700,1,12.5,700,1,14.64,100,1,12.46,200,2,14.68,1400,2,12.43,700,1,14.81,200,2,12.42,700,1,14.88,200,2,12.37,700,1,15.06,100,1
2025-07-17T15:42:34.005667449Z,2025-07-17T15:42:34.005832926Z,160,2,1108,C,A,0,14.81,100,0,165477,251901305,ARL,299926849,13.26,100,1,14.07,2,1,13.04,2,1,14.12,100,1,13.03,100,1,14.4,100,1,12.73,100,1,14.56,900,3,12.71,100,1,14.6,700,1,12.5,700,1,14.64,100,1,12.46,200,2,14.68,1400,2,12.43,700,1,14.81,100,1,12.42,700,1,14.88,200,2,12.37,700,1,15.06,100,1
2025-07-17T15:42:34.005667449Z,2025-07-17T15:42:34.005832926Z,160,2,1108,A,A,0,14.96,100,130,165477,251901305,ARL,300280777,13.26,100,1,14.07,2,1,13.04,2,1,14.12,100,1,13.03,100,1,14.4,100,1,12.73,100,1,14.56,900,3,12.71,100,1,14.6,700,1,12.5,700,1,14.64,100,1,12.46,200,2,14.68,1400,2,12.43,700,1,14.81,100,1,12.42,700,1,14.88,200,2,12.37,700,1,14.96,100,1
2025-07-17T15:42:34.006665512Z,2025-07-17T15:42:34.006831024Z,160,2,1108,C,A,0,17.58,100,0,165512,251901319,ARL,299926861,13.26,100,1,14.07,2,1,13.04,2,1,14.12,100,1,13.03,100,1,14.4,100,1,12.73,100,1,14.56,900,3,12.71,100,1,14.6,700,1,12.5,700,1,14.64,100,1,12.46,200,2,14.68,1400,2,12.43,700,1,14.81,100,1,12.42,700,1,14.88,200,2,12.37,700,1,14.96,100,1
2025-07-17T15:42:34.006665512Z,2025-07-17T15:42:34.006831024Z,160,2,1108,A,A,0,17.76,100,130,165512,251901319,ARL,300280797,13.26,100,1,14.07,2,1,13.04,2,1,14.12,100,1,13.03,100,1,14.4,100,1,12.73,100,1,14.56,900,3,12.71,100,1,14.6,700,1,12.5,700,1,14.64,100,1,12.46,200,2,14.68,1400,2,12.43,700,1,14.81,100,1,12.42,700,1,14.88,200,2,12.37,700,1,14.96,100,1
2025-07-17T15:42:34.007743383Z,2025-07-17T15:42:34.007908678Z,160,2,1108,C,A,0,14.64,100,130,165295,251901330,ARL,299926813,13.26,100,1,14.07,2,1,13.04,2,1,14.12,100,1,13.03,100,1,14.4,100,1,12.73,100,1,14.56,900,3,12.71,100,1,14.6,700,1,12.5,700,1,14.68,1400,2,12.46,200,2,14.81,100,1,12.43,700,1,14.88,200,2,12.42,700,1,14.96,100,1,12.37,700,1,15.06,100,1
2025-07-17T15:42:34.007907269Z,2025-07-17T15:42:34.008072663Z,160,2,1108,A,A,0,14.78,100,130,165394,251901331,ARL,300280825,13.26,100,1,14.07,2,1,13.04,2,1,14.12,100,1,13.03,100,1,14.4,100,1,12.73,100,1,14.56,900,3,12.71,100,1,14.6,700,1,12.5,700,1,14.68,1400,2,12.46,200,2,14.78,100,1,12.43,700,1,14.81,100,1,12.42,700,1,14.88,200,2,12.37,700,1,14.96,100,1
2025-07-17T15:42:34.010031518Z,2025-07-17T15:42:34.010196831Z,160,2,1108,C,A,0,14.12,100,130,165313,251901352,ARL,299926965,13.26,100,1,14.07,2,1,13.04,2,1,14.4,100,1,13.03,100,1,14.56,900,3,12.73,100,1,14.6,700,1,12.71,100,1,14.68,1400,2,12.5,700,1,14.78,100,1,12.46,200,2,14.81,100,1,12.43,700,1,14.88,200,2,12.42,700,1,14.96,100,1,12.37,700,1,15.06,100,1
2025-07-17T15:42:34.010083409Z,2025-07-17T15:42:34.010248842Z,160,2,1108,A,A,0,14.26,100,130,165433,251901353,ARL,300280857,13.26,100,1,14.07,2,1,13.04,2,1,14.26,100,1,13.03,100,1,14.4,100,1,12.73,100,1,14.56,900,3,12.71,100,1,14.6,700,1,12.5,700,1,14.68,1400,2,12.46,200,2,14.78,100,1,12.43,700,1,14.81,100,1,12.42,700,1,14.88,200,2,12.37,700,1,14.96,100,1
2025-07-17T15:42:34.010406771Z,2025-07-17T15:42:34.010572370Z,160,2,1108,C,A,0,14.81,100,0,165599,251901355,ARL,299926857,13.26,100,1,14.07,2,1,13.04,2,1,14.26,100,1,13.03,100,1,14.4,100,1,12.73,100,1,14.56,900,3,12.71,100,1,14.6,700,1,12.5,700,1,14.68,1400,2,12.46,200,2,14.78,100,1,12.43,700,1,14.88,200,2,12.42,700,1,14.96,100,1,12.37,700,1,15.06,100,1
2025-07-17T15:42:34.010406771Z,2025-07-17T15:42:34.010572370Z,160,2,1108,A,A,0,14.96,100,130,165599,251901355,ARL,300280873,13.26,100,1,14.07,2,1,13.04,2,1,14.26,100,1,13.03,100,1,14.4,100,1,12.73,100,1,14.56,900,3,12.71,100,1,14.6,700,1,12.5,700,1,14.68,1400,2,12.46,200,2,14.78,100,1,12.43,700,1,14.88,200,2,12.42,700,1,14.96,200,2,12.37,700,1,15.06,100,1
2025-07-17T15:42:34.951932909Z,2025-07-17T15:42:34.952098027Z,160,2,1108,A,A,0,14.08,100,130,165118,251912292,ARL,300294885,13.26,100,1,14.07,2,1,13.04,2,1,14.08,100,1,13.03,100,1,14.26,100,1,12.73,100,1,14.4,100,1,12.71,100,1,14.56,900,3,12.5,700,1,14.6,700,1,12.46,200,2,14.68,1400,2,12.43,700,1,14.78,100,1,12.42,700,1,14.88,200,2,12.37,700,1,14.96,200,2
2025-07-17T15:43:21.513673603Z,2025-07-17T15:43:21.513838949Z,160,2,1108,A,A,0,13.92,15,130,165346,252622568,ARL,301218889,13.26,100,1,13.92,15,1,13.04,2,1,14.07,2,1,13.03,100,1,14.08,100,1,12.73,100,1,14.26,100,1,12.71,100,1,14.4,100,1,12.5,700,1,14.56,900,3,12.46,200,2,14.6,700,1,12.43,700,1,14.68,1400,2,12.42,700,1,14.78,100,1,12.37,700,1,14.88,200,2
2025-07-17T15:43:24.878071152Z,2025-07-17T15:43:24.878236760Z,160,2,1108,C,A,0,14.08,100,0,165608,252681819,ARL,300294885,13.26,100,1,13.92,15,1,13.04,2,1,14.07,2,1,13.03,100,1,14.26,100,1,12.73,100,1,14.4,100,1,12.71,100,1,14.56,900,3,12.5,700,1,14.6,700,1,12.46,200,2,14.68,1400,2,12.43,700,1,14.78,100,1,12.42,700,1,14.88,200,2,12.37,700,1,14.96,200,2
2025-07-17T15:43:24.878071152Z,2025-07-17T15:43:24.878236760Z,160,2,1108,A,A,0,13.93,100,130,165608,252681819,ARL,301295841,13.26,100,1,13.92,15,1,13.04,2,1,13.93,100,1,13.03,100,1,14.07,2,1,12.73,100,1,14.26,100,1,12.71,100,1,14.4,100,1,12.5,700,1,14.56,900,3,12.46,200,2,14.6,700,1,12.43,700,1,14.68,1400,2,12.42,700,1,14.78,100,1,12.37,700,1,14.88,200,2
2025-07-17T15:43:24.878837670Z,2025-07-17T15:43:24.879003443Z,160,2,1108,C,A,0,15.06,100,0,165773,252681832,ARL,300280757,13.26,100,1,13.92,15,1,13.04,2,1,13.93,100,1,13.03,100,1,14.07,2,1,12.73,100,1,14.26,100,1,12.71,100,1,14.4,100,1,12.5,700,1,14.56,900,3,12.46,200,2,14.6,700,1,12.43,700,1,14.68,1400,2,12.42,700,1,14.78,100,1,12.37,700,1,14.88,200,2
2025-07-17T15:43:24.878837670Z,2025-07-17T15:43:24.879003443Z,160,2,1108,A,A,0,15.01,100,130,165773,252681832,ARL,301295873,13.26,100,1,13.92,15,1,13.04,2,1,13.93,100,1,13.03,100,1,14.07,2,1,12.73,100,1,14.26,100,1,12.71,100,1,14.4,100,1,12.5,700,1,14.56,900,3,12.46,200,2,14.6,700,1,12.43,700,1,14.68,1400,2,12.42,700,1,14.78,100,1,12.37,700,1,14.88,200,2
2025-07-17T15:43:32.780206927Z,2025-07-17T15:43:32.780372412Z,160,2,1108,A,A,0,13.88,15,130,165485,252800884,ARL,301451057,13.26,100,1,13.88,15,1,13.04,2,1,13.92,15,1,13.03,100,1,13.93,100,1,12.73,100,1,14.07,2,1,12.71,100,1,14.26,100,1,12.5,700,1,14.4,100,1,12.46,200,2,14.56,900,3,12.43,700,1,14.6,700,1,12.42,700,1,14.68,1400,2,12.37,700,1,14.78,100,1
2025-07-17T15:43:32.780474141Z,2025-07-17T15:43:32.780639619Z,160,2,1108,C,A,0,13.93,100,0,165478,252800887,ARL,301295841,13.26,100,1,13.88,15,1,13.04,2,1,13.92,15,1,13.03,100,1,14.07,2,1,12.73,100,1,14.26,100,1,12.71,100,1,14.4,100,1,12.5,700,1,14.56,900,3,12.46,200,2,14.6,700,1,12.43,700,1,14.68,1400,2,12.42,700,1,14.78,100,1,12.37,700,1,14.88,200,2
2025-07-17T15:43:32.780474141Z,2025-07-17T15:43:32.780639619Z,160,2,1108,A,A,0,13.89,100,130,165478,252800887,ARL,301451061,13.26,100,1,13.88,15,1,13.04,2,1,13.89,100,1,13.03,100,1,13.92,15,1,12.73,100,1,14.07,2,1,12.71,100,1,14.26,100,1,12.5,700,1,14.4,100,1,12.46,200,2,14.56,900,3,12.43,700,1,14.6,700,1,12.42,700,1,14.68,1400,2,12.37,700,1,14.78,100,1
2025-07-17T15:43:32.781216589Z,2025-07-17T15:43:32.781382162Z,160,2,1108,C,A,0,15.01,100,0,165573,252800892,ARL,301295873,13.26,100,1,13.88,15,1,13.04,2,1,13.89,100,1,13.03,100,1,13.92,15,1,12.73,100,1,14.07,2,1,12.71,100,1,14.26,100,1,12.5,700,1,14.4,100,1,12.46,200,2,14.56,900,3,12.43,700,1,14.6,700,1,12.42,700,1,14.68,1400,2,12.37,700,1,14.78,100,1
2025-07-17T15:43:32.781216589Z,2025-07-17T15:43:32.781382162Z,160,2,1108,A,A,0,14.97,100,130,165573,252800892,ARL,301451077,13.26,100,1,13.88,15,1,13.04,2,1,13.89,100,1,13.03,100,1,13.92,15,1,12.73,100,1,14.07,2,1,12.71,100,1,14.26,100,1,12.5,700,1,14.4,100,1,12.46,200,2,14.56,900,3,12.43,700,1,14.6,700,1,12.42,700,1,14.68,1400,2,12.37,700,1,14.78,100,1
2025-07-17T15:43:32.791954053Z,2025-07-17T15:43:32.792119698Z,160,2,1108,C,A,0,14.26,100,130,165645,252801681,ARL,300280857,13.26,100,1,13.88,15,1,13.04,2,1,13.89,100,1,13.03,100,1,13.92,15,1,12.73,100,1,14.07,2,1,12.71,100,1,14.4,100,1,12.5,700,1,14.56,900,3,12.46,200,2,14.6,700,1,12.43,700,1,14.68,1400,2,12.42,700,1,14.78,100,1,12.37,700,1,14.88,200,2
2025-07-17T15:43:32.792008881Z,2025-07-17T15:43:32.792174617Z,160,2,1108,A,A,0,14.17,100,130,165736,252801689,ARL,301452785,13.26,100,1,13.88,15,1,13.04,2,1,13.89,100,1,13.03,100,1,13.92,15,1,12.73,100,1,14.07,2,1,12.71,100,1,14.17,100,1,12.5,700,1,14.4,100,1,12.46,200,2,14.56,900,3,12.43,700,1,14.6,700,1,12.42,700,1,14.68,1400,2,12.37,700,1,14.78,100,1
2025-07-17T15:43:44.004667259Z,2025-07-17T15:43:44.004832641Z,160,2,1108,C,A,0,13.92,15,130,165382,252977583,ARL,301218889,13.26,100,1,13.88,15,1,13.04,2,1,13.89,100,1,13.03,100,1,14.07,2,1,12.73,100,1,14.17,100,1,12.71,100,1,14.4,100,1,12.5,700,1,14.56,900,3,12.46,200,2,14.6,700,1,12.43,700,1,14.68,1400,2,12.42,700,1,14.78,100,1,12.37,700,1,14.88,200,2
2025-07-17T15:43:44.005025587Z,2025-07-17T15:43:44.005191111Z,160,2,1108,C,A,0,14.88,100,0,165524,252977592,ARL,300280761,13.26,100,1,13.88,15,1,13.04,2,1,13.89,100,1,13.03,100,1,14.07,2,1,12.73,100,1,14.17,100,1,12.71,100,1,14.4,100,1,12.5,700,1,14.56,900,3,12.46,200,2,14.6,700,1,12.43,700,1,14.68,1400,2,12.42,700,1,14.78,100,1,12.37,700,1,14.88,100,1
2025-07-17T15:43:44.005025587Z,2025-07-17T15:43:44.005191111Z,160,2,1108,A,A,0,14.77,100,130,165524,252977592,ARL,301671709,13.26,100,1,13.88,15,1,13.04,2,1,13.89,100,1,13.03,100,1,14.07,2,1,12.73,100,1,14.17,100,1,12.71,100,1,14.4,100,1,12.5,700,1,14.56,900,3,12.46,200,2,14.6,700,1,12.43,700,1,14.68,1400,2,12.42,700,1,14.77,100,1,12.37,700,1,14.78,100,1
2025-07-17T15:43:44.005147707Z,2025-07-17T15:43:44.005313071Z,160,2,1108,C,A,0,14.88,100,0,165364,252977595,ARL,300280745,13.26,100,1,13.88,15,1,13.04,2,1,13.89,100,1,13.03,100,1,14.07,2,1,12.73,100,1,14.17,100,1,12.71,100,1,14.4,100,1,12.5,700,1,14.56,900,3,12.46,200,2,14.6,700,1,12.43,700,1,14.68,1400,2,12.42,700,1,14.77,100,1,12.37,700,1,14.78,100,1
2025-07-17T15:43:44.005147707Z,2025-07-17T15:43:44.005313071Z,160,2,1108,A,A,0,14.77,100,130,165364,252977595,ARL,301671713,13.26,100,1,13.88,15,1,13.04,2,1,13.89,100,1,13.03,100,1,14.07,2,1,12.73,100,1,14.17,100,1,12.71,100,1,14.4,100,1,12.5,700,1,14.56,900,3,12.46,200,2,14.6,700,1,12.43,700,1,14.68,1400,2,12.42,700,1,14.77,200,2,12.37,700,1,14.78,100,1
2025-07-17T15:43:48.787332399Z,2025-07-17T15:43:48.787497664Z,160,2,1108,A,A,0,13.83,15,130,165265,253027890,ARL,301746941,13.26,100,1,13.83,15,1,13.04,2,1,13.88,15,1,13.03,100,1,13.89,100,1,12.73,100,1,14.07,2,1,12.71,100,1,14.17,100,1,12.5,700,1,14.4,100,1,12.46,200,2,14.56,900,3,12.43,700,1,14.6,700,1,12.42,700,1,14.68,1400,2,12.37,700,1,14.77,200,2
2025-07-17T15:43:48.787601640Z,2025-07-17T15:43:48.787766907Z,160,2,1108,C,A,0,13.89,100,0,165267,253027924,ARL,301451061,13.26,100,1,13.83,15,1,13.04,2,1,13.88,15,1,13.03,100,1,14.07,2,1,12.73,100,1,14.17,100,1,12.71,100,1,14.4,100,1,12.5,700,1,14.56,900,3,12.46,200,2,14.6,700,1,12.43,700,1,14.68,1400,2,12.42,700,1,14.77,200,2,12.37,700,1,14.78,100,1
2025-07-17T15:43:48.787601640Z,2025-07-17T15:43:48.787766907Z,160,2,1108,A,A,0,13.84,100,130,165267,253027924,ARL,301746949,13.26,100,1,13.83,15,1,13.04,2,1,13.84,100,1,13.03,100,1,13.88,15,1,12.73,100,1,14.07,2,1,12.71,100,1,14.17,100,1,12.5,700,1,14.4,100,1,12.46,200,2,14.56,900,3,12.43,700,1,14.6,700,1,12.42,700,1,14.68,1400,2,12.37,700,1,14.77,200,2
2025-07-17T15:43:48.788345787Z,2025-07-17T15:43:48.788512022Z,160,2,1108,C,A,0,14.97,100,0,166235,253027959,ARL,301451077,13.26,100,1,13.83,15,1,13.04,2,1,13.84,100,1,13.03,100,1,13.88,15,1,12.73,100,1,14.07,2,1,12.71,100,1,14.17,100,1,12.5,700,1,14.4,100,1,12.46,200,2,14.56,900,3,12.43,700,1,14.6,700,1,12.42,700,1,14.68,1400,2,12.37,700,1,14.77,200,2
2025-07-17T15:43:48.788345787Z,2025-07-17T15:43:48.788512022Z,160,2,1108,A,A,0,14.91,100,128,166235,253027959,ARL,301746969,13.26,100,1,13.83,15,1,13.04,2,1,13.84,100,1,13.03,100,1,13.88,15,1,12.73,100,1,14.07,2,1,12.71,100,1,14.17,100,1,12.5,700,1,14.4,100,1,12.46,200,2,14.56,900,3,12.43,700,1,14.6,700,1,12.42,700,1,14.68,1400,2,12.37,700,1,14.77,200,2
2025-07-17T15:43:48.790408191Z,2025-07-17T15:43:48.790573820Z,160,2,1108,C,A,0,14.96,100,0,165629,253028026,ARL,300280777,13.26,100,1,13.83,15,1,13.04,2,1,13.84,100,1,13.03,100,1,13.88,15,1,12.73,100,1,14.07,2,1,12.71,100,1,14.17,100,1,12.5,700,1,14.4,100,1,12.46,200,2,14.56,900,3,12.43,700,1,14.6,700,1,12.42,700,1,14.68,1400,2,12.37,700,1,14.77,200,2
2025-07-17T15:43:48.790408191Z,2025-07-17T15:43:48.790573820Z,160,2,1108,A,A,0,14.81,100,130,165629,253028026,ARL,301747001,13.26,100,1,13.83,15,1,13.04,2,1,13.84,100,1,13.03,100,1,13.88,15,1,12.73,100,1,14.07,2,1,12.71,100,1,14.17,100,1,12.5,700,1,14.4,100,1,12.46,200,2,14.56,900,3,12.43,700,1,14.6,700,1,12.42,700,1,14.68,1400,2,12.37,700,1,14.77,200,2
2025-07-17T15:43:48.790434947Z,2025-07-17T15:43:48.790600546Z,160,2,1108,C,A,0,14.78,100,0,165599,253028027,ARL,300280825,13.26,100,1,13.83,15,1,13.04,2,1,13.84,100,1,13.03,100,1,13.88,15,1,12.73,100,1,14.07,2,1,12.71,100,1,14.17,100,1,12.5,700,1,14.4,100,1,12.46,200,2,14.56,900,3,12.43,700,1,14.6,700,1,12.42,700,1,14.68,1400,2,12.37,700,1,14.77,200,2
2025-07-17T15:43:48.790434947Z,2025-07-17T15:43:48.790600546Z,160,2,1108,A,A,0,14.64,100,130,165599,253028027,ARL,301747005,13.26,100,1,13.83,15,1,13.04,2,1,13.84,100,1,13.03,100,1,13.88,15,1,12.73,100,1,14.07,2,1,12.71,100,1,14.17,100,1,12.5,700,1,14.4,100,1,12.46,200,2,14.56,900,3,12.43,700,1,14.6,700,1,12.42,700,1,14.64,100,1,12.37,700,1,14.68,1400,2
2025-07-17T15:43:48.800794196Z,2025-07-17T15:43:48.800959598Z,160,2,1108,C,A,0,17.76,100,0,165402,253028707,ARL,300280797,13.26,100,1,13.83,15,1,13.04,2,1,13.84,100,1,13.03,100,1,13.88,15,1,12.73,100,1,14.07,2,1,12.71,100,1,14.17,100,1,12.5,700,1,14.4,100,1,12.46,200,2,14.56,900,3,12.43,700,1,14.6,700,1,12.42,700,1,14.64,100,1,12.37,700,1,14.68,1400,2
2025-07-17T15:43:48.800794196Z,2025-07-17T15:43:48.800959598Z,160,2,1108,A,A,0,17.58,100,130,165402,253028707,ARL,301747261,13.26,100,1,13.83,15,1,13.04,2,1,13.84,100,1,13.03,100,1,13.88,15,1,12.73,100,1,14.07,2,1,12.71,100,1,14.17,100,1,12.5,700,1,14.4,100,1,12.46,200,2,14.56,900,3,12.43,700,1,14.6,700,1,12.42,700,1,14.64,100,1,12.37,700,1,14.68,1400,2
2025-07-17T15:43:48.806679708Z,2025-07-17T15:43:48.806845249Z,160,2,1108,C,A,0,16.08,100,0,165541,253028803,ARL,300280773,13.26,100,1,13.83,15,1,13.04,2,1,13.84,100,1,13.03,100,1,13.88,15,1,12.73,100,1,14.07,2,1,12.71,100,1,14.17,100,1,12.5,700,1,14.4,100,1,12.46,200,2,14.56,900,3,12.43,700,1,14.6,700,1,12.42,700,1,14.64,100,1,12.37,700,1,14.68,1400,2
2025-07-17T15:43:48.806679708Z,2025-07-17T15:43:48.806845249Z,160,2,1108,A,A,0,15.92,100,130,165541,253028803,ARL,301747301,13.26,100,1,13.83,15,1,13.04,2,1,13.84,100,1,13.03,100,1,13.88,15,1,12.73,100,1,14.07,2,1,12.71,100,1,14.17,100,1,12.5,700,1,14.4,100,1,12.46,200,2,14.56,900,3,12.43,700,1,14.6,700,1,12.42,700,1,14.64,100,1,12.37,700,1,14.68,1400,2
2025-07-17T15:43:48.852405047Z,2025-07-17T15:43:48.852570853Z,160,2,1108,C,A,0,14.96,100,0,165806,253029437,ARL,300280873,13.26,100,1,13.83,15,1,13.04,2,1,13.84,100,1,13.03,100,1,13.88,15,1,12.73,100,1,14.07,2,1,12.71,100,1,14.17,100,1,12.5,700,1,14.4,100,1,12.46,200,2,14.56,900,3,12.43,700,1,14.6,700,1,12.42,700,1,14.64,100,1,12.37,700,1,14.68,1400,2
2025-07-17T15:43:48.852405047Z,2025-07-17T15:43:48.852570853Z,160,2,1108,A,A,0,14.81,100,130,165806,253029437,ARL,301747957,13.26,100,1,13.83,15,1,13.04,2,1,13.84,100,1,13.03,100,1,13.88,15,1,12.73,100,1,14.07,2,1,12.71,100,1,14.17,100,1,12.5,700,1,14.4,100,1,12.46,200,2,14.56,900,3,12.43,700,1,14.6,700,1,12.42,700,1,14.64,100,1,12.37,700,1,14.68,1400,2
2025-07-17T15:43:53.123652480Z,2025-07-17T15:43:53.123817759Z,160,2,1108,C,A,0,13.88,15,130,165279,253100941,ARL,301451057,13.26,100,1,13.83,15,1,13.04,2,1,13.84,100,1,13.03,100,1,14.07,2,1,12.73,100,1,14.17,100,1,12.71,100,1,14.4,100,1,12.5,700,1,14.56,900,3,12.46,200,2,14.6,700,1,12.43,700,1,14.64,100,1,12.42,700,1,14.68,1400,2,12.37,700,1,14.77,200,2
2025-07-17T15:43:54.126111293Z,2025-07-17T15:43:54.126276976Z,160,2,1108,A,A,0,13.81,15,130,165683,253121467,ARL,301867541,13.26,100,1,13.81,15,1,13.04,2,1,13.83,15,1,13.03,100,1,13.84,100,1,12.73,100,1,14.07,2,1,12.71,100,1,14.17,100,1,12.5,700,1,14.4,100,1,12.46,200,2,14.56,900,3,12.43,700,1,14.6,700,1,12.42,700,1,14.64,100,1,12.37,700,1,14.68,1400,2
2025-07-17T15:43:54.998073317Z,2025-07-17T15:43:54.998238933Z,160,2,1108,C,A,0,13.84,100,0,165616,253137948,ARL,301746949,13.26,100,1,13.81,15,1,13.04,2,1,13.83,15,1,13.03,100,1,14.07,2,1,12.73,100,1,14.17,100,1,12.71,100,1,14.4,100,1,12.5,700,1,14.56,900,3,12.46,200,2,14.6,700,1,12.43,700,1,14.64,100,1,12.42,700,1,14.68,1400,2,12.37,700,1,14.77,200,2
2025-07-17T15:43:54.998073317Z,2025-07-17T15:43:54.998238933Z,160,2,1108,A,A,0,13.82,100,130,165616,253137948,ARL,301885353,13.26,100,1,13.81,15,1,13.04,2,1,13.82,100,1,13.03,100,1,13.83,15,1,12.73,100,1,14.07,2,1,12.71,100,1,14.17,100,1,12.5,700,1,14.4,100,1,12.46,200,2,14.56,900,3,12.43,700,1,14.6,700,1,12.42,700,1,14.64,100,1,12.37,700,1,14.68,1400,2
2025-07-17T15:43:55.019007300Z,2025-07-17T15:43:55.019172741Z,160,2,1108,C,A,0,14.17,100,130,165441,253138492,ARL,301452785,13.26,100,1,13.81,15,1,13.04,2,1,13.82,100,1,13.03,100,1,13.83,15,1,12.73,100,1,14.07,2,1,12.71,100,1,14.4,100,1,12.5,700,1,14.56,900,3,12.46,200,2,14.6,700,1,12.43,700,1,14.64,100,1,12.42,700,1,14.68,1400,2,12.37,700,1,14.77,200,2
2025-07-17T15:43:55.019060515Z,2025-07-17T15:43:55.019225935Z,160,2,1108,A,A,0,14.1,100,130,165420,253138493,ARL,301886057,13.26,100,1,13.81,15,1,13.04,2,1,13.82,100,1,13.03,100,1,13.83,15,1,12.73,100,1,14.07,2,1,12.71,100,1,14.1,100,1,12.5,700,1,14.4,100,1,12.46,200,2,14.56,900,3,12.43,700,1,14.6,700,1,12.42,700,1,14.64,100,1,12.37,700,1,14.68,1400,2
2025-07-17T15:44:01.698626200Z,2025-07-17T15:44:01.698791467Z,160,2,1108,C,A,0,13.83,15,130,165267,253246317,ARL,301746941,13.26,100,1,13.81,15,1,13.04,2,1,13.82,100,1,13.03,100,1,14.07,2,1,12.73,100,1,14.1,100,1,12.71,100,1,14.4,100,1,12.5,700,1,14.56,900,3,12.46,200,2,14.6,700,1,12.43,700,1,14.64,100,1,12.42,700,1,14.68,1400,2,12.37,700,1,14.77,200,2
2025-07-17T15:44:04.014712730Z,2025-07-17T15:44:04.014878156Z,160,2,1108,A,A,0,13.83,100,130,165426,253292355,ARL,302078553,13.26,100,1,13.81,15,1,13.04,2,1,13.82,100,1,13.03,100,1,13.83,100,1,12.73,100,1,14.07,2,1,12.71,100,1,14.1,100,1,12.5,700,1,14.4,100,1,12.46,200,2,14.56,900,3,12.43,700,1,14.6,700,1,12.42,700,1,14.64,100,1,12.37,700,1,14.68,1400,2
2025-07-17T15:44:05.055461574Z,2025-07-17T15:44:05.055626948Z,160,2,1108,A,A,0,13.81,100,130,165374,253307083,ARL,302100649,13.26,100,1,13.81,115,2,13.04,2,1,13.82,100,1,13.03,100,1,13.83,100,1,12.73,100,1,14.07,2,1,12.71,100,1,14.1,100,1,12.5,700,1,14.4,100,1,12.46,200,2,14.56,900,3,12.43,700,1,14.6,700,1,12.42,700,1,14.64,100,1,12.37,700,1,14.68,1400,2
2025-07-17T15:44:05.062266845Z,2025-07-17T15:44:05.062431949Z,160,2,1108,C,A,0,13.83,100,130,165104,253307147,ARL,302078553,13.26,100,1,13.81,115,2,13.04,2,1,13.82,100,1,13.03,100,1,14.07,2,1,12.73,100,1,14.1,100,1,12.71,100,1,14.4,100,1,12.5,700,1,14.56,900,3,12.46,200,2,14.6,700,1,12.43,700,1,14.64,100,1,12.42,700,1,14.68,1400,2,12.37,700,1,14.77,200,2
2025-07-17T15:44:09.389548394Z,2025-07-17T15:44:09.389713730Z,160,2,1108,A,A,0,13.76,15,130,165336,253384422,ARL,302205249,13.26,100,1,13.76,15,1,13.04,2,1,13.81,115,2,13.03,100,1,13.82,100,1,12.73,100,1,14.07,2,1,12.71,100,1,14.1,100,1,12.5,700,1,14.4,100,1,12.46,200,2,14.56,900,3,12.43,700,1,14.6,700,1,12.42,700,1,14.64,100,1,12.37,700,1,14.68,1400,2
2025-07-17T15:44:09.390329935Z,2025-07-17T15:44:09.390496140Z,160,2,1108,C,A,0,14.77,100,0,166205,253384438,ARL,301671709,13.26,100,1,13.76,15,1,13.04,2,1,13.81,115,2,13.03,100,1,13.82,100,1,12.73,100,1,14.07,2,1,12.71,100,1,14.1,100,1,12.5,700,1,14.4,100,1,12.46,200,2,14.56,900,3,12.43,700,1,14.6,700,1,12.42,700,1,14.64,100,1,12.37,700,1,14.68,1400,2
2025-07-17T15:44:09.390329935Z,2025-07-17T15:44:09.390496140Z,160,2,1108,A,A,0,14.66,100,128,166205,253384438,ARL,302205289,13.26,100,1,13.76,15,1,13.04,2,1,13.81,115,2,13.03,100,1,13.82,100,1,12.73,100,1,14.07,2,1,12.71,100,1,14.1,100,1,12.5,700,1,14.4,100,1,12.46,200,2,14.56,900,3,12.43,700,1,14.6,700,1,12.42,700,1,14.64,100,1,12.37,700,1,14.66,100,1
2025-07-17T15:44:09.390893172Z,2025-07-17T15:44:09.391058486Z,160,2,1108,C,A,0,14.77,100,0,165314,253384456,ARL,301671713,13.26,100,1,13.76,15,1,13.04,2,1,13.81,115,2,13.03,100,1,13.82,100,1,12.73,100,1,14.07,2,1,12.71,100,1,14.1,100,1,12.5,700,1,14.4,100,1,12.46,200,2,14.56,900,3,12.43,700,1,14.6,700,1,12.42,700,1,14.64,100,1,12.37,700,1,14.66,100,1
2025-07-17T15:44:09.390893172Z,2025-07-17T15:44:09.391058486Z,160,2,1108,A,A,0,14.66,100,130,165314,253384456,ARL,302205309,13.26,100,1,13.76,15,1,13.04,2,1,13.81,115,2,13.03,100,1,13.82,100,1,12.73,100,1,14.07,2,1,12.71,100,1,14.1,100,1,12.5,700,1,14.4,100,1,12.46,200,2,14.56,900,3,12.43,700,1,14.6,700,1,12.42,700,1,14.64,100,1,12.37,700,1,14.66,200,2
2025-07-17T15:44:09.395281780Z,2025-07-17T15:44:09.395447612Z,160,2,1108,C,A,0,13.82,100,0,165832,253384698,ARL,301885353,13.26,100,1,13.76,15,1,13.04,2,1,13.81,115,2,13.03,100,1,14.07,2,1,12.73,100,1,14.1,100,1,12.71,100,1,14.4,100,1,12.5,700,1,14.56,900,3,12.46,200,2,14.6,700,1,12.43,700,1,14.64,100,1,12.42,700,1,14.66,200,2,12.37,700,1,14.68,1400,2
2025-07-17T15:44:09.395281780Z,2025-07-17T15:44:09.395447612Z,160,2,1108,A,A,0,13.77,100,130,165832,253384698,ARL,302205493,13.26,100,1,13.76,15,1,13.04,2,1,13.77,100,1,13.03,100,1,13.81,115,2,12.73,100,1,14.07,2,1,12.71,100,1,14.1,100,1,12.5,700,1,14.4,100,1,12.46,200,2,14.56,900,3,12.43,700,1,14.6,700,1,12.42,700,1,14.64,100,1,12.37,700,1,14.66,200,2
2025-07-17T15:44:09.396030225Z,2025-07-17T15:44:09.396195647Z,160,2,1108,C,A,0,14.91,100,0,165422,253384731,ARL,301746969,13.26,100,1,13.76,15,1,13.04,2,1,13.77,100,1,13.03,100,1,13.81,115,2,12.73,100,1,14.07,2,1,12.71,100,1,14.1,100,1,12.5,700,1,14.4,100,1,12.46,200,2,14.56,900,3,12.43,700,1,14.6,700,1,12.42,700,1,14.64,100,1,12.37,700,1,14.66,200,2
2025-07-17T15:44:09.396030225Z,2025-07-17T15:44:09.396195647Z,160,2,1108,A,A,0,14.84,100,130,165422,253384731,ARL,302205537,13.26,100,1,13.76,15,1,13.04,2,1,13.77,100,1,13.03,100,1,13.81,115,2,12.73,100,1,14.07,2,1,12.71,100,1,14.1,100,1,12.5,700,1,14.4,100,1,12.46,200,2,14.56,900,3,12.43,700,1,14.6,700,1,12.42,700,1,14.64,100,1,12.37,700,1,14.66,200,2
2025-07-17T15:44:09.397845986Z,2025-07-17T15:44:09.398011186Z,160,2,1108,A,A,0,13.79,100,130,165200,253384788,ARL,302205561,13.26,100,1,13.76,15,1,13.04,2,1,13.77,100,1,13.03,100,1,13.79,100,1,12.73,100,1,13.81,115,2,12.71,100,1,14.07,2,1,12.5,700,1,14.1,100,1,12.46,200,2,14.4,100,1,12.43,700,1,14.56,900,3,12.42,700,1,14.6,700,1,12.37,700,1,14.64,100,1
2025-07-17T15:44:09.404663816Z,2025-07-17T15:44:09.404828956Z,160,2,1108,C,A,0,13.81,100,130,165140,253385013,ARL,302100649,13.26,100,1,13.76,15,1,13.04,2,1,13.77,100,1,13.03,100,1,13.79,100,1,12.73,100,1,13.81,15,1,12.71,100,1,14.07,2,1,12.5,700,1,14.1,100,1,12.46,200,2,14.4,100,1,12.43,700,1,14.56,900,3,12.42,700,1,14.6,700,1,12.37,700,1,14.64,100,1
2025-07-17T15:44:20.402370565Z,2025-07-17T15:44:20.402535831Z,160,2,1108,C,A,0,13.81,15,130,165266,253562230,ARL,301867541,13.26,100,1,13.76,15,1,13.04,2,1,13.77,100,1,13.03,100,1,13.79,100,1,12.73,100,1,14.07,2,1,12.71,100,1,14.1,100,1,12.5,700,1,14.4,100,1,12.46,200,2,14.56,900,3,12.43,700,1,14.6,700,1,12.42,700,1,14.64,100,1,12.37,700,1,14.66,200,2
2025-07-17T15:44:21.405320730Z,2025-07-17T15:44:21.405486122Z,160,2,1108,A,A,0,13.74,15,130,165392,253582427,ARL,302458113,13.26,100,1,13.74,15,1,13.04,2,1,13.76,15,1,13.03,100,1,13.77,100,1,12.73,100,1,13.79,100,1,12.71,100,1,14.07,2,1,12.5,700,1,14.1,100,1,12.46,200,2,14.4,100,1,12.43,700,1,14.56,900,3,12.42,700,1,14.6,700,1,12.37,700,1,14.64,100,1
2025-07-17T15:44:21.843070079Z,2025-07-17T15:44:21.843235911Z,160,2,1108,C,A,0,13.77,100,0,165832,253590641,ARL,302205493,13.26,100,1,13.74,15,1,13.04,2,1,13.76,15,1,13.03,100,1,13.79,100,1,12.73,100,1,14.07,2,1,12.71,100,1,14.1,100,1,12.5,700,1,14.4,100,1,12.46,200,2,14.56,900,3,12.43,700,1,14.6,700,1,12.42,700,1,14.64,100,1,12.37,700,1,14.66,200,2
2025-07-17T15:44:21.843070079Z,2025-07-17T15:44:21.843235911Z,160,2,1108,A,A,0,13.75,100,130,165832,253590641,ARL,302466045,13.26,100,1,13.74,15,1,13.04,2,1,13.75,100,1,13.03,100,1,13.76,15,1,12.73,100,1,13.79,100,1,12.71,100,1,14.07,2,1,12.5,700,1,14.1,100,1,12.46,200,2,14.4,100,1,12.43,700,1,14.56,900,3,12.42,700,1,14.6,700,1,12.37,700,1,14.64,100,1
2025-07-17T15:44:21.855250804Z,2025-07-17T15:44:21.855416093Z,160,2,1108,C,A,0,14.1,100,130,165289,253590837,ARL,301886057,13.26,100,1,13.74,15,1,13.04,2,1,13.75,100,1,13.03,100,1,13.76,15,1,12.73,100,1,13.79,100,1,12.71,100,1,14.07,2,1,12.5,700,1,14.4,100,1,12.46,200,2,14.56,900,3,12.43,700,1,14.6,700,1,12.42,700,1,14.64,100,1,12.37,700,1,14.66,200,2
2025-07-17T15:44:21.855305995Z,2025-07-17T15:44:21.855471158Z,160,2,1108,A,A,0,14.03,100,130,165163,253590838,ARL,302466157,13.26,100,1,13.74,15,1,13.04,2,1,13.75,100,1,13.03,100,1,13.76,15,1,12.73,100,1,13.79,100,1,12.71,100,1,14.03,100,1,12.5,700,1,14.07,2,1,12.46,200,2,14.4,100,1,12.43,700,1,14.56,900,3,12.42,700,1,14.6,700,1,12.37,700,1,14.64,100,1
2025-07-17T15:44:24.446910206Z,2025-07-17T15:44:24.447075532Z,160,2,1108,A,A,0,13.77,100,130,165326,253614407,ARL,302500469,13.26,100,1,13.74,15,1,13.04,2,1,13.75,100,1,13.03,100,1,13.76,15,1,12.73,100,1,13.77,100,1,12.71,100,1,13.79,100,1,12.5,700,1,14.03,100,1,12.46,200,2,14.07,2,1,12.43,700,1,14.4,100,1,12.42,700,1,14.56,900,3,12.37,700,1,14.6,700,1
2025-07-17T15:44:24.465390625Z,2025-07-17T15:44:24.465555818Z,160,2,1108,C,A,0,13.79,100,130,165193,253614591,ARL,302205561,13.26,100,1,13.74,15,1,13.04,2,1,13.75,100,1,13.03,100,1,13.76,15,1,12.73,100,1,13.77,100,1,12.71,100,1,14.03,100,1,12.5,700,1,14.07,2,1,12.46,200,2,14.4,100,1,12.43,700,1,14.56,900,3,12.42,700,1,14.6,700,1,12.37,700,1,14.64,100,1
2025-07-17T15:44:30.846657613Z,2025-07-17T15:44:30.846822983Z,160,2,1108,C,A,0,13.76,15,130,165370,253704439,ARL,302205249,13.26,100,1,13.74,15,1,13.04,2,1,13.75,100,1,13.03,100,1,13.77,100,1,12.73,100,1,14.03,100,1,12.71,100,1,14.07,2,1,12.5,700,1,14.4,100,1,12.46,200,2,14.56,900,3,12.43,700,1,14.6,700,1,12.42,700,1,14.64,100,1,12.37,700,1,14.66,200,2
2025-07-17T15:44:31.849618640Z,2025-07-17T15:44:31.849784693Z,160,2,1108,A,A,0,13.72,15,130,166053,253721156,ARL,302649021,13.26,100,1,13.72,15,1,13.04,2,1,13.74,15,1,13.03,100,1,13.75,100,1,12.73,100,1,13.77,100,1,12.71,100,1,14.03,100,1,12.5,700,1,14.07,2,1,12.46,200,2,14.4,100,1,12.43,700,1,14.56,900,3,12.42,700,1,14.6,700,1,12.37,700,1,14.64,100,1
2025-07-17T15:44:31.849756452Z,2025-07-17T15:44:31.849921857Z,160,2,1108,A,A,0,13.75,100,130,165405,253721157,ARL,302649029,13.26,100,1,13.72,15,1,13.04,2,1,13.74,15,1,13.03,100,1,13.75,200,2,12.73,100,1,13.77,100,1,12.71,100,1,14.03,100,1,12.5,700,1,14.07,2,1,12.46,200,2,14.4,100,1,12.43,700,1,14.56,900,3,12.42,700,1,14.6,700,1,12.37,700,1,14.64,100,1
2025-07-17T15:44:31.909959614Z,2025-07-17T15:44:31.910124978Z,160,2,1108,C,A,0,13.77,100,130,165364,253722140,ARL,302500469,13.26,100,1,13.72,15,1,13.04,2,1,13.74,15,1,13.03,100,1,13.75,200,2,12.73,100,1,14.03,100,1,12.71,100,1,14.07,2,1,12.5,700,1,14.4,100,1,12.46,200,2,14.56,900,3,12.43,700,1,14.6,700,1,12.42,700,1,14.64,100,1,12.37,700,1,14.66,200,2
2025-07-17T15:44:32.484331764Z,2025-07-17T15:44:32.484497230Z,160,2,1108,C,A,0,13.75,100,0,165466,253730877,ARL,302466045,13.26,100,1,13.72,15,1,13.04,2,1,13.74,15,1,13.03,100,1,13.75,100,1,12.73,100,1,14.03,100,1,12.71,100,1,14.07,2,1,12.5,700,1,14.4,100,1,12.46,200,2,14.56,900,3,12.43,700,1,14.6,700,1,12.42,700,1,14.64,100,1,12.37,700,1,14.66,200,2
2025-07-17T15:44:32.484331764Z,2025-07-17T15:44:32.484497230Z,160,2,1108,A,A,0,13.73,100,130,165466,253730877,ARL,302662769,13.26,100,1,13.72,15,1,13.04,2,1,13.73,100,1,13.03,100,1,13.74,15,1,12.73,100,1,13.75,100,1,12.71,100,1,14.03,100,1,12.5,700,1,14.07,2,1,12.46,200,2,14.4,100,1,12.43,700,1,14.56,900,3,12.42,700,1,14.6,700,1,12.37,700,1,14.64,100,1
2025-07-17T15:44:32.485072552Z,2025-07-17T15:44:32.485238209Z,160,2,1108,C,A,0,14.84,100,0,165657,253730907,ARL,302205537,13.26,100,1,13.72,15,1,13.04,2,1,13.73,100,1,13.03,100,1,13.74,15,1,12.73,100,1,13.75,100,1,12.71,100,1,14.03,100,1,12.5,700,1,14.07,2,1,12.46,200,2,14.4,100,1,12.43,700,1,14.56,900,3,12.42,700,1,14.6,700,1,12.37,700,1,14.64,100,1
2025-07-17T15:44:32.485072552Z,2025-07-17T15:44:32.485238209Z,160,2,1108,A,A,0,14.79,100,130,165657,253730907,ARL,302662821,13.26,100,1,13.72,15,1,13.04,2,1,13.73,100,1,13.03,100,1,13.74,15,1,12.73,100,1,13.75,100,1,12.71,100,1,14.03,100,1,12.5,700,1,14.07,2,1,12.46,200,2,14.4,100,1,12.43,700,1,14.56,900,3,12.42,700,1,14.6,700,1,12.37,700,1,14.64,100,1
2025-07-17T15:44:33.389222513Z,2025-07-17T15:44:33.389387814Z,160,2,1108,A,A,0,14.28,100,130,165301,253745665,ARL,302681357,13.26,100,1,13.72,15,1,13.04,2,1,13.73,100,1,13.03,100,1,13.74,15,1,12.73,100,1,13.75,100,1,12.71,100,1,14.03,100,1,12.5,700,1,14.07,2,1,12.46,200,2,14.28,100,1,12.43,700,1,14.4,100,1,12.42,700,1,14.56,900,3,12.37,700,1,14.6,700,1
2025-07-17T15:44:33.389223581Z,2025-07-17T15:44:33.389389030Z,160,2,1108,C,A,0,14.56,100,130,165449,253745666,ARL,146960005,13.26,100,1,13.72,15,1,13.04,2,1,13.73,100,1,13.03,100,1,13.74,15,1,12.73,100,1,13.75,100,1,12.71,100,1,14.03,100,1,12.5,700,1,14.07,2,1,12.46,200,2,14.28,100,1,12.43,700,1,14.4,100,1,12.42,700,1,14.56,800,2,12.37,700,1,14.6,700,1
2025-07-17T15:44:36.362022168Z,2025-07-17T15:44:36.362187673Z,160,2,1108,C,A,0,13.74,15,130,165505,253783635,ARL,302458113,13.26,100,1,13.72,15,1,13.04,2,1,13.73,100,1,13.03,100,1,13.75,100,1,12.73,100,1,14.03,100,1,12.71,100,1,14.07,2,1,12.5,700,1,14.28,100,1,12.46,200,2,14.4,100,1,12.43,700,1,14.56,800,2,12.42,700,1,14.6,700,1,12.37,700,1,14.64,100,1
2025-07-17T15:44:37.364212109Z,2025-07-17T15:44:37.364377419Z,160,2,1108,A,A,0,13.7,15,130,165310,253797506,ARL,302750929,13.26,100,1,13.7,15,1,13.04,2,1,13.72,15,1,13.03,100,1,13.73,100,1,12.73,100,1,13.75,100,1,12.71,100,1,14.03,100,1,12.5,700,1,14.07,2,1,12.46,200,2,14.28,100,1,12.43,700,1,14.4,100,1,12.42,700,1,14.56,800,2,12.37,700,1,14.6,700,1
2025-07-17T15:44:37.364353897Z,2025-07-17T15:44:37.364519067Z,160,2,1108,A,A,0,13.73,100,130,165170,253797510,ARL,302750937,13.26,100,1,13.7,15,1,13.04,2,1,13.72,15,1,13.03,100,1,13.73,200,2,12.73,100,1,13.75,100,1,12.71,100,1,14.03,100,1,12.5,700,1,14.07,2,1,12.46,200,2,14.28,100,1,12.43,700,1,14.4,100,1,12.42,700,1,14.56,800,2,12.37,700,1,14.6,700,1
2025-07-17T15:44:37.457954350Z,2025-07-17T15:44:37.458119494Z,160,2,1108,C,A,0,13.75,100,130,165144,253798432,ARL,302649029,13.26,100,1,13.7,15,1,13.04,2,1,13.72,15,1,13.03,100,1,13.73,200,2,12.73,100,1,14.03,100,1,12.71,100,1,14.07,2,1,12.5,700,1,14.28,100,1,12.46,200,2,14.4,100,1,12.43,700,1,14.56,800,2,12.42,700,1,14.6,700,1,12.37,700,1,14.64,100,1
2025-07-17T15:44:38.432294362Z,2025-07-17T15:44:38.432460509Z,160,2,1108,C,A,0,13.73,100,0,166147,253807786,ARL,302662769,13.26,100,1,13.7,15,1,13.04,2,1,13.72,15,1,13.03,100,1,13.73,100,1,12.73,100,1,14.03,100,1,12.71,100,1,14.07,2,1,12.5,700,1,14.28,100,1,12.46,200,2,14.4,100,1,12.43,700,1,14.56,800,2,12.42,700,1,14.6,700,1,12.37,700,1,14.64,100,1
2025-07-17T15:44:38.432294362Z,2025-07-17T15:44:38.432460509Z,160,2,1108,A,A,0,13.71,100,130,166147,253807786,ARL,302763889,13.26,100,1,13.7,15,1,13.04,2,1,13.71,100,1,13.03,100,1,13.72,15,1,12.73,100,1,13.73,100,1,12.71,100,1,14.03,100,1,12.5,700,1,14.07,2,1,12.46,200,2,14.28,100,1,12.43,700,1,14.4,100,1,12.42,700,1,14.56,800,2,12.37,700,1,14.6,700,1
2025-07-17T15:44:38.439088042Z,2025-07-17T15:44:38.439253975Z,160,2,1108,C,A,0,15.92,100,0,165933,253808105,ARL,301747301,13.26,100,1,13.7,15,1,13.04,2,1,13.71,100,1,13.03,100,1,13.72,15,1,12.73,100,1,13.73,100,1,12.71,100,1,14.03,100,1,12.5,700,1,14.07,2,1,12.46,200,2,14.28,100,1,12.43,700,1,14.4,100,1,12.42,700,1,14.56,800,2,12.37,700,1,14.6,700,1
2025-07-17T15:44:38.439088042Z,2025-07-17T15:44:38.439253975Z,160,2,1108,A,A,0,15.77,100,130,165933,253808105,ARL,302764121,13.26,100,1,13.7,15,1,13.04,2,1,13.71,100,1,13.03,100,1,13.72,15,1,12.73,100,1,13.73,100,1,12.71,100,1,14.03,100,1,12.5,700,1,14.07,2,1,12.46,200,2,14.28,100,1,12.43,700,1,14.4,100,1,12.42,700,1,14.56,800,2,12.37,700,1,14.6,700,1
2025-07-17T15:44:38.440156077Z,2025-07-17T15:44:38.440321697Z,160,2,1108,C,A,0,17.58,100,0,165620,253808122,ARL,301747261,13.26,100,1,13.7,15,1,13.04,2,1,13.71,100,1,13.03,100,1,13.72,15,1,12.73,100,1,13.73,100,1,12.71,100,1,14.03,100,1,12.5,700,1,14.07,2,1,12.46,200,2,14.28,100,1,12.43,700,1,14.4,100,1,12.42,700,1,14.56,800,2,12.37,700,1,14.6,700,1
2025-07-17T15:44:38.440156077Z,2025-07-17T15:44:38.440321697Z,160,2,1108,A,A,0,17.42,100,130,165620,253808122,ARL,302764137,13.26,100,1,13.7,15,1,13.04,2,1,13.71,100,1,13.03,100,1,13.72,15,1,12.73,100,1,13.73,100,1,12.71,100,1,14.03,100,1,12.5,700,1,14.07,2,1,12.46,200,2,14.28,100,1,12.43,700,1,14.4,100,1,12.42,700,1,14.56,800,2,12.37,700,1,14.6,700,1
2025-07-17T15:44:43.019083502Z,2025-07-17T15:44:43.019262217Z,160,2,1108,C,A,0,13.7,15,128,178715,253875920,ARL,302750929,13.26,100,1,13.71,100,1,13.04,2,1,13.72,15,1,13.03,100,1,13.73,100,1,12.73,100,1,14.03,100,1,12.71,100,1,14.07,2,1,12.5,700,1,14.28,100,1,12.46,200,2,14.4,100,1,12.43,700,1,14.56,800,2,12.42,700,1,14.6,700,1,12.37,700,1,14.64,100,1
2025-07-17T15:44:43.019184132Z,2025-07-17T15:44:43.019352658Z,160,2,1108,C,A,0,13.72,15,128,168526,253876010,ARL,302649021,13.26,100,1,13.71,100,1,13.04,2,1,13.73,100,1,13.03,100,1,14.03,100,1,12.73,100,1,14.07,2,1,12.71,100,1,14.28,100,1,12.5,700,1,14.4,100,1,12.46,200,2,14.56,800,2,12.43,700,1,14.6,700,1,12.42,700,1,14.64,100,1,12.37,700,1,14.66,200,2
2025-07-17T15:44:44.075843113Z,2025-07-17T15:44:44.076009999Z,160,2,1108,A,A,0,13.7,15,128,166886,253892869,ARL,302867209,13.26,100,1,13.7,15,1,13.04,2,1,13.71,100,1,13.03,100,1,13.73,100,1,12.73,100,1,14.03,100,1,12.71,100,1,14.07,2,1,12.5,700,1,14.28,100,1,12.46,200,2,14.4,100,1,12.43,700,1,14.56,800,2,12.42,700,1,14.6,700,1,12.37,700,1,14.64,100,1
2025-07-17T15:44:44.781464821Z,2025-07-17T15:44:44.781630732Z,160,2,1108,C,A,0,13.7,15,130,165911,253901222,ARL,302867209,13.26,100,1,13.71,100,1,13.04,2,1,13.73,100,1,13.03,100,1,14.03,100,1,12.73,100,1,14.07,2,1,12.71,100,1,14.28,100,1,12.5,700,1,14.4,100,1,12.46,200,2,14.56,800,2,12.43,700,1,14.6,700,1,12.42,700,1,14.64,100,1,12.37,700,1,14.66,200,2
2025-07-17T15:44:53.143083969Z,2025-07-17T15:44:53.143249270Z,160,2,1108,C,A,0,13.73,100,130,165301,254011871,ARL,302750937,13.26,100,1,13.71,100,1,13.04,2,1,14.03,100,1,13.03,100,1,14.07,2,1,12.73,100,1,14.28,100,1,12.71,100,1,14.4,100,1,12.5,700,1,14.56,800,2,12.46,200,2,14.6,700,1,12.43,700,1,14.64,100,1,12.42,700,1,14.66,200,2,12.37,700,1,14.68,1400,2
2025-07-17T15:44:57.191023026Z,2025-07-17T15:44:57.191188470Z,160,2,1108,A,A,0,13.75,100,130,165444,254079162,ARL,303118785,13.26,100,1,13.71,100,1,13.04,2,1,13.75,100,1,13.03,100,1,14.03,100,1,12.73,100,1,14.07,2,1,12.71,100,1,14.28,100,1,12.5,700,1,14.4,100,1,12.46,200,2,14.56,800,2,12.43,700,1,14.6,700,1,12.42,700,1,14.64,100,1,12.37,700,1,14.66,200,2
2025-07-17T15:45:07.065587919Z,2025-07-17T15:45:07.065756574Z,160,2,1108,C,A,0,13.71,100,128,168655,254244597,ARL,302763889,13.26,100,1,13.75,100,1,13.04,2,1,14.03,100,1,13.03,100,1,14.07,2,1,12.73,100,1,14.28,100,1,12.71,100,1,14.4,100,1,12.5,700,1,14.56,800,2,12.46,200,2,14.6,700,1,12.43,700,1,14.64,100,1,12.42,700,1,14.66,200,2,12.37,700,1,14.68,1400,2
2025-07-17T15:45:07.079966224Z,2025-07-17T15:45:07.080131505Z,160,2,1108,C,A,0,13.75,100,130,165281,254245492,ARL,303118785,13.26,100,1,14.03,100,1,13.04,2,1,14.07,2,1,13.03,100,1,14.28,100,1,12.73,100,1,14.4,100,1,12.71,100,1,14.56,800,2,12.5,700,1,14.6,700,1,12.46,200,2,14.64,100,1,12.43,700,1,14.66,200,2,12.42,700,1,14.68,1400,2,12.37,700,1,14.79,100,1
2025-07-17T15:45:07.080521807Z,2025-07-17T15:45:07.080687215Z,160,2,1108,C,A,0,14.66,100,0,165408,254245505,ARL,302205289,13.26,100,1,14.03,100,1,13.04,2,1,14.07,2,1,13.03,100,1,14.28,100,1,12.73,100,1,14.4,100,1,12.71,100,1,14.56,800,2,12.5,700,1,14.6,700,1,12.46,200,2,14.64,100,1,12.43,700,1,14.66,100,1,12.42,700,1,14.68,1400,2,12.37,700,1,14.79,100,1
2025-07-17T15:45:07.080521807Z,2025-07-17T15:45:07.080687215Z,160,2,1108,A,A,0,14.89,100,130,165408,254245505,ARL,303330477,13.26,100,1,14.03,100,1,13.04,2,1,14.07,2,1,13.03,100,1,14.28,100,1,12.73,100,1,14.4,100,1,12.71,100,1,14.56,800,2,12.5,700,1,14.6,700,1,12.46,200,2,14.64,100,1,12.43,700,1,14.66,100,1,12.42,700,1,14.68,1400,2,12.37,700,1,14.79,100,1
2025-07-17T15:45:07.080706110Z,2025-07-17T15:45:07.080872245Z,160,2,1108,C,A,0,14.79,100,0,166135,254245511,ARL,302662821,13.26,100,1,14.03,100,1,13.04,2,1,14.07,2,1,13.03,100,1,14.28,100,1,12.73,100,1,14.4,100,1,12.71,100,1,14.56,800,2,12.5,700,1,14.6,700,1,12.46,200,2,14.64,100,1,12.43,700,1,14.66,100,1,12.42,700,1,14.68,1400,2,12.37,700,1,14.81,200,2
