ts_event,ts_recv,r_type,publisher,instrument_id,action,side,depth,price,size,flags,ts_in_delta,sequence,symbol,order_id,bid_px_00,bid_sz_00,bid_ct_00,ask_px_00,ask_sz_00,ask_ct_00,bid_px_01,bid_sz_01,bid_ct_01,ask_px_01,ask_sz_01,ask_ct_01,bid_px_02,bid_sz_02,bid_ct_02,ask_px_02,ask_sz_02,ask_ct_02,bid_px_03,bid_sz_03,bid_ct_03,ask_px_03,ask_sz_03,ask_ct_03,bid_px_04,bid_sz_04,bid_ct_04,ask_px_04,ask_sz_04,ask_ct_04,bid_px_05,bid_sz_05,bid_ct_05,ask_px_05,ask_sz_05,ask_ct_05,bid_px_06,bid_sz_06,bid_ct_06,ask_px_06,ask_sz_06,ask_ct_06,bid_px_07,bid_sz_07,bid_ct_07,ask_px_07,ask_sz_07,ask_ct_07,bid_px_08,bid_sz_08,bid_ct_08,ask_px_08,ask_sz_08,ask_ct_08,bid_px_09,bid_sz_09,bid_ct_09,ask_px_09,ask_sz_09,ask_ct_09
2025-07-17T16:12:40.997135307Z,2025-07-17T16:12:40.997300700Z,160,2,1108,C,A,0,14.33,100,130,165393,282007914,ARL,337790761,13.11,100,1,13.48,15,1,12.98,200,2,13.74,2,1,12.92,2,1,13.79,100,1,12.86,100,1,14.25,100,1,12.73,100,1,14.28,100,1,12.71,100,1,14.4,200,2,12.5,700,1,14.47,700,1,12.46,100,1,14.48,700,1,12.43,700,1,14.49,100,1,12.42,700,1,14.54,700,1
2025-07-17T16:12:40.997257014Z,2025-07-17T16:12:40.997422356Z,160,2,1108,A,A,0,14.58,100,130,165342,282007916,ARL,338864317,13.11,100,1,13.48,15,1,12.98,200,2,13.74,2,1,12.92,2,1,13.79,100,1,12.86,100,1,14.25,100,1,12.73,100,1,14.28,100,1,12.71,100,1,14.4,200,2,12.5,700,1,14.47,700,1,12.46,100,1,14.48,700,1,12.43,700,1,14.49,100,1,12.42,700,1,14.54,700,1
2025-07-17T16:12:41.004063876Z,2025-07-17T16:12:41.004229622Z,160,2,1108,C,A,0,14.49,100,0,165746,282007959,ARL,337790777,13.11,100,1,13.48,15,1,12.98,200,2,13.74,2,1,12.92,2,1,13.79,100,1,12.86,100,1,14.25,100,1,12.73,100,1,14.28,100,1,12.71,100,1,14.4,200,2,12.5,700,1,14.47,700,1,12.46,100,1,14.48,700,1,12.43,700,1,14.54,700,1,12.42,700,1,14.56,800,2
2025-07-17T16:12:41.004063876Z,2025-07-17T16:12:41.004229622Z,160,2,1108,A,A,0,14.76,100,130,165746,282007959,ARL,338864405,13.11,100,1,13.48,15,1,12.98,200,2,13.74,2,1,12.92,2,1,13.79,100,1,12.86,100,1,14.25,100,1,12.73,100,1,14.28,100,1,12.71,100,1,14.4,200,2,12.5,700,1,14.47,700,1,12.46,100,1,14.48,700,1,12.43,700,1,14.54,700,1,12.42,700,1,14.56,800,2
2025-07-17T16:12:41.005406614Z,2025-07-17T16:12:41.005576053Z,160,2,1108,A,A,0,13.49,100,128,169439,282008256,ARL,338864581,13.11,100,1,13.48,15,1,12.98,200,2,13.49,100,1,12.92,2,1,13.74,2,1,12.86,100,1,13.79,100,1,12.73,100,1,14.25,100,1,12.71,100,1,14.28,100,1,12.5,700,1,14.4,200,2,12.46,100,1,14.47,700,1,12.43,700,1,14.48,700,1,12.42,700,1,14.54,700,1
2025-07-17T16:12:41.010473041Z,2025-07-17T16:12:41.010638351Z,160,2,1108,C,A,0,14.76,100,0,165310,282008884,ARL,338864405,13.11,100,1,13.48,15,1,12.98,200,2,13.49,100,1,12.92,2,1,13.74,2,1,12.86,100,1,13.79,100,1,12.73,100,1,14.25,100,1,12.71,100,1,14.28,100,1,12.5,700,1,14.4,200,2,12.46,100,1,14.47,700,1,12.43,700,1,14.48,700,1,12.42,700,1,14.54,700,1
2025-07-17T16:12:41.010473041Z,2025-07-17T16:12:41.010638351Z,160,2,1108,A,A,0,14.44,100,130,165310,282008884,ARL,338865133,13.11,100,1,13.48,15,1,12.98,200,2,13.49,100,1,12.92,2,1,13.74,2,1,12.86,100,1,13.79,100,1,12.73,100,1,14.25,100,1,12.71,100,1,14.28,100,1,12.5,700,1,14.4,200,2,12.46,100,1,14.44,100,1,12.43,700,1,14.47,700,1,12.42,700,1,14.48,700,1
2025-07-17T16:12:41.010994859Z,2025-07-17T16:12:41.011160341Z,160,2,1108,C,A,0,13.79,100,130,165482,282008914,ARL,338044233,13.11,100,1,13.48,15,1,12.98,200,2,13.49,100,1,12.92,2,1,13.74,2,1,12.86,100,1,14.25,100,1,12.73,100,1,14.28,100,1,12.71,100,1,14.4,200,2,12.5,700,1,14.44,100,1,12.46,100,1,14.47,700,1,12.43,700,1,14.48,700,1,12.42,700,1,14.54,700,1
2025-07-17T16:12:41.011046717Z,2025-07-17T16:12:41.011211986Z,160,2,1108,A,A,0,14.06,100,130,165269,282008916,ARL,338865141,13.11,100,1,13.48,15,1,12.98,200,2,13.49,100,1,12.92,2,1,13.74,2,1,12.86,100,1,14.06,100,1,12.73,100,1,14.25,100,1,12.71,100,1,14.28,100,1,12.5,700,1,14.4,200,2,12.46,100,1,14.44,100,1,12.43,700,1,14.47,700,1,12.42,700,1,14.48,700,1
2025-07-17T16:12:41.011390077Z,2025-07-17T16:12:41.011555342Z,160,2,1108,C,A,0,14.76,100,0,165265,282008942,ARL,338864217,13.11,100,1,13.48,15,1,12.98,200,2,13.49,100,1,12.92,2,1,13.74,2,1,12.86,100,1,14.06,100,1,12.73,100,1,14.25,100,1,12.71,100,1,14.28,100,1,12.5,700,1,14.4,200,2,12.46,100,1,14.44,100,1,12.43,700,1,14.47,700,1,12.42,700,1,14.48,700,1
2025-07-17T16:12:41.011390077Z,2025-07-17T16:12:41.011555342Z,160,2,1108,A,A,0,14.44,100,130,165265,282008942,ARL,338865165,13.11,100,1,13.48,15,1,12.98,200,2,13.49,100,1,12.92,2,1,13.74,2,1,12.86,100,1,14.06,100,1,12.73,100,1,14.25,100,1,12.71,100,1,14.28,100,1,12.5,700,1,14.4,200,2,12.46,100,1,14.44,200,2,12.43,700,1,14.47,700,1,12.42,700,1,14.48,700,1
2025-07-17T16:12:41.011879795Z,2025-07-17T16:12:41.012044919Z,160,2,1108,C,A,0,14.06,100,130,165124,282008953,ARL,338865141,13.11,100,1,13.48,15,1,12.98,200,2,13.49,100,1,12.92,2,1,13.74,2,1,12.86,100,1,14.25,100,1,12.73,100,1,14.28,100,1,12.71,100,1,14.4,200,2,12.5,700,1,14.44,200,2,12.46,100,1,14.47,700,1,12.43,700,1,14.48,700,1,12.42,700,1,14.54,700,1
2025-07-17T16:12:41.011929033Z,2025-07-17T16:12:41.012094494Z,160,2,1108,A,A,0,13.76,100,130,165461,282008954,ARL,338865177,13.11,100,1,13.48,15,1,12.98,200,2,13.49,100,1,12.92,2,1,13.74,2,1,12.86,100,1,13.76,100,1,12.73,100,1,14.25,100,1,12.71,100,1,14.28,100,1,12.5,700,1,14.4,200,2,12.46,100,1,14.44,200,2,12.43,700,1,14.47,700,1,12.42,700,1,14.48,700,1
2025-07-17T16:12:41.014809197Z,2025-07-17T16:12:41.014974491Z,160,2,1108,C,A,0,17.52,100,0,165294,282008990,ARL,338864289,13.11,100,1,13.48,15,1,12.98,200,2,13.49,100,1,12.92,2,1,13.74,2,1,12.86,100,1,13.76,100,1,12.73,100,1,14.25,100,1,12.71,100,1,14.28,100,1,12.5,700,1,14.4,200,2,12.46,100,1,14.44,200,2,12.43,700,1,14.47,700,1,12.42,700,1,14.48,700,1
2025-07-17T16:12:41.014809197Z,2025-07-17T16:12:41.014974491Z,160,2,1108,A,A,0,17.14,100,130,165294,282008990,ARL,338865253,13.11,100,1,13.48,15,1,12.98,200,2,13.49,100,1,12.92,2,1,13.74,2,1,12.86,100,1,13.76,100,1,12.73,100,1,14.25,100,1,12.71,100,1,14.28,100,1,12.5,700,1,14.4,200,2,12.46,100,1,14.44,200,2,12.43,700,1,14.47,700,1,12.42,700,1,14.48,700,1
2025-07-17T16:12:41.017672033Z,2025-07-17T16:12:41.017837378Z,160,2,1108,C,A,0,15.86,100,0,165345,282009053,ARL,338864245,13.11,100,1,13.48,15,1,12.98,200,2,13.49,100,1,12.92,2,1,13.74,2,1,12.86,100,1,13.76,100,1,12.73,100,1,14.25,100,1,12.71,100,1,14.28,100,1,12.5,700,1,14.4,200,2,12.46,100,1,14.44,200,2,12.43,700,1,14.47,700,1,12.42,700,1,14.48,700,1
2025-07-17T16:12:41.017672033Z,2025-07-17T16:12:41.017837378Z,160,2,1108,A,A,0,15.52,100,130,165345,282009053,ARL,338865301,13.11,100,1,13.48,15,1,12.98,200,2,13.49,100,1,12.92,2,1,13.74,2,1,12.86,100,1,13.76,100,1,12.73,100,1,14.25,100,1,12.71,100,1,14.28,100,1,12.5,700,1,14.4,200,2,12.46,100,1,14.44,200,2,12.43,700,1,14.47,700,1,12.42,700,1,14.48,700,1
2025-07-17T16:12:41.032105565Z,2025-07-17T16:12:41.032270817Z,160,2,1108,C,A,0,15.17,100,0,165252,282009412,ARL,338864221,13.11,100,1,13.48,15,1,12.98,200,2,13.49,100,1,12.92,2,1,13.74,2,1,12.86,100,1,13.76,100,1,12.73,100,1,14.25,100,1,12.71,100,1,14.28,100,1,12.5,700,1,14.4,200,2,12.46,100,1,14.44,200,2,12.43,700,1,14.47,700,1,12.42,700,1,14.48,700,1
2025-07-17T16:12:41.032105565Z,2025-07-17T16:12:41.032270817Z,160,2,1108,A,A,0,14.84,100,130,165252,282009412,ARL,338866081,13.11,100,1,13.48,15,1,12.98,200,2,13.49,100,1,12.92,2,1,13.74,2,1,12.86,100,1,13.76,100,1,12.73,100,1,14.25,100,1,12.71,100,1,14.28,100,1,12.5,700,1,14.4,200,2,12.46,100,1,14.44,200,2,12.43,700,1,14.47,700,1,12.42,700,1,14.48,700,1
2025-07-17T16:12:41.032147083Z,2025-07-17T16:12:41.032312420Z,160,2,1108,A,A,0,15.38,100,130,165337,282009414,ARL,338866089,13.11,100,1,13.48,15,1,12.98,200,2,13.49,100,1,12.92,2,1,13.74,2,1,12.86,100,1,13.76,100,1,12.73,100,1,14.25,100,1,12.71,100,1,14.28,100,1,12.5,700,1,14.4,200,2,12.46,100,1,14.44,200,2,12.43,700,1,14.47,700,1,12.42,700,1,14.48,700,1
2025-07-17T16:12:41.032159348Z,2025-07-17T16:12:41.032324438Z,160,2,1108,C,A,0,15.71,100,130,165090,282009415,ARL,338864177,13.11,100,1,13.48,15,1,12.98,200,2,13.49,100,1,12.92,2,1,13.74,2,1,12.86,100,1,13.76,100,1,12.73,100,1,14.25,100,1,12.71,100,1,14.28,100,1,12.5,700,1,14.4,200,2,12.46,100,1,14.44,200,2,12.43,700,1,14.47,700,1,12.42,700,1,14.48,700,1
2025-07-17T16:12:41.043241012Z,2025-07-17T16:12:41.043406383Z,160,2,1108,C,A,0,14.85,100,0,165371,282009482,ARL,338864189,13.11,100,1,13.48,15,1,12.98,200,2,13.49,100,1,12.92,2,1,13.74,2,1,12.86,100,1,13.76,100,1,12.73,100,1,14.25,100,1,12.71,100,1,14.28,100,1,12.5,700,1,14.4,200,2,12.46,100,1,14.44,200,2,12.43,700,1,14.47,700,1,12.42,700,1,14.48,700,1
2025-07-17T16:12:41.043241012Z,2025-07-17T16:12:41.043406383Z,160,2,1108,A,A,0,14.54,100,130,165371,282009482,ARL,338866245,13.11,100,1,13.48,15,1,12.98,200,2,13.49,100,1,12.92,2,1,13.74,2,1,12.86,100,1,13.76,100,1,12.73,100,1,14.25,100,1,12.71,100,1,14.28,100,1,12.5,700,1,14.4,200,2,12.46,100,1,14.44,200,2,12.43,700,1,14.47,700,1,12.42,700,1,14.48,700,1
2025-07-17T16:12:42.001182016Z,2025-07-17T16:12:42.001347844Z,160,2,1108,C,A,0,14.58,100,0,165828,282033913,ARL,338864317,13.11,100,1,13.48,15,1,12.98,200,2,13.49,100,1,12.92,2,1,13.74,2,1,12.86,100,1,13.76,100,1,12.73,100,1,14.25,100,1,12.71,100,1,14.28,100,1,12.5,700,1,14.4,200,2,12.46,100,1,14.44,200,2,12.43,700,1,14.47,700,1,12.42,700,1,14.48,700,1
2025-07-17T16:12:42.001182016Z,2025-07-17T16:12:42.001347844Z,160,2,1108,A,A,0,14.28,100,130,165828,282033913,ARL,338894329,13.11,100,1,13.48,15,1,12.98,200,2,13.49,100,1,12.92,2,1,13.74,2,1,12.86,100,1,13.76,100,1,12.73,100,1,14.25,100,1,12.71,100,1,14.28,200,2,12.5,700,1,14.4,200,2,12.46,100,1,14.44,200,2,12.43,700,1,14.47,700,1,12.42,700,1,14.48,700,1
2025-07-17T16:12:42.761989222Z,2025-07-17T16:12:42.762154469Z,160,2,1108,A,A,0,13.46,15,130,165247,282042242,ARL,338904977,13.11,100,1,13.46,15,1,12.98,200,2,13.48,15,1,12.92,2,1,13.49,100,1,12.86,100,1,13.74,2,1,12.73,100,1,13.76,100,1,12.71,100,1,14.25,100,1,12.5,700,1,14.28,200,2,12.46,100,1,14.4,200,2,12.43,700,1,14.44,200,2,12.42,700,1,14.47,700,1
2025-07-17T16:12:43.021951997Z,2025-07-17T16:12:43.022127902Z,160,2,1108,C,A,0,13.49,100,0,175905,282057719,ARL,338864581,13.11,100,1,13.46,15,1,12.98,200,2,13.48,15,1,12.92,2,1,13.74,2,1,12.86,100,1,13.76,100,1,12.73,100,1,14.25,100,1,12.71,100,1,14.28,200,2,12.5,700,1,14.4,200,2,12.46,100,1,14.44,200,2,12.43,700,1,14.47,700,1,12.42,700,1,14.48,700,1
2025-07-17T16:12:43.021951997Z,2025-07-17T16:12:43.022127902Z,160,2,1108,A,A,0,13.47,100,128,175905,282057719,ARL,338918217,13.11,100,1,13.46,15,1,12.98,200,2,13.47,100,1,12.92,2,1,13.48,15,1,12.86,100,1,13.74,2,1,12.73,100,1,13.76,100,1,12.71,100,1,14.25,100,1,12.5,700,1,14.28,200,2,12.46,100,1,14.4,200,2,12.43,700,1,14.44,200,2,12.42,700,1,14.47,700,1
2025-07-17T16:12:43.022444956Z,2025-07-17T16:12:43.022612177Z,160,2,1108,A,A,0,15.69,100,128,167221,282058085,ARL,338918553,13.11,100,1,13.46,15,1,12.98,200,2,13.47,100,1,12.92,2,1,13.48,15,1,12.86,100,1,13.74,2,1,12.73,100,1,13.76,100,1,12.71,100,1,14.25,100,1,12.5,700,1,14.28,200,2,12.46,100,1,14.4,200,2,12.43,700,1,14.44,200,2,12.42,700,1,14.47,700,1
2025-07-17T16:12:43.022461725Z,2025-07-17T16:12:43.022627592Z,160,2,1108,C,A,0,15.38,100,130,165867,282058088,ARL,338866089,13.11,100,1,13.46,15,1,12.98,200,2,13.47,100,1,12.92,2,1,13.48,15,1,12.86,100,1,13.74,2,1,12.73,100,1,13.76,100,1,12.71,100,1,14.25,100,1,12.5,700,1,14.28,200,2,12.46,100,1,14.4,200,2,12.43,700,1,14.44,200,2,12.42,700,1,14.47,700,1
2025-07-17T16:12:43.049119139Z,2025-07-17T16:12:43.049284355Z,160,2,1108,A,A,0,15.36,100,130,165216,282065940,ARL,338926929,13.11,100,1,13.46,15,1,12.98,200,2,13.47,100,1,12.92,2,1,13.48,15,1,12.86,100,1,13.74,2,1,12.73,100,1,13.76,100,1,12.71,100,1,14.25,100,1,12.5,700,1,14.28,200,2,12.46,100,1,14.4,200,2,12.43,700,1,14.44,200,2,12.42,700,1,14.47,700,1
2025-07-17T16:12:43.049132842Z,2025-07-17T16:12:43.049298989Z,160,2,1108,C,A,0,15.69,100,128,166147,282065943,ARL,338918553,13.11,100,1,13.46,15,1,12.98,200,2,13.47,100,1,12.92,2,1,13.48,15,1,12.86,100,1,13.74,2,1,12.73,100,1,13.76,100,1,12.71,100,1,14.25,100,1,12.5,700,1,14.28,200,2,12.46,100,1,14.4,200,2,12.43,700,1,14.44,200,2,12.42,700,1,14.47,700,1
2025-07-17T16:12:43.154787212Z,2025-07-17T16:12:43.154952375Z,160,2,1108,A,A,0,14.27,100,130,165163,282073056,ARL,338932853,13.11,100,1,13.46,15,1,12.98,200,2,13.47,100,1,12.92,2,1,13.48,15,1,12.86,100,1,13.74,2,1,12.73,100,1,13.76,100,1,12.71,100,1,14.25,100,1,12.5,700,1,14.27,100,1,12.46,100,1,14.28,200,2,12.43,700,1,14.4,200,2,12.42,700,1,14.44,200,2
2025-07-17T16:12:43.154800020Z,2025-07-17T16:12:43.154965183Z,160,2,1108,C,A,0,14.56,100,130,165163,282073058,ARL,296391881,13.11,100,1,13.46,15,1,12.98,200,2,13.47,100,1,12.92,2,1,13.48,15,1,12.86,100,1,13.74,2,1,12.73,100,1,13.76,100,1,12.71,100,1,14.25,100,1,12.5,700,1,14.27,100,1,12.46,100,1,14.28,200,2,12.43,700,1,14.4,200,2,12.42,700,1,14.44,200,2
2025-07-17T16:12:43.915387059Z,2025-07-17T16:12:43.915552526Z,160,2,1108,C,A,0,14.28,100,130,165467,282085822,ARL,302681357,13.11,100,1,13.46,15,1,12.98,200,2,13.47,100,1,12.92,2,1,13.48,15,1,12.86,100,1,13.74,2,1,12.73,100,1,13.76,100,1,12.71,100,1,14.25,100,1,12.5,700,1,14.27,100,1,12.46,100,1,14.28,100,1,12.43,700,1,14.4,200,2,12.42,700,1,14.44,200,2
2025-07-17T16:12:43.915389642Z,2025-07-17T16:12:43.915555340Z,160,2,1108,A,A,0,14,100,130,165698,282085823,ARL,338945933,13.11,100,1,13.46,15,1,12.98,200,2,13.47,100,1,12.92,2,1,13.48,15,1,12.86,100,1,13.74,2,1,12.73,100,1,13.76,100,1,12.71,100,1,14,100,1,12.5,700,1,14.25,100,1,12.46,100,1,14.27,100,1,12.43,700,1,14.28,100,1,12.42,700,1,14.4,200,2
2025-07-17T16:12:50.729079105Z,2025-07-17T16:12:50.729244449Z,160,2,1108,C,A,0,13.46,15,130,165344,282168721,ARL,338904977,13.11,100,1,13.47,100,1,12.98,200,2,13.48,15,1,12.92,2,1,13.74,2,1,12.86,100,1,13.76,100,1,12.73,100,1,14,100,1,12.71,100,1,14.25,100,1,12.5,700,1,14.27,100,1,12.46,100,1,14.28,100,1,12.43,700,1,14.4,200,2,12.42,700,1,14.44,200,2
2025-07-17T16:12:50.729252907Z,2025-07-17T16:12:50.729418237Z,160,2,1108,C,A,0,13.48,15,130,165330,282168744,ARL,338707945,13.11,100,1,13.47,100,1,12.98,200,2,13.74,2,1,12.92,2,1,13.76,100,1,12.86,100,1,14,100,1,12.73,100,1,14.25,100,1,12.71,100,1,14.27,100,1,12.5,700,1,14.28,100,1,12.46,100,1,14.4,200,2,12.43,700,1,14.44,200,2,12.42,700,1,14.47,700,1
2025-07-17T16:12:50.729409745Z,2025-07-17T16:12:50.729575741Z,160,2,1108,A,A,0,13.47,96,130,165996,282168754,ARL,339054149,13.11,100,1,13.47,196,2,12.98,200,2,13.74,2,1,12.92,2,1,13.76,100,1,12.86,100,1,14,100,1,12.73,100,1,14.25,100,1,12.71,100,1,14.27,100,1,12.5,700,1,14.28,100,1,12.46,100,1,14.4,200,2,12.43,700,1,14.44,200,2,12.42,700,1,14.47,700,1
2025-07-17T16:12:53.021749348Z,2025-07-17T16:12:53.021914652Z,160,2,1108,A,A,0,13.46,15,130,165304,282194154,ARL,339096733,13.11,100,1,13.46,15,1,12.98,200,2,13.47,196,2,12.92,2,1,13.74,2,1,12.86,100,1,13.76,100,1,12.73,100,1,14,100,1,12.71,100,1,14.25,100,1,12.5,700,1,14.27,100,1,12.46,100,1,14.28,100,1,12.43,700,1,14.4,200,2,12.42,700,1,14.44,200,2
2025-07-17T16:12:53.021793735Z,2025-07-17T16:12:53.021959141Z,160,2,1108,C,A,0,13.47,100,130,165406,282194157,ARL,338918217,13.11,100,1,13.46,15,1,12.98,200,2,13.47,96,1,12.92,2,1,13.74,2,1,12.86,100,1,13.76,100,1,12.73,100,1,14,100,1,12.71,100,1,14.25,100,1,12.5,700,1,14.27,100,1,12.46,100,1,14.28,100,1,12.43,700,1,14.4,200,2,12.42,700,1,14.44,200,2
2025-07-17T16:12:53.022064745Z,2025-07-17T16:12:53.022230122Z,160,2,1108,C,A,0,13.47,96,130,165377,282194159,ARL,339054149,13.11,100,1,13.46,15,1,12.98,200,2,13.74,2,1,12.92,2,1,13.76,100,1,12.86,100,1,14,100,1,12.73,100,1,14.25,100,1,12.71,100,1,14.27,100,1,12.5,700,1,14.28,100,1,12.46,100,1,14.4,200,2,12.43,700,1,14.44,200,2,12.42,700,1,14.47,700,1
2025-07-17T16:12:53.022406202Z,2025-07-17T16:12:53.022572023Z,160,2,1108,A,A,0,15.69,100,130,165821,282194161,ARL,339096757,13.11,100,1,13.46,15,1,12.98,200,2,13.74,2,1,12.92,2,1,13.76,100,1,12.86,100,1,14,100,1,12.73,100,1,14.25,100,1,12.71,100,1,14.27,100,1,12.5,700,1,14.28,100,1,12.46,100,1,14.4,200,2,12.43,700,1,14.44,200,2,12.42,700,1,14.47,700,1
2025-07-17T16:12:53.022418950Z,2025-07-17T16:12:53.022584264Z,160,2,1108,C,A,0,15.36,100,130,165314,282194162,ARL,338926929,13.11,100,1,13.46,15,1,12.98,200,2,13.74,2,1,12.92,2,1,13.76,100,1,12.86,100,1,14,100,1,12.73,100,1,14.25,100,1,12.71,100,1,14.27,100,1,12.5,700,1,14.28,100,1,12.46,100,1,14.4,200,2,12.43,700,1,14.44,200,2,12.42,700,1,14.47,700,1
2025-07-17T16:12:53.022797046Z,2025-07-17T16:12:53.022962940Z,160,2,1108,C,A,0,14.54,100,0,165894,282194167,ARL,338866245,13.11,100,1,13.46,15,1,12.98,200,2,13.74,2,1,12.92,2,1,13.76,100,1,12.86,100,1,14,100,1,12.73,100,1,14.25,100,1,12.71,100,1,14.27,100,1,12.5,700,1,14.28,100,1,12.46,100,1,14.4,200,2,12.43,700,1,14.44,200,2,12.42,700,1,14.47,700,1
2025-07-17T16:12:53.022797046Z,2025-07-17T16:12:53.022962940Z,160,2,1108,A,A,0,14.83,100,130,165894,282194167,ARL,339096773,13.11,100,1,13.46,15,1,12.98,200,2,13.74,2,1,12.92,2,1,13.76,100,1,12.86,100,1,14,100,1,12.73,100,1,14.25,100,1,12.71,100,1,14.27,100,1,12.5,700,1,14.28,100,1,12.46,100,1,14.4,200,2,12.43,700,1,14.44,200,2,12.42,700,1,14.47,700,1
2025-07-17T16:12:53.023423468Z,2025-07-17T16:12:53.023589530Z,160,2,1108,C,A,0,14.44,100,0,166062,282194181,ARL,338865165,13.11,100,1,13.46,15,1,12.98,200,2,13.74,2,1,12.92,2,1,13.76,100,1,12.86,100,1,14,100,1,12.73,100,1,14.25,100,1,12.71,100,1,14.27,100,1,12.5,700,1,14.28,100,1,12.46,100,1,14.4,200,2,12.43,700,1,14.44,100,1,12.42,700,1,14.47,700,1
2025-07-17T16:12:53.023423468Z,2025-07-17T16:12:53.023589530Z,160,2,1108,A,A,0,14.73,100,130,166062,282194181,ARL,339096797,13.11,100,1,13.46,15,1,12.98,200,2,13.74,2,1,12.92,2,1,13.76,100,1,12.86,100,1,14,100,1,12.73,100,1,14.25,100,1,12.71,100,1,14.27,100,1,12.5,700,1,14.28,100,1,12.46,100,1,14.4,200,2,12.43,700,1,14.44,100,1,12.42,700,1,14.47,700,1
2025-07-17T16:12:53.023903582Z,2025-07-17T16:12:53.024069153Z,160,2,1108,C,A,0,17.14,100,0,165571,282194183,ARL,338865253,13.11,100,1,13.46,15,1,12.98,200,2,13.74,2,1,12.92,2,1,13.76,100,1,12.86,100,1,14,100,1,12.73,100,1,14.25,100,1,12.71,100,1,14.27,100,1,12.5,700,1,14.28,100,1,12.46,100,1,14.4,200,2,12.43,700,1,14.44,100,1,12.42,700,1,14.47,700,1
2025-07-17T16:12:53.023903582Z,2025-07-17T16:12:53.024069153Z,160,2,1108,A,A,0,17.48,100,130,165571,282194183,ARL,339096809,13.11,100,1,13.46,15,1,12.98,200,2,13.74,2,1,12.92,2,1,13.76,100,1,12.86,100,1,14,100,1,12.73,100,1,14.25,100,1,12.71,100,1,14.27,100,1,12.5,700,1,14.28,100,1,12.46,100,1,14.4,200,2,12.43,700,1,14.44,100,1,12.42,700,1,14.47,700,1
2025-07-17T16:12:53.025418159Z,2025-07-17T16:12:53.025583784Z,160,2,1108,C,A,0,14.84,100,0,165625,282194188,ARL,338866081,13.11,100,1,13.46,15,1,12.98,200,2,13.74,2,1,12.92,2,1,13.76,100,1,12.86,100,1,14,100,1,12.73,100,1,14.25,100,1,12.71,100,1,14.27,100,1,12.5,700,1,14.28,100,1,12.46,100,1,14.4,200,2,12.43,700,1,14.44,100,1,12.42,700,1,14.47,700,1
2025-07-17T16:12:53.025418159Z,2025-07-17T16:12:53.025583784Z,160,2,1108,A,A,0,15.14,100,130,165625,282194188,ARL,339096813,13.11,100,1,13.46,15,1,12.98,200,2,13.74,2,1,12.92,2,1,13.76,100,1,12.86,100,1,14,100,1,12.73,100,1,14.25,100,1,12.71,100,1,14.27,100,1,12.5,700,1,14.28,100,1,12.46,100,1,14.4,200,2,12.43,700,1,14.44,100,1,12.42,700,1,14.47,700,1
2025-07-17T16:12:53.025486466Z,2025-07-17T16:12:53.025651983Z,160,2,1108,C,A,0,14.44,100,0,165517,282194189,ARL,338865133,13.11,100,1,13.46,15,1,12.98,200,2,13.74,2,1,12.92,2,1,13.76,100,1,12.86,100,1,14,100,1,12.73,100,1,14.25,100,1,12.71,100,1,14.27,100,1,12.5,700,1,14.28,100,1,12.46,100,1,14.4,200,2,12.43,700,1,14.47,700,1,12.42,700,1,14.48,700,1
2025-07-17T16:12:53.025486466Z,2025-07-17T16:12:53.025651983Z,160,2,1108,A,A,0,14.73,100,130,165517,282194189,ARL,339096817,13.11,100,1,13.46,15,1,12.98,200,2,13.74,2,1,12.92,2,1,13.76,100,1,12.86,100,1,14,100,1,12.73,100,1,14.25,100,1,12.71,100,1,14.27,100,1,12.5,700,1,14.28,100,1,12.46,100,1,14.4,200,2,12.43,700,1,14.47,700,1,12.42,700,1,14.48,700,1
2025-07-17T16:12:53.027549524Z,2025-07-17T16:12:53.027715026Z,160,2,1108,C,A,0,14.28,100,130,165502,282194224,ARL,338894329,13.11,100,1,13.46,15,1,12.98,200,2,13.74,2,1,12.92,2,1,13.76,100,1,12.86,100,1,14,100,1,12.73,100,1,14.25,100,1,12.71,100,1,14.27,100,1,12.5,700,1,14.4,200,2,12.46,100,1,14.47,700,1,12.43,700,1,14.48,700,1,12.42,700,1,14.54,700,1
2025-07-17T16:12:53.027701439Z,2025-07-17T16:12:53.027866777Z,160,2,1108,A,A,0,14.55,100,130,165338,282194226,ARL,339096833,13.11,100,1,13.46,15,1,12.98,200,2,13.74,2,1,12.92,2,1,13.76,100,1,12.86,100,1,14,100,1,12.73,100,1,14.25,100,1,12.71,100,1,14.27,100,1,12.5,700,1,14.4,200,2,12.46,100,1,14.47,700,1,12.43,700,1,14.48,700,1,12.42,700,1,14.54,700,1
2025-07-17T16:12:53.027821450Z,2025-07-17T16:12:53.027987030Z,160,2,1108,C,A,0,15.52,100,0,165580,282194228,ARL,338865301,13.11,100,1,13.46,15,1,12.98,200,2,13.74,2,1,12.92,2,1,13.76,100,1,12.86,100,1,14,100,1,12.73,100,1,14.25,100,1,12.71,100,1,14.27,100,1,12.5,700,1,14.4,200,2,12.46,100,1,14.47,700,1,12.43,700,1,14.48,700,1,12.42,700,1,14.54,700,1
2025-07-17T16:12:53.027821450Z,2025-07-17T16:12:53.027987030Z,160,2,1108,A,A,0,15.83,100,130,165580,282194228,ARL,339096837,13.11,100,1,13.46,15,1,12.98,200,2,13.74,2,1,12.92,2,1,13.76,100,1,12.86,100,1,14,100,1,12.73,100,1,14.25,100,1,12.71,100,1,14.27,100,1,12.5,700,1,14.4,200,2,12.46,100,1,14.47,700,1,12.43,700,1,14.48,700,1,12.42,700,1,14.54,700,1
2025-07-17T16:12:53.033101265Z,2025-07-17T16:12:53.033266537Z,160,2,1108,C,A,0,13.76,100,130,165272,282194348,ARL,338865177,13.11,100,1,13.46,15,1,12.98,200,2,13.74,2,1,12.92,2,1,14,100,1,12.86,100,1,14.25,100,1,12.73,100,1,14.27,100,1,12.71,100,1,14.4,200,2,12.5,700,1,14.47,700,1,12.46,100,1,14.48,700,1,12.43,700,1,14.54,700,1,12.42,700,1,14.55,100,1
2025-07-17T16:12:53.033137644Z,2025-07-17T16:12:53.033302848Z,160,2,1108,C,A,0,14.47,700,130,165204,282194349,ARL,338864173,13.11,100,1,13.46,15,1,12.98,200,2,13.74,2,1,12.92,2,1,14,100,1,12.86,100,1,14.25,100,1,12.73,100,1,14.27,100,1,12.71,100,1,14.4,200,2,12.5,700,1,14.48,700,1,12.46,100,1,14.54,700,1,12.43,700,1,14.55,100,1,12.42,700,1,14.56,700,1
2025-07-17T16:12:53.033153612Z,2025-07-17T16:12:53.033318818Z,160,2,1108,A,A,0,14.04,100,130,165206,282194350,ARL,339096893,13.11,100,1,13.46,15,1,12.98,200,2,13.74,2,1,12.92,2,1,14,100,1,12.86,100,1,14.04,100,1,12.73,100,1,14.25,100,1,12.71,100,1,14.27,100,1,12.5,700,1,14.4,200,2,12.46,100,1,14.48,700,1,12.43,700,1,14.54,700,1,12.42,700,1,14.55,100,1
2025-07-17T16:12:53.033183560Z,2025-07-17T16:12:53.033349323Z,160,2,1108,A,A,0,14.68,700,130,165763,282194351,ARL,339096897,13.11,100,1,13.46,15,1,12.98,200,2,13.74,2,1,12.92,2,1,14,100,1,12.86,100,1,14.04,100,1,12.73,100,1,14.25,100,1,12.71,100,1,14.27,100,1,12.5,700,1,14.4,200,2,12.46,100,1,14.48,700,1,12.43,700,1,14.54,700,1,12.42,700,1,14.55,100,1
2025-07-17T16:12:53.033596046Z,2025-07-17T16:12:53.033762072Z,160,2,1108,C,A,0,13.74,2,0,166026,282194354,ARL,338371797,13.11,100,1,13.46,15,1,12.98,200,2,14,100,1,12.92,2,1,14.04,100,1,12.86,100,1,14.25,100,1,12.73,100,1,14.27,100,1,12.71,100,1,14.4,200,2,12.5,700,1,14.48,700,1,12.46,100,1,14.54,700,1,12.43,700,1,14.55,100,1,12.42,700,1,14.56,700,1
2025-07-17T16:12:53.033596046Z,2025-07-17T16:12:53.033762072Z,160,2,1108,A,A,0,13.98,2,130,166026,282194354,ARL,339096909,13.11,100,1,13.46,15,1,12.98,200,2,13.98,2,1,12.92,2,1,14,100,1,12.86,100,1,14.04,100,1,12.73,100,1,14.25,100,1,12.71,100,1,14.27,100,1,12.5,700,1,14.4,200,2,12.46,100,1,14.48,700,1,12.43,700,1,14.54,700,1,12.42,700,1,14.55,100,1
2025-07-17T16:12:53.033835120Z,2025-07-17T16:12:53.034000646Z,160,2,1108,C,A,0,14.25,100,130,165526,282194360,ARL,336161365,13.11,100,1,13.46,15,1,12.98,200,2,13.98,2,1,12.92,2,1,14,100,1,12.86,100,1,14.04,100,1,12.73,100,1,14.27,100,1,12.71,100,1,14.4,200,2,12.5,700,1,14.48,700,1,12.46,100,1,14.54,700,1,12.43,700,1,14.55,100,1,12.42,700,1,14.56,700,1
2025-07-17T16:12:53.033977054Z,2025-07-17T16:12:53.034142471Z,160,2,1108,C,A,0,14.73,100,0,165417,282194361,ARL,339096797,13.11,100,1,13.46,15,1,12.98,200,2,13.98,2,1,12.92,2,1,14,100,1,12.86,100,1,14.04,100,1,12.73,100,1,14.27,100,1,12.71,100,1,14.4,200,2,12.5,700,1,14.48,700,1,12.46,100,1,14.54,700,1,12.43,700,1,14.55,100,1,12.42,700,1,14.56,700,1
2025-07-17T16:12:53.033977054Z,2025-07-17T16:12:53.034142471Z,160,2,1108,A,A,0,14.96,100,130,165417,282194361,ARL,339096917,13.11,100,1,13.46,15,1,12.98,200,2,13.98,2,1,12.92,2,1,14,100,1,12.86,100,1,14.04,100,1,12.73,100,1,14.27,100,1,12.71,100,1,14.4,200,2,12.5,700,1,14.48,700,1,12.46,100,1,14.54,700,1,12.43,700,1,14.55,100,1,12.42,700,1,14.56,700,1
2025-07-17T16:12:53.034012618Z,2025-07-17T16:12:53.034178176Z,160,2,1108,C,A,0,15.83,100,0,165558,282194362,ARL,339096837,13.11,100,1,13.46,15,1,12.98,200,2,13.98,2,1,12.92,2,1,14,100,1,12.86,100,1,14.04,100,1,12.73,100,1,14.27,100,1,12.71,100,1,14.4,200,2,12.5,700,1,14.48,700,1,12.46,100,1,14.54,700,1,12.43,700,1,14.55,100,1,12.42,700,1,14.56,700,1
2025-07-17T16:12:53.034012618Z,2025-07-17T16:12:53.034178176Z,160,2,1108,A,A,0,16.08,100,130,165558,282194362,ARL,339096921,13.11,100,1,13.46,15,1,12.98,200,2,13.98,2,1,12.92,2,1,14,100,1,12.86,100,1,14.04,100,1,12.73,100,1,14.27,100,1,12.71,100,1,14.4,200,2,12.5,700,1,14.48,700,1,12.46,100,1,14.54,700,1,12.43,700,1,14.55,100,1,12.42,700,1,14.56,700,1
2025-07-17T16:12:53.034187864Z,2025-07-17T16:12:53.034353140Z,160,2,1108,A,A,0,14.6,100,130,165276,282194365,ARL,339096925,13.11,100,1,13.46,15,1,12.98,200,2,13.98,2,1,12.92,2,1,14,100,1,12.86,100,1,14.04,100,1,12.73,100,1,14.27,100,1,12.71,100,1,14.4,200,2,12.5,700,1,14.48,700,1,12.46,100,1,14.54,700,1,12.43,700,1,14.55,100,1,12.42,700,1,14.56,700,1
2025-07-17T16:12:53.035246187Z,2025-07-17T16:12:53.035411748Z,160,2,1108,C,A,0,15.05,100,0,165561,282194373,ARL,335220549,13.11,100,1,13.46,15,1,12.98,200,2,13.98,2,1,12.92,2,1,14,100,1,12.86,100,1,14.04,100,1,12.73,100,1,14.27,100,1,12.71,100,1,14.4,200,2,12.5,700,1,14.48,700,1,12.46,100,1,14.54,700,1,12.43,700,1,14.55,100,1,12.42,700,1,14.56,700,1
2025-07-17T16:12:53.035246187Z,2025-07-17T16:12:53.035411748Z,160,2,1108,A,A,0,15.38,100,130,165561,282194373,ARL,339096929,13.11,100,1,13.46,15,1,12.98,200,2,13.98,2,1,12.92,2,1,14,100,1,12.86,100,1,14.04,100,1,12.73,100,1,14.27,100,1,12.71,100,1,14.4,200,2,12.5,700,1,14.48,700,1,12.46,100,1,14.54,700,1,12.43,700,1,14.55,100,1,12.42,700,1,14.56,700,1
2025-07-17T16:12:53.036142164Z,2025-07-17T16:12:53.036307382Z,160,2,1108,C,A,0,17.48,100,0,165218,282194381,ARL,339096809,13.11,100,1,13.46,15,1,12.98,200,2,13.98,2,1,12.92,2,1,14,100,1,12.86,100,1,14.04,100,1,12.73,100,1,14.27,100,1,12.71,100,1,14.4,200,2,12.5,700,1,14.48,700,1,12.46,100,1,14.54,700,1,12.43,700,1,14.55,100,1,12.42,700,1,14.56,700,1
2025-07-17T16:12:53.036142164Z,2025-07-17T16:12:53.036307382Z,160,2,1108,A,A,0,17.76,100,130,165218,282194381,ARL,339096949,13.11,100,1,13.46,15,1,12.98,200,2,13.98,2,1,12.92,2,1,14,100,1,12.86,100,1,14.04,100,1,12.73,100,1,14.27,100,1,12.71,100,1,14.4,200,2,12.5,700,1,14.48,700,1,12.46,100,1,14.54,700,1,12.43,700,1,14.55,100,1,12.42,700,1,14.56,700,1
2025-07-17T16:12:53.039879965Z,2025-07-17T16:12:53.040045217Z,160,2,1108,C,A,0,14.73,100,0,165252,282194416,ARL,339096817,13.11,100,1,13.46,15,1,12.98,200,2,13.98,2,1,12.92,2,1,14,100,1,12.86,100,1,14.04,100,1,12.73,100,1,14.27,100,1,12.71,100,1,14.4,200,2,12.5,700,1,14.48,700,1,12.46,100,1,14.54,700,1,12.43,700,1,14.55,100,1,12.42,700,1,14.56,700,1
2025-07-17T16:12:53.039879965Z,2025-07-17T16:12:53.040045217Z,160,2,1108,A,A,0,14.96,100,130,165252,282194416,ARL,339096977,13.11,100,1,13.46,15,1,12.98,200,2,13.98,2,1,12.92,2,1,14,100,1,12.86,100,1,14.04,100,1,12.73,100,1,14.27,100,1,12.71,100,1,14.4,200,2,12.5,700,1,14.48,700,1,12.46,100,1,14.54,700,1,12.43,700,1,14.55,100,1,12.42,700,1,14.56,700,1
2025-07-17T16:12:53.043562198Z,2025-07-17T16:12:53.043727225Z,160,2,1108,C,A,0,14.04,100,130,165027,282194436,ARL,339096893,13.11,100,1,13.46,15,1,12.98,200,2,13.98,2,1,12.92,2,1,14,100,1,12.86,100,1,14.27,100,1,12.73,100,1,14.4,200,2,12.71,100,1,14.48,700,1,12.5,700,1,14.54,700,1,12.46,100,1,14.55,100,1,12.43,700,1,14.56,700,1,12.42,700,1,14.6,100,1
2025-07-17T16:12:53.043610101Z,2025-07-17T16:12:53.043775299Z,160,2,1108,A,A,0,14.26,100,130,165198,282194438,ARL,339097005,13.11,100,1,13.46,15,1,12.98,200,2,13.98,2,1,12.92,2,1,14,100,1,12.86,100,1,14.26,100,1,12.73,100,1,14.27,100,1,12.71,100,1,14.4,200,2,12.5,700,1,14.48,700,1,12.46,100,1,14.54,700,1,12.43,700,1,14.55,100,1,12.42,700,1,14.56,700,1
2025-07-17T16:12:53.072887133Z,2025-07-17T16:12:53.073052597Z,160,2,1108,C,A,0,14.83,100,0,165464,282194725,ARL,339096773,13.11,100,1,13.46,15,1,12.98,200,2,13.98,2,1,12.92,2,1,14,100,1,12.86,100,1,14.26,100,1,12.73,100,1,14.27,100,1,12.71,100,1,14.4,200,2,12.5,700,1,14.48,700,1,12.46,100,1,14.54,700,1,12.43,700,1,14.55,100,1,12.42,700,1,14.56,700,1
2025-07-17T16:12:53.072887133Z,2025-07-17T16:12:53.073052597Z,160,2,1108,A,A,0,15.06,100,130,165464,282194725,ARL,339097245,13.11,100,1,13.46,15,1,12.98,200,2,13.98,2,1,12.92,2,1,14,100,1,12.86,100,1,14.26,100,1,12.73,100,1,14.27,100,1,12.71,100,1,14.4,200,2,12.5,700,1,14.48,700,1,12.46,100,1,14.54,700,1,12.43,700,1,14.55,100,1,12.42,700,1,14.56,700,1
2025-07-17T16:12:53.332564148Z,2025-07-17T16:12:53.332729487Z,160,2,1108,C,A,0,14,100,130,165339,282196976,ARL,338945933,13.11,100,1,13.46,15,1,12.98,200,2,13.98,2,1,12.92,2,1,14.26,100,1,12.86,100,1,14.27,100,1,12.73,100,1,14.4,200,2,12.71,100,1,14.48,700,1,12.5,700,1,14.54,700,1,12.46,100,1,14.55,100,1,12.43,700,1,14.56,700,1,12.42,700,1,14.6,100,1
2025-07-17T16:12:53.332565150Z,2025-07-17T16:12:53.332730508Z,160,2,1108,A,A,0,14.53,100,130,165358,282196977,ARL,339100477,13.11,100,1,13.46,15,1,12.98,200,2,13.98,2,1,12.92,2,1,14.26,100,1,12.86,100,1,14.27,100,1,12.73,100,1,14.4,200,2,12.71,100,1,14.48,700,1,12.5,700,1,14.53,100,1,12.46,100,1,14.54,700,1,12.43,700,1,14.55,100,1,12.42,700,1,14.56,700,1
2025-07-17T16:12:53.587623157Z,2025-07-17T16:12:53.587788615Z,160,2,1108,A,A,0,14.81,100,130,165458,282200199,ARL,339103269,13.11,100,1,13.46,15,1,12.98,200,2,13.98,2,1,12.92,2,1,14.26,100,1,12.86,100,1,14.27,100,1,12.73,100,1,14.4,200,2,12.71,100,1,14.48,700,1,12.5,700,1,14.53,100,1,12.46,100,1,14.54,700,1,12.43,700,1,14.55,100,1,12.42,700,1,14.56,700,1
2025-07-17T16:12:53.587644886Z,2025-07-17T16:12:53.587810242Z,160,2,1108,C,A,0,14.27,100,130,165356,282200200,ARL,338932853,13.11,100,1,13.46,15,1,12.98,200,2,13.98,2,1,12.92,2,1,14.26,100,1,12.86,100,1,14.4,200,2,12.73,100,1,14.48,700,1,12.71,100,1,14.53,100,1,12.5,700,1,14.54,700,1,12.46,100,1,14.55,100,1,12.43,700,1,14.56,700,1,12.42,700,1,14.6,100,1
2025-07-17T16:12:54.015051915Z,2025-07-17T16:12:54.015217279Z,160,2,1108,A,A,0,13.47,100,130,165364,282207405,ARL,339110853,13.11,100,1,13.46,15,1,12.98,200,2,13.47,100,1,12.92,2,1,13.98,2,1,12.86,100,1,14.26,100,1,12.73,100,1,14.4,200,2,12.71,100,1,14.48,700,1,12.5,700,1,14.53,100,1,12.46,100,1,14.54,700,1,12.43,700,1,14.55,100,1,12.42,700,1,14.56,700,1
2025-07-17T16:12:54.015785325Z,2025-07-17T16:12:54.015951319Z,160,2,1108,C,A,0,14.6,100,130,165994,282207428,ARL,339096925,13.11,100,1,13.46,15,1,12.98,200,2,13.47,100,1,12.92,2,1,13.98,2,1,12.86,100,1,14.26,100,1,12.73,100,1,14.4,200,2,12.71,100,1,14.48,700,1,12.5,700,1,14.53,100,1,12.46,100,1,14.54,700,1,12.43,700,1,14.55,100,1,12.42,700,1,14.56,700,1
2025-07-17T16:12:54.015788678Z,2025-07-17T16:12:54.015954059Z,160,2,1108,C,A,0,15.06,100,0,165381,282207429,ARL,339097245,13.11,100,1,13.46,15,1,12.98,200,2,13.47,100,1,12.92,2,1,13.98,2,1,12.86,100,1,14.26,100,1,12.73,100,1,14.4,200,2,12.71,100,1,14.48,700,1,12.5,700,1,14.53,100,1,12.46,100,1,14.54,700,1,12.43,700,1,14.55,100,1,12.42,700,1,14.56,700,1
2025-07-17T16:12:54.015788678Z,2025-07-17T16:12:54.015954059Z,160,2,1108,A,A,0,14.52,100,130,165381,282207429,ARL,339110897,13.11,100,1,13.46,15,1,12.98,200,2,13.47,100,1,12.92,2,1,13.98,2,1,12.86,100,1,14.26,100,1,12.73,100,1,14.4,200,2,12.71,100,1,14.48,700,1,12.5,700,1,14.52,100,1,12.46,100,1,14.53,100,1,12.43,700,1,14.54,700,1,12.42,700,1,14.55,100,1
2025-07-17T16:12:54.016139684Z,2025-07-17T16:12:54.016305036Z,160,2,1108,A,A,0,14.07,100,130,165352,282207437,ARL,339110909,13.11,100,1,13.46,15,1,12.98,200,2,13.47,100,1,12.92,2,1,13.98,2,1,12.86,100,1,14.07,100,1,12.73,100,1,14.26,100,1,12.71,100,1,14.4,200,2,12.5,700,1,14.48,700,1,12.46,100,1,14.52,100,1,12.43,700,1,14.53,100,1,12.42,700,1,14.54,700,1
2025-07-17T16:12:54.016988897Z,2025-07-17T16:12:54.017154493Z,160,2,1108,C,A,0,14.96,100,0,165596,282207488,ARL,339096917,13.11,100,1,13.46,15,1,12.98,200,2,13.47,100,1,12.92,2,1,13.98,2,1,12.86,100,1,14.07,100,1,12.73,100,1,14.26,100,1,12.71,100,1,14.4,200,2,12.5,700,1,14.48,700,1,12.46,100,1,14.52,100,1,12.43,700,1,14.53,100,1,12.42,700,1,14.54,700,1
2025-07-17T16:12:54.016988897Z,2025-07-17T16:12:54.017154493Z,160,2,1108,A,A,0,14.42,100,130,165596,282207488,ARL,339110981,13.11,100,1,13.46,15,1,12.98,200,2,13.47,100,1,12.92,2,1,13.98,2,1,12.86,100,1,14.07,100,1,12.73,100,1,14.26,100,1,12.71,100,1,14.4,200,2,12.5,700,1,14.42,100,1,12.46,100,1,14.48,700,1,12.43,700,1,14.52,100,1,12.42,700,1,14.53,100,1
2025-07-17T16:12:54.017215883Z,2025-07-17T16:12:54.017381126Z,160,2,1108,C,A,0,13.98,2,0,165243,282207495,ARL,339096909,13.11,100,1,13.46,15,1,12.98,200,2,13.47,100,1,12.92,2,1,14.07,100,1,12.86,100,1,14.26,100,1,12.73,100,1,14.4,200,2,12.71,100,1,14.42,100,1,12.5,700,1,14.48,700,1,12.46,100,1,14.52,100,1,12.43,700,1,14.53,100,1,12.42,700,1,14.54,700,1
2025-07-17T16:12:54.017215883Z,2025-07-17T16:12:54.017381126Z,160,2,1108,A,A,0,13.73,2,130,165243,282207495,ARL,339110993,13.11,100,1,13.46,15,1,12.98,200,2,13.47,100,1,12.92,2,1,13.73,2,1,12.86,100,1,14.07,100,1,12.73,100,1,14.26,100,1,12.71,100,1,14.4,200,2,12.5,700,1,14.42,100,1,12.46,100,1,14.48,700,1,12.43,700,1,14.52,100,1,12.42,700,1,14.53,100,1
2025-07-17T16:12:54.017622232Z,2025-07-17T16:12:54.017787766Z,160,2,1108,C,A,0,15.38,100,0,165534,282207502,ARL,339096929,13.11,100,1,13.46,15,1,12.98,200,2,13.47,100,1,12.92,2,1,13.73,2,1,12.86,100,1,14.07,100,1,12.73,100,1,14.26,100,1,12.71,100,1,14.4,200,2,12.5,700,1,14.42,100,1,12.46,100,1,14.48,700,1,12.43,700,1,14.52,100,1,12.42,700,1,14.53,100,1
2025-07-17T16:12:54.017622232Z,2025-07-17T16:12:54.017787766Z,160,2,1108,A,A,0,14.82,100,130,165534,282207502,ARL,339111005,13.11,100,1,13.46,15,1,12.98,200,2,13.47,100,1,12.92,2,1,13.73,2,1,12.86,100,1,14.07,100,1,12.73,100,1,14.26,100,1,12.71,100,1,14.4,200,2,12.5,700,1,14.42,100,1,12.46,100,1,14.48,700,1,12.43,700,1,14.52,100,1,12.42,700,1,14.53,100,1
2025-07-17T16:12:54.020013940Z,2025-07-17T16:12:54.020179178Z,160,2,1108,C,A,0,14.26,100,130,165238,282207539,ARL,339097005,13.11,100,1,13.46,15,1,12.98,200,2,13.47,100,1,12.92,2,1,13.73,2,1,12.86,100,1,14.07,100,1,12.73,100,1,14.4,200,2,12.71,100,1,14.42,100,1,12.5,700,1,14.48,700,1,12.46,100,1,14.52,100,1,12.43,700,1,14.53,100,1,12.42,700,1,14.54,700,1
2025-07-17T16:12:54.020067630Z,2025-07-17T16:12:54.020233019Z,160,2,1108,A,A,0,13.74,100,130,165389,282207540,ARL,339111029,13.11,100,1,13.46,15,1,12.98,200,2,13.47,100,1,12.92,2,1,13.73,2,1,12.86,100,1,13.74,100,1,12.73,100,1,14.07,100,1,12.71,100,1,14.4,200,2,12.5,700,1,14.42,100,1,12.46,100,1,14.48,700,1,12.43,700,1,14.52,100,1,12.42,700,1,14.53,100,1
2025-07-17T16:12:54.022862493Z,2025-07-17T16:12:54.023027943Z,160,2,1108,C,A,0,17.76,100,0,165450,282207651,ARL,339096949,13.11,100,1,13.46,15,1,12.98,200,2,13.47,100,1,12.92,2,1,13.73,2,1,12.86,100,1,13.74,100,1,12.73,100,1,14.07,100,1,12.71,100,1,14.4,200,2,12.5,700,1,14.42,100,1,12.46,100,1,14.48,700,1,12.43,700,1,14.52,100,1,12.42,700,1,14.53,100,1
2025-07-17T16:12:54.022862493Z,2025-07-17T16:12:54.023027943Z,160,2,1108,A,A,0,17.11,100,130,165450,282207651,ARL,339111097,13.11,100,1,13.46,15,1,12.98,200,2,13.47,100,1,12.92,2,1,13.73,2,1,12.86,100,1,13.74,100,1,12.73,100,1,14.07,100,1,12.71,100,1,14.4,200,2,12.5,700,1,14.42,100,1,12.46,100,1,14.48,700,1,12.43,700,1,14.52,100,1,12.42,700,1,14.53,100,1
2025-07-17T16:12:54.026021681Z,2025-07-17T16:12:54.026187354Z,160,2,1108,C,A,0,16.08,100,0,165673,282207700,ARL,339096921,13.11,100,1,13.46,15,1,12.98,200,2,13.47,100,1,12.92,2,1,13.73,2,1,12.86,100,1,13.74,100,1,12.73,100,1,14.07,100,1,12.71,100,1,14.4,200,2,12.5,700,1,14.42,100,1,12.46,100,1,14.48,700,1,12.43,700,1,14.52,100,1,12.42,700,1,14.53,100,1
2025-07-17T16:12:54.026021681Z,2025-07-17T16:12:54.026187354Z,160,2,1108,A,A,0,15.5,100,130,165673,282207700,ARL,339111149,13.11,100,1,13.46,15,1,12.98,200,2,13.47,100,1,12.92,2,1,13.73,2,1,12.86,100,1,13.74,100,1,12.73,100,1,14.07,100,1,12.71,100,1,14.4,200,2,12.5,700,1,14.42,100,1,12.46,100,1,14.48,700,1,12.43,700,1,14.52,100,1,12.42,700,1,14.53,100,1
2025-07-17T16:12:54.029066847Z,2025-07-17T16:12:54.029232379Z,160,2,1108,C,A,0,14.55,100,0,165532,282207737,ARL,339096833,13.11,100,1,13.46,15,1,12.98,200,2,13.47,100,1,12.92,2,1,13.73,2,1,12.86,100,1,13.74,100,1,12.73,100,1,14.07,100,1,12.71,100,1,14.4,200,2,12.5,700,1,14.42,100,1,12.46,100,1,14.48,700,1,12.43,700,1,14.52,100,1,12.42,700,1,14.53,100,1
2025-07-17T16:12:54.029066847Z,2025-07-17T16:12:54.029232379Z,160,2,1108,A,A,0,14.26,100,130,165532,282207737,ARL,339111189,13.11,100,1,13.46,15,1,12.98,200,2,13.47,100,1,12.92,2,1,13.73,2,1,12.86,100,1,13.74,100,1,12.73,100,1,14.07,100,1,12.71,100,1,14.26,100,1,12.5,700,1,14.4,200,2,12.46,100,1,14.42,100,1,12.43,700,1,14.48,700,1,12.42,700,1,14.52,100,1
2025-07-17T16:12:54.055092122Z,2025-07-17T16:12:54.055257401Z,160,2,1108,A,A,0,15.36,100,130,165279,282209385,ARL,339112469,13.11,100,1,13.46,15,1,12.98,200,2,13.47,100,1,12.92,2,1,13.73,2,1,12.86,100,1,13.74,100,1,12.73,100,1,14.07,100,1,12.71,100,1,14.26,100,1,12.5,700,1,14.4,200,2,12.46,100,1,14.42,100,1,12.43,700,1,14.48,700,1,12.42,700,1,14.52,100,1
2025-07-17T16:12:54.055104415Z,2025-07-17T16:12:54.055269406Z,160,2,1108,C,A,0,15.69,100,130,164991,282209392,ARL,339096757,13.11,100,1,13.46,15,1,12.98,200,2,13.47,100,1,12.92,2,1,13.73,2,1,12.86,100,1,13.74,100,1,12.73,100,1,14.07,100,1,12.71,100,1,14.26,100,1,12.5,700,1,14.4,200,2,12.46,100,1,14.42,100,1,12.43,700,1,14.48,700,1,12.42,700,1,14.52,100,1
2025-07-17T16:12:54.069614114Z,2025-07-17T16:12:54.069779810Z,160,2,1108,C,A,0,14.96,100,0,165696,282210148,ARL,339096977,13.11,100,1,13.46,15,1,12.98,200,2,13.47,100,1,12.92,2,1,13.73,2,1,12.86,100,1,13.74,100,1,12.73,100,1,14.07,100,1,12.71,100,1,14.26,100,1,12.5,700,1,14.4,200,2,12.46,100,1,14.42,100,1,12.43,700,1,14.48,700,1,12.42,700,1,14.52,100,1
2025-07-17T16:12:54.069614114Z,2025-07-17T16:12:54.069779810Z,160,2,1108,A,A,0,14.42,100,130,165696,282210148,ARL,339112945,13.11,100,1,13.46,15,1,12.98,200,2,13.47,100,1,12.92,2,1,13.73,2,1,12.86,100,1,13.74,100,1,12.73,100,1,14.07,100,1,12.71,100,1,14.26,100,1,12.5,700,1,14.4,200,2,12.46,100,1,14.42,200,2,12.43,700,1,14.48,700,1,12.42,700,1,14.52,100,1
2025-07-17T16:12:54.072716256Z,2025-07-17T16:12:54.072881596Z,160,2,1108,C,A,0,15.14,100,0,165340,282210181,ARL,339096813,13.11,100,1,13.46,15,1,12.98,200,2,13.47,100,1,12.92,2,1,13.73,2,1,12.86,100,1,13.74,100,1,12.73,100,1,14.07,100,1,12.71,100,1,14.26,100,1,12.5,700,1,14.4,200,2,12.46,100,1,14.42,200,2,12.43,700,1,14.48,700,1,12.42,700,1,14.52,100,1
2025-07-17T16:12:54.072716256Z,2025-07-17T16:12:54.072881596Z,160,2,1108,A,A,0,14.82,100,130,165340,282210181,ARL,339112981,13.11,100,1,13.46,15,1,12.98,200,2,13.47,100,1,12.92,2,1,13.73,2,1,12.86,100,1,13.74,100,1,12.73,100,1,14.07,100,1,12.71,100,1,14.26,100,1,12.5,700,1,14.4,200,2,12.46,100,1,14.42,200,2,12.43,700,1,14.48,700,1,12.42,700,1,14.52,100,1
2025-07-17T16:12:54.694630780Z,2025-07-17T16:12:54.694796063Z,160,2,1108,A,A,0,14.27,100,130,165283,282224916,ARL,339126221,13.11,100,1,13.46,15,1,12.98,200,2,13.47,100,1,12.92,2,1,13.73,2,1,12.86,100,1,13.74,100,1,12.73,100,1,14.07,100,1,12.71,100,1,14.26,100,1,12.5,700,1,14.27,100,1,12.46,100,1,14.4,200,2,12.43,700,1,14.42,200,2,12.42,700,1,14.48,700,1
2025-07-17T16:12:54.694644316Z,2025-07-17T16:12:54.694809520Z,160,2,1108,C,A,0,14.81,100,130,165204,282224917,ARL,339103269,13.11,100,1,13.46,15,1,12.98,200,2,13.47,100,1,12.92,2,1,13.73,2,1,12.86,100,1,13.74,100,1,12.73,100,1,14.07,100,1,12.71,100,1,14.26,100,1,12.5,700,1,14.27,100,1,12.46,100,1,14.4,200,2,12.43,700,1,14.42,200,2,12.42,700,1,14.48,700,1
2025-07-17T16:12:55.255162003Z,2025-07-17T16:12:55.255327586Z,160,2,1108,A,A,0,14,100,130,165583,282231441,ARL,339133353,13.11,100,1,13.46,15,1,12.98,200,2,13.47,100,1,12.92,2,1,13.73,2,1,12.86,100,1,13.74,100,1,12.73,100,1,14,100,1,12.71,100,1,14.07,100,1,12.5,700,1,14.26,100,1,12.46,100,1,14.27,100,1,12.43,700,1,14.4,200,2,12.42,700,1,14.42,200,2
2025-07-17T16:12:55.255163083Z,2025-07-17T16:12:55.255328269Z,160,2,1108,C,A,0,14.53,100,130,165186,282231442,ARL,339100477,13.11,100,1,13.46,15,1,12.98,200,2,13.47,100,1,12.92,2,1,13.73,2,1,12.86,100,1,13.74,100,1,12.73,100,1,14,100,1,12.71,100,1,14.07,100,1,12.5,700,1,14.26,100,1,12.46,100,1,14.27,100,1,12.43,700,1,14.4,200,2,12.42,700,1,14.42,200,2
2025-07-17T16:12:58.302017238Z,2025-07-17T16:12:58.302183447Z,160,2,1108,C,A,0,13.46,15,128,166209,282279351,ARL,339096733,13.11,100,1,13.47,100,1,12.98,200,2,13.73,2,1,12.92,2,1,13.74,100,1,12.86,100,1,14,100,1,12.73,100,1,14.07,100,1,12.71,100,1,14.26,100,1,12.5,700,1,14.27,100,1,12.46,100,1,14.4,200,2,12.43,700,1,14.42,200,2,12.42,700,1,14.48,700,1
2025-07-17T16:12:58.420710579Z,2025-07-17T16:12:58.420887746Z,160,2,1108,C,A,0,13.47,100,128,177167,282288716,ARL,339110853,13.11,100,1,13.73,2,1,12.98,200,2,13.74,100,1,12.92,2,1,14,100,1,12.86,100,1,14.07,100,1,12.73,100,1,14.26,100,1,12.71,100,1,14.27,100,1,12.5,700,1,14.4,200,2,12.46,100,1,14.42,200,2,12.43,700,1,14.48,700,1,12.42,700,1,14.52,100,1
2025-07-17T16:12:58.420776003Z,2025-07-17T16:12:58.420950587Z,160,2,1108,A,A,0,13.47,96,128,174584,282288757,ARL,339201549,13.11,100,1,13.47,96,1,12.98,200,2,13.73,2,1,12.92,2,1,13.74,100,1,12.86,100,1,14,100,1,12.73,100,1,14.07,100,1,12.71,100,1,14.26,100,1,12.5,700,1,14.27,100,1,12.46,100,1,14.4,200,2,12.43,700,1,14.42,200,2,12.42,700,1,14.48,700,1
2025-07-17T16:12:58.421165414Z,2025-07-17T16:12:58.421338553Z,160,2,1108,C,A,0,13.47,96,130,173139,282289082,ARL,339201549,13.11,100,1,13.73,2,1,12.98,200,2,13.74,100,1,12.92,2,1,14,100,1,12.86,100,1,14.07,100,1,12.73,100,1,14.26,100,1,12.71,100,1,14.27,100,1,12.5,700,1,14.4,200,2,12.46,100,1,14.42,200,2,12.43,700,1,14.48,700,1,12.42,700,1,14.52,100,1
2025-07-17T16:12:58.421205027Z,2025-07-17T16:12:58.421379924Z,160,2,1108,A,A,0,15.67,100,128,174897,282289111,ARL,339202065,13.11,100,1,13.73,2,1,12.98,200,2,13.74,100,1,12.92,2,1,14,100,1,12.86,100,1,14.07,100,1,12.73,100,1,14.26,100,1,12.71,100,1,14.27,100,1,12.5,700,1,14.4,200,2,12.46,100,1,14.42,200,2,12.43,700,1,14.48,700,1,12.42,700,1,14.52,100,1
2025-07-17T16:12:58.421248082Z,2025-07-17T16:12:58.421423275Z,160,2,1108,C,A,0,15.36,100,128,175193,282289154,ARL,339112469,13.11,100,1,13.73,2,1,12.98,200,2,13.74,100,1,12.92,2,1,14,100,1,12.86,100,1,14.07,100,1,12.73,100,1,14.26,100,1,12.71,100,1,14.27,100,1,12.5,700,1,14.4,200,2,12.46,100,1,14.42,200,2,12.43,700,1,14.48,700,1,12.42,700,1,14.52,100,1
2025-07-17T16:12:58.421581692Z,2025-07-17T16:12:58.421756726Z,160,2,1108,C,A,0,14.07,100,130,175034,282289338,ARL,339110909,13.11,100,1,13.73,2,1,12.98,200,2,13.74,100,1,12.92,2,1,14,100,1,12.86,100,1,14.26,100,1,12.73,100,1,14.27,100,1,12.71,100,1,14.4,200,2,12.5,700,1,14.42,200,2,12.46,100,1,14.48,700,1,12.43,700,1,14.52,100,1,12.42,700,1,14.54,700,1
2025-07-17T16:12:58.421969675Z,2025-07-17T16:12:58.422145785Z,160,2,1108,A,A,0,14.35,100,128,176110,282289650,ARL,339202733,13.11,100,1,13.73,2,1,12.98,200,2,13.74,100,1,12.92,2,1,14,100,1,12.86,100,1,14.26,100,1,12.73,100,1,14.27,100,1,12.71,100,1,14.35,100,1,12.5,700,1,14.4,200,2,12.46,100,1,14.42,200,2,12.43,700,1,14.48,700,1,12.42,700,1,14.52,100,1
2025-07-17T16:12:58.422073305Z,2025-07-17T16:12:58.422247877Z,160,2,1108,C,A,0,14.52,100,0,174572,282289747,ARL,339110897,13.11,100,1,13.73,2,1,12.98,200,2,13.74,100,1,12.92,2,1,14,100,1,12.86,100,1,14.26,100,1,12.73,100,1,14.27,100,1,12.71,100,1,14.35,100,1,12.5,700,1,14.4,200,2,12.46,100,1,14.42,200,2,12.43,700,1,14.48,700,1,12.42,700,1,14.54,700,1
2025-07-17T16:12:58.422073305Z,2025-07-17T16:12:58.422247877Z,160,2,1108,A,A,0,14.81,100,128,174572,282289747,ARL,339202805,13.11,100,1,13.73,2,1,12.98,200,2,13.74,100,1,12.92,2,1,14,100,1,12.86,100,1,14.26,100,1,12.73,100,1,14.27,100,1,12.71,100,1,14.35,100,1,12.5,700,1,14.4,200,2,12.46,100,1,14.42,200,2,12.43,700,1,14.48,700,1,12.42,700,1,14.54,700,1
2025-07-17T16:12:58.424789366Z,2025-07-17T16:12:58.424958370Z,160,2,1108,C,A,0,14.4,100,0,169004,282290622,ARL,338139585,13.11,100,1,13.73,2,1,12.98,200,2,13.74,100,1,12.92,2,1,14,100,1,12.86,100,1,14.26,100,1,12.73,100,1,14.27,100,1,12.71,100,1,14.35,100,1,12.5,700,1,14.4,100,1,12.46,100,1,14.42,200,2,12.43,700,1,14.48,700,1,12.42,700,1,14.54,700,1
2025-07-17T16:12:58.424789366Z,2025-07-17T16:12:58.424958370Z,160,2,1108,A,A,0,14.57,100,128,169004,282290622,ARL,339203693,13.11,100,1,13.73,2,1,12.98,200,2,13.74,100,1,12.92,2,1,14,100,1,12.86,100,1,14.26,100,1,12.73,100,1,14.27,100,1,12.71,100,1,14.35,100,1,12.5,700,1,14.4,100,1,12.46,100,1,14.42,200,2,12.43,700,1,14.48,700,1,12.42,700,1,14.54,700,1
2025-07-17T16:12:58.425283932Z,2025-07-17T16:12:58.425450176Z,160,2,1108,C,A,0,14.4,100,0,166244,282290769,ARL,338139601,13.11,100,1,13.73,2,1,12.98,200,2,13.74,100,1,12.92,2,1,14,100,1,12.86,100,1,14.26,100,1,12.73,100,1,14.27,100,1,12.71,100,1,14.35,100,1,12.5,700,1,14.42,200,2,12.46,100,1,14.48,700,1,12.43,700,1,14.54,700,1,12.42,700,1,14.56,700,1
2025-07-17T16:12:58.425283932Z,2025-07-17T16:12:58.425450176Z,160,2,1108,A,A,0,14.57,100,128,166244,282290769,ARL,339203897,13.11,100,1,13.73,2,1,12.98,200,2,13.74,100,1,12.92,2,1,14,100,1,12.86,100,1,14.26,100,1,12.73,100,1,14.27,100,1,12.71,100,1,14.35,100,1,12.5,700,1,14.42,200,2,12.46,100,1,14.48,700,1,12.43,700,1,14.54,700,1,12.42,700,1,14.56,700,1
2025-07-17T16:12:58.426258092Z,2025-07-17T16:12:58.426423622Z,160,2,1108,C,A,0,14.26,100,130,165530,282290946,ARL,339111189,13.11,100,1,13.73,2,1,12.98,200,2,13.74,100,1,12.92,2,1,14,100,1,12.86,100,1,14.27,100,1,12.73,100,1,14.35,100,1,12.71,100,1,14.42,200,2,12.5,700,1,14.48,700,1,12.46,100,1,14.54,700,1,12.43,700,1,14.56,700,1,12.42,700,1,14.57,200,2
2025-07-17T16:12:58.426378483Z,2025-07-17T16:12:58.426544477Z,160,2,1108,A,A,0,14.53,100,130,165994,282290959,ARL,339204077,13.11,100,1,13.73,2,1,12.98,200,2,13.74,100,1,12.92,2,1,14,100,1,12.86,100,1,14.27,100,1,12.73,100,1,14.35,100,1,12.71,100,1,14.42,200,2,12.5,700,1,14.48,700,1,12.46,100,1,14.53,100,1,12.43,700,1,14.54,700,1,12.42,700,1,14.56,700,1
2025-07-17T16:12:58.430665639Z,2025-07-17T16:12:58.430830694Z,160,2,1108,C,A,0,13.74,100,130,165055,282291933,ARL,339111029,13.11,100,1,13.73,2,1,12.98,200,2,14,100,1,12.92,2,1,14.27,100,1,12.86,100,1,14.35,100,1,12.73,100,1,14.42,200,2,12.71,100,1,14.48,700,1,12.5,700,1,14.53,100,1,12.46,100,1,14.54,700,1,12.43,700,1,14.56,700,1,12.42,700,1,14.57,200,2
2025-07-17T16:12:58.430720526Z,2025-07-17T16:12:58.430888526Z,160,2,1108,A,A,0,14.01,100,128,168000,282291946,ARL,339205213,13.11,100,1,13.73,2,1,12.98,200,2,14,100,1,12.92,2,1,14.01,100,1,12.86,100,1,14.27,100,1,12.73,100,1,14.35,100,1,12.71,100,1,14.42,200,2,12.5,700,1,14.48,700,1,12.46,100,1,14.53,100,1,12.43,700,1,14.54,700,1,12.42,700,1,14.56,700,1
2025-07-17T16:12:58.432736189Z,2025-07-17T16:12:58.432901795Z,160,2,1108,C,A,0,14.82,100,0,165606,282292390,ARL,339111005,13.11,100,1,13.73,2,1,12.98,200,2,14,100,1,12.92,2,1,14.01,100,1,12.86,100,1,14.27,100,1,12.73,100,1,14.35,100,1,12.71,100,1,14.42,200,2,12.5,700,1,14.48,700,1,12.46,100,1,14.53,100,1,12.43,700,1,14.54,700,1,12.42,700,1,14.56,700,1
2025-07-17T16:12:58.432736189Z,2025-07-17T16:12:58.432901795Z,160,2,1108,A,A,0,15.38,100,130,165606,282292390,ARL,339206141,13.11,100,1,13.73,2,1,12.98,200,2,14,100,1,12.92,2,1,14.01,100,1,12.86,100,1,14.27,100,1,12.73,100,1,14.35,100,1,12.71,100,1,14.42,200,2,12.5,700,1,14.48,700,1,12.46,100,1,14.53,100,1,12.43,700,1,14.54,700,1,12.42,700,1,14.56,700,1
2025-07-17T16:12:58.437907652Z,2025-07-17T16:12:58.438073339Z,160,2,1108,C,B,0,12.92,2,0,165687,282292938,ARL,338044113,13.11,100,1,13.73,2,1,12.98,200,2,14,100,1,12.86,100,1,14.01,100,1,12.73,100,1,14.27,100,1,12.71,100,1,14.35,100,1,12.5,700,1,14.42,200,2,12.46,100,1,14.48,700,1,12.43,700,1,14.53,100,1,12.42,700,1,14.54,700,1,12.37,700,1,14.56,700,1
2025-07-17T16:12:58.437907652Z,2025-07-17T16:12:58.438073339Z,160,2,1108,A,B,0,13.02,2,130,165687,282292938,ARL,339207125,13.11,100,1,13.73,2,1,13.02,2,1,14,100,1,12.98,200,2,14.01,100,1,12.86,100,1,14.27,100,1,12.73,100,1,14.35,100,1,12.71,100,1,14.42,200,2,12.5,700,1,14.48,700,1,12.46,100,1,14.53,100,1,12.43,700,1,14.54,700,1,12.42,700,1,14.56,700,1
2025-07-17T16:12:58.437911392Z,2025-07-17T16:12:58.438076762Z,160,2,1108,C,A,0,13.73,2,0,165370,282292939,ARL,339110993,13.11,100,1,14,100,1,13.02,2,1,14.01,100,1,12.98,200,2,14.27,100,1,12.86,100,1,14.35,100,1,12.73,100,1,14.42,200,2,12.71,100,1,14.48,700,1,12.5,700,1,14.53,100,1,12.46,100,1,14.54,700,1,12.43,700,1,14.56,700,1,12.42,700,1,14.57,200,2
2025-07-17T16:12:58.437911392Z,2025-07-17T16:12:58.438076762Z,160,2,1108,A,A,0,13.98,2,130,165370,282292939,ARL,339207129,13.11,100,1,13.98,2,1,13.02,2,1,14,100,1,12.98,200,2,14.01,100,1,12.86,100,1,14.27,100,1,12.73,100,1,14.35,100,1,12.71,100,1,14.42,200,2,12.5,700,1,14.48,700,1,12.46,100,1,14.53,100,1,12.43,700,1,14.54,700,1,12.42,700,1,14.56,700,1
2025-07-17T16:12:58.438678961Z,2025-07-17T16:12:58.438843944Z,160,2,1108,C,A,0,14.01,100,130,164983,282293023,ARL,339205213,13.11,100,1,13.98,2,1,13.02,2,1,14,100,1,12.98,200,2,14.27,100,1,12.86,100,1,14.35,100,1,12.73,100,1,14.42,200,2,12.71,100,1,14.48,700,1,12.5,700,1,14.53,100,1,12.46,100,1,14.54,700,1,12.43,700,1,14.56,700,1,12.42,700,1,14.57,200,2
2025-07-17T16:12:58.438728994Z,2025-07-17T16:12:58.438894336Z,160,2,1108,A,A,0,14.24,100,130,165342,282293026,ARL,339207197,13.11,100,1,13.98,2,1,13.02,2,1,14,100,1,12.98,200,2,14.24,100,1,12.86,100,1,14.27,100,1,12.73,100,1,14.35,100,1,12.71,100,1,14.42,200,2,12.5,700,1,14.48,700,1,12.46,100,1,14.53,100,1,12.43,700,1,14.54,700,1,12.42,700,1,14.56,700,1
2025-07-17T16:12:58.441669159Z,2025-07-17T16:12:58.441834497Z,160,2,1108,C,A,0,14.42,100,0,165338,282293191,ARL,339110981,13.11,100,1,13.98,2,1,13.02,2,1,14,100,1,12.98,200,2,14.24,100,1,12.86,100,1,14.27,100,1,12.73,100,1,14.35,100,1,12.71,100,1,14.42,100,1,12.5,700,1,14.48,700,1,12.46,100,1,14.53,100,1,12.43,700,1,14.54,700,1,12.42,700,1,14.56,700,1
2025-07-17T16:12:58.441669159Z,2025-07-17T16:12:58.441834497Z,160,2,1108,A,A,0,14.96,100,130,165338,282293191,ARL,339207505,13.11,100,1,13.98,2,1,13.02,2,1,14,100,1,12.98,200,2,14.24,100,1,12.86,100,1,14.27,100,1,12.73,100,1,14.35,100,1,12.71,100,1,14.42,100,1,12.5,700,1,14.48,700,1,12.46,100,1,14.53,100,1,12.43,700,1,14.54,700,1,12.42,700,1,14.56,700,1
2025-07-17T16:12:58.454211242Z,2025-07-17T16:12:58.454376675Z,160,2,1108,C,A,0,17.11,100,0,165433,282293811,ARL,339111097,13.11,100,1,13.98,2,1,13.02,2,1,14,100,1,12.98,200,2,14.24,100,1,12.86,100,1,14.27,100,1,12.73,100,1,14.35,100,1,12.71,100,1,14.42,100,1,12.5,700,1,14.48,700,1,12.46,100,1,14.53,100,1,12.43,700,1,14.54,700,1,12.42,700,1,14.56,700,1
2025-07-17T16:12:58.454211242Z,2025-07-17T16:12:58.454376675Z,160,2,1108,A,A,0,17.76,100,130,165433,282293811,ARL,339208377,13.11,100,1,13.98,2,1,13.02,2,1,14,100,1,12.98,200,2,14.24,100,1,12.86,100,1,14.27,100,1,12.73,100,1,14.35,100,1,12.71,100,1,14.42,100,1,12.5,700,1,14.48,700,1,12.46,100,1,14.53,100,1,12.43,700,1,14.54,700,1,12.42,700,1,14.56,700,1
2025-07-17T16:12:58.472126777Z,2025-07-17T16:12:58.472292476Z,160,2,1108,C,A,0,15.5,100,0,165699,282294411,ARL,339111149,13.11,100,1,13.98,2,1,13.02,2,1,14,100,1,12.98,200,2,14.24,100,1,12.86,100,1,14.27,100,1,12.73,100,1,14.35,100,1,12.71,100,1,14.42,100,1,12.5,700,1,14.48,700,1,12.46,100,1,14.53,100,1,12.43,700,1,14.54,700,1,12.42,700,1,14.56,700,1
2025-07-17T16:12:58.472126777Z,2025-07-17T16:12:58.472292476Z,160,2,1108,A,A,0,16.08,100,130,165699,282294411,ARL,339209241,13.11,100,1,13.98,2,1,13.02,2,1,14,100,1,12.98,200,2,14.24,100,1,12.86,100,1,14.27,100,1,12.73,100,1,14.35,100,1,12.71,100,1,14.42,100,1,12.5,700,1,14.48,700,1,12.46,100,1,14.53,100,1,12.43,700,1,14.54,700,1,12.42,700,1,14.56,700,1
2025-07-17T16:12:58.472458830Z,2025-07-17T16:12:58.472624779Z,160,2,1108,C,A,0,14.81,100,0,165949,282294423,ARL,339202805,13.11,100,1,13.98,2,1,13.02,2,1,14,100,1,12.98,200,2,14.24,100,1,12.86,100,1,14.27,100,1,12.73,100,1,14.35,100,1,12.71,100,1,14.42,100,1,12.5,700,1,14.48,700,1,12.46,100,1,14.53,100,1,12.43,700,1,14.54,700,1,12.42,700,1,14.56,700,1
2025-07-17T16:12:58.472458830Z,2025-07-17T16:12:58.472624779Z,160,2,1108,A,A,0,15.04,100,130,165949,282294423,ARL,339209257,13.11,100,1,13.98,2,1,13.02,2,1,14,100,1,12.98,200,2,14.24,100,1,12.86,100,1,14.27,100,1,12.73,100,1,14.35,100,1,12.71,100,1,14.42,100,1,12.5,700,1,14.48,700,1,12.46,100,1,14.53,100,1,12.43,700,1,14.54,700,1,12.42,700,1,14.56,700,1
2025-07-17T16:12:58.571679985Z,2025-07-17T16:12:58.571845708Z,160,2,1108,C,A,0,14.82,100,0,165723,282298942,ARL,339112981,13.11,100,1,13.98,2,1,13.02,2,1,14,100,1,12.98,200,2,14.24,100,1,12.86,100,1,14.27,100,1,12.73,100,1,14.35,100,1,12.71,100,1,14.42,100,1,12.5,700,1,14.48,700,1,12.46,100,1,14.53,100,1,12.43,700,1,14.54,700,1,12.42,700,1,14.56,700,1
2025-07-17T16:12:58.571679985Z,2025-07-17T16:12:58.571845708Z,160,2,1108,A,A,0,15.38,100,130,165723,282298942,ARL,339215205,13.11,100,1,13.98,2,1,13.02,2,1,14,100,1,12.98,200,2,14.24,100,1,12.86,100,1,14.27,100,1,12.73,100,1,14.35,100,1,12.71,100,1,14.42,100,1,12.5,700,1,14.48,700,1,12.46,100,1,14.53,100,1,12.43,700,1,14.54,700,1,12.42,700,1,14.56,700,1
2025-07-17T16:12:58.619238614Z,2025-07-17T16:12:58.619404102Z,160,2,1108,C,A,0,14.42,100,0,165488,282299781,ARL,339112945,13.11,100,1,13.98,2,1,13.02,2,1,14,100,1,12.98,200,2,14.24,100,1,12.86,100,1,14.27,100,1,12.73,100,1,14.35,100,1,12.71,100,1,14.48,700,1,12.5,700,1,14.53,100,1,12.46,100,1,14.54,700,1,12.43,700,1,14.56,700,1,12.42,700,1,14.57,200,2
2025-07-17T16:12:58.619238614Z,2025-07-17T16:12:58.619404102Z,160,2,1108,A,A,0,14.96,100,130,165488,282299781,ARL,339216161,13.11,100,1,13.98,2,1,13.02,2,1,14,100,1,12.98,200,2,14.24,100,1,12.86,100,1,14.27,100,1,12.73,100,1,14.35,100,1,12.71,100,1,14.48,700,1,12.5,700,1,14.53,100,1,12.46,100,1,14.54,700,1,12.43,700,1,14.56,700,1,12.42,700,1,14.57,200,2
2025-07-17T16:12:58.985928594Z,2025-07-17T16:12:58.986093948Z,160,2,1108,C,B,0,13.02,2,0,165354,282305386,ARL,339207125,13.11,100,1,13.98,2,1,12.98,200,2,14,100,1,12.86,100,1,14.24,100,1,12.73,100,1,14.27,100,1,12.71,100,1,14.35,100,1,12.5,700,1,14.48,700,1,12.46,100,1,14.53,100,1,12.43,700,1,14.54,700,1,12.42,700,1,14.56,700,1,12.37,700,1,14.57,200,2
2025-07-17T16:12:58.985928594Z,2025-07-17T16:12:58.986093948Z,160,2,1108,A,B,0,12.86,2,130,165354,282305386,ARL,339222617,13.11,100,1,13.98,2,1,12.98,200,2,14,100,1,12.86,102,2,14.24,100,1,12.73,100,1,14.27,100,1,12.71,100,1,14.35,100,1,12.5,700,1,14.48,700,1,12.46,100,1,14.53,100,1,12.43,700,1,14.54,700,1,12.42,700,1,14.56,700,1,12.37,700,1,14.57,200,2
2025-07-17T16:12:59.062943193Z,2025-07-17T16:12:59.063108412Z,160,2,1108,A,A,0,13.99,100,130,165219,282306400,ARL,339224109,13.11,100,1,13.98,2,1,12.98,200,2,13.99,100,1,12.86,102,2,14,100,1,12.73,100,1,14.24,100,1,12.71,100,1,14.27,100,1,12.5,700,1,14.35,100,1,12.46,100,1,14.48,700,1,12.43,700,1,14.53,100,1,12.42,700,1,14.54,700,1,12.37,700,1,14.56,700,1
2025-07-17T16:12:59.082690430Z,2025-07-17T16:12:59.082855570Z,160,2,1108,C,A,0,14,100,130,165140,282307908,ARL,339133353,13.11,100,1,13.98,2,1,12.98,200,2,13.99,100,1,12.86,102,2,14.24,100,1,12.73,100,1,14.27,100,1,12.71,100,1,14.35,100,1,12.5,700,1,14.48,700,1,12.46,100,1,14.53,100,1,12.43,700,1,14.54,700,1,12.42,700,1,14.56,700,1,12.37,700,1,14.57,200,2
2025-07-17T16:12:59.082691385Z,2025-07-17T16:12:59.082856640Z,160,2,1108,A,A,0,14.53,100,130,165255,282307909,ARL,339225769,13.11,100,1,13.98,2,1,12.98,200,2,13.99,100,1,12.86,102,2,14.24,100,1,12.73,100,1,14.27,100,1,12.71,100,1,14.35,100,1,12.5,700,1,14.48,700,1,12.46,100,1,14.53,200,2,12.43,700,1,14.54,700,1,12.42,700,1,14.56,700,1,12.37,700,1,14.57,200,2
2025-07-17T16:12:59.088629294Z,2025-07-17T16:12:59.088794570Z,160,2,1108,A,A,0,14.81,100,130,165276,282308093,ARL,339225885,13.11,100,1,13.98,2,1,12.98,200,2,13.99,100,1,12.86,102,2,14.24,100,1,12.73,100,1,14.27,100,1,12.71,100,1,14.35,100,1,12.5,700,1,14.48,700,1,12.46,100,1,14.53,200,2,12.43,700,1,14.54,700,1,12.42,700,1,14.56,700,1,12.37,700,1,14.57,200,2
2025-07-17T16:12:59.088642718Z,2025-07-17T16:12:59.088808117Z,160,2,1108,C,A,0,14.27,100,130,165399,282308094,ARL,339126221,13.11,100,1,13.98,2,1,12.98,200,2,13.99,100,1,12.86,102,2,14.24,100,1,12.73,100,1,14.35,100,1,12.71,100,1,14.48,700,1,12.5,700,1,14.53,200,2,12.46,100,1,14.54,700,1,12.43,700,1,14.56,700,1,12.42,700,1,14.57,200,2,12.37,700,1,14.68,700,1
2025-07-17T16:12:59.092762564Z,2025-07-17T16:12:59.092927842Z,160,2,1108,C,A,0,14.35,100,130,165278,282308154,ARL,339202733,13.11,100,1,13.98,2,1,12.98,200,2,13.99,100,1,12.86,102,2,14.24,100,1,12.73,100,1,14.48,700,1,12.71,100,1,14.53,200,2,12.5,700,1,14.54,700,1,12.46,100,1,14.56,700,1,12.43,700,1,14.57,200,2,12.42,700,1,14.68,700,1,12.37,700,1,14.81,100,1
2025-07-17T16:12:59.093113488Z,2025-07-17T16:12:59.093278915Z,160,2,1108,A,A,0,14.6,100,130,165427,282308163,ARL,339226021,13.11,100,1,13.98,2,1,12.98,200,2,13.99,100,1,12.86,102,2,14.24,100,1,12.73,100,1,14.48,700,1,12.71,100,1,14.53,200,2,12.5,700,1,14.54,700,1,12.46,100,1,14.56,700,1,12.43,700,1,14.57,200,2,12.42,700,1,14.6,100,1,12.37,700,1,14.68,700,1
2025-07-17T16:12:59.430320610Z,2025-07-17T16:12:59.430486012Z,160,2,1108,C,A,0,14.53,100,0,165402,282313368,ARL,339204077,13.11,100,1,13.98,2,1,12.98,200,2,13.99,100,1,12.86,102,2,14.24,100,1,12.73,100,1,14.48,700,1,12.71,100,1,14.53,100,1,12.5,700,1,14.54,700,1,12.46,100,1,14.56,700,1,12.43,700,1,14.57,200,2,12.42,700,1,14.6,100,1,12.37,700,1,14.68,700,1
2025-07-17T16:12:59.430320610Z,2025-07-17T16:12:59.430486012Z,160,2,1108,A,A,0,14.77,100,130,165402,282313368,ARL,339232213,13.11,100,1,13.98,2,1,12.98,200,2,13.99,100,1,12.86,102,2,14.24,100,1,12.73,100,1,14.48,700,1,12.71,100,1,14.53,100,1,12.5,700,1,14.54,700,1,12.46,100,1,14.56,700,1,12.43,700,1,14.57,200,2,12.42,700,1,14.6,100,1,12.37,700,1,14.68,700,1
2025-07-17T16:13:04.825736034Z,2025-07-17T16:13:04.825902166Z,160,2,1108,A,A,0,13.66,15,128,166132,282392593,ARL,339332865,13.11,100,1,13.66,15,1,12.98,200,2,13.98,2,1,12.86,102,2,13.99,100,1,12.73,100,1,14.24,100,1,12.71,100,1,14.48,700,1,12.5,700,1,14.53,100,1,12.46,100,1,14.54,700,1,12.43,700,1,14.56,700,1,12.42,700,1,14.57,200,2,12.37,700,1,14.6,100,1
2025-07-17T16:13:06.189110140Z,2025-07-17T16:13:06.189275812Z,160,2,1108,C,B,0,12.86,2,0,165672,282411935,ARL,339222617,13.11,100,1,13.66,15,1,12.98,200,2,13.98,2,1,12.86,100,1,13.99,100,1,12.73,100,1,14.24,100,1,12.71,100,1,14.48,700,1,12.5,700,1,14.53,100,1,12.46,100,1,14.54,700,1,12.43,700,1,14.56,700,1,12.42,700,1,14.57,200,2,12.37,700,1,14.6,100,1
2025-07-17T16:13:06.189110140Z,2025-07-17T16:13:06.189275812Z,160,2,1108,A,B,0,12.96,2,130,165672,282411935,ARL,339356397,13.11,100,1,13.66,15,1,12.98,200,2,13.98,2,1,12.96,2,1,13.99,100,1,12.86,100,1,14.24,100,1,12.73,100,1,14.48,700,1,12.71,100,1,14.53,100,1,12.5,700,1,14.54,700,1,12.46,100,1,14.56,700,1,12.43,700,1,14.57,200,2,12.42,700,1,14.6,100,1
2025-07-17T16:13:06.224732787Z,2025-07-17T16:13:06.224898389Z,160,2,1108,C,A,0,13.99,100,0,165602,282413599,ARL,339224109,13.11,100,1,13.66,15,1,12.98,200,2,13.98,2,1,12.96,2,1,14.24,100,1,12.86,100,1,14.48,700,1,12.73,100,1,14.53,100,1,12.71,100,1,14.54,700,1,12.5,700,1,14.56,700,1,12.46,100,1,14.57,200,2,12.43,700,1,14.6,100,1,12.42,700,1,14.68,700,1
2025-07-17T16:13:06.224732787Z,2025-07-17T16:13:06.224898389Z,160,2,1108,A,A,0,13.67,100,130,165602,282413599,ARL,339358233,13.11,100,1,13.66,15,1,12.98,200,2,13.67,100,1,12.96,2,1,13.98,2,1,12.86,100,1,14.24,100,1,12.73,100,1,14.48,700,1,12.71,100,1,14.53,100,1,12.5,700,1,14.54,700,1,12.46,100,1,14.56,700,1,12.43,700,1,14.57,200,2,12.42,700,1,14.6,100,1
2025-07-17T16:13:06.225475518Z,2025-07-17T16:13:06.225642781Z,160,2,1108,C,A,0,15.04,100,0,167263,282413677,ARL,339209257,13.11,100,1,13.66,15,1,12.98,200,2,13.67,100,1,12.96,2,1,13.98,2,1,12.86,100,1,14.24,100,1,12.73,100,1,14.48,700,1,12.71,100,1,14.53,100,1,12.5,700,1,14.54,700,1,12.46,100,1,14.56,700,1,12.43,700,1,14.57,200,2,12.42,700,1,14.6,100,1
2025-07-17T16:13:06.225475518Z,2025-07-17T16:13:06.225642781Z,160,2,1108,A,A,0,14.73,100,0,167263,282413677,ARL,339358293,13.11,100,1,13.66,15,1,12.98,200,2,13.67,100,1,12.96,2,1,13.98,2,1,12.86,100,1,14.24,100,1,12.73,100,1,14.48,700,1,12.71,100,1,14.53,100,1,12.5,700,1,14.54,700,1,12.46,100,1,14.56,700,1,12.43,700,1,14.57,200,2,12.42,700,1,14.6,100,1
2025-07-17T16:13:06.225475906Z,2025-07-17T16:13:06.225642781Z,160,2,1108,C,A,0,14.6,100,128,166875,282413678,ARL,339226021,13.11,100,1,13.66,15,1,12.98,200,2,13.67,100,1,12.96,2,1,13.98,2,1,12.86,100,1,14.24,100,1,12.73,100,1,14.48,700,1,12.71,100,1,14.53,100,1,12.5,700,1,14.54,700,1,12.46,100,1,14.56,700,1,12.43,700,1,14.57,200,2,12.42,700,1,14.68,700,1
2025-07-17T16:13:06.225829921Z,2025-07-17T16:13:06.225995297Z,160,2,1108,A,A,0,14.28,100,130,165376,282413699,ARL,339358333,13.11,100,1,13.66,15,1,12.98,200,2,13.67,100,1,12.96,2,1,13.98,2,1,12.86,100,1,14.24,100,1,12.73,100,1,14.28,100,1,12.71,100,1,14.48,700,1,12.5,700,1,14.53,100,1,12.46,100,1,14.54,700,1,12.43,700,1,14.56,700,1,12.42,700,1,14.57,200,2
2025-07-17T16:13:06.226624084Z,2025-07-17T16:13:06.226789913Z,160,2,1108,C,A,0,15.38,100,0,165829,282413738,ARL,339206141,13.11,100,1,13.66,15,1,12.98,200,2,13.67,100,1,12.96,2,1,13.98,2,1,12.86,100,1,14.24,100,1,12.73,100,1,14.28,100,1,12.71,100,1,14.48,700,1,12.5,700,1,14.53,100,1,12.46,100,1,14.54,700,1,12.43,700,1,14.56,700,1,12.42,700,1,14.57,200,2
2025-07-17T16:13:06.226624084Z,2025-07-17T16:13:06.226789913Z,160,2,1108,A,A,0,15.04,100,130,165829,282413738,ARL,339358349,13.11,100,1,13.66,15,1,12.98,200,2,13.67,100,1,12.96,2,1,13.98,2,1,12.86,100,1,14.24,100,1,12.73,100,1,14.28,100,1,12.71,100,1,14.48,700,1,12.5,700,1,14.53,100,1,12.46,100,1,14.54,700,1,12.43,700,1,14.56,700,1,12.42,700,1,14.57,200,2
2025-07-17T16:13:06.226716697Z,2025-07-17T16:13:06.226882302Z,160,2,1108,C,A,0,14.96,100,0,165605,282413745,ARL,339207505,13.11,100,1,13.66,15,1,12.98,200,2,13.67,100,1,12.96,2,1,13.98,2,1,12.86,100,1,14.24,100,1,12.73,100,1,14.28,100,1,12.71,100,1,14.48,700,1,12.5,700,1,14.53,100,1,12.46,100,1,14.54,700,1,12.43,700,1,14.56,700,1,12.42,700,1,14.57,200,2
2025-07-17T16:13:06.226716697Z,2025-07-17T16:13:06.226882302Z,160,2,1108,A,A,0,14.63,100,130,165605,282413745,ARL,339358353,13.11,100,1,13.66,15,1,12.98,200,2,13.67,100,1,12.96,2,1,13.98,2,1,12.86,100,1,14.24,100,1,12.73,100,1,14.28,100,1,12.71,100,1,14.48,700,1,12.5,700,1,14.53,100,1,12.46,100,1,14.54,700,1,12.43,700,1,14.56,700,1,12.42,700,1,14.57,200,2
2025-07-17T16:13:06.229693020Z,2025-07-17T16:13:06.229858538Z,160,2,1108,C,A,0,13.98,2,0,165518,282413801,ARL,339207129,13.11,100,1,13.66,15,1,12.98,200,2,13.67,100,1,12.96,2,1,14.24,100,1,12.86,100,1,14.28,100,1,12.73,100,1,14.48,700,1,12.71,100,1,14.53,100,1,12.5,700,1,14.54,700,1,12.46,100,1,14.56,700,1,12.43,700,1,14.57,200,2,12.42,700,1,14.63,100,1
2025-07-17T16:13:06.229693020Z,2025-07-17T16:13:06.229858538Z,160,2,1108,A,A,0,13.81,2,130,165518,282413801,ARL,339358409,13.11,100,1,13.66,15,1,12.98,200,2,13.67,100,1,12.96,2,1,13.81,2,1,12.86,100,1,14.24,100,1,12.73,100,1,14.28,100,1,12.71,100,1,14.48,700,1,12.5,700,1,14.53,100,1,12.46,100,1,14.54,700,1,12.43,700,1,14.56,700,1,12.42,700,1,14.57,200,2
2025-07-17T16:13:06.235428434Z,2025-07-17T16:13:06.235594115Z,160,2,1108,C,A,0,17.76,100,0,165681,282414050,ARL,339208377,13.11,100,1,13.66,15,1,12.98,200,2,13.67,100,1,12.96,2,1,13.81,2,1,12.86,100,1,14.24,100,1,12.73,100,1,14.28,100,1,12.71,100,1,14.48,700,1,12.5,700,1,14.53,100,1,12.46,100,1,14.54,700,1,12.43,700,1,14.56,700,1,12.42,700,1,14.57,200,2
2025-07-17T16:13:06.235428434Z,2025-07-17T16:13:06.235594115Z,160,2,1108,A,A,0,17.37,100,130,165681,282414050,ARL,339358609,13.11,100,1,13.66,15,1,12.98,200,2,13.67,100,1,12.96,2,1,13.81,2,1,12.86,100,1,14.24,100,1,12.73,100,1,14.28,100,1,12.71,100,1,14.48,700,1,12.5,700,1,14.53,100,1,12.46,100,1,14.54,700,1,12.43,700,1,14.56,700,1,12.42,700,1,14.57,200,2
2025-07-17T16:13:06.236401579Z,2025-07-17T16:13:06.236567790Z,160,2,1108,C,A,0,14.24,100,130,166211,282414131,ARL,339207197,13.11,100,1,13.66,15,1,12.98,200,2,13.67,100,1,12.96,2,1,13.81,2,1,12.86,100,1,14.28,100,1,12.73,100,1,14.48,700,1,12.71,100,1,14.53,100,1,12.5,700,1,14.54,700,1,12.46,100,1,14.56,700,1,12.43,700,1,14.57,200,2,12.42,700,1,14.63,100,1
2025-07-17T16:13:06.236456489Z,2025-07-17T16:13:06.236621535Z,160,2,1108,A,A,0,13.94,100,130,165046,282414141,ARL,339358741,13.11,100,1,13.66,15,1,12.98,200,2,13.67,100,1,12.96,2,1,13.81,2,1,12.86,100,1,13.94,100,1,12.73,100,1,14.28,100,1,12.71,100,1,14.48,700,1,12.5,700,1,14.53,100,1,12.46,100,1,14.54,700,1,12.43,700,1,14.56,700,1,12.42,700,1,14.57,200,2
2025-07-17T16:13:06.243743642Z,2025-07-17T16:13:06.243909112Z,160,2,1108,C,A,0,16.08,100,0,165470,282414340,ARL,339209241,13.11,100,1,13.66,15,1,12.98,200,2,13.67,100,1,12.96,2,1,13.81,2,1,12.86,100,1,13.94,100,1,12.73,100,1,14.28,100,1,12.71,100,1,14.48,700,1,12.5,700,1,14.53,100,1,12.46,100,1,14.54,700,1,12.43,700,1,14.56,700,1,12.42,700,1,14.57,200,2
2025-07-17T16:13:06.243743642Z,2025-07-17T16:13:06.243909112Z,160,2,1108,A,A,0,15.73,100,130,165470,282414340,ARL,339359077,13.11,100,1,13.66,15,1,12.98,200,2,13.67,100,1,12.96,2,1,13.81,2,1,12.86,100,1,13.94,100,1,12.73,100,1,14.28,100,1,12.71,100,1,14.48,700,1,12.5,700,1,14.53,100,1,12.46,100,1,14.54,700,1,12.43,700,1,14.56,700,1,12.42,700,1,14.57,200,2
2025-07-17T16:13:06.267886189Z,2025-07-17T16:13:06.268052093Z,160,2,1108,C,A,0,15.38,100,0,165904,282414570,ARL,339215205,13.11,100,1,13.66,15,1,12.98,200,2,13.67,100,1,12.96,2,1,13.81,2,1,12.86,100,1,13.94,100,1,12.73,100,1,14.28,100,1,12.71,100,1,14.48,700,1,12.5,700,1,14.53,100,1,12.46,100,1,14.54,700,1,12.43,700,1,14.56,700,1,12.42,700,1,14.57,200,2
2025-07-17T16:13:06.267886189Z,2025-07-17T16:13:06.268052093Z,160,2,1108,A,A,0,15.04,100,130,165904,282414570,ARL,339359357,13.11,100,1,13.66,15,1,12.98,200,2,13.67,100,1,12.96,2,1,13.81,2,1,12.86,100,1,13.94,100,1,12.73,100,1,14.28,100,1,12.71,100,1,14.48,700,1,12.5,700,1,14.53,100,1,12.46,100,1,14.54,700,1,12.43,700,1,14.56,700,1,12.42,700,1,14.57,200,2
2025-07-17T16:13:06.275720866Z,2025-07-17T16:13:06.275886461Z,160,2,1108,C,A,0,14.96,100,0,165595,282414642,ARL,339216161,13.11,100,1,13.66,15,1,12.98,200,2,13.67,100,1,12.96,2,1,13.81,2,1,12.86,100,1,13.94,100,1,12.73,100,1,14.28,100,1,12.71,100,1,14.48,700,1,12.5,700,1,14.53,100,1,12.46,100,1,14.54,700,1,12.43,700,1,14.56,700,1,12.42,700,1,14.57,200,2
2025-07-17T16:13:06.275720866Z,2025-07-17T16:13:06.275886461Z,160,2,1108,A,A,0,14.63,100,130,165595,282414642,ARL,339359401,13.11,100,1,13.66,15,1,12.98,200,2,13.67,100,1,12.96,2,1,13.81,2,1,12.86,100,1,13.94,100,1,12.73,100,1,14.28,100,1,12.71,100,1,14.48,700,1,12.5,700,1,14.53,100,1,12.46,100,1,14.54,700,1,12.43,700,1,14.56,700,1,12.42,700,1,14.57,200,2
2025-07-17T16:13:06.276882863Z,2025-07-17T16:13:06.277048260Z,160,2,1108,C,A,0,14.77,100,130,165397,282414659,ARL,339232213,13.11,100,1,13.66,15,1,12.98,200,2,13.67,100,1,12.96,2,1,13.81,2,1,12.86,100,1,13.94,100,1,12.73,100,1,14.28,100,1,12.71,100,1,14.48,700,1,12.5,700,1,14.53,100,1,12.46,100,1,14.54,700,1,12.43,700,1,14.56,700,1,12.42,700,1,14.57,200,2
2025-07-17T16:13:06.277013512Z,2025-07-17T16:13:06.277178914Z,160,2,1108,A,A,0,14.46,100,130,165402,282414660,ARL,339359421,13.11,100,1,13.66,15,1,12.98,200,2,13.67,100,1,12.96,2,1,13.81,2,1,12.86,100,1,13.94,100,1,12.73,100,1,14.28,100,1,12.71,100,1,14.46,100,1,12.5,700,1,14.48,700,1,12.46,100,1,14.53,100,1,12.43,700,1,14.54,700,1,12.42,700,1,14.56,700,1
2025-07-17T16:13:06.622493734Z,2025-07-17T16:13:06.622659102Z,160,2,1108,A,A,0,14.22,100,130,165368,282418746,ARL,339365193,13.11,100,1,13.66,15,1,12.98,200,2,13.67,100,1,12.96,2,1,13.81,2,1,12.86,100,1,13.94,100,1,12.73,100,1,14.22,100,1,12.71,100,1,14.28,100,1,12.5,700,1,14.46,100,1,12.46,100,1,14.48,700,1,12.43,700,1,14.53,100,1,12.42,700,1,14.54,700,1
2025-07-17T16:13:06.663671305Z,2025-07-17T16:13:06.663836744Z,160,2,1108,C,A,0,14.53,100,130,165439,282418921,ARL,339225769,13.11,100,1,13.66,15,1,12.98,200,2,13.67,100,1,12.96,2,1,13.81,2,1,12.86,100,1,13.94,100,1,12.73,100,1,14.22,100,1,12.71,100,1,14.28,100,1,12.5,700,1,14.46,100,1,12.46,100,1,14.48,700,1,12.43,700,1,14.54,700,1,12.42,700,1,14.56,700,1
2025-07-17T16:13:06.759625628Z,2025-07-17T16:13:06.759791103Z,160,2,1108,A,A,0,14.49,100,130,165475,282419471,ARL,339366385,13.11,100,1,13.66,15,1,12.98,200,2,13.67,100,1,12.96,2,1,13.81,2,1,12.86,100,1,13.94,100,1,12.73,100,1,14.22,100,1,12.71,100,1,14.28,100,1,12.5,700,1,14.46,100,1,12.46,100,1,14.48,700,1,12.43,700,1,14.49,100,1,12.42,700,1,14.54,700,1
2025-07-17T16:13:06.759638890Z,2025-07-17T16:13:06.759804641Z,160,2,1108,C,A,0,14.81,100,130,165751,282419472,ARL,339225885,13.11,100,1,13.66,15,1,12.98,200,2,13.67,100,1,12.96,2,1,13.81,2,1,12.86,100,1,13.94,100,1,12.73,100,1,14.22,100,1,12.71,100,1,14.28,100,1,12.5,700,1,14.46,100,1,12.46,100,1,14.48,700,1,12.43,700,1,14.49,100,1,12.42,700,1,14.54,700,1
2025-07-17T16:13:09.353883614Z,2025-07-17T16:13:09.354048740Z,160,2,1108,A,A,0,13.64,15,130,165126,282469242,ARL,339425837,13.11,100,1,13.64,15,1,12.98,200,2,13.66,15,1,12.96,2,1,13.67,100,1,12.86,100,1,13.81,2,1,12.73,100,1,13.94,100,1,12.71,100,1,14.22,100,1,12.5,700,1,14.28,100,1,12.46,100,1,14.46,100,1,12.43,700,1,14.48,700,1,12.42,700,1,14.49,100,1
2025-07-17T16:13:09.368030843Z,2025-07-17T16:13:09.368197659Z,160,2,1108,C,A,0,13.67,100,0,166816,282470466,ARL,339358233,13.11,100,1,13.64,15,1,12.98,200,2,13.66,15,1,12.96,2,1,13.81,2,1,12.86,100,1,13.94,100,1,12.73,100,1,14.22,100,1,12.71,100,1,14.28,100,1,12.5,700,1,14.46,100,1,12.46,100,1,14.48,700,1,12.43,700,1,14.49,100,1,12.42,700,1,14.54,700,1
2025-07-17T16:13:09.368030843Z,2025-07-17T16:13:09.368197659Z,160,2,1108,A,A,0,13.65,100,128,166816,282470466,ARL,339427217,13.11,100,1,13.64,15,1,12.98,200,2,13.65,100,1,12.96,2,1,13.66,15,1,12.86,100,1,13.81,2,1,12.73,100,1,13.94,100,1,12.71,100,1,14.22,100,1,12.5,700,1,14.28,100,1,12.46,100,1,14.46,100,1,12.43,700,1,14.48,700,1,12.42,700,1,14.49,100,1
2025-07-17T16:13:14.046102556Z,2025-07-17T16:13:14.046267875Z,160,2,1108,C,A,0,13.66,15,130,165319,282563502,ARL,339332865,13.11,100,1,13.64,15,1,12.98,200,2,13.65,100,1,12.96,2,1,13.81,2,1,12.86,100,1,13.94,100,1,12.73,100,1,14.22,100,1,12.71,100,1,14.28,100,1,12.5,700,1,14.46,100,1,12.46,100,1,14.48,700,1,12.43,700,1,14.49,100,1,12.42,700,1,14.54,700,1
2025-07-17T16:13:17.775045316Z,2025-07-17T16:13:17.775210916Z,160,2,1108,A,A,0,13.57,15,130,165600,282616566,ARL,339610637,13.11,100,1,13.57,15,1,12.98,200,2,13.64,15,1,12.96,2,1,13.65,100,1,12.86,100,1,13.81,2,1,12.73,100,1,13.94,100,1,12.71,100,1,14.22,100,1,12.5,700,1,14.28,100,1,12.46,100,1,14.46,100,1,12.43,700,1,14.48,700,1,12.42,700,1,14.49,100,1
2025-07-17T16:13:19.780978185Z,2025-07-17T16:13:19.781143691Z,160,2,1108,C,A,0,13.65,100,0,165506,282644181,ARL,339427217,13.11,100,1,13.57,15,1,12.98,200,2,13.64,15,1,12.96,2,1,13.81,2,1,12.86,100,1,13.94,100,1,12.73,100,1,14.22,100,1,12.71,100,1,14.28,100,1,12.5,700,1,14.46,100,1,12.46,100,1,14.48,700,1,12.43,700,1,14.49,100,1,12.42,700,1,14.54,700,1
2025-07-17T16:13:19.780978185Z,2025-07-17T16:13:19.781143691Z,160,2,1108,A,A,0,13.58,100,130,165506,282644181,ARL,339641813,13.11,100,1,13.57,15,1,12.98,200,2,13.58,100,1,12.96,2,1,13.64,15,1,12.86,100,1,13.81,2,1,12.73,100,1,13.94,100,1,12.71,100,1,14.22,100,1,12.5,700,1,14.28,100,1,12.46,100,1,14.46,100,1,12.43,700,1,14.48,700,1,12.42,700,1,14.49,100,1
2025-07-17T16:13:19.781723964Z,2025-07-17T16:13:19.781889805Z,160,2,1108,C,A,0,14.73,100,0,165841,282644189,ARL,339358293,13.11,100,1,13.57,15,1,12.98,200,2,13.58,100,1,12.96,2,1,13.64,15,1,12.86,100,1,13.81,2,1,12.73,100,1,13.94,100,1,12.71,100,1,14.22,100,1,12.5,700,1,14.28,100,1,12.46,100,1,14.46,100,1,12.43,700,1,14.48,700,1,12.42,700,1,14.49,100,1
2025-07-17T16:13:19.781723964Z,2025-07-17T16:13:19.781889805Z,160,2,1108,A,A,0,14.63,100,130,165841,282644189,ARL,339641865,13.11,100,1,13.57,15,1,12.98,200,2,13.58,100,1,12.96,2,1,13.64,15,1,12.86,100,1,13.81,2,1,12.73,100,1,13.94,100,1,12.71,100,1,14.22,100,1,12.5,700,1,14.28,100,1,12.46,100,1,14.46,100,1,12.43,700,1,14.48,700,1,12.42,700,1,14.49,100,1
2025-07-17T16:13:19.789606057Z,2025-07-17T16:13:19.789771458Z,160,2,1108,C,A,0,13.94,100,130,165401,282644321,ARL,339358741,13.11,100,1,13.57,15,1,12.98,200,2,13.58,100,1,12.96,2,1,13.64,15,1,12.86,100,1,13.81,2,1,12.73,100,1,14.22,100,1,12.71,100,1,14.28,100,1,12.5,700,1,14.46,100,1,12.46,100,1,14.48,700,1,12.43,700,1,14.49,100,1,12.42,700,1,14.54,700,1
2025-07-17T16:13:19.789656689Z,2025-07-17T16:13:19.789822010Z,160,2,1108,A,A,0,13.85,100,130,165321,282644322,ARL,339642033,13.11,100,1,13.57,15,1,12.98,200,2,13.58,100,1,12.96,2,1,13.64,15,1,12.86,100,1,13.81,2,1,12.73,100,1,13.85,100,1,12.71,100,1,14.22,100,1,12.5,700,1,14.28,100,1,12.46,100,1,14.46,100,1,12.43,700,1,14.48,700,1,12.42,700,1,14.49,100,1
2025-07-17T16:13:19.863452537Z,2025-07-17T16:13:19.863618706Z,160,2,1108,C,A,0,13.57,15,130,166169,282645966,ARL,339610637,13.11,100,1,13.58,100,1,12.98,200,2,13.64,15,1,12.96,2,1,13.81,2,1,12.86,100,1,13.85,100,1,12.73,100,1,14.22,100,1,12.71,100,1,14.28,100,1,12.5,700,1,14.46,100,1,12.46,100,1,14.48,700,1,12.43,700,1,14.49,100,1,12.42,700,1,14.54,700,1
2025-07-17T16:13:19.863624798Z,2025-07-17T16:13:19.863790083Z,160,2,1108,C,A,0,13.64,15,130,165285,282646001,ARL,339425837,13.11,100,1,13.58,100,1,12.98,200,2,13.81,2,1,12.96,2,1,13.85,100,1,12.86,100,1,14.22,100,1,12.73,100,1,14.28,100,1,12.71,100,1,14.46,100,1,12.5,700,1,14.48,700,1,12.46,100,1,14.49,100,1,12.43,700,1,14.54,700,1,12.42,700,1,14.56,700,1
2025-07-17T16:13:19.863803503Z,2025-07-17T16:13:19.863968792Z,160,2,1108,A,A,0,13.58,96,130,165289,282646014,ARL,339643285,13.11,100,1,13.58,196,2,12.98,200,2,13.81,2,1,12.96,2,1,13.85,100,1,12.86,100,1,14.22,100,1,12.73,100,1,14.28,100,1,12.71,100,1,14.46,100,1,12.5,700,1,14.48,700,1,12.46,100,1,14.49,100,1,12.43,700,1,14.54,700,1,12.42,700,1,14.56,700,1
2025-07-17T16:13:24.182459676Z,2025-07-17T16:13:24.182625011Z,160,2,1108,A,A,0,13.57,15,130,165335,282694909,ARL,339710089,13.11,100,1,13.57,15,1,12.98,200,2,13.58,196,2,12.96,2,1,13.81,2,1,12.86,100,1,13.85,100,1,12.73,100,1,14.22,100,1,12.71,100,1,14.28,100,1,12.5,700,1,14.46,100,1,12.46,100,1,14.48,700,1,12.43,700,1,14.49,100,1,12.42,700,1,14.54,700,1
2025-07-17T16:13:24.182753004Z,2025-07-17T16:13:24.182918202Z,160,2,1108,C,A,0,13.58,96,130,165198,282694924,ARL,339643285,13.11,100,1,13.57,15,1,12.98,200,2,13.58,100,1,12.96,2,1,13.81,2,1,12.86,100,1,13.85,100,1,12.73,100,1,14.22,100,1,12.71,100,1,14.28,100,1,12.5,700,1,14.46,100,1,12.46,100,1,14.48,700,1,12.43,700,1,14.49,100,1,12.42,700,1,14.54,700,1
2025-07-17T16:13:24.627209125Z,2025-07-17T16:13:24.627374514Z,160,2,1108,A,A,0,14.26,700,130,165389,282700118,ARL,339716321,13.11,100,1,13.57,15,1,12.98,200,2,13.58,100,1,12.96,2,1,13.81,2,1,12.86,100,1,13.85,100,1,12.73,100,1,14.22,100,1,12.71,100,1,14.26,700,1,12.5,700,1,14.28,100,1,12.46,100,1,14.46,100,1,12.43,700,1,14.48,700,1,12.42,700,1,14.49,100,1
2025-07-17T16:13:24.627265040Z,2025-07-17T16:13:24.627430447Z,160,2,1108,C,A,0,14.68,700,130,165407,282700120,ARL,339096897,13.11,100,1,13.57,15,1,12.98,200,2,13.58,100,1,12.96,2,1,13.81,2,1,12.86,100,1,13.85,100,1,12.73,100,1,14.22,100,1,12.71,100,1,14.26,700,1,12.5,700,1,14.28,100,1,12.46,100,1,14.46,100,1,12.43,700,1,14.48,700,1,12.42,700,1,14.49,100,1
2025-07-17T16:13:25.962552288Z,2025-07-17T16:13:25.962717944Z,160,2,1108,C,A,0,14.57,100,0,165656,282719507,ARL,339203693,13.11,100,1,13.57,15,1,12.98,200,2,13.58,100,1,12.96,2,1,13.81,2,1,12.86,100,1,13.85,100,1,12.73,100,1,14.22,100,1,12.71,100,1,14.26,700,1,12.5,700,1,14.28,100,1,12.46,100,1,14.46,100,1,12.43,700,1,14.48,700,1,12.42,700,1,14.49,100,1
2025-07-17T16:13:25.962552288Z,2025-07-17T16:13:25.962717944Z,160,2,1108,A,A,0,14.46,100,130,165656,282719507,ARL,339739285,13.11,100,1,13.57,15,1,12.98,200,2,13.58,100,1,12.96,2,1,13.81,2,1,12.86,100,1,13.85,100,1,12.73,100,1,14.22,100,1,12.71,100,1,14.26,700,1,12.5,700,1,14.28,100,1,12.46,100,1,14.46,200,2,12.43,700,1,14.48,700,1,12.42,700,1,14.49,100,1
2025-07-17T16:13:25.963043858Z,2025-07-17T16:13:25.963209328Z,160,2,1108,C,A,0,14.57,100,0,165470,282719515,ARL,339203897,13.11,100,1,13.57,15,1,12.98,200,2,13.58,100,1,12.96,2,1,13.81,2,1,12.86,100,1,13.85,100,1,12.73,100,1,14.22,100,1,12.71,100,1,14.26,700,1,12.5,700,1,14.28,100,1,12.46,100,1,14.46,200,2,12.43,700,1,14.48,700,1,12.42,700,1,14.49,100,1
2025-07-17T16:13:25.963043858Z,2025-07-17T16:13:25.963209328Z,160,2,1108,A,A,0,14.46,100,130,165470,282719515,ARL,339739297,13.11,100,1,13.57,15,1,12.98,200,2,13.58,100,1,12.96,2,1,13.81,2,1,12.86,100,1,13.85,100,1,12.73,100,1,14.22,100,1,12.71,100,1,14.26,700,1,12.5,700,1,14.28,100,1,12.46,100,1,14.46,300,3,12.43,700,1,14.48,700,1,12.42,700,1,14.49,100,1
2025-07-17T16:13:34.825063658Z,2025-07-17T16:13:34.825229037Z,160,2,1108,A,A,0,13.55,15,130,165379,282849136,ARL,339897885,13.11,100,1,13.55,15,1,12.98,200,2,13.57,15,1,12.96,2,1,13.58,100,1,12.86,100,1,13.81,2,1,12.73,100,1,13.85,100,1,12.71,100,1,14.22,100,1,12.5,700,1,14.26,700,1,12.46,100,1,14.28,100,1,12.43,700,1,14.46,300,3,12.42,700,1,14.48,700,1
2025-07-17T16:13:36.525285006Z,2025-07-17T16:13:36.525450545Z,160,2,1108,C,A,0,13.58,100,0,165539,282880671,ARL,339641813,13.11,100,1,13.55,15,1,12.98,200,2,13.57,15,1,12.96,2,1,13.81,2,1,12.86,100,1,13.85,100,1,12.73,100,1,14.22,100,1,12.71,100,1,14.26,700,1,12.5,700,1,14.28,100,1,12.46,100,1,14.46,300,3,12.43,700,1,14.48,700,1,12.42,700,1,14.49,100,1
2025-07-17T16:13:36.525285006Z,2025-07-17T16:13:36.525450545Z,160,2,1108,A,A,0,13.56,100,130,165539,282880671,ARL,339937253,13.11,100,1,13.55,15,1,12.98,200,2,13.56,100,1,12.96,2,1,13.57,15,1,12.86,100,1,13.81,2,1,12.73,100,1,13.85,100,1,12.71,100,1,14.22,100,1,12.5,700,1,14.26,700,1,12.46,100,1,14.28,100,1,12.43,700,1,14.46,300,3,12.42,700,1,14.48,700,1
2025-07-17T16:13:36.528160728Z,2025-07-17T16:13:36.528326337Z,160,2,1108,C,A,0,17.37,100,0,165609,282880690,ARL,339358609,13.11,100,1,13.55,15,1,12.98,200,2,13.56,100,1,12.96,2,1,13.57,15,1,12.86,100,1,13.81,2,1,12.73,100,1,13.85,100,1,12.71,100,1,14.22,100,1,12.5,700,1,14.26,700,1,12.46,100,1,14.28,100,1,12.43,700,1,14.46,300,3,12.42,700,1,14.48,700,1
2025-07-17T16:13:36.528160728Z,2025-07-17T16:13:36.528326337Z,160,2,1108,A,A,0,17.23,100,130,165609,282880690,ARL,339937293,13.11,100,1,13.55,15,1,12.98,200,2,13.56,100,1,12.96,2,1,13.57,15,1,12.86,100,1,13.81,2,1,12.73,100,1,13.85,100,1,12.71,100,1,14.22,100,1,12.5,700,1,14.26,700,1,12.46,100,1,14.28,100,1,12.43,700,1,14.46,300,3,12.42,700,1,14.48,700,1
2025-07-17T16:13:40.166532673Z,2025-07-17T16:13:40.166698198Z,160,2,1108,C,A,0,13.57,15,130,165525,282934517,ARL,339710089,13.11,100,1,13.55,15,1,12.98,200,2,13.56,100,1,12.96,2,1,13.81,2,1,12.86,100,1,13.85,100,1,12.73,100,1,14.22,100,1,12.71,100,1,14.26,700,1,12.5,700,1,14.28,100,1,12.46,100,1,14.46,300,3,12.43,700,1,14.48,700,1,12.42,700,1,14.49,100,1
2025-07-17T16:13:41.168516592Z,2025-07-17T16:13:41.168681977Z,160,2,1108,A,A,0,13.53,15,130,165385,282947373,ARL,340027925,13.11,100,1,13.53,15,1,12.98,200,2,13.55,15,1,12.96,2,1,13.56,100,1,12.86,100,1,13.81,2,1,12.73,100,1,13.85,100,1,12.71,100,1,14.22,100,1,12.5,700,1,14.26,700,1,12.46,100,1,14.28,100,1,12.43,700,1,14.46,300,3,12.42,700,1,14.48,700,1
2025-07-17T16:13:41.810482971Z,2025-07-17T16:13:41.810648775Z,160,2,1108,C,A,0,13.56,100,0,165804,282959674,ARL,339937253,13.11,100,1,13.53,15,1,12.98,200,2,13.55,15,1,12.96,2,1,13.81,2,1,12.86,100,1,13.85,100,1,12.73,100,1,14.22,100,1,12.71,100,1,14.26,700,1,12.5,700,1,14.28,100,1,12.46,100,1,14.46,300,3,12.43,700,1,14.48,700,1,12.42,700,1,14.49,100,1
2025-07-17T16:13:41.810482971Z,2025-07-17T16:13:41.810648775Z,160,2,1108,A,A,0,13.54,100,130,165804,282959674,ARL,340046965,13.11,100,1,13.53,15,1,12.98,200,2,13.54,100,1,12.96,2,1,13.55,15,1,12.86,100,1,13.81,2,1,12.73,100,1,13.85,100,1,12.71,100,1,14.22,100,1,12.5,700,1,14.26,700,1,12.46,100,1,14.28,100,1,12.43,700,1,14.46,300,3,12.42,700,1,14.48,700,1
2025-07-17T16:13:41.811231743Z,2025-07-17T16:13:41.811397213Z,160,2,1108,C,A,0,14.63,100,0,165470,282959705,ARL,339641865,13.11,100,1,13.53,15,1,12.98,200,2,13.54,100,1,12.96,2,1,13.55,15,1,12.86,100,1,13.81,2,1,12.73,100,1,13.85,100,1,12.71,100,1,14.22,100,1,12.5,700,1,14.26,700,1,12.46,100,1,14.28,100,1,12.43,700,1,14.46,300,3,12.42,700,1,14.48,700,1
2025-07-17T16:13:41.811231743Z,2025-07-17T16:13:41.811397213Z,160,2,1108,A,A,0,14.59,100,130,165470,282959705,ARL,340047001,13.11,100,1,13.53,15,1,12.98,200,2,13.54,100,1,12.96,2,1,13.55,15,1,12.86,100,1,13.81,2,1,12.73,100,1,13.85,100,1,12.71,100,1,14.22,100,1,12.5,700,1,14.26,700,1,12.46,100,1,14.28,100,1,12.43,700,1,14.46,300,3,12.42,700,1,14.48,700,1
2025-07-17T16:13:41.846384162Z,2025-07-17T16:13:41.846549822Z,160,2,1108,C,A,0,15.73,100,0,165660,282960440,ARL,339359077,13.11,100,1,13.53,15,1,12.98,200,2,13.54,100,1,12.96,2,1,13.55,15,1,12.86,100,1,13.81,2,1,12.73,100,1,13.85,100,1,12.71,100,1,14.22,100,1,12.5,700,1,14.26,700,1,12.46,100,1,14.28,100,1,12.43,700,1,14.46,300,3,12.42,700,1,14.48,700,1
2025-07-17T16:13:41.846384162Z,2025-07-17T16:13:41.846549822Z,160,2,1108,A,A,0,15.58,100,130,165660,282960440,ARL,340047805,13.11,100,1,13.53,15,1,12.98,200,2,13.54,100,1,12.96,2,1,13.55,15,1,12.86,100,1,13.81,2,1,12.73,100,1,13.85,100,1,12.71,100,1,14.22,100,1,12.5,700,1,14.26,700,1,12.46,100,1,14.28,100,1,12.43,700,1,14.46,300,3,12.42,700,1,14.48,700,1
2025-07-17T16:13:53.138226660Z,2025-07-17T16:13:53.138391930Z,160,2,1108,C,A,0,13.53,15,130,165270,283090735,ARL,340027925,13.11,100,1,13.54,100,1,12.98,200,2,13.55,15,1,12.96,2,1,13.81,2,1,12.86,100,1,13.85,100,1,12.73,100,1,14.22,100,1,12.71,100,1,14.26,700,1,12.5,700,1,14.28,100,1,12.46,100,1,14.46,300,3,12.43,700,1,14.48,700,1,12.42,700,1,14.49,100,1
2025-07-17T16:13:53.784124590Z,2025-07-17T16:13:53.784302227Z,160,2,1108,C,A,0,13.55,15,128,177637,283098338,ARL,339897885,13.11,100,1,13.54,100,1,12.98,200,2,13.81,2,1,12.96,2,1,13.85,100,1,12.86,100,1,14.22,100,1,12.73,100,1,14.26,700,1,12.71,100,1,14.28,100,1,12.5,700,1,14.46,300,3,12.46,100,1,14.48,700,1,12.43,700,1,14.49,100,1,12.42,700,1,14.54,700,1
2025-07-17T16:14:06.190701389Z,2025-07-17T16:14:06.190866982Z,160,2,1108,C,A,0,13.81,2,0,165593,283262191,ARL,339358409,13.11,100,1,13.54,100,1,12.98,200,2,13.85,100,1,12.96,2,1,14.22,100,1,12.86,100,1,14.26,700,1,12.73,100,1,14.28,100,1,12.71,100,1,14.46,300,3,12.5,700,1,14.48,700,1,12.46,100,1,14.49,100,1,12.43,700,1,14.54,700,1,12.42,700,1,14.56,700,1
2025-07-17T16:14:06.190701389Z,2025-07-17T16:14:06.190866982Z,160,2,1108,A,A,0,13.74,2,130,165593,283262191,ARL,340449865,13.11,100,1,13.54,100,1,12.98,200,2,13.74,2,1,12.96,2,1,13.85,100,1,12.86,100,1,14.22,100,1,12.73,100,1,14.26,700,1,12.71,100,1,14.28,100,1,12.5,700,1,14.46,300,3,12.46,100,1,14.48,700,1,12.43,700,1,14.49,100,1,12.42,700,1,14.54,700,1
2025-07-17T16:14:10.827253317Z,2025-07-17T16:14:10.827419207Z,160,2,1108,A,A,0,13.51,15,130,165890,283315922,ARL,340526285,13.11,100,1,13.51,15,1,12.98,200,2,13.54,100,1,12.96,2,1,13.74,2,1,12.86,100,1,13.85,100,1,12.73,100,1,14.22,100,1,12.71,100,1,14.26,700,1,12.5,700,1,14.28,100,1,12.46,100,1,14.46,300,3,12.43,700,1,14.48,700,1,12.42,700,1,14.49,100,1
2025-07-17T16:14:10.876729278Z,2025-07-17T16:14:10.876894854Z,160,2,1108,C,A,0,13.54,100,0,165576,283317356,ARL,340046965,13.11,100,1,13.51,15,1,12.98,200,2,13.74,2,1,12.96,2,1,13.85,100,1,12.86,100,1,14.22,100,1,12.73,100,1,14.26,700,1,12.71,100,1,14.28,100,1,12.5,700,1,14.46,300,3,12.46,100,1,14.48,700,1,12.43,700,1,14.49,100,1,12.42,700,1,14.54,700,1
2025-07-17T16:14:10.876729278Z,2025-07-17T16:14:10.876894854Z,160,2,1108,A,A,0,13.52,100,130,165576,283317356,ARL,340527921,13.11,100,1,13.51,15,1,12.98,200,2,13.52,100,1,12.96,2,1,13.74,2,1,12.86,100,1,13.85,100,1,12.73,100,1,14.22,100,1,12.71,100,1,14.26,700,1,12.5,700,1,14.28,100,1,12.46,100,1,14.46,300,3,12.43,700,1,14.48,700,1,12.42,700,1,14.49,100,1
2025-07-17T16:14:10.878435316Z,2025-07-17T16:14:10.878601199Z,160,2,1108,C,A,0,14.63,100,0,165883,283317367,ARL,339358353,13.11,100,1,13.51,15,1,12.98,200,2,13.52,100,1,12.96,2,1,13.74,2,1,12.86,100,1,13.85,100,1,12.73,100,1,14.22,100,1,12.71,100,1,14.26,700,1,12.5,700,1,14.28,100,1,12.46,100,1,14.46,300,3,12.43,700,1,14.48,700,1,12.42,700,1,14.49,100,1
2025-07-17T16:14:10.878435316Z,2025-07-17T16:14:10.878601199Z,160,2,1108,A,A,0,14.47,100,130,165883,283317367,ARL,340527969,13.11,100,1,13.51,15,1,12.98,200,2,13.52,100,1,12.96,2,1,13.74,2,1,12.86,100,1,13.85,100,1,12.73,100,1,14.22,100,1,12.71,100,1,14.26,700,1,12.5,700,1,14.28,100,1,12.46,100,1,14.46,300,3,12.43,700,1,14.47,100,1,12.42,700,1,14.48,700,1
2025-07-17T16:14:10.892513823Z,2025-07-17T16:14:10.892679514Z,160,2,1108,C,A,0,14.63,100,0,165691,283317451,ARL,339359401,13.11,100,1,13.51,15,1,12.98,200,2,13.52,100,1,12.96,2,1,13.74,2,1,12.86,100,1,13.85,100,1,12.73,100,1,14.22,100,1,12.71,100,1,14.26,700,1,12.5,700,1,14.28,100,1,12.46,100,1,14.46,300,3,12.43,700,1,14.47,100,1,12.42,700,1,14.48,700,1
2025-07-17T16:14:10.892513823Z,2025-07-17T16:14:10.892679514Z,160,2,1108,A,A,0,14.47,100,130,165691,283317451,ARL,340528121,13.11,100,1,13.51,15,1,12.98,200,2,13.52,100,1,12.96,2,1,13.74,2,1,12.86,100,1,13.85,100,1,12.73,100,1,14.22,100,1,12.71,100,1,14.26,700,1,12.5,700,1,14.28,100,1,12.46,100,1,14.46,300,3,12.43,700,1,14.47,200,2,12.42,700,1,14.48,700,1
2025-07-17T16:14:10.985342000Z,2025-07-17T16:14:10.985507716Z,160,2,1108,C,A,0,14.46,100,0,165716,283318181,ARL,339359421,13.11,100,1,13.51,15,1,12.98,200,2,13.52,100,1,12.96,2,1,13.74,2,1,12.86,100,1,13.85,100,1,12.73,100,1,14.22,100,1,12.71,100,1,14.26,700,1,12.5,700,1,14.28,100,1,12.46,100,1,14.46,200,2,12.43,700,1,14.47,200,2,12.42,700,1,14.48,700,1
2025-07-17T16:14:10.985342000Z,2025-07-17T16:14:10.985507716Z,160,2,1108,A,A,0,14.31,100,130,165716,283318181,ARL,340529021,13.11,100,1,13.51,15,1,12.98,200,2,13.52,100,1,12.96,2,1,13.74,2,1,12.86,100,1,13.85,100,1,12.73,100,1,14.22,100,1,12.71,100,1,14.26,700,1,12.5,700,1,14.28,100,1,12.46,100,1,14.31,100,1,12.43,700,1,14.46,200,2,12.42,700,1,14.47,200,2
2025-07-17T16:14:19.528322793Z,2025-07-17T16:14:19.528488233Z,160,2,1108,A,A,0,13.49,15,130,165440,283419160,ARL,340664453,13.11,100,1,13.49,15,1,12.98,200,2,13.51,15,1,12.96,2,1,13.52,100,1,12.86,100,1,13.74,2,1,12.73,100,1,13.85,100,1,12.71,100,1,14.22,100,1,12.5,700,1,14.26,700,1,12.46,100,1,14.28,100,1,12.43,700,1,14.31,100,1,12.42,700,1,14.46,200,2
2025-07-17T16:14:21.306599291Z,2025-07-17T16:14:21.306764970Z,160,2,1108,C,A,0,13.52,100,0,165679,283454179,ARL,340527921,13.11,100,1,13.49,15,1,12.98,200,2,13.51,15,1,12.96,2,1,13.74,2,1,12.86,100,1,13.85,100,1,12.73,100,1,14.22,100,1,12.71,100,1,14.26,700,1,12.5,700,1,14.28,100,1,12.46,100,1,14.31,100,1,12.43,700,1,14.46,200,2,12.42,700,1,14.47,200,2
2025-07-17T16:14:21.306599291Z,2025-07-17T16:14:21.306764970Z,160,2,1108,A,A,0,13.5,100,130,165679,283454179,ARL,340704401,13.11,100,1,13.49,15,1,12.98,200,2,13.5,100,1,12.96,2,1,13.51,15,1,12.86,100,1,13.74,2,1,12.73,100,1,13.85,100,1,12.71,100,1,14.22,100,1,12.5,700,1,14.26,700,1,12.46,100,1,14.28,100,1,12.43,700,1,14.31,100,1,12.42,700,1,14.46,200,2
2025-07-17T16:14:21.307346403Z,2025-07-17T16:14:21.307512009Z,160,2,1108,C,A,0,14.59,100,0,165606,283454259,ARL,340047001,13.11,100,1,13.49,15,1,12.98,200,2,13.5,100,1,12.96,2,1,13.51,15,1,12.86,100,1,13.74,2,1,12.73,100,1,13.85,100,1,12.71,100,1,14.22,100,1,12.5,700,1,14.26,700,1,12.46,100,1,14.28,100,1,12.43,700,1,14.31,100,1,12.42,700,1,14.46,200,2
2025-07-17T16:14:21.307346403Z,2025-07-17T16:14:21.307512009Z,160,2,1108,A,A,0,14.55,100,130,165606,283454259,ARL,340704465,13.11,100,1,13.49,15,1,12.98,200,2,13.5,100,1,12.96,2,1,13.51,15,1,12.86,100,1,13.74,2,1,12.73,100,1,13.85,100,1,12.71,100,1,14.22,100,1,12.5,700,1,14.26,700,1,12.46,100,1,14.28,100,1,12.43,700,1,14.31,100,1,12.42,700,1,14.46,200,2
2025-07-17T16:14:21.317096752Z,2025-07-17T16:14:21.317261991Z,160,2,1108,C,A,0,13.85,100,130,165239,283454878,ARL,339642033,13.11,100,1,13.49,15,1,12.98,200,2,13.5,100,1,12.96,2,1,13.51,15,1,12.86,100,1,13.74,2,1,12.73,100,1,14.22,100,1,12.71,100,1,14.26,700,1,12.5,700,1,14.28,100,1,12.46,100,1,14.31,100,1,12.43,700,1,14.46,200,2,12.42,700,1,14.47,200,2
2025-07-17T16:14:21.317148983Z,2025-07-17T16:14:21.317314136Z,160,2,1108,A,A,0,13.77,100,130,165153,283454882,ARL,340705133,13.11,100,1,13.49,15,1,12.98,200,2,13.5,100,1,12.96,2,1,13.51,15,1,12.86,100,1,13.74,2,1,12.73,100,1,13.77,100,1,12.71,100,1,14.22,100,1,12.5,700,1,14.26,700,1,12.46,100,1,14.28,100,1,12.43,700,1,14.31,100,1,12.42,700,1,14.46,200,2
2025-07-17T16:14:21.343129166Z,2025-07-17T16:14:21.343294261Z,160,2,1108,A,A,0,15.39,100,130,165095,283455758,ARL,340706373,13.11,100,1,13.49,15,1,12.98,200,2,13.5,100,1,12.96,2,1,13.51,15,1,12.86,100,1,13.74,2,1,12.73,100,1,13.77,100,1,12.71,100,1,14.22,100,1,12.5,700,1,14.26,700,1,12.46,100,1,14.28,100,1,12.43,700,1,14.31,100,1,12.42,700,1,14.46,200,2
2025-07-17T16:14:21.343142096Z,2025-07-17T16:14:21.343307836Z,160,2,1108,C,A,0,15.67,100,130,165740,283455759,ARL,339202065,13.11,100,1,13.49,15,1,12.98,200,2,13.5,100,1,12.96,2,1,13.51,15,1,12.86,100,1,13.74,2,1,12.73,100,1,13.77,100,1,12.71,100,1,14.22,100,1,12.5,700,1,14.26,700,1,12.46,100,1,14.28,100,1,12.43,700,1,14.31,100,1,12.42,700,1,14.46,200,2
2025-07-17T16:14:36.523382949Z,2025-07-17T16:14:36.523553349Z,160,2,1108,C,A,0,13.49,15,128,170400,283655411,ARL,340664453,13.11,100,1,13.5,100,1,12.98,200,2,13.51,15,1,12.96,2,1,13.74,2,1,12.86,100,1,13.77,100,1,12.73,100,1,14.22,100,1,12.71,100,1,14.26,700,1,12.5,700,1,14.28,100,1,12.46,100,1,14.31,100,1,12.43,700,1,14.46,200,2,12.42,700,1,14.47,200,2
2025-07-17T16:14:36.523564373Z,2025-07-17T16:14:36.523730500Z,160,2,1108,C,A,0,13.51,15,128,166127,283655455,ARL,340526285,13.11,100,1,13.5,100,1,12.98,200,2,13.74,2,1,12.96,2,1,13.77,100,1,12.86,100,1,14.22,100,1,12.73,100,1,14.26,700,1,12.71,100,1,14.28,100,1,12.5,700,1,14.31,100,1,12.46,100,1,14.46,200,2,12.43,700,1,14.47,200,2,12.42,700,1,14.48,700,1
2025-07-17T16:14:36.523696080Z,2025-07-17T16:14:36.523862340Z,160,2,1108,A,A,0,13.5,99,128,166260,283655477,ARL,340971661,13.11,100,1,13.5,199,2,12.98,200,2,13.74,2,1,12.96,2,1,13.77,100,1,12.86,100,1,14.22,100,1,12.73,100,1,14.26,700,1,12.71,100,1,14.28,100,1,12.5,700,1,14.31,100,1,12.46,100,1,14.46,200,2,12.43,700,1,14.47,200,2,12.42,700,1,14.48,700,1
2025-07-17T16:14:52.280428336Z,2025-07-17T16:14:52.280593678Z,160,2,1108,C,A,0,13.5,99,130,165342,283870929,ARL,340971661,13.11,100,1,13.5,100,1,12.98,200,2,13.74,2,1,12.96,2,1,13.77,100,1,12.86,100,1,14.22,100,1,12.73,100,1,14.26,700,1,12.71,100,1,14.28,100,1,12.5,700,1,14.31,100,1,12.46,100,1,14.46,200,2,12.43,700,1,14.47,200,2,12.42,700,1,14.48,700,1
2025-07-17T16:14:52.296871817Z,2025-07-17T16:14:52.297037125Z,160,2,1108,A,A,0,13.48,15,130,165308,283871393,ARL,341248825,13.11,100,1,13.48,15,1,12.98,200,2,13.5,100,1,12.96,2,1,13.74,2,1,12.86,100,1,13.77,100,1,12.73,100,1,14.22,100,1,12.71,100,1,14.26,700,1,12.5,700,1,14.28,100,1,12.46,100,1,14.31,100,1,12.43,700,1,14.46,200,2,12.42,700,1,14.47,200,2
2025-07-17T16:14:52.828556785Z,2025-07-17T16:14:52.828721867Z,160,2,1108,C,A,0,13.48,15,130,165082,283875146,ARL,341248825,13.11,100,1,13.5,100,1,12.98,200,2,13.74,2,1,12.96,2,1,13.77,100,1,12.86,100,1,14.22,100,1,12.73,100,1,14.26,700,1,12.71,100,1,14.28,100,1,12.5,700,1,14.31,100,1,12.46,100,1,14.46,200,2,12.43,700,1,14.47,200,2,12.42,700,1,14.48,700,1
2025-07-17T16:14:52.828868258Z,2025-07-17T16:14:52.829033713Z,160,2,1108,A,A,0,13.5,99,130,165455,283875150,ARL,341253573,13.11,100,1,13.5,199,2,12.98,200,2,13.74,2,1,12.96,2,1,13.77,100,1,12.86,100,1,14.22,100,1,12.73,100,1,14.26,700,1,12.71,100,1,14.28,100,1,12.5,700,1,14.31,100,1,12.46,100,1,14.46,200,2,12.43,700,1,14.47,200,2,12.42,700,1,14.48,700,1
2025-07-17T16:15:16.987204735Z,2025-07-17T16:15:16.987369971Z,160,2,1108,C,A,0,13.5,99,130,165236,284194889,ARL,341253573,13.11,100,1,13.5,100,1,12.98,200,2,13.74,2,1,12.96,2,1,13.77,100,1,12.86,100,1,14.22,100,1,12.73,100,1,14.26,700,1,12.71,100,1,14.28,100,1,12.5,700,1,14.31,100,1,12.46,100,1,14.46,200,2,12.43,700,1,14.47,200,2,12.42,700,1,14.48,700,1
2025-07-17T16:15:16.987249289Z,2025-07-17T16:15:16.987414675Z,160,2,1108,C,A,0,13.5,100,130,165386,284194891,ARL,340704401,13.11,100,1,13.74,2,1,12.98,200,2,13.77,100,1,12.96,2,1,14.22,100,1,12.86,100,1,14.26,700,1,12.73,100,1,14.28,100,1,12.71,100,1,14.31,100,1,12.5,700,1,14.46,200,2,12.46,100,1,14.47,200,2,12.43,700,1,14.48,700,1,12.42,700,1,14.49,100,1
2025-07-17T16:15:16.987524101Z,2025-07-17T16:15:16.987689493Z,160,2,1108,C,A,0,14.26,700,130,165392,284194901,ARL,339716321,13.11,100,1,13.74,2,1,12.98,200,2,13.77,100,1,12.96,2,1,14.22,100,1,12.86,100,1,14.28,100,1,12.73,100,1,14.31,100,1,12.71,100,1,14.46,200,2,12.5,700,1,14.47,200,2,12.46,100,1,14.48,700,1,12.43,700,1,14.49,100,1,12.42,700,1,14.54,700,1
2025-07-17T16:15:16.987579177Z,2025-07-17T16:15:16.987744468Z,160,2,1108,A,A,0,14.46,700,130,165291,284194908,ARL,341661841,13.11,100,1,13.74,2,1,12.98,200,2,13.77,100,1,12.96,2,1,14.22,100,1,12.86,100,1,14.28,100,1,12.73,100,1,14.31,100,1,12.71,100,1,14.46,900,3,12.5,700,1,14.47,200,2,12.46,100,1,14.48,700,1,12.43,700,1,14.49,100,1,12.42,700,1,14.54,700,1
2025-07-17T16:15:16.987607468Z,2025-07-17T16:15:16.987772549Z,160,2,1108,A,A,0,15.7,100,130,165081,284194910,ARL,341661849,13.11,100,1,13.74,2,1,12.98,200,2,13.77,100,1,12.96,2,1,14.22,100,1,12.86,100,1,14.28,100,1,12.73,100,1,14.31,100,1,12.71,100,1,14.46,900,3,12.5,700,1,14.47,200,2,12.46,100,1,14.48,700,1,12.43,700,1,14.49,100,1,12.42,700,1,14.54,700,1
2025-07-17T16:15:16.987620573Z,2025-07-17T16:15:16.987786087Z,160,2,1108,C,A,0,15.39,100,130,165514,284194911,ARL,340706373,13.11,100,1,13.74,2,1,12.98,200,2,13.77,100,1,12.96,2,1,14.22,100,1,12.86,100,1,14.28,100,1,12.73,100,1,14.31,100,1,12.71,100,1,14.46,900,3,12.5,700,1,14.47,200,2,12.46,100,1,14.48,700,1,12.43,700,1,14.49,100,1,12.42,700,1,14.54,700,1
2025-07-17T16:15:16.987980299Z,2025-07-17T16:15:16.988145770Z,160,2,1108,C,A,0,14.55,100,0,165471,284194935,ARL,340704465,13.11,100,1,13.74,2,1,12.98,200,2,13.77,100,1,12.96,2,1,14.22,100,1,12.86,100,1,14.28,100,1,12.73,100,1,14.31,100,1,12.71,100,1,14.46,900,3,12.5,700,1,14.47,200,2,12.46,100,1,14.48,700,1,12.43,700,1,14.49,100,1,12.42,700,1,14.54,700,1
2025-07-17T16:15:16.987980299Z,2025-07-17T16:15:16.988145770Z,160,2,1108,A,A,0,14.6,100,130,165471,284194935,ARL,341661869,13.11,100,1,13.74,2,1,12.98,200,2,13.77,100,1,12.96,2,1,14.22,100,1,12.86,100,1,14.28,100,1,12.73,100,1,14.31,100,1,12.71,100,1,14.46,900,3,12.5,700,1,14.47,200,2,12.46,100,1,14.48,700,1,12.43,700,1,14.49,100,1,12.42,700,1,14.54,700,1
2025-07-17T16:15:16.988244795Z,2025-07-17T16:15:16.988410269Z,160,2,1108,C,A,0,14.47,100,0,165474,284194952,ARL,340527969,13.11,100,1,13.74,2,1,12.98,200,2,13.77,100,1,12.96,2,1,14.22,100,1,12.86,100,1,14.28,100,1,12.73,100,1,14.31,100,1,12.71,100,1,14.46,900,3,12.5,700,1,14.47,100,1,12.46,100,1,14.48,700,1,12.43,700,1,14.49,100,1,12.42,700,1,14.54,700,1
2025-07-17T16:15:16.988244795Z,2025-07-17T16:15:16.988410269Z,160,2,1108,A,A,0,14.74,100,130,165474,284194952,ARL,341661877,13.11,100,1,13.74,2,1,12.98,200,2,13.77,100,1,12.96,2,1,14.22,100,1,12.86,100,1,14.28,100,1,12.73,100,1,14.31,100,1,12.71,100,1,14.46,900,3,12.5,700,1,14.47,100,1,12.46,100,1,14.48,700,1,12.43,700,1,14.49,100,1,12.42,700,1,14.54,700,1
2025-07-17T16:15:16.989147294Z,2025-07-17T16:15:16.989313102Z,160,2,1108,C,A,0,15.58,100,0,165808,284195117,ARL,340047805,13.11,100,1,13.74,2,1,12.98,200,2,13.77,100,1,12.96,2,1,14.22,100,1,12.86,100,1,14.28,100,1,12.73,100,1,14.31,100,1,12.71,100,1,14.46,900,3,12.5,700,1,14.47,100,1,12.46,100,1,14.48,700,1,12.43,700,1,14.49,100,1,12.42,700,1,14.54,700,1
2025-07-17T16:15:16.989147294Z,2025-07-17T16:15:16.989313102Z,160,2,1108,A,A,0,15.84,100,130,165808,284195117,ARL,341661893,13.11,100,1,13.74,2,1,12.98,200,2,13.77,100,1,12.96,2,1,14.22,100,1,12.86,100,1,14.28,100,1,12.73,100,1,14.31,100,1,12.71,100,1,14.46,900,3,12.5,700,1,14.47,100,1,12.46,100,1,14.48,700,1,12.43,700,1,14.49,100,1,12.42,700,1,14.54,700,1
2025-07-17T16:15:16.989598095Z,2025-07-17T16:15:16.989763697Z,160,2,1108,C,A,0,17.23,100,0,165602,284195176,ARL,339937293,13.11,100,1,13.74,2,1,12.98,200,2,13.77,100,1,12.96,2,1,14.22,100,1,12.86,100,1,14.28,100,1,12.73,100,1,14.31,100,1,12.71,100,1,14.46,900,3,12.5,700,1,14.47,100,1,12.46,100,1,14.48,700,1,12.43,700,1,14.49,100,1,12.42,700,1,14.54,700,1
2025-07-17T16:15:16.989598095Z,2025-07-17T16:15:16.989763697Z,160,2,1108,A,A,0,17.49,100,130,165602,284195176,ARL,341661901,13.11,100,1,13.74,2,1,12.98,200,2,13.77,100,1,12.96,2,1,14.22,100,1,12.86,100,1,14.28,100,1,12.73,100,1,14.31,100,1,12.71,100,1,14.46,900,3,12.5,700,1,14.47,100,1,12.46,100,1,14.48,700,1,12.43,700,1,14.49,100,1,12.42,700,1,14.54,700,1
2025-07-17T16:15:16.989720957Z,2025-07-17T16:15:16.989886697Z,160,2,1108,C,A,0,14.47,100,0,165740,284195185,ARL,340528121,13.11,100,1,13.74,2,1,12.98,200,2,13.77,100,1,12.96,2,1,14.22,100,1,12.86,100,1,14.28,100,1,12.73,100,1,14.31,100,1,12.71,100,1,14.46,900,3,12.5,700,1,14.48,700,1,12.46,100,1,14.49,100,1,12.43,700,1,14.54,700,1,12.42,700,1,14.56,700,1
2025-07-17T16:15:16.989720957Z,2025-07-17T16:15:16.989886697Z,160,2,1108,A,A,0,14.74,100,130,165740,284195185,ARL,341661905,13.11,100,1,13.74,2,1,12.98,200,2,13.77,100,1,12.96,2,1,14.22,100,1,12.86,100,1,14.28,100,1,12.73,100,1,14.31,100,1,12.71,100,1,14.46,900,3,12.5,700,1,14.48,700,1,12.46,100,1,14.49,100,1,12.43,700,1,14.54,700,1,12.42,700,1,14.56,700,1
2025-07-17T16:15:16.992638952Z,2025-07-17T16:15:16.992804347Z,160,2,1108,C,A,0,14.31,100,130,165395,284195309,ARL,340529021,13.11,100,1,13.74,2,1,12.98,200,2,13.77,100,1,12.96,2,1,14.22,100,1,12.86,100,1,14.28,100,1,12.73,100,1,14.46,900,3,12.71,100,1,14.48,700,1,12.5,700,1,14.49,100,1,12.46,100,1,14.54,700,1,12.43,700,1,14.56,700,1,12.42,700,1,14.6,100,1
2025-07-17T16:15:16.992776612Z,2025-07-17T16:15:16.992941967Z,160,2,1108,A,A,0,14.56,100,130,165355,284195310,ARL,341661985,13.11,100,1,13.74,2,1,12.98,200,2,13.77,100,1,12.96,2,1,14.22,100,1,12.86,100,1,14.28,100,1,12.73,100,1,14.46,900,3,12.71,100,1,14.48,700,1,12.5,700,1,14.49,100,1,12.46,100,1,14.54,700,1,12.43,700,1,14.56,800,2,12.42,700,1,14.6,100,1
2025-07-17T16:15:17.000422944Z,2025-07-17T16:15:17.000588174Z,160,2,1108,C,A,0,13.77,100,130,165230,284195454,ARL,340705133,13.11,100,1,13.74,2,1,12.98,200,2,14.22,100,1,12.96,2,1,14.28,100,1,12.86,100,1,14.46,900,3,12.73,100,1,14.48,700,1,12.71,100,1,14.49,100,1,12.5,700,1,14.54,700,1,12.46,100,1,14.56,800,2,12.43,700,1,14.6,100,1,12.42,700,1,14.74,200,2
2025-07-17T16:15:17.000456046Z,2025-07-17T16:15:17.000621056Z,160,2,1108,C,A,0,14.46,700,130,165010,284195456,ARL,341661841,13.11,100,1,13.74,2,1,12.98,200,2,14.22,100,1,12.96,2,1,14.28,100,1,12.86,100,1,14.46,200,2,12.73,100,1,14.48,700,1,12.71,100,1,14.49,100,1,12.5,700,1,14.54,700,1,12.46,100,1,14.56,800,2,12.43,700,1,14.6,100,1,12.42,700,1,14.74,200,2
2025-07-17T16:15:17.000474862Z,2025-07-17T16:15:17.000640033Z,160,2,1108,A,A,0,14.05,100,130,165171,284195458,ARL,341662085,13.11,100,1,13.74,2,1,12.98,200,2,14.05,100,1,12.96,2,1,14.22,100,1,12.86,100,1,14.28,100,1,12.73,100,1,14.46,200,2,12.71,100,1,14.48,700,1,12.5,700,1,14.49,100,1,12.46,100,1,14.54,700,1,12.43,700,1,14.56,800,2,12.42,700,1,14.6,100,1
2025-07-17T16:15:17.001158038Z,2025-07-17T16:15:17.001323406Z,160,2,1108,C,A,0,14.28,100,130,165368,284195476,ARL,339358333,13.11,100,1,13.74,2,1,12.98,200,2,14.05,100,1,12.96,2,1,14.22,100,1,12.86,100,1,14.46,200,2,12.73,100,1,14.48,700,1,12.71,100,1,14.49,100,1,12.5,700,1,14.54,700,1,12.46,100,1,14.56,800,2,12.43,700,1,14.6,100,1,12.42,700,1,14.74,200,2
2025-07-17T16:15:17.001522171Z,2025-07-17T16:15:17.001687312Z,160,2,1108,A,A,0,14.6,100,130,165141,284195477,ARL,341662113,13.11,100,1,13.74,2,1,12.98,200,2,14.05,100,1,12.96,2,1,14.22,100,1,12.86,100,1,14.46,200,2,12.73,100,1,14.48,700,1,12.71,100,1,14.49,100,1,12.5,700,1,14.54,700,1,12.46,100,1,14.56,800,2,12.43,700,1,14.6,200,2,12.42,700,1,14.74,200,2
2025-07-17T16:15:17.002064284Z,2025-07-17T16:15:17.002229963Z,160,2,1108,C,A,0,14.74,100,0,165679,284195479,ARL,341661905,13.11,100,1,13.74,2,1,12.98,200,2,14.05,100,1,12.96,2,1,14.22,100,1,12.86,100,1,14.46,200,2,12.73,100,1,14.48,700,1,12.71,100,1,14.49,100,1,12.5,700,1,14.54,700,1,12.46,100,1,14.56,800,2,12.43,700,1,14.6,200,2,12.42,700,1,14.74,100,1
2025-07-17T16:15:17.002064284Z,2025-07-17T16:15:17.002229963Z,160,2,1108,A,A,0,14.96,100,130,165679,284195479,ARL,341662117,13.11,100,1,13.74,2,1,12.98,200,2,14.05,100,1,12.96,2,1,14.22,100,1,12.86,100,1,14.46,200,2,12.73,100,1,14.48,700,1,12.71,100,1,14.49,100,1,12.5,700,1,14.54,700,1,12.46,100,1,14.56,800,2,12.43,700,1,14.6,200,2,12.42,700,1,14.74,100,1
2025-07-17T16:15:17.002625119Z,2025-07-17T16:15:17.002790290Z,160,2,1108,C,A,0,17.49,100,0,165171,284195482,ARL,341661901,13.11,100,1,13.74,2,1,12.98,200,2,14.05,100,1,12.96,2,1,14.22,100,1,12.86,100,1,14.46,200,2,12.73,100,1,14.48,700,1,12.71,100,1,14.49,100,1,12.5,700,1,14.54,700,1,12.46,100,1,14.56,800,2,12.43,700,1,14.6,200,2,12.42,700,1,14.74,100,1
2025-07-17T16:15:17.002625119Z,2025-07-17T16:15:17.002790290Z,160,2,1108,A,A,0,17.76,100,130,165171,284195482,ARL,341662125,13.11,100,1,13.74,2,1,12.98,200,2,14.05,100,1,12.96,2,1,14.22,100,1,12.86,100,1,14.46,200,2,12.73,100,1,14.48,700,1,12.71,100,1,14.49,100,1,12.5,700,1,14.54,700,1,12.46,100,1,14.56,800,2,12.43,700,1,14.6,200,2,12.42,700,1,14.74,100,1
2025-07-17T16:15:17.003081581Z,2025-07-17T16:15:17.003246802Z,160,2,1108,C,A,0,14.74,100,0,165221,284195486,ARL,341661877,13.11,100,1,13.74,2,1,12.98,200,2,14.05,100,1,12.96,2,1,14.22,100,1,12.86,100,1,14.46,200,2,12.73,100,1,14.48,700,1,12.71,100,1,14.49,100,1,12.5,700,1,14.54,700,1,12.46,100,1,14.56,800,2,12.43,700,1,14.6,200,2,12.42,700,1,14.96,100,1
2025-07-17T16:15:17.003081581Z,2025-07-17T16:15:17.003246802Z,160,2,1108,A,A,0,14.96,100,130,165221,284195486,ARL,341662133,13.11,100,1,13.74,2,1,12.98,200,2,14.05,100,1,12.96,2,1,14.22,100,1,12.86,100,1,14.46,200,2,12.73,100,1,14.48,700,1,12.71,100,1,14.49,100,1,12.5,700,1,14.54,700,1,12.46,100,1,14.56,800,2,12.43,700,1,14.6,200,2,12.42,700,1,14.96,200,2
2025-07-17T16:15:17.003216492Z,2025-07-17T16:15:17.003381863Z,160,2,1108,C,A,0,15.84,100,0,165371,284195487,ARL,341661893,13.11,100,1,13.74,2,1,12.98,200,2,14.05,100,1,12.96,2,1,14.22,100,1,12.86,100,1,14.46,200,2,12.73,100,1,14.48,700,1,12.71,100,1,14.49,100,1,12.5,700,1,14.54,700,1,12.46,100,1,14.56,800,2,12.43,700,1,14.6,200,2,12.42,700,1,14.96,200,2
2025-07-17T16:15:17.003216492Z,2025-07-17T16:15:17.003381863Z,160,2,1108,A,A,0,16.08,100,130,165371,284195487,ARL,341662137,13.11,100,1,13.74,2,1,12.98,200,2,14.05,100,1,12.96,2,1,14.22,100,1,12.86,100,1,14.46,200,2,12.73,100,1,14.48,700,1,12.71,100,1,14.49,100,1,12.5,700,1,14.54,700,1,12.46,100,1,14.56,800,2,12.43,700,1,14.6,200,2,12.42,700,1,14.96,200,2
2025-07-17T16:15:17.003708485Z,2025-07-17T16:15:17.003874553Z,160,2,1108,C,A,0,15.04,100,0,166068,284195498,ARL,339358349,13.11,100,1,13.74,2,1,12.98,200,2,14.05,100,1,12.96,2,1,14.22,100,1,12.86,100,1,14.46,200,2,12.73,100,1,14.48,700,1,12.71,100,1,14.49,100,1,12.5,700,1,14.54,700,1,12.46,100,1,14.56,800,2,12.43,700,1,14.6,200,2,12.42,700,1,14.96,200,2
2025-07-17T16:15:17.003708485Z,2025-07-17T16:15:17.003874553Z,160,2,1108,A,A,0,15.38,100,130,166068,284195498,ARL,341662145,13.11,100,1,13.74,2,1,12.98,200,2,14.05,100,1,12.96,2,1,14.22,100,1,12.86,100,1,14.46,200,2,12.73,100,1,14.48,700,1,12.71,100,1,14.49,100,1,12.5,700,1,14.54,700,1,12.46,100,1,14.56,800,2,12.43,700,1,14.6,200,2,12.42,700,1,14.96,200,2
2025-07-17T16:15:17.003717832Z,2025-07-17T16:15:17.003883470Z,160,2,1108,C,A,0,15.04,100,0,165638,284195499,ARL,339359357,13.11,100,1,13.74,2,1,12.98,200,2,14.05,100,1,12.96,2,1,14.22,100,1,12.86,100,1,14.46,200,2,12.73,100,1,14.48,700,1,12.71,100,1,14.49,100,1,12.5,700,1,14.54,700,1,12.46,100,1,14.56,800,2,12.43,700,1,14.6,200,2,12.42,700,1,14.96,200,2
2025-07-17T16:15:17.003717832Z,2025-07-17T16:15:17.003883470Z,160,2,1108,A,A,0,15.38,100,130,165638,284195499,ARL,341662149,13.11,100,1,13.74,2,1,12.98,200,2,14.05,100,1,12.96,2,1,14.22,100,1,12.86,100,1,14.46,200,2,12.73,100,1,14.48,700,1,12.71,100,1,14.49,100,1,12.5,700,1,14.54,700,1,12.46,100,1,14.56,800,2,12.43,700,1,14.6,200,2,12.42,700,1,14.96,200,2
2025-07-17T16:15:17.019402521Z,2025-07-17T16:15:17.019567564Z,160,2,1108,C,A,0,14.05,100,130,165043,284195602,ARL,341662085,13.11,100,1,13.74,2,1,12.98,200,2,14.22,100,1,12.96,2,1,14.46,200,2,12.86,100,1,14.48,700,1,12.73,100,1,14.49,100,1,12.71,100,1,14.54,700,1,12.5,700,1,14.56,800,2,12.46,100,1,14.6,200,2,12.43,700,1,14.96,200,2,12.42,700,1,15.3,100,1
2025-07-17T16:15:17.019452245Z,2025-07-17T16:15:17.019617602Z,160,2,1108,A,A,0,14.26,100,130,165357,284195603,ARL,341662313,13.11,100,1,13.74,2,1,12.98,200,2,14.22,100,1,12.96,2,1,14.26,100,1,12.86,100,1,14.46,200,2,12.73,100,1,14.48,700,1,12.71,100,1,14.49,100,1,12.5,700,1,14.54,700,1,12.46,100,1,14.56,800,2,12.43,700,1,14.6,200,2,12.42,700,1,14.96,200,2
2025-07-17T16:15:17.037096157Z,2025-07-17T16:15:17.037261626Z,160,2,1108,C,A,0,14.6,100,0,165469,284195665,ARL,341661869,13.11,100,1,13.74,2,1,12.98,200,2,14.22,100,1,12.96,2,1,14.26,100,1,12.86,100,1,14.46,200,2,12.73,100,1,14.48,700,1,12.71,100,1,14.49,100,1,12.5,700,1,14.54,700,1,12.46,100,1,14.56,800,2,12.43,700,1,14.6,100,1,12.42,700,1,14.96,200,2
2025-07-17T16:15:17.037096157Z,2025-07-17T16:15:17.037261626Z,160,2,1108,A,A,0,15.06,100,130,165469,284195665,ARL,341662429,13.11,100,1,13.74,2,1,12.98,200,2,14.22,100,1,12.96,2,1,14.26,100,1,12.86,100,1,14.46,200,2,12.73,100,1,14.48,700,1,12.71,100,1,14.49,100,1,12.5,700,1,14.54,700,1,12.46,100,1,14.56,800,2,12.43,700,1,14.6,100,1,12.42,700,1,14.96,200,2
2025-07-17T16:15:17.048901142Z,2025-07-17T16:15:17.049066370Z,160,2,1108,A,A,0,13.75,100,130,165228,284196195,ARL,341663101,13.11,100,1,13.74,2,1,12.98,200,2,13.75,100,1,12.96,2,1,14.22,100,1,12.86,100,1,14.26,100,1,12.73,100,1,14.46,200,2,12.71,100,1,14.48,700,1,12.5,700,1,14.49,100,1,12.46,100,1,14.54,700,1,12.43,700,1,14.56,800,2,12.42,700,1,14.6,100,1
2025-07-17T16:15:17.048943087Z,2025-07-17T16:15:17.049108554Z,160,2,1108,A,A,0,14.68,700,130,165467,284196196,ARL,341663105,13.11,100,1,13.74,2,1,12.98,200,2,13.75,100,1,12.96,2,1,14.22,100,1,12.86,100,1,14.26,100,1,12.73,100,1,14.46,200,2,12.71,100,1,14.48,700,1,12.5,700,1,14.49,100,1,12.46,100,1,14.54,700,1,12.43,700,1,14.56,800,2,12.42,700,1,14.6,100,1
2025-07-17T16:15:17.050646751Z,2025-07-17T16:15:17.050812161Z,160,2,1108,C,A,0,14.96,100,0,165410,284196235,ARL,341662133,13.11,100,1,13.74,2,1,12.98,200,2,13.75,100,1,12.96,2,1,14.22,100,1,12.86,100,1,14.26,100,1,12.73,100,1,14.46,200,2,12.71,100,1,14.48,700,1,12.5,700,1,14.49,100,1,12.46,100,1,14.54,700,1,12.43,700,1,14.56,800,2,12.42,700,1,14.6,100,1
2025-07-17T16:15:17.050646751Z,2025-07-17T16:15:17.050812161Z,160,2,1108,A,A,0,14.72,100,130,165410,284196235,ARL,341663261,13.11,100,1,13.74,2,1,12.98,200,2,13.75,100,1,12.96,2,1,14.22,100,1,12.86,100,1,14.26,100,1,12.73,100,1,14.46,200,2,12.71,100,1,14.48,700,1,12.5,700,1,14.49,100,1,12.46,100,1,14.54,700,1,12.43,700,1,14.56,800,2,12.42,700,1,14.6,100,1
2025-07-17T16:15:17.051479522Z,2025-07-17T16:15:17.051644859Z,160,2,1108,C,A,0,17.76,100,0,165337,284196242,ARL,341662125,13.11,100,1,13.74,2,1,12.98,200,2,13.75,100,1,12.96,2,1,14.22,100,1,12.86,100,1,14.26,100,1,12.73,100,1,14.46,200,2,12.71,100,1,14.48,700,1,12.5,700,1,14.49,100,1,12.46,100,1,14.54,700,1,12.43,700,1,14.56,800,2,12.42,700,1,14.6,100,1
2025-07-17T16:15:17.051479522Z,2025-07-17T16:15:17.051644859Z,160,2,1108,A,A,0,17.47,100,130,165337,284196242,ARL,341663289,13.11,100,1,13.74,2,1,12.98,200,2,13.75,100,1,12.96,2,1,14.22,100,1,12.86,100,1,14.26,100,1,12.73,100,1,14.46,200,2,12.71,100,1,14.48,700,1,12.5,700,1,14.49,100,1,12.46,100,1,14.54,700,1,12.43,700,1,14.56,800,2,12.42,700,1,14.6,100,1
2025-07-17T16:15:17.053993491Z,2025-07-17T16:15:17.054159307Z,160,2,1108,C,A,0,16.08,100,0,165816,284196273,ARL,341662137,13.11,100,1,13.74,2,1,12.98,200,2,13.75,100,1,12.96,2,1,14.22,100,1,12.86,100,1,14.26,100,1,12.73,100,1,14.46,200,2,12.71,100,1,14.48,700,1,12.5,700,1,14.49,100,1,12.46,100,1,14.54,700,1,12.43,700,1,14.56,800,2,12.42,700,1,14.6,100,1
2025-07-17T16:15:17.053993491Z,2025-07-17T16:15:17.054159307Z,160,2,1108,A,A,0,15.82,100,130,165816,284196273,ARL,341663317,13.11,100,1,13.74,2,1,12.98,200,2,13.75,100,1,12.96,2,1,14.22,100,1,12.86,100,1,14.26,100,1,12.73,100,1,14.46,200,2,12.71,100,1,14.48,700,1,12.5,700,1,14.49,100,1,12.46,100,1,14.54,700,1,12.43,700,1,14.56,800,2,12.42,700,1,14.6,100,1
2025-07-17T16:15:17.059338704Z,2025-07-17T16:15:17.059504149Z,160,2,1108,C,A,0,14.26,100,130,165445,284196314,ARL,341662313,13.11,100,1,13.74,2,1,12.98,200,2,13.75,100,1,12.96,2,1,14.22,100,1,12.86,100,1,14.46,200,2,12.73,100,1,14.48,700,1,12.71,100,1,14.49,100,1,12.5,700,1,14.54,700,1,12.46,100,1,14.56,800,2,12.43,700,1,14.6,100,1,12.42,700,1,14.68,700,1
2025-07-17T16:15:17.059387360Z,2025-07-17T16:15:17.059552653Z,160,2,1108,A,A,0,14.03,100,130,165293,284196315,ARL,341663401,13.11,100,1,13.74,2,1,12.98,200,2,13.75,100,1,12.96,2,1,14.03,100,1,12.86,100,1,14.22,100,1,12.73,100,1,14.46,200,2,12.71,100,1,14.48,700,1,12.5,700,1,14.49,100,1,12.46,100,1,14.54,700,1,12.43,700,1,14.56,800,2,12.42,700,1,14.6,100,1
2025-07-17T16:15:17.083936164Z,2025-07-17T16:15:17.084101480Z,160,2,1108,C,A,0,14.96,100,0,165316,284196410,ARL,341662117,13.11,100,1,13.74,2,1,12.98,200,2,13.75,100,1,12.96,2,1,14.03,100,1,12.86,100,1,14.22,100,1,12.73,100,1,14.46,200,2,12.71,100,1,14.48,700,1,12.5,700,1,14.49,100,1,12.46,100,1,14.54,700,1,12.43,700,1,14.56,800,2,12.42,700,1,14.6,100,1
2025-07-17T16:15:17.083936164Z,2025-07-17T16:15:17.084101480Z,160,2,1108,A,A,0,14.72,100,130,165316,284196410,ARL,341663737,13.11,100,1,13.74,2,1,12.98,200,2,13.75,100,1,12.96,2,1,14.03,100,1,12.86,100,1,14.22,100,1,12.73,100,1,14.46,200,2,12.71,100,1,14.48,700,1,12.5,700,1,14.49,100,1,12.46,100,1,14.54,700,1,12.43,700,1,14.56,800,2,12.42,700,1,14.6,100,1
2025-07-17T16:15:17.087688271Z,2025-07-17T16:15:17.087853488Z,160,2,1108,C,A,0,15.06,100,0,165217,284196429,ARL,341662429,13.11,100,1,13.74,2,1,12.98,200,2,13.75,100,1,12.96,2,1,14.03,100,1,12.86,100,1,14.22,100,1,12.73,100,1,14.46,200,2,12.71,100,1,14.48,700,1,12.5,700,1,14.49,100,1,12.46,100,1,14.54,700,1,12.43,700,1,14.56,800,2,12.42,700,1,14.6,100,1
2025-07-17T16:15:17.087688271Z,2025-07-17T16:15:17.087853488Z,160,2,1108,A,A,0,14.82,100,130,165217,284196429,ARL,341663749,13.11,100,1,13.74,2,1,12.98,200,2,13.75,100,1,12.96,2,1,14.03,100,1,12.86,100,1,14.22,100,1,12.73,100,1,14.46,200,2,12.71,100,1,14.48,700,1,12.5,700,1,14.49,100,1,12.46,100,1,14.54,700,1,12.43,700,1,14.56,800,2,12.42,700,1,14.6,100,1
2025-07-17T16:15:17.643653020Z,2025-07-17T16:15:17.643818240Z,160,2,1108,C,A,0,14.6,100,130,165220,284202090,ARL,341662113,13.11,100,1,13.74,2,1,12.98,200,2,13.75,100,1,12.96,2,1,14.03,100,1,12.86,100,1,14.22,100,1,12.73,100,1,14.46,200,2,12.71,100,1,14.48,700,1,12.5,700,1,14.49,100,1,12.46,100,1,14.54,700,1,12.43,700,1,14.56,800,2,12.42,700,1,14.68,700,1
2025-07-17T16:15:17.644003726Z,2025-07-17T16:15:17.644168944Z,160,2,1108,A,A,0,14.36,100,130,165218,284202091,ARL,341671053,13.11,100,1,13.74,2,1,12.98,200,2,13.75,100,1,12.96,2,1,14.03,100,1,12.86,100,1,14.22,100,1,12.73,100,1,14.36,100,1,12.71,100,1,14.46,200,2,12.5,700,1,14.48,700,1,12.46,100,1,14.49,100,1,12.43,700,1,14.54,700,1,12.42,700,1,14.56,800,2
2025-07-17T16:15:35.998974923Z,2025-07-17T16:15:35.999140348Z,160,2,1108,C,B,0,12.36,100,0,165425,284480502,ARL,336572057,13.11,100,1,13.74,2,1,12.98,200,2,13.75,100,1,12.96,2,1,14.03,100,1,12.86,100,1,14.22,100,1,12.73,100,1,14.36,100,1,12.71,100,1,14.46,200,2,12.5,700,1,14.48,700,1,12.46,100,1,14.49,100,1,12.43,700,1,14.54,700,1,12.42,700,1,14.56,800,2
2025-07-17T16:15:35.998974923Z,2025-07-17T16:15:35.999140348Z,160,2,1108,A,B,0,12.22,100,130,165425,284480502,ARL,342029561,13.11,100,1,13.74,2,1,12.98,200,2,13.75,100,1,12.96,2,1,14.03,100,1,12.86,100,1,14.22,100,1,12.73,100,1,14.36,100,1,12.71,100,1,14.46,200,2,12.5,700,1,14.48,700,1,12.46,100,1,14.49,100,1,12.43,700,1,14.54,700,1,12.42,700,1,14.56,800,2
2025-07-17T16:15:35.999596382Z,2025-07-17T16:15:35.999762137Z,160,2,1108,C,B,0,12.36,100,0,165755,284480519,ARL,336572069,13.11,100,1,13.74,2,1,12.98,200,2,13.75,100,1,12.96,2,1,14.03,100,1,12.86,100,1,14.22,100,1,12.73,100,1,14.36,100,1,12.71,100,1,14.46,200,2,12.5,700,1,14.48,700,1,12.46,100,1,14.49,100,1,12.43,700,1,14.54,700,1,12.42,700,1,14.56,800,2
2025-07-17T16:15:35.999596382Z,2025-07-17T16:15:35.999762137Z,160,2,1108,A,B,0,12.22,100,130,165755,284480519,ARL,342029581,13.11,100,1,13.74,2,1,12.98,200,2,13.75,100,1,12.96,2,1,14.03,100,1,12.86,100,1,14.22,100,1,12.73,100,1,14.36,100,1,12.71,100,1,14.46,200,2,12.5,700,1,14.48,700,1,12.46,100,1,14.49,100,1,12.43,700,1,14.54,700,1,12.42,700,1,14.56,800,2
2025-07-17T16:16:30.787282866Z,2025-07-17T16:16:30.787448429Z,160,2,1108,C,B,0,12.96,2,0,165563,285308466,ARL,339356397,13.11,100,1,13.74,2,1,12.98,200,2,13.75,100,1,12.86,100,1,14.03,100,1,12.73,100,1,14.22,100,1,12.71,100,1,14.36,100,1,12.5,700,1,14.46,200,2,12.46,100,1,14.48,700,1,12.43,700,1,14.49,100,1,12.42,700,1,14.54,700,1,12.37,700,1,14.56,800,2
2025-07-17T16:16:30.787282866Z,2025-07-17T16:16:30.787448429Z,160,2,1108,A,B,0,13.03,2,130,165563,285308466,ARL,343084165,13.11,100,1,13.74,2,1,13.03,2,1,13.75,100,1,12.98,200,2,14.03,100,1,12.86,100,1,14.22,100,1,12.73,100,1,14.36,100,1,12.71,100,1,14.46,200,2,12.5,700,1,14.48,700,1,12.46,100,1,14.49,100,1,12.43,700,1,14.54,700,1,12.42,700,1,14.56,800,2
2025-07-17T16:17:22.832783132Z,2025-07-17T16:17:22.832948558Z,160,2,1108,A,A,0,13.47,15,130,165426,286207282,ARL,344211173,13.11,100,1,13.47,15,1,13.03,2,1,13.74,2,1,12.98,200,2,13.75,100,1,12.86,100,1,14.03,100,1,12.73,100,1,14.22,100,1,12.71,100,1,14.36,100,1,12.5,700,1,14.46,200,2,12.46,100,1,14.48,700,1,12.43,700,1,14.49,100,1,12.42,700,1,14.54,700,1
2025-07-17T16:17:23.620290881Z,2025-07-17T16:17:23.620456421Z,160,2,1108,C,A,0,13.75,100,0,165540,286219821,ARL,341663101,13.11,100,1,13.47,15,1,13.03,2,1,13.74,2,1,12.98,200,2,14.03,100,1,12.86,100,1,14.22,100,1,12.73,100,1,14.36,100,1,12.71,100,1,14.46,200,2,12.5,700,1,14.48,700,1,12.46,100,1,14.49,100,1,12.43,700,1,14.54,700,1,12.42,700,1,14.56,800,2
2025-07-17T16:17:23.620290881Z,2025-07-17T16:17:23.620456421Z,160,2,1108,A,A,0,13.48,100,130,165540,286219821,ARL,344225341,13.11,100,1,13.47,15,1,13.03,2,1,13.48,100,1,12.98,200,2,13.74,2,1,12.86,100,1,14.03,100,1,12.73,100,1,14.22,100,1,12.71,100,1,14.36,100,1,12.5,700,1,14.46,200,2,12.46,100,1,14.48,700,1,12.43,700,1,14.49,100,1,12.42,700,1,14.54,700,1
2025-07-17T16:17:23.621034171Z,2025-07-17T16:17:23.621199578Z,160,2,1108,C,A,0,14.36,100,130,165407,286219868,ARL,341671053,13.11,100,1,13.47,15,1,13.03,2,1,13.48,100,1,12.98,200,2,13.74,2,1,12.86,100,1,14.03,100,1,12.73,100,1,14.22,100,1,12.71,100,1,14.46,200,2,12.5,700,1,14.48,700,1,12.46,100,1,14.49,100,1,12.43,700,1,14.54,700,1,12.42,700,1,14.56,800,2
2025-07-17T16:17:23.621040069Z,2025-07-17T16:17:23.621205573Z,160,2,1108,C,A,0,14.82,100,0,165504,286219869,ARL,341663749,13.11,100,1,13.47,15,1,13.03,2,1,13.48,100,1,12.98,200,2,13.74,2,1,12.86,100,1,14.03,100,1,12.73,100,1,14.22,100,1,12.71,100,1,14.46,200,2,12.5,700,1,14.48,700,1,12.46,100,1,14.49,100,1,12.43,700,1,14.54,700,1,12.42,700,1,14.56,800,2
2025-07-17T16:17:23.621040069Z,2025-07-17T16:17:23.621205573Z,160,2,1108,A,A,0,14.53,100,130,165504,286219869,ARL,344225385,13.11,100,1,13.47,15,1,13.03,2,1,13.48,100,1,12.98,200,2,13.74,2,1,12.86,100,1,14.03,100,1,12.73,100,1,14.22,100,1,12.71,100,1,14.46,200,2,12.5,700,1,14.48,700,1,12.46,100,1,14.49,100,1,12.43,700,1,14.53,100,1,12.42,700,1,14.54,700,1
2025-07-17T16:17:23.621221535Z,2025-07-17T16:17:23.621387062Z,160,2,1108,C,A,0,15.82,100,0,165527,286219879,ARL,341663317,13.11,100,1,13.47,15,1,13.03,2,1,13.48,100,1,12.98,200,2,13.74,2,1,12.86,100,1,14.03,100,1,12.73,100,1,14.22,100,1,12.71,100,1,14.46,200,2,12.5,700,1,14.48,700,1,12.46,100,1,14.49,100,1,12.43,700,1,14.53,100,1,12.42,700,1,14.54,700,1
2025-07-17T16:17:23.621221535Z,2025-07-17T16:17:23.621387062Z,160,2,1108,A,A,0,15.51,100,130,165527,286219879,ARL,344225393,13.11,100,1,13.47,15,1,13.03,2,1,13.48,100,1,12.98,200,2,13.74,2,1,12.86,100,1,14.03,100,1,12.73,100,1,14.22,100,1,12.71,100,1,14.46,200,2,12.5,700,1,14.48,700,1,12.46,100,1,14.49,100,1,12.43,700,1,14.53,100,1,12.42,700,1,14.54,700,1
2025-07-17T16:17:23.621389325Z,2025-07-17T16:17:23.621555609Z,160,2,1108,A,A,0,14.08,100,130,166284,286219881,ARL,344225397,13.11,100,1,13.47,15,1,13.03,2,1,13.48,100,1,12.98,200,2,13.74,2,1,12.86,100,1,14.03,100,1,12.73,100,1,14.08,100,1,12.71,100,1,14.22,100,1,12.5,700,1,14.46,200,2,12.46,100,1,14.48,700,1,12.43,700,1,14.49,100,1,12.42,700,1,14.53,100,1
2025-07-17T16:17:23.621812403Z,2025-07-17T16:17:23.621978089Z,160,2,1108,C,A,0,15.38,100,0,165686,286219887,ARL,341662145,13.11,100,1,13.47,15,1,13.03,2,1,13.48,100,1,12.98,200,2,13.74,2,1,12.86,100,1,14.03,100,1,12.73,100,1,14.08,100,1,12.71,100,1,14.22,100,1,12.5,700,1,14.46,200,2,12.46,100,1,14.48,700,1,12.43,700,1,14.49,100,1,12.42,700,1,14.53,100,1
2025-07-17T16:17:23.621812403Z,2025-07-17T16:17:23.621978089Z,160,2,1108,A,A,0,14.83,100,130,165686,286219887,ARL,344225405,13.11,100,1,13.47,15,1,13.03,2,1,13.48,100,1,12.98,200,2,13.74,2,1,12.86,100,1,14.03,100,1,12.73,100,1,14.08,100,1,12.71,100,1,14.22,100,1,12.5,700,1,14.46,200,2,12.46,100,1,14.48,700,1,12.43,700,1,14.49,100,1,12.42,700,1,14.53,100,1
2025-07-17T16:17:23.622668656Z,2025-07-17T16:17:23.622834183Z,160,2,1108,C,A,0,14.72,100,0,165527,286219894,ARL,341663261,13.11,100,1,13.47,15,1,13.03,2,1,13.48,100,1,12.98,200,2,13.74,2,1,12.86,100,1,14.03,100,1,12.73,100,1,14.08,100,1,12.71,100,1,14.22,100,1,12.5,700,1,14.46,200,2,12.46,100,1,14.48,700,1,12.43,700,1,14.49,100,1,12.42,700,1,14.53,100,1
2025-07-17T16:17:23.622668656Z,2025-07-17T16:17:23.622834183Z,160,2,1108,A,A,0,14.43,100,130,165527,286219894,ARL,344225449,13.11,100,1,13.47,15,1,13.03,2,1,13.48,100,1,12.98,200,2,13.74,2,1,12.86,100,1,14.03,100,1,12.73,100,1,14.08,100,1,12.71,100,1,14.22,100,1,12.5,700,1,14.43,100,1,12.46,100,1,14.46,200,2,12.43,700,1,14.48,700,1,12.42,700,1,14.49,100,1
2025-07-17T16:17:23.622845856Z,2025-07-17T16:17:23.623011421Z,160,2,1108,C,A,0,14.56,100,0,165565,286219895,ARL,341661985,13.11,100,1,13.47,15,1,13.03,2,1,13.48,100,1,12.98,200,2,13.74,2,1,12.86,100,1,14.03,100,1,12.73,100,1,14.08,100,1,12.71,100,1,14.22,100,1,12.5,700,1,14.43,100,1,12.46,100,1,14.46,200,2,12.43,700,1,14.48,700,1,12.42,700,1,14.49,100,1
2025-07-17T16:17:23.622845856Z,2025-07-17T16:17:23.623011421Z,160,2,1108,A,A,0,14.27,100,130,165565,286219895,ARL,344225453,13.11,100,1,13.47,15,1,13.03,2,1,13.48,100,1,12.98,200,2,13.74,2,1,12.86,100,1,14.03,100,1,12.73,100,1,14.08,100,1,12.71,100,1,14.22,100,1,12.5,700,1,14.27,100,1,12.46,100,1,14.43,100,1,12.43,700,1,14.46,200,2,12.42,700,1,14.48,700,1
2025-07-17T16:17:23.622887237Z,2025-07-17T16:17:23.623052802Z,160,2,1108,C,A,0,17.47,100,0,165565,286219896,ARL,341663289,13.11,100,1,13.47,15,1,13.03,2,1,13.48,100,1,12.98,200,2,13.74,2,1,12.86,100,1,14.03,100,1,12.73,100,1,14.08,100,1,12.71,100,1,14.22,100,1,12.5,700,1,14.27,100,1,12.46,100,1,14.43,100,1,12.43,700,1,14.46,200,2,12.42,700,1,14.48,700,1
2025-07-17T16:17:23.622887237Z,2025-07-17T16:17:23.623052802Z,160,2,1108,A,A,0,17.12,100,130,165565,286219896,ARL,344225457,13.11,100,1,13.47,15,1,13.03,2,1,13.48,100,1,12.98,200,2,13.74,2,1,12.86,100,1,14.03,100,1,12.73,100,1,14.08,100,1,12.71,100,1,14.22,100,1,12.5,700,1,14.27,100,1,12.46,100,1,14.43,100,1,12.43,700,1,14.46,200,2,12.42,700,1,14.48,700,1
2025-07-17T16:17:23.624413295Z,2025-07-17T16:17:23.624578699Z,160,2,1108,C,A,0,15.38,100,0,165404,286219909,ARL,341662149,13.11,100,1,13.47,15,1,13.03,2,1,13.48,100,1,12.98,200,2,13.74,2,1,12.86,100,1,14.03,100,1,12.73,100,1,14.08,100,1,12.71,100,1,14.22,100,1,12.5,700,1,14.27,100,1,12.46,100,1,14.43,100,1,12.43,700,1,14.46,200,2,12.42,700,1,14.48,700,1
2025-07-17T16:17:23.624413295Z,2025-07-17T16:17:23.624578699Z,160,2,1108,A,A,0,14.83,100,130,165404,286219909,ARL,344225485,13.11,100,1,13.47,15,1,13.03,2,1,13.48,100,1,12.98,200,2,13.74,2,1,12.86,100,1,14.03,100,1,12.73,100,1,14.08,100,1,12.71,100,1,14.22,100,1,12.5,700,1,14.27,100,1,12.46,100,1,14.43,100,1,12.43,700,1,14.46,200,2,12.42,700,1,14.48,700,1
2025-07-17T16:17:23.624472504Z,2025-07-17T16:17:23.624638111Z,160,2,1108,C,A,0,14.72,100,0,165607,286219911,ARL,341663737,13.11,100,1,13.47,15,1,13.03,2,1,13.48,100,1,12.98,200,2,13.74,2,1,12.86,100,1,14.03,100,1,12.73,100,1,14.08,100,1,12.71,100,1,14.22,100,1,12.5,700,1,14.27,100,1,12.46,100,1,14.43,100,1,12.43,700,1,14.46,200,2,12.42,700,1,14.48,700,1
2025-07-17T16:17:23.624472504Z,2025-07-17T16:17:23.624638111Z,160,2,1108,A,A,0,14.43,100,130,165607,286219911,ARL,344225489,13.11,100,1,13.47,15,1,13.03,2,1,13.48,100,1,12.98,200,2,13.74,2,1,12.86,100,1,14.03,100,1,12.73,100,1,14.08,100,1,12.71,100,1,14.22,100,1,12.5,700,1,14.27,100,1,12.46,100,1,14.43,200,2,12.43,700,1,14.46,200,2,12.42,700,1,14.48,700,1
2025-07-17T16:17:23.627488304Z,2025-07-17T16:17:23.627653611Z,160,2,1108,C,A,0,14.03,100,130,165307,286219940,ARL,341663401,13.11,100,1,13.47,15,1,13.03,2,1,13.48,100,1,12.98,200,2,13.74,2,1,12.86,100,1,14.08,100,1,12.73,100,1,14.22,100,1,12.71,100,1,14.27,100,1,12.5,700,1,14.43,200,2,12.46,100,1,14.46,200,2,12.43,700,1,14.48,700,1,12.42,700,1,14.49,100,1
2025-07-17T16:17:23.627539425Z,2025-07-17T16:17:23.627704598Z,160,2,1108,A,A,0,13.75,100,130,165173,286219941,ARL,344225533,13.11,100,1,13.47,15,1,13.03,2,1,13.48,100,1,12.98,200,2,13.74,2,1,12.86,100,1,13.75,100,1,12.73,100,1,14.08,100,1,12.71,100,1,14.22,100,1,12.5,700,1,14.27,100,1,12.46,100,1,14.43,200,2,12.43,700,1,14.46,200,2,12.42,700,1,14.48,700,1
2025-07-17T16:17:23.653641816Z,2025-07-17T16:17:23.653807815Z,160,2,1108,A,A,0,15.37,100,130,165999,286220138,ARL,344225829,13.11,100,1,13.47,15,1,13.03,2,1,13.48,100,1,12.98,200,2,13.74,2,1,12.86,100,1,13.75,100,1,12.73,100,1,14.08,100,1,12.71,100,1,14.22,100,1,12.5,700,1,14.27,100,1,12.46,100,1,14.43,200,2,12.43,700,1,14.46,200,2,12.42,700,1,14.48,700,1
2025-07-17T16:17:23.653655443Z,2025-07-17T16:17:23.653821034Z,160,2,1108,C,A,0,15.7,100,130,165591,286220139,ARL,341661849,13.11,100,1,13.47,15,1,13.03,2,1,13.48,100,1,12.98,200,2,13.74,2,1,12.86,100,1,13.75,100,1,12.73,100,1,14.08,100,1,12.71,100,1,14.22,100,1,12.5,700,1,14.27,100,1,12.46,100,1,14.43,200,2,12.43,700,1,14.46,200,2,12.42,700,1,14.48,700,1
2025-07-17T16:17:24.832175508Z,2025-07-17T16:17:24.832340976Z,160,2,1108,C,A,0,13.47,15,130,165468,286237340,ARL,344211173,13.11,100,1,13.48,100,1,13.03,2,1,13.74,2,1,12.98,200,2,13.75,100,1,12.86,100,1,14.08,100,1,12.73,100,1,14.22,100,1,12.71,100,1,14.27,100,1,12.5,700,1,14.43,200,2,12.46,100,1,14.46,200,2,12.43,700,1,14.48,700,1,12.42,700,1,14.49,100,1
2025-07-17T16:17:26.823396428Z,2025-07-17T16:17:26.823562625Z,160,2,1108,C,A,0,13.48,100,130,166197,286261717,ARL,344225341,13.11,100,1,13.74,2,1,13.03,2,1,13.75,100,1,12.98,200,2,14.08,100,1,12.86,100,1,14.22,100,1,12.73,100,1,14.27,100,1,12.71,100,1,14.43,200,2,12.5,700,1,14.46,200,2,12.46,100,1,14.48,700,1,12.43,700,1,14.49,100,1,12.42,700,1,14.53,100,1
2025-07-17T16:17:26.823758552Z,2025-07-17T16:17:26.823923686Z,160,2,1108,A,A,0,15.68,100,130,165134,286261727,ARL,344280537,13.11,100,1,13.74,2,1,13.03,2,1,13.75,100,1,12.98,200,2,14.08,100,1,12.86,100,1,14.22,100,1,12.73,100,1,14.27,100,1,12.71,100,1,14.43,200,2,12.5,700,1,14.46,200,2,12.46,100,1,14.48,700,1,12.43,700,1,14.49,100,1,12.42,700,1,14.53,100,1
2025-07-17T16:17:26.823771696Z,2025-07-17T16:17:26.823937553Z,160,2,1108,C,A,0,15.37,100,130,165857,286261728,ARL,344225829,13.11,100,1,13.74,2,1,13.03,2,1,13.75,100,1,12.98,200,2,14.08,100,1,12.86,100,1,14.22,100,1,12.73,100,1,14.27,100,1,12.71,100,1,14.43,200,2,12.5,700,1,14.46,200,2,12.46,100,1,14.48,700,1,12.43,700,1,14.49,100,1,12.42,700,1,14.53,100,1
2025-07-17T16:17:26.824137854Z,2025-07-17T16:17:26.824304510Z,160,2,1108,C,A,0,14.53,100,0,166656,286261743,ARL,344225385,13.11,100,1,13.74,2,1,13.03,2,1,13.75,100,1,12.98,200,2,14.08,100,1,12.86,100,1,14.22,100,1,12.73,100,1,14.27,100,1,12.71,100,1,14.43,200,2,12.5,700,1,14.46,200,2,12.46,100,1,14.48,700,1,12.43,700,1,14.49,100,1,12.42,700,1,14.54,700,1
2025-07-17T16:17:26.824137854Z,2025-07-17T16:17:26.824304510Z,160,2,1108,A,A,0,14.58,100,0,166656,286261743,ARL,344280577,13.11,100,1,13.74,2,1,13.03,2,1,13.75,100,1,12.98,200,2,14.08,100,1,12.86,100,1,14.22,100,1,12.73,100,1,14.27,100,1,12.71,100,1,14.43,200,2,12.5,700,1,14.46,200,2,12.46,100,1,14.48,700,1,12.43,700,1,14.49,100,1,12.42,700,1,14.54,700,1
2025-07-17T16:17:26.824138799Z,2025-07-17T16:17:26.824304510Z,160,2,1108,C,A,0,14.08,100,130,165711,286261744,ARL,344225397,13.11,100,1,13.74,2,1,13.03,2,1,13.75,100,1,12.98,200,2,14.22,100,1,12.86,100,1,14.27,100,1,12.73,100,1,14.43,200,2,12.71,100,1,14.46,200,2,12.5,700,1,14.48,700,1,12.46,100,1,14.49,100,1,12.43,700,1,14.54,700,1,12.42,700,1,14.56,700,1
2025-07-17T16:17:26.824492765Z,2025-07-17T16:17:26.824657956Z,160,2,1108,A,A,0,14.36,100,130,165191,286261759,ARL,344280617,13.11,100,1,13.74,2,1,13.03,2,1,13.75,100,1,12.98,200,2,14.22,100,1,12.86,100,1,14.27,100,1,12.73,100,1,14.36,100,1,12.71,100,1,14.43,200,2,12.5,700,1,14.46,200,2,12.46,100,1,14.48,700,1,12.43,700,1,14.49,100,1,12.42,700,1,14.54,700,1
2025-07-17T16:17:26.825823014Z,2025-07-17T16:17:26.825988253Z,160,2,1108,C,A,0,14.27,100,130,165239,286261769,ARL,344225453,13.11,100,1,13.74,2,1,13.03,2,1,13.75,100,1,12.98,200,2,14.22,100,1,12.86,100,1,14.36,100,1,12.73,100,1,14.43,200,2,12.71,100,1,14.46,200,2,12.5,700,1,14.48,700,1,12.46,100,1,14.49,100,1,12.43,700,1,14.54,700,1,12.42,700,1,14.56,700,1
2025-07-17T16:17:26.825885765Z,2025-07-17T16:17:26.826051208Z,160,2,1108,C,A,0,14.43,100,0,165443,286261770,ARL,344225449,13.11,100,1,13.74,2,1,13.03,2,1,13.75,100,1,12.98,200,2,14.22,100,1,12.86,100,1,14.36,100,1,12.73,100,1,14.43,100,1,12.71,100,1,14.46,200,2,12.5,700,1,14.48,700,1,12.46,100,1,14.49,100,1,12.43,700,1,14.54,700,1,12.42,700,1,14.56,700,1
2025-07-17T16:17:26.825885765Z,2025-07-17T16:17:26.826051208Z,160,2,1108,A,A,0,14.72,100,130,165443,286261770,ARL,344280641,13.11,100,1,13.74,2,1,13.03,2,1,13.75,100,1,12.98,200,2,14.22,100,1,12.86,100,1,14.36,100,1,12.73,100,1,14.43,100,1,12.71,100,1,14.46,200,2,12.5,700,1,14.48,700,1,12.46,100,1,14.49,100,1,12.43,700,1,14.54,700,1,12.42,700,1,14.56,700,1
2025-07-17T16:17:26.825993909Z,2025-07-17T16:17:26.826159189Z,160,2,1108,A,A,0,14.54,100,130,165280,286261771,ARL,344280645,13.11,100,1,13.74,2,1,13.03,2,1,13.75,100,1,12.98,200,2,14.22,100,1,12.86,100,1,14.36,100,1,12.73,100,1,14.43,100,1,12.71,100,1,14.46,200,2,12.5,700,1,14.48,700,1,12.46,100,1,14.49,100,1,12.43,700,1,14.54,800,2,12.42,700,1,14.56,700,1
2025-07-17T16:17:26.826128663Z,2025-07-17T16:17:26.826294122Z,160,2,1108,C,A,0,14.83,100,0,165459,286261775,ARL,344225405,13.11,100,1,13.74,2,1,13.03,2,1,13.75,100,1,12.98,200,2,14.22,100,1,12.86,100,1,14.36,100,1,12.73,100,1,14.43,100,1,12.71,100,1,14.46,200,2,12.5,700,1,14.48,700,1,12.46,100,1,14.49,100,1,12.43,700,1,14.54,800,2,12.42,700,1,14.56,700,1
2025-07-17T16:17:26.826128663Z,2025-07-17T16:17:26.826294122Z,160,2,1108,A,A,0,15.13,100,130,165459,286261775,ARL,344280653,13.11,100,1,13.74,2,1,13.03,2,1,13.75,100,1,12.98,200,2,14.22,100,1,12.86,100,1,14.36,100,1,12.73,100,1,14.43,100,1,12.71,100,1,14.46,200,2,12.5,700,1,14.48,700,1,12.46,100,1,14.49,100,1,12.43,700,1,14.54,800,2,12.42,700,1,14.56,700,1
2025-07-17T16:17:26.828373551Z,2025-07-17T16:17:26.828538841Z,160,2,1108,C,A,0,13.75,100,130,165290,286261785,ARL,344225533,13.11,100,1,13.74,2,1,13.03,2,1,14.22,100,1,12.98,200,2,14.36,100,1,12.86,100,1,14.43,100,1,12.73,100,1,14.46,200,2,12.71,100,1,14.48,700,1,12.5,700,1,14.49,100,1,12.46,100,1,14.54,800,2,12.43,700,1,14.56,700,1,12.42,700,1,14.58,100,1
2025-07-17T16:17:26.828423432Z,2025-07-17T16:17:26.828589142Z,160,2,1108,A,A,0,14.03,100,130,165710,286261786,ARL,344280689,13.11,100,1,13.74,2,1,13.03,2,1,14.03,100,1,12.98,200,2,14.22,100,1,12.86,100,1,14.36,100,1,12.73,100,1,14.43,100,1,12.71,100,1,14.46,200,2,12.5,700,1,14.48,700,1,12.46,100,1,14.49,100,1,12.43,700,1,14.54,800,2,12.42,700,1,14.56,700,1
2025-07-17T16:17:26.828681062Z,2025-07-17T16:17:26.828846606Z,160,2,1108,C,A,0,13.74,2,0,165544,286261788,ARL,340449865,13.11,100,1,14.03,100,1,13.03,2,1,14.22,100,1,12.98,200,2,14.36,100,1,12.86,100,1,14.43,100,1,12.73,100,1,14.46,200,2,12.71,100,1,14.48,700,1,12.5,700,1,14.49,100,1,12.46,100,1,14.54,800,2,12.43,700,1,14.56,700,1,12.42,700,1,14.58,100,1
2025-07-17T16:17:26.828681062Z,2025-07-17T16:17:26.828846606Z,160,2,1108,A,A,0,13.97,2,130,165544,286261788,ARL,344280721,13.11,100,1,13.97,2,1,13.03,2,1,14.03,100,1,12.98,200,2,14.22,100,1,12.86,100,1,14.36,100,1,12.73,100,1,14.43,100,1,12.71,100,1,14.46,200,2,12.5,700,1,14.48,700,1,12.46,100,1,14.49,100,1,12.43,700,1,14.54,800,2,12.42,700,1,14.56,700,1
2025-07-17T16:17:26.829901530Z,2025-07-17T16:17:26.830066702Z,160,2,1108,C,A,0,14.72,100,0,165172,286262023,ARL,344280641,13.11,100,1,13.97,2,1,13.03,2,1,14.03,100,1,12.98,200,2,14.22,100,1,12.86,100,1,14.36,100,1,12.73,100,1,14.43,100,1,12.71,100,1,14.46,200,2,12.5,700,1,14.48,700,1,12.46,100,1,14.49,100,1,12.43,700,1,14.54,800,2,12.42,700,1,14.56,700,1
2025-07-17T16:17:26.829901530Z,2025-07-17T16:17:26.830066702Z,160,2,1108,A,A,0,14.96,100,130,165172,286262023,ARL,344280825,13.11,100,1,13.97,2,1,13.03,2,1,14.03,100,1,12.98,200,2,14.22,100,1,12.86,100,1,14.36,100,1,12.73,100,1,14.43,100,1,12.71,100,1,14.46,200,2,12.5,700,1,14.48,700,1,12.46,100,1,14.49,100,1,12.43,700,1,14.54,800,2,12.42,700,1,14.56,700,1
2025-07-17T16:17:26.831860798Z,2025-07-17T16:17:26.832026257Z,160,2,1108,C,A,0,17.12,100,0,165459,286262118,ARL,344225457,13.11,100,1,13.97,2,1,13.03,2,1,14.03,100,1,12.98,200,2,14.22,100,1,12.86,100,1,14.36,100,1,12.73,100,1,14.43,100,1,12.71,100,1,14.46,200,2,12.5,700,1,14.48,700,1,12.46,100,1,14.49,100,1,12.43,700,1,14.54,800,2,12.42,700,1,14.56,700,1
2025-07-17T16:17:26.831860798Z,2025-07-17T16:17:26.832026257Z,160,2,1108,A,A,0,17.76,100,130,165459,286262118,ARL,344280917,13.11,100,1,13.97,2,1,13.03,2,1,14.03,100,1,12.98,200,2,14.22,100,1,12.86,100,1,14.36,100,1,12.73,100,1,14.43,100,1,12.71,100,1,14.46,200,2,12.5,700,1,14.48,700,1,12.46,100,1,14.49,100,1,12.43,700,1,14.54,800,2,12.42,700,1,14.56,700,1
2025-07-17T16:17:26.833029512Z,2025-07-17T16:17:26.833194882Z,160,2,1108,C,A,0,15.51,100,0,165370,286262137,ARL,344225393,13.11,100,1,13.97,2,1,13.03,2,1,14.03,100,1,12.98,200,2,14.22,100,1,12.86,100,1,14.36,100,1,12.73,100,1,14.43,100,1,12.71,100,1,14.46,200,2,12.5,700,1,14.48,700,1,12.46,100,1,14.49,100,1,12.43,700,1,14.54,800,2,12.42,700,1,14.56,700,1
2025-07-17T16:17:26.833029512Z,2025-07-17T16:17:26.833194882Z,160,2,1108,A,A,0,16.08,100,130,165370,286262137,ARL,344280941,13.11,100,1,13.97,2,1,13.03,2,1,14.03,100,1,12.98,200,2,14.22,100,1,12.86,100,1,14.36,100,1,12.73,100,1,14.43,100,1,12.71,100,1,14.46,200,2,12.5,700,1,14.48,700,1,12.46,100,1,14.49,100,1,12.43,700,1,14.54,800,2,12.42,700,1,14.56,700,1
2025-07-17T16:17:26.834746475Z,2025-07-17T16:17:26.834911649Z,160,2,1108,C,A,0,14.03,100,130,165174,286262165,ARL,344280689,13.11,100,1,13.97,2,1,13.03,2,1,14.22,100,1,12.98,200,2,14.36,100,1,12.86,100,1,14.43,100,1,12.73,100,1,14.46,200,2,12.71,100,1,14.48,700,1,12.5,700,1,14.49,100,1,12.46,100,1,14.54,800,2,12.43,700,1,14.56,700,1,12.42,700,1,14.58,100,1
2025-07-17T16:17:26.834796238Z,2025-07-17T16:17:26.834961494Z,160,2,1108,A,A,0,14.25,100,130,165256,286262166,ARL,344280953,13.11,100,1,13.97,2,1,13.03,2,1,14.22,100,1,12.98,200,2,14.25,100,1,12.86,100,1,14.36,100,1,12.73,100,1,14.43,100,1,12.71,100,1,14.46,200,2,12.5,700,1,14.48,700,1,12.46,100,1,14.49,100,1,12.43,700,1,14.54,800,2,12.42,700,1,14.56,700,1
2025-07-17T16:17:26.846401696Z,2025-07-17T16:17:26.846567340Z,160,2,1108,C,A,0,14.83,100,0,165644,286262231,ARL,344225485,13.11,100,1,13.97,2,1,13.03,2,1,14.22,100,1,12.98,200,2,14.25,100,1,12.86,100,1,14.36,100,1,12.73,100,1,14.43,100,1,12.71,100,1,14.46,200,2,12.5,700,1,14.48,700,1,12.46,100,1,14.49,100,1,12.43,700,1,14.54,800,2,12.42,700,1,14.56,700,1
2025-07-17T16:17:26.846401696Z,2025-07-17T16:17:26.846567340Z,160,2,1108,A,A,0,15.38,100,130,165644,286262231,ARL,344281229,13.11,100,1,13.97,2,1,13.03,2,1,14.22,100,1,12.98,200,2,14.25,100,1,12.86,100,1,14.36,100,1,12.73,100,1,14.43,100,1,12.71,100,1,14.46,200,2,12.5,700,1,14.48,700,1,12.46,100,1,14.49,100,1,12.43,700,1,14.54,800,2,12.42,700,1,14.56,700,1
2025-07-17T16:17:26.849505109Z,2025-07-17T16:17:26.849670659Z,160,2,1108,C,A,0,14.43,100,0,165550,286262262,ARL,344225489,13.11,100,1,13.97,2,1,13.03,2,1,14.22,100,1,12.98,200,2,14.25,100,1,12.86,100,1,14.36,100,1,12.73,100,1,14.46,200,2,12.71,100,1,14.48,700,1,12.5,700,1,14.49,100,1,12.46,100,1,14.54,800,2,12.43,700,1,14.56,700,1,12.42,700,1,14.58,100,1
2025-07-17T16:17:26.849505109Z,2025-07-17T16:17:26.849670659Z,160,2,1108,A,A,0,14.96,100,130,165550,286262262,ARL,344281257,13.11,100,1,13.97,2,1,13.03,2,1,14.22,100,1,12.98,200,2,14.25,100,1,12.86,100,1,14.36,100,1,12.73,100,1,14.46,200,2,12.71,100,1,14.48,700,1,12.5,700,1,14.49,100,1,12.46,100,1,14.54,800,2,12.43,700,1,14.56,700,1,12.42,700,1,14.58,100,1
2025-07-17T16:17:26.874264677Z,2025-07-17T16:17:26.874430238Z,160,2,1108,C,A,0,14.58,100,0,165561,286262413,ARL,344280577,13.11,100,1,13.97,2,1,13.03,2,1,14.22,100,1,12.98,200,2,14.25,100,1,12.86,100,1,14.36,100,1,12.73,100,1,14.46,200,2,12.71,100,1,14.48,700,1,12.5,700,1,14.49,100,1,12.46,100,1,14.54,800,2,12.43,700,1,14.56,700,1,12.42,700,1,14.68,700,1
2025-07-17T16:17:26.874264677Z,2025-07-17T16:17:26.874430238Z,160,2,1108,A,A,0,15.05,100,130,165561,286262413,ARL,344281457,13.11,100,1,13.97,2,1,13.03,2,1,14.22,100,1,12.98,200,2,14.25,100,1,12.86,100,1,14.36,100,1,12.73,100,1,14.46,200,2,12.71,100,1,14.48,700,1,12.5,700,1,14.49,100,1,12.46,100,1,14.54,800,2,12.43,700,1,14.56,700,1,12.42,700,1,14.68,700,1
2025-07-17T16:17:27.000617575Z,2025-07-17T16:17:27.000782790Z,160,2,1108,A,A,0,13.98,100,130,165215,286264622,ARL,344283633,13.11,100,1,13.97,2,1,13.03,2,1,13.98,100,1,12.98,200,2,14.22,100,1,12.86,100,1,14.25,100,1,12.73,100,1,14.36,100,1,12.71,100,1,14.46,200,2,12.5,700,1,14.48,700,1,12.46,100,1,14.49,100,1,12.43,700,1,14.54,800,2,12.42,700,1,14.56,700,1
2025-07-17T16:17:27.204728176Z,2025-07-17T16:17:27.204893988Z,160,2,1108,C,A,0,14.22,100,130,165812,286267644,ARL,339365193,13.11,100,1,13.97,2,1,13.03,2,1,13.98,100,1,12.98,200,2,14.25,100,1,12.86,100,1,14.36,100,1,12.73,100,1,14.46,200,2,12.71,100,1,14.48,700,1,12.5,700,1,14.49,100,1,12.46,100,1,14.54,800,2,12.43,700,1,14.56,700,1,12.42,700,1,14.68,700,1
2025-07-17T16:17:27.204730160Z,2025-07-17T16:17:27.204895267Z,160,2,1108,A,A,0,14.53,100,130,165107,286267645,ARL,344288585,13.11,100,1,13.97,2,1,13.03,2,1,13.98,100,1,12.98,200,2,14.25,100,1,12.86,100,1,14.36,100,1,12.73,100,1,14.46,200,2,12.71,100,1,14.48,700,1,12.5,700,1,14.49,100,1,12.46,100,1,14.53,100,1,12.43,700,1,14.54,800,2,12.42,700,1,14.56,700,1
2025-07-17T16:17:27.381626601Z,2025-07-17T16:17:27.381792167Z,160,2,1108,A,A,0,14.81,100,130,165566,286271009,ARL,344292849,13.11,100,1,13.97,2,1,13.03,2,1,13.98,100,1,12.98,200,2,14.25,100,1,12.86,100,1,14.36,100,1,12.73,100,1,14.46,200,2,12.71,100,1,14.48,700,1,12.5,700,1,14.49,100,1,12.46,100,1,14.53,100,1,12.43,700,1,14.54,800,2,12.42,700,1,14.56,700,1
2025-07-17T16:17:27.381644366Z,2025-07-17T16:17:27.381809823Z,160,2,1108,C,A,0,14.49,100,130,165457,286271010,ARL,339366385,13.11,100,1,13.97,2,1,13.03,2,1,13.98,100,1,12.98,200,2,14.25,100,1,12.86,100,1,14.36,100,1,12.73,100,1,14.46,200,2,12.71,100,1,14.48,700,1,12.5,700,1,14.53,100,1,12.46,100,1,14.54,800,2,12.43,700,1,14.56,700,1,12.42,700,1,14.68,700,1
2025-07-17T16:17:27.442997426Z,2025-07-17T16:17:27.443162448Z,160,2,1108,C,A,0,14.36,100,130,165022,286271749,ARL,344280617,13.11,100,1,13.97,2,1,13.03,2,1,13.98,100,1,12.98,200,2,14.25,100,1,12.86,100,1,14.46,200,2,12.73,100,1,14.48,700,1,12.71,100,1,14.53,100,1,12.5,700,1,14.54,800,2,12.46,100,1,14.56,700,1,12.43,700,1,14.68,700,1,12.42,700,1,14.81,100,1
2025-07-17T16:17:27.443347265Z,2025-07-17T16:17:27.443512590Z,160,2,1108,A,A,0,14.6,100,130,165325,286271751,ARL,344294245,13.11,100,1,13.97,2,1,13.03,2,1,13.98,100,1,12.98,200,2,14.25,100,1,12.86,100,1,14.46,200,2,12.73,100,1,14.48,700,1,12.71,100,1,14.53,100,1,12.5,700,1,14.54,800,2,12.46,100,1,14.56,700,1,12.43,700,1,14.6,100,1,12.42,700,1,14.68,700,1
2025-07-17T16:17:27.828890080Z,2025-07-17T16:17:27.829055288Z,160,2,1108,C,A,0,14.54,100,0,165208,286275353,ARL,344280645,13.11,100,1,13.97,2,1,13.03,2,1,13.98,100,1,12.98,200,2,14.25,100,1,12.86,100,1,14.46,200,2,12.73,100,1,14.48,700,1,12.71,100,1,14.53,100,1,12.5,700,1,14.54,700,1,12.46,100,1,14.56,700,1,12.43,700,1,14.6,100,1,12.42,700,1,14.68,700,1
2025-07-17T16:17:27.828890080Z,2025-07-17T16:17:27.829055288Z,160,2,1108,A,A,0,14.77,100,130,165208,286275353,ARL,344300085,13.11,100,1,13.97,2,1,13.03,2,1,13.98,100,1,12.98,200,2,14.25,100,1,12.86,100,1,14.46,200,2,12.73,100,1,14.48,700,1,12.71,100,1,14.53,100,1,12.5,700,1,14.54,700,1,12.46,100,1,14.56,700,1,12.43,700,1,14.6,100,1,12.42,700,1,14.68,700,1
2025-07-17T16:17:39.514525397Z,2025-07-17T16:17:39.514690751Z,160,2,1108,A,A,0,13.47,15,130,165354,286508705,ARL,344587533,13.11,100,1,13.47,15,1,13.03,2,1,13.97,2,1,12.98,200,2,13.98,100,1,12.86,100,1,14.25,100,1,12.73,100,1,14.46,200,2,12.71,100,1,14.48,700,1,12.5,700,1,14.53,100,1,12.46,100,1,14.54,700,1,12.43,700,1,14.56,700,1,12.42,700,1,14.6,100,1
2025-07-17T16:17:39.828851797Z,2025-07-17T16:17:39.829017289Z,160,2,1108,C,A,0,14.46,100,0,165492,286513833,ARL,339739285,13.11,100,1,13.47,15,1,13.03,2,1,13.97,2,1,12.98,200,2,13.98,100,1,12.86,100,1,14.25,100,1,12.73,100,1,14.46,100,1,12.71,100,1,14.48,700,1,12.5,700,1,14.53,100,1,12.46,100,1,14.54,700,1,12.43,700,1,14.56,700,1,12.42,700,1,14.6,100,1
2025-07-17T16:17:39.828851797Z,2025-07-17T16:17:39.829017289Z,160,2,1108,A,A,0,14.35,100,130,165492,286513833,ARL,344593405,13.11,100,1,13.47,15,1,13.03,2,1,13.97,2,1,12.98,200,2,13.98,100,1,12.86,100,1,14.25,100,1,12.73,100,1,14.35,100,1,12.71,100,1,14.46,100,1,12.5,700,1,14.48,700,1,12.46,100,1,14.53,100,1,12.43,700,1,14.54,700,1,12.42,700,1,14.56,700,1
2025-07-17T16:17:39.829081898Z,2025-07-17T16:17:39.829247357Z,160,2,1108,C,A,0,14.46,100,0,165459,286513835,ARL,339739297,13.11,100,1,13.47,15,1,13.03,2,1,13.97,2,1,12.98,200,2,13.98,100,1,12.86,100,1,14.25,100,1,12.73,100,1,14.35,100,1,12.71,100,1,14.48,700,1,12.5,700,1,14.53,100,1,12.46,100,1,14.54,700,1,12.43,700,1,14.56,700,1,12.42,700,1,14.6,100,1
2025-07-17T16:17:39.829081898Z,2025-07-17T16:17:39.829247357Z,160,2,1108,A,A,0,14.35,100,130,165459,286513835,ARL,344593409,13.11,100,1,13.47,15,1,13.03,2,1,13.97,2,1,12.98,200,2,13.98,100,1,12.86,100,1,14.25,100,1,12.73,100,1,14.35,200,2,12.71,100,1,14.48,700,1,12.5,700,1,14.53,100,1,12.46,100,1,14.54,700,1,12.43,700,1,14.56,700,1,12.42,700,1,14.6,100,1
2025-07-17T16:17:40.321161439Z,2025-07-17T16:17:40.321326768Z,160,2,1108,C,A,0,13.98,100,0,165329,286524785,ARL,344283633,13.11,100,1,13.47,15,1,13.03,2,1,13.97,2,1,12.98,200,2,14.25,100,1,12.86,100,1,14.35,200,2,12.73,100,1,14.48,700,1,12.71,100,1,14.53,100,1,12.5,700,1,14.54,700,1,12.46,100,1,14.56,700,1,12.43,700,1,14.6,100,1,12.42,700,1,14.68,700,1
2025-07-17T16:17:40.321161439Z,2025-07-17T16:17:40.321326768Z,160,2,1108,A,A,0,13.48,100,130,165329,286524785,ARL,344607833,13.11,100,1,13.47,15,1,13.03,2,1,13.48,100,1,12.98,200,2,13.97,2,1,12.86,100,1,14.25,100,1,12.73,100,1,14.35,200,2,12.71,100,1,14.48,700,1,12.5,700,1,14.53,100,1,12.46,100,1,14.54,700,1,12.43,700,1,14.56,700,1,12.42,700,1,14.6,100,1
2025-07-17T16:17:40.321898765Z,2025-07-17T16:17:40.322064038Z,160,2,1108,C,A,0,14.6,100,130,165273,286524815,ARL,344294245,13.11,100,1,13.47,15,1,13.03,2,1,13.48,100,1,12.98,200,2,13.97,2,1,12.86,100,1,14.25,100,1,12.73,100,1,14.35,200,2,12.71,100,1,14.48,700,1,12.5,700,1,14.53,100,1,12.46,100,1,14.54,700,1,12.43,700,1,14.56,700,1,12.42,700,1,14.68,700,1
2025-07-17T16:17:40.321903984Z,2025-07-17T16:17:40.322069742Z,160,2,1108,C,A,0,15.05,100,0,165758,286524817,ARL,344281457,13.11,100,1,13.47,15,1,13.03,2,1,13.48,100,1,12.98,200,2,13.97,2,1,12.86,100,1,14.25,100,1,12.73,100,1,14.35,200,2,12.71,100,1,14.48,700,1,12.5,700,1,14.53,100,1,12.46,100,1,14.54,700,1,12.43,700,1,14.56,700,1,12.42,700,1,14.68,700,1
2025-07-17T16:17:40.321903984Z,2025-07-17T16:17:40.322069742Z,160,2,1108,A,A,0,14.53,100,130,165758,286524817,ARL,344607889,13.11,100,1,13.47,15,1,13.03,2,1,13.48,100,1,12.98,200,2,13.97,2,1,12.86,100,1,14.25,100,1,12.73,100,1,14.35,200,2,12.71,100,1,14.48,700,1,12.5,700,1,14.53,200,2,12.46,100,1,14.54,700,1,12.43,700,1,14.56,700,1,12.42,700,1,14.68,700,1
2025-07-17T16:17:40.322250847Z,2025-07-17T16:17:40.322416015Z,160,2,1108,A,A,0,14.08,100,130,165168,286524822,ARL,344607893,13.11,100,1,13.47,15,1,13.03,2,1,13.48,100,1,12.98,200,2,13.97,2,1,12.86,100,1,14.08,100,1,12.73,100,1,14.25,100,1,12.71,100,1,14.35,200,2,12.5,700,1,14.48,700,1,12.46,100,1,14.53,200,2,12.43,700,1,14.54,700,1,12.42,700,1,14.56,700,1
2025-07-17T16:17:40.329015669Z,2025-07-17T16:17:40.329180897Z,160,2,1108,C,A,0,14.25,100,130,165228,286524967,ARL,344280953,13.11,100,1,13.47,15,1,13.03,2,1,13.48,100,1,12.98,200,2,13.97,2,1,12.86,100,1,14.08,100,1,12.73,100,1,14.35,200,2,12.71,100,1,14.48,700,1,12.5,700,1,14.53,200,2,12.46,100,1,14.54,700,1,12.43,700,1,14.56,700,1,12.42,700,1,14.68,700,1
2025-07-17T16:17:40.329067996Z,2025-07-17T16:17:40.329233157Z,160,2,1108,A,A,0,13.75,100,130,165161,286524969,ARL,344608193,13.11,100,1,13.47,15,1,13.03,2,1,13.48,100,1,12.98,200,2,13.75,100,1,12.86,100,1,13.97,2,1,12.73,100,1,14.08,100,1,12.71,100,1,14.35,200,2,12.5,700,1,14.48,700,1,12.46,100,1,14.53,200,2,12.43,700,1,14.54,700,1,12.42,700,1,14.56,700,1
2025-07-17T16:17:40.330282519Z,2025-07-17T16:17:40.330448099Z,160,2,1108,C,A,0,15.13,100,0,165580,286524982,ARL,344280653,13.11,100,1,13.47,15,1,13.03,2,1,13.48,100,1,12.98,200,2,13.75,100,1,12.86,100,1,13.97,2,1,12.73,100,1,14.08,100,1,12.71,100,1,14.35,200,2,12.5,700,1,14.48,700,1,12.46,100,1,14.53,200,2,12.43,700,1,14.54,700,1,12.42,700,1,14.56,700,1
2025-07-17T16:17:40.330282519Z,2025-07-17T16:17:40.330448099Z,160,2,1108,A,A,0,14.83,100,130,165580,286524982,ARL,344608205,13.11,100,1,13.47,15,1,13.03,2,1,13.48,100,1,12.98,200,2,13.75,100,1,12.86,100,1,13.97,2,1,12.73,100,1,14.08,100,1,12.71,100,1,14.35,200,2,12.5,700,1,14.48,700,1,12.46,100,1,14.53,200,2,12.43,700,1,14.54,700,1,12.42,700,1,14.56,700,1
2025-07-17T16:17:40.331264268Z,2025-07-17T16:17:40.331429414Z,160,2,1108,C,A,0,14.77,100,130,165146,286524998,ARL,344300085,13.11,100,1,13.47,15,1,13.03,2,1,13.48,100,1,12.98,200,2,13.75,100,1,12.86,100,1,13.97,2,1,12.73,100,1,14.08,100,1,12.71,100,1,14.35,200,2,12.5,700,1,14.48,700,1,12.46,100,1,14.53,200,2,12.43,700,1,14.54,700,1,12.42,700,1,14.56,700,1
2025-07-17T16:17:40.331386492Z,2025-07-17T16:17:40.331551656Z,160,2,1108,A,A,0,14.27,100,130,165164,286525005,ARL,344608225,13.11,100,1,13.47,15,1,13.03,2,1,13.48,100,1,12.98,200,2,13.75,100,1,12.86,100,1,13.97,2,1,12.73,100,1,14.08,100,1,12.71,100,1,14.27,100,1,12.5,700,1,14.35,200,2,12.46,100,1,14.48,700,1,12.43,700,1,14.53,200,2,12.42,700,1,14.54,700,1
2025-07-17T16:17:40.333513866Z,2025-07-17T16:17:40.333679181Z,160,2,1108,C,A,0,14.96,100,0,165315,286525029,ARL,344280825,13.11,100,1,13.47,15,1,13.03,2,1,13.48,100,1,12.98,200,2,13.75,100,1,12.86,100,1,13.97,2,1,12.73,100,1,14.08,100,1,12.71,100,1,14.27,100,1,12.5,700,1,14.35,200,2,12.46,100,1,14.48,700,1,12.43,700,1,14.53,200,2,12.42,700,1,14.54,700,1
2025-07-17T16:17:40.333513866Z,2025-07-17T16:17:40.333679181Z,160,2,1108,A,A,0,14.43,100,130,165315,286525029,ARL,344608253,13.11,100,1,13.47,15,1,13.03,2,1,13.48,100,1,12.98,200,2,13.75,100,1,12.86,100,1,13.97,2,1,12.73,100,1,14.08,100,1,12.71,100,1,14.27,100,1,12.5,700,1,14.35,200,2,12.46,100,1,14.43,100,1,12.43,700,1,14.48,700,1,12.42,700,1,14.53,200,2
2025-07-17T16:17:40.348830748Z,2025-07-17T16:17:40.348996221Z,160,2,1108,C,A,0,17.76,100,0,165473,286525170,ARL,344280917,13.11,100,1,13.47,15,1,13.03,2,1,13.48,100,1,12.98,200,2,13.75,100,1,12.86,100,1,13.97,2,1,12.73,100,1,14.08,100,1,12.71,100,1,14.27,100,1,12.5,700,1,14.35,200,2,12.46,100,1,14.43,100,1,12.43,700,1,14.48,700,1,12.42,700,1,14.53,200,2
2025-07-17T16:17:40.348830748Z,2025-07-17T16:17:40.348996221Z,160,2,1108,A,A,0,17.12,100,130,165473,286525170,ARL,344608637,13.11,100,1,13.47,15,1,13.03,2,1,13.48,100,1,12.98,200,2,13.75,100,1,12.86,100,1,13.97,2,1,12.73,100,1,14.08,100,1,12.71,100,1,14.27,100,1,12.5,700,1,14.35,200,2,12.46,100,1,14.43,100,1,12.43,700,1,14.48,700,1,12.42,700,1,14.53,200,2
2025-07-17T16:17:40.348916703Z,2025-07-17T16:17:40.349081921Z,160,2,1108,A,A,0,15.37,100,130,165218,286525175,ARL,344608641,13.11,100,1,13.47,15,1,13.03,2,1,13.48,100,1,12.98,200,2,13.75,100,1,12.86,100,1,13.97,2,1,12.73,100,1,14.08,100,1,12.71,100,1,14.27,100,1,12.5,700,1,14.35,200,2,12.46,100,1,14.43,100,1,12.43,700,1,14.48,700,1,12.42,700,1,14.53,200,2
2025-07-17T16:17:40.348930117Z,2025-07-17T16:17:40.349095477Z,160,2,1108,C,A,0,15.68,100,130,165360,286525177,ARL,344280537,13.11,100,1,13.47,15,1,13.03,2,1,13.48,100,1,12.98,200,2,13.75,100,1,12.86,100,1,13.97,2,1,12.73,100,1,14.08,100,1,12.71,100,1,14.27,100,1,12.5,700,1,14.35,200,2,12.46,100,1,14.43,100,1,12.43,700,1,14.48,700,1,12.42,700,1,14.53,200,2
2025-07-17T16:17:40.357201846Z,2025-07-17T16:17:40.357367234Z,160,2,1108,C,A,0,16.08,100,0,165388,286525428,ARL,344280941,13.11,100,1,13.47,15,1,13.03,2,1,13.48,100,1,12.98,200,2,13.75,100,1,12.86,100,1,13.97,2,1,12.73,100,1,14.08,100,1,12.71,100,1,14.27,100,1,12.5,700,1,14.35,200,2,12.46,100,1,14.43,100,1,12.43,700,1,14.48,700,1,12.42,700,1,14.53,200,2
2025-07-17T16:17:40.357201846Z,2025-07-17T16:17:40.357367234Z,160,2,1108,A,A,0,15.51,100,130,165388,286525428,ARL,344608797,13.11,100,1,13.47,15,1,13.03,2,1,13.48,100,1,12.98,200,2,13.75,100,1,12.86,100,1,13.97,2,1,12.73,100,1,14.08,100,1,12.71,100,1,14.27,100,1,12.5,700,1,14.35,200,2,12.46,100,1,14.43,100,1,12.43,700,1,14.48,700,1,12.42,700,1,14.53,200,2
2025-07-17T16:17:40.403073956Z,2025-07-17T16:17:40.403239477Z,160,2,1108,C,A,0,15.38,100,0,165521,286526316,ARL,344281229,13.11,100,1,13.47,15,1,13.03,2,1,13.48,100,1,12.98,200,2,13.75,100,1,12.86,100,1,13.97,2,1,12.73,100,1,14.08,100,1,12.71,100,1,14.27,100,1,12.5,700,1,14.35,200,2,12.46,100,1,14.43,100,1,12.43,700,1,14.48,700,1,12.42,700,1,14.53,200,2
2025-07-17T16:17:40.403073956Z,2025-07-17T16:17:40.403239477Z,160,2,1108,A,A,0,14.83,100,130,165521,286526316,ARL,344609897,13.11,100,1,13.47,15,1,13.03,2,1,13.48,100,1,12.98,200,2,13.75,100,1,12.86,100,1,13.97,2,1,12.73,100,1,14.08,100,1,12.71,100,1,14.27,100,1,12.5,700,1,14.35,200,2,12.46,100,1,14.43,100,1,12.43,700,1,14.48,700,1,12.42,700,1,14.53,200,2
2025-07-17T16:17:40.426425205Z,2025-07-17T16:17:40.426590567Z,160,2,1108,C,A,0,14.96,100,0,165362,286526540,ARL,344281257,13.11,100,1,13.47,15,1,13.03,2,1,13.48,100,1,12.98,200,2,13.75,100,1,12.86,100,1,13.97,2,1,12.73,100,1,14.08,100,1,12.71,100,1,14.27,100,1,12.5,700,1,14.35,200,2,12.46,100,1,14.43,100,1,12.43,700,1,14.48,700,1,12.42,700,1,14.53,200,2
2025-07-17T16:17:40.426425205Z,2025-07-17T16:17:40.426590567Z,160,2,1108,A,A,0,14.43,100,130,165362,286526540,ARL,344610073,13.11,100,1,13.47,15,1,13.03,2,1,13.48,100,1,12.98,200,2,13.75,100,1,12.86,100,1,13.97,2,1,12.73,100,1,14.08,100,1,12.71,100,1,14.27,100,1,12.5,700,1,14.35,200,2,12.46,100,1,14.43,200,2,12.43,700,1,14.48,700,1,12.42,700,1,14.53,200,2
2025-07-17T16:17:40.474675991Z,2025-07-17T16:17:40.474841118Z,160,2,1108,A,A,0,14.01,100,130,165127,286527611,ARL,344612049,13.11,100,1,13.47,15,1,13.03,2,1,13.48,100,1,12.98,200,2,13.75,100,1,12.86,100,1,13.97,2,1,12.73,100,1,14.01,100,1,12.71,100,1,14.08,100,1,12.5,700,1,14.27,100,1,12.46,100,1,14.35,200,2,12.43,700,1,14.43,200,2,12.42,700,1,14.48,700,1
2025-07-17T16:17:40.474677082Z,2025-07-17T16:17:40.474842468Z,160,2,1108,C,A,0,14.53,100,130,165386,286527612,ARL,344288585,13.11,100,1,13.47,15,1,13.03,2,1,13.48,100,1,12.98,200,2,13.75,100,1,12.86,100,1,13.97,2,1,12.73,100,1,14.01,100,1,12.71,100,1,14.08,100,1,12.5,700,1,14.27,100,1,12.46,100,1,14.35,200,2,12.43,700,1,14.43,200,2,12.42,700,1,14.48,700,1
2025-07-17T16:17:40.697555911Z,2025-07-17T16:17:40.697721205Z,160,2,1108,A,A,0,14.28,100,130,165294,286530329,ARL,344615393,13.11,100,1,13.47,15,1,13.03,2,1,13.48,100,1,12.98,200,2,13.75,100,1,12.86,100,1,13.97,2,1,12.73,100,1,14.01,100,1,12.71,100,1,14.08,100,1,12.5,700,1,14.27,100,1,12.46,100,1,14.28,100,1,12.43,700,1,14.35,200,2,12.42,700,1,14.43,200,2
2025-07-17T16:17:40.697568713Z,2025-07-17T16:17:40.697733924Z,160,2,1108,C,A,0,14.81,100,130,165211,286530330,ARL,344292849,13.11,100,1,13.47,15,1,13.03,2,1,13.48,100,1,12.98,200,2,13.75,100,1,12.86,100,1,13.97,2,1,12.73,100,1,14.01,100,1,12.71,100,1,14.08,100,1,12.5,700,1,14.27,100,1,12.46,100,1,14.28,100,1,12.43,700,1,14.35,200,2,12.42,700,1,14.43,200,2
2025-07-17T16:17:41.585985709Z,2025-07-17T16:17:41.586151161Z,160,2,1108,C,A,0,13.97,2,0,165452,286543225,ARL,344280721,13.11,100,1,13.47,15,1,13.03,2,1,13.48,100,1,12.98,200,2,13.75,100,1,12.86,100,1,14.01,100,1,12.73,100,1,14.08,100,1,12.71,100,1,14.27,100,1,12.5,700,1,14.28,100,1,12.46,100,1,14.35,200,2,12.43,700,1,14.43,200,2,12.42,700,1,14.48,700,1
2025-07-17T16:17:41.585985709Z,2025-07-17T16:17:41.586151161Z,160,2,1108,A,A,0,13.87,2,130,165452,286543225,ARL,344631921,13.11,100,1,13.47,15,1,13.03,2,1,13.48,100,1,12.98,200,2,13.75,100,1,12.86,100,1,13.87,2,1,12.73,100,1,14.01,100,1,12.71,100,1,14.08,100,1,12.5,700,1,14.27,100,1,12.46,100,1,14.28,100,1,12.43,700,1,14.35,200,2,12.42,700,1,14.43,200,2
2025-07-17T16:17:42.552968542Z,2025-07-17T16:17:42.553133650Z,160,2,1108,A,A,0,13.45,15,130,165108,286561347,ARL,344653009,13.11,100,1,13.45,15,1,13.03,2,1,13.47,15,1,12.98,200,2,13.48,100,1,12.86,100,1,13.75,100,1,12.73,100,1,13.87,2,1,12.71,100,1,14.01,100,1,12.5,700,1,14.08,100,1,12.46,100,1,14.27,100,1,12.43,700,1,14.28,100,1,12.42,700,1,14.35,200,2
2025-07-17T16:17:44.014448587Z,2025-07-17T16:17:44.014614049Z,160,2,1108,C,A,0,13.48,100,0,165462,286577648,ARL,344607833,13.11,100,1,13.45,15,1,13.03,2,1,13.47,15,1,12.98,200,2,13.75,100,1,12.86,100,1,13.87,2,1,12.73,100,1,14.01,100,1,12.71,100,1,14.08,100,1,12.5,700,1,14.27,100,1,12.46,100,1,14.28,100,1,12.43,700,1,14.35,200,2,12.42,700,1,14.43,200,2
2025-07-17T16:17:44.014448587Z,2025-07-17T16:17:44.014614049Z,160,2,1108,A,A,0,13.46,100,130,165462,286577648,ARL,344673481,13.11,100,1,13.45,15,1,13.03,2,1,13.46,100,1,12.98,200,2,13.47,15,1,12.86,100,1,13.75,100,1,12.73,100,1,13.87,2,1,12.71,100,1,14.01,100,1,12.5,700,1,14.08,100,1,12.46,100,1,14.27,100,1,12.43,700,1,14.28,100,1,12.42,700,1,14.35,200,2
2025-07-17T16:17:44.014812396Z,2025-07-17T16:17:44.014977545Z,160,2,1108,A,A,0,15.68,100,130,165149,286577651,ARL,344673501,13.11,100,1,13.45,15,1,13.03,2,1,13.46,100,1,12.98,200,2,13.47,15,1,12.86,100,1,13.75,100,1,12.73,100,1,13.87,2,1,12.71,100,1,14.01,100,1,12.5,700,1,14.08,100,1,12.46,100,1,14.27,100,1,12.43,700,1,14.28,100,1,12.42,700,1,14.35,200,2
2025-07-17T16:17:44.014825581Z,2025-07-17T16:17:44.014991037Z,160,2,1108,C,A,0,15.37,100,130,165456,286577652,ARL,344608641,13.11,100,1,13.45,15,1,13.03,2,1,13.46,100,1,12.98,200,2,13.47,15,1,12.86,100,1,13.75,100,1,12.73,100,1,13.87,2,1,12.71,100,1,14.01,100,1,12.5,700,1,14.08,100,1,12.46,100,1,14.27,100,1,12.43,700,1,14.28,100,1,12.42,700,1,14.35,200,2
2025-07-17T16:17:44.042811526Z,2025-07-17T16:17:44.042976984Z,160,2,1108,A,A,0,15.35,100,130,165458,286578356,ARL,344674517,13.11,100,1,13.45,15,1,13.03,2,1,13.46,100,1,12.98,200,2,13.47,15,1,12.86,100,1,13.75,100,1,12.73,100,1,13.87,2,1,12.71,100,1,14.01,100,1,12.5,700,1,14.08,100,1,12.46,100,1,14.27,100,1,12.43,700,1,14.28,100,1,12.42,700,1,14.35,200,2
2025-07-17T16:17:44.042824242Z,2025-07-17T16:17:44.042989197Z,160,2,1108,C,A,0,15.68,100,130,164955,286578357,ARL,344673501,13.11,100,1,13.45,15,1,13.03,2,1,13.46,100,1,12.98,200,2,13.47,15,1,12.86,100,1,13.75,100,1,12.73,100,1,13.87,2,1,12.71,100,1,14.01,100,1,12.5,700,1,14.08,100,1,12.46,100,1,14.27,100,1,12.43,700,1,14.28,100,1,12.42,700,1,14.35,200,2
2025-07-17T16:17:46.828095134Z,2025-07-17T16:17:46.828260391Z,160,2,1108,A,A,0,14.18,700,130,165257,286618024,ARL,344724301,13.11,100,1,13.45,15,1,13.03,2,1,13.46,100,1,12.98,200,2,13.47,15,1,12.86,100,1,13.75,100,1,12.73,100,1,13.87,2,1,12.71,100,1,14.01,100,1,12.5,700,1,14.08,100,1,12.46,100,1,14.18,700,1,12.43,700,1,14.27,100,1,12.42,700,1,14.28,100,1
2025-07-17T16:17:46.828160338Z,2025-07-17T16:17:46.828325564Z,160,2,1108,C,A,0,14.68,700,130,165226,286618025,ARL,341663105,13.11,100,1,13.45,15,1,13.03,2,1,13.46,100,1,12.98,200,2,13.47,15,1,12.86,100,1,13.75,100,1,12.73,100,1,13.87,2,1,12.71,100,1,14.01,100,1,12.5,700,1,14.08,100,1,12.46,100,1,14.18,700,1,12.43,700,1,14.27,100,1,12.42,700,1,14.28,100,1
2025-07-17T16:17:49.387365405Z,2025-07-17T16:17:49.387530942Z,160,2,1108,C,A,0,13.87,2,0,165537,286651544,ARL,344631921,13.11,100,1,13.45,15,1,13.03,2,1,13.46,100,1,12.98,200,2,13.47,15,1,12.86,100,1,13.75,100,1,12.73,100,1,14.01,100,1,12.71,100,1,14.08,100,1,12.5,700,1,14.18,700,1,12.46,100,1,14.27,100,1,12.43,700,1,14.28,100,1,12.42,700,1,14.35,200,2
2025-07-17T16:17:49.387365405Z,2025-07-17T16:17:49.387530942Z,160,2,1108,A,A,0,13.79,2,130,165537,286651544,ARL,344765077,13.11,100,1,13.45,15,1,13.03,2,1,13.46,100,1,12.98,200,2,13.47,15,1,12.86,100,1,13.75,100,1,12.73,100,1,13.79,2,1,12.71,100,1,14.01,100,1,12.5,700,1,14.08,100,1,12.46,100,1,14.18,700,1,12.43,700,1,14.27,100,1,12.42,700,1,14.28,100,1
2025-07-17T16:17:52.834008196Z,2025-07-17T16:17:52.834173973Z,160,2,1108,C,A,0,13.47,15,130,165777,286689853,ARL,344587533,13.11,100,1,13.45,15,1,13.03,2,1,13.46,100,1,12.98,200,2,13.75,100,1,12.86,100,1,13.79,2,1,12.73,100,1,14.01,100,1,12.71,100,1,14.08,100,1,12.5,700,1,14.18,700,1,12.46,100,1,14.27,100,1,12.43,700,1,14.28,100,1,12.42,700,1,14.35,200,2
2025-07-17T16:17:58.033161898Z,2025-07-17T16:17:58.033327053Z,160,2,1108,C,A,0,13.45,15,130,165155,286753046,ARL,344653009,13.11,100,1,13.46,100,1,13.03,2,1,13.75,100,1,12.98,200,2,13.79,2,1,12.86,100,1,14.01,100,1,12.73,100,1,14.08,100,1,12.71,100,1,14.18,700,1,12.5,700,1,14.27,100,1,12.46,100,1,14.28,100,1,12.43,700,1,14.35,200,2,12.42,700,1,14.43,200,2
2025-07-17T16:17:58.036423237Z,2025-07-17T16:17:58.036588469Z,160,2,1108,C,A,0,13.46,100,130,165232,286753126,ARL,344673481,13.11,100,1,13.75,100,1,13.03,2,1,13.79,2,1,12.98,200,2,14.01,100,1,12.86,100,1,14.08,100,1,12.73,100,1,14.18,700,1,12.71,100,1,14.27,100,1,12.5,700,1,14.28,100,1,12.46,100,1,14.35,200,2,12.43,700,1,14.43,200,2,12.42,700,1,14.48,700,1
2025-07-17T16:17:58.036696806Z,2025-07-17T16:17:58.036861922Z,160,2,1108,C,A,0,14.18,700,130,165116,286753127,ARL,344724301,13.11,100,1,13.75,100,1,13.03,2,1,13.79,2,1,12.98,200,2,14.01,100,1,12.86,100,1,14.08,100,1,12.73,100,1,14.27,100,1,12.71,100,1,14.28,100,1,12.5,700,1,14.35,200,2,12.46,100,1,14.43,200,2,12.43,700,1,14.48,700,1,12.42,700,1,14.53,100,1
2025-07-17T16:17:58.036748831Z,2025-07-17T16:17:58.036914002Z,160,2,1108,A,A,0,14.44,700,130,165171,286753128,ARL,344897921,13.11,100,1,13.75,100,1,13.03,2,1,13.79,2,1,12.98,200,2,14.01,100,1,12.86,100,1,14.08,100,1,12.73,100,1,14.27,100,1,12.71,100,1,14.28,100,1,12.5,700,1,14.35,200,2,12.46,100,1,14.43,200,2,12.43,700,1,14.44,700,1,12.42,700,1,14.48,700,1
2025-07-17T16:17:58.036806229Z,2025-07-17T16:17:58.036971455Z,160,2,1108,A,A,0,15.68,100,130,165226,286753129,ARL,344897933,13.11,100,1,13.75,100,1,13.03,2,1,13.79,2,1,12.98,200,2,14.01,100,1,12.86,100,1,14.08,100,1,12.73,100,1,14.27,100,1,12.71,100,1,14.28,100,1,12.5,700,1,14.35,200,2,12.46,100,1,14.43,200,2,12.43,700,1,14.44,700,1,12.42,700,1,14.48,700,1
2025-07-17T16:17:58.036818196Z,2025-07-17T16:17:58.036983460Z,160,2,1108,C,A,0,15.35,100,130,165264,286753132,ARL,344674517,13.11,100,1,13.75,100,1,13.03,2,1,13.79,2,1,12.98,200,2,14.01,100,1,12.86,100,1,14.08,100,1,12.73,100,1,14.27,100,1,12.71,100,1,14.28,100,1,12.5,700,1,14.35,200,2,12.46,100,1,14.43,200,2,12.43,700,1,14.44,700,1,12.42,700,1,14.48,700,1
2025-07-17T16:17:58.037160197Z,2025-07-17T16:17:58.037325671Z,160,2,1108,C,A,0,14.53,100,0,165474,286753136,ARL,344607889,13.11,100,1,13.75,100,1,13.03,2,1,13.79,2,1,12.98,200,2,14.01,100,1,12.86,100,1,14.08,100,1,12.73,100,1,14.27,100,1,12.71,100,1,14.28,100,1,12.5,700,1,14.35,200,2,12.46,100,1,14.43,200,2,12.43,700,1,14.44,700,1,12.42,700,1,14.48,700,1
2025-07-17T16:17:58.037160197Z,2025-07-17T16:17:58.037325671Z,160,2,1108,A,A,0,14.82,100,130,165474,286753136,ARL,344897945,13.11,100,1,13.75,100,1,13.03,2,1,13.79,2,1,12.98,200,2,14.01,100,1,12.86,100,1,14.08,100,1,12.73,100,1,14.27,100,1,12.71,100,1,14.28,100,1,12.5,700,1,14.35,200,2,12.46,100,1,14.43,200,2,12.43,700,1,14.44,700,1,12.42,700,1,14.48,700,1
2025-07-17T16:17:58.037165870Z,2025-07-17T16:17:58.037330946Z,160,2,1108,C,A,0,14.08,100,130,165076,286753137,ARL,344607893,13.11,100,1,13.75,100,1,13.03,2,1,13.79,2,1,12.98,200,2,14.01,100,1,12.86,100,1,14.27,100,1,12.73,100,1,14.28,100,1,12.71,100,1,14.35,200,2,12.5,700,1,14.43,200,2,12.46,100,1,14.44,700,1,12.43,700,1,14.48,700,1,12.42,700,1,14.54,700,1
2025-07-17T16:17:58.037521442Z,2025-07-17T16:17:58.037686676Z,160,2,1108,A,A,0,14.36,100,130,165234,286753149,ARL,344897953,13.11,100,1,13.75,100,1,13.03,2,1,13.79,2,1,12.98,200,2,14.01,100,1,12.86,100,1,14.27,100,1,12.73,100,1,14.28,100,1,12.71,100,1,14.35,200,2,12.5,700,1,14.36,100,1,12.46,100,1,14.43,200,2,12.43,700,1,14.44,700,1,12.42,700,1,14.48,700,1
2025-07-17T16:17:58.038594284Z,2025-07-17T16:17:58.038759735Z,160,2,1108,C,A,0,14.43,100,0,165451,286753168,ARL,344608253,13.11,100,1,13.75,100,1,13.03,2,1,13.79,2,1,12.98,200,2,14.01,100,1,12.86,100,1,14.27,100,1,12.73,100,1,14.28,100,1,12.71,100,1,14.35,200,2,12.5,700,1,14.36,100,1,12.46,100,1,14.43,100,1,12.43,700,1,14.44,700,1,12.42,700,1,14.48,700,1
2025-07-17T16:17:58.038594284Z,2025-07-17T16:17:58.038759735Z,160,2,1108,A,A,0,14.72,100,130,165451,286753168,ARL,344897989,13.11,100,1,13.75,100,1,13.03,2,1,13.79,2,1,12.98,200,2,14.01,100,1,12.86,100,1,14.27,100,1,12.73,100,1,14.28,100,1,12.71,100,1,14.35,200,2,12.5,700,1,14.36,100,1,12.46,100,1,14.43,100,1,12.43,700,1,14.44,700,1,12.42,700,1,14.48,700,1
2025-07-17T16:17:58.039215838Z,2025-07-17T16:17:58.039381900Z,160,2,1108,C,A,0,14.83,100,0,166062,286753172,ARL,344608205,13.11,100,1,13.75,100,1,13.03,2,1,13.79,2,1,12.98,200,2,14.01,100,1,12.86,100,1,14.27,100,1,12.73,100,1,14.28,100,1,12.71,100,1,14.35,200,2,12.5,700,1,14.36,100,1,12.46,100,1,14.43,100,1,12.43,700,1,14.44,700,1,12.42,700,1,14.48,700,1
2025-07-17T16:17:58.039215838Z,2025-07-17T16:17:58.039381900Z,160,2,1108,A,A,0,15.13,100,130,166062,286753172,ARL,344897997,13.11,100,1,13.75,100,1,13.03,2,1,13.79,2,1,12.98,200,2,14.01,100,1,12.86,100,1,14.27,100,1,12.73,100,1,14.28,100,1,12.71,100,1,14.35,200,2,12.5,700,1,14.36,100,1,12.46,100,1,14.43,100,1,12.43,700,1,14.44,700,1,12.42,700,1,14.48,700,1
2025-07-17T16:17:58.047696769Z,2025-07-17T16:17:58.047862207Z,160,2,1108,C,A,0,17.12,100,0,165438,286753519,ARL,344608637,13.11,100,1,13.75,100,1,13.03,2,1,13.79,2,1,12.98,200,2,14.01,100,1,12.86,100,1,14.27,100,1,12.73,100,1,14.28,100,1,12.71,100,1,14.35,200,2,12.5,700,1,14.36,100,1,12.46,100,1,14.43,100,1,12.43,700,1,14.44,700,1,12.42,700,1,14.48,700,1
2025-07-17T16:17:58.047696769Z,2025-07-17T16:17:58.047862207Z,160,2,1108,A,A,0,17.47,100,130,165438,286753519,ARL,344898485,13.11,100,1,13.75,100,1,13.03,2,1,13.79,2,1,12.98,200,2,14.01,100,1,12.86,100,1,14.27,100,1,12.73,100,1,14.28,100,1,12.71,100,1,14.35,200,2,12.5,700,1,14.36,100,1,12.46,100,1,14.43,100,1,12.43,700,1,14.44,700,1,12.42,700,1,14.48,700,1
2025-07-17T16:17:58.051466948Z,2025-07-17T16:17:58.051632876Z,160,2,1108,C,A,0,15.51,100,0,165928,286753581,ARL,344608797,13.11,100,1,13.75,100,1,13.03,2,1,13.79,2,1,12.98,200,2,14.01,100,1,12.86,100,1,14.27,100,1,12.73,100,1,14.28,100,1,12.71,100,1,14.35,200,2,12.5,700,1,14.36,100,1,12.46,100,1,14.43,100,1,12.43,700,1,14.44,700,1,12.42,700,1,14.48,700,1
2025-07-17T16:17:58.051466948Z,2025-07-17T16:17:58.051632876Z,160,2,1108,A,A,0,15.82,100,130,165928,286753581,ARL,344898677,13.11,100,1,13.75,100,1,13.03,2,1,13.79,2,1,12.98,200,2,14.01,100,1,12.86,100,1,14.27,100,1,12.73,100,1,14.28,100,1,12.71,100,1,14.35,200,2,12.5,700,1,14.36,100,1,12.46,100,1,14.43,100,1,12.43,700,1,14.44,700,1,12.42,700,1,14.48,700,1
2025-07-17T16:17:58.053883828Z,2025-07-17T16:17:58.054049362Z,160,2,1108,C,A,0,13.75,100,130,165534,286753747,ARL,344608193,13.11,100,1,13.79,2,1,13.03,2,1,14.01,100,1,12.98,200,2,14.27,100,1,12.86,100,1,14.28,100,1,12.73,100,1,14.35,200,2,12.71,100,1,14.36,100,1,12.5,700,1,14.43,100,1,12.46,100,1,14.44,700,1,12.43,700,1,14.48,700,1,12.42,700,1,14.54,700,1
2025-07-17T16:17:58.053934652Z,2025-07-17T16:17:58.054100805Z,160,2,1108,C,A,0,14.44,700,130,166153,286753751,ARL,344897921,13.11,100,1,13.79,2,1,13.03,2,1,14.01,100,1,12.98,200,2,14.27,100,1,12.86,100,1,14.28,100,1,12.73,100,1,14.35,200,2,12.71,100,1,14.36,100,1,12.5,700,1,14.43,100,1,12.46,100,1,14.48,700,1,12.43,700,1,14.54,700,1,12.42,700,1,14.56,700,1
2025-07-17T16:17:58.053935872Z,2025-07-17T16:17:58.054101429Z,160,2,1108,A,A,0,14.03,100,130,165557,286753752,ARL,344898949,13.11,100,1,13.79,2,1,13.03,2,1,14.01,100,1,12.98,200,2,14.03,100,1,12.86,100,1,14.27,100,1,12.73,100,1,14.28,100,1,12.71,100,1,14.35,200,2,12.5,700,1,14.36,100,1,12.46,100,1,14.43,100,1,12.43,700,1,14.48,700,1,12.42,700,1,14.54,700,1
2025-07-17T16:17:58.056799769Z,2025-07-17T16:17:58.056965001Z,160,2,1108,C,A,0,14.72,100,0,165232,286753926,ARL,344897989,13.11,100,1,13.79,2,1,13.03,2,1,14.01,100,1,12.98,200,2,14.03,100,1,12.86,100,1,14.27,100,1,12.73,100,1,14.28,100,1,12.71,100,1,14.35,200,2,12.5,700,1,14.36,100,1,12.46,100,1,14.43,100,1,12.43,700,1,14.48,700,1,12.42,700,1,14.54,700,1
2025-07-17T16:17:58.056799769Z,2025-07-17T16:17:58.056965001Z,160,2,1108,A,A,0,14.96,100,130,165232,286753926,ARL,344899081,13.11,100,1,13.79,2,1,13.03,2,1,14.01,100,1,12.98,200,2,14.03,100,1,12.86,100,1,14.27,100,1,12.73,100,1,14.28,100,1,12.71,100,1,14.35,200,2,12.5,700,1,14.36,100,1,12.46,100,1,14.43,100,1,12.43,700,1,14.48,700,1,12.42,700,1,14.54,700,1
2025-07-17T16:17:58.057644161Z,2025-07-17T16:17:58.057809322Z,160,2,1108,C,A,0,15.82,100,0,165161,286753935,ARL,344898677,13.11,100,1,13.79,2,1,13.03,2,1,14.01,100,1,12.98,200,2,14.03,100,1,12.86,100,1,14.27,100,1,12.73,100,1,14.28,100,1,12.71,100,1,14.35,200,2,12.5,700,1,14.36,100,1,12.46,100,1,14.43,100,1,12.43,700,1,14.48,700,1,12.42,700,1,14.54,700,1
2025-07-17T16:17:58.057644161Z,2025-07-17T16:17:58.057809322Z,160,2,1108,A,A,0,16.08,100,130,165161,286753935,ARL,344899093,13.11,100,1,13.79,2,1,13.03,2,1,14.01,100,1,12.98,200,2,14.03,100,1,12.86,100,1,14.27,100,1,12.73,100,1,14.28,100,1,12.71,100,1,14.35,200,2,12.5,700,1,14.36,100,1,12.46,100,1,14.43,100,1,12.43,700,1,14.48,700,1,12.42,700,1,14.54,700,1
2025-07-17T16:17:58.061505885Z,2025-07-17T16:17:58.061670860Z,160,2,1108,C,A,0,14.03,100,130,164975,286754272,ARL,344898949,13.11,100,1,13.79,2,1,13.03,2,1,14.01,100,1,12.98,200,2,14.27,100,1,12.86,100,1,14.28,100,1,12.73,100,1,14.35,200,2,12.71,100,1,14.36,100,1,12.5,700,1,14.43,100,1,12.46,100,1,14.48,700,1,12.43,700,1,14.54,700,1,12.42,700,1,14.56,700,1
2025-07-17T16:17:58.061563628Z,2025-07-17T16:17:58.061730836Z,160,2,1108,A,A,0,14.25,100,130,167208,286754286,ARL,344899417,13.11,100,1,13.79,2,1,13.03,2,1,14.01,100,1,12.98,200,2,14.25,100,1,12.86,100,1,14.27,100,1,12.73,100,1,14.28,100,1,12.71,100,1,14.35,200,2,12.5,700,1,14.36,100,1,12.46,100,1,14.43,100,1,12.43,700,1,14.48,700,1,12.42,700,1,14.54,700,1
2025-07-17T16:17:58.061971960Z,2025-07-17T16:17:58.062137122Z,160,2,1108,C,A,0,17.47,100,0,165162,286754339,ARL,344898485,13.11,100,1,13.79,2,1,13.03,2,1,14.01,100,1,12.98,200,2,14.25,100,1,12.86,100,1,14.27,100,1,12.73,100,1,14.28,100,1,12.71,100,1,14.35,200,2,12.5,700,1,14.36,100,1,12.46,100,1,14.43,100,1,12.43,700,1,14.48,700,1,12.42,700,1,14.54,700,1
2025-07-17T16:17:58.061971960Z,2025-07-17T16:17:58.062137122Z,160,2,1108,A,A,0,17.76,100,130,165162,286754339,ARL,344899449,13.11,100,1,13.79,2,1,13.03,2,1,14.01,100,1,12.98,200,2,14.25,100,1,12.86,100,1,14.27,100,1,12.73,100,1,14.28,100,1,12.71,100,1,14.35,200,2,12.5,700,1,14.36,100,1,12.46,100,1,14.43,100,1,12.43,700,1,14.48,700,1,12.42,700,1,14.54,700,1
2025-07-17T16:17:58.086415950Z,2025-07-17T16:17:58.086582033Z,160,2,1108,C,A,0,14.27,100,0,166083,286754819,ARL,344608225,13.11,100,1,13.79,2,1,13.03,2,1,14.01,100,1,12.98,200,2,14.25,100,1,12.86,100,1,14.28,100,1,12.73,100,1,14.35,200,2,12.71,100,1,14.36,100,1,12.5,700,1,14.43,100,1,12.46,100,1,14.48,700,1,12.43,700,1,14.54,700,1,12.42,700,1,14.56,700,1
2025-07-17T16:17:58.086415950Z,2025-07-17T16:17:58.086582033Z,160,2,1108,A,A,0,14.54,100,130,166083,286754819,ARL,344899913,13.11,100,1,13.79,2,1,13.03,2,1,14.01,100,1,12.98,200,2,14.25,100,1,12.86,100,1,14.28,100,1,12.73,100,1,14.35,200,2,12.71,100,1,14.36,100,1,12.5,700,1,14.43,100,1,12.46,100,1,14.48,700,1,12.43,700,1,14.54,800,2,12.42,700,1,14.56,700,1
2025-07-17T16:17:58.087663773Z,2025-07-17T16:17:58.087829372Z,160,2,1108,C,A,0,14.82,100,0,165599,286754826,ARL,344897945,13.11,100,1,13.79,2,1,13.03,2,1,14.01,100,1,12.98,200,2,14.25,100,1,12.86,100,1,14.28,100,1,12.73,100,1,14.35,200,2,12.71,100,1,14.36,100,1,12.5,700,1,14.43,100,1,12.46,100,1,14.48,700,1,12.43,700,1,14.54,800,2,12.42,700,1,14.56,700,1
2025-07-17T16:17:58.087663773Z,2025-07-17T16:17:58.087829372Z,160,2,1108,A,A,0,15.05,100,130,165599,286754826,ARL,344899937,13.11,100,1,13.79,2,1,13.03,2,1,14.01,100,1,12.98,200,2,14.25,100,1,12.86,100,1,14.28,100,1,12.73,100,1,14.35,200,2,12.71,100,1,14.36,100,1,12.5,700,1,14.43,100,1,12.46,100,1,14.48,700,1,12.43,700,1,14.54,800,2,12.42,700,1,14.56,700,1
2025-07-17T16:17:58.113216665Z,2025-07-17T16:17:58.113382320Z,160,2,1108,C,A,0,14.83,100,0,165655,286755076,ARL,344609897,13.11,100,1,13.79,2,1,13.03,2,1,14.01,100,1,12.98,200,2,14.25,100,1,12.86,100,1,14.28,100,1,12.73,100,1,14.35,200,2,12.71,100,1,14.36,100,1,12.5,700,1,14.43,100,1,12.46,100,1,14.48,700,1,12.43,700,1,14.54,800,2,12.42,700,1,14.56,700,1
2025-07-17T16:17:58.113216665Z,2025-07-17T16:17:58.113382320Z,160,2,1108,A,A,0,15.38,100,130,165655,286755076,ARL,344900289,13.11,100,1,13.79,2,1,13.03,2,1,14.01,100,1,12.98,200,2,14.25,100,1,12.86,100,1,14.28,100,1,12.73,100,1,14.35,200,2,12.71,100,1,14.36,100,1,12.5,700,1,14.43,100,1,12.46,100,1,14.48,700,1,12.43,700,1,14.54,800,2,12.42,700,1,14.56,700,1
2025-07-17T16:17:58.145382853Z,2025-07-17T16:17:58.145548497Z,160,2,1108,C,A,0,14.43,100,0,165644,286755340,ARL,344610073,13.11,100,1,13.79,2,1,13.03,2,1,14.01,100,1,12.98,200,2,14.25,100,1,12.86,100,1,14.28,100,1,12.73,100,1,14.35,200,2,12.71,100,1,14.36,100,1,12.5,700,1,14.48,700,1,12.46,100,1,14.54,800,2,12.43,700,1,14.56,700,1,12.42,700,1,14.96,100,1
2025-07-17T16:17:58.145382853Z,2025-07-17T16:17:58.145548497Z,160,2,1108,A,A,0,14.96,100,130,165644,286755340,ARL,344900597,13.11,100,1,13.79,2,1,13.03,2,1,14.01,100,1,12.98,200,2,14.25,100,1,12.86,100,1,14.28,100,1,12.73,100,1,14.35,200,2,12.71,100,1,14.36,100,1,12.5,700,1,14.48,700,1,12.46,100,1,14.54,800,2,12.43,700,1,14.56,700,1,12.42,700,1,14.96,200,2
2025-07-17T16:17:58.173665745Z,2025-07-17T16:17:58.173831273Z,160,2,1108,A,A,0,14.81,100,130,165528,286755602,ARL,344900925,13.11,100,1,13.79,2,1,13.03,2,1,14.01,100,1,12.98,200,2,14.25,100,1,12.86,100,1,14.28,100,1,12.73,100,1,14.35,200,2,12.71,100,1,14.36,100,1,12.5,700,1,14.48,700,1,12.46,100,1,14.54,800,2,12.43,700,1,14.56,700,1,12.42,700,1,14.81,100,1
2025-07-17T16:17:58.173687330Z,2025-07-17T16:17:58.173852767Z,160,2,1108,C,A,0,14.28,100,130,165437,286755603,ARL,344615393,13.11,100,1,13.79,2,1,13.03,2,1,14.01,100,1,12.98,200,2,14.25,100,1,12.86,100,1,14.35,200,2,12.73,100,1,14.36,100,1,12.71,100,1,14.48,700,1,12.5,700,1,14.54,800,2,12.46,100,1,14.56,700,1,12.43,700,1,14.81,100,1,12.42,700,1,14.96,200,2
2025-07-17T16:17:58.235623452Z,2025-07-17T16:17:58.235788576Z,160,2,1108,A,A,0,14.68,700,130,165124,286756143,ARL,344902153,13.11,100,1,13.79,2,1,13.03,2,1,14.01,100,1,12.98,200,2,14.25,100,1,12.86,100,1,14.35,200,2,12.73,100,1,14.36,100,1,12.71,100,1,14.48,700,1,12.5,700,1,14.54,800,2,12.46,100,1,14.56,700,1,12.43,700,1,14.68,700,1,12.42,700,1,14.81,100,1
2025-07-17T16:17:58.502691073Z,2025-07-17T16:17:58.502856372Z,160,2,1108,A,A,0,14.53,100,130,165299,286758830,ARL,344905321,13.11,100,1,13.79,2,1,13.03,2,1,14.01,100,1,12.98,200,2,14.25,100,1,12.86,100,1,14.35,200,2,12.73,100,1,14.36,100,1,12.71,100,1,14.48,700,1,12.5,700,1,14.53,100,1,12.46,100,1,14.54,800,2,12.43,700,1,14.56,700,1,12.42,700,1,14.68,700,1
2025-07-17T16:17:58.502692641Z,2025-07-17T16:17:58.502858100Z,160,2,1108,C,A,0,14.01,100,130,165459,286758831,ARL,344612049,13.11,100,1,13.79,2,1,13.03,2,1,14.25,100,1,12.98,200,2,14.35,200,2,12.86,100,1,14.36,100,1,12.73,100,1,14.48,700,1,12.71,100,1,14.53,100,1,12.5,700,1,14.54,800,2,12.46,100,1,14.56,700,1,12.43,700,1,14.68,700,1,12.42,700,1,14.81,100,1
2025-07-17T16:17:58.704699676Z,2025-07-17T16:17:58.704865076Z,160,2,1108,C,A,0,14.36,100,130,165400,286760091,ARL,344897953,13.11,100,1,13.79,2,1,13.03,2,1,14.25,100,1,12.98,200,2,14.35,200,2,12.86,100,1,14.48,700,1,12.73,100,1,14.53,100,1,12.71,100,1,14.54,800,2,12.5,700,1,14.56,700,1,12.46,100,1,14.68,700,1,12.43,700,1,14.81,100,1,12.42,700,1,14.96,200,2
2025-07-17T16:17:58.705051532Z,2025-07-17T16:17:58.705216838Z,160,2,1108,A,A,0,14.6,100,130,165306,286760096,ARL,344906945,13.11,100,1,13.79,2,1,13.03,2,1,14.25,100,1,12.98,200,2,14.35,200,2,12.86,100,1,14.48,700,1,12.73,100,1,14.53,100,1,12.71,100,1,14.54,800,2,12.5,700,1,14.56,700,1,12.46,100,1,14.6,100,1,12.43,700,1,14.68,700,1,12.42,700,1,14.81,100,1
2025-07-17T16:17:59.086273873Z,2025-07-17T16:17:59.086439158Z,160,2,1108,C,A,0,14.54,100,130,165285,286766349,ARL,344899913,13.11,100,1,13.79,2,1,13.03,2,1,14.25,100,1,12.98,200,2,14.35,200,2,12.86,100,1,14.48,700,1,12.73,100,1,14.53,100,1,12.71,100,1,14.54,700,1,12.5,700,1,14.56,700,1,12.46,100,1,14.6,100,1,12.43,700,1,14.68,700,1,12.42,700,1,14.81,100,1
2025-07-17T16:17:59.086395964Z,2025-07-17T16:17:59.086561438Z,160,2,1108,A,A,0,14.77,100,130,165474,286766355,ARL,344914361,13.11,100,1,13.79,2,1,13.03,2,1,14.25,100,1,12.98,200,2,14.35,200,2,12.86,100,1,14.48,700,1,12.73,100,1,14.53,100,1,12.71,100,1,14.54,700,1,12.5,700,1,14.56,700,1,12.46,100,1,14.6,100,1,12.43,700,1,14.68,700,1,12.42,700,1,14.77,100,1
2025-07-17T16:18:02.178463984Z,2025-07-17T16:18:02.178629167Z,160,2,1108,A,A,0,13.8,100,130,165183,286829047,ARL,344989393,13.11,100,1,13.79,2,1,13.03,2,1,13.8,100,1,12.98,200,2,14.25,100,1,12.86,100,1,14.35,200,2,12.73,100,1,14.48,700,1,12.71,100,1,14.53,100,1,12.5,700,1,14.54,700,1,12.46,100,1,14.56,700,1,12.43,700,1,14.6,100,1,12.42,700,1,14.68,700,1
2025-07-17T16:18:02.179214149Z,2025-07-17T16:18:02.179379565Z,160,2,1108,C,A,0,15.05,100,0,165416,286829057,ARL,344899937,13.11,100,1,13.79,2,1,13.03,2,1,13.8,100,1,12.98,200,2,14.25,100,1,12.86,100,1,14.35,200,2,12.73,100,1,14.48,700,1,12.71,100,1,14.53,100,1,12.5,700,1,14.54,700,1,12.46,100,1,14.56,700,1,12.43,700,1,14.6,100,1,12.42,700,1,14.68,700,1
2025-07-17T16:18:02.179214149Z,2025-07-17T16:18:02.179379565Z,160,2,1108,A,A,0,14.87,100,130,165416,286829057,ARL,344989421,13.11,100,1,13.79,2,1,13.03,2,1,13.8,100,1,12.98,200,2,14.25,100,1,12.86,100,1,14.35,200,2,12.73,100,1,14.48,700,1,12.71,100,1,14.53,100,1,12.5,700,1,14.54,700,1,12.46,100,1,14.56,700,1,12.43,700,1,14.6,100,1,12.42,700,1,14.68,700,1
2025-07-17T16:18:02.181307241Z,2025-07-17T16:18:02.181473898Z,160,2,1108,C,A,0,14.96,100,0,166657,286829106,ARL,344899081,13.11,100,1,13.79,2,1,13.03,2,1,13.8,100,1,12.98,200,2,14.25,100,1,12.86,100,1,14.35,200,2,12.73,100,1,14.48,700,1,12.71,100,1,14.53,100,1,12.5,700,1,14.54,700,1,12.46,100,1,14.56,700,1,12.43,700,1,14.6,100,1,12.42,700,1,14.68,700,1
2025-07-17T16:18:02.181307241Z,2025-07-17T16:18:02.181473898Z,160,2,1108,A,A,0,14.77,100,128,166657,286829106,ARL,344989525,13.11,100,1,13.79,2,1,13.03,2,1,13.8,100,1,12.98,200,2,14.25,100,1,12.86,100,1,14.35,200,2,12.73,100,1,14.48,700,1,12.71,100,1,14.53,100,1,12.5,700,1,14.54,700,1,12.46,100,1,14.56,700,1,12.43,700,1,14.6,100,1,12.42,700,1,14.68,700,1
2025-07-17T16:18:02.182309015Z,2025-07-17T16:18:02.182474498Z,160,2,1108,C,A,0,17.76,100,0,165483,286829137,ARL,344899449,13.11,100,1,13.79,2,1,13.03,2,1,13.8,100,1,12.98,200,2,14.25,100,1,12.86,100,1,14.35,200,2,12.73,100,1,14.48,700,1,12.71,100,1,14.53,100,1,12.5,700,1,14.54,700,1,12.46,100,1,14.56,700,1,12.43,700,1,14.6,100,1,12.42,700,1,14.68,700,1
2025-07-17T16:18:02.182309015Z,2025-07-17T16:18:02.182474498Z,160,2,1108,A,A,0,17.53,100,130,165483,286829137,ARL,344989557,13.11,100,1,13.79,2,1,13.03,2,1,13.8,100,1,12.98,200,2,14.25,100,1,12.86,100,1,14.35,200,2,12.73,100,1,14.48,700,1,12.71,100,1,14.53,100,1,12.5,700,1,14.54,700,1,12.46,100,1,14.56,700,1,12.43,700,1,14.6,100,1,12.42,700,1,14.68,700,1
2025-07-17T16:18:02.184622698Z,2025-07-17T16:18:02.184788371Z,160,2,1108,C,A,0,14.25,100,130,165673,286829173,ARL,344899417,13.11,100,1,13.79,2,1,13.03,2,1,13.8,100,1,12.98,200,2,14.35,200,2,12.86,100,1,14.48,700,1,12.73,100,1,14.53,100,1,12.71,100,1,14.54,700,1,12.5,700,1,14.56,700,1,12.46,100,1,14.6,100,1,12.43,700,1,14.68,700,1,12.42,700,1,14.77,200,2
2025-07-17T16:18:02.184674810Z,2025-07-17T16:18:02.184840010Z,160,2,1108,A,A,0,14.08,100,130,165200,286829174,ARL,344989601,13.11,100,1,13.79,2,1,13.03,2,1,13.8,100,1,12.98,200,2,14.08,100,1,12.86,100,1,14.35,200,2,12.73,100,1,14.48,700,1,12.71,100,1,14.53,100,1,12.5,700,1,14.54,700,1,12.46,100,1,14.56,700,1,12.43,700,1,14.6,100,1,12.42,700,1,14.68,700,1
2025-07-17T16:18:02.186745185Z,2025-07-17T16:18:02.186910586Z,160,2,1108,C,A,0,14.77,100,0,165401,286829206,ARL,344914361,13.11,100,1,13.79,2,1,13.03,2,1,13.8,100,1,12.98,200,2,14.08,100,1,12.86,100,1,14.35,200,2,12.73,100,1,14.48,700,1,12.71,100,1,14.53,100,1,12.5,700,1,14.54,700,1,12.46,100,1,14.56,700,1,12.43,700,1,14.6,100,1,12.42,700,1,14.68,700,1
2025-07-17T16:18:02.186745185Z,2025-07-17T16:18:02.186910586Z,160,2,1108,A,A,0,14.59,100,130,165401,286829206,ARL,344989661,13.11,100,1,13.79,2,1,13.03,2,1,13.8,100,1,12.98,200,2,14.08,100,1,12.86,100,1,14.35,200,2,12.73,100,1,14.48,700,1,12.71,100,1,14.53,100,1,12.5,700,1,14.54,700,1,12.46,100,1,14.56,700,1,12.43,700,1,14.59,100,1,12.42,700,1,14.6,100,1
2025-07-17T16:18:02.189371317Z,2025-07-17T16:18:02.189536873Z,160,2,1108,C,A,0,16.08,100,0,165556,286829251,ARL,344899093,13.11,100,1,13.79,2,1,13.03,2,1,13.8,100,1,12.98,200,2,14.08,100,1,12.86,100,1,14.35,200,2,12.73,100,1,14.48,700,1,12.71,100,1,14.53,100,1,12.5,700,1,14.54,700,1,12.46,100,1,14.56,700,1,12.43,700,1,14.59,100,1,12.42,700,1,14.6,100,1
2025-07-17T16:18:02.189371317Z,2025-07-17T16:18:02.189536873Z,160,2,1108,A,A,0,15.87,100,130,165556,286829251,ARL,344989713,13.11,100,1,13.79,2,1,13.03,2,1,13.8,100,1,12.98,200,2,14.08,100,1,12.86,100,1,14.35,200,2,12.73,100,1,14.48,700,1,12.71,100,1,14.53,100,1,12.5,700,1,14.54,700,1,12.46,100,1,14.56,700,1,12.43,700,1,14.59,100,1,12.42,700,1,14.6,100,1
2025-07-17T16:18:02.271437003Z,2025-07-17T16:18:02.271602472Z,160,2,1108,C,A,0,14.96,100,0,165469,286830984,ARL,344900597,13.11,100,1,13.79,2,1,13.03,2,1,13.8,100,1,12.98,200,2,14.08,100,1,12.86,100,1,14.35,200,2,12.73,100,1,14.48,700,1,12.71,100,1,14.53,100,1,12.5,700,1,14.54,700,1,12.46,100,1,14.56,700,1,12.43,700,1,14.59,100,1,12.42,700,1,14.6,100,1
2025-07-17T16:18:02.271437003Z,2025-07-17T16:18:02.271602472Z,160,2,1108,A,A,0,14.77,100,130,165469,286830984,ARL,344990837,13.11,100,1,13.79,2,1,13.03,2,1,13.8,100,1,12.98,200,2,14.08,100,1,12.86,100,1,14.35,200,2,12.73,100,1,14.48,700,1,12.71,100,1,14.53,100,1,12.5,700,1,14.54,700,1,12.46,100,1,14.56,700,1,12.43,700,1,14.59,100,1,12.42,700,1,14.6,100,1
2025-07-17T16:18:44.836067409Z,2025-07-17T16:18:44.836233374Z,160,2,1108,A,A,0,13.47,15,130,165965,287534438,ARL,345869437,13.11,100,1,13.47,15,1,13.03,2,1,13.79,2,1,12.98,200,2,13.8,100,1,12.86,100,1,14.08,100,1,12.73,100,1,14.35,200,2,12.71,100,1,14.48,700,1,12.5,700,1,14.53,100,1,12.46,100,1,14.54,700,1,12.43,700,1,14.56,700,1,12.42,700,1,14.59,100,1
2025-07-17T16:18:45.977398557Z,2025-07-17T16:18:45.977564112Z,160,2,1108,C,A,0,13.8,100,0,165555,287547865,ARL,344989393,13.11,100,1,13.47,15,1,13.03,2,1,13.79,2,1,12.98,200,2,14.08,100,1,12.86,100,1,14.35,200,2,12.73,100,1,14.48,700,1,12.71,100,1,14.53,100,1,12.5,700,1,14.54,700,1,12.46,100,1,14.56,700,1,12.43,700,1,14.59,100,1,12.42,700,1,14.6,100,1
2025-07-17T16:18:45.977398557Z,2025-07-17T16:18:45.977564112Z,160,2,1108,A,A,0,13.48,100,130,165555,287547865,ARL,345889137,13.11,100,1,13.47,15,1,13.03,2,1,13.48,100,1,12.98,200,2,13.79,2,1,12.86,100,1,14.08,100,1,12.73,100,1,14.35,200,2,12.71,100,1,14.48,700,1,12.5,700,1,14.53,100,1,12.46,100,1,14.54,700,1,12.43,700,1,14.56,700,1,12.42,700,1,14.59,100,1
2025-07-17T16:18:45.978139497Z,2025-07-17T16:18:45.978304784Z,160,2,1108,C,A,0,14.6,100,130,165287,287547870,ARL,344906945,13.11,100,1,13.47,15,1,13.03,2,1,13.48,100,1,12.98,200,2,13.79,2,1,12.86,100,1,14.08,100,1,12.73,100,1,14.35,200,2,12.71,100,1,14.48,700,1,12.5,700,1,14.53,100,1,12.46,100,1,14.54,700,1,12.43,700,1,14.56,700,1,12.42,700,1,14.59,100,1
2025-07-17T16:18:45.978141738Z,2025-07-17T16:18:45.978307201Z,160,2,1108,C,A,0,14.87,100,0,165463,287547871,ARL,344989421,13.11,100,1,13.47,15,1,13.03,2,1,13.48,100,1,12.98,200,2,13.79,2,1,12.86,100,1,14.08,100,1,12.73,100,1,14.35,200,2,12.71,100,1,14.48,700,1,12.5,700,1,14.53,100,1,12.46,100,1,14.54,700,1,12.43,700,1,14.56,700,1,12.42,700,1,14.59,100,1
2025-07-17T16:18:45.978141738Z,2025-07-17T16:18:45.978307201Z,160,2,1108,A,A,0,14.53,100,130,165463,287547871,ARL,345889161,13.11,100,1,13.47,15,1,13.03,2,1,13.48,100,1,12.98,200,2,13.79,2,1,12.86,100,1,14.08,100,1,12.73,100,1,14.35,200,2,12.71,100,1,14.48,700,1,12.5,700,1,14.53,200,2,12.46,100,1,14.54,700,1,12.43,700,1,14.56,700,1,12.42,700,1,14.59,100,1
2025-07-17T16:18:45.978493799Z,2025-07-17T16:18:45.978659056Z,160,2,1108,A,A,0,14.08,100,130,165257,287547872,ARL,345889165,13.11,100,1,13.47,15,1,13.03,2,1,13.48,100,1,12.98,200,2,13.79,2,1,12.86,100,1,14.08,200,2,12.73,100,1,14.35,200,2,12.71,100,1,14.48,700,1,12.5,700,1,14.53,200,2,12.46,100,1,14.54,700,1,12.43,700,1,14.56,700,1,12.42,700,1,14.59,100,1
2025-07-17T16:18:45.979031886Z,2025-07-17T16:18:45.979197330Z,160,2,1108,C,A,0,15.13,100,0,165444,287547882,ARL,344897997,13.11,100,1,13.47,15,1,13.03,2,1,13.48,100,1,12.98,200,2,13.79,2,1,12.86,100,1,14.08,200,2,12.73,100,1,14.35,200,2,12.71,100,1,14.48,700,1,12.5,700,1,14.53,200,2,12.46,100,1,14.54,700,1,12.43,700,1,14.56,700,1,12.42,700,1,14.59,100,1
2025-07-17T16:18:45.979031886Z,2025-07-17T16:18:45.979197330Z,160,2,1108,A,A,0,14.83,100,130,165444,287547882,ARL,345889185,13.11,100,1,13.47,15,1,13.03,2,1,13.48,100,1,12.98,200,2,13.79,2,1,12.86,100,1,14.08,200,2,12.73,100,1,14.35,200,2,12.71,100,1,14.48,700,1,12.5,700,1,14.53,200,2,12.46,100,1,14.54,700,1,12.43,700,1,14.56,700,1,12.42,700,1,14.59,100,1
2025-07-17T16:18:45.979287575Z,2025-07-17T16:18:45.979453023Z,160,2,1108,C,A,0,14.77,100,0,165448,287547885,ARL,344990837,13.11,100,1,13.47,15,1,13.03,2,1,13.48,100,1,12.98,200,2,13.79,2,1,12.86,100,1,14.08,200,2,12.73,100,1,14.35,200,2,12.71,100,1,14.48,700,1,12.5,700,1,14.53,200,2,12.46,100,1,14.54,700,1,12.43,700,1,14.56,700,1,12.42,700,1,14.59,100,1
2025-07-17T16:18:45.979287575Z,2025-07-17T16:18:45.979453023Z,160,2,1108,A,A,0,14.43,100,130,165448,287547885,ARL,345889189,13.11,100,1,13.47,15,1,13.03,2,1,13.48,100,1,12.98,200,2,13.79,2,1,12.86,100,1,14.08,200,2,12.73,100,1,14.35,200,2,12.71,100,1,14.43,100,1,12.5,700,1,14.48,700,1,12.46,100,1,14.53,200,2,12.43,700,1,14.54,700,1,12.42,700,1,14.56,700,1
2025-07-17T16:18:45.979732081Z,2025-07-17T16:18:45.979897527Z,160,2,1108,C,A,0,15.87,100,0,165446,287547887,ARL,344989713,13.11,100,1,13.47,15,1,13.03,2,1,13.48,100,1,12.98,200,2,13.79,2,1,12.86,100,1,14.08,200,2,12.73,100,1,14.35,200,2,12.71,100,1,14.43,100,1,12.5,700,1,14.48,700,1,12.46,100,1,14.53,200,2,12.43,700,1,14.54,700,1,12.42,700,1,14.56,700,1
2025-07-17T16:18:45.979732081Z,2025-07-17T16:18:45.979897527Z,160,2,1108,A,A,0,15.51,100,130,165446,287547887,ARL,345889193,13.11,100,1,13.47,15,1,13.03,2,1,13.48,100,1,12.98,200,2,13.79,2,1,12.86,100,1,14.08,200,2,12.73,100,1,14.35,200,2,12.71,100,1,14.43,100,1,12.5,700,1,14.48,700,1,12.46,100,1,14.53,200,2,12.43,700,1,14.54,700,1,12.42,700,1,14.56,700,1
2025-07-17T16:18:45.979972220Z,2025-07-17T16:18:45.980137835Z,160,2,1108,C,A,0,14.77,100,0,165615,287547890,ARL,344989525,13.11,100,1,13.47,15,1,13.03,2,1,13.48,100,1,12.98,200,2,13.79,2,1,12.86,100,1,14.08,200,2,12.73,100,1,14.35,200,2,12.71,100,1,14.43,100,1,12.5,700,1,14.48,700,1,12.46,100,1,14.53,200,2,12.43,700,1,14.54,700,1,12.42,700,1,14.56,700,1
2025-07-17T16:18:45.979972220Z,2025-07-17T16:18:45.980137835Z,160,2,1108,A,A,0,14.43,100,130,165615,287547890,ARL,345889201,13.11,100,1,13.47,15,1,13.03,2,1,13.48,100,1,12.98,200,2,13.79,2,1,12.86,100,1,14.08,200,2,12.73,100,1,14.35,200,2,12.71,100,1,14.43,200,2,12.5,700,1,14.48,700,1,12.46,100,1,14.53,200,2,12.43,700,1,14.54,700,1,12.42,700,1,14.56,700,1
2025-07-17T16:18:45.980031732Z,2025-07-17T16:18:45.980197213Z,160,2,1108,C,A,0,17.53,100,0,165481,287547891,ARL,344989557,13.11,100,1,13.47,15,1,13.03,2,1,13.48,100,1,12.98,200,2,13.79,2,1,12.86,100,1,14.08,200,2,12.73,100,1,14.35,200,2,12.71,100,1,14.43,200,2,12.5,700,1,14.48,700,1,12.46,100,1,14.53,200,2,12.43,700,1,14.54,700,1,12.42,700,1,14.56,700,1
2025-07-17T16:18:45.980031732Z,2025-07-17T16:18:45.980197213Z,160,2,1108,A,A,0,17.12,100,130,165481,287547891,ARL,345889205,13.11,100,1,13.47,15,1,13.03,2,1,13.48,100,1,12.98,200,2,13.79,2,1,12.86,100,1,14.08,200,2,12.73,100,1,14.35,200,2,12.71,100,1,14.43,200,2,12.5,700,1,14.48,700,1,12.46,100,1,14.53,200,2,12.43,700,1,14.54,700,1,12.42,700,1,14.56,700,1
2025-07-17T16:18:45.980040000Z,2025-07-17T16:18:45.980205832Z,160,2,1108,C,A,0,15.38,100,0,165832,287547892,ARL,344900289,13.11,100,1,13.47,15,1,13.03,2,1,13.48,100,1,12.98,200,2,13.79,2,1,12.86,100,1,14.08,200,2,12.73,100,1,14.35,200,2,12.71,100,1,14.43,200,2,12.5,700,1,14.48,700,1,12.46,100,1,14.53,200,2,12.43,700,1,14.54,700,1,12.42,700,1,14.56,700,1
2025-07-17T16:18:45.980040000Z,2025-07-17T16:18:45.980205832Z,160,2,1108,A,A,0,14.83,100,130,165832,287547892,ARL,345889209,13.11,100,1,13.47,15,1,13.03,2,1,13.48,100,1,12.98,200,2,13.79,2,1,12.86,100,1,14.08,200,2,12.73,100,1,14.35,200,2,12.71,100,1,14.43,200,2,12.5,700,1,14.48,700,1,12.46,100,1,14.53,200,2,12.43,700,1,14.54,700,1,12.42,700,1,14.56,700,1
2025-07-17T16:18:45.982798406Z,2025-07-17T16:18:45.982963696Z,160,2,1108,C,A,0,14.59,100,130,165290,287547919,ARL,344989661,13.11,100,1,13.47,15,1,13.03,2,1,13.48,100,1,12.98,200,2,13.79,2,1,12.86,100,1,14.08,200,2,12.73,100,1,14.35,200,2,12.71,100,1,14.43,200,2,12.5,700,1,14.48,700,1,12.46,100,1,14.53,200,2,12.43,700,1,14.54,700,1,12.42,700,1,14.56,700,1
2025-07-17T16:18:45.982933040Z,2025-07-17T16:18:45.983098604Z,160,2,1108,A,A,0,14.27,100,130,165564,287547921,ARL,345889277,13.11,100,1,13.47,15,1,13.03,2,1,13.48,100,1,12.98,200,2,13.79,2,1,12.86,100,1,14.08,200,2,12.73,100,1,14.27,100,1,12.71,100,1,14.35,200,2,12.5,700,1,14.43,200,2,12.46,100,1,14.48,700,1,12.43,700,1,14.53,200,2,12.42,700,1,14.54,700,1
2025-07-17T16:18:45.994141218Z,2025-07-17T16:18:45.994306597Z,160,2,1108,C,A,0,14.08,100,130,165379,287548000,ARL,344989601,13.11,100,1,13.47,15,1,13.03,2,1,13.48,100,1,12.98,200,2,13.79,2,1,12.86,100,1,14.08,100,1,12.73,100,1,14.27,100,1,12.71,100,1,14.35,200,2,12.5,700,1,14.43,200,2,12.46,100,1,14.48,700,1,12.43,700,1,14.53,200,2,12.42,700,1,14.54,700,1
2025-07-17T16:18:45.994191684Z,2025-07-17T16:18:45.994356983Z,160,2,1108,A,A,0,13.75,100,130,165299,287548002,ARL,345889457,13.11,100,1,13.47,15,1,13.03,2,1,13.48,100,1,12.98,200,2,13.75,100,1,12.86,100,1,13.79,2,1,12.73,100,1,14.08,100,1,12.71,100,1,14.27,100,1,12.5,700,1,14.35,200,2,12.46,100,1,14.43,200,2,12.43,700,1,14.48,700,1,12.42,700,1,14.53,200,2
2025-07-17T16:18:46.020605332Z,2025-07-17T16:18:46.020770846Z,160,2,1108,A,A,0,15.37,100,130,165514,287548308,ARL,345889897,13.11,100,1,13.47,15,1,13.03,2,1,13.48,100,1,12.98,200,2,13.75,100,1,12.86,100,1,13.79,2,1,12.73,100,1,14.08,100,1,12.71,100,1,14.27,100,1,12.5,700,1,14.35,200,2,12.46,100,1,14.43,200,2,12.43,700,1,14.48,700,1,12.42,700,1,14.53,200,2
2025-07-17T16:18:46.020617704Z,2025-07-17T16:18:46.020783162Z,160,2,1108,C,A,0,15.68,100,130,165458,287548309,ARL,344897933,13.11,100,1,13.47,15,1,13.03,2,1,13.48,100,1,12.98,200,2,13.75,100,1,12.86,100,1,13.79,2,1,12.73,100,1,14.08,100,1,12.71,100,1,14.27,100,1,12.5,700,1,14.35,200,2,12.46,100,1,14.43,200,2,12.43,700,1,14.48,700,1,12.42,700,1,14.53,200,2
2025-07-17T16:18:46.583636828Z,2025-07-17T16:18:46.583802176Z,160,2,1108,A,A,0,14.28,100,130,165348,287559115,ARL,345903265,13.11,100,1,13.47,15,1,13.03,2,1,13.48,100,1,12.98,200,2,13.75,100,1,12.86,100,1,13.79,2,1,12.73,100,1,14.08,100,1,12.71,100,1,14.27,100,1,12.5,700,1,14.28,100,1,12.46,100,1,14.35,200,2,12.43,700,1,14.43,200,2,12.42,700,1,14.48,700,1
2025-07-17T16:18:46.583649620Z,2025-07-17T16:18:46.583815469Z,160,2,1108,C,A,0,14.81,100,128,165849,287559119,ARL,344900925,13.11,100,1,13.47,15,1,13.03,2,1,13.48,100,1,12.98,200,2,13.75,100,1,12.86,100,1,13.79,2,1,12.73,100,1,14.08,100,1,12.71,100,1,14.27,100,1,12.5,700,1,14.28,100,1,12.46,100,1,14.35,200,2,12.43,700,1,14.43,200,2,12.42,700,1,14.48,700,1
2025-07-17T16:18:46.972688613Z,2025-07-17T16:18:46.972854044Z,160,2,1108,C,A,0,14.53,100,130,165431,287565224,ARL,344905321,13.11,100,1,13.47,15,1,13.03,2,1,13.48,100,1,12.98,200,2,13.75,100,1,12.86,100,1,13.79,2,1,12.73,100,1,14.08,100,1,12.71,100,1,14.27,100,1,12.5,700,1,14.28,100,1,12.46,100,1,14.35,200,2,12.43,700,1,14.43,200,2,12.42,700,1,14.48,700,1
2025-07-17T16:18:46.972689989Z,2025-07-17T16:18:46.972855248Z,160,2,1108,A,A,0,14.01,100,130,165259,287565225,ARL,345911213,13.11,100,1,13.47,15,1,13.03,2,1,13.48,100,1,12.98,200,2,13.75,100,1,12.86,100,1,13.79,2,1,12.73,100,1,14.01,100,1,12.71,100,1,14.08,100,1,12.5,700,1,14.27,100,1,12.46,100,1,14.28,100,1,12.43,700,1,14.35,200,2,12.42,700,1,14.43,200,2
2025-07-17T16:18:47.836002486Z,2025-07-17T16:18:47.836167832Z,160,2,1108,A,A,0,13.45,15,130,165346,287577128,ARL,345924181,13.11,100,1,13.45,15,1,13.03,2,1,13.47,15,1,12.98,200,2,13.48,100,1,12.86,100,1,13.75,100,1,12.73,100,1,13.79,2,1,12.71,100,1,14.01,100,1,12.5,700,1,14.08,100,1,12.46,100,1,14.27,100,1,12.43,700,1,14.28,100,1,12.42,700,1,14.35,200,2
2025-07-17T16:18:47.956070064Z,2025-07-17T16:18:47.956236479Z,160,2,1108,C,A,0,13.48,100,0,166415,287579474,ARL,345889137,13.11,100,1,13.45,15,1,13.03,2,1,13.47,15,1,12.98,200,2,13.75,100,1,12.86,100,1,13.79,2,1,12.73,100,1,14.01,100,1,12.71,100,1,14.08,100,1,12.5,700,1,14.27,100,1,12.46,100,1,14.28,100,1,12.43,700,1,14.35,200,2,12.42,700,1,14.43,200,2
2025-07-17T16:18:47.956070064Z,2025-07-17T16:18:47.956236479Z,160,2,1108,A,A,0,13.46,100,130,166415,287579474,ARL,345926413,13.11,100,1,13.45,15,1,13.03,2,1,13.46,100,1,12.98,200,2,13.47,15,1,12.86,100,1,13.75,100,1,12.73,100,1,13.79,2,1,12.71,100,1,14.01,100,1,12.5,700,1,14.08,100,1,12.46,100,1,14.27,100,1,12.43,700,1,14.28,100,1,12.42,700,1,14.35,200,2
2025-07-17T16:18:47.956448830Z,2025-07-17T16:18:47.956614041Z,160,2,1108,A,A,0,15.68,100,130,165211,287579583,ARL,345926449,13.11,100,1,13.45,15,1,13.03,2,1,13.46,100,1,12.98,200,2,13.47,15,1,12.86,100,1,13.75,100,1,12.73,100,1,13.79,2,1,12.71,100,1,14.01,100,1,12.5,700,1,14.08,100,1,12.46,100,1,14.27,100,1,12.43,700,1,14.28,100,1,12.42,700,1,14.35,200,2
2025-07-17T16:18:47.956462726Z,2025-07-17T16:18:47.956628879Z,160,2,1108,C,A,0,15.37,100,130,166153,287579592,ARL,345889897,13.11,100,1,13.45,15,1,13.03,2,1,13.46,100,1,12.98,200,2,13.47,15,1,12.86,100,1,13.75,100,1,12.73,100,1,13.79,2,1,12.71,100,1,14.01,100,1,12.5,700,1,14.08,100,1,12.46,100,1,14.27,100,1,12.43,700,1,14.28,100,1,12.42,700,1,14.35,200,2
2025-07-17T16:18:47.983119698Z,2025-07-17T16:18:47.983287076Z,160,2,1108,A,A,0,15.35,100,128,167378,287583059,ARL,345930785,13.11,100,1,13.45,15,1,13.03,2,1,13.46,100,1,12.98,200,2,13.47,15,1,12.86,100,1,13.75,100,1,12.73,100,1,13.79,2,1,12.71,100,1,14.01,100,1,12.5,700,1,14.08,100,1,12.46,100,1,14.27,100,1,12.43,700,1,14.28,100,1,12.42,700,1,14.35,200,2
2025-07-17T16:18:47.983140841Z,2025-07-17T16:18:47.983312942Z,160,2,1108,C,A,0,15.68,100,128,172101,287583076,ARL,345926449,13.11,100,1,13.45,15,1,13.03,2,1,13.46,100,1,12.98,200,2,13.47,15,1,12.86,100,1,13.75,100,1,12.73,100,1,13.79,2,1,12.71,100,1,14.01,100,1,12.5,700,1,14.08,100,1,12.46,100,1,14.27,100,1,12.43,700,1,14.28,100,1,12.42,700,1,14.35,200,2
2025-07-17T16:18:51.228274415Z,2025-07-17T16:18:51.228439638Z,160,2,1108,A,A,0,14.18,700,130,165223,287639434,ARL,345998433,13.11,100,1,13.45,15,1,13.03,2,1,13.46,100,1,12.98,200,2,13.47,15,1,12.86,100,1,13.75,100,1,12.73,100,1,13.79,2,1,12.71,100,1,14.01,100,1,12.5,700,1,14.08,100,1,12.46,100,1,14.18,700,1,12.43,700,1,14.27,100,1,12.42,700,1,14.28,100,1
2025-07-17T16:18:51.228351310Z,2025-07-17T16:18:51.228516429Z,160,2,1108,C,A,0,14.68,700,130,165119,287639437,ARL,344902153,13.11,100,1,13.45,15,1,13.03,2,1,13.46,100,1,12.98,200,2,13.47,15,1,12.86,100,1,13.75,100,1,12.73,100,1,13.79,2,1,12.71,100,1,14.01,100,1,12.5,700,1,14.08,100,1,12.46,100,1,14.18,700,1,12.43,700,1,14.27,100,1,12.42,700,1,14.28,100,1
2025-07-17T16:18:57.882196648Z,2025-07-17T16:18:57.882365457Z,160,2,1108,C,A,0,13.47,15,128,168809,287807679,ARL,345869437,13.11,100,1,13.45,15,1,13.03,2,1,13.46,100,1,12.98,200,2,13.75,100,1,12.86,100,1,13.79,2,1,12.73,100,1,14.01,100,1,12.71,100,1,14.08,100,1,12.5,700,1,14.18,700,1,12.46,100,1,14.27,100,1,12.43,700,1,14.28,100,1,12.42,700,1,14.35,200,2
2025-07-17T16:19:04.990724544Z,2025-07-17T16:19:04.990890102Z,160,2,1108,C,A,0,13.79,2,0,165558,288025773,ARL,344765077,13.11,100,1,13.45,15,1,13.03,2,1,13.46,100,1,12.98,200,2,13.75,100,1,12.86,100,1,14.01,100,1,12.73,100,1,14.08,100,1,12.71,100,1,14.18,700,1,12.5,700,1,14.27,100,1,12.46,100,1,14.28,100,1,12.43,700,1,14.35,200,2,12.42,700,1,14.43,200,2
2025-07-17T16:19:04.990724544Z,2025-07-17T16:19:04.990890102Z,160,2,1108,A,A,0,13.72,2,130,165558,288025773,ARL,346423105,13.11,100,1,13.45,15,1,13.03,2,1,13.46,100,1,12.98,200,2,13.72,2,1,12.86,100,1,13.75,100,1,12.73,100,1,14.01,100,1,12.71,100,1,14.08,100,1,12.5,700,1,14.18,700,1,12.46,100,1,14.27,100,1,12.43,700,1,14.28,100,1,12.42,700,1,14.35,200,2
2025-07-17T16:19:08.837120837Z,2025-07-17T16:19:08.837286193Z,160,2,1108,A,A,0,13.43,15,130,165356,288088546,ARL,346492493,13.11,100,1,13.43,15,1,13.03,2,1,13.45,15,1,12.98,200,2,13.46,100,1,12.86,100,1,13.72,2,1,12.73,100,1,13.75,100,1,12.71,100,1,14.01,100,1,12.5,700,1,14.08,100,1,12.46,100,1,14.18,700,1,12.43,700,1,14.27,100,1,12.42,700,1,14.28,100,1
2025-07-17T16:19:11.008187551Z,2025-07-17T16:19:11.008353202Z,160,2,1108,C,A,0,13.46,100,0,165651,288143215,ARL,345926413,13.11,100,1,13.43,15,1,13.03,2,1,13.45,15,1,12.98,200,2,13.72,2,1,12.86,100,1,13.75,100,1,12.73,100,1,14.01,100,1,12.71,100,1,14.08,100,1,12.5,700,1,14.18,700,1,12.46,100,1,14.27,100,1,12.43,700,1,14.28,100,1,12.42,700,1,14.35,200,2
2025-07-17T16:19:11.008187551Z,2025-07-17T16:19:11.008353202Z,160,2,1108,A,A,0,13.44,100,130,165651,288143215,ARL,346562289,13.11,100,1,13.43,15,1,13.03,2,1,13.44,100,1,12.98,200,2,13.45,15,1,12.86,100,1,13.72,2,1,12.73,100,1,13.75,100,1,12.71,100,1,14.01,100,1,12.5,700,1,14.08,100,1,12.46,100,1,14.18,700,1,12.43,700,1,14.27,100,1,12.42,700,1,14.28,100,1
2025-07-17T16:19:11.008600601Z,2025-07-17T16:19:11.008765986Z,160,2,1108,A,A,0,15.68,100,130,165385,288143223,ARL,346562317,13.11,100,1,13.43,15,1,13.03,2,1,13.44,100,1,12.98,200,2,13.45,15,1,12.86,100,1,13.72,2,1,12.73,100,1,13.75,100,1,12.71,100,1,14.01,100,1,12.5,700,1,14.08,100,1,12.46,100,1,14.18,700,1,12.43,700,1,14.27,100,1,12.42,700,1,14.28,100,1
2025-07-17T16:19:11.008613992Z,2025-07-17T16:19:11.008779449Z,160,2,1108,C,A,0,15.35,100,130,165457,288143225,ARL,345930785,13.11,100,1,13.43,15,1,13.03,2,1,13.44,100,1,12.98,200,2,13.45,15,1,12.86,100,1,13.72,2,1,12.73,100,1,13.75,100,1,12.71,100,1,14.01,100,1,12.5,700,1,14.08,100,1,12.46,100,1,14.18,700,1,12.43,700,1,14.27,100,1,12.42,700,1,14.28,100,1
2025-07-17T16:19:11.008923390Z,2025-07-17T16:19:11.009089771Z,160,2,1108,C,A,0,14.53,100,0,166381,288143233,ARL,345889161,13.11,100,1,13.43,15,1,13.03,2,1,13.44,100,1,12.98,200,2,13.45,15,1,12.86,100,1,13.72,2,1,12.73,100,1,13.75,100,1,12.71,100,1,14.01,100,1,12.5,700,1,14.08,100,1,12.46,100,1,14.18,700,1,12.43,700,1,14.27,100,1,12.42,700,1,14.28,100,1
2025-07-17T16:19:11.008923390Z,2025-07-17T16:19:11.009089771Z,160,2,1108,A,A,0,14.48,100,130,166381,288143233,ARL,346562329,13.11,100,1,13.43,15,1,13.03,2,1,13.44,100,1,12.98,200,2,13.45,15,1,12.86,100,1,13.72,2,1,12.73,100,1,13.75,100,1,12.71,100,1,14.01,100,1,12.5,700,1,14.08,100,1,12.46,100,1,14.18,700,1,12.43,700,1,14.27,100,1,12.42,700,1,14.28,100,1
2025-07-17T16:19:11.035215637Z,2025-07-17T16:19:11.035380853Z,160,2,1108,A,A,0,15.33,100,130,165216,288143789,ARL,346563437,13.11,100,1,13.43,15,1,13.03,2,1,13.44,100,1,12.98,200,2,13.45,15,1,12.86,100,1,13.72,2,1,12.73,100,1,13.75,100,1,12.71,100,1,14.01,100,1,12.5,700,1,14.08,100,1,12.46,100,1,14.18,700,1,12.43,700,1,14.27,100,1,12.42,700,1,14.28,100,1
2025-07-17T16:19:11.035227814Z,2025-07-17T16:19:11.035392933Z,160,2,1108,C,A,0,15.68,100,130,165119,288143791,ARL,346562317,13.11,100,1,13.43,15,1,13.03,2,1,13.44,100,1,12.98,200,2,13.45,15,1,12.86,100,1,13.72,2,1,12.73,100,1,13.75,100,1,12.71,100,1,14.01,100,1,12.5,700,1,14.08,100,1,12.46,100,1,14.18,700,1,12.43,700,1,14.27,100,1,12.42,700,1,14.28,100,1
2025-07-17T16:19:20.837342130Z,2025-07-17T16:19:20.837507906Z,160,2,1108,C,A,0,13.45,15,130,165776,288310746,ARL,345924181,13.11,100,1,13.43,15,1,13.03,2,1,13.44,100,1,12.98,200,2,13.72,2,1,12.86,100,1,13.75,100,1,12.73,100,1,14.01,100,1,12.71,100,1,14.08,100,1,12.5,700,1,14.18,700,1,12.46,100,1,14.27,100,1,12.43,700,1,14.28,100,1,12.42,700,1,14.35,200,2
2025-07-17T16:19:26.653909048Z,2025-07-17T16:19:26.654075072Z,160,2,1108,A,A,0,13.41,15,128,166024,288411319,ARL,346891037,13.11,100,1,13.41,15,1,13.03,2,1,13.43,15,1,12.98,200,2,13.44,100,1,12.86,100,1,13.72,2,1,12.73,100,1,13.75,100,1,12.71,100,1,14.01,100,1,12.5,700,1,14.08,100,1,12.46,100,1,14.18,700,1,12.43,700,1,14.27,100,1,12.42,700,1,14.28,100,1
2025-07-17T16:19:27.200430092Z,2025-07-17T16:19:27.200595996Z,160,2,1108,C,A,0,13.44,100,0,165904,288424564,ARL,346562289,13.11,100,1,13.41,15,1,13.03,2,1,13.43,15,1,12.98,200,2,13.72,2,1,12.86,100,1,13.75,100,1,12.73,100,1,14.01,100,1,12.71,100,1,14.08,100,1,12.5,700,1,14.18,700,1,12.46,100,1,14.27,100,1,12.43,700,1,14.28,100,1,12.42,700,1,14.35,200,2
2025-07-17T16:19:27.200430092Z,2025-07-17T16:19:27.200595996Z,160,2,1108,A,A,0,13.42,100,130,165904,288424564,ARL,346904153,13.11,100,1,13.41,15,1,13.03,2,1,13.42,100,1,12.98,200,2,13.43,15,1,12.86,100,1,13.72,2,1,12.73,100,1,13.75,100,1,12.71,100,1,14.01,100,1,12.5,700,1,14.08,100,1,12.46,100,1,14.18,700,1,12.43,700,1,14.27,100,1,12.42,700,1,14.28,100,1
2025-07-17T16:19:27.200820552Z,2025-07-17T16:19:27.200986286Z,160,2,1108,A,A,0,15.68,100,130,165734,288424568,ARL,346904169,13.11,100,1,13.41,15,1,13.03,2,1,13.42,100,1,12.98,200,2,13.43,15,1,12.86,100,1,13.72,2,1,12.73,100,1,13.75,100,1,12.71,100,1,14.01,100,1,12.5,700,1,14.08,100,1,12.46,100,1,14.18,700,1,12.43,700,1,14.27,100,1,12.42,700,1,14.28,100,1
2025-07-17T16:19:27.200833294Z,2025-07-17T16:19:27.201000330Z,160,2,1108,C,A,0,15.33,100,128,167036,288424570,ARL,346563437,13.11,100,1,13.41,15,1,13.03,2,1,13.42,100,1,12.98,200,2,13.43,15,1,12.86,100,1,13.72,2,1,12.73,100,1,13.75,100,1,12.71,100,1,14.01,100,1,12.5,700,1,14.08,100,1,12.46,100,1,14.18,700,1,12.43,700,1,14.27,100,1,12.42,700,1,14.28,100,1
2025-07-17T16:19:27.201212584Z,2025-07-17T16:19:27.201378249Z,160,2,1108,A,A,0,14.19,700,130,165665,288424582,ARL,346904221,13.11,100,1,13.41,15,1,13.03,2,1,13.42,100,1,12.98,200,2,13.43,15,1,12.86,100,1,13.72,2,1,12.73,100,1,13.75,100,1,12.71,100,1,14.01,100,1,12.5,700,1,14.08,100,1,12.46,100,1,14.18,700,1,12.43,700,1,14.19,700,1,12.42,700,1,14.27,100,1
2025-07-17T16:19:27.201611743Z,2025-07-17T16:19:27.201777312Z,160,2,1108,C,A,0,14.56,700,130,165569,288424585,ARL,282969973,13.11,100,1,13.41,15,1,13.03,2,1,13.42,100,1,12.98,200,2,13.43,15,1,12.86,100,1,13.72,2,1,12.73,100,1,13.75,100,1,12.71,100,1,14.01,100,1,12.5,700,1,14.08,100,1,12.46,100,1,14.18,700,1,12.43,700,1,14.19,700,1,12.42,700,1,14.27,100,1
2025-07-17T16:19:27.228297629Z,2025-07-17T16:19:27.228463152Z,160,2,1108,A,A,0,15.3,100,130,165523,288425148,ARL,346904561,13.11,100,1,13.41,15,1,13.03,2,1,13.42,100,1,12.98,200,2,13.43,15,1,12.86,100,1,13.72,2,1,12.73,100,1,13.75,100,1,12.71,100,1,14.01,100,1,12.5,700,1,14.08,100,1,12.46,100,1,14.18,700,1,12.43,700,1,14.19,700,1,12.42,700,1,14.27,100,1
2025-07-17T16:19:27.228308764Z,2025-07-17T16:19:27.228473898Z,160,2,1108,C,A,0,15.68,100,130,165134,288425149,ARL,346904169,13.11,100,1,13.41,15,1,13.03,2,1,13.42,100,1,12.98,200,2,13.43,15,1,12.86,100,1,13.72,2,1,12.73,100,1,13.75,100,1,12.71,100,1,14.01,100,1,12.5,700,1,14.08,100,1,12.46,100,1,14.18,700,1,12.43,700,1,14.19,700,1,12.42,700,1,14.27,100,1
2025-07-17T16:19:28.991142567Z,2025-07-17T16:19:28.991308227Z,160,2,1108,C,B,0,13.03,2,0,165660,288452523,ARL,343084165,13.11,100,1,13.41,15,1,12.98,200,2,13.42,100,1,12.86,100,1,13.43,15,1,12.73,100,1,13.72,2,1,12.71,100,1,13.75,100,1,12.5,700,1,14.01,100,1,12.46,100,1,14.08,100,1,12.43,700,1,14.18,700,1,12.42,700,1,14.19,700,1,12.37,700,1,14.27,100,1
2025-07-17T16:19:28.991142567Z,2025-07-17T16:19:28.991308227Z,160,2,1108,A,B,0,12.95,2,130,165660,288452523,ARL,346942181,13.11,100,1,13.41,15,1,12.98,200,2,13.42,100,1,12.95,2,1,13.43,15,1,12.86,100,1,13.72,2,1,12.73,100,1,13.75,100,1,12.71,100,1,14.01,100,1,12.5,700,1,14.08,100,1,12.46,100,1,14.18,700,1,12.43,700,1,14.19,700,1,12.42,700,1,14.27,100,1
2025-07-17T16:19:30.834293908Z,2025-07-17T16:19:30.834459284Z,160,2,1108,C,A,0,13.41,15,130,165376,288478995,ARL,346891037,13.11,100,1,13.42,100,1,12.98,200,2,13.43,15,1,12.95,2,1,13.72,2,1,12.86,100,1,13.75,100,1,12.73,100,1,14.01,100,1,12.71,100,1,14.08,100,1,12.5,700,1,14.18,700,1,12.46,100,1,14.19,700,1,12.43,700,1,14.27,100,1,12.42,700,1,14.28,100,1
2025-07-17T16:19:30.834842536Z,2025-07-17T16:19:30.835008022Z,160,2,1108,C,A,0,13.42,100,130,165486,288479015,ARL,346904153,13.11,100,1,13.43,15,1,12.98,200,2,13.72,2,1,12.95,2,1,13.75,100,1,12.86,100,1,14.01,100,1,12.73,100,1,14.08,100,1,12.71,100,1,14.18,700,1,12.5,700,1,14.19,700,1,12.46,100,1,14.27,100,1,12.43,700,1,14.28,100,1,12.42,700,1,14.35,200,2
2025-07-17T16:19:30.835403659Z,2025-07-17T16:19:30.835569072Z,160,2,1108,C,A,0,13.43,15,130,165413,288479032,ARL,346492493,13.11,100,1,13.72,2,1,12.98,200,2,13.75,100,1,12.95,2,1,14.01,100,1,12.86,100,1,14.08,100,1,12.73,100,1,14.18,700,1,12.71,100,1,14.19,700,1,12.5,700,1,14.27,100,1,12.46,100,1,14.28,100,1,12.43,700,1,14.35,200,2,12.42,700,1,14.43,200,2
2025-07-17T16:19:32.547320695Z,2025-07-17T16:19:32.547487183Z,160,2,1108,C,A,0,14.18,700,130,166488,288512762,ARL,345998433,13.11,100,1,13.72,2,1,12.98,200,2,13.75,100,1,12.95,2,1,14.01,100,1,12.86,100,1,14.08,100,1,12.73,100,1,14.19,700,1,12.71,100,1,14.27,100,1,12.5,700,1,14.28,100,1,12.46,100,1,14.35,200,2,12.43,700,1,14.43,200,2,12.42,700,1,14.48,800,2
2025-07-17T16:19:32.547362298Z,2025-07-17T16:19:32.547527626Z,160,2,1108,A,A,0,14.44,700,130,165328,288512763,ARL,347022701,13.11,100,1,13.72,2,1,12.98,200,2,13.75,100,1,12.95,2,1,14.01,100,1,12.86,100,1,14.08,100,1,12.73,100,1,14.19,700,1,12.71,100,1,14.27,100,1,12.5,700,1,14.28,100,1,12.46,100,1,14.35,200,2,12.43,700,1,14.43,200,2,12.42,700,1,14.44,700,1
