ts_event,ts_recv,r_type,publisher,instrument_id,action,side,depth,price,size,flags,ts_in_delta,sequence,symbol,order_id,bid_px_00,bid_sz_00,bid_ct_00,ask_px_00,ask_sz_00,ask_ct_00,bid_px_01,bid_sz_01,bid_ct_01,ask_px_01,ask_sz_01,ask_ct_01,bid_px_02,bid_sz_02,bid_ct_02,ask_px_02,ask_sz_02,ask_ct_02,bid_px_03,bid_sz_03,bid_ct_03,ask_px_03,ask_sz_03,ask_ct_03,bid_px_04,bid_sz_04,bid_ct_04,ask_px_04,ask_sz_04,ask_ct_04,bid_px_05,bid_sz_05,bid_ct_05,ask_px_05,ask_sz_05,ask_ct_05,bid_px_06,bid_sz_06,bid_ct_06,ask_px_06,ask_sz_06,ask_ct_06,bid_px_07,bid_sz_07,bid_ct_07,ask_px_07,ask_sz_07,ask_ct_07,bid_px_08,bid_sz_08,bid_ct_08,ask_px_08,ask_sz_08,ask_ct_08,bid_px_09,bid_sz_09,bid_ct_09,ask_px_09,ask_sz_09,ask_ct_09
2025-07-17T08:05:03.360677248Z,2025-07-17T08:05:03.360842448Z,160,2,1108,A,B,0,5.51,100,130,165200,851012,ARL,817593,5.51,100,1,,,,,,,,,,,,,,,,,,,,,,,,,,,,,,,,,,,,,,,,,,,,,,,,,,,,,,,,,
2025-07-17T08:05:03.360683462Z,2025-07-17T08:05:03.360848793Z,160,2,1108,A,A,0,21.33,100,130,165331,851013,ARL,817597,5.51,100,1,21.33,100,1,,,,,,,,,,,,,,,,,,,,,,,,,,,,,,,,,,,,,,,,,,,,,,,,,,,,,,
2025-07-17T08:05:03.361327319Z,2025-07-17T08:05:03.361492517Z,160,2,1108,A,B,0,5.9,100,130,165198,851022,ARL,817633,5.9,100,1,21.33,100,1,5.51,100,1,,,,,,,,,,,,,,,,,,,,,,,,,,,,,,,,,,,,,,,,,,,,,,,,,,,
2025-07-17T08:05:03.361332576Z,2025-07-17T08:05:03.361497823Z,160,2,1108,A,A,0,20.94,100,130,165247,851023,ARL,817637,5.9,100,1,20.94,100,1,5.51,100,1,21.33,100,1,,,,,,,,,,,,,,,,,,,,,,,,,,,,,,,,,,,,,,,,,,,,,,,,
2025-07-17T08:09:48.860696464Z,2025-07-17T08:09:48.860862095Z,160,2,1108,C,B,0,5.51,100,130,165631,1289631,ARL,817593,5.9,100,1,20.94,100,1,,,,21.33,100,1,,,,,,,,,,,,,,,,,,,,,,,,,,,,,,,,,,,,,,,,,,,,,,,,
2025-07-17T08:09:48.860705588Z,2025-07-17T08:09:48.860870885Z,160,2,1108,A,B,0,5.37,100,130,165297,1289632,ARL,1263973,5.9,100,1,20.94,100,1,5.37,100,1,21.33,100,1,,,,,,,,,,,,,,,,,,,,,,,,,,,,,,,,,,,,,,,,,,,,,,,,
2025-07-17T08:09:49.157896784Z,2025-07-17T08:09:49.158061899Z,160,2,1108,C,B,0,5.9,100,130,165115,1290626,ARL,817633,5.37,100,1,20.94,100,1,,,,21.33,100,1,,,,,,,,,,,,,,,,,,,,,,,,,,,,,,,,,,,,,,,,,,,,,,,,
2025-07-17T08:09:49.157903443Z,2025-07-17T08:09:49.158069452Z,160,2,1108,A,B,0,5.4,100,0,166009,1290627,ARL,1264721,5.4,100,1,20.94,100,1,5.37,100,1,21.33,100,1,,,,,,,,,,,,,,,,,,,,,,,,,,,,,,,,,,,,,,,,,,,,,,,,
2025-07-17T08:09:49.157903798Z,2025-07-17T08:09:49.158069452Z,160,2,1108,C,A,0,20.94,100,130,165654,1290628,ARL,817637,5.4,100,1,21.33,100,1,5.37,100,1,,,,,,,,,,,,,,,,,,,,,,,,,,,,,,,,,,,,,,,,,,,,,,,,,,,
2025-07-17T08:09:49.157909054Z,2025-07-17T08:09:49.158074599Z,160,2,1108,A,A,0,21.47,100,130,165545,1290629,ARL,1264725,5.4,100,1,21.33,100,1,5.37,100,1,21.47,100,1,,,,,,,,,,,,,,,,,,,,,,,,,,,,,,,,,,,,,,,,,,,,,,,,
2025-07-17T11:00:00.125174985Z,2025-07-17T11:00:00.125340914Z,160,2,1108,C,B,0,5.37,100,130,165929,10583317,ARL,1263973,5.4,100,1,21.33,100,1,,,,21.47,100,1,,,,,,,,,,,,,,,,,,,,,,,,,,,,,,,,,,,,,,,,,,,,,,,,
2025-07-17T11:00:00.125182048Z,2025-07-17T11:00:00.125347247Z,160,2,1108,A,B,0,9.79,100,130,165199,10583320,ARL,12852457,9.79,100,1,21.33,100,1,5.4,100,1,21.47,100,1,,,,,,,,,,,,,,,,,,,,,,,,,,,,,,,,,,,,,,,,,,,,,,,,
2025-07-17T11:00:00.125454029Z,2025-07-17T11:00:00.125619742Z,160,2,1108,C,B,0,5.4,100,130,165713,10583363,ARL,1264721,9.79,100,1,21.33,100,1,,,,21.47,100,1,,,,,,,,,,,,,,,,,,,,,,,,,,,,,,,,,,,,,,,,,,,,,,,,
2025-07-17T11:00:00.125460962Z,2025-07-17T11:00:00.125626050Z,160,2,1108,A,B,0,9.84,100,130,165088,10583364,ARL,12852537,9.84,100,1,21.33,100,1,9.79,100,1,21.47,100,1,,,,,,,,,,,,,,,,,,,,,,,,,,,,,,,,,,,,,,,,,,,,,,,,
2025-07-17T11:00:07.975824831Z,2025-07-17T11:00:07.975990221Z,160,2,1108,C,A,0,21.33,100,130,165390,10674471,ARL,817597,9.84,100,1,21.47,100,1,9.79,100,1,,,,,,,,,,,,,,,,,,,,,,,,,,,,,,,,,,,,,,,,,,,,,,,,,,,
2025-07-17T11:00:07.975837956Z,2025-07-17T11:00:07.976003383Z,160,2,1108,A,A,0,17.44,100,130,165427,10674472,ARL,12983425,9.84,100,1,17.44,100,1,9.79,100,1,21.47,100,1,,,,,,,,,,,,,,,,,,,,,,,,,,,,,,,,,,,,,,,,,,,,,,,,
2025-07-17T11:00:07.975972618Z,2025-07-17T11:00:07.976138102Z,160,2,1108,C,A,0,21.47,100,130,165484,10674473,ARL,1264725,9.84,100,1,17.44,100,1,9.79,100,1,,,,,,,,,,,,,,,,,,,,,,,,,,,,,,,,,,,,,,,,,,,,,,,,,,,
2025-07-17T11:00:07.975979367Z,2025-07-17T11:00:07.976144724Z,160,2,1108,A,A,0,17.36,100,130,165357,10674474,ARL,12983429,9.84,100,1,17.36,100,1,9.79,100,1,17.44,100,1,,,,,,,,,,,,,,,,,,,,,,,,,,,,,,,,,,,,,,,,,,,,,,,,
2025-07-17T11:00:08.254975294Z,2025-07-17T11:00:08.255140498Z,160,2,1108,C,A,0,17.44,100,130,165204,10676310,ARL,12983425,9.84,100,1,17.36,100,1,9.79,100,1,,,,,,,,,,,,,,,,,,,,,,,,,,,,,,,,,,,,,,,,,,,,,,,,,,,
2025-07-17T11:00:08.254985173Z,2025-07-17T11:00:08.255150459Z,160,2,1108,A,A,0,18.92,100,130,165286,10676311,ARL,12985397,9.84,100,1,17.36,100,1,9.79,100,1,18.92,100,1,,,,,,,,,,,,,,,,,,,,,,,,,,,,,,,,,,,,,,,,,,,,,,,,
2025-07-17T11:00:08.255147130Z,2025-07-17T11:00:08.255312226Z,160,2,1108,C,A,0,17.36,100,130,165096,10676314,ARL,12983429,9.84,100,1,18.92,100,1,9.79,100,1,,,,,,,,,,,,,,,,,,,,,,,,,,,,,,,,,,,,,,,,,,,,,,,,,,,
2025-07-17T11:00:08.255155317Z,2025-07-17T11:00:08.255320414Z,160,2,1108,A,A,0,18.84,100,130,165097,10676315,ARL,12985401,9.84,100,1,18.84,100,1,9.79,100,1,18.92,100,1,,,,,,,,,,,,,,,,,,,,,,,,,,,,,,,,,,,,,,,,,,,,,,,,
2025-07-17T11:00:08.255862656Z,2025-07-17T11:00:08.256027692Z,160,2,1108,C,A,0,18.92,100,130,165036,10676320,ARL,12985397,9.84,100,1,18.84,100,1,9.79,100,1,,,,,,,,,,,,,,,,,,,,,,,,,,,,,,,,,,,,,,,,,,,,,,,,,,,
2025-07-17T11:00:08.255871843Z,2025-07-17T11:00:08.256037075Z,160,2,1108,A,A,0,20.62,100,130,165232,10676321,ARL,12985405,9.84,100,1,18.84,100,1,9.79,100,1,20.62,100,1,,,,,,,,,,,,,,,,,,,,,,,,,,,,,,,,,,,,,,,,,,,,,,,,
2025-07-17T11:00:08.256168895Z,2025-07-17T11:00:08.256333906Z,160,2,1108,C,A,0,18.84,100,130,165011,10676324,ARL,12985401,9.84,100,1,20.62,100,1,9.79,100,1,,,,,,,,,,,,,,,,,,,,,,,,,,,,,,,,,,,,,,,,,,,,,,,,,,,
2025-07-17T11:00:08.256175346Z,2025-07-17T11:00:08.256340615Z,160,2,1108,A,A,0,20.53,100,130,165269,10676325,ARL,12985413,9.84,100,1,20.53,100,1,9.79,100,1,20.62,100,1,,,,,,,,,,,,,,,,,,,,,,,,,,,,,,,,,,,,,,,,,,,,,,,,
2025-07-17T11:00:08.256885010Z,2025-07-17T11:00:08.257050282Z,160,2,1108,C,A,0,20.62,100,130,165272,10676333,ARL,12985405,9.84,100,1,20.53,100,1,9.79,100,1,,,,,,,,,,,,,,,,,,,,,,,,,,,,,,,,,,,,,,,,,,,,,,,,,,,
2025-07-17T11:00:08.256892686Z,2025-07-17T11:00:08.257058070Z,160,2,1108,A,A,0,21.47,100,130,165384,10676334,ARL,12985417,9.84,100,1,20.53,100,1,9.79,100,1,21.47,100,1,,,,,,,,,,,,,,,,,,,,,,,,,,,,,,,,,,,,,,,,,,,,,,,,
2025-07-17T11:00:08.257069458Z,2025-07-17T11:00:08.257234812Z,160,2,1108,C,A,0,20.53,100,130,165354,10676335,ARL,12985413,9.84,100,1,21.47,100,1,9.79,100,1,,,,,,,,,,,,,,,,,,,,,,,,,,,,,,,,,,,,,,,,,,,,,,,,,,,
2025-07-17T11:00:08.257076085Z,2025-07-17T11:00:08.257241334Z,160,2,1108,A,A,0,21.47,100,130,165249,10676336,ARL,12985421,9.84,100,1,21.47,200,2,9.79,100,1,,,,,,,,,,,,,,,,,,,,,,,,,,,,,,,,,,,,,,,,,,,,,,,,,,,
2025-07-17T11:01:05.260421351Z,2025-07-17T11:01:05.260586668Z,160,2,1108,C,A,0,21.47,100,130,165317,10824633,ARL,12985417,9.84,100,1,21.47,100,1,9.79,100,1,,,,,,,,,,,,,,,,,,,,,,,,,,,,,,,,,,,,,,,,,,,,,,,,,,,
2025-07-17T11:01:05.260445703Z,2025-07-17T11:01:05.260611137Z,160,2,1108,A,A,0,17.44,100,130,165434,10824634,ARL,13174157,9.84,100,1,17.44,100,1,9.79,100,1,21.47,100,1,,,,,,,,,,,,,,,,,,,,,,,,,,,,,,,,,,,,,,,,,,,,,,,,
2025-07-17T11:01:05.260693130Z,2025-07-17T11:01:05.260858436Z,160,2,1108,C,A,0,21.47,100,130,165306,10824635,ARL,12985421,9.84,100,1,17.44,100,1,9.79,100,1,,,,,,,,,,,,,,,,,,,,,,,,,,,,,,,,,,,,,,,,,,,,,,,,,,,
2025-07-17T11:01:05.260709480Z,2025-07-17T11:01:05.260874630Z,160,2,1108,A,A,0,17.36,100,130,165150,10824636,ARL,13174161,9.84,100,1,17.36,100,1,9.79,100,1,17.44,100,1,,,,,,,,,,,,,,,,,,,,,,,,,,,,,,,,,,,,,,,,,,,,,,,,
2025-07-17T11:56:26.691461161Z,2025-07-17T11:56:26.691626843Z,160,2,1108,C,B,0,9.79,100,130,165682,14213017,ARL,12852457,9.84,100,1,17.36,100,1,,,,17.44,100,1,,,,,,,,,,,,,,,,,,,,,,,,,,,,,,,,,,,,,,,,,,,,,,,,
2025-07-17T11:56:26.691465204Z,2025-07-17T11:56:26.691630539Z,160,2,1108,C,A,0,17.44,100,130,165335,14213018,ARL,13174157,9.84,100,1,17.36,100,1,,,,,,,,,,,,,,,,,,,,,,,,,,,,,,,,,,,,,,,,,,,,,,,,,,,,,,
2025-07-17T11:56:26.694767820Z,2025-07-17T11:56:26.694933250Z,160,2,1108,A,B,0,9.79,100,130,165430,14213075,ARL,19202569,9.84,100,1,17.36,100,1,9.79,100,1,,,,,,,,,,,,,,,,,,,,,,,,,,,,,,,,,,,,,,,,,,,,,,,,,,,
2025-07-17T11:56:26.694772016Z,2025-07-17T11:56:26.694937361Z,160,2,1108,A,A,0,17.44,100,130,165345,14213076,ARL,19202573,9.84,100,1,17.36,100,1,9.79,100,1,17.44,100,1,,,,,,,,,,,,,,,,,,,,,,,,,,,,,,,,,,,,,,,,,,,,,,,,
2025-07-17T11:56:30.445937099Z,2025-07-17T11:56:30.446102409Z,160,2,1108,C,A,0,17.44,100,130,165310,14219824,ARL,19202573,9.84,100,1,17.36,100,1,9.79,100,1,,,,,,,,,,,,,,,,,,,,,,,,,,,,,,,,,,,,,,,,,,,,,,,,,,,
2025-07-17T11:56:30.445951937Z,2025-07-17T11:56:30.446117449Z,160,2,1108,A,A,0,17.93,100,130,165512,14219825,ARL,19218909,9.84,100,1,17.36,100,1,9.79,100,1,17.93,100,1,,,,,,,,,,,,,,,,,,,,,,,,,,,,,,,,,,,,,,,,,,,,,,,,
2025-07-17T11:56:30.446066952Z,2025-07-17T11:56:30.446231965Z,160,2,1108,C,A,0,17.93,100,130,165013,14219826,ARL,19218909,9.84,100,1,17.36,100,1,9.79,100,1,,,,,,,,,,,,,,,,,,,,,,,,,,,,,,,,,,,,,,,,,,,,,,,,,,,
2025-07-17T11:56:30.446084801Z,2025-07-17T11:56:30.446250148Z,160,2,1108,A,A,0,17.44,100,130,165347,14219827,ARL,19218913,9.84,100,1,17.36,100,1,9.79,100,1,17.44,100,1,,,,,,,,,,,,,,,,,,,,,,,,,,,,,,,,,,,,,,,,,,,,,,,,
2025-07-17T11:56:30.446191769Z,2025-07-17T11:56:30.446357192Z,160,2,1108,C,A,0,17.36,100,130,165423,14219828,ARL,13174161,9.84,100,1,17.44,100,1,9.79,100,1,,,,,,,,,,,,,,,,,,,,,,,,,,,,,,,,,,,,,,,,,,,,,,,,,,,
2025-07-17T11:56:30.446213519Z,2025-07-17T11:56:30.446379036Z,160,2,1108,A,A,0,17.85,100,130,165517,14219829,ARL,19218917,9.84,100,1,17.44,100,1,9.79,100,1,17.85,100,1,,,,,,,,,,,,,,,,,,,,,,,,,,,,,,,,,,,,,,,,,,,,,,,,
2025-07-17T11:56:30.446378732Z,2025-07-17T11:56:30.446543637Z,160,2,1108,C,A,0,17.85,100,130,164905,14219830,ARL,19218917,9.84,100,1,17.44,100,1,9.79,100,1,,,,,,,,,,,,,,,,,,,,,,,,,,,,,,,,,,,,,,,,,,,,,,,,,,,
2025-07-17T11:56:30.446558412Z,2025-07-17T11:56:30.446723646Z,160,2,1108,A,A,0,17.36,100,130,165234,14219831,ARL,19218921,9.84,100,1,17.36,100,1,9.79,100,1,17.44,100,1,,,,,,,,,,,,,,,,,,,,,,,,,,,,,,,,,,,,,,,,,,,,,,,,
2025-07-17T11:57:30.222822537Z,2025-07-17T11:57:30.222987797Z,160,2,1108,C,B,0,9.84,100,130,165260,14325877,ARL,12852537,9.79,100,1,17.36,100,1,,,,17.44,100,1,,,,,,,,,,,,,,,,,,,,,,,,,,,,,,,,,,,,,,,,,,,,,,,,
2025-07-17T11:57:30.222823580Z,2025-07-17T11:57:30.222988778Z,160,2,1108,C,A,0,17.36,100,130,165198,14325878,ARL,19218921,9.79,100,1,17.44,100,1,,,,,,,,,,,,,,,,,,,,,,,,,,,,,,,,,,,,,,,,,,,,,,,,,,,,,,
2025-07-17T11:57:30.223986626Z,2025-07-17T11:57:30.224151967Z,160,2,1108,A,B,0,9.84,100,130,165341,14325937,ARL,19346173,9.84,100,1,17.44,100,1,9.79,100,1,,,,,,,,,,,,,,,,,,,,,,,,,,,,,,,,,,,,,,,,,,,,,,,,,,,
2025-07-17T11:57:30.223991040Z,2025-07-17T11:57:30.224156146Z,160,2,1108,A,A,0,17.36,100,130,165106,14325938,ARL,19346177,9.84,100,1,17.36,100,1,9.79,100,1,17.44,100,1,,,,,,,,,,,,,,,,,,,,,,,,,,,,,,,,,,,,,,,,,,,,,,,,
2025-07-17T12:30:01.317842911Z,2025-07-17T12:30:01.318008785Z,160,2,1108,A,A,0,20.48,100,130,165874,16864046,ARL,23570297,9.84,100,1,17.36,100,1,9.79,100,1,17.44,100,1,,,,20.48,100,1,,,,,,,,,,,,,,,,,,,,,,,,,,,,,,,,,,,,,,,,,,
2025-07-17T12:30:03.426300621Z,2025-07-17T12:30:03.426465857Z,160,2,1108,A,B,0,7.74,100,130,165236,16882670,ARL,23616197,9.84,100,1,17.36,100,1,9.79,100,1,17.44,100,1,7.74,100,1,20.48,100,1,,,,,,,,,,,,,,,,,,,,,,,,,,,,,,,,,,,,,,,,,,
2025-07-17T12:30:03.426301523Z,2025-07-17T12:30:03.426466862Z,160,2,1108,A,A,0,20.48,100,130,165339,16882671,ARL,23616201,9.84,100,1,17.36,100,1,9.79,100,1,17.44,100,1,7.74,100,1,20.48,200,2,,,,,,,,,,,,,,,,,,,,,,,,,,,,,,,,,,,,,,,,,,
2025-07-17T12:30:03.604533925Z,2025-07-17T12:30:03.604699168Z,160,2,1108,A,B,0,7.74,100,130,165243,16886020,ARL,23622101,9.84,100,1,17.36,100,1,9.79,100,1,17.44,100,1,7.74,200,2,20.48,200,2,,,,,,,,,,,,,,,,,,,,,,,,,,,,,,,,,,,,,,,,,,
2025-07-17T12:30:51.178228608Z,2025-07-17T12:30:51.178394233Z,160,2,1108,A,A,0,20.48,100,130,165625,17120703,ARL,24099409,9.84,100,1,17.36,100,1,9.79,100,1,17.44,100,1,7.74,200,2,20.48,300,3,,,,,,,,,,,,,,,,,,,,,,,,,,,,,,,,,,,,,,,,,,
2025-07-17T12:30:51.642959794Z,2025-07-17T12:30:51.643125167Z,160,2,1108,A,B,0,7.74,100,130,165373,17122998,ARL,24102329,9.84,100,1,17.36,100,1,9.79,100,1,17.44,100,1,7.74,300,3,20.48,300,3,,,,,,,,,,,,,,,,,,,,,,,,,,,,,,,,,,,,,,,,,,
2025-07-17T13:15:00.032446132Z,2025-07-17T13:15:00.032611736Z,160,2,1108,C,A,0,17.44,100,130,165604,23080007,ARL,19218913,9.84,100,1,17.36,100,1,9.79,100,1,20.48,300,3,7.74,300,3,,,,,,,,,,,,,,,,,,,,,,,,,,,,,,,,,,,,,,,,,,,,,
2025-07-17T13:15:00.032483824Z,2025-07-17T13:15:00.032651211Z,160,2,1108,C,B,0,9.79,100,128,167387,23080041,ARL,19202569,9.84,100,1,17.36,100,1,7.74,300,3,20.48,300,3,,,,,,,,,,,,,,,,,,,,,,,,,,,,,,,,,,,,,,,,,,,,,,,,
2025-07-17T13:15:00.058314138Z,2025-07-17T13:15:00.058480238Z,160,2,1108,C,A,0,17.36,100,128,166100,23101369,ARL,19346177,9.84,100,1,20.48,300,3,7.74,300,3,,,,,,,,,,,,,,,,,,,,,,,,,,,,,,,,,,,,,,,,,,,,,,,,,,,
2025-07-17T13:15:00.058371545Z,2025-07-17T13:15:00.058537384Z,160,2,1108,C,B,0,9.84,100,130,165839,23101396,ARL,19346173,7.74,300,3,20.48,300,3,,,,,,,,,,,,,,,,,,,,,,,,,,,,,,,,,,,,,,,,,,,,,,,,,,,,,,
2025-07-17T13:15:01.925073727Z,2025-07-17T13:15:01.925239044Z,160,2,1108,A,B,0,7.74,100,130,165317,23123943,ARL,31960841,7.74,400,4,20.48,300,3,,,,,,,,,,,,,,,,,,,,,,,,,,,,,,,,,,,,,,,,,,,,,,,,,,,,,,
2025-07-17T13:15:02.042741730Z,2025-07-17T13:15:02.042906947Z,160,2,1108,A,A,0,20.48,100,130,165217,23124563,ARL,31962113,7.74,400,4,20.48,400,4,,,,,,,,,,,,,,,,,,,,,,,,,,,,,,,,,,,,,,,,,,,,,,,,,,,,,,
2025-07-17T13:17:49.831164624Z,2025-07-17T13:17:49.831329888Z,160,2,1108,A,B,0,7.74,100,130,165264,23465434,ARL,33574717,7.74,500,5,20.48,400,4,,,,,,,,,,,,,,,,,,,,,,,,,,,,,,,,,,,,,,,,,,,,,,,,,,,,,,
2025-07-17T13:17:49.831544051Z,2025-07-17T13:17:49.831709365Z,160,2,1108,A,A,0,20.48,100,130,165314,23465435,ARL,33574725,7.74,500,5,20.48,500,5,,,,,,,,,,,,,,,,,,,,,,,,,,,,,,,,,,,,,,,,,,,,,,,,,,,,,,
2025-07-17T13:19:57.597203040Z,2025-07-17T13:19:57.597368321Z,160,2,1108,A,B,0,8.74,100,130,165281,23710201,ARL,34790041,8.74,100,1,20.48,500,5,7.74,500,5,,,,,,,,,,,,,,,,,,,,,,,,,,,,,,,,,,,,,,,,,,,,,,,,,,,
2025-07-17T13:19:57.597291053Z,2025-07-17T13:19:57.597456270Z,160,2,1108,A,A,0,18.35,100,130,165217,23710202,ARL,34790045,8.74,100,1,18.35,100,1,7.74,500,5,20.48,500,5,,,,,,,,,,,,,,,,,,,,,,,,,,,,,,,,,,,,,,,,,,,,,,,,
2025-07-17T13:19:58.492619751Z,2025-07-17T13:19:58.492785060Z,160,2,1108,A,A,0,18.24,100,130,165309,23728432,ARL,34810233,8.74,100,1,18.24,100,1,7.74,500,5,18.35,100,1,,,,20.48,500,5,,,,,,,,,,,,,,,,,,,,,,,,,,,,,,,,,,,,,,,,,,
2025-07-17T13:19:58.492634480Z,2025-07-17T13:19:58.492799826Z,160,2,1108,A,B,0,9.24,100,130,165346,23728435,ARL,34810241,9.24,100,1,18.24,100,1,8.74,100,1,18.35,100,1,7.74,500,5,20.48,500,5,,,,,,,,,,,,,,,,,,,,,,,,,,,,,,,,,,,,,,,,,,
2025-07-17T13:20:00.525263842Z,2025-07-17T13:20:00.525430361Z,160,2,1108,C,A,0,18.24,100,0,166519,23765825,ARL,34810233,9.24,100,1,18.35,100,1,8.74,100,1,20.48,500,5,7.74,500,5,,,,,,,,,,,,,,,,,,,,,,,,,,,,,,,,,,,,,,,,,,,,,
2025-07-17T13:20:00.525264700Z,2025-07-17T13:20:00.525430361Z,160,2,1108,C,B,0,9.24,100,130,165661,23765826,ARL,34810241,8.74,100,1,18.35,100,1,7.74,500,5,20.48,500,5,,,,,,,,,,,,,,,,,,,,,,,,,,,,,,,,,,,,,,,,,,,,,,,,
2025-07-17T13:25:00.157467184Z,2025-07-17T13:25:00.157632223Z,160,2,1108,C,B,0,8.74,100,130,165039,24448205,ARL,34790041,7.74,500,5,18.35,100,1,,,,20.48,500,5,,,,,,,,,,,,,,,,,,,,,,,,,,,,,,,,,,,,,,,,,,,,,,,,
2025-07-17T13:25:00.157473422Z,2025-07-17T13:25:00.157638512Z,160,2,1108,C,A,0,18.35,100,130,165090,24448207,ARL,34790045,7.74,500,5,20.48,500,5,,,,,,,,,,,,,,,,,,,,,,,,,,,,,,,,,,,,,,,,,,,,,,,,,,,,,,
2025-07-17T13:25:01.732320109Z,2025-07-17T13:25:01.732485386Z,160,2,1108,A,B,0,7.74,100,130,165277,24478872,ARL,38041417,7.74,600,6,20.48,500,5,,,,,,,,,,,,,,,,,,,,,,,,,,,,,,,,,,,,,,,,,,,,,,,,,,,,,,
2025-07-17T13:25:01.819282823Z,2025-07-17T13:25:01.819447960Z,160,2,1108,A,A,0,20.48,100,130,165137,24480276,ARL,38043741,7.74,600,6,20.48,600,6,,,,,,,,,,,,,,,,,,,,,,,,,,,,,,,,,,,,,,,,,,,,,,,,,,,,,,
2025-07-17T13:28:08.191915168Z,2025-07-17T13:28:08.192080463Z,160,2,1108,A,B,0,7.74,100,130,165295,25597187,ARL,40617777,7.74,700,7,20.48,600,6,,,,,,,,,,,,,,,,,,,,,,,,,,,,,,,,,,,,,,,,,,,,,,,,,,,,,,
2025-07-17T13:28:08.191982270Z,2025-07-17T13:28:08.192147601Z,160,2,1108,A,A,0,20.48,100,130,165331,25597189,ARL,40617785,7.74,700,7,20.48,700,7,,,,,,,,,,,,,,,,,,,,,,,,,,,,,,,,,,,,,,,,,,,,,,,,,,,,,,
2025-07-17T13:28:21.011249114Z,2025-07-17T13:28:21.011414592Z,160,2,1108,A,A,0,18.32,700,130,165478,25907820,ARL,40846101,7.74,700,7,18.32,700,1,,,,20.48,700,7,,,,,,,,,,,,,,,,,,,,,,,,,,,,,,,,,,,,,,,,,,,,,,,,
2025-07-17T13:28:21.028865155Z,2025-07-17T13:28:21.029030365Z,160,2,1108,A,B,0,9.29,700,130,165210,25917006,ARL,40851989,9.29,700,1,18.32,700,1,7.74,700,7,20.48,700,7,,,,,,,,,,,,,,,,,,,,,,,,,,,,,,,,,,,,,,,,,,,,,,,,
2025-07-17T13:28:30.048730211Z,2025-07-17T13:28:30.048895468Z,160,2,1108,A,B,0,9.67,100,130,165257,26140646,ARL,40999441,9.67,100,1,18.32,700,1,9.29,700,1,20.48,700,7,7.74,700,7,,,,,,,,,,,,,,,,,,,,,,,,,,,,,,,,,,,,,,,,,,,,,
2025-07-17T13:28:30.048741690Z,2025-07-17T13:28:30.048907452Z,160,2,1108,A,A,0,17.6,100,130,165762,26140658,ARL,40999449,9.67,100,1,17.6,100,1,9.29,700,1,18.32,700,1,7.74,700,7,20.48,700,7,,,,,,,,,,,,,,,,,,,,,,,,,,,,,,,,,,,,,,,,,,
2025-07-17T13:28:30.051894007Z,2025-07-17T13:28:30.052061798Z,160,2,1108,A,B,0,9.99,100,130,167791,26142104,ARL,41000165,9.99,100,1,17.6,100,1,9.67,100,1,18.32,700,1,9.29,700,1,20.48,700,7,7.74,700,7,,,,,,,,,,,,,,,,,,,,,,,,,,,,,,,,,,,,,,,
2025-07-17T13:28:30.051907073Z,2025-07-17T13:28:30.052072568Z,160,2,1108,A,A,0,17.12,100,130,165495,26142118,ARL,41000173,9.99,100,1,17.12,100,1,9.67,100,1,17.6,100,1,9.29,700,1,18.32,700,1,7.74,700,7,20.48,700,7,,,,,,,,,,,,,,,,,,,,,,,,,,,,,,,,,,,,
2025-07-17T13:28:30.256853564Z,2025-07-17T13:28:30.257018844Z,160,2,1108,A,B,0,9.67,100,130,165280,26170917,ARL,41021369,9.99,100,1,17.12,100,1,9.67,200,2,17.6,100,1,9.29,700,1,18.32,700,1,7.74,700,7,20.48,700,7,,,,,,,,,,,,,,,,,,,,,,,,,,,,,,,,,,,,
2025-07-17T13:28:30.256865858Z,2025-07-17T13:28:30.257031156Z,160,2,1108,A,A,0,17.6,100,130,165298,26170918,ARL,41021373,9.99,100,1,17.12,100,1,9.67,200,2,17.6,200,2,9.29,700,1,18.32,700,1,7.74,700,7,20.48,700,7,,,,,,,,,,,,,,,,,,,,,,,,,,,,,,,,,,,,
2025-07-17T13:28:30.277457031Z,2025-07-17T13:28:30.277622346Z,160,2,1108,A,B,0,9.99,100,130,165315,26171531,ARL,41021837,9.99,200,2,17.12,100,1,9.67,200,2,17.6,200,2,9.29,700,1,18.32,700,1,7.74,700,7,20.48,700,7,,,,,,,,,,,,,,,,,,,,,,,,,,,,,,,,,,,,
2025-07-17T13:28:30.277470320Z,2025-07-17T13:28:30.277635645Z,160,2,1108,A,A,0,17.12,100,130,165325,26171533,ARL,41021841,9.99,200,2,17.12,200,2,9.67,200,2,17.6,200,2,9.29,700,1,18.32,700,1,7.74,700,7,20.48,700,7,,,,,,,,,,,,,,,,,,,,,,,,,,,,,,,,,,,,
2025-07-17T13:28:30.613317490Z,2025-07-17T13:28:30.613482667Z,160,2,1108,A,B,0,9.13,100,130,165177,26182390,ARL,41032049,9.99,200,2,17.12,200,2,9.67,200,2,17.6,200,2,9.29,700,1,18.32,700,1,9.13,100,1,20.48,700,7,7.74,700,7,,,,,,,,,,,,,,,,,,,,,,,,,,,,,,,,,
2025-07-17T13:28:30.613329849Z,2025-07-17T13:28:30.613495057Z,160,2,1108,A,A,0,18.4,100,130,165208,26182393,ARL,41032057,9.99,200,2,17.12,200,2,9.67,200,2,17.6,200,2,9.29,700,1,18.32,700,1,9.13,100,1,18.4,100,1,7.74,700,7,20.48,700,7,,,,,,,,,,,,,,,,,,,,,,,,,,,,,,
2025-07-17T13:28:41.476711173Z,2025-07-17T13:28:41.476876547Z,160,2,1108,A,B,0,7.84,100,130,165374,26518296,ARL,41306441,9.99,200,2,17.12,200,2,9.67,200,2,17.6,200,2,9.29,700,1,18.32,700,1,9.13,100,1,18.4,100,1,7.84,100,1,20.48,700,7,7.74,700,7,,,,,,,,,,,,,,,,,,,,,,,,,,,
2025-07-17T13:28:41.476722715Z,2025-07-17T13:28:41.476887975Z,160,2,1108,A,A,0,20.32,100,130,165260,26518297,ARL,41306445,9.99,200,2,17.12,200,2,9.67,200,2,17.6,200,2,9.29,700,1,18.32,700,1,9.13,100,1,18.4,100,1,7.84,100,1,20.32,100,1,7.74,700,7,20.48,700,7,,,,,,,,,,,,,,,,,,,,,,,,
2025-07-17T13:28:46.014739305Z,2025-07-17T13:28:46.014904874Z,160,2,1108,A,A,0,15.3,100,130,165569,26613800,ARL,41370837,9.99,200,2,15.3,100,1,9.67,200,2,17.12,200,2,9.29,700,1,17.6,200,2,9.13,100,1,18.32,700,1,7.84,100,1,18.4,100,1,7.74,700,7,20.32,100,1,,,,20.48,700,7,,,,,,,,,,,,,,,,,,
2025-07-17T13:28:46.014802018Z,2025-07-17T13:28:46.014968000Z,160,2,1108,C,A,0,20.48,100,0,165982,26613836,ARL,23570297,9.99,200,2,15.3,100,1,9.67,200,2,17.12,200,2,9.29,700,1,17.6,200,2,9.13,100,1,18.32,700,1,7.84,100,1,18.4,100,1,7.74,700,7,20.32,100,1,,,,20.48,600,6,,,,,,,,,,,,,,,,,,
2025-07-17T13:28:46.014802018Z,2025-07-17T13:28:46.014968000Z,160,2,1108,A,A,0,19.58,100,130,165982,26613836,ARL,41370945,9.99,200,2,15.3,100,1,9.67,200,2,17.12,200,2,9.29,700,1,17.6,200,2,9.13,100,1,18.32,700,1,7.84,100,1,18.4,100,1,7.74,700,7,19.58,100,1,,,,20.32,100,1,,,,20.48,600,6,,,,,,,,,,,,
2025-07-17T13:28:46.014803011Z,2025-07-17T13:28:46.014969135Z,160,2,1108,C,A,0,20.48,100,0,166124,26613837,ARL,23616201,9.99,200,2,15.3,100,1,9.67,200,2,17.12,200,2,9.29,700,1,17.6,200,2,9.13,100,1,18.32,700,1,7.84,100,1,18.4,100,1,7.74,700,7,19.58,100,1,,,,20.32,100,1,,,,20.48,500,5,,,,,,,,,,,,
2025-07-17T13:28:46.014803011Z,2025-07-17T13:28:46.014969135Z,160,2,1108,A,A,0,19.58,100,130,166124,26613837,ARL,41370949,9.99,200,2,15.3,100,1,9.67,200,2,17.12,200,2,9.29,700,1,17.6,200,2,9.13,100,1,18.32,700,1,7.84,100,1,18.4,100,1,7.74,700,7,19.58,200,2,,,,20.32,100,1,,,,20.48,500,5,,,,,,,,,,,,
2025-07-17T13:28:46.014804158Z,2025-07-17T13:28:46.014970699Z,160,2,1108,C,A,0,20.48,100,0,166541,26613838,ARL,24099409,9.99,200,2,15.3,100,1,9.67,200,2,17.12,200,2,9.29,700,1,17.6,200,2,9.13,100,1,18.32,700,1,7.84,100,1,18.4,100,1,7.74,700,7,19.58,200,2,,,,20.32,100,1,,,,20.48,400,4,,,,,,,,,,,,
2025-07-17T13:28:46.014804158Z,2025-07-17T13:28:46.014970699Z,160,2,1108,A,A,0,19.58,100,0,166541,26613838,ARL,41370953,9.99,200,2,15.3,100,1,9.67,200,2,17.12,200,2,9.29,700,1,17.6,200,2,9.13,100,1,18.32,700,1,7.84,100,1,18.4,100,1,7.74,700,7,19.58,300,3,,,,20.32,100,1,,,,20.48,400,4,,,,,,,,,,,,
2025-07-17T13:28:46.014804564Z,2025-07-17T13:28:46.014970699Z,160,2,1108,C,A,0,20.48,100,0,166135,26613839,ARL,31962113,9.99,200,2,15.3,100,1,9.67,200,2,17.12,200,2,9.29,700,1,17.6,200,2,9.13,100,1,18.32,700,1,7.84,100,1,18.4,100,1,7.74,700,7,19.58,300,3,,,,20.32,100,1,,,,20.48,300,3,,,,,,,,,,,,
2025-07-17T13:28:46.014804564Z,2025-07-17T13:28:46.014970699Z,160,2,1108,A,A,0,19.58,100,130,166135,26613839,ARL,41370957,9.99,200,2,15.3,100,1,9.67,200,2,17.12,200,2,9.29,700,1,17.6,200,2,9.13,100,1,18.32,700,1,7.84,100,1,18.4,100,1,7.74,700,7,19.58,400,4,,,,20.32,100,1,,,,20.48,300,3,,,,,,,,,,,,
2025-07-17T13:28:46.014805680Z,2025-07-17T13:28:46.014972151Z,160,2,1108,C,A,0,20.48,100,0,166471,26613840,ARL,33574725,9.99,200,2,15.3,100,1,9.67,200,2,17.12,200,2,9.29,700,1,17.6,200,2,9.13,100,1,18.32,700,1,7.84,100,1,18.4,100,1,7.74,700,7,19.58,400,4,,,,20.32,100,1,,,,20.48,200,2,,,,,,,,,,,,
2025-07-17T13:28:46.014805680Z,2025-07-17T13:28:46.014972151Z,160,2,1108,A,A,0,19.58,100,0,166471,26613840,ARL,41370961,9.99,200,2,15.3,100,1,9.67,200,2,17.12,200,2,9.29,700,1,17.6,200,2,9.13,100,1,18.32,700,1,7.84,100,1,18.4,100,1,7.74,700,7,19.58,500,5,,,,20.32,100,1,,,,20.48,200,2,,,,,,,,,,,,
2025-07-17T13:28:46.014805841Z,2025-07-17T13:28:46.014972151Z,160,2,1108,C,A,0,20.48,100,0,166310,26613841,ARL,38043741,9.99,200,2,15.3,100,1,9.67,200,2,17.12,200,2,9.29,700,1,17.6,200,2,9.13,100,1,18.32,700,1,7.84,100,1,18.4,100,1,7.74,700,7,19.58,500,5,,,,20.32,100,1,,,,20.48,100,1,,,,,,,,,,,,
2025-07-17T13:28:46.014805841Z,2025-07-17T13:28:46.014972151Z,160,2,1108,A,A,0,19.58,100,130,166310,26613841,ARL,41370965,9.99,200,2,15.3,100,1,9.67,200,2,17.12,200,2,9.29,700,1,17.6,200,2,9.13,100,1,18.32,700,1,7.84,100,1,18.4,100,1,7.74,700,7,19.58,600,6,,,,20.32,100,1,,,,20.48,100,1,,,,,,,,,,,,
2025-07-17T13:28:46.014807086Z,2025-07-17T13:28:46.014973343Z,160,2,1108,C,A,0,20.48,100,0,166257,26613842,ARL,40617785,9.99,200,2,15.3,100,1,9.67,200,2,17.12,200,2,9.29,700,1,17.6,200,2,9.13,100,1,18.32,700,1,7.84,100,1,18.4,100,1,7.74,700,7,19.58,600,6,,,,20.32,100,1,,,,,,,,,,,,,,,,,,
2025-07-17T13:28:46.014807086Z,2025-07-17T13:28:46.014973343Z,160,2,1108,A,A,0,19.58,100,130,166257,26613842,ARL,41370969,9.99,200,2,15.3,100,1,9.67,200,2,17.12,200,2,9.29,700,1,17.6,200,2,9.13,100,1,18.32,700,1,7.84,100,1,18.4,100,1,7.74,700,7,19.58,700,7,,,,20.32,100,1,,,,,,,,,,,,,,,,,,
2025-07-17T13:28:46.015523291Z,2025-07-17T13:28:46.015690361Z,160,2,1108,A,B,0,10.18,700,130,167070,26614152,ARL,41371221,10.18,700,1,15.3,100,1,9.99,200,2,17.12,200,2,9.67,200,2,17.6,200,2,9.29,700,1,18.32,700,1,9.13,100,1,18.4,100,1,7.84,100,1,19.58,700,7,7.74,700,7,20.32,100,1,,,,,,,,,,,,,,,,,,
2025-07-17T13:28:46.015525315Z,2025-07-17T13:28:46.015691617Z,160,2,1108,A,A,0,16.11,700,130,166302,26614155,ARL,41371225,10.18,700,1,15.3,100,1,9.99,200,2,16.11,700,1,9.67,200,2,17.12,200,2,9.29,700,1,17.6,200,2,9.13,100,1,18.32,700,1,7.84,100,1,18.4,100,1,7.74,700,7,19.58,700,7,,,,20.32,100,1,,,,,,,,,,,,
2025-07-17T13:28:46.017209641Z,2025-07-17T13:28:46.017375168Z,160,2,1108,C,A,0,17.12,100,0,165527,26614961,ARL,41000173,10.18,700,1,15.3,100,1,9.99,200,2,16.11,700,1,9.67,200,2,17.12,100,1,9.29,700,1,17.6,200,2,9.13,100,1,18.32,700,1,7.84,100,1,18.4,100,1,7.74,700,7,19.58,700,7,,,,20.32,100,1,,,,,,,,,,,,
2025-07-17T13:28:46.017209641Z,2025-07-17T13:28:46.017375168Z,160,2,1108,A,A,0,16.38,100,130,165527,26614961,ARL,41372085,10.18,700,1,15.3,100,1,9.99,200,2,16.11,700,1,9.67,200,2,16.38,100,1,9.29,700,1,17.12,100,1,9.13,100,1,17.6,200,2,7.84,100,1,18.32,700,1,7.74,700,7,18.4,100,1,,,,19.58,700,7,,,,20.32,100,1,,,,,,
2025-07-17T13:28:46.017260228Z,2025-07-17T13:28:46.017425627Z,160,2,1108,C,A,0,17.6,100,0,165399,26614991,ARL,40999449,10.18,700,1,15.3,100,1,9.99,200,2,16.11,700,1,9.67,200,2,16.38,100,1,9.29,700,1,17.12,100,1,9.13,100,1,17.6,100,1,7.84,100,1,18.32,700,1,7.74,700,7,18.4,100,1,,,,19.58,700,7,,,,20.32,100,1,,,,,,
2025-07-17T13:28:46.017260228Z,2025-07-17T13:28:46.017425627Z,160,2,1108,A,A,0,16.83,100,130,165399,26614991,ARL,41372125,10.18,700,1,15.3,100,1,9.99,200,2,16.11,700,1,9.67,200,2,16.38,100,1,9.29,700,1,16.83,100,1,9.13,100,1,17.12,100,1,7.84,100,1,17.6,100,1,7.74,700,7,18.32,700,1,,,,18.4,100,1,,,,19.58,700,7,,,,20.32,100,1
2025-07-17T13:28:46.017531156Z,2025-07-17T13:28:46.017696573Z,160,2,1108,C,A,0,17.12,100,0,165417,26615138,ARL,41021841,10.18,700,1,15.3,100,1,9.99,200,2,16.11,700,1,9.67,200,2,16.38,100,1,9.29,700,1,16.83,100,1,9.13,100,1,17.6,100,1,7.84,100,1,18.32,700,1,7.74,700,7,18.4,100,1,,,,19.58,700,7,,,,20.32,100,1,,,,,,
2025-07-17T13:28:46.017531156Z,2025-07-17T13:28:46.017696573Z,160,2,1108,A,A,0,16.38,100,130,165417,26615138,ARL,41372369,10.18,700,1,15.3,100,1,9.99,200,2,16.11,700,1,9.67,200,2,16.38,200,2,9.29,700,1,16.83,100,1,9.13,100,1,17.6,100,1,7.84,100,1,18.32,700,1,7.74,700,7,18.4,100,1,,,,19.58,700,7,,,,20.32,100,1,,,,,,
2025-07-17T13:28:46.017657609Z,2025-07-17T13:28:46.017823073Z,160,2,1108,C,A,0,17.6,100,0,165464,26615203,ARL,41021373,10.18,700,1,15.3,100,1,9.99,200,2,16.11,700,1,9.67,200,2,16.38,200,2,9.29,700,1,16.83,100,1,9.13,100,1,18.32,700,1,7.84,100,1,18.4,100,1,7.74,700,7,19.58,700,7,,,,20.32,100,1,,,,,,,,,,,,
2025-07-17T13:28:46.017657609Z,2025-07-17T13:28:46.017823073Z,160,2,1108,A,A,0,16.83,100,130,165464,26615203,ARL,41372469,10.18,700,1,15.3,100,1,9.99,200,2,16.11,700,1,9.67,200,2,16.38,200,2,9.29,700,1,16.83,200,2,9.13,100,1,18.32,700,1,7.84,100,1,18.4,100,1,7.74,700,7,19.58,700,7,,,,20.32,100,1,,,,,,,,,,,,
2025-07-17T13:28:46.017721028Z,2025-07-17T13:28:46.017886428Z,160,2,1108,C,A,0,18.4,100,0,165400,26615230,ARL,41032057,10.18,700,1,15.3,100,1,9.99,200,2,16.11,700,1,9.67,200,2,16.38,200,2,9.29,700,1,16.83,200,2,9.13,100,1,18.32,700,1,7.84,100,1,19.58,700,7,7.74,700,7,20.32,100,1,,,,,,,,,,,,,,,,,,
2025-07-17T13:28:46.017721028Z,2025-07-17T13:28:46.017886428Z,160,2,1108,A,A,0,17.6,100,130,165400,26615230,ARL,41372493,10.18,700,1,15.3,100,1,9.99,200,2,16.11,700,1,9.67,200,2,16.38,200,2,9.29,700,1,16.83,200,2,9.13,100,1,17.6,100,1,7.84,100,1,18.32,700,1,7.74,700,7,19.58,700,7,,,,20.32,100,1,,,,,,,,,,,,
2025-07-17T13:28:46.017837874Z,2025-07-17T13:28:46.018003119Z,160,2,1108,C,A,0,20.32,100,0,165245,26615283,ARL,41306445,10.18,700,1,15.3,100,1,9.99,200,2,16.11,700,1,9.67,200,2,16.38,200,2,9.29,700,1,16.83,200,2,9.13,100,1,17.6,100,1,7.84,100,1,18.32,700,1,7.74,700,7,19.58,700,7,,,,,,,,,,,,,,,,,,
2025-07-17T13:28:46.017837874Z,2025-07-17T13:28:46.018003119Z,160,2,1108,A,A,0,19.44,100,130,165245,26615283,ARL,41372549,10.18,700,1,15.3,100,1,9.99,200,2,16.11,700,1,9.67,200,2,16.38,200,2,9.29,700,1,16.83,200,2,9.13,100,1,17.6,100,1,7.84,100,1,18.32,700,1,7.74,700,7,19.44,100,1,,,,19.58,700,7,,,,,,,,,,,,
2025-07-17T13:28:46.022095254Z,2025-07-17T13:28:46.022262428Z,160,2,1108,A,B,0,10.05,700,128,167174,26616844,ARL,41375793,10.18,700,1,15.3,100,1,10.05,700,1,16.11,700,1,9.99,200,2,16.38,200,2,9.67,200,2,16.83,200,2,9.29,700,1,17.6,100,1,9.13,100,1,18.32,700,1,7.84,100,1,19.44,100,1,7.74,700,7,19.58,700,7,,,,,,,,,,,,
2025-07-17T13:28:46.022822832Z,2025-07-17T13:28:46.022988063Z,160,2,1108,A,A,0,16.3,700,130,165231,26617168,ARL,41375973,10.18,700,1,15.3,100,1,10.05,700,1,16.11,700,1,9.99,200,2,16.3,700,1,9.67,200,2,16.38,200,2,9.29,700,1,16.83,200,2,9.13,100,1,17.6,100,1,7.84,100,1,18.32,700,1,7.74,700,7,19.44,100,1,,,,19.58,700,7,,,,,,
2025-07-17T13:28:46.025816567Z,2025-07-17T13:28:46.025981579Z,160,2,1108,A,B,0,11.76,100,130,165012,26618403,ARL,41376297,11.76,100,1,15.3,100,1,10.18,700,1,16.11,700,1,10.05,700,1,16.3,700,1,9.99,200,2,16.38,200,2,9.67,200,2,16.83,200,2,9.29,700,1,17.6,100,1,9.13,100,1,18.32,700,1,7.84,100,1,19.44,100,1,7.74,700,7,19.58,700,7,,,,,,
2025-07-17T13:28:46.025870563Z,2025-07-17T13:28:46.026037162Z,160,2,1108,C,B,0,7.74,100,0,166599,26618436,ARL,23616197,11.76,100,1,15.3,100,1,10.18,700,1,16.11,700,1,10.05,700,1,16.3,700,1,9.99,200,2,16.38,200,2,9.67,200,2,16.83,200,2,9.29,700,1,17.6,100,1,9.13,100,1,18.32,700,1,7.84,100,1,19.44,100,1,7.74,600,6,19.58,700,7,,,,,,
2025-07-17T13:28:46.025870563Z,2025-07-17T13:28:46.026037162Z,160,2,1108,A,B,0,8.47,100,130,166599,26618436,ARL,41376333,11.76,100,1,15.3,100,1,10.18,700,1,16.11,700,1,10.05,700,1,16.3,700,1,9.99,200,2,16.38,200,2,9.67,200,2,16.83,200,2,9.29,700,1,17.6,100,1,9.13,100,1,18.32,700,1,8.47,100,1,19.44,100,1,7.84,100,1,19.58,700,7,7.74,600,6,,,
2025-07-17T13:28:46.025872146Z,2025-07-17T13:28:46.026038058Z,160,2,1108,C,B,0,7.74,100,0,165912,26618438,ARL,23622101,11.76,100,1,15.3,100,1,10.18,700,1,16.11,700,1,10.05,700,1,16.3,700,1,9.99,200,2,16.38,200,2,9.67,200,2,16.83,200,2,9.29,700,1,17.6,100,1,9.13,100,1,18.32,700,1,8.47,100,1,19.44,100,1,7.84,100,1,19.58,700,7,7.74,500,5,,,
2025-07-17T13:28:46.025872146Z,2025-07-17T13:28:46.026038058Z,160,2,1108,A,B,0,8.47,100,130,165912,26618438,ARL,41376337,11.76,100,1,15.3,100,1,10.18,700,1,16.11,700,1,10.05,700,1,16.3,700,1,9.99,200,2,16.38,200,2,9.67,200,2,16.83,200,2,9.29,700,1,17.6,100,1,9.13,100,1,18.32,700,1,8.47,200,2,19.44,100,1,7.84,100,1,19.58,700,7,7.74,500,5,,,
2025-07-17T13:28:46.025873388Z,2025-07-17T13:28:46.026039687Z,160,2,1108,C,B,0,7.74,100,0,166299,26618439,ARL,24102329,11.76,100,1,15.3,100,1,10.18,700,1,16.11,700,1,10.05,700,1,16.3,700,1,9.99,200,2,16.38,200,2,9.67,200,2,16.83,200,2,9.29,700,1,17.6,100,1,9.13,100,1,18.32,700,1,8.47,200,2,19.44,100,1,7.84,100,1,19.58,700,7,7.74,400,4,,,
2025-07-17T13:28:46.025873388Z,2025-07-17T13:28:46.026039687Z,160,2,1108,A,B,0,8.47,100,128,166299,26618439,ARL,41376341,11.76,100,1,15.3,100,1,10.18,700,1,16.11,700,1,10.05,700,1,16.3,700,1,9.99,200,2,16.38,200,2,9.67,200,2,16.83,200,2,9.29,700,1,17.6,100,1,9.13,100,1,18.32,700,1,8.47,300,3,19.44,100,1,7.84,100,1,19.58,700,7,7.74,400,4,,,
2025-07-17T13:28:46.025874774Z,2025-07-17T13:28:46.026045679Z,160,2,1108,C,B,0,7.74,100,0,170905,26618441,ARL,31960841,11.76,100,1,15.3,100,1,10.18,700,1,16.11,700,1,10.05,700,1,16.3,700,1,9.99,200,2,16.38,200,2,9.67,200,2,16.83,200,2,9.29,700,1,17.6,100,1,9.13,100,1,18.32,700,1,8.47,300,3,19.44,100,1,7.84,100,1,19.58,700,7,7.74,300,3,,,
2025-07-17T13:28:46.025874774Z,2025-07-17T13:28:46.026045679Z,160,2,1108,A,B,0,8.47,100,0,170905,26618441,ARL,41376345,11.76,100,1,15.3,100,1,10.18,700,1,16.11,700,1,10.05,700,1,16.3,700,1,9.99,200,2,16.38,200,2,9.67,200,2,16.83,200,2,9.29,700,1,17.6,100,1,9.13,100,1,18.32,700,1,8.47,400,4,19.44,100,1,7.84,100,1,19.58,700,7,7.74,300,3,,,
2025-07-17T13:28:46.025875041Z,2025-07-17T13:28:46.026045679Z,160,2,1108,C,B,0,7.74,100,0,170638,26618442,ARL,33574717,11.76,100,1,15.3,100,1,10.18,700,1,16.11,700,1,10.05,700,1,16.3,700,1,9.99,200,2,16.38,200,2,9.67,200,2,16.83,200,2,9.29,700,1,17.6,100,1,9.13,100,1,18.32,700,1,8.47,400,4,19.44,100,1,7.84,100,1,19.58,700,7,7.74,200,2,,,
2025-07-17T13:28:46.025875041Z,2025-07-17T13:28:46.026045679Z,160,2,1108,A,B,0,8.47,100,0,170638,26618442,ARL,41376349,11.76,100,1,15.3,100,1,10.18,700,1,16.11,700,1,10.05,700,1,16.3,700,1,9.99,200,2,16.38,200,2,9.67,200,2,16.83,200,2,9.29,700,1,17.6,100,1,9.13,100,1,18.32,700,1,8.47,500,5,19.44,100,1,7.84,100,1,19.58,700,7,7.74,200,2,,,
2025-07-17T13:28:46.025875401Z,2025-07-17T13:28:46.026045679Z,160,2,1108,C,B,0,7.74,100,0,170278,26618443,ARL,38041417,11.76,100,1,15.3,100,1,10.18,700,1,16.11,700,1,10.05,700,1,16.3,700,1,9.99,200,2,16.38,200,2,9.67,200,2,16.83,200,2,9.29,700,1,17.6,100,1,9.13,100,1,18.32,700,1,8.47,500,5,19.44,100,1,7.84,100,1,19.58,700,7,7.74,100,1,,,
2025-07-17T13:28:46.025875401Z,2025-07-17T13:28:46.026045679Z,160,2,1108,A,B,0,8.47,100,0,170278,26618443,ARL,41376353,11.76,100,1,15.3,100,1,10.18,700,1,16.11,700,1,10.05,700,1,16.3,700,1,9.99,200,2,16.38,200,2,9.67,200,2,16.83,200,2,9.29,700,1,17.6,100,1,9.13,100,1,18.32,700,1,8.47,600,6,19.44,100,1,7.84,100,1,19.58,700,7,7.74,100,1,,,
2025-07-17T13:28:46.025877502Z,2025-07-17T13:28:46.026045679Z,160,2,1108,C,B,0,7.74,100,0,168177,26618447,ARL,40617777,11.76,100,1,15.3,100,1,10.18,700,1,16.11,700,1,10.05,700,1,16.3,700,1,9.99,200,2,16.38,200,2,9.67,200,2,16.83,200,2,9.29,700,1,17.6,100,1,9.13,100,1,18.32,700,1,8.47,600,6,19.44,100,1,7.84,100,1,19.58,700,7,,,,,,
2025-07-17T13:28:46.025877502Z,2025-07-17T13:28:46.026045679Z,160,2,1108,A,B,0,8.47,100,130,168177,26618447,ARL,41376357,11.76,100,1,15.3,100,1,10.18,700,1,16.11,700,1,10.05,700,1,16.3,700,1,9.99,200,2,16.38,200,2,9.67,200,2,16.83,200,2,9.29,700,1,17.6,100,1,9.13,100,1,18.32,700,1,8.47,700,7,19.44,100,1,7.84,100,1,19.58,700,7,,,,,,
2025-07-17T13:28:46.027560174Z,2025-07-17T13:28:46.027725683Z,160,2,1108,C,B,0,9.99,100,0,165509,26619144,ARL,41000165,11.76,100,1,15.3,100,1,10.18,700,1,16.11,700,1,10.05,700,1,16.3,700,1,9.99,100,1,16.38,200,2,9.67,200,2,16.83,200,2,9.29,700,1,17.6,100,1,9.13,100,1,18.32,700,1,8.47,700,7,19.44,100,1,7.84,100,1,19.58,700,7,,,,,,
2025-07-17T13:28:46.027560174Z,2025-07-17T13:28:46.027725683Z,160,2,1108,A,B,0,10.93,100,130,165509,26619144,ARL,41376501,11.76,100,1,15.3,100,1,10.93,100,1,16.11,700,1,10.18,700,1,16.3,700,1,10.05,700,1,16.38,200,2,9.99,100,1,16.83,200,2,9.67,200,2,17.6,100,1,9.29,700,1,18.32,700,1,9.13,100,1,19.44,100,1,8.47,700,7,19.58,700,7,7.84,100,1,,,
2025-07-17T13:28:46.029556957Z,2025-07-17T13:28:46.029726785Z,160,2,1108,C,B,0,9.67,100,0,169828,26619966,ARL,40999441,11.76,100,1,15.3,100,1,10.93,100,1,16.11,700,1,10.18,700,1,16.3,700,1,10.05,700,1,16.38,200,2,9.99,100,1,16.83,200,2,9.67,100,1,17.6,100,1,9.29,700,1,18.32,700,1,9.13,100,1,19.44,100,1,8.47,700,7,19.58,700,7,7.84,100,1,,,
2025-07-17T13:28:46.029556957Z,2025-07-17T13:28:46.029726785Z,160,2,1108,A,B,0,10.58,100,128,169828,26619966,ARL,41376725,11.76,100,1,15.3,100,1,10.93,100,1,16.11,700,1,10.58,100,1,16.3,700,1,10.18,700,1,16.38,200,2,10.05,700,1,16.83,200,2,9.99,100,1,17.6,100,1,9.67,100,1,18.32,700,1,9.29,700,1,19.44,100,1,9.13,100,1,19.58,700,7,8.47,700,7,,,
2025-07-17T13:28:46.029609064Z,2025-07-17T13:28:46.029775250Z,160,2,1108,C,B,0,7.84,100,0,166186,26619999,ARL,41306441,11.76,100,1,15.3,100,1,10.93,100,1,16.11,700,1,10.58,100,1,16.3,700,1,10.18,700,1,16.38,200,2,10.05,700,1,16.83,200,2,9.99,100,1,17.6,100,1,9.67,100,1,18.32,700,1,9.29,700,1,19.44,100,1,9.13,100,1,19.58,700,7,8.47,700,7,,,
2025-07-17T13:28:46.029609064Z,2025-07-17T13:28:46.029775250Z,160,2,1108,A,B,0,8.58,100,130,166186,26619999,ARL,41376733,11.76,100,1,15.3,100,1,10.93,100,1,16.11,700,1,10.58,100,1,16.3,700,1,10.18,700,1,16.38,200,2,10.05,700,1,16.83,200,2,9.99,100,1,17.6,100,1,9.67,100,1,18.32,700,1,9.29,700,1,19.44,100,1,9.13,100,1,19.58,700,7,8.58,100,1,,,
2025-07-17T13:28:46.031073916Z,2025-07-17T13:28:46.031239452Z,160,2,1108,C,B,0,9.13,100,0,165536,26620530,ARL,41032049,11.76,100,1,15.3,100,1,10.93,100,1,16.11,700,1,10.58,100,1,16.3,700,1,10.18,700,1,16.38,200,2,10.05,700,1,16.83,200,2,9.99,100,1,17.6,100,1,9.67,100,1,18.32,700,1,9.29,700,1,19.44,100,1,8.58,100,1,19.58,700,7,8.47,700,7,,,
2025-07-17T13:28:46.031073916Z,2025-07-17T13:28:46.031239452Z,160,2,1108,A,B,0,9.99,100,130,165536,26620530,ARL,41376769,11.76,100,1,15.3,100,1,10.93,100,1,16.11,700,1,10.58,100,1,16.3,700,1,10.18,700,1,16.38,200,2,10.05,700,1,16.83,200,2,9.99,200,2,17.6,100,1,9.67,100,1,18.32,700,1,9.29,700,1,19.44,100,1,8.58,100,1,19.58,700,7,8.47,700,7,,,
2025-07-17T13:28:46.037954661Z,2025-07-17T13:28:46.038120992Z,160,2,1108,C,B,0,9.67,100,0,166331,26623213,ARL,41021369,11.76,100,1,15.3,100,1,10.93,100,1,16.11,700,1,10.58,100,1,16.3,700,1,10.18,700,1,16.38,200,2,10.05,700,1,16.83,200,2,9.99,200,2,17.6,100,1,9.29,700,1,18.32,700,1,8.58,100,1,19.44,100,1,8.47,700,7,19.58,700,7,,,,,,
2025-07-17T13:28:46.037954661Z,2025-07-17T13:28:46.038120992Z,160,2,1108,A,B,0,10.58,100,128,166331,26623213,ARL,41377117,11.76,100,1,15.3,100,1,10.93,100,1,16.11,700,1,10.58,200,2,16.3,700,1,10.18,700,1,16.38,200,2,10.05,700,1,16.83,200,2,9.99,200,2,17.6,100,1,9.29,700,1,18.32,700,1,8.58,100,1,19.44,100,1,8.47,700,7,19.58,700,7,,,,,,
2025-07-17T13:28:46.042858782Z,2025-07-17T13:28:46.043024422Z,160,2,1108,C,B,0,9.99,100,0,165640,26625366,ARL,41021837,11.76,100,1,15.3,100,1,10.93,100,1,16.11,700,1,10.58,200,2,16.3,700,1,10.18,700,1,16.38,200,2,10.05,700,1,16.83,200,2,9.99,100,1,17.6,100,1,9.29,700,1,18.32,700,1,8.58,100,1,19.44,100,1,8.47,700,7,19.58,700,7,,,,,,
2025-07-17T13:28:46.042858782Z,2025-07-17T13:28:46.043024422Z,160,2,1108,A,B,0,10.93,100,130,165640,26625366,ARL,41379985,11.76,100,1,15.3,100,1,10.93,200,2,16.11,700,1,10.58,200,2,16.3,700,1,10.18,700,1,16.38,200,2,10.05,700,1,16.83,200,2,9.99,100,1,17.6,100,1,9.29,700,1,18.32,700,1,8.58,100,1,19.44,100,1,8.47,700,7,19.58,700,7,,,,,,
2025-07-17T13:28:52.312295020Z,2025-07-17T13:28:52.312460374Z,160,2,1108,A,B,0,10.75,700,130,165354,26806665,ARL,41507073,11.76,100,1,15.3,100,1,10.93,200,2,16.11,700,1,10.75,700,1,16.3,700,1,10.58,200,2,16.38,200,2,10.18,700,1,16.83,200,2,10.05,700,1,17.6,100,1,9.99,100,1,18.32,700,1,9.29,700,1,19.44,100,1,8.58,100,1,19.58,700,7,8.47,700,7,,,
2025-07-17T13:28:52.312330796Z,2025-07-17T13:28:52.312496032Z,160,2,1108,C,B,0,10.05,700,130,165236,26806666,ARL,41375793,11.76,100,1,15.3,100,1,10.93,200,2,16.11,700,1,10.75,700,1,16.3,700,1,10.58,200,2,16.38,200,2,10.18,700,1,16.83,200,2,9.99,100,1,17.6,100,1,9.29,700,1,18.32,700,1,8.58,100,1,19.44,100,1,8.47,700,7,19.58,700,7,,,,,,
2025-07-17T13:28:52.512292648Z,2025-07-17T13:28:52.512457909Z,160,2,1108,A,B,0,10.99,700,130,165261,26808221,ARL,41509393,11.76,100,1,15.3,100,1,10.99,700,1,16.11,700,1,10.93,200,2,16.3,700,1,10.75,700,1,16.38,200,2,10.58,200,2,16.83,200,2,10.18,700,1,17.6,100,1,9.99,100,1,18.32,700,1,9.29,700,1,19.44,100,1,8.58,100,1,19.58,700,7,8.47,700,7,,,
2025-07-17T13:28:52.513090520Z,2025-07-17T13:28:52.513255552Z,160,2,1108,C,B,0,10.75,700,130,165032,26808222,ARL,41507073,11.76,100,1,15.3,100,1,10.99,700,1,16.11,700,1,10.93,200,2,16.3,700,1,10.58,200,2,16.38,200,2,10.18,700,1,16.83,200,2,9.99,100,1,17.6,100,1,9.29,700,1,18.32,700,1,8.58,100,1,19.44,100,1,8.47,700,7,19.58,700,7,,,,,,
2025-07-17T13:28:53.957067631Z,2025-07-17T13:28:53.957233148Z,160,2,1108,A,A,0,16.15,700,130,165517,26835971,ARL,41528029,11.76,100,1,15.3,100,1,10.99,700,1,16.11,700,1,10.93,200,2,16.15,700,1,10.58,200,2,16.3,700,1,10.18,700,1,16.38,200,2,9.99,100,1,16.83,200,2,9.29,700,1,17.6,100,1,8.58,100,1,18.32,700,1,8.47,700,7,19.44,100,1,,,,19.58,700,7
2025-07-17T13:28:53.957116061Z,2025-07-17T13:28:53.957281517Z,160,2,1108,C,A,0,18.32,700,130,165456,26835974,ARL,40846101,11.76,100,1,15.3,100,1,10.99,700,1,16.11,700,1,10.93,200,2,16.15,700,1,10.58,200,2,16.3,700,1,10.18,700,1,16.38,200,2,9.99,100,1,16.83,200,2,9.29,700,1,17.6,100,1,8.58,100,1,19.44,100,1,8.47,700,7,19.58,700,7,,,,,,
2025-07-17T13:28:54.128310778Z,2025-07-17T13:28:54.128476219Z,160,2,1108,A,B,0,9.99,700,130,165441,26850111,ARL,41530665,11.76,100,1,15.3,100,1,10.99,700,1,16.11,700,1,10.93,200,2,16.15,700,1,10.58,200,2,16.3,700,1,10.18,700,1,16.38,200,2,9.99,800,2,16.83,200,2,9.29,700,1,17.6,100,1,8.58,100,1,19.44,100,1,8.47,700,7,19.58,700,7,,,,,,
2025-07-17T13:28:54.128338727Z,2025-07-17T13:28:54.128503934Z,160,2,1108,C,B,0,9.29,700,130,165207,26850112,ARL,40851989,11.76,100,1,15.3,100,1,10.99,700,1,16.11,700,1,10.93,200,2,16.15,700,1,10.58,200,2,16.3,700,1,10.18,700,1,16.38,200,2,9.99,800,2,16.83,200,2,8.58,100,1,17.6,100,1,8.47,700,7,19.44,100,1,,,,19.58,700,7,,,,,,
2025-07-17T13:28:54.328487063Z,2025-07-17T13:28:54.328652337Z,160,2,1108,A,B,0,10.26,700,130,165274,26851888,ARL,41533513,11.76,100,1,15.3,100,1,10.99,700,1,16.11,700,1,10.93,200,2,16.15,700,1,10.58,200,2,16.3,700,1,10.26,700,1,16.38,200,2,10.18,700,1,16.83,200,2,9.99,800,2,17.6,100,1,8.58,100,1,19.44,100,1,8.47,700,7,19.58,700,7,,,,,,
2025-07-17T13:28:54.328519057Z,2025-07-17T13:28:54.328684086Z,160,2,1108,C,B,0,9.99,700,130,165029,26851889,ARL,41530665,11.76,100,1,15.3,100,1,10.99,700,1,16.11,700,1,10.93,200,2,16.15,700,1,10.58,200,2,16.3,700,1,10.26,700,1,16.38,200,2,10.18,700,1,16.83,200,2,9.99,100,1,17.6,100,1,8.58,100,1,19.44,100,1,8.47,700,7,19.58,700,7,,,,,,
2025-07-17T13:28:54.477455479Z,2025-07-17T13:28:54.477620754Z,160,2,1108,A,B,0,11.14,700,130,165275,26853475,ARL,41534785,11.76,100,1,15.3,100,1,11.14,700,1,16.11,700,1,10.99,700,1,16.15,700,1,10.93,200,2,16.3,700,1,10.58,200,2,16.38,200,2,10.26,700,1,16.83,200,2,10.18,700,1,17.6,100,1,9.99,100,1,19.44,100,1,8.58,100,1,19.58,700,7,8.47,700,7,,,
2025-07-17T13:28:54.477852651Z,2025-07-17T13:28:54.478018001Z,160,2,1108,C,B,0,10.18,700,130,165350,26853478,ARL,41371221,11.76,100,1,15.3,100,1,11.14,700,1,16.11,700,1,10.99,700,1,16.15,700,1,10.93,200,2,16.3,700,1,10.58,200,2,16.38,200,2,10.26,700,1,16.83,200,2,9.99,100,1,17.6,100,1,8.58,100,1,19.44,100,1,8.47,700,7,19.58,700,7,,,,,,
2025-07-17T13:28:54.528542919Z,2025-07-17T13:28:54.528708243Z,160,2,1108,A,B,0,10.53,700,130,165324,26853925,ARL,41535173,11.76,100,1,15.3,100,1,11.14,700,1,16.11,700,1,10.99,700,1,16.15,700,1,10.93,200,2,16.3,700,1,10.58,200,2,16.38,200,2,10.53,700,1,16.83,200,2,10.26,700,1,17.6,100,1,9.99,100,1,19.44,100,1,8.58,100,1,19.58,700,7,8.47,700,7,,,
2025-07-17T13:28:54.528571375Z,2025-07-17T13:28:54.528736554Z,160,2,1108,C,B,0,10.26,700,130,165179,26853926,ARL,41533513,11.76,100,1,15.3,100,1,11.14,700,1,16.11,700,1,10.99,700,1,16.15,700,1,10.93,200,2,16.3,700,1,10.58,200,2,16.38,200,2,10.53,700,1,16.83,200,2,9.99,100,1,17.6,100,1,8.58,100,1,19.44,100,1,8.47,700,7,19.58,700,7,,,,,,
2025-07-17T13:28:54.728575124Z,2025-07-17T13:28:54.728740313Z,160,2,1108,A,B,0,10.8,700,130,165189,26856081,ARL,41537525,11.76,100,1,15.3,100,1,11.14,700,1,16.11,700,1,10.99,700,1,16.15,700,1,10.93,200,2,16.3,700,1,10.8,700,1,16.38,200,2,10.58,200,2,16.83,200,2,10.53,700,1,17.6,100,1,9.99,100,1,19.44,100,1,8.58,100,1,19.58,700,7,8.47,700,7,,,
2025-07-17T13:28:54.728651317Z,2025-07-17T13:28:54.728816275Z,160,2,1108,C,B,0,10.53,700,130,164958,26856082,ARL,41535173,11.76,100,1,15.3,100,1,11.14,700,1,16.11,700,1,10.99,700,1,16.15,700,1,10.93,200,2,16.3,700,1,10.8,700,1,16.38,200,2,10.58,200,2,16.83,200,2,9.99,100,1,17.6,100,1,8.58,100,1,19.44,100,1,8.47,700,7,19.58,700,7,,,,,,
2025-07-17T13:28:54.928412211Z,2025-07-17T13:28:54.928577406Z,160,2,1108,A,B,0,11.07,700,130,165195,26858349,ARL,41539477,11.76,100,1,15.3,100,1,11.14,700,1,16.11,700,1,11.07,700,1,16.15,700,1,10.99,700,1,16.3,700,1,10.93,200,2,16.38,200,2,10.8,700,1,16.83,200,2,10.58,200,2,17.6,100,1,9.99,100,1,19.44,100,1,8.58,100,1,19.58,700,7,8.47,700,7,,,
2025-07-17T13:28:54.928488170Z,2025-07-17T13:28:54.928653303Z,160,2,1108,C,B,0,10.8,700,130,165133,26858351,ARL,41537525,11.76,100,1,15.3,100,1,11.14,700,1,16.11,700,1,11.07,700,1,16.15,700,1,10.99,700,1,16.3,700,1,10.93,200,2,16.38,200,2,10.58,200,2,16.83,200,2,9.99,100,1,17.6,100,1,8.58,100,1,19.44,100,1,8.47,700,7,19.58,700,7,,,,,,
2025-07-17T13:29:00.583110843Z,2025-07-17T13:29:00.583276463Z,160,2,1108,A,B,0,10.84,100,130,165620,27000961,ARL,41635065,11.76,100,1,15.3,100,1,11.14,700,1,16.11,700,1,11.07,700,1,16.15,700,1,10.99,700,1,16.3,700,1,10.93,200,2,16.38,200,2,10.84,100,1,16.83,200,2,10.58,200,2,17.6,100,1,9.99,100,1,19.44,100,1,8.58,100,1,19.58,700,7,8.47,700,7,,,
2025-07-17T13:29:00.583124331Z,2025-07-17T13:29:00.583289800Z,160,2,1108,A,A,0,16.49,100,130,165469,27000962,ARL,41635069,11.76,100,1,15.3,100,1,11.14,700,1,16.11,700,1,11.07,700,1,16.15,700,1,10.99,700,1,16.3,700,1,10.93,200,2,16.38,200,2,10.84,100,1,16.49,100,1,10.58,200,2,16.83,200,2,9.99,100,1,17.6,100,1,8.58,100,1,19.44,100,1,8.47,700,7,19.58,700,7
2025-07-17T13:29:31.666485583Z,2025-07-17T13:29:31.666650984Z,160,2,1108,A,B,0,11.05,100,130,165401,27592251,ARL,42089321,11.76,100,1,15.3,100,1,11.14,700,1,16.11,700,1,11.07,700,1,16.15,700,1,11.05,100,1,16.3,700,1,10.99,700,1,16.38,200,2,10.93,200,2,16.49,100,1,10.84,100,1,16.83,200,2,10.58,200,2,17.6,100,1,9.99,100,1,19.44,100,1,8.58,100,1,19.58,700,7
2025-07-17T13:29:31.666510533Z,2025-07-17T13:29:31.666676040Z,160,2,1108,A,A,0,16.22,100,130,165507,27592252,ARL,42089325,11.76,100,1,15.3,100,1,11.14,700,1,16.11,700,1,11.07,700,1,16.15,700,1,11.05,100,1,16.22,100,1,10.99,700,1,16.3,700,1,10.93,200,2,16.38,200,2,10.84,100,1,16.49,100,1,10.58,200,2,16.83,200,2,9.99,100,1,17.6,100,1,8.58,100,1,19.44,100,1
2025-07-17T13:29:32.011088073Z,2025-07-17T13:29:32.011253336Z,160,2,1108,A,B,0,11.29,100,130,165263,27599196,ARL,42099317,11.76,100,1,15.3,100,1,11.29,100,1,16.11,700,1,11.14,700,1,16.15,700,1,11.07,700,1,16.22,100,1,11.05,100,1,16.3,700,1,10.99,700,1,16.38,200,2,10.93,200,2,16.49,100,1,10.84,100,1,16.83,200,2,10.58,200,2,17.6,100,1,9.99,100,1,19.44,100,1
2025-07-17T13:29:32.011092154Z,2025-07-17T13:29:32.011257301Z,160,2,1108,A,A,0,15.91,100,130,165147,27599197,ARL,42099321,11.76,100,1,15.3,100,1,11.29,100,1,15.91,100,1,11.14,700,1,16.11,700,1,11.07,700,1,16.15,700,1,11.05,100,1,16.22,100,1,10.99,700,1,16.3,700,1,10.93,200,2,16.38,200,2,10.84,100,1,16.49,100,1,10.58,200,2,16.83,200,2,9.99,100,1,17.6,100,1
2025-07-17T13:29:39.839973111Z,2025-07-17T13:29:39.840138413Z,160,2,1108,A,B,0,8.47,100,130,165302,27759427,ARL,42202297,11.76,100,1,15.3,100,1,11.29,100,1,15.91,100,1,11.14,700,1,16.11,700,1,11.07,700,1,16.15,700,1,11.05,100,1,16.22,100,1,10.99,700,1,16.3,700,1,10.93,200,2,16.38,200,2,10.84,100,1,16.49,100,1,10.58,200,2,16.83,200,2,9.99,100,1,17.6,100,1
2025-07-17T13:29:40.000183284Z,2025-07-17T13:29:40.000349567Z,160,2,1108,A,A,0,19.58,100,130,166283,27760200,ARL,42204681,11.76,100,1,15.3,100,1,11.29,100,1,15.91,100,1,11.14,700,1,16.11,700,1,11.07,700,1,16.15,700,1,11.05,100,1,16.22,100,1,10.99,700,1,16.3,700,1,10.93,200,2,16.38,200,2,10.84,100,1,16.49,100,1,10.58,200,2,16.83,200,2,9.99,100,1,17.6,100,1
2025-07-17T13:29:55.529183618Z,2025-07-17T13:29:55.529348997Z,160,2,1108,A,B,0,11.52,100,130,165379,28123971,ARL,42446497,11.76,100,1,15.3,100,1,11.52,100,1,15.91,100,1,11.29,100,1,16.11,700,1,11.14,700,1,16.15,700,1,11.07,700,1,16.22,100,1,11.05,100,1,16.3,700,1,10.99,700,1,16.38,200,2,10.93,200,2,16.49,100,1,10.84,100,1,16.83,200,2,10.58,200,2,17.6,100,1
2025-07-17T13:29:55.529200619Z,2025-07-17T13:29:55.529365902Z,160,2,1108,A,A,0,15.61,100,130,165283,28123973,ARL,42446501,11.76,100,1,15.3,100,1,11.52,100,1,15.61,100,1,11.29,100,1,15.91,100,1,11.14,700,1,16.11,700,1,11.07,700,1,16.15,700,1,11.05,100,1,16.22,100,1,10.99,700,1,16.3,700,1,10.93,200,2,16.38,200,2,10.84,100,1,16.49,100,1,10.58,200,2,16.83,200,2
2025-07-17T13:29:59.677285294Z,2025-07-17T13:29:59.677450683Z,160,2,1108,A,B,0,10.11,100,130,165389,28321241,ARL,42583289,11.76,100,1,15.3,100,1,11.52,100,1,15.61,100,1,11.29,100,1,15.91,100,1,11.14,700,1,16.11,700,1,11.07,700,1,16.15,700,1,11.05,100,1,16.22,100,1,10.99,700,1,16.3,700,1,10.93,200,2,16.38,200,2,10.84,100,1,16.49,100,1,10.58,200,2,16.83,200,2
2025-07-17T13:29:59.677290064Z,2025-07-17T13:29:59.677457187Z,160,2,1108,A,A,0,17.45,100,128,167123,28321242,ARL,42583293,11.76,100,1,15.3,100,1,11.52,100,1,15.61,100,1,11.29,100,1,15.91,100,1,11.14,700,1,16.11,700,1,11.07,700,1,16.15,700,1,11.05,100,1,16.22,100,1,10.99,700,1,16.3,700,1,10.93,200,2,16.38,200,2,10.84,100,1,16.49,100,1,10.58,200,2,16.83,200,2
2025-07-17T13:30:00.092900330Z,2025-07-17T13:30:00.093085479Z,160,2,1108,A,B,0,11.01,100,128,185149,28409476,ARL,42674817,11.76,100,1,15.3,100,1,11.52,100,1,15.61,100,1,11.29,100,1,15.91,100,1,11.14,700,1,16.11,700,1,11.07,700,1,16.15,700,1,11.05,100,1,16.22,100,1,11.01,100,1,16.3,700,1,10.99,700,1,16.38,200,2,10.93,200,2,16.49,100,1,10.84,100,1,16.83,200,2
2025-07-17T13:30:00.092988904Z,2025-07-17T13:30:00.093164566Z,160,2,1108,A,A,0,16.1,100,128,175662,28409593,ARL,42674989,11.76,100,1,15.3,100,1,11.52,100,1,15.61,100,1,11.29,100,1,15.91,100,1,11.14,700,1,16.1,100,1,11.07,700,1,16.11,700,1,11.05,100,1,16.15,700,1,11.01,100,1,16.22,100,1,10.99,700,1,16.3,700,1,10.93,200,2,16.38,200,2,10.84,100,1,16.49,100,1
2025-07-17T13:30:00.412637542Z,2025-07-17T13:30:00.412816741Z,160,2,1108,A,A,0,19.58,100,128,179199,28676200,ARL,42946053,11.76,100,1,15.3,100,1,11.52,100,1,15.61,100,1,11.29,100,1,15.91,100,1,11.14,700,1,16.1,100,1,11.07,700,1,16.11,700,1,11.05,100,1,16.15,700,1,11.01,100,1,16.22,100,1,10.99,700,1,16.3,700,1,10.93,200,2,16.38,200,2,10.84,100,1,16.49,100,1
2025-07-17T13:30:00.421937186Z,2025-07-17T13:30:00.422103919Z,160,2,1108,A,B,0,8.47,100,128,166733,28680759,ARL,42951397,11.76,100,1,15.3,100,1,11.52,100,1,15.61,100,1,11.29,100,1,15.91,100,1,11.14,700,1,16.1,100,1,11.07,700,1,16.11,700,1,11.05,100,1,16.15,700,1,11.01,100,1,16.22,100,1,10.99,700,1,16.3,700,1,10.93,200,2,16.38,200,2,10.84,100,1,16.49,100,1
2025-07-17T13:30:00.675553569Z,2025-07-17T13:30:00.675725361Z,160,2,1108,A,B,0,10.92,100,128,171792,28833560,ARL,43143317,11.76,100,1,15.3,100,1,11.52,100,1,15.61,100,1,11.29,100,1,15.91,100,1,11.14,700,1,16.1,100,1,11.07,700,1,16.11,700,1,11.05,100,1,16.15,700,1,11.01,100,1,16.22,100,1,10.99,700,1,16.3,700,1,10.93,200,2,16.38,200,2,10.92,100,1,16.49,100,1
2025-07-17T13:30:00.675570319Z,2025-07-17T13:30:00.675748539Z,160,2,1108,A,A,0,16.2,100,128,178220,28833574,ARL,43143333,11.76,100,1,15.3,100,1,11.52,100,1,15.61,100,1,11.29,100,1,15.91,100,1,11.14,700,1,16.1,100,1,11.07,700,1,16.11,700,1,11.05,100,1,16.15,700,1,11.01,100,1,16.2,100,1,10.99,700,1,16.22,100,1,10.93,200,2,16.3,700,1,10.92,100,1,16.38,200,2
2025-07-17T13:30:00.730688348Z,2025-07-17T13:30:00.730859228Z,160,2,1108,A,B,0,10.92,100,130,170880,28858298,ARL,43191333,11.76,100,1,15.3,100,1,11.52,100,1,15.61,100,1,11.29,100,1,15.91,100,1,11.14,700,1,16.1,100,1,11.07,700,1,16.11,700,1,11.05,100,1,16.15,700,1,11.01,100,1,16.2,100,1,10.99,700,1,16.22,100,1,10.93,200,2,16.3,700,1,10.92,200,2,16.38,200,2
2025-07-17T13:30:00.730693126Z,2025-07-17T13:30:00.730867405Z,160,2,1108,A,A,0,16.2,100,128,174279,28858300,ARL,43191369,11.76,100,1,15.3,100,1,11.52,100,1,15.61,100,1,11.29,100,1,15.91,100,1,11.14,700,1,16.1,100,1,11.07,700,1,16.11,700,1,11.05,100,1,16.15,700,1,11.01,100,1,16.2,200,2,10.99,700,1,16.22,100,1,10.93,200,2,16.3,700,1,10.92,200,2,16.38,200,2
2025-07-17T13:30:00.869714108Z,2025-07-17T13:30:00.869893365Z,160,2,1108,A,B,0,9.41,100,0,179257,28963643,ARL,43313553,11.76,100,1,15.3,100,1,11.52,100,1,15.61,100,1,11.29,100,1,15.91,100,1,11.14,700,1,16.1,100,1,11.07,700,1,16.11,700,1,11.05,100,1,16.15,700,1,11.01,100,1,16.2,200,2,10.99,700,1,16.22,100,1,10.93,200,2,16.3,700,1,10.92,200,2,16.38,200,2
2025-07-17T13:30:00.869715708Z,2025-07-17T13:30:00.869893365Z,160,2,1108,A,A,0,18.36,100,128,177657,28963646,ARL,43313565,11.76,100,1,15.3,100,1,11.52,100,1,15.61,100,1,11.29,100,1,15.91,100,1,11.14,700,1,16.1,100,1,11.07,700,1,16.11,700,1,11.05,100,1,16.15,700,1,11.01,100,1,16.2,200,2,10.99,700,1,16.22,100,1,10.93,200,2,16.3,700,1,10.92,200,2,16.38,200,2
2025-07-17T13:30:00.869746905Z,2025-07-17T13:30:00.869922678Z,160,2,1108,A,A,0,18.36,100,128,175773,28963685,ARL,43313633,11.76,100,1,15.3,100,1,11.52,100,1,15.61,100,1,11.29,100,1,15.91,100,1,11.14,700,1,16.1,100,1,11.07,700,1,16.11,700,1,11.05,100,1,16.15,700,1,11.01,100,1,16.2,200,2,10.99,700,1,16.22,100,1,10.93,200,2,16.3,700,1,10.92,200,2,16.38,200,2
2025-07-17T13:30:00.869768981Z,2025-07-17T13:30:00.869941215Z,160,2,1108,A,B,0,9.41,100,130,172234,28963699,ARL,43313681,11.76,100,1,15.3,100,1,11.52,100,1,15.61,100,1,11.29,100,1,15.91,100,1,11.14,700,1,16.1,100,1,11.07,700,1,16.11,700,1,11.05,100,1,16.15,700,1,11.01,100,1,16.2,200,2,10.99,700,1,16.22,100,1,10.93,200,2,16.3,700,1,10.92,200,2,16.38,200,2
2025-07-17T13:30:00.869883482Z,2025-07-17T13:30:00.870056916Z,160,2,1108,A,B,0,11.24,100,128,173434,28963823,ARL,43313941,11.76,100,1,15.3,100,1,11.52,100,1,15.61,100,1,11.29,100,1,15.91,100,1,11.24,100,1,16.1,100,1,11.14,700,1,16.11,700,1,11.07,700,1,16.15,700,1,11.05,100,1,16.2,200,2,11.01,100,1,16.22,100,1,10.99,700,1,16.3,700,1,10.93,200,2,16.38,200,2
2025-07-17T13:30:00.869917271Z,2025-07-17T13:30:00.870086307Z,160,2,1108,A,A,0,15.98,100,130,169036,28963843,ARL,43314009,11.76,100,1,15.3,100,1,11.52,100,1,15.61,100,1,11.29,100,1,15.91,100,1,11.24,100,1,15.98,100,1,11.14,700,1,16.1,100,1,11.07,700,1,16.11,700,1,11.05,100,1,16.15,700,1,11.01,100,1,16.2,200,2,10.99,700,1,16.22,100,1,10.93,200,2,16.3,700,1
2025-07-17T13:30:00.869979897Z,2025-07-17T13:30:00.870161301Z,160,2,1108,C,B,0,8.47,100,0,181404,28963935,ARL,41376333,11.76,100,1,15.3,100,1,11.52,100,1,15.61,100,1,11.29,100,1,15.91,100,1,11.24,100,1,15.98,100,1,11.14,700,1,16.1,100,1,11.07,700,1,16.11,700,1,11.05,100,1,16.15,700,1,11.01,100,1,16.2,200,2,10.99,700,1,16.22,100,1,10.93,200,2,16.3,700,1
2025-07-17T13:30:00.869979897Z,2025-07-17T13:30:00.870161301Z,160,2,1108,A,B,0,9.55,100,0,181404,28963935,ARL,43314145,11.76,100,1,15.3,100,1,11.52,100,1,15.61,100,1,11.29,100,1,15.91,100,1,11.24,100,1,15.98,100,1,11.14,700,1,16.1,100,1,11.07,700,1,16.11,700,1,11.05,100,1,16.15,700,1,11.01,100,1,16.2,200,2,10.99,700,1,16.22,100,1,10.93,200,2,16.3,700,1
2025-07-17T13:30:00.869983764Z,2025-07-17T13:30:00.870161301Z,160,2,1108,C,B,0,8.47,100,0,177537,28963938,ARL,41376337,11.76,100,1,15.3,100,1,11.52,100,1,15.61,100,1,11.29,100,1,15.91,100,1,11.24,100,1,15.98,100,1,11.14,700,1,16.1,100,1,11.07,700,1,16.11,700,1,11.05,100,1,16.15,700,1,11.01,100,1,16.2,200,2,10.99,700,1,16.22,100,1,10.93,200,2,16.3,700,1
2025-07-17T13:30:00.869983764Z,2025-07-17T13:30:00.870161301Z,160,2,1108,A,B,0,9.55,100,128,177537,28963938,ARL,43314149,11.76,100,1,15.3,100,1,11.52,100,1,15.61,100,1,11.29,100,1,15.91,100,1,11.24,100,1,15.98,100,1,11.14,700,1,16.1,100,1,11.07,700,1,16.11,700,1,11.05,100,1,16.15,700,1,11.01,100,1,16.2,200,2,10.99,700,1,16.22,100,1,10.93,200,2,16.3,700,1
2025-07-17T13:30:00.869988740Z,2025-07-17T13:30:00.870165319Z,160,2,1108,C,B,0,8.47,100,0,176579,28963943,ARL,41376341,11.76,100,1,15.3,100,1,11.52,100,1,15.61,100,1,11.29,100,1,15.91,100,1,11.24,100,1,15.98,100,1,11.14,700,1,16.1,100,1,11.07,700,1,16.11,700,1,11.05,100,1,16.15,700,1,11.01,100,1,16.2,200,2,10.99,700,1,16.22,100,1,10.93,200,2,16.3,700,1
2025-07-17T13:30:00.869988740Z,2025-07-17T13:30:00.870165319Z,160,2,1108,A,B,0,9.55,100,0,176579,28963943,ARL,43314153,11.76,100,1,15.3,100,1,11.52,100,1,15.61,100,1,11.29,100,1,15.91,100,1,11.24,100,1,15.98,100,1,11.14,700,1,16.1,100,1,11.07,700,1,16.11,700,1,11.05,100,1,16.15,700,1,11.01,100,1,16.2,200,2,10.99,700,1,16.22,100,1,10.93,200,2,16.3,700,1
2025-07-17T13:30:00.869989204Z,2025-07-17T13:30:00.870165319Z,160,2,1108,C,B,0,8.47,100,0,176115,28963944,ARL,41376345,11.76,100,1,15.3,100,1,11.52,100,1,15.61,100,1,11.29,100,1,15.91,100,1,11.24,100,1,15.98,100,1,11.14,700,1,16.1,100,1,11.07,700,1,16.11,700,1,11.05,100,1,16.15,700,1,11.01,100,1,16.2,200,2,10.99,700,1,16.22,100,1,10.93,200,2,16.3,700,1
2025-07-17T13:30:00.869989204Z,2025-07-17T13:30:00.870165319Z,160,2,1108,A,B,0,9.55,100,128,176115,28963944,ARL,43314157,11.76,100,1,15.3,100,1,11.52,100,1,15.61,100,1,11.29,100,1,15.91,100,1,11.24,100,1,15.98,100,1,11.14,700,1,16.1,100,1,11.07,700,1,16.11,700,1,11.05,100,1,16.15,700,1,11.01,100,1,16.2,200,2,10.99,700,1,16.22,100,1,10.93,200,2,16.3,700,1
2025-07-17T13:30:00.869996105Z,2025-07-17T13:30:00.870174640Z,160,2,1108,C,B,0,8.47,100,0,178535,28963952,ARL,41376349,11.76,100,1,15.3,100,1,11.52,100,1,15.61,100,1,11.29,100,1,15.91,100,1,11.24,100,1,15.98,100,1,11.14,700,1,16.1,100,1,11.07,700,1,16.11,700,1,11.05,100,1,16.15,700,1,11.01,100,1,16.2,200,2,10.99,700,1,16.22,100,1,10.93,200,2,16.3,700,1
2025-07-17T13:30:00.869996105Z,2025-07-17T13:30:00.870174640Z,160,2,1108,A,B,0,9.55,100,0,178535,28963952,ARL,43314161,11.76,100,1,15.3,100,1,11.52,100,1,15.61,100,1,11.29,100,1,15.91,100,1,11.24,100,1,15.98,100,1,11.14,700,1,16.1,100,1,11.07,700,1,16.11,700,1,11.05,100,1,16.15,700,1,11.01,100,1,16.2,200,2,10.99,700,1,16.22,100,1,10.93,200,2,16.3,700,1
2025-07-17T13:30:00.869996504Z,2025-07-17T13:30:00.870174640Z,160,2,1108,C,B,0,8.47,100,0,178136,28963953,ARL,41376353,11.76,100,1,15.3,100,1,11.52,100,1,15.61,100,1,11.29,100,1,15.91,100,1,11.24,100,1,15.98,100,1,11.14,700,1,16.1,100,1,11.07,700,1,16.11,700,1,11.05,100,1,16.15,700,1,11.01,100,1,16.2,200,2,10.99,700,1,16.22,100,1,10.93,200,2,16.3,700,1
2025-07-17T13:30:00.869996504Z,2025-07-17T13:30:00.870174640Z,160,2,1108,A,B,0,9.55,100,0,178136,28963953,ARL,43314165,11.76,100,1,15.3,100,1,11.52,100,1,15.61,100,1,11.29,100,1,15.91,100,1,11.24,100,1,15.98,100,1,11.14,700,1,16.1,100,1,11.07,700,1,16.11,700,1,11.05,100,1,16.15,700,1,11.01,100,1,16.2,200,2,10.99,700,1,16.22,100,1,10.93,200,2,16.3,700,1
2025-07-17T13:30:00.869997057Z,2025-07-17T13:30:00.870174640Z,160,2,1108,C,B,0,8.47,100,0,177583,28963954,ARL,41376357,11.76,100,1,15.3,100,1,11.52,100,1,15.61,100,1,11.29,100,1,15.91,100,1,11.24,100,1,15.98,100,1,11.14,700,1,16.1,100,1,11.07,700,1,16.11,700,1,11.05,100,1,16.15,700,1,11.01,100,1,16.2,200,2,10.99,700,1,16.22,100,1,10.93,200,2,16.3,700,1
2025-07-17T13:30:00.869997057Z,2025-07-17T13:30:00.870174640Z,160,2,1108,A,B,0,9.55,100,128,177583,28963954,ARL,43314169,11.76,100,1,15.3,100,1,11.52,100,1,15.61,100,1,11.29,100,1,15.91,100,1,11.24,100,1,15.98,100,1,11.14,700,1,16.1,100,1,11.07,700,1,16.11,700,1,11.05,100,1,16.15,700,1,11.01,100,1,16.2,200,2,10.99,700,1,16.22,100,1,10.93,200,2,16.3,700,1
2025-07-17T13:30:00.870003387Z,2025-07-17T13:30:00.870179751Z,160,2,1108,C,B,0,8.47,100,0,176364,28963962,ARL,42202297,11.76,100,1,15.3,100,1,11.52,100,1,15.61,100,1,11.29,100,1,15.91,100,1,11.24,100,1,15.98,100,1,11.14,700,1,16.1,100,1,11.07,700,1,16.11,700,1,11.05,100,1,16.15,700,1,11.01,100,1,16.2,200,2,10.99,700,1,16.22,100,1,10.93,200,2,16.3,700,1
2025-07-17T13:30:00.870003387Z,2025-07-17T13:30:00.870179751Z,160,2,1108,A,B,0,9.55,100,0,176364,28963962,ARL,43314173,11.76,100,1,15.3,100,1,11.52,100,1,15.61,100,1,11.29,100,1,15.91,100,1,11.24,100,1,15.98,100,1,11.14,700,1,16.1,100,1,11.07,700,1,16.11,700,1,11.05,100,1,16.15,700,1,11.01,100,1,16.2,200,2,10.99,700,1,16.22,100,1,10.93,200,2,16.3,700,1
2025-07-17T13:30:00.870004158Z,2025-07-17T13:30:00.870179751Z,160,2,1108,C,B,0,8.47,100,0,175593,28963963,ARL,42951397,11.76,100,1,15.3,100,1,11.52,100,1,15.61,100,1,11.29,100,1,15.91,100,1,11.24,100,1,15.98,100,1,11.14,700,1,16.1,100,1,11.07,700,1,16.11,700,1,11.05,100,1,16.15,700,1,11.01,100,1,16.2,200,2,10.99,700,1,16.22,100,1,10.93,200,2,16.3,700,1
2025-07-17T13:30:00.870004158Z,2025-07-17T13:30:00.870179751Z,160,2,1108,A,B,0,9.55,100,128,175593,28963963,ARL,43314177,11.76,100,1,15.3,100,1,11.52,100,1,15.61,100,1,11.29,100,1,15.91,100,1,11.24,100,1,15.98,100,1,11.14,700,1,16.1,100,1,11.07,700,1,16.11,700,1,11.05,100,1,16.15,700,1,11.01,100,1,16.2,200,2,10.99,700,1,16.22,100,1,10.93,200,2,16.3,700,1
2025-07-17T13:30:00.870009922Z,2025-07-17T13:30:00.870186428Z,160,2,1108,C,A,0,19.58,100,0,176506,28963970,ARL,41370945,11.76,100,1,15.3,100,1,11.52,100,1,15.61,100,1,11.29,100,1,15.91,100,1,11.24,100,1,15.98,100,1,11.14,700,1,16.1,100,1,11.07,700,1,16.11,700,1,11.05,100,1,16.15,700,1,11.01,100,1,16.2,200,2,10.99,700,1,16.22,100,1,10.93,200,2,16.3,700,1
2025-07-17T13:30:00.870009922Z,2025-07-17T13:30:00.870186428Z,160,2,1108,A,A,0,18.38,100,0,176506,28963970,ARL,43314181,11.76,100,1,15.3,100,1,11.52,100,1,15.61,100,1,11.29,100,1,15.91,100,1,11.24,100,1,15.98,100,1,11.14,700,1,16.1,100,1,11.07,700,1,16.11,700,1,11.05,100,1,16.15,700,1,11.01,100,1,16.2,200,2,10.99,700,1,16.22,100,1,10.93,200,2,16.3,700,1
2025-07-17T13:30:00.870010386Z,2025-07-17T13:30:00.870186428Z,160,2,1108,C,A,0,19.58,100,0,176042,28963971,ARL,41370949,11.76,100,1,15.3,100,1,11.52,100,1,15.61,100,1,11.29,100,1,15.91,100,1,11.24,100,1,15.98,100,1,11.14,700,1,16.1,100,1,11.07,700,1,16.11,700,1,11.05,100,1,16.15,700,1,11.01,100,1,16.2,200,2,10.99,700,1,16.22,100,1,10.93,200,2,16.3,700,1
2025-07-17T13:30:00.870010386Z,2025-07-17T13:30:00.870186428Z,160,2,1108,A,A,0,18.38,100,128,176042,28963971,ARL,43314185,11.76,100,1,15.3,100,1,11.52,100,1,15.61,100,1,11.29,100,1,15.91,100,1,11.24,100,1,15.98,100,1,11.14,700,1,16.1,100,1,11.07,700,1,16.11,700,1,11.05,100,1,16.15,700,1,11.01,100,1,16.2,200,2,10.99,700,1,16.22,100,1,10.93,200,2,16.3,700,1
2025-07-17T13:30:00.870017071Z,2025-07-17T13:30:00.870194394Z,160,2,1108,C,A,0,19.58,100,0,177323,28963981,ARL,41370953,11.76,100,1,15.3,100,1,11.52,100,1,15.61,100,1,11.29,100,1,15.91,100,1,11.24,100,1,15.98,100,1,11.14,700,1,16.1,100,1,11.07,700,1,16.11,700,1,11.05,100,1,16.15,700,1,11.01,100,1,16.2,200,2,10.99,700,1,16.22,100,1,10.93,200,2,16.3,700,1
2025-07-17T13:30:00.870017071Z,2025-07-17T13:30:00.870194394Z,160,2,1108,A,A,0,18.38,100,0,177323,28963981,ARL,43314189,11.76,100,1,15.3,100,1,11.52,100,1,15.61,100,1,11.29,100,1,15.91,100,1,11.24,100,1,15.98,100,1,11.14,700,1,16.1,100,1,11.07,700,1,16.11,700,1,11.05,100,1,16.15,700,1,11.01,100,1,16.2,200,2,10.99,700,1,16.22,100,1,10.93,200,2,16.3,700,1
2025-07-17T13:30:00.870022776Z,2025-07-17T13:30:00.870194394Z,160,2,1108,C,A,0,19.58,100,0,171618,28963983,ARL,41370957,11.76,100,1,15.3,100,1,11.52,100,1,15.61,100,1,11.29,100,1,15.91,100,1,11.24,100,1,15.98,100,1,11.14,700,1,16.1,100,1,11.07,700,1,16.11,700,1,11.05,100,1,16.15,700,1,11.01,100,1,16.2,200,2,10.99,700,1,16.22,100,1,10.93,200,2,16.3,700,1
2025-07-17T13:30:00.870022776Z,2025-07-17T13:30:00.870194394Z,160,2,1108,A,A,0,18.38,100,0,171618,28963983,ARL,43314233,11.76,100,1,15.3,100,1,11.52,100,1,15.61,100,1,11.29,100,1,15.91,100,1,11.24,100,1,15.98,100,1,11.14,700,1,16.1,100,1,11.07,700,1,16.11,700,1,11.05,100,1,16.15,700,1,11.01,100,1,16.2,200,2,10.99,700,1,16.22,100,1,10.93,200,2,16.3,700,1
2025-07-17T13:30:00.870023199Z,2025-07-17T13:30:00.870194394Z,160,2,1108,C,A,0,19.58,100,0,171195,28963984,ARL,41370961,11.76,100,1,15.3,100,1,11.52,100,1,15.61,100,1,11.29,100,1,15.91,100,1,11.24,100,1,15.98,100,1,11.14,700,1,16.1,100,1,11.07,700,1,16.11,700,1,11.05,100,1,16.15,700,1,11.01,100,1,16.2,200,2,10.99,700,1,16.22,100,1,10.93,200,2,16.3,700,1
2025-07-17T13:30:00.870023199Z,2025-07-17T13:30:00.870194394Z,160,2,1108,A,A,0,18.38,100,0,171195,28963984,ARL,43314237,11.76,100,1,15.3,100,1,11.52,100,1,15.61,100,1,11.29,100,1,15.91,100,1,11.24,100,1,15.98,100,1,11.14,700,1,16.1,100,1,11.07,700,1,16.11,700,1,11.05,100,1,16.15,700,1,11.01,100,1,16.2,200,2,10.99,700,1,16.22,100,1,10.93,200,2,16.3,700,1
2025-07-17T13:30:00.870023701Z,2025-07-17T13:30:00.870194394Z,160,2,1108,C,A,0,19.58,100,0,170693,28963985,ARL,41370965,11.76,100,1,15.3,100,1,11.52,100,1,15.61,100,1,11.29,100,1,15.91,100,1,11.24,100,1,15.98,100,1,11.14,700,1,16.1,100,1,11.07,700,1,16.11,700,1,11.05,100,1,16.15,700,1,11.01,100,1,16.2,200,2,10.99,700,1,16.22,100,1,10.93,200,2,16.3,700,1
2025-07-17T13:30:00.870023701Z,2025-07-17T13:30:00.870194394Z,160,2,1108,A,A,0,18.38,100,130,170693,28963985,ARL,43314241,11.76,100,1,15.3,100,1,11.52,100,1,15.61,100,1,11.29,100,1,15.91,100,1,11.24,100,1,15.98,100,1,11.14,700,1,16.1,100,1,11.07,700,1,16.11,700,1,11.05,100,1,16.15,700,1,11.01,100,1,16.2,200,2,10.99,700,1,16.22,100,1,10.93,200,2,16.3,700,1
2025-07-17T13:30:00.870053023Z,2025-07-17T13:30:00.870229401Z,160,2,1108,C,A,0,19.58,100,0,176378,28964015,ARL,41370969,11.76,100,1,15.3,100,1,11.52,100,1,15.61,100,1,11.29,100,1,15.91,100,1,11.24,100,1,15.98,100,1,11.14,700,1,16.1,100,1,11.07,700,1,16.11,700,1,11.05,100,1,16.15,700,1,11.01,100,1,16.2,200,2,10.99,700,1,16.22,100,1,10.93,200,2,16.3,700,1
2025-07-17T13:30:00.870053023Z,2025-07-17T13:30:00.870229401Z,160,2,1108,A,A,0,18.38,100,0,176378,28964015,ARL,43314245,11.76,100,1,15.3,100,1,11.52,100,1,15.61,100,1,11.29,100,1,15.91,100,1,11.24,100,1,15.98,100,1,11.14,700,1,16.1,100,1,11.07,700,1,16.11,700,1,11.05,100,1,16.15,700,1,11.01,100,1,16.2,200,2,10.99,700,1,16.22,100,1,10.93,200,2,16.3,700,1
2025-07-17T13:30:00.870053791Z,2025-07-17T13:30:00.870229401Z,160,2,1108,C,A,0,19.58,100,0,175610,28964016,ARL,42204681,11.76,100,1,15.3,100,1,11.52,100,1,15.61,100,1,11.29,100,1,15.91,100,1,11.24,100,1,15.98,100,1,11.14,700,1,16.1,100,1,11.07,700,1,16.11,700,1,11.05,100,1,16.15,700,1,11.01,100,1,16.2,200,2,10.99,700,1,16.22,100,1,10.93,200,2,16.3,700,1
2025-07-17T13:30:00.870053791Z,2025-07-17T13:30:00.870229401Z,160,2,1108,A,A,0,18.38,100,0,175610,28964016,ARL,43314253,11.76,100,1,15.3,100,1,11.52,100,1,15.61,100,1,11.29,100,1,15.91,100,1,11.24,100,1,15.98,100,1,11.14,700,1,16.1,100,1,11.07,700,1,16.11,700,1,11.05,100,1,16.15,700,1,11.01,100,1,16.2,200,2,10.99,700,1,16.22,100,1,10.93,200,2,16.3,700,1
2025-07-17T13:30:00.870054073Z,2025-07-17T13:30:00.870229401Z,160,2,1108,C,A,0,19.58,100,0,175328,28964017,ARL,42946053,11.76,100,1,15.3,100,1,11.52,100,1,15.61,100,1,11.29,100,1,15.91,100,1,11.24,100,1,15.98,100,1,11.14,700,1,16.1,100,1,11.07,700,1,16.11,700,1,11.05,100,1,16.15,700,1,11.01,100,1,16.2,200,2,10.99,700,1,16.22,100,1,10.93,200,2,16.3,700,1
2025-07-17T13:30:00.870054073Z,2025-07-17T13:30:00.870229401Z,160,2,1108,A,A,0,18.38,100,128,175328,28964017,ARL,43314257,11.76,100,1,15.3,100,1,11.52,100,1,15.61,100,1,11.29,100,1,15.91,100,1,11.24,100,1,15.98,100,1,11.14,700,1,16.1,100,1,11.07,700,1,16.11,700,1,11.05,100,1,16.15,700,1,11.01,100,1,16.2,200,2,10.99,700,1,16.22,100,1,10.93,200,2,16.3,700,1
2025-07-17T13:30:00.870063003Z,2025-07-17T13:30:00.870236146Z,160,2,1108,C,A,0,18.36,100,0,173143,28964020,ARL,43313633,11.76,100,1,15.3,100,1,11.52,100,1,15.61,100,1,11.29,100,1,15.91,100,1,11.24,100,1,15.98,100,1,11.14,700,1,16.1,100,1,11.07,700,1,16.11,700,1,11.05,100,1,16.15,700,1,11.01,100,1,16.2,200,2,10.99,700,1,16.22,100,1,10.93,200,2,16.3,700,1
2025-07-17T13:30:00.870063920Z,2025-07-17T13:30:00.870236146Z,160,2,1108,C,B,0,9.41,100,128,172226,28964021,ARL,43313681,11.76,100,1,15.3,100,1,11.52,100,1,15.61,100,1,11.29,100,1,15.91,100,1,11.24,100,1,15.98,100,1,11.14,700,1,16.1,100,1,11.07,700,1,16.11,700,1,11.05,100,1,16.15,700,1,11.01,100,1,16.2,200,2,10.99,700,1,16.22,100,1,10.93,200,2,16.3,700,1
2025-07-17T13:30:00.870151543Z,2025-07-17T13:30:00.870319397Z,160,2,1108,A,B,0,10.61,100,128,167854,28964128,ARL,43314465,11.76,100,1,15.3,100,1,11.52,100,1,15.61,100,1,11.29,100,1,15.91,100,1,11.24,100,1,15.98,100,1,11.14,700,1,16.1,100,1,11.07,700,1,16.11,700,1,11.05,100,1,16.15,700,1,11.01,100,1,16.2,200,2,10.99,700,1,16.22,100,1,10.93,200,2,16.3,700,1
2025-07-17T13:30:00.870209113Z,2025-07-17T13:30:00.870390228Z,160,2,1108,A,A,0,17.23,100,128,181115,28964207,ARL,43314561,11.76,100,1,15.3,100,1,11.52,100,1,15.61,100,1,11.29,100,1,15.91,100,1,11.24,100,1,15.98,100,1,11.14,700,1,16.1,100,1,11.07,700,1,16.11,700,1,11.05,100,1,16.15,700,1,11.01,100,1,16.2,200,2,10.99,700,1,16.22,100,1,10.93,200,2,16.3,700,1
2025-07-17T13:30:00.870273955Z,2025-07-17T13:30:00.870452050Z,160,2,1108,C,B,0,11.24,100,0,178095,28964259,ARL,43313941,11.76,100,1,15.3,100,1,11.52,100,1,15.61,100,1,11.29,100,1,15.91,100,1,11.14,700,1,15.98,100,1,11.07,700,1,16.1,100,1,11.05,100,1,16.11,700,1,11.01,100,1,16.15,700,1,10.99,700,1,16.2,200,2,10.93,200,2,16.22,100,1,10.92,200,2,16.3,700,1
2025-07-17T13:30:00.870278857Z,2025-07-17T13:30:00.870452050Z,160,2,1108,C,A,0,15.98,100,128,173193,28964260,ARL,43314009,11.76,100,1,15.3,100,1,11.52,100,1,15.61,100,1,11.29,100,1,15.91,100,1,11.14,700,1,16.1,100,1,11.07,700,1,16.11,700,1,11.05,100,1,16.15,700,1,11.01,100,1,16.2,200,2,10.99,700,1,16.22,100,1,10.93,200,2,16.3,700,1,10.92,200,2,16.38,200,2
2025-07-17T13:30:00.870579856Z,2025-07-17T13:30:00.870748921Z,160,2,1108,C,B,0,9.41,100,0,169065,28964629,ARL,43313553,11.76,100,1,15.3,100,1,11.52,100,1,15.61,100,1,11.29,100,1,15.91,100,1,11.14,700,1,16.1,100,1,11.07,700,1,16.11,700,1,11.05,100,1,16.15,700,1,11.01,100,1,16.2,200,2,10.99,700,1,16.22,100,1,10.93,200,2,16.3,700,1,10.92,200,2,16.38,200,2
2025-07-17T13:30:00.870580243Z,2025-07-17T13:30:00.870748921Z,160,2,1108,C,A,0,18.36,100,128,168678,28964630,ARL,43313565,11.76,100,1,15.3,100,1,11.52,100,1,15.61,100,1,11.29,100,1,15.91,100,1,11.14,700,1,16.1,100,1,11.07,700,1,16.11,700,1,11.05,100,1,16.15,700,1,11.01,100,1,16.2,200,2,10.99,700,1,16.22,100,1,10.93,200,2,16.3,700,1,10.92,200,2,16.38,200,2
2025-07-17T13:30:00.870848973Z,2025-07-17T13:30:00.871024910Z,160,2,1108,A,B,0,11.4,100,128,175937,28964903,ARL,43315905,11.76,100,1,15.3,100,1,11.52,100,1,15.61,100,1,11.4,100,1,15.91,100,1,11.29,100,1,16.1,100,1,11.14,700,1,16.11,700,1,11.07,700,1,16.15,700,1,11.05,100,1,16.2,200,2,11.01,100,1,16.22,100,1,10.99,700,1,16.3,700,1,10.93,200,2,16.38,200,2
2025-07-17T13:30:00.870874152Z,2025-07-17T13:30:00.871047347Z,160,2,1108,C,B,0,10.11,100,128,173195,28964931,ARL,42583289,11.76,100,1,15.3,100,1,11.52,100,1,15.61,100,1,11.4,100,1,15.91,100,1,11.29,100,1,16.1,100,1,11.14,700,1,16.11,700,1,11.07,700,1,16.15,700,1,11.05,100,1,16.2,200,2,11.01,100,1,16.22,100,1,10.99,700,1,16.3,700,1,10.93,200,2,16.38,200,2
2025-07-17T13:30:00.871359085Z,2025-07-17T13:30:00.871535485Z,160,2,1108,A,A,0,16.38,100,128,176400,28965402,ARL,43317137,11.76,100,1,15.3,100,1,11.52,100,1,15.61,100,1,11.4,100,1,15.91,100,1,11.29,100,1,16.1,100,1,11.14,700,1,16.11,700,1,11.07,700,1,16.15,700,1,11.05,100,1,16.2,200,2,11.01,100,1,16.22,100,1,10.99,700,1,16.3,700,1,10.93,200,2,16.38,300,3
2025-07-17T13:30:00.871371794Z,2025-07-17T13:30:00.871544335Z,160,2,1108,A,B,0,10.61,100,128,172541,28965409,ARL,43317177,11.76,100,1,15.3,100,1,11.52,100,1,15.61,100,1,11.4,100,1,15.91,100,1,11.29,100,1,16.1,100,1,11.14,700,1,16.11,700,1,11.07,700,1,16.15,700,1,11.05,100,1,16.2,200,2,11.01,100,1,16.22,100,1,10.99,700,1,16.3,700,1,10.93,200,2,16.38,300,3
2025-07-17T13:30:00.871379595Z,2025-07-17T13:30:00.871552017Z,160,2,1108,A,A,0,17.23,100,0,172422,28965416,ARL,43317185,11.76,100,1,15.3,100,1,11.52,100,1,15.61,100,1,11.4,100,1,15.91,100,1,11.29,100,1,16.1,100,1,11.14,700,1,16.11,700,1,11.07,700,1,16.15,700,1,11.05,100,1,16.2,200,2,11.01,100,1,16.22,100,1,10.99,700,1,16.3,700,1,10.93,200,2,16.38,300,3
2025-07-17T13:30:00.871381021Z,2025-07-17T13:30:00.871552017Z,160,2,1108,C,A,0,17.45,100,128,170996,28965418,ARL,42583293,11.76,100,1,15.3,100,1,11.52,100,1,15.61,100,1,11.4,100,1,15.91,100,1,11.29,100,1,16.1,100,1,11.14,700,1,16.11,700,1,11.07,700,1,16.15,700,1,11.05,100,1,16.2,200,2,11.01,100,1,16.22,100,1,10.99,700,1,16.3,700,1,10.93,200,2,16.38,300,3
2025-07-17T13:30:00.871520352Z,2025-07-17T13:30:00.871701004Z,160,2,1108,C,B,0,10.84,100,0,180652,28965571,ARL,41635065,11.76,100,1,15.3,100,1,11.52,100,1,15.61,100,1,11.4,100,1,15.91,100,1,11.29,100,1,16.1,100,1,11.14,700,1,16.11,700,1,11.07,700,1,16.15,700,1,11.05,100,1,16.2,200,2,11.01,100,1,16.22,100,1,10.99,700,1,16.3,700,1,10.93,200,2,16.38,300,3
2025-07-17T13:30:00.871520352Z,2025-07-17T13:30:00.871701004Z,160,2,1108,A,B,0,12.23,100,128,180652,28965571,ARL,43317473,12.23,100,1,15.3,100,1,11.76,100,1,15.61,100,1,11.52,100,1,15.91,100,1,11.4,100,1,16.1,100,1,11.29,100,1,16.11,700,1,11.14,700,1,16.15,700,1,11.07,700,1,16.2,200,2,11.05,100,1,16.22,100,1,11.01,100,1,16.3,700,1,10.99,700,1,16.38,300,3
2025-07-17T13:30:00.871548318Z,2025-07-17T13:30:00.871723283Z,160,2,1108,C,A,0,16.49,100,0,174965,28965592,ARL,41635069,12.23,100,1,15.3,100,1,11.76,100,1,15.61,100,1,11.52,100,1,15.91,100,1,11.4,100,1,16.1,100,1,11.29,100,1,16.11,700,1,11.14,700,1,16.15,700,1,11.07,700,1,16.2,200,2,11.05,100,1,16.22,100,1,11.01,100,1,16.3,700,1,10.99,700,1,16.38,300,3
2025-07-17T13:30:00.871548318Z,2025-07-17T13:30:00.871723283Z,160,2,1108,A,A,0,15.47,100,128,174965,28965592,ARL,43317561,12.23,100,1,15.3,100,1,11.76,100,1,15.47,100,1,11.52,100,1,15.61,100,1,11.4,100,1,15.91,100,1,11.29,100,1,16.1,100,1,11.14,700,1,16.11,700,1,11.07,700,1,16.15,700,1,11.05,100,1,16.2,200,2,11.01,100,1,16.22,100,1,10.99,700,1,16.3,700,1
2025-07-17T13:30:00.911486897Z,2025-07-17T13:30:00.911711427Z,160,2,1108,A,B,0,11.69,2,128,224530,28973032,ARL,43324133,12.23,100,1,15.3,100,1,11.76,100,1,15.47,100,1,11.69,2,1,15.61,100,1,11.52,100,1,15.91,100,1,11.4,100,1,16.1,100,1,11.29,100,1,16.11,700,1,11.14,700,1,16.15,700,1,11.07,700,1,16.2,200,2,11.05,100,1,16.22,100,1,11.01,100,1,16.3,700,1
2025-07-17T13:30:00.914351054Z,2025-07-17T13:30:00.914528735Z,160,2,1108,A,A,0,15.31,2,128,177681,28975648,ARL,43328313,12.23,100,1,15.3,100,1,11.76,100,1,15.31,2,1,11.69,2,1,15.47,100,1,11.52,100,1,15.61,100,1,11.4,100,1,15.91,100,1,11.29,100,1,16.1,100,1,11.14,700,1,16.11,700,1,11.07,700,1,16.15,700,1,11.05,100,1,16.2,200,2,11.01,100,1,16.22,100,1
2025-07-17T13:30:00.915197739Z,2025-07-17T13:30:00.915372008Z,160,2,1108,C,B,0,10.58,100,0,174269,28976307,ARL,41376725,12.23,100,1,15.3,100,1,11.76,100,1,15.31,2,1,11.69,2,1,15.47,100,1,11.52,100,1,15.61,100,1,11.4,100,1,15.91,100,1,11.29,100,1,16.1,100,1,11.14,700,1,16.11,700,1,11.07,700,1,16.15,700,1,11.05,100,1,16.2,200,2,11.01,100,1,16.22,100,1
2025-07-17T13:30:00.915197739Z,2025-07-17T13:30:00.915372008Z,160,2,1108,A,B,0,11.93,100,130,174269,28976307,ARL,43329953,12.23,100,1,15.3,100,1,11.93,100,1,15.31,2,1,11.76,100,1,15.47,100,1,11.69,2,1,15.61,100,1,11.52,100,1,15.91,100,1,11.4,100,1,16.1,100,1,11.29,100,1,16.11,700,1,11.14,700,1,16.15,700,1,11.07,700,1,16.2,200,2,11.05,100,1,16.22,100,1
2025-07-17T13:30:00.916332252Z,2025-07-17T13:30:00.916507980Z,160,2,1108,C,A,0,16.83,100,0,175728,28977103,ARL,41372125,12.23,100,1,15.3,100,1,11.93,100,1,15.31,2,1,11.76,100,1,15.47,100,1,11.69,2,1,15.61,100,1,11.52,100,1,15.91,100,1,11.4,100,1,16.1,100,1,11.29,100,1,16.11,700,1,11.14,700,1,16.15,700,1,11.07,700,1,16.2,200,2,11.05,100,1,16.22,100,1
2025-07-17T13:30:00.916332252Z,2025-07-17T13:30:00.916507980Z,160,2,1108,A,A,0,15.8,100,128,175728,28977103,ARL,43331877,12.23,100,1,15.3,100,1,11.93,100,1,15.31,2,1,11.76,100,1,15.47,100,1,11.69,2,1,15.61,100,1,11.52,100,1,15.8,100,1,11.4,100,1,15.91,100,1,11.29,100,1,16.1,100,1,11.14,700,1,16.11,700,1,11.07,700,1,16.15,700,1,11.05,100,1,16.2,200,2
2025-07-17T13:30:00.920144110Z,2025-07-17T13:30:00.920319545Z,160,2,1108,C,A,0,18.38,100,0,175435,28979475,ARL,43314181,12.23,100,1,15.3,100,1,11.93,100,1,15.31,2,1,11.76,100,1,15.47,100,1,11.69,2,1,15.61,100,1,11.52,100,1,15.8,100,1,11.4,100,1,15.91,100,1,11.29,100,1,16.1,100,1,11.14,700,1,16.11,700,1,11.07,700,1,16.15,700,1,11.05,100,1,16.2,200,2
2025-07-17T13:30:00.920144110Z,2025-07-17T13:30:00.920319545Z,160,2,1108,A,A,0,17.15,100,0,175435,28979475,ARL,43339133,12.23,100,1,15.3,100,1,11.93,100,1,15.31,2,1,11.76,100,1,15.47,100,1,11.69,2,1,15.61,100,1,11.52,100,1,15.8,100,1,11.4,100,1,15.91,100,1,11.29,100,1,16.1,100,1,11.14,700,1,16.11,700,1,11.07,700,1,16.15,700,1,11.05,100,1,16.2,200,2
2025-07-17T13:30:00.920147410Z,2025-07-17T13:30:00.920319545Z,160,2,1108,C,A,0,18.38,100,0,172135,28979478,ARL,43314185,12.23,100,1,15.3,100,1,11.93,100,1,15.31,2,1,11.76,100,1,15.47,100,1,11.69,2,1,15.61,100,1,11.52,100,1,15.8,100,1,11.4,100,1,15.91,100,1,11.29,100,1,16.1,100,1,11.14,700,1,16.11,700,1,11.07,700,1,16.15,700,1,11.05,100,1,16.2,200,2
2025-07-17T13:30:00.920147410Z,2025-07-17T13:30:00.920319545Z,160,2,1108,A,A,0,17.15,100,130,172135,28979478,ARL,43339165,12.23,100,1,15.3,100,1,11.93,100,1,15.31,2,1,11.76,100,1,15.47,100,1,11.69,2,1,15.61,100,1,11.52,100,1,15.8,100,1,11.4,100,1,15.91,100,1,11.29,100,1,16.1,100,1,11.14,700,1,16.11,700,1,11.07,700,1,16.15,700,1,11.05,100,1,16.2,200,2
2025-07-17T13:30:00.920208398Z,2025-07-17T13:30:00.920380241Z,160,2,1108,C,A,0,18.38,100,0,171843,28979515,ARL,43314189,12.23,100,1,15.3,100,1,11.93,100,1,15.31,2,1,11.76,100,1,15.47,100,1,11.69,2,1,15.61,100,1,11.52,100,1,15.8,100,1,11.4,100,1,15.91,100,1,11.29,100,1,16.1,100,1,11.14,700,1,16.11,700,1,11.07,700,1,16.15,700,1,11.05,100,1,16.2,200,2
2025-07-17T13:30:00.920208398Z,2025-07-17T13:30:00.920380241Z,160,2,1108,A,A,0,17.15,100,0,171843,28979515,ARL,43339333,12.23,100,1,15.3,100,1,11.93,100,1,15.31,2,1,11.76,100,1,15.47,100,1,11.69,2,1,15.61,100,1,11.52,100,1,15.8,100,1,11.4,100,1,15.91,100,1,11.29,100,1,16.1,100,1,11.14,700,1,16.11,700,1,11.07,700,1,16.15,700,1,11.05,100,1,16.2,200,2
2025-07-17T13:30:00.920208920Z,2025-07-17T13:30:00.920380241Z,160,2,1108,C,A,0,18.38,100,0,171321,28979516,ARL,43314233,12.23,100,1,15.3,100,1,11.93,100,1,15.31,2,1,11.76,100,1,15.47,100,1,11.69,2,1,15.61,100,1,11.52,100,1,15.8,100,1,11.4,100,1,15.91,100,1,11.29,100,1,16.1,100,1,11.14,700,1,16.11,700,1,11.07,700,1,16.15,700,1,11.05,100,1,16.2,200,2
2025-07-17T13:30:00.920208920Z,2025-07-17T13:30:00.920380241Z,160,2,1108,A,A,0,17.15,100,130,171321,28979516,ARL,43339337,12.23,100,1,15.3,100,1,11.93,100,1,15.31,2,1,11.76,100,1,15.47,100,1,11.69,2,1,15.61,100,1,11.52,100,1,15.8,100,1,11.4,100,1,15.91,100,1,11.29,100,1,16.1,100,1,11.14,700,1,16.11,700,1,11.07,700,1,16.15,700,1,11.05,100,1,16.2,200,2
2025-07-17T13:30:00.920209286Z,2025-07-17T13:30:00.920390005Z,160,2,1108,C,A,0,18.38,100,0,180719,28979517,ARL,43314237,12.23,100,1,15.3,100,1,11.93,100,1,15.31,2,1,11.76,100,1,15.47,100,1,11.69,2,1,15.61,100,1,11.52,100,1,15.8,100,1,11.4,100,1,15.91,100,1,11.29,100,1,16.1,100,1,11.14,700,1,16.11,700,1,11.07,700,1,16.15,700,1,11.05,100,1,16.2,200,2
2025-07-17T13:30:00.920209286Z,2025-07-17T13:30:00.920390005Z,160,2,1108,A,A,0,17.15,100,0,180719,28979517,ARL,43339341,12.23,100,1,15.3,100,1,11.93,100,1,15.31,2,1,11.76,100,1,15.47,100,1,11.69,2,1,15.61,100,1,11.52,100,1,15.8,100,1,11.4,100,1,15.91,100,1,11.29,100,1,16.1,100,1,11.14,700,1,16.11,700,1,11.07,700,1,16.15,700,1,11.05,100,1,16.2,200,2
2025-07-17T13:30:00.920216613Z,2025-07-17T13:30:00.920390005Z,160,2,1108,C,A,0,18.38,100,0,173392,28979521,ARL,43314241,12.23,100,1,15.3,100,1,11.93,100,1,15.31,2,1,11.76,100,1,15.47,100,1,11.69,2,1,15.61,100,1,11.52,100,1,15.8,100,1,11.4,100,1,15.91,100,1,11.29,100,1,16.1,100,1,11.14,700,1,16.11,700,1,11.07,700,1,16.15,700,1,11.05,100,1,16.2,200,2
2025-07-17T13:30:00.920216613Z,2025-07-17T13:30:00.920390005Z,160,2,1108,A,A,0,17.15,100,0,173392,28979521,ARL,43339377,12.23,100,1,15.3,100,1,11.93,100,1,15.31,2,1,11.76,100,1,15.47,100,1,11.69,2,1,15.61,100,1,11.52,100,1,15.8,100,1,11.4,100,1,15.91,100,1,11.29,100,1,16.1,100,1,11.14,700,1,16.11,700,1,11.07,700,1,16.15,700,1,11.05,100,1,16.2,200,2
2025-07-17T13:30:00.920217193Z,2025-07-17T13:30:00.920390005Z,160,2,1108,C,A,0,18.38,100,0,172812,28979522,ARL,43314245,12.23,100,1,15.3,100,1,11.93,100,1,15.31,2,1,11.76,100,1,15.47,100,1,11.69,2,1,15.61,100,1,11.52,100,1,15.8,100,1,11.4,100,1,15.91,100,1,11.29,100,1,16.1,100,1,11.14,700,1,16.11,700,1,11.07,700,1,16.15,700,1,11.05,100,1,16.2,200,2
2025-07-17T13:30:00.920217193Z,2025-07-17T13:30:00.920390005Z,160,2,1108,A,A,0,17.15,100,0,172812,28979522,ARL,43339381,12.23,100,1,15.3,100,1,11.93,100,1,15.31,2,1,11.76,100,1,15.47,100,1,11.69,2,1,15.61,100,1,11.52,100,1,15.8,100,1,11.4,100,1,15.91,100,1,11.29,100,1,16.1,100,1,11.14,700,1,16.11,700,1,11.07,700,1,16.15,700,1,11.05,100,1,16.2,200,2
2025-07-17T13:30:00.920217632Z,2025-07-17T13:30:00.920390005Z,160,2,1108,C,A,0,18.38,100,0,172373,28979523,ARL,43314253,12.23,100,1,15.3,100,1,11.93,100,1,15.31,2,1,11.76,100,1,15.47,100,1,11.69,2,1,15.61,100,1,11.52,100,1,15.8,100,1,11.4,100,1,15.91,100,1,11.29,100,1,16.1,100,1,11.14,700,1,16.11,700,1,11.07,700,1,16.15,700,1,11.05,100,1,16.2,200,2
2025-07-17T13:30:00.920217632Z,2025-07-17T13:30:00.920390005Z,160,2,1108,A,A,0,17.15,100,130,172373,28979523,ARL,43339385,12.23,100,1,15.3,100,1,11.93,100,1,15.31,2,1,11.76,100,1,15.47,100,1,11.69,2,1,15.61,100,1,11.52,100,1,15.8,100,1,11.4,100,1,15.91,100,1,11.29,100,1,16.1,100,1,11.14,700,1,16.11,700,1,11.07,700,1,16.15,700,1,11.05,100,1,16.2,200,2
2025-07-17T13:30:00.920351772Z,2025-07-17T13:30:00.920530105Z,160,2,1108,C,A,0,18.38,100,0,178333,28979649,ARL,43314257,12.23,100,1,15.3,100,1,11.93,100,1,15.31,2,1,11.76,100,1,15.47,100,1,11.69,2,1,15.61,100,1,11.52,100,1,15.8,100,1,11.4,100,1,15.91,100,1,11.29,100,1,16.1,100,1,11.14,700,1,16.11,700,1,11.07,700,1,16.15,700,1,11.05,100,1,16.2,200,2
2025-07-17T13:30:00.920351772Z,2025-07-17T13:30:00.920530105Z,160,2,1108,A,A,0,17.15,100,128,178333,28979649,ARL,43339565,12.23,100,1,15.3,100,1,11.93,100,1,15.31,2,1,11.76,100,1,15.47,100,1,11.69,2,1,15.61,100,1,11.52,100,1,15.8,100,1,11.4,100,1,15.91,100,1,11.29,100,1,16.1,100,1,11.14,700,1,16.11,700,1,11.07,700,1,16.15,700,1,11.05,100,1,16.2,200,2
2025-07-17T13:30:00.931432717Z,2025-07-17T13:30:00.931605690Z,160,2,1108,C,A,0,15.8,100,0,172973,28991138,ARL,43331877,12.23,100,1,15.3,100,1,11.93,100,1,15.31,2,1,11.76,100,1,15.47,100,1,11.69,2,1,15.61,100,1,11.52,100,1,15.91,100,1,11.4,100,1,16.1,100,1,11.29,100,1,16.11,700,1,11.14,700,1,16.15,700,1,11.07,700,1,16.2,200,2,11.05,100,1,16.22,100,1
2025-07-17T13:30:00.931432717Z,2025-07-17T13:30:00.931605690Z,160,2,1108,A,A,0,14.74,100,128,172973,28991138,ARL,43357029,12.23,100,1,14.74,100,1,11.93,100,1,15.3,100,1,11.76,100,1,15.31,2,1,11.69,2,1,15.47,100,1,11.52,100,1,15.61,100,1,11.4,100,1,15.91,100,1,11.29,100,1,16.1,100,1,11.14,700,1,16.11,700,1,11.07,700,1,16.15,700,1,11.05,100,1,16.2,200,2
2025-07-17T13:30:00.940916945Z,2025-07-17T13:30:00.941082601Z,160,2,1108,C,A,0,15.47,100,0,165656,29000554,ARL,43317561,12.23,100,1,14.74,100,1,11.93,100,1,15.3,100,1,11.76,100,1,15.31,2,1,11.69,2,1,15.61,100,1,11.52,100,1,15.91,100,1,11.4,100,1,16.1,100,1,11.29,100,1,16.11,700,1,11.14,700,1,16.15,700,1,11.07,700,1,16.2,200,2,11.05,100,1,16.22,100,1
2025-07-17T13:30:00.940916945Z,2025-07-17T13:30:00.941082601Z,160,2,1108,A,A,0,14.44,100,130,165656,29000554,ARL,43373009,12.23,100,1,14.44,100,1,11.93,100,1,14.74,100,1,11.76,100,1,15.3,100,1,11.69,2,1,15.31,2,1,11.52,100,1,15.61,100,1,11.4,100,1,15.91,100,1,11.29,100,1,16.1,100,1,11.14,700,1,16.11,700,1,11.07,700,1,16.15,700,1,11.05,100,1,16.2,200,2
2025-07-17T13:30:00.941071231Z,2025-07-17T13:30:00.941236862Z,160,2,1108,A,A,0,15.28,100,130,165631,29000677,ARL,43373085,12.23,100,1,14.44,100,1,11.93,100,1,14.74,100,1,11.76,100,1,15.28,100,1,11.69,2,1,15.3,100,1,11.52,100,1,15.31,2,1,11.4,100,1,15.61,100,1,11.29,100,1,15.91,100,1,11.14,700,1,16.1,100,1,11.07,700,1,16.11,700,1,11.05,100,1,16.15,700,1
2025-07-17T13:30:00.941085073Z,2025-07-17T13:30:00.941255157Z,160,2,1108,C,A,0,16.38,100,128,170084,29000688,ARL,43317137,12.23,100,1,14.44,100,1,11.93,100,1,14.74,100,1,11.76,100,1,15.28,100,1,11.69,2,1,15.3,100,1,11.52,100,1,15.31,2,1,11.4,100,1,15.61,100,1,11.29,100,1,15.91,100,1,11.14,700,1,16.1,100,1,11.07,700,1,16.11,700,1,11.05,100,1,16.15,700,1
2025-07-17T13:30:01.086438727Z,2025-07-17T13:30:01.086605950Z,160,2,1108,C,B,0,11.01,100,0,167223,29116818,ARL,42674817,12.23,100,1,14.44,100,1,11.93,100,1,14.74,100,1,11.76,100,1,15.28,100,1,11.69,2,1,15.3,100,1,11.52,100,1,15.31,2,1,11.4,100,1,15.61,100,1,11.29,100,1,15.91,100,1,11.14,700,1,16.1,100,1,11.07,700,1,16.11,700,1,11.05,100,1,16.15,700,1
2025-07-17T13:30:01.086438727Z,2025-07-17T13:30:01.086605950Z,160,2,1108,A,B,0,12.47,100,130,167223,29116818,ARL,43554133,12.47,100,1,14.44,100,1,12.23,100,1,14.74,100,1,11.93,100,1,15.28,100,1,11.76,100,1,15.3,100,1,11.69,2,1,15.31,2,1,11.52,100,1,15.61,100,1,11.4,100,1,15.91,100,1,11.29,100,1,16.1,100,1,11.14,700,1,16.11,700,1,11.07,700,1,16.15,700,1
2025-07-17T13:30:01.086456460Z,2025-07-17T13:30:01.086625226Z,160,2,1108,C,A,0,16.1,100,0,168766,29116862,ARL,42674989,12.47,100,1,14.44,100,1,12.23,100,1,14.74,100,1,11.93,100,1,15.28,100,1,11.76,100,1,15.3,100,1,11.69,2,1,15.31,2,1,11.52,100,1,15.61,100,1,11.4,100,1,15.91,100,1,11.29,100,1,16.11,700,1,11.14,700,1,16.15,700,1,11.07,700,1,16.2,200,2
2025-07-17T13:30:01.086456460Z,2025-07-17T13:30:01.086625226Z,160,2,1108,A,A,0,14.2,100,128,168766,29116862,ARL,43554141,12.47,100,1,14.2,100,1,12.23,100,1,14.44,100,1,11.93,100,1,14.74,100,1,11.76,100,1,15.28,100,1,11.69,2,1,15.3,100,1,11.52,100,1,15.31,2,1,11.4,100,1,15.61,100,1,11.29,100,1,15.91,100,1,11.14,700,1,16.11,700,1,11.07,700,1,16.15,700,1
2025-07-17T13:30:01.214703183Z,2025-07-17T13:30:01.214882922Z,160,2,1108,A,B,0,12.67,100,0,179739,29196804,ARL,43663229,12.67,100,1,14.2,100,1,12.47,100,1,14.44,100,1,12.23,100,1,14.74,100,1,11.93,100,1,15.28,100,1,11.76,100,1,15.3,100,1,11.69,2,1,15.31,2,1,11.52,100,1,15.61,100,1,11.4,100,1,15.91,100,1,11.29,100,1,16.11,700,1,11.14,700,1,16.15,700,1
2025-07-17T13:30:01.214704496Z,2025-07-17T13:30:01.214882922Z,160,2,1108,A,A,0,14,100,128,178426,29196805,ARL,43663233,12.67,100,1,14,100,1,12.47,100,1,14.2,100,1,12.23,100,1,14.44,100,1,11.93,100,1,14.74,100,1,11.76,100,1,15.28,100,1,11.69,2,1,15.3,100,1,11.52,100,1,15.31,2,1,11.4,100,1,15.61,100,1,11.29,100,1,15.91,100,1,11.14,700,1,16.11,700,1
2025-07-17T13:30:01.252206360Z,2025-07-17T13:30:01.252386379Z,160,2,1108,A,B,0,7.74,100,0,180019,29221770,ARL,27015957,12.67,100,1,14,100,1,12.47,100,1,14.2,100,1,12.23,100,1,14.44,100,1,11.93,100,1,14.74,100,1,11.76,100,1,15.28,100,1,11.69,2,1,15.3,100,1,11.52,100,1,15.31,2,1,11.4,100,1,15.61,100,1,11.29,100,1,15.91,100,1,11.14,700,1,16.11,700,1
2025-07-17T13:30:01.252206360Z,2025-07-17T13:30:01.252386379Z,160,2,1108,A,A,0,20.48,100,0,180019,29221771,ARL,27015965,12.67,100,1,14,100,1,12.47,100,1,14.2,100,1,12.23,100,1,14.44,100,1,11.93,100,1,14.74,100,1,11.76,100,1,15.28,100,1,11.69,2,1,15.3,100,1,11.52,100,1,15.31,2,1,11.4,100,1,15.61,100,1,11.29,100,1,15.91,100,1,11.14,700,1,16.11,700,1
2025-07-17T13:30:01.252206360Z,2025-07-17T13:30:01.252386379Z,160,2,1108,A,B,0,7.74,100,0,180019,29221772,ARL,38084501,12.67,100,1,14,100,1,12.47,100,1,14.2,100,1,12.23,100,1,14.44,100,1,11.93,100,1,14.74,100,1,11.76,100,1,15.28,100,1,11.69,2,1,15.3,100,1,11.52,100,1,15.31,2,1,11.4,100,1,15.61,100,1,11.29,100,1,15.91,100,1,11.14,700,1,16.11,700,1
2025-07-17T13:30:01.252206360Z,2025-07-17T13:30:01.252386379Z,160,2,1108,A,A,0,20.48,100,0,180019,29221773,ARL,38073517,12.67,100,1,14,100,1,12.47,100,1,14.2,100,1,12.23,100,1,14.44,100,1,11.93,100,1,14.74,100,1,11.76,100,1,15.28,100,1,11.69,2,1,15.3,100,1,11.52,100,1,15.31,2,1,11.4,100,1,15.61,100,1,11.29,100,1,15.91,100,1,11.14,700,1,16.11,700,1
2025-07-17T13:30:01.252206360Z,2025-07-17T13:30:01.252386379Z,160,2,1108,A,B,0,7.74,100,0,180019,29221774,ARL,38130589,12.67,100,1,14,100,1,12.47,100,1,14.2,100,1,12.23,100,1,14.44,100,1,11.93,100,1,14.74,100,1,11.76,100,1,15.28,100,1,11.69,2,1,15.3,100,1,11.52,100,1,15.31,2,1,11.4,100,1,15.61,100,1,11.29,100,1,15.91,100,1,11.14,700,1,16.11,700,1
2025-07-17T13:30:01.252206360Z,2025-07-17T13:30:01.252386379Z,160,2,1108,A,A,0,20.48,100,0,180019,29221775,ARL,38134973,12.67,100,1,14,100,1,12.47,100,1,14.2,100,1,12.23,100,1,14.44,100,1,11.93,100,1,14.74,100,1,11.76,100,1,15.28,100,1,11.69,2,1,15.3,100,1,11.52,100,1,15.31,2,1,11.4,100,1,15.61,100,1,11.29,100,1,15.91,100,1,11.14,700,1,16.11,700,1
2025-07-17T13:30:01.252206360Z,2025-07-17T13:30:01.252386379Z,160,2,1108,A,B,0,7.74,100,0,180019,29221776,ARL,38470185,12.67,100,1,14,100,1,12.47,100,1,14.2,100,1,12.23,100,1,14.44,100,1,11.93,100,1,14.74,100,1,11.76,100,1,15.28,100,1,11.69,2,1,15.3,100,1,11.52,100,1,15.31,2,1,11.4,100,1,15.61,100,1,11.29,100,1,15.91,100,1,11.14,700,1,16.11,700,1
2025-07-17T13:30:01.252206360Z,2025-07-17T13:30:01.252386379Z,160,2,1108,A,A,0,20.48,100,0,180019,29221777,ARL,38471493,12.67,100,1,14,100,1,12.47,100,1,14.2,100,1,12.23,100,1,14.44,100,1,11.93,100,1,14.74,100,1,11.76,100,1,15.28,100,1,11.69,2,1,15.3,100,1,11.52,100,1,15.31,2,1,11.4,100,1,15.61,100,1,11.29,100,1,15.91,100,1,11.14,700,1,16.11,700,1
2025-07-17T13:30:01.252206360Z,2025-07-17T13:30:01.252386379Z,160,2,1108,A,B,0,7.74,100,0,180019,29221778,ARL,38759997,12.67,100,1,14,100,1,12.47,100,1,14.2,100,1,12.23,100,1,14.44,100,1,11.93,100,1,14.74,100,1,11.76,100,1,15.28,100,1,11.69,2,1,15.3,100,1,11.52,100,1,15.31,2,1,11.4,100,1,15.61,100,1,11.29,100,1,15.91,100,1,11.14,700,1,16.11,700,1
2025-07-17T13:30:01.252206360Z,2025-07-17T13:30:01.252386379Z,160,2,1108,A,A,0,20.48,100,0,180019,29221779,ARL,38758965,12.67,100,1,14,100,1,12.47,100,1,14.2,100,1,12.23,100,1,14.44,100,1,11.93,100,1,14.74,100,1,11.76,100,1,15.28,100,1,11.69,2,1,15.3,100,1,11.52,100,1,15.31,2,1,11.4,100,1,15.61,100,1,11.29,100,1,15.91,100,1,11.14,700,1,16.11,700,1
2025-07-17T13:30:01.252206360Z,2025-07-17T13:30:01.252386379Z,160,2,1108,A,B,0,7.74,100,0,180019,29221780,ARL,38775373,12.67,100,1,14,100,1,12.47,100,1,14.2,100,1,12.23,100,1,14.44,100,1,11.93,100,1,14.74,100,1,11.76,100,1,15.28,100,1,11.69,2,1,15.3,100,1,11.52,100,1,15.31,2,1,11.4,100,1,15.61,100,1,11.29,100,1,15.91,100,1,11.14,700,1,16.11,700,1
2025-07-17T13:30:01.252206360Z,2025-07-17T13:30:01.252386379Z,160,2,1108,A,A,0,20.48,100,0,180019,29221781,ARL,38776877,12.67,100,1,14,100,1,12.47,100,1,14.2,100,1,12.23,100,1,14.44,100,1,11.93,100,1,14.74,100,1,11.76,100,1,15.28,100,1,11.69,2,1,15.3,100,1,11.52,100,1,15.31,2,1,11.4,100,1,15.61,100,1,11.29,100,1,15.91,100,1,11.14,700,1,16.11,700,1
2025-07-17T13:30:01.252206360Z,2025-07-17T13:30:01.252386379Z,160,2,1108,A,B,0,7.74,100,0,180019,29221782,ARL,38865193,12.67,100,1,14,100,1,12.47,100,1,14.2,100,1,12.23,100,1,14.44,100,1,11.93,100,1,14.74,100,1,11.76,100,1,15.28,100,1,11.69,2,1,15.3,100,1,11.52,100,1,15.31,2,1,11.4,100,1,15.61,100,1,11.29,100,1,15.91,100,1,11.14,700,1,16.11,700,1
2025-07-17T13:30:01.252206360Z,2025-07-17T13:30:01.252386379Z,160,2,1108,A,A,0,20.48,100,128,180019,29221783,ARL,38863877,12.67,100,1,14,100,1,12.47,100,1,14.2,100,1,12.23,100,1,14.44,100,1,11.93,100,1,14.74,100,1,11.76,100,1,15.28,100,1,11.69,2,1,15.3,100,1,11.52,100,1,15.31,2,1,11.4,100,1,15.61,100,1,11.29,100,1,15.91,100,1,11.14,700,1,16.11,700,1
2025-07-17T13:30:01.252269158Z,2025-07-17T13:30:01.252444419Z,160,2,1108,C,B,0,7.74,100,0,175261,29221828,ARL,27015957,12.67,100,1,14,100,1,12.47,100,1,14.2,100,1,12.23,100,1,14.44,100,1,11.93,100,1,14.74,100,1,11.76,100,1,15.28,100,1,11.69,2,1,15.3,100,1,11.52,100,1,15.31,2,1,11.4,100,1,15.61,100,1,11.29,100,1,15.91,100,1,11.14,700,1,16.11,700,1
2025-07-17T13:30:01.252269158Z,2025-07-17T13:30:01.252444419Z,160,2,1108,A,B,0,9.55,100,0,175261,29221828,ARL,43690797,12.67,100,1,14,100,1,12.47,100,1,14.2,100,1,12.23,100,1,14.44,100,1,11.93,100,1,14.74,100,1,11.76,100,1,15.28,100,1,11.69,2,1,15.3,100,1,11.52,100,1,15.31,2,1,11.4,100,1,15.61,100,1,11.29,100,1,15.91,100,1,11.14,700,1,16.11,700,1
2025-07-17T13:30:01.252269575Z,2025-07-17T13:30:01.252444419Z,160,2,1108,C,B,0,7.74,100,0,174844,29221829,ARL,38084501,12.67,100,1,14,100,1,12.47,100,1,14.2,100,1,12.23,100,1,14.44,100,1,11.93,100,1,14.74,100,1,11.76,100,1,15.28,100,1,11.69,2,1,15.3,100,1,11.52,100,1,15.31,2,1,11.4,100,1,15.61,100,1,11.29,100,1,15.91,100,1,11.14,700,1,16.11,700,1
2025-07-17T13:30:01.252269575Z,2025-07-17T13:30:01.252444419Z,160,2,1108,A,B,0,9.55,100,0,174844,29221829,ARL,43690801,12.67,100,1,14,100,1,12.47,100,1,14.2,100,1,12.23,100,1,14.44,100,1,11.93,100,1,14.74,100,1,11.76,100,1,15.28,100,1,11.69,2,1,15.3,100,1,11.52,100,1,15.31,2,1,11.4,100,1,15.61,100,1,11.29,100,1,15.91,100,1,11.14,700,1,16.11,700,1
2025-07-17T13:30:01.252269960Z,2025-07-17T13:30:01.252444419Z,160,2,1108,C,B,0,7.74,100,0,174459,29221830,ARL,38130589,12.67,100,1,14,100,1,12.47,100,1,14.2,100,1,12.23,100,1,14.44,100,1,11.93,100,1,14.74,100,1,11.76,100,1,15.28,100,1,11.69,2,1,15.3,100,1,11.52,100,1,15.31,2,1,11.4,100,1,15.61,100,1,11.29,100,1,15.91,100,1,11.14,700,1,16.11,700,1
2025-07-17T13:30:01.252269960Z,2025-07-17T13:30:01.252444419Z,160,2,1108,A,B,0,9.55,100,0,174459,29221830,ARL,43690805,12.67,100,1,14,100,1,12.47,100,1,14.2,100,1,12.23,100,1,14.44,100,1,11.93,100,1,14.74,100,1,11.76,100,1,15.28,100,1,11.69,2,1,15.3,100,1,11.52,100,1,15.31,2,1,11.4,100,1,15.61,100,1,11.29,100,1,15.91,100,1,11.14,700,1,16.11,700,1
2025-07-17T13:30:01.252270596Z,2025-07-17T13:30:01.252444419Z,160,2,1108,C,B,0,7.74,100,0,173823,29221831,ARL,38470185,12.67,100,1,14,100,1,12.47,100,1,14.2,100,1,12.23,100,1,14.44,100,1,11.93,100,1,14.74,100,1,11.76,100,1,15.28,100,1,11.69,2,1,15.3,100,1,11.52,100,1,15.31,2,1,11.4,100,1,15.61,100,1,11.29,100,1,15.91,100,1,11.14,700,1,16.11,700,1
2025-07-17T13:30:01.252270596Z,2025-07-17T13:30:01.252444419Z,160,2,1108,A,B,0,9.55,100,0,173823,29221831,ARL,43690809,12.67,100,1,14,100,1,12.47,100,1,14.2,100,1,12.23,100,1,14.44,100,1,11.93,100,1,14.74,100,1,11.76,100,1,15.28,100,1,11.69,2,1,15.3,100,1,11.52,100,1,15.31,2,1,11.4,100,1,15.61,100,1,11.29,100,1,15.91,100,1,11.14,700,1,16.11,700,1
2025-07-17T13:30:01.252270987Z,2025-07-17T13:30:01.252444419Z,160,2,1108,C,B,0,7.74,100,0,173432,29221832,ARL,38759997,12.67,100,1,14,100,1,12.47,100,1,14.2,100,1,12.23,100,1,14.44,100,1,11.93,100,1,14.74,100,1,11.76,100,1,15.28,100,1,11.69,2,1,15.3,100,1,11.52,100,1,15.31,2,1,11.4,100,1,15.61,100,1,11.29,100,1,15.91,100,1,11.14,700,1,16.11,700,1
2025-07-17T13:30:01.252270987Z,2025-07-17T13:30:01.252444419Z,160,2,1108,A,B,0,9.55,100,0,173432,29221832,ARL,43690813,12.67,100,1,14,100,1,12.47,100,1,14.2,100,1,12.23,100,1,14.44,100,1,11.93,100,1,14.74,100,1,11.76,100,1,15.28,100,1,11.69,2,1,15.3,100,1,11.52,100,1,15.31,2,1,11.4,100,1,15.61,100,1,11.29,100,1,15.91,100,1,11.14,700,1,16.11,700,1
2025-07-17T13:30:01.252271274Z,2025-07-17T13:30:01.252444419Z,160,2,1108,C,B,0,7.74,100,0,173145,29221833,ARL,38775373,12.67,100,1,14,100,1,12.47,100,1,14.2,100,1,12.23,100,1,14.44,100,1,11.93,100,1,14.74,100,1,11.76,100,1,15.28,100,1,11.69,2,1,15.3,100,1,11.52,100,1,15.31,2,1,11.4,100,1,15.61,100,1,11.29,100,1,15.91,100,1,11.14,700,1,16.11,700,1
2025-07-17T13:30:01.252271274Z,2025-07-17T13:30:01.252444419Z,160,2,1108,A,B,0,9.55,100,0,173145,29221833,ARL,43690817,12.67,100,1,14,100,1,12.47,100,1,14.2,100,1,12.23,100,1,14.44,100,1,11.93,100,1,14.74,100,1,11.76,100,1,15.28,100,1,11.69,2,1,15.3,100,1,11.52,100,1,15.31,2,1,11.4,100,1,15.61,100,1,11.29,100,1,15.91,100,1,11.14,700,1,16.11,700,1
2025-07-17T13:30:01.252272011Z,2025-07-17T13:30:01.252444419Z,160,2,1108,C,B,0,7.74,100,0,172408,29221834,ARL,38865193,12.67,100,1,14,100,1,12.47,100,1,14.2,100,1,12.23,100,1,14.44,100,1,11.93,100,1,14.74,100,1,11.76,100,1,15.28,100,1,11.69,2,1,15.3,100,1,11.52,100,1,15.31,2,1,11.4,100,1,15.61,100,1,11.29,100,1,15.91,100,1,11.14,700,1,16.11,700,1
2025-07-17T13:30:01.252272011Z,2025-07-17T13:30:01.252444419Z,160,2,1108,A,B,0,9.55,100,128,172408,29221834,ARL,43690821,12.67,100,1,14,100,1,12.47,100,1,14.2,100,1,12.23,100,1,14.44,100,1,11.93,100,1,14.74,100,1,11.76,100,1,15.28,100,1,11.69,2,1,15.3,100,1,11.52,100,1,15.31,2,1,11.4,100,1,15.61,100,1,11.29,100,1,15.91,100,1,11.14,700,1,16.11,700,1
2025-07-17T13:30:01.252279681Z,2025-07-17T13:30:01.252457898Z,160,2,1108,C,A,0,20.48,100,0,178217,29221840,ARL,27015965,12.67,100,1,14,100,1,12.47,100,1,14.2,100,1,12.23,100,1,14.44,100,1,11.93,100,1,14.74,100,1,11.76,100,1,15.28,100,1,11.69,2,1,15.3,100,1,11.52,100,1,15.31,2,1,11.4,100,1,15.61,100,1,11.29,100,1,15.91,100,1,11.14,700,1,16.11,700,1
2025-07-17T13:30:01.252279681Z,2025-07-17T13:30:01.252457898Z,160,2,1108,A,A,0,17.15,100,0,178217,29221840,ARL,43690825,12.67,100,1,14,100,1,12.47,100,1,14.2,100,1,12.23,100,1,14.44,100,1,11.93,100,1,14.74,100,1,11.76,100,1,15.28,100,1,11.69,2,1,15.3,100,1,11.52,100,1,15.31,2,1,11.4,100,1,15.61,100,1,11.29,100,1,15.91,100,1,11.14,700,1,16.11,700,1
2025-07-17T13:30:01.252280017Z,2025-07-17T13:30:01.252457898Z,160,2,1108,C,A,0,20.48,100,0,177881,29221841,ARL,38073517,12.67,100,1,14,100,1,12.47,100,1,14.2,100,1,12.23,100,1,14.44,100,1,11.93,100,1,14.74,100,1,11.76,100,1,15.28,100,1,11.69,2,1,15.3,100,1,11.52,100,1,15.31,2,1,11.4,100,1,15.61,100,1,11.29,100,1,15.91,100,1,11.14,700,1,16.11,700,1
2025-07-17T13:30:01.252280017Z,2025-07-17T13:30:01.252457898Z,160,2,1108,A,A,0,17.15,100,0,177881,29221841,ARL,43690829,12.67,100,1,14,100,1,12.47,100,1,14.2,100,1,12.23,100,1,14.44,100,1,11.93,100,1,14.74,100,1,11.76,100,1,15.28,100,1,11.69,2,1,15.3,100,1,11.52,100,1,15.31,2,1,11.4,100,1,15.61,100,1,11.29,100,1,15.91,100,1,11.14,700,1,16.11,700,1
2025-07-17T13:30:01.252280383Z,2025-07-17T13:30:01.252457898Z,160,2,1108,C,A,0,20.48,100,0,177515,29221842,ARL,38134973,12.67,100,1,14,100,1,12.47,100,1,14.2,100,1,12.23,100,1,14.44,100,1,11.93,100,1,14.74,100,1,11.76,100,1,15.28,100,1,11.69,2,1,15.3,100,1,11.52,100,1,15.31,2,1,11.4,100,1,15.61,100,1,11.29,100,1,15.91,100,1,11.14,700,1,16.11,700,1
2025-07-17T13:30:01.252280383Z,2025-07-17T13:30:01.252457898Z,160,2,1108,A,A,0,17.15,100,0,177515,29221842,ARL,43690833,12.67,100,1,14,100,1,12.47,100,1,14.2,100,1,12.23,100,1,14.44,100,1,11.93,100,1,14.74,100,1,11.76,100,1,15.28,100,1,11.69,2,1,15.3,100,1,11.52,100,1,15.31,2,1,11.4,100,1,15.61,100,1,11.29,100,1,15.91,100,1,11.14,700,1,16.11,700,1
2025-07-17T13:30:01.252280683Z,2025-07-17T13:30:01.252457898Z,160,2,1108,C,A,0,20.48,100,0,177215,29221843,ARL,38471493,12.67,100,1,14,100,1,12.47,100,1,14.2,100,1,12.23,100,1,14.44,100,1,11.93,100,1,14.74,100,1,11.76,100,1,15.28,100,1,11.69,2,1,15.3,100,1,11.52,100,1,15.31,2,1,11.4,100,1,15.61,100,1,11.29,100,1,15.91,100,1,11.14,700,1,16.11,700,1
2025-07-17T13:30:01.252280683Z,2025-07-17T13:30:01.252457898Z,160,2,1108,A,A,0,17.15,100,0,177215,29221843,ARL,43690837,12.67,100,1,14,100,1,12.47,100,1,14.2,100,1,12.23,100,1,14.44,100,1,11.93,100,1,14.74,100,1,11.76,100,1,15.28,100,1,11.69,2,1,15.3,100,1,11.52,100,1,15.31,2,1,11.4,100,1,15.61,100,1,11.29,100,1,15.91,100,1,11.14,700,1,16.11,700,1
2025-07-17T13:30:01.252281079Z,2025-07-17T13:30:01.252457898Z,160,2,1108,C,A,0,20.48,100,0,176819,29221844,ARL,38758965,12.67,100,1,14,100,1,12.47,100,1,14.2,100,1,12.23,100,1,14.44,100,1,11.93,100,1,14.74,100,1,11.76,100,1,15.28,100,1,11.69,2,1,15.3,100,1,11.52,100,1,15.31,2,1,11.4,100,1,15.61,100,1,11.29,100,1,15.91,100,1,11.14,700,1,16.11,700,1
2025-07-17T13:30:01.252281079Z,2025-07-17T13:30:01.252457898Z,160,2,1108,A,A,0,17.15,100,0,176819,29221844,ARL,43690841,12.67,100,1,14,100,1,12.47,100,1,14.2,100,1,12.23,100,1,14.44,100,1,11.93,100,1,14.74,100,1,11.76,100,1,15.28,100,1,11.69,2,1,15.3,100,1,11.52,100,1,15.31,2,1,11.4,100,1,15.61,100,1,11.29,100,1,15.91,100,1,11.14,700,1,16.11,700,1
2025-07-17T13:30:01.252281306Z,2025-07-17T13:30:01.252457898Z,160,2,1108,C,A,0,20.48,100,0,176592,29221845,ARL,38776877,12.67,100,1,14,100,1,12.47,100,1,14.2,100,1,12.23,100,1,14.44,100,1,11.93,100,1,14.74,100,1,11.76,100,1,15.28,100,1,11.69,2,1,15.3,100,1,11.52,100,1,15.31,2,1,11.4,100,1,15.61,100,1,11.29,100,1,15.91,100,1,11.14,700,1,16.11,700,1
2025-07-17T13:30:01.252281306Z,2025-07-17T13:30:01.252457898Z,160,2,1108,A,A,0,17.15,100,0,176592,29221845,ARL,43690845,12.67,100,1,14,100,1,12.47,100,1,14.2,100,1,12.23,100,1,14.44,100,1,11.93,100,1,14.74,100,1,11.76,100,1,15.28,100,1,11.69,2,1,15.3,100,1,11.52,100,1,15.31,2,1,11.4,100,1,15.61,100,1,11.29,100,1,15.91,100,1,11.14,700,1,16.11,700,1
2025-07-17T13:30:01.252281648Z,2025-07-17T13:30:01.252457898Z,160,2,1108,C,A,0,20.48,100,0,176250,29221846,ARL,38863877,12.67,100,1,14,100,1,12.47,100,1,14.2,100,1,12.23,100,1,14.44,100,1,11.93,100,1,14.74,100,1,11.76,100,1,15.28,100,1,11.69,2,1,15.3,100,1,11.52,100,1,15.31,2,1,11.4,100,1,15.61,100,1,11.29,100,1,15.91,100,1,11.14,700,1,16.11,700,1
2025-07-17T13:30:01.252281648Z,2025-07-17T13:30:01.252457898Z,160,2,1108,A,A,0,17.15,100,130,176250,29221846,ARL,43690849,12.67,100,1,14,100,1,12.47,100,1,14.2,100,1,12.23,100,1,14.44,100,1,11.93,100,1,14.74,100,1,11.76,100,1,15.28,100,1,11.69,2,1,15.3,100,1,11.52,100,1,15.31,2,1,11.4,100,1,15.61,100,1,11.29,100,1,15.91,100,1,11.14,700,1,16.11,700,1
2025-07-17T13:30:01.254829854Z,2025-07-17T13:30:01.255007539Z,160,2,1108,C,B,0,11.69,2,0,177685,29223480,ARL,43324133,12.67,100,1,14,100,1,12.47,100,1,14.2,100,1,12.23,100,1,14.44,100,1,11.93,100,1,14.74,100,1,11.76,100,1,15.28,100,1,11.52,100,1,15.3,100,1,11.4,100,1,15.31,2,1,11.29,100,1,15.61,100,1,11.14,700,1,15.91,100,1,11.07,700,1,16.11,700,1
2025-07-17T13:30:01.254829854Z,2025-07-17T13:30:01.255007539Z,160,2,1108,A,B,0,12.33,2,128,177685,29223480,ARL,43692153,12.67,100,1,14,100,1,12.47,100,1,14.2,100,1,12.33,2,1,14.44,100,1,12.23,100,1,14.74,100,1,11.93,100,1,15.28,100,1,11.76,100,1,15.3,100,1,11.52,100,1,15.31,2,1,11.4,100,1,15.61,100,1,11.29,100,1,15.91,100,1,11.14,700,1,16.11,700,1
2025-07-17T13:30:01.254836082Z,2025-07-17T13:30:01.255016966Z,160,2,1108,C,A,0,15.31,2,0,180884,29223485,ARL,43328313,12.67,100,1,14,100,1,12.47,100,1,14.2,100,1,12.33,2,1,14.44,100,1,12.23,100,1,14.74,100,1,11.93,100,1,15.28,100,1,11.76,100,1,15.3,100,1,11.52,100,1,15.61,100,1,11.4,100,1,15.91,100,1,11.29,100,1,16.11,700,1,11.14,700,1,16.15,700,1
2025-07-17T13:30:01.254836082Z,2025-07-17T13:30:01.255016966Z,160,2,1108,A,A,0,14.65,2,128,180884,29223485,ARL,43692157,12.67,100,1,14,100,1,12.47,100,1,14.2,100,1,12.33,2,1,14.44,100,1,12.23,100,1,14.65,2,1,11.93,100,1,14.74,100,1,11.76,100,1,15.28,100,1,11.52,100,1,15.3,100,1,11.4,100,1,15.61,100,1,11.29,100,1,15.91,100,1,11.14,700,1,16.11,700,1
2025-07-17T13:30:01.326934077Z,2025-07-17T13:30:01.327109477Z,160,2,1108,C,B,0,11.52,100,130,175400,29250087,ARL,42446497,12.67,100,1,14,100,1,12.47,100,1,14.2,100,1,12.33,2,1,14.44,100,1,12.23,100,1,14.65,2,1,11.93,100,1,14.74,100,1,11.76,100,1,15.28,100,1,11.4,100,1,15.3,100,1,11.29,100,1,15.61,100,1,11.14,700,1,15.91,100,1,11.07,700,1,16.11,700,1
2025-07-17T13:30:01.327714478Z,2025-07-17T13:30:01.327894898Z,160,2,1108,C,A,0,15.61,100,128,180420,29250293,ARL,42446501,12.67,100,1,14,100,1,12.47,100,1,14.2,100,1,12.33,2,1,14.44,100,1,12.23,100,1,14.65,2,1,11.93,100,1,14.74,100,1,11.76,100,1,15.28,100,1,11.4,100,1,15.3,100,1,11.29,100,1,15.91,100,1,11.14,700,1,16.11,700,1,11.07,700,1,16.15,700,1
2025-07-17T13:30:01.367244122Z,2025-07-17T13:30:01.367410233Z,160,2,1108,C,B,0,10.93,100,0,166111,29262273,ARL,41376501,12.67,100,1,14,100,1,12.47,100,1,14.2,100,1,12.33,2,1,14.44,100,1,12.23,100,1,14.65,2,1,11.93,100,1,14.74,100,1,11.76,100,1,15.28,100,1,11.4,100,1,15.3,100,1,11.29,100,1,15.91,100,1,11.14,700,1,16.11,700,1,11.07,700,1,16.15,700,1
2025-07-17T13:30:01.367244122Z,2025-07-17T13:30:01.367410233Z,160,2,1108,A,B,0,12.33,100,130,166111,29262273,ARL,43755813,12.67,100,1,14,100,1,12.47,100,1,14.2,100,1,12.33,102,2,14.44,100,1,12.23,100,1,14.65,2,1,11.93,100,1,14.74,100,1,11.76,100,1,15.28,100,1,11.4,100,1,15.3,100,1,11.29,100,1,15.91,100,1,11.14,700,1,16.11,700,1,11.07,700,1,16.15,700,1
2025-07-17T13:30:01.367256226Z,2025-07-17T13:30:01.367421844Z,160,2,1108,C,A,0,16.38,100,0,165618,29262274,ARL,41372085,12.67,100,1,14,100,1,12.47,100,1,14.2,100,1,12.33,102,2,14.44,100,1,12.23,100,1,14.65,2,1,11.93,100,1,14.74,100,1,11.76,100,1,15.28,100,1,11.4,100,1,15.3,100,1,11.29,100,1,15.91,100,1,11.14,700,1,16.11,700,1,11.07,700,1,16.15,700,1
2025-07-17T13:30:01.367256226Z,2025-07-17T13:30:01.367421844Z,160,2,1108,A,A,0,14.34,100,130,165618,29262274,ARL,43755821,12.67,100,1,14,100,1,12.47,100,1,14.2,100,1,12.33,102,2,14.34,100,1,12.23,100,1,14.44,100,1,11.93,100,1,14.65,2,1,11.76,100,1,14.74,100,1,11.4,100,1,15.28,100,1,11.29,100,1,15.3,100,1,11.14,700,1,15.91,100,1,11.07,700,1,16.11,700,1
2025-07-17T13:30:01.456460560Z,2025-07-17T13:30:01.456631847Z,160,2,1108,C,B,0,10.92,100,0,171287,29285993,ARL,43143317,12.67,100,1,14,100,1,12.47,100,1,14.2,100,1,12.33,102,2,14.34,100,1,12.23,100,1,14.44,100,1,11.93,100,1,14.65,2,1,11.76,100,1,14.74,100,1,11.4,100,1,15.28,100,1,11.29,100,1,15.3,100,1,11.14,700,1,15.91,100,1,11.07,700,1,16.11,700,1
2025-07-17T13:30:01.456460560Z,2025-07-17T13:30:01.456631847Z,160,2,1108,A,B,0,12.36,100,130,171287,29285993,ARL,43781537,12.67,100,1,14,100,1,12.47,100,1,14.2,100,1,12.36,100,1,14.34,100,1,12.33,102,2,14.44,100,1,12.23,100,1,14.65,2,1,11.93,100,1,14.74,100,1,11.76,100,1,15.28,100,1,11.4,100,1,15.3,100,1,11.29,100,1,15.91,100,1,11.14,700,1,16.11,700,1
2025-07-17T13:30:01.456476348Z,2025-07-17T13:30:01.456642950Z,160,2,1108,C,A,0,16.2,100,0,166602,29285996,ARL,43143333,12.67,100,1,14,100,1,12.47,100,1,14.2,100,1,12.36,100,1,14.34,100,1,12.33,102,2,14.44,100,1,12.23,100,1,14.65,2,1,11.93,100,1,14.74,100,1,11.76,100,1,15.28,100,1,11.4,100,1,15.3,100,1,11.29,100,1,15.91,100,1,11.14,700,1,16.11,700,1
2025-07-17T13:30:01.456476348Z,2025-07-17T13:30:01.456642950Z,160,2,1108,A,A,0,14.9,100,130,166602,29285996,ARL,43781545,12.67,100,1,14,100,1,12.47,100,1,14.2,100,1,12.36,100,1,14.34,100,1,12.33,102,2,14.44,100,1,12.23,100,1,14.65,2,1,11.93,100,1,14.74,100,1,11.76,100,1,14.9,100,1,11.4,100,1,15.28,100,1,11.29,100,1,15.3,100,1,11.14,700,1,15.91,100,1
2025-07-17T13:30:01.487884350Z,2025-07-17T13:30:01.488050182Z,160,2,1108,C,B,0,10.92,100,0,165832,29297612,ARL,43191333,12.67,100,1,14,100,1,12.47,100,1,14.2,100,1,12.36,100,1,14.34,100,1,12.33,102,2,14.44,100,1,12.23,100,1,14.65,2,1,11.93,100,1,14.74,100,1,11.76,100,1,14.9,100,1,11.4,100,1,15.28,100,1,11.29,100,1,15.3,100,1,11.14,700,1,15.91,100,1
2025-07-17T13:30:01.487884350Z,2025-07-17T13:30:01.488050182Z,160,2,1108,A,B,0,12.36,100,130,165832,29297612,ARL,43787977,12.67,100,1,14,100,1,12.47,100,1,14.2,100,1,12.36,200,2,14.34,100,1,12.33,102,2,14.44,100,1,12.23,100,1,14.65,2,1,11.93,100,1,14.74,100,1,11.76,100,1,14.9,100,1,11.4,100,1,15.28,100,1,11.29,100,1,15.3,100,1,11.14,700,1,15.91,100,1
2025-07-17T13:30:01.487905785Z,2025-07-17T13:30:01.488082852Z,160,2,1108,C,A,0,16.2,100,0,177067,29297619,ARL,43191369,12.67,100,1,14,100,1,12.47,100,1,14.2,100,1,12.36,200,2,14.34,100,1,12.33,102,2,14.44,100,1,12.23,100,1,14.65,2,1,11.93,100,1,14.74,100,1,11.76,100,1,14.9,100,1,11.4,100,1,15.28,100,1,11.29,100,1,15.3,100,1,11.14,700,1,15.91,100,1
2025-07-17T13:30:01.487905785Z,2025-07-17T13:30:01.488082852Z,160,2,1108,A,A,0,14.9,100,128,177067,29297619,ARL,43787985,12.67,100,1,14,100,1,12.47,100,1,14.2,100,1,12.36,200,2,14.34,100,1,12.33,102,2,14.44,100,1,12.23,100,1,14.65,2,1,11.93,100,1,14.74,100,1,11.76,100,1,14.9,200,2,11.4,100,1,15.28,100,1,11.29,100,1,15.3,100,1,11.14,700,1,15.91,100,1
2025-07-17T13:30:01.488809902Z,2025-07-17T13:30:01.488981292Z,160,2,1108,C,A,0,17.23,100,128,171390,29298089,ARL,43314561,12.67,100,1,14,100,1,12.47,100,1,14.2,100,1,12.36,200,2,14.34,100,1,12.33,102,2,14.44,100,1,12.23,100,1,14.65,2,1,11.93,100,1,14.74,100,1,11.76,100,1,14.9,200,2,11.4,100,1,15.28,100,1,11.29,100,1,15.3,100,1,11.14,700,1,15.91,100,1
2025-07-17T13:30:01.488866053Z,2025-07-17T13:30:01.489038112Z,160,2,1108,A,A,0,16.08,100,128,172059,29298118,ARL,43788313,12.67,100,1,14,100,1,12.47,100,1,14.2,100,1,12.36,200,2,14.34,100,1,12.33,102,2,14.44,100,1,12.23,100,1,14.65,2,1,11.93,100,1,14.74,100,1,11.76,100,1,14.9,200,2,11.4,100,1,15.28,100,1,11.29,100,1,15.3,100,1,11.14,700,1,15.91,100,1
2025-07-17T13:30:01.532274368Z,2025-07-17T13:30:01.532444998Z,160,2,1108,A,B,0,12.46,100,128,170630,29318499,ARL,43804025,12.67,100,1,14,100,1,12.47,100,1,14.2,100,1,12.46,100,1,14.34,100,1,12.36,200,2,14.44,100,1,12.33,102,2,14.65,2,1,12.23,100,1,14.74,100,1,11.93,100,1,14.9,200,2,11.76,100,1,15.28,100,1,11.4,100,1,15.3,100,1,11.29,100,1,15.91,100,1
2025-07-17T13:30:01.532293890Z,2025-07-17T13:30:01.532474492Z,160,2,1108,C,B,0,11.05,100,128,180602,29318513,ARL,42089321,12.67,100,1,14,100,1,12.47,100,1,14.2,100,1,12.46,100,1,14.34,100,1,12.36,200,2,14.44,100,1,12.33,102,2,14.65,2,1,12.23,100,1,14.74,100,1,11.93,100,1,14.9,200,2,11.76,100,1,15.28,100,1,11.4,100,1,15.3,100,1,11.29,100,1,15.91,100,1
2025-07-17T13:30:01.532324961Z,2025-07-17T13:30:01.532498294Z,160,2,1108,A,A,0,14.2,100,128,173333,29318528,ARL,43804081,12.67,100,1,14,100,1,12.47,100,1,14.2,200,2,12.46,100,1,14.34,100,1,12.36,200,2,14.44,100,1,12.33,102,2,14.65,2,1,12.23,100,1,14.74,100,1,11.93,100,1,14.9,200,2,11.76,100,1,15.28,100,1,11.4,100,1,15.3,100,1,11.29,100,1,15.91,100,1
2025-07-17T13:30:01.532347519Z,2025-07-17T13:30:01.532528215Z,160,2,1108,C,A,0,16.22,100,128,180696,29318534,ARL,42089325,12.67,100,1,14,100,1,12.47,100,1,14.2,200,2,12.46,100,1,14.34,100,1,12.36,200,2,14.44,100,1,12.33,102,2,14.65,2,1,12.23,100,1,14.74,100,1,11.93,100,1,14.9,200,2,11.76,100,1,15.28,100,1,11.4,100,1,15.3,100,1,11.29,100,1,15.91,100,1
2025-07-17T13:30:01.537195873Z,2025-07-17T13:30:01.537373659Z,160,2,1108,A,B,0,12.99,100,128,177786,29320724,ARL,43805737,12.99,100,1,14,100,1,12.67,100,1,14.2,200,2,12.47,100,1,14.34,100,1,12.46,100,1,14.44,100,1,12.36,200,2,14.65,2,1,12.33,102,2,14.74,100,1,12.23,100,1,14.9,200,2,11.93,100,1,15.28,100,1,11.76,100,1,15.3,100,1,11.4,100,1,15.91,100,1
2025-07-17T13:30:01.537219414Z,2025-07-17T13:30:01.537387032Z,160,2,1108,A,A,0,14.65,100,128,167618,29320743,ARL,43805773,12.99,100,1,14,100,1,12.67,100,1,14.2,200,2,12.47,100,1,14.34,100,1,12.46,100,1,14.44,100,1,12.36,200,2,14.65,102,2,12.33,102,2,14.74,100,1,12.23,100,1,14.9,200,2,11.93,100,1,15.28,100,1,11.76,100,1,15.3,100,1,11.4,100,1,15.91,100,1
2025-07-17T13:30:01.571375465Z,2025-07-17T13:30:01.571558801Z,160,2,1108,A,B,0,13.2,28,130,183336,29336931,ARL,43820541,13.2,28,1,14,100,1,12.99,100,1,14.2,200,2,12.67,100,1,14.34,100,1,12.47,100,1,14.44,100,1,12.46,100,1,14.65,102,2,12.36,200,2,14.74,100,1,12.33,102,2,14.9,200,2,12.23,100,1,15.28,100,1,11.93,100,1,15.3,100,1,11.76,100,1,15.91,100,1
2025-07-17T13:30:01.589592733Z,2025-07-17T13:30:01.589767581Z,160,2,1108,C,A,0,17.23,100,128,174848,29345825,ARL,43317185,13.2,28,1,14,100,1,12.99,100,1,14.2,200,2,12.67,100,1,14.34,100,1,12.47,100,1,14.44,100,1,12.46,100,1,14.65,102,2,12.36,200,2,14.74,100,1,12.33,102,2,14.9,200,2,12.23,100,1,15.28,100,1,11.93,100,1,15.3,100,1,11.76,100,1,15.91,100,1
2025-07-17T13:30:01.590381387Z,2025-07-17T13:30:01.590564534Z,160,2,1108,A,A,0,16.08,100,128,183147,29346224,ARL,43826261,13.2,28,1,14,100,1,12.99,100,1,14.2,200,2,12.67,100,1,14.34,100,1,12.47,100,1,14.44,100,1,12.46,100,1,14.65,102,2,12.36,200,2,14.74,100,1,12.33,102,2,14.9,200,2,12.23,100,1,15.28,100,1,11.93,100,1,15.3,100,1,11.76,100,1,15.91,100,1
2025-07-17T13:30:01.592507554Z,2025-07-17T13:30:01.592691520Z,160,2,1108,C,B,0,9.99,100,0,183966,29347436,ARL,41376769,13.2,28,1,14,100,1,12.99,100,1,14.2,200,2,12.67,100,1,14.34,100,1,12.47,100,1,14.44,100,1,12.46,100,1,14.65,102,2,12.36,200,2,14.74,100,1,12.33,102,2,14.9,200,2,12.23,100,1,15.28,100,1,11.93,100,1,15.3,100,1,11.76,100,1,15.91,100,1
2025-07-17T13:30:01.592507554Z,2025-07-17T13:30:01.592691520Z,160,2,1108,A,B,0,11.27,100,128,183966,29347436,ARL,43826785,13.2,28,1,14,100,1,12.99,100,1,14.2,200,2,12.67,100,1,14.34,100,1,12.47,100,1,14.44,100,1,12.46,100,1,14.65,102,2,12.36,200,2,14.74,100,1,12.33,102,2,14.9,200,2,12.23,100,1,15.28,100,1,11.93,100,1,15.3,100,1,11.76,100,1,15.91,100,1
2025-07-17T13:30:01.592539240Z,2025-07-17T13:30:01.592712062Z,160,2,1108,C,A,0,17.6,100,0,172822,29347463,ARL,41372493,13.2,28,1,14,100,1,12.99,100,1,14.2,200,2,12.67,100,1,14.34,100,1,12.47,100,1,14.44,100,1,12.46,100,1,14.65,102,2,12.36,200,2,14.74,100,1,12.33,102,2,14.9,200,2,12.23,100,1,15.28,100,1,11.93,100,1,15.3,100,1,11.76,100,1,15.91,100,1
2025-07-17T13:30:01.592539240Z,2025-07-17T13:30:01.592712062Z,160,2,1108,A,A,0,15.41,100,128,172822,29347463,ARL,43826805,13.2,28,1,14,100,1,12.99,100,1,14.2,200,2,12.67,100,1,14.34,100,1,12.47,100,1,14.44,100,1,12.46,100,1,14.65,102,2,12.36,200,2,14.74,100,1,12.33,102,2,14.9,200,2,12.23,100,1,15.28,100,1,11.93,100,1,15.3,100,1,11.76,100,1,15.41,100,1
2025-07-17T13:30:01.661958252Z,2025-07-17T13:30:01.662123703Z,160,2,1108,C,B,0,10.58,100,0,165451,29378719,ARL,41377117,13.2,28,1,14,100,1,12.99,100,1,14.2,200,2,12.67,100,1,14.34,100,1,12.47,100,1,14.44,100,1,12.46,100,1,14.65,102,2,12.36,200,2,14.74,100,1,12.33,102,2,14.9,200,2,12.23,100,1,15.28,100,1,11.93,100,1,15.3,100,1,11.76,100,1,15.41,100,1
2025-07-17T13:30:01.661958252Z,2025-07-17T13:30:01.662123703Z,160,2,1108,A,B,0,11.93,100,130,165451,29378719,ARL,43852121,13.2,28,1,14,100,1,12.99,100,1,14.2,200,2,12.67,100,1,14.34,100,1,12.47,100,1,14.44,100,1,12.46,100,1,14.65,102,2,12.36,200,2,14.74,100,1,12.33,102,2,14.9,200,2,12.23,100,1,15.28,100,1,11.93,200,2,15.3,100,1,11.76,100,1,15.41,100,1
2025-07-17T13:30:01.661989524Z,2025-07-17T13:30:01.662159610Z,160,2,1108,C,A,0,16.83,100,0,170086,29378727,ARL,41372469,13.2,28,1,14,100,1,12.99,100,1,14.2,200,2,12.67,100,1,14.34,100,1,12.47,100,1,14.44,100,1,12.46,100,1,14.65,102,2,12.36,200,2,14.74,100,1,12.33,102,2,14.9,200,2,12.23,100,1,15.28,100,1,11.93,200,2,15.3,100,1,11.76,100,1,15.41,100,1
2025-07-17T13:30:01.661989524Z,2025-07-17T13:30:01.662159610Z,160,2,1108,A,A,0,14.74,100,128,170086,29378727,ARL,43852129,13.2,28,1,14,100,1,12.99,100,1,14.2,200,2,12.67,100,1,14.34,100,1,12.47,100,1,14.44,100,1,12.46,100,1,14.65,102,2,12.36,200,2,14.74,200,2,12.33,102,2,14.9,200,2,12.23,100,1,15.28,100,1,11.93,200,2,15.3,100,1,11.76,100,1,15.41,100,1
2025-07-17T13:30:01.929395142Z,2025-07-17T13:30:01.929560509Z,160,2,1108,C,A,0,14.65,100,130,165367,29480243,ARL,43805773,13.2,28,1,14,100,1,12.99,100,1,14.2,200,2,12.67,100,1,14.34,100,1,12.47,100,1,14.44,100,1,12.46,100,1,14.65,2,1,12.36,200,2,14.74,200,2,12.33,102,2,14.9,200,2,12.23,100,1,15.28,100,1,11.93,200,2,15.3,100,1,11.76,100,1,15.41,100,1
2025-07-17T13:30:01.930800767Z,2025-07-17T13:30:01.930966377Z,160,2,1108,A,A,0,13.67,100,130,165610,29480698,ARL,43953649,13.2,28,1,13.67,100,1,12.99,100,1,14,100,1,12.67,100,1,14.2,200,2,12.47,100,1,14.34,100,1,12.46,100,1,14.44,100,1,12.36,200,2,14.65,2,1,12.33,102,2,14.74,200,2,12.23,100,1,14.9,200,2,11.93,200,2,15.28,100,1,11.76,100,1,15.3,100,1
2025-07-17T13:30:02.208989359Z,2025-07-17T13:30:02.209154979Z,160,2,1108,A,A,0,17.15,100,130,165620,29556866,ARL,44040361,13.2,28,1,13.67,100,1,12.99,100,1,14,100,1,12.67,100,1,14.2,200,2,12.47,100,1,14.34,100,1,12.46,100,1,14.44,100,1,12.36,200,2,14.65,2,1,12.33,102,2,14.74,200,2,12.23,100,1,14.9,200,2,11.93,200,2,15.28,100,1,11.76,100,1,15.3,100,1
2025-07-17T13:30:02.209004229Z,2025-07-17T13:30:02.209170665Z,160,2,1108,A,B,0,9.55,100,128,166436,29556867,ARL,44040369,13.2,28,1,13.67,100,1,12.99,100,1,14,100,1,12.67,100,1,14.2,200,2,12.47,100,1,14.34,100,1,12.46,100,1,14.44,100,1,12.36,200,2,14.65,2,1,12.33,102,2,14.74,200,2,12.23,100,1,14.9,200,2,11.93,200,2,15.28,100,1,11.76,100,1,15.3,100,1
2025-07-17T13:30:02.378274380Z,2025-07-17T13:30:02.378440054Z,160,2,1108,A,B,0,12.73,100,130,165674,29585499,ARL,44066409,13.2,28,1,13.67,100,1,12.99,100,1,14,100,1,12.73,100,1,14.2,200,2,12.67,100,1,14.34,100,1,12.47,100,1,14.44,100,1,12.46,100,1,14.65,2,1,12.36,200,2,14.74,200,2,12.33,102,2,14.9,200,2,12.23,100,1,15.28,100,1,11.93,200,2,15.3,100,1
2025-07-17T13:30:02.378280610Z,2025-07-17T13:30:02.378446229Z,160,2,1108,A,A,0,13.93,100,130,165619,29585501,ARL,44066417,13.2,28,1,13.67,100,1,12.99,100,1,13.93,100,1,12.73,100,1,14,100,1,12.67,100,1,14.2,200,2,12.47,100,1,14.34,100,1,12.46,100,1,14.44,100,1,12.36,200,2,14.65,2,1,12.33,102,2,14.74,200,2,12.23,100,1,14.9,200,2,11.93,200,2,15.28,100,1
2025-07-17T13:30:02.378286605Z,2025-07-17T13:30:02.378454598Z,160,2,1108,C,B,0,11.29,100,128,167993,29585502,ARL,42099317,13.2,28,1,13.67,100,1,12.99,100,1,13.93,100,1,12.73,100,1,14,100,1,12.67,100,1,14.2,200,2,12.47,100,1,14.34,100,1,12.46,100,1,14.44,100,1,12.36,200,2,14.65,2,1,12.33,102,2,14.74,200,2,12.23,100,1,14.9,200,2,11.93,200,2,15.28,100,1
2025-07-17T13:30:02.378293244Z,2025-07-17T13:30:02.378458883Z,160,2,1108,C,A,0,15.91,100,130,165639,29585504,ARL,42099321,13.2,28,1,13.67,100,1,12.99,100,1,13.93,100,1,12.73,100,1,14,100,1,12.67,100,1,14.2,200,2,12.47,100,1,14.34,100,1,12.46,100,1,14.44,100,1,12.36,200,2,14.65,2,1,12.33,102,2,14.74,200,2,12.23,100,1,14.9,200,2,11.93,200,2,15.28,100,1
2025-07-17T13:30:02.476818222Z,2025-07-17T13:30:02.476983806Z,160,2,1108,C,A,0,14.9,100,0,165584,29601178,ARL,43781545,13.2,28,1,13.67,100,1,12.99,100,1,13.93,100,1,12.73,100,1,14,100,1,12.67,100,1,14.2,200,2,12.47,100,1,14.34,100,1,12.46,100,1,14.44,100,1,12.36,200,2,14.65,2,1,12.33,102,2,14.74,200,2,12.23,100,1,14.9,100,1,11.93,200,2,15.28,100,1
2025-07-17T13:30:02.476818222Z,2025-07-17T13:30:02.476983806Z,160,2,1108,A,A,0,14.57,100,130,165584,29601178,ARL,44076709,13.2,28,1,13.67,100,1,12.99,100,1,13.93,100,1,12.73,100,1,14,100,1,12.67,100,1,14.2,200,2,12.47,100,1,14.34,100,1,12.46,100,1,14.44,100,1,12.36,200,2,14.57,100,1,12.33,102,2,14.65,2,1,12.23,100,1,14.74,200,2,11.93,200,2,14.9,100,1
2025-07-17T13:30:02.483131658Z,2025-07-17T13:30:02.483297761Z,160,2,1108,C,A,0,14.9,100,0,166103,29601999,ARL,43787985,13.2,28,1,13.67,100,1,12.99,100,1,13.93,100,1,12.73,100,1,14,100,1,12.67,100,1,14.2,200,2,12.47,100,1,14.34,100,1,12.46,100,1,14.44,100,1,12.36,200,2,14.57,100,1,12.33,102,2,14.65,2,1,12.23,100,1,14.74,200,2,11.93,200,2,15.28,100,1
2025-07-17T13:30:02.483131658Z,2025-07-17T13:30:02.483297761Z,160,2,1108,A,A,0,14.57,100,130,166103,29601999,ARL,44077497,13.2,28,1,13.67,100,1,12.99,100,1,13.93,100,1,12.73,100,1,14,100,1,12.67,100,1,14.2,200,2,12.47,100,1,14.34,100,1,12.46,100,1,14.44,100,1,12.36,200,2,14.57,200,2,12.33,102,2,14.65,2,1,12.23,100,1,14.74,200,2,11.93,200,2,15.28,100,1
2025-07-17T13:30:02.524755932Z,2025-07-17T13:30:02.524921786Z,160,2,1108,C,B,0,8.58,100,0,165854,29608933,ARL,41376733,13.2,28,1,13.67,100,1,12.99,100,1,13.93,100,1,12.73,100,1,14,100,1,12.67,100,1,14.2,200,2,12.47,100,1,14.34,100,1,12.46,100,1,14.44,100,1,12.36,200,2,14.57,200,2,12.33,102,2,14.65,2,1,12.23,100,1,14.74,200,2,11.93,200,2,15.28,100,1
2025-07-17T13:30:02.524755932Z,2025-07-17T13:30:02.524921786Z,160,2,1108,A,B,0,9.67,100,130,165854,29608933,ARL,44082961,13.2,28,1,13.67,100,1,12.99,100,1,13.93,100,1,12.73,100,1,14,100,1,12.67,100,1,14.2,200,2,12.47,100,1,14.34,100,1,12.46,100,1,14.44,100,1,12.36,200,2,14.57,200,2,12.33,102,2,14.65,2,1,12.23,100,1,14.74,200,2,11.93,200,2,15.28,100,1
2025-07-17T13:30:02.524769583Z,2025-07-17T13:30:02.524935181Z,160,2,1108,C,A,0,19.44,100,0,165598,29608936,ARL,41372549,13.2,28,1,13.67,100,1,12.99,100,1,13.93,100,1,12.73,100,1,14,100,1,12.67,100,1,14.2,200,2,12.47,100,1,14.34,100,1,12.46,100,1,14.44,100,1,12.36,200,2,14.57,200,2,12.33,102,2,14.65,2,1,12.23,100,1,14.74,200,2,11.93,200,2,15.28,100,1
2025-07-17T13:30:02.524769583Z,2025-07-17T13:30:02.524935181Z,160,2,1108,A,A,0,17.02,100,130,165598,29608936,ARL,44082969,13.2,28,1,13.67,100,1,12.99,100,1,13.93,100,1,12.73,100,1,14,100,1,12.67,100,1,14.2,200,2,12.47,100,1,14.34,100,1,12.46,100,1,14.44,100,1,12.36,200,2,14.57,200,2,12.33,102,2,14.65,2,1,12.23,100,1,14.74,200,2,11.93,200,2,15.28,100,1
2025-07-17T13:30:02.573606685Z,2025-07-17T13:30:02.573774313Z,160,2,1108,C,B,0,10.93,100,0,167628,29618524,ARL,41379985,13.2,28,1,13.67,100,1,12.99,100,1,13.93,100,1,12.73,100,1,14,100,1,12.67,100,1,14.2,200,2,12.47,100,1,14.34,100,1,12.46,100,1,14.44,100,1,12.36,200,2,14.57,200,2,12.33,102,2,14.65,2,1,12.23,100,1,14.74,200,2,11.93,200,2,15.28,100,1
2025-07-17T13:30:02.573606685Z,2025-07-17T13:30:02.573774313Z,160,2,1108,A,B,0,12.33,100,128,167628,29618524,ARL,44088633,13.2,28,1,13.67,100,1,12.99,100,1,13.93,100,1,12.73,100,1,14,100,1,12.67,100,1,14.2,200,2,12.47,100,1,14.34,100,1,12.46,100,1,14.44,100,1,12.36,200,2,14.57,200,2,12.33,202,3,14.65,2,1,12.23,100,1,14.74,200,2,11.93,200,2,15.28,100,1
2025-07-17T13:30:02.573623478Z,2025-07-17T13:30:02.573792046Z,160,2,1108,C,A,0,16.38,100,0,168568,29618531,ARL,41372369,13.2,28,1,13.67,100,1,12.99,100,1,13.93,100,1,12.73,100,1,14,100,1,12.67,100,1,14.2,200,2,12.47,100,1,14.34,100,1,12.46,100,1,14.44,100,1,12.36,200,2,14.57,200,2,12.33,202,3,14.65,2,1,12.23,100,1,14.74,200,2,11.93,200,2,15.28,100,1
2025-07-17T13:30:02.573623478Z,2025-07-17T13:30:02.573792046Z,160,2,1108,A,A,0,14.34,100,128,168568,29618531,ARL,44088637,13.2,28,1,13.67,100,1,12.99,100,1,13.93,100,1,12.73,100,1,14,100,1,12.67,100,1,14.2,200,2,12.47,100,1,14.34,200,2,12.46,100,1,14.44,100,1,12.36,200,2,14.57,200,2,12.33,202,3,14.65,2,1,12.23,100,1,14.74,200,2,11.93,200,2,15.28,100,1
2025-07-17T13:30:06.757383618Z,2025-07-17T13:30:06.757549069Z,160,2,1108,A,A,0,14.27,700,130,165451,30107583,ARL,44491681,13.2,28,1,13.67,100,1,12.99,100,1,13.93,100,1,12.73,100,1,14,100,1,12.67,100,1,14.2,200,2,12.47,100,1,14.27,700,1,12.46,100,1,14.34,200,2,12.36,200,2,14.44,100,1,12.33,202,3,14.57,200,2,12.23,100,1,14.65,2,1,11.93,200,2,14.74,200,2
2025-07-17T13:30:06.757435491Z,2025-07-17T13:30:06.757600916Z,160,2,1108,C,A,0,16.15,700,130,165425,30107590,ARL,41528029,13.2,28,1,13.67,100,1,12.99,100,1,13.93,100,1,12.73,100,1,14,100,1,12.67,100,1,14.2,200,2,12.47,100,1,14.27,700,1,12.46,100,1,14.34,200,2,12.36,200,2,14.44,100,1,12.33,202,3,14.57,200,2,12.23,100,1,14.65,2,1,11.93,200,2,14.74,200,2
2025-07-17T13:30:07.194841610Z,2025-07-17T13:30:07.195006880Z,160,2,1108,A,A,0,15.3,700,130,165270,30150210,ARL,44520965,13.2,28,1,13.67,100,1,12.99,100,1,13.93,100,1,12.73,100,1,14,100,1,12.67,100,1,14.2,200,2,12.47,100,1,14.27,700,1,12.46,100,1,14.34,200,2,12.36,200,2,14.44,100,1,12.33,202,3,14.57,200,2,12.23,100,1,14.65,2,1,11.93,200,2,14.74,200,2
2025-07-17T13:30:07.194880522Z,2025-07-17T13:30:07.195046929Z,160,2,1108,C,A,0,16.3,700,128,166407,30150214,ARL,41375973,13.2,28,1,13.67,100,1,12.99,100,1,13.93,100,1,12.73,100,1,14,100,1,12.67,100,1,14.2,200,2,12.47,100,1,14.27,700,1,12.46,100,1,14.34,200,2,12.36,200,2,14.44,100,1,12.33,202,3,14.57,200,2,12.23,100,1,14.65,2,1,11.93,200,2,14.74,200,2
2025-07-17T13:30:07.394882479Z,2025-07-17T13:30:07.395047633Z,160,2,1108,A,A,0,15,700,130,165154,30169157,ARL,44533061,13.2,28,1,13.67,100,1,12.99,100,1,13.93,100,1,12.73,100,1,14,100,1,12.67,100,1,14.2,200,2,12.47,100,1,14.27,700,1,12.46,100,1,14.34,200,2,12.36,200,2,14.44,100,1,12.33,202,3,14.57,200,2,12.23,100,1,14.65,2,1,11.93,200,2,14.74,200,2
2025-07-17T13:30:07.395357697Z,2025-07-17T13:30:07.395522844Z,160,2,1108,C,A,0,15.3,700,130,165147,30169278,ARL,44520965,13.2,28,1,13.67,100,1,12.99,100,1,13.93,100,1,12.73,100,1,14,100,1,12.67,100,1,14.2,200,2,12.47,100,1,14.27,700,1,12.46,100,1,14.34,200,2,12.36,200,2,14.44,100,1,12.33,202,3,14.57,200,2,12.23,100,1,14.65,2,1,11.93,200,2,14.74,200,2
2025-07-17T13:30:07.594772046Z,2025-07-17T13:30:07.594948559Z,160,2,1108,A,A,0,14.7,700,128,176513,30189080,ARL,44545381,13.2,28,1,13.67,100,1,12.99,100,1,13.93,100,1,12.73,100,1,14,100,1,12.67,100,1,14.2,200,2,12.47,100,1,14.27,700,1,12.46,100,1,14.34,200,2,12.36,200,2,14.44,100,1,12.33,202,3,14.57,200,2,12.23,100,1,14.65,2,1,11.93,200,2,14.7,700,1
2025-07-17T13:30:07.594797098Z,2025-07-17T13:30:07.594962236Z,160,2,1108,C,A,0,15,700,130,165138,30189120,ARL,44533061,13.2,28,1,13.67,100,1,12.99,100,1,13.93,100,1,12.73,100,1,14,100,1,12.67,100,1,14.2,200,2,12.47,100,1,14.27,700,1,12.46,100,1,14.34,200,2,12.36,200,2,14.44,100,1,12.33,202,3,14.57,200,2,12.23,100,1,14.65,2,1,11.93,200,2,14.7,700,1
2025-07-17T13:30:07.663083798Z,2025-07-17T13:30:07.663249150Z,160,2,1108,A,A,0,14.46,700,130,165352,30194197,ARL,44548325,13.2,28,1,13.67,100,1,12.99,100,1,13.93,100,1,12.73,100,1,14,100,1,12.67,100,1,14.2,200,2,12.47,100,1,14.27,700,1,12.46,100,1,14.34,200,2,12.36,200,2,14.44,100,1,12.33,202,3,14.46,700,1,12.23,100,1,14.57,200,2,11.93,200,2,14.65,2,1
2025-07-17T13:30:07.663798482Z,2025-07-17T13:30:07.663963574Z,160,2,1108,C,A,0,14.7,700,130,165092,30194234,ARL,44545381,13.2,28,1,13.67,100,1,12.99,100,1,13.93,100,1,12.73,100,1,14,100,1,12.67,100,1,14.2,200,2,12.47,100,1,14.27,700,1,12.46,100,1,14.34,200,2,12.36,200,2,14.44,100,1,12.33,202,3,14.46,700,1,12.23,100,1,14.57,200,2,11.93,200,2,14.65,2,1
2025-07-17T13:30:07.914271879Z,2025-07-17T13:30:07.914437226Z,160,2,1108,A,B,0,11.76,700,130,165347,30213834,ARL,44560257,13.2,28,1,13.67,100,1,12.99,100,1,13.93,100,1,12.73,100,1,14,100,1,12.67,100,1,14.2,200,2,12.47,100,1,14.27,700,1,12.46,100,1,14.34,200,2,12.36,200,2,14.44,100,1,12.33,202,3,14.46,700,1,12.23,100,1,14.57,200,2,11.93,200,2,14.65,2,1
2025-07-17T13:30:07.914949951Z,2025-07-17T13:30:07.915115414Z,160,2,1108,C,B,0,10.99,700,130,165463,30213941,ARL,41509393,13.2,28,1,13.67,100,1,12.99,100,1,13.93,100,1,12.73,100,1,14,100,1,12.67,100,1,14.2,200,2,12.47,100,1,14.27,700,1,12.46,100,1,14.34,200,2,12.36,200,2,14.44,100,1,12.33,202,3,14.46,700,1,12.23,100,1,14.57,200,2,11.93,200,2,14.65,2,1
2025-07-17T13:30:08.025660842Z,2025-07-17T13:30:08.025826192Z,160,2,1108,A,B,0,12.02,700,130,165350,30224657,ARL,44565617,13.2,28,1,13.67,100,1,12.99,100,1,13.93,100,1,12.73,100,1,14,100,1,12.67,100,1,14.2,200,2,12.47,100,1,14.27,700,1,12.46,100,1,14.34,200,2,12.36,200,2,14.44,100,1,12.33,202,3,14.46,700,1,12.23,100,1,14.57,200,2,12.02,700,1,14.65,2,1
2025-07-17T13:30:08.025673570Z,2025-07-17T13:30:08.025838588Z,160,2,1108,C,B,0,11.76,700,130,165018,30224658,ARL,44560257,13.2,28,1,13.67,100,1,12.99,100,1,13.93,100,1,12.73,100,1,14,100,1,12.67,100,1,14.2,200,2,12.47,100,1,14.27,700,1,12.46,100,1,14.34,200,2,12.36,200,2,14.44,100,1,12.33,202,3,14.46,700,1,12.23,100,1,14.57,200,2,12.02,700,1,14.65,2,1
2025-07-17T13:30:08.114272470Z,2025-07-17T13:30:08.114437837Z,160,2,1108,A,B,0,12.26,700,130,165367,30233944,ARL,44570585,13.2,28,1,13.67,100,1,12.99,100,1,13.93,100,1,12.73,100,1,14,100,1,12.67,100,1,14.2,200,2,12.47,100,1,14.27,700,1,12.46,100,1,14.34,200,2,12.36,200,2,14.44,100,1,12.33,202,3,14.46,700,1,12.26,700,1,14.57,200,2,12.23,100,1,14.65,2,1
2025-07-17T13:30:08.115068904Z,2025-07-17T13:30:08.115234484Z,160,2,1108,C,B,0,12.02,700,130,165580,30234078,ARL,44565617,13.2,28,1,13.67,100,1,12.99,100,1,13.93,100,1,12.73,100,1,14,100,1,12.67,100,1,14.2,200,2,12.47,100,1,14.27,700,1,12.46,100,1,14.34,200,2,12.36,200,2,14.44,100,1,12.33,202,3,14.46,700,1,12.26,700,1,14.57,200,2,12.23,100,1,14.65,2,1
2025-07-17T13:30:08.394373251Z,2025-07-17T13:30:08.394538665Z,160,2,1108,A,B,0,13.25,11,130,165414,30258008,ARL,44586753,13.25,11,1,13.67,100,1,13.2,28,1,13.93,100,1,12.99,100,1,14,100,1,12.73,100,1,14.2,200,2,12.67,100,1,14.27,700,1,12.47,100,1,14.34,200,2,12.46,100,1,14.44,100,1,12.36,200,2,14.46,700,1,12.33,202,3,14.57,200,2,12.26,700,1,14.65,2,1
2025-07-17T13:30:08.402012613Z,2025-07-17T13:30:08.402177882Z,160,2,1108,C,B,0,13.2,28,130,165269,30259240,ARL,43820541,13.25,11,1,13.67,100,1,12.99,100,1,13.93,100,1,12.73,100,1,14,100,1,12.67,100,1,14.2,200,2,12.47,100,1,14.27,700,1,12.46,100,1,14.34,200,2,12.36,200,2,14.44,100,1,12.33,202,3,14.46,700,1,12.26,700,1,14.57,200,2,12.23,100,1,14.65,2,1
2025-07-17T13:30:08.512579639Z,2025-07-17T13:30:08.512744920Z,160,2,1108,A,A,0,14.26,700,130,165281,30276907,ARL,44598153,13.25,11,1,13.67,100,1,12.99,100,1,13.93,100,1,12.73,100,1,14,100,1,12.67,100,1,14.2,200,2,12.47,100,1,14.26,700,1,12.46,100,1,14.27,700,1,12.36,200,2,14.34,200,2,12.33,202,3,14.44,100,1,12.26,700,1,14.46,700,1,12.23,100,1,14.57,200,2
2025-07-17T13:30:08.512974877Z,2025-07-17T13:30:08.513140882Z,160,2,1108,C,A,0,16.11,700,130,166005,30276990,ARL,41371225,13.25,11,1,13.67,100,1,12.99,100,1,13.93,100,1,12.73,100,1,14,100,1,12.67,100,1,14.2,200,2,12.47,100,1,14.26,700,1,12.46,100,1,14.27,700,1,12.36,200,2,14.34,200,2,12.33,202,3,14.44,100,1,12.26,700,1,14.46,700,1,12.23,100,1,14.57,200,2
2025-07-17T13:30:09.128991840Z,2025-07-17T13:30:09.129158268Z,160,2,1108,A,B,0,11.76,700,128,166428,30336805,ARL,44628617,13.25,11,1,13.67,100,1,12.99,100,1,13.93,100,1,12.73,100,1,14,100,1,12.67,100,1,14.2,200,2,12.47,100,1,14.26,700,1,12.46,100,1,14.27,700,1,12.36,200,2,14.34,200,2,12.33,202,3,14.44,100,1,12.26,700,1,14.46,700,1,12.23,100,1,14.57,200,2
2025-07-17T13:30:09.129006013Z,2025-07-17T13:30:09.129171567Z,160,2,1108,C,B,0,11.07,700,130,165554,30336807,ARL,41539477,13.25,11,1,13.67,100,1,12.99,100,1,13.93,100,1,12.73,100,1,14,100,1,12.67,100,1,14.2,200,2,12.47,100,1,14.26,700,1,12.46,100,1,14.27,700,1,12.36,200,2,14.34,200,2,12.33,202,3,14.44,100,1,12.26,700,1,14.46,700,1,12.23,100,1,14.57,200,2
2025-07-17T13:30:09.329050977Z,2025-07-17T13:30:09.329216559Z,160,2,1108,A,B,0,12.02,700,130,165582,30353905,ARL,44641397,13.25,11,1,13.67,100,1,12.99,100,1,13.93,100,1,12.73,100,1,14,100,1,12.67,100,1,14.2,200,2,12.47,100,1,14.26,700,1,12.46,100,1,14.27,700,1,12.36,200,2,14.34,200,2,12.33,202,3,14.44,100,1,12.26,700,1,14.46,700,1,12.23,100,1,14.57,200,2
2025-07-17T13:30:09.329118219Z,2025-07-17T13:30:09.329283504Z,160,2,1108,C,B,0,11.76,700,130,165285,30353910,ARL,44628617,13.25,11,1,13.67,100,1,12.99,100,1,13.93,100,1,12.73,100,1,14,100,1,12.67,100,1,14.2,200,2,12.47,100,1,14.26,700,1,12.46,100,1,14.27,700,1,12.36,200,2,14.34,200,2,12.33,202,3,14.44,100,1,12.26,700,1,14.46,700,1,12.23,100,1,14.57,200,2
2025-07-17T13:30:10.081175039Z,2025-07-17T13:30:10.081340519Z,160,2,1108,A,A,0,13.4,10,130,165480,30441651,ARL,44719917,13.25,11,1,13.4,10,1,12.99,100,1,13.67,100,1,12.73,100,1,13.93,100,1,12.67,100,1,14,100,1,12.47,100,1,14.2,200,2,12.46,100,1,14.26,700,1,12.36,200,2,14.27,700,1,12.33,202,3,14.34,200,2,12.26,700,1,14.44,100,1,12.23,100,1,14.46,700,1
2025-07-17T13:30:10.082150107Z,2025-07-17T13:30:10.082315658Z,160,2,1108,C,A,0,14.57,100,0,165551,30441855,ARL,44076709,13.25,11,1,13.4,10,1,12.99,100,1,13.67,100,1,12.73,100,1,13.93,100,1,12.67,100,1,14,100,1,12.47,100,1,14.2,200,2,12.46,100,1,14.26,700,1,12.36,200,2,14.27,700,1,12.33,202,3,14.34,200,2,12.26,700,1,14.44,100,1,12.23,100,1,14.46,700,1
2025-07-17T13:30:10.082150107Z,2025-07-17T13:30:10.082315658Z,160,2,1108,A,A,0,14.29,100,130,165551,30441855,ARL,44719985,13.25,11,1,13.4,10,1,12.99,100,1,13.67,100,1,12.73,100,1,13.93,100,1,12.67,100,1,14,100,1,12.47,100,1,14.2,200,2,12.46,100,1,14.26,700,1,12.36,200,2,14.27,700,1,12.33,202,3,14.29,100,1,12.26,700,1,14.34,200,2,12.23,100,1,14.44,100,1
2025-07-17T13:30:10.082662762Z,2025-07-17T13:30:10.082828352Z,160,2,1108,C,A,0,14.57,100,0,165590,30441930,ARL,44077497,13.25,11,1,13.4,10,1,12.99,100,1,13.67,100,1,12.73,100,1,13.93,100,1,12.67,100,1,14,100,1,12.47,100,1,14.2,200,2,12.46,100,1,14.26,700,1,12.36,200,2,14.27,700,1,12.33,202,3,14.29,100,1,12.26,700,1,14.34,200,2,12.23,100,1,14.44,100,1
2025-07-17T13:30:10.082662762Z,2025-07-17T13:30:10.082828352Z,160,2,1108,A,A,0,14.29,100,130,165590,30441930,ARL,44720033,13.25,11,1,13.4,10,1,12.99,100,1,13.67,100,1,12.73,100,1,13.93,100,1,12.67,100,1,14,100,1,12.47,100,1,14.2,200,2,12.46,100,1,14.26,700,1,12.36,200,2,14.27,700,1,12.33,202,3,14.29,200,2,12.26,700,1,14.34,200,2,12.23,100,1,14.44,100,1
2025-07-17T13:30:10.084896414Z,2025-07-17T13:30:10.085062201Z,160,2,1108,A,B,0,12.42,700,130,165787,30442720,ARL,44720357,13.25,11,1,13.4,10,1,12.99,100,1,13.67,100,1,12.73,100,1,13.93,100,1,12.67,100,1,14,100,1,12.47,100,1,14.2,200,2,12.46,100,1,14.26,700,1,12.42,700,1,14.27,700,1,12.36,200,2,14.29,200,2,12.33,202,3,14.34,200,2,12.26,700,1,14.44,100,1
2025-07-17T13:30:10.085332605Z,2025-07-17T13:30:10.085497770Z,160,2,1108,C,B,0,11.14,700,130,165165,30442750,ARL,41534785,13.25,11,1,13.4,10,1,12.99,100,1,13.67,100,1,12.73,100,1,13.93,100,1,12.67,100,1,14,100,1,12.47,100,1,14.2,200,2,12.46,100,1,14.26,700,1,12.42,700,1,14.27,700,1,12.36,200,2,14.29,200,2,12.33,202,3,14.34,200,2,12.26,700,1,14.44,100,1
2025-07-17T13:30:12.194582572Z,2025-07-17T13:30:12.194748173Z,160,2,1108,C,A,0,14.65,2,0,165601,30681385,ARL,43692157,13.25,11,1,13.4,10,1,12.99,100,1,13.67,100,1,12.73,100,1,13.93,100,1,12.67,100,1,14,100,1,12.47,100,1,14.2,200,2,12.46,100,1,14.26,700,1,12.42,700,1,14.27,700,1,12.36,200,2,14.29,200,2,12.33,202,3,14.34,200,2,12.26,700,1,14.44,100,1
2025-07-17T13:30:12.194582572Z,2025-07-17T13:30:12.194748173Z,160,2,1108,A,A,0,14.43,2,130,165601,30681385,ARL,44904733,13.25,11,1,13.4,10,1,12.99,100,1,13.67,100,1,12.73,100,1,13.93,100,1,12.67,100,1,14,100,1,12.47,100,1,14.2,200,2,12.46,100,1,14.26,700,1,12.42,700,1,14.27,700,1,12.36,200,2,14.29,200,2,12.33,202,3,14.34,200,2,12.26,700,1,14.43,2,1
2025-07-17T13:30:14.128932140Z,2025-07-17T13:30:14.129097570Z,160,2,1108,A,B,0,12.37,700,130,165430,30851531,ARL,45025165,13.25,11,1,13.4,10,1,12.99,100,1,13.67,100,1,12.73,100,1,13.93,100,1,12.67,100,1,14,100,1,12.47,100,1,14.2,200,2,12.46,100,1,14.26,700,1,12.42,700,1,14.27,700,1,12.37,700,1,14.29,200,2,12.36,200,2,14.34,200,2,12.33,202,3,14.43,2,1
2025-07-17T13:30:14.129008546Z,2025-07-17T13:30:14.129174026Z,160,2,1108,C,B,0,12.02,700,130,165480,30851532,ARL,44641397,13.25,11,1,13.4,10,1,12.99,100,1,13.67,100,1,12.73,100,1,13.93,100,1,12.67,100,1,14,100,1,12.47,100,1,14.2,200,2,12.46,100,1,14.26,700,1,12.42,700,1,14.27,700,1,12.37,700,1,14.29,200,2,12.36,200,2,14.34,200,2,12.33,202,3,14.43,2,1
2025-07-17T13:30:23.695564208Z,2025-07-17T13:30:23.695729484Z,160,2,1108,A,A,0,13.4,12,130,165276,31649134,ARL,45593201,13.25,11,1,13.4,22,2,12.99,100,1,13.67,100,1,12.73,100,1,13.93,100,1,12.67,100,1,14,100,1,12.47,100,1,14.2,200,2,12.46,100,1,14.26,700,1,12.42,700,1,14.27,700,1,12.37,700,1,14.29,200,2,12.36,200,2,14.34,200,2,12.33,202,3,14.43,2,1
2025-07-17T13:30:25.512069243Z,2025-07-17T13:30:25.512235443Z,160,2,1108,C,A,0,13.4,10,128,166200,31806233,ARL,44719917,13.25,11,1,13.4,12,1,12.99,100,1,13.67,100,1,12.73,100,1,13.93,100,1,12.67,100,1,14,100,1,12.47,100,1,14.2,200,2,12.46,100,1,14.26,700,1,12.42,700,1,14.27,700,1,12.37,700,1,14.29,200,2,12.36,200,2,14.34,200,2,12.33,202,3,14.43,2,1
2025-07-17T13:30:26.553160650Z,2025-07-17T13:30:26.553325979Z,160,2,1108,A,A,0,13.4,10,130,165329,31897785,ARL,45748261,13.25,11,1,13.4,22,2,12.99,100,1,13.67,100,1,12.73,100,1,13.93,100,1,12.67,100,1,14,100,1,12.47,100,1,14.2,200,2,12.46,100,1,14.26,700,1,12.42,700,1,14.27,700,1,12.37,700,1,14.29,200,2,12.36,200,2,14.34,200,2,12.33,202,3,14.43,2,1
2025-07-17T13:30:35.240400172Z,2025-07-17T13:30:35.240569990Z,160,2,1108,C,A,0,13.4,10,130,169818,32725426,ARL,45748261,13.25,11,1,13.4,12,1,12.99,100,1,13.67,100,1,12.73,100,1,13.93,100,1,12.67,100,1,14,100,1,12.47,100,1,14.2,200,2,12.46,100,1,14.26,700,1,12.42,700,1,14.27,700,1,12.37,700,1,14.29,200,2,12.36,200,2,14.34,200,2,12.33,202,3,14.43,2,1
2025-07-17T13:30:43.952999157Z,2025-07-17T13:30:43.953164386Z,160,2,1108,C,A,0,13.4,12,130,165229,33659635,ARL,45593201,13.25,11,1,13.67,100,1,12.99,100,1,13.93,100,1,12.73,100,1,14,100,1,12.67,100,1,14.2,200,2,12.47,100,1,14.26,700,1,12.46,100,1,14.27,700,1,12.42,700,1,14.29,200,2,12.37,700,1,14.34,200,2,12.36,200,2,14.43,2,1,12.33,202,3,14.44,100,1
2025-07-17T13:30:43.953363128Z,2025-07-17T13:30:43.953528491Z,160,2,1108,A,A,0,13.4,24,130,165363,33659657,ARL,46613073,13.25,11,1,13.4,24,1,12.99,100,1,13.67,100,1,12.73,100,1,13.93,100,1,12.67,100,1,14,100,1,12.47,100,1,14.2,200,2,12.46,100,1,14.26,700,1,12.42,700,1,14.27,700,1,12.37,700,1,14.29,200,2,12.36,200,2,14.34,200,2,12.33,202,3,14.43,2,1
2025-07-17T13:30:47.814108950Z,2025-07-17T13:30:47.814275253Z,160,2,1108,A,A,0,13.4,10,130,166303,34075767,ARL,46784085,13.25,11,1,13.4,34,2,12.99,100,1,13.67,100,1,12.73,100,1,13.93,100,1,12.67,100,1,14,100,1,12.47,100,1,14.2,200,2,12.46,100,1,14.26,700,1,12.42,700,1,14.27,700,1,12.37,700,1,14.29,200,2,12.36,200,2,14.34,200,2,12.33,202,3,14.43,2,1
2025-07-17T13:30:48.271611303Z,2025-07-17T13:30:48.271777831Z,160,2,1108,C,A,0,13.4,10,130,166528,34129837,ARL,46784085,13.25,11,1,13.4,24,1,12.99,100,1,13.67,100,1,12.73,100,1,13.93,100,1,12.67,100,1,14,100,1,12.47,100,1,14.2,200,2,12.46,100,1,14.26,700,1,12.42,700,1,14.27,700,1,12.37,700,1,14.29,200,2,12.36,200,2,14.34,200,2,12.33,202,3,14.43,2,1
2025-07-17T13:30:56.518283181Z,2025-07-17T13:30:56.518448581Z,160,2,1108,A,A,0,13.4,10,130,165400,34951153,ARL,47164169,13.25,11,1,13.4,34,2,12.99,100,1,13.67,100,1,12.73,100,1,13.93,100,1,12.67,100,1,14,100,1,12.47,100,1,14.2,200,2,12.46,100,1,14.26,700,1,12.42,700,1,14.27,700,1,12.37,700,1,14.29,200,2,12.36,200,2,14.34,200,2,12.33,202,3,14.43,2,1
2025-07-17T13:31:01.011743292Z,2025-07-17T13:31:01.011909405Z,160,2,1108,A,A,0,14.2,700,128,166113,35180694,ARL,47376925,13.25,11,1,13.4,34,2,12.99,100,1,13.67,100,1,12.73,100,1,13.93,100,1,12.67,100,1,14,100,1,12.47,100,1,14.2,900,3,12.46,100,1,14.26,700,1,12.42,700,1,14.27,700,1,12.37,700,1,14.29,200,2,12.36,200,2,14.34,200,2,12.33,202,3,14.43,2,1
2025-07-17T13:31:01.028848502Z,2025-07-17T13:31:01.029013770Z,160,2,1108,A,B,0,12.43,700,130,165268,35188622,ARL,47383873,13.25,11,1,13.4,34,2,12.99,100,1,13.67,100,1,12.73,100,1,13.93,100,1,12.67,100,1,14,100,1,12.47,100,1,14.2,900,3,12.46,100,1,14.26,700,1,12.43,700,1,14.27,700,1,12.42,700,1,14.29,200,2,12.37,700,1,14.34,200,2,12.36,200,2,14.43,2,1
2025-07-17T13:31:01.131557345Z,2025-07-17T13:31:01.131725810Z,160,2,1108,C,A,0,13.4,10,128,168465,35203355,ARL,47164169,13.25,11,1,13.4,24,1,12.99,100,1,13.67,100,1,12.73,100,1,13.93,100,1,12.67,100,1,14,100,1,12.47,100,1,14.2,900,3,12.46,100,1,14.26,700,1,12.43,700,1,14.27,700,1,12.42,700,1,14.29,200,2,12.37,700,1,14.34,200,2,12.36,200,2,14.43,2,1
2025-07-17T13:31:08.376321454Z,2025-07-17T13:31:08.376486633Z,160,2,1108,C,A,0,13.4,24,130,165179,35703639,ARL,46613073,13.25,11,1,13.67,100,1,12.99,100,1,13.93,100,1,12.73,100,1,14,100,1,12.67,100,1,14.2,900,3,12.47,100,1,14.26,700,1,12.46,100,1,14.27,700,1,12.43,700,1,14.29,200,2,12.42,700,1,14.34,200,2,12.37,700,1,14.43,2,1,12.36,200,2,14.44,100,1
2025-07-17T13:31:08.376692815Z,2025-07-17T13:31:08.376858048Z,160,2,1108,A,A,0,13.4,18,130,165233,35703653,ARL,47873813,13.25,11,1,13.4,18,1,12.99,100,1,13.67,100,1,12.73,100,1,13.93,100,1,12.67,100,1,14,100,1,12.47,100,1,14.2,900,3,12.46,100,1,14.26,700,1,12.43,700,1,14.27,700,1,12.42,700,1,14.29,200,2,12.37,700,1,14.34,200,2,12.36,200,2,14.43,2,1
2025-07-17T13:31:08.377022927Z,2025-07-17T13:31:08.377188468Z,160,2,1108,C,A,0,14.29,100,0,165541,35703666,ARL,44720033,13.25,11,1,13.4,18,1,12.99,100,1,13.67,100,1,12.73,100,1,13.93,100,1,12.67,100,1,14,100,1,12.47,100,1,14.2,900,3,12.46,100,1,14.26,700,1,12.43,700,1,14.27,700,1,12.42,700,1,14.29,100,1,12.37,700,1,14.34,200,2,12.36,200,2,14.43,2,1
2025-07-17T13:31:08.377022927Z,2025-07-17T13:31:08.377188468Z,160,2,1108,A,A,0,14.56,100,130,165541,35703666,ARL,47873821,13.25,11,1,13.4,18,1,12.99,100,1,13.67,100,1,12.73,100,1,13.93,100,1,12.67,100,1,14,100,1,12.47,100,1,14.2,900,3,12.46,100,1,14.26,700,1,12.43,700,1,14.27,700,1,12.42,700,1,14.29,100,1,12.37,700,1,14.34,200,2,12.36,200,2,14.43,2,1
2025-07-17T13:31:09.399928944Z,2025-07-17T13:31:09.400094773Z,160,2,1108,C,A,0,14.56,100,0,165829,35758774,ARL,47873821,13.25,11,1,13.4,18,1,12.99,100,1,13.67,100,1,12.73,100,1,13.93,100,1,12.67,100,1,14,100,1,12.47,100,1,14.2,900,3,12.46,100,1,14.26,700,1,12.43,700,1,14.27,700,1,12.42,700,1,14.29,100,1,12.37,700,1,14.34,200,2,12.36,200,2,14.43,2,1
2025-07-17T13:31:09.399928944Z,2025-07-17T13:31:09.400094773Z,160,2,1108,A,A,0,14.29,100,130,165829,35758774,ARL,47927629,13.25,11,1,13.4,18,1,12.99,100,1,13.67,100,1,12.73,100,1,13.93,100,1,12.67,100,1,14,100,1,12.47,100,1,14.2,900,3,12.46,100,1,14.26,700,1,12.43,700,1,14.27,700,1,12.42,700,1,14.29,200,2,12.37,700,1,14.34,200,2,12.36,200,2,14.43,2,1
2025-07-17T13:31:16.538876621Z,2025-07-17T13:31:16.539042057Z,160,2,1108,A,A,0,13.4,10,130,165436,36186495,ARL,48315949,13.25,11,1,13.4,28,2,12.99,100,1,13.67,100,1,12.73,100,1,13.93,100,1,12.67,100,1,14,100,1,12.47,100,1,14.2,900,3,12.46,100,1,14.26,700,1,12.43,700,1,14.27,700,1,12.42,700,1,14.29,200,2,12.37,700,1,14.34,200,2,12.36,200,2,14.43,2,1
2025-07-17T13:31:17.448559991Z,2025-07-17T13:31:17.448727976Z,160,2,1108,C,A,0,13.4,10,128,167985,36232894,ARL,48315949,13.25,11,1,13.4,18,1,12.99,100,1,13.67,100,1,12.73,100,1,13.93,100,1,12.67,100,1,14,100,1,12.47,100,1,14.2,900,3,12.46,100,1,14.26,700,1,12.43,700,1,14.27,700,1,12.42,700,1,14.29,200,2,12.37,700,1,14.34,200,2,12.36,200,2,14.43,2,1
2025-07-17T13:31:34.835937627Z,2025-07-17T13:31:34.836102962Z,160,2,1108,C,A,0,13.4,18,130,165335,37177882,ARL,47873813,13.25,11,1,13.67,100,1,12.99,100,1,13.93,100,1,12.73,100,1,14,100,1,12.67,100,1,14.2,900,3,12.47,100,1,14.26,700,1,12.46,100,1,14.27,700,1,12.43,700,1,14.29,200,2,12.42,700,1,14.34,200,2,12.37,700,1,14.43,2,1,12.36,200,2,14.44,100,1
2025-07-17T13:31:34.836694504Z,2025-07-17T13:31:34.836860858Z,160,2,1108,C,A,0,14.29,100,0,166354,37177896,ARL,44719985,13.25,11,1,13.67,100,1,12.99,100,1,13.93,100,1,12.73,100,1,14,100,1,12.67,100,1,14.2,900,3,12.47,100,1,14.26,700,1,12.46,100,1,14.27,700,1,12.43,700,1,14.29,100,1,12.42,700,1,14.34,200,2,12.37,700,1,14.43,2,1,12.36,200,2,14.44,100,1
2025-07-17T13:31:34.836694504Z,2025-07-17T13:31:34.836860858Z,160,2,1108,A,A,0,14.56,100,130,166354,37177896,ARL,49226081,13.25,11,1,13.67,100,1,12.99,100,1,13.93,100,1,12.73,100,1,14,100,1,12.67,100,1,14.2,900,3,12.47,100,1,14.26,700,1,12.46,100,1,14.27,700,1,12.43,700,1,14.29,100,1,12.42,700,1,14.34,200,2,12.37,700,1,14.43,2,1,12.36,200,2,14.44,100,1
2025-07-17T13:31:34.837099615Z,2025-07-17T13:31:34.837265065Z,160,2,1108,C,A,0,14.29,100,0,165450,37177905,ARL,47927629,13.25,11,1,13.67,100,1,12.99,100,1,13.93,100,1,12.73,100,1,14,100,1,12.67,100,1,14.2,900,3,12.47,100,1,14.26,700,1,12.46,100,1,14.27,700,1,12.43,700,1,14.34,200,2,12.42,700,1,14.43,2,1,12.37,700,1,14.44,100,1,12.36,200,2,14.46,700,1
2025-07-17T13:31:34.837099615Z,2025-07-17T13:31:34.837265065Z,160,2,1108,A,A,0,14.56,100,130,165450,37177905,ARL,49226101,13.25,11,1,13.67,100,1,12.99,100,1,13.93,100,1,12.73,100,1,14,100,1,12.67,100,1,14.2,900,3,12.47,100,1,14.26,700,1,12.46,100,1,14.27,700,1,12.43,700,1,14.34,200,2,12.42,700,1,14.43,2,1,12.37,700,1,14.44,100,1,12.36,200,2,14.46,700,1
2025-07-17T13:35:00.187526221Z,2025-07-17T13:35:00.187694195Z,160,2,1108,C,B,0,12.33,2,0,167974,45447658,ARL,43692153,13.25,11,1,13.67,100,1,12.99,100,1,13.93,100,1,12.73,100,1,14,100,1,12.67,100,1,14.2,900,3,12.47,100,1,14.26,700,1,12.46,100,1,14.27,700,1,12.43,700,1,14.34,200,2,12.42,700,1,14.43,2,1,12.37,700,1,14.44,100,1,12.36,200,2,14.46,700,1
2025-07-17T13:35:00.187526221Z,2025-07-17T13:35:00.187694195Z,160,2,1108,A,B,0,12.88,2,128,167974,45447658,ARL,58709193,13.25,11,1,13.67,100,1,12.99,100,1,13.93,100,1,12.88,2,1,14,100,1,12.73,100,1,14.2,900,3,12.67,100,1,14.26,700,1,12.47,100,1,14.27,700,1,12.46,100,1,14.34,200,2,12.43,700,1,14.43,2,1,12.42,700,1,14.44,100,1,12.37,700,1,14.46,700,1
2025-07-17T13:35:00.187528642Z,2025-07-17T13:35:00.187694720Z,160,2,1108,C,A,0,14.43,2,0,166078,45447661,ARL,44904733,13.25,11,1,13.67,100,1,12.99,100,1,13.93,100,1,12.88,2,1,14,100,1,12.73,100,1,14.2,900,3,12.67,100,1,14.26,700,1,12.47,100,1,14.27,700,1,12.46,100,1,14.34,200,2,12.43,700,1,14.44,100,1,12.42,700,1,14.46,700,1,12.37,700,1,14.56,200,2
2025-07-17T13:35:00.187528642Z,2025-07-17T13:35:00.187694720Z,160,2,1108,A,A,0,13.78,2,130,166078,45447661,ARL,58709197,13.25,11,1,13.67,100,1,12.99,100,1,13.78,2,1,12.88,2,1,13.93,100,1,12.73,100,1,14,100,1,12.67,100,1,14.2,900,3,12.47,100,1,14.26,700,1,12.46,100,1,14.27,700,1,12.43,700,1,14.34,200,2,12.42,700,1,14.44,100,1,12.37,700,1,14.46,700,1
2025-07-17T13:37:31.076154614Z,2025-07-17T13:37:31.076320046Z,160,2,1108,C,A,0,14.56,100,0,165432,51978366,ARL,49226101,13.25,11,1,13.67,100,1,12.99,100,1,13.78,2,1,12.88,2,1,13.93,100,1,12.73,100,1,14,100,1,12.67,100,1,14.2,900,3,12.47,100,1,14.26,700,1,12.46,100,1,14.27,700,1,12.43,700,1,14.34,200,2,12.42,700,1,14.44,100,1,12.37,700,1,14.46,700,1
2025-07-17T13:37:31.076154614Z,2025-07-17T13:37:31.076320046Z,160,2,1108,A,A,0,14.29,100,130,165432,51978366,ARL,65160189,13.25,11,1,13.67,100,1,12.99,100,1,13.78,2,1,12.88,2,1,13.93,100,1,12.73,100,1,14,100,1,12.67,100,1,14.2,900,3,12.47,100,1,14.26,700,1,12.46,100,1,14.27,700,1,12.43,700,1,14.29,100,1,12.42,700,1,14.34,200,2,12.37,700,1,14.44,100,1
2025-07-17T13:37:31.076330756Z,2025-07-17T13:37:31.076496403Z,160,2,1108,C,A,0,14.56,100,0,165647,51978372,ARL,49226081,13.25,11,1,13.67,100,1,12.99,100,1,13.78,2,1,12.88,2,1,13.93,100,1,12.73,100,1,14,100,1,12.67,100,1,14.2,900,3,12.47,100,1,14.26,700,1,12.46,100,1,14.27,700,1,12.43,700,1,14.29,100,1,12.42,700,1,14.34,200,2,12.37,700,1,14.44,100,1
2025-07-17T13:37:31.076330756Z,2025-07-17T13:37:31.076496403Z,160,2,1108,A,A,0,14.29,100,130,165647,51978372,ARL,65160193,13.25,11,1,13.67,100,1,12.99,100,1,13.78,2,1,12.88,2,1,13.93,100,1,12.73,100,1,14,100,1,12.67,100,1,14.2,900,3,12.47,100,1,14.26,700,1,12.46,100,1,14.27,700,1,12.43,700,1,14.29,200,2,12.42,700,1,14.34,200,2,12.37,700,1,14.44,100,1
2025-07-17T13:38:08.679744459Z,2025-07-17T13:38:08.679910189Z,160,2,1108,C,A,0,14.29,100,0,165730,53264917,ARL,65160189,13.25,11,1,13.67,100,1,12.99,100,1,13.78,2,1,12.88,2,1,13.93,100,1,12.73,100,1,14,100,1,12.67,100,1,14.2,900,3,12.47,100,1,14.26,700,1,12.46,100,1,14.27,700,1,12.43,700,1,14.29,100,1,12.42,700,1,14.34,200,2,12.37,700,1,14.44,100,1
2025-07-17T13:38:08.679744459Z,2025-07-17T13:38:08.679910189Z,160,2,1108,A,A,0,14.56,100,130,165730,53264917,ARL,66501333,13.25,11,1,13.67,100,1,12.99,100,1,13.78,2,1,12.88,2,1,13.93,100,1,12.73,100,1,14,100,1,12.67,100,1,14.2,900,3,12.47,100,1,14.26,700,1,12.46,100,1,14.27,700,1,12.43,700,1,14.29,100,1,12.42,700,1,14.34,200,2,12.37,700,1,14.44,100,1
2025-07-17T13:38:08.679752190Z,2025-07-17T13:38:08.679917832Z,160,2,1108,C,A,0,14.29,100,0,165642,53264918,ARL,65160193,13.25,11,1,13.67,100,1,12.99,100,1,13.78,2,1,12.88,2,1,13.93,100,1,12.73,100,1,14,100,1,12.67,100,1,14.2,900,3,12.47,100,1,14.26,700,1,12.46,100,1,14.27,700,1,12.43,700,1,14.34,200,2,12.42,700,1,14.44,100,1,12.37,700,1,14.46,700,1
2025-07-17T13:38:08.679752190Z,2025-07-17T13:38:08.679917832Z,160,2,1108,A,A,0,14.56,100,130,165642,53264918,ARL,66501341,13.25,11,1,13.67,100,1,12.99,100,1,13.78,2,1,12.88,2,1,13.93,100,1,12.73,100,1,14,100,1,12.67,100,1,14.2,900,3,12.47,100,1,14.26,700,1,12.46,100,1,14.27,700,1,12.43,700,1,14.34,200,2,12.42,700,1,14.44,100,1,12.37,700,1,14.46,700,1
2025-07-17T13:38:09.686863512Z,2025-07-17T13:38:09.687028970Z,160,2,1108,C,A,0,14.56,100,0,165458,53302839,ARL,66501333,13.25,11,1,13.67,100,1,12.99,100,1,13.78,2,1,12.88,2,1,13.93,100,1,12.73,100,1,14,100,1,12.67,100,1,14.2,900,3,12.47,100,1,14.26,700,1,12.46,100,1,14.27,700,1,12.43,700,1,14.34,200,2,12.42,700,1,14.44,100,1,12.37,700,1,14.46,700,1
2025-07-17T13:38:09.686863512Z,2025-07-17T13:38:09.687028970Z,160,2,1108,A,A,0,14.29,100,130,165458,53302839,ARL,66538149,13.25,11,1,13.67,100,1,12.99,100,1,13.78,2,1,12.88,2,1,13.93,100,1,12.73,100,1,14,100,1,12.67,100,1,14.2,900,3,12.47,100,1,14.26,700,1,12.46,100,1,14.27,700,1,12.43,700,1,14.29,100,1,12.42,700,1,14.34,200,2,12.37,700,1,14.44,100,1
2025-07-17T13:38:09.708029202Z,2025-07-17T13:38:09.708195003Z,160,2,1108,C,A,0,14.56,100,0,165801,53303094,ARL,66501341,13.25,11,1,13.67,100,1,12.99,100,1,13.78,2,1,12.88,2,1,13.93,100,1,12.73,100,1,14,100,1,12.67,100,1,14.2,900,3,12.47,100,1,14.26,700,1,12.46,100,1,14.27,700,1,12.43,700,1,14.29,100,1,12.42,700,1,14.34,200,2,12.37,700,1,14.44,100,1
2025-07-17T13:38:09.708029202Z,2025-07-17T13:38:09.708195003Z,160,2,1108,A,A,0,14.29,100,130,165801,53303094,ARL,66538573,13.25,11,1,13.67,100,1,12.99,100,1,13.78,2,1,12.88,2,1,13.93,100,1,12.73,100,1,14,100,1,12.67,100,1,14.2,900,3,12.47,100,1,14.26,700,1,12.46,100,1,14.27,700,1,12.43,700,1,14.29,200,2,12.42,700,1,14.34,200,2,12.37,700,1,14.44,100,1
2025-07-17T13:38:44.678957477Z,2025-07-17T13:38:44.679122862Z,160,2,1108,A,A,0,13.4,15,130,165385,54485050,ARL,67832461,13.25,11,1,13.4,15,1,12.99,100,1,13.67,100,1,12.88,2,1,13.78,2,1,12.73,100,1,13.93,100,1,12.67,100,1,14,100,1,12.47,100,1,14.2,900,3,12.46,100,1,14.26,700,1,12.43,700,1,14.27,700,1,12.42,700,1,14.29,200,2,12.37,700,1,14.34,200,2
2025-07-17T13:38:44.679278833Z,2025-07-17T13:38:44.679444346Z,160,2,1108,C,A,0,14.29,100,0,165513,54485052,ARL,66538149,13.25,11,1,13.4,15,1,12.99,100,1,13.67,100,1,12.88,2,1,13.78,2,1,12.73,100,1,13.93,100,1,12.67,100,1,14,100,1,12.47,100,1,14.2,900,3,12.46,100,1,14.26,700,1,12.43,700,1,14.27,700,1,12.42,700,1,14.29,100,1,12.37,700,1,14.34,200,2
2025-07-17T13:38:44.679278833Z,2025-07-17T13:38:44.679444346Z,160,2,1108,A,A,0,14.56,100,130,165513,54485052,ARL,67832465,13.25,11,1,13.4,15,1,12.99,100,1,13.67,100,1,12.88,2,1,13.78,2,1,12.73,100,1,13.93,100,1,12.67,100,1,14,100,1,12.47,100,1,14.2,900,3,12.46,100,1,14.26,700,1,12.43,700,1,14.27,700,1,12.42,700,1,14.29,100,1,12.37,700,1,14.34,200,2
2025-07-17T13:38:45.695265148Z,2025-07-17T13:38:45.695430520Z,160,2,1108,C,A,0,14.56,100,0,165372,54508575,ARL,67832465,13.25,11,1,13.4,15,1,12.99,100,1,13.67,100,1,12.88,2,1,13.78,2,1,12.73,100,1,13.93,100,1,12.67,100,1,14,100,1,12.47,100,1,14.2,900,3,12.46,100,1,14.26,700,1,12.43,700,1,14.27,700,1,12.42,700,1,14.29,100,1,12.37,700,1,14.34,200,2
2025-07-17T13:38:45.695265148Z,2025-07-17T13:38:45.695430520Z,160,2,1108,A,A,0,14.29,100,130,165372,54508575,ARL,67857641,13.25,11,1,13.4,15,1,12.99,100,1,13.67,100,1,12.88,2,1,13.78,2,1,12.73,100,1,13.93,100,1,12.67,100,1,14,100,1,12.47,100,1,14.2,900,3,12.46,100,1,14.26,700,1,12.43,700,1,14.27,700,1,12.42,700,1,14.29,200,2,12.37,700,1,14.34,200,2
2025-07-17T13:39:08.713907562Z,2025-07-17T13:39:08.714072882Z,160,2,1108,C,A,0,13.4,15,130,165320,55204868,ARL,67832461,13.25,11,1,13.67,100,1,12.99,100,1,13.78,2,1,12.88,2,1,13.93,100,1,12.73,100,1,14,100,1,12.67,100,1,14.2,900,3,12.47,100,1,14.26,700,1,12.46,100,1,14.27,700,1,12.43,700,1,14.29,200,2,12.42,700,1,14.34,200,2,12.37,700,1,14.44,100,1
2025-07-17T13:39:08.714284059Z,2025-07-17T13:39:08.714449550Z,160,2,1108,A,A,0,13.4,24,130,165491,55204884,ARL,68625181,13.25,11,1,13.4,24,1,12.99,100,1,13.67,100,1,12.88,2,1,13.78,2,1,12.73,100,1,13.93,100,1,12.67,100,1,14,100,1,12.47,100,1,14.2,900,3,12.46,100,1,14.26,700,1,12.43,700,1,14.27,700,1,12.42,700,1,14.29,200,2,12.37,700,1,14.34,200,2
2025-07-17T13:39:39.996436857Z,2025-07-17T13:39:39.996603180Z,160,2,1108,C,A,0,13.4,1,130,166323,56150102,ARL,68625181,13.25,11,1,13.4,23,1,12.99,100,1,13.67,100,1,12.88,2,1,13.78,2,1,12.73,100,1,13.93,100,1,12.67,100,1,14,100,1,12.47,100,1,14.2,900,3,12.46,100,1,14.26,700,1,12.43,700,1,14.27,700,1,12.42,700,1,14.29,200,2,12.37,700,1,14.34,200,2
2025-07-17T13:39:39.996833282Z,2025-07-17T13:39:39.996998334Z,160,2,1108,C,A,0,13.4,23,130,165052,56150114,ARL,68625181,13.25,11,1,13.67,100,1,12.99,100,1,13.78,2,1,12.88,2,1,13.93,100,1,12.73,100,1,14,100,1,12.67,100,1,14.2,900,3,12.47,100,1,14.26,700,1,12.46,100,1,14.27,700,1,12.43,700,1,14.29,200,2,12.42,700,1,14.34,200,2,12.37,700,1,14.44,100,1
2025-07-17T13:39:39.997144158Z,2025-07-17T13:39:39.997309515Z,160,2,1108,C,A,0,14.29,100,0,165357,56150130,ARL,66538573,13.25,11,1,13.67,100,1,12.99,100,1,13.78,2,1,12.88,2,1,13.93,100,1,12.73,100,1,14,100,1,12.67,100,1,14.2,900,3,12.47,100,1,14.26,700,1,12.46,100,1,14.27,700,1,12.43,700,1,14.29,100,1,12.42,700,1,14.34,200,2,12.37,700,1,14.44,100,1
2025-07-17T13:39:39.997144158Z,2025-07-17T13:39:39.997309515Z,160,2,1108,A,A,0,14.57,100,130,165357,56150130,ARL,69677517,13.25,11,1,13.67,100,1,12.99,100,1,13.78,2,1,12.88,2,1,13.93,100,1,12.73,100,1,14,100,1,12.67,100,1,14.2,900,3,12.47,100,1,14.26,700,1,12.46,100,1,14.27,700,1,12.43,700,1,14.29,100,1,12.42,700,1,14.34,200,2,12.37,700,1,14.44,100,1
2025-07-17T13:39:39.997211562Z,2025-07-17T13:39:39.997376873Z,160,2,1108,A,A,0,13.4,24,130,165311,56150131,ARL,69677521,13.25,11,1,13.4,24,1,12.99,100,1,13.67,100,1,12.88,2,1,13.78,2,1,12.73,100,1,13.93,100,1,12.67,100,1,14,100,1,12.47,100,1,14.2,900,3,12.46,100,1,14.26,700,1,12.43,700,1,14.27,700,1,12.42,700,1,14.29,100,1,12.37,700,1,14.34,200,2
2025-07-17T13:39:41.018783466Z,2025-07-17T13:39:41.018948933Z,160,2,1108,C,A,0,14.57,100,0,165467,56183429,ARL,69677517,13.25,11,1,13.4,24,1,12.99,100,1,13.67,100,1,12.88,2,1,13.78,2,1,12.73,100,1,13.93,100,1,12.67,100,1,14,100,1,12.47,100,1,14.2,900,3,12.46,100,1,14.26,700,1,12.43,700,1,14.27,700,1,12.42,700,1,14.29,100,1,12.37,700,1,14.34,200,2
2025-07-17T13:39:41.018783466Z,2025-07-17T13:39:41.018948933Z,160,2,1108,A,A,0,14.3,100,130,165467,56183429,ARL,69725541,13.25,11,1,13.4,24,1,12.99,100,1,13.67,100,1,12.88,2,1,13.78,2,1,12.73,100,1,13.93,100,1,12.67,100,1,14,100,1,12.47,100,1,14.2,900,3,12.46,100,1,14.26,700,1,12.43,700,1,14.27,700,1,12.42,700,1,14.29,100,1,12.37,700,1,14.3,100,1
2025-07-17T13:40:08.782383621Z,2025-07-17T13:40:08.782549047Z,160,2,1108,C,A,0,13.4,24,130,165426,57235944,ARL,69677521,13.25,11,1,13.67,100,1,12.99,100,1,13.78,2,1,12.88,2,1,13.93,100,1,12.73,100,1,14,100,1,12.67,100,1,14.2,900,3,12.47,100,1,14.26,700,1,12.46,100,1,14.27,700,1,12.43,700,1,14.29,100,1,12.42,700,1,14.3,100,1,12.37,700,1,14.34,200,2
2025-07-17T13:40:08.782758499Z,2025-07-17T13:40:08.782923978Z,160,2,1108,A,A,0,13.4,18,130,165479,57235956,ARL,70897053,13.25,11,1,13.4,18,1,12.99,100,1,13.67,100,1,12.88,2,1,13.78,2,1,12.73,100,1,13.93,100,1,12.67,100,1,14,100,1,12.47,100,1,14.2,900,3,12.46,100,1,14.26,700,1,12.43,700,1,14.27,700,1,12.42,700,1,14.29,100,1,12.37,700,1,14.3,100,1
2025-07-17T13:41:08.818711250Z,2025-07-17T13:41:08.818876572Z,160,2,1108,C,A,0,13.4,18,130,165322,59313726,ARL,70897053,13.25,11,1,13.67,100,1,12.99,100,1,13.78,2,1,12.88,2,1,13.93,100,1,12.73,100,1,14,100,1,12.67,100,1,14.2,900,3,12.47,100,1,14.26,700,1,12.46,100,1,14.27,700,1,12.43,700,1,14.29,100,1,12.42,700,1,14.3,100,1,12.37,700,1,14.34,200,2
2025-07-17T13:41:08.819083504Z,2025-07-17T13:41:08.819249545Z,160,2,1108,A,A,0,13.4,24,130,166041,59313736,ARL,73109413,13.25,11,1,13.4,24,1,12.99,100,1,13.67,100,1,12.88,2,1,13.78,2,1,12.73,100,1,13.93,100,1,12.67,100,1,14,100,1,12.47,100,1,14.2,900,3,12.46,100,1,14.26,700,1,12.43,700,1,14.27,700,1,12.42,700,1,14.29,100,1,12.37,700,1,14.3,100,1
2025-07-17T13:41:08.819104931Z,2025-07-17T13:41:08.819270512Z,160,2,1108,C,A,0,14.3,100,0,165581,59313739,ARL,69725541,13.25,11,1,13.4,24,1,12.99,100,1,13.67,100,1,12.88,2,1,13.78,2,1,12.73,100,1,13.93,100,1,12.67,100,1,14,100,1,12.47,100,1,14.2,900,3,12.46,100,1,14.26,700,1,12.43,700,1,14.27,700,1,12.42,700,1,14.29,100,1,12.37,700,1,14.34,200,2
2025-07-17T13:41:08.819104931Z,2025-07-17T13:41:08.819270512Z,160,2,1108,A,A,0,14.57,100,130,165581,59313739,ARL,73109417,13.25,11,1,13.4,24,1,12.99,100,1,13.67,100,1,12.88,2,1,13.78,2,1,12.73,100,1,13.93,100,1,12.67,100,1,14,100,1,12.47,100,1,14.2,900,3,12.46,100,1,14.26,700,1,12.43,700,1,14.27,700,1,12.42,700,1,14.29,100,1,12.37,700,1,14.34,200,2
2025-07-17T13:41:09.881085734Z,2025-07-17T13:41:09.881251193Z,160,2,1108,C,A,0,14.57,100,0,165459,59383199,ARL,73109417,13.25,11,1,13.4,24,1,12.99,100,1,13.67,100,1,12.88,2,1,13.78,2,1,12.73,100,1,13.93,100,1,12.67,100,1,14,100,1,12.47,100,1,14.2,900,3,12.46,100,1,14.26,700,1,12.43,700,1,14.27,700,1,12.42,700,1,14.29,100,1,12.37,700,1,14.34,200,2
2025-07-17T13:41:09.881085734Z,2025-07-17T13:41:09.881251193Z,160,2,1108,A,A,0,14.3,100,130,165459,59383199,ARL,73183421,13.25,11,1,13.4,24,1,12.99,100,1,13.67,100,1,12.88,2,1,13.78,2,1,12.73,100,1,13.93,100,1,12.67,100,1,14,100,1,12.47,100,1,14.2,900,3,12.46,100,1,14.26,700,1,12.43,700,1,14.27,700,1,12.42,700,1,14.29,100,1,12.37,700,1,14.3,100,1
2025-07-17T13:41:44.348494744Z,2025-07-17T13:41:44.348660105Z,160,2,1108,C,A,0,13.4,24,130,165361,60614543,ARL,73109413,13.25,11,1,13.67,100,1,12.99,100,1,13.78,2,1,12.88,2,1,13.93,100,1,12.73,100,1,14,100,1,12.67,100,1,14.2,900,3,12.47,100,1,14.26,700,1,12.46,100,1,14.27,700,1,12.43,700,1,14.29,100,1,12.42,700,1,14.3,100,1,12.37,700,1,14.34,200,2
2025-07-17T13:41:44.349416601Z,2025-07-17T13:41:44.349581977Z,160,2,1108,C,A,0,14.3,100,0,165376,60614557,ARL,73183421,13.25,11,1,13.67,100,1,12.99,100,1,13.78,2,1,12.88,2,1,13.93,100,1,12.73,100,1,14,100,1,12.67,100,1,14.2,900,3,12.47,100,1,14.26,700,1,12.46,100,1,14.27,700,1,12.43,700,1,14.29,100,1,12.42,700,1,14.34,200,2,12.37,700,1,14.44,100,1
2025-07-17T13:41:44.349416601Z,2025-07-17T13:41:44.349581977Z,160,2,1108,A,A,0,14.57,100,130,165376,60614557,ARL,74549681,13.25,11,1,13.67,100,1,12.99,100,1,13.78,2,1,12.88,2,1,13.93,100,1,12.73,100,1,14,100,1,12.67,100,1,14.2,900,3,12.47,100,1,14.26,700,1,12.46,100,1,14.27,700,1,12.43,700,1,14.29,100,1,12.42,700,1,14.34,200,2,12.37,700,1,14.44,100,1
2025-07-17T13:41:45.405013016Z,2025-07-17T13:41:45.405178844Z,160,2,1108,C,A,0,14.57,100,0,165828,60651462,ARL,74549681,13.25,11,1,13.67,100,1,12.99,100,1,13.78,2,1,12.88,2,1,13.93,100,1,12.73,100,1,14,100,1,12.67,100,1,14.2,900,3,12.47,100,1,14.26,700,1,12.46,100,1,14.27,700,1,12.43,700,1,14.29,100,1,12.42,700,1,14.34,200,2,12.37,700,1,14.44,100,1
2025-07-17T13:41:45.405013016Z,2025-07-17T13:41:45.405178844Z,160,2,1108,A,A,0,14.3,100,130,165828,60651462,ARL,74589605,13.25,11,1,13.67,100,1,12.99,100,1,13.78,2,1,12.88,2,1,13.93,100,1,12.73,100,1,14,100,1,12.67,100,1,14.2,900,3,12.47,100,1,14.26,700,1,12.46,100,1,14.27,700,1,12.43,700,1,14.29,100,1,12.42,700,1,14.3,100,1,12.37,700,1,14.34,200,2
2025-07-17T13:42:08.821155108Z,2025-07-17T13:42:08.821320823Z,160,2,1108,C,A,0,14.29,100,0,165715,61488742,ARL,67857641,13.25,11,1,13.67,100,1,12.99,100,1,13.78,2,1,12.88,2,1,13.93,100,1,12.73,100,1,14,100,1,12.67,100,1,14.2,900,3,12.47,100,1,14.26,700,1,12.46,100,1,14.27,700,1,12.43,700,1,14.3,100,1,12.42,700,1,14.34,200,2,12.37,700,1,14.44,100,1
2025-07-17T13:42:08.821155108Z,2025-07-17T13:42:08.821320823Z,160,2,1108,A,A,0,14.57,100,130,165715,61488742,ARL,75537553,13.25,11,1,13.67,100,1,12.99,100,1,13.78,2,1,12.88,2,1,13.93,100,1,12.73,100,1,14,100,1,12.67,100,1,14.2,900,3,12.47,100,1,14.26,700,1,12.46,100,1,14.27,700,1,12.43,700,1,14.3,100,1,12.42,700,1,14.34,200,2,12.37,700,1,14.44,100,1
2025-07-17T13:42:09.826891682Z,2025-07-17T13:42:09.827057338Z,160,2,1108,C,A,0,14.57,100,0,165656,61523538,ARL,75537553,13.25,11,1,13.67,100,1,12.99,100,1,13.78,2,1,12.88,2,1,13.93,100,1,12.73,100,1,14,100,1,12.67,100,1,14.2,900,3,12.47,100,1,14.26,700,1,12.46,100,1,14.27,700,1,12.43,700,1,14.3,100,1,12.42,700,1,14.34,200,2,12.37,700,1,14.44,100,1
2025-07-17T13:42:09.826891682Z,2025-07-17T13:42:09.827057338Z,160,2,1108,A,A,0,14.3,100,130,165656,61523538,ARL,75577257,13.25,11,1,13.67,100,1,12.99,100,1,13.78,2,1,12.88,2,1,13.93,100,1,12.73,100,1,14,100,1,12.67,100,1,14.2,900,3,12.47,100,1,14.26,700,1,12.46,100,1,14.27,700,1,12.43,700,1,14.3,200,2,12.42,700,1,14.34,200,2,12.37,700,1,14.44,100,1
2025-07-17T13:43:08.826078491Z,2025-07-17T13:43:08.826244125Z,160,2,1108,C,A,0,14.3,100,0,165634,63579150,ARL,75577257,13.25,11,1,13.67,100,1,12.99,100,1,13.78,2,1,12.88,2,1,13.93,100,1,12.73,100,1,14,100,1,12.67,100,1,14.2,900,3,12.47,100,1,14.26,700,1,12.46,100,1,14.27,700,1,12.43,700,1,14.3,100,1,12.42,700,1,14.34,200,2,12.37,700,1,14.44,100,1
2025-07-17T13:43:08.826078491Z,2025-07-17T13:43:08.826244125Z,160,2,1108,A,A,0,14.57,100,130,165634,63579150,ARL,77879933,13.25,11,1,13.67,100,1,12.99,100,1,13.78,2,1,12.88,2,1,13.93,100,1,12.73,100,1,14,100,1,12.67,100,1,14.2,900,3,12.47,100,1,14.26,700,1,12.46,100,1,14.27,700,1,12.43,700,1,14.3,100,1,12.42,700,1,14.34,200,2,12.37,700,1,14.44,100,1
2025-07-17T13:43:09.832406764Z,2025-07-17T13:43:09.832572415Z,160,2,1108,C,A,0,14.57,100,0,165651,63604352,ARL,77879933,13.25,11,1,13.67,100,1,12.99,100,1,13.78,2,1,12.88,2,1,13.93,100,1,12.73,100,1,14,100,1,12.67,100,1,14.2,900,3,12.47,100,1,14.26,700,1,12.46,100,1,14.27,700,1,12.43,700,1,14.3,100,1,12.42,700,1,14.34,200,2,12.37,700,1,14.44,100,1
2025-07-17T13:43:09.832406764Z,2025-07-17T13:43:09.832572415Z,160,2,1108,A,A,0,14.3,100,130,165651,63604352,ARL,77910357,13.25,11,1,13.67,100,1,12.99,100,1,13.78,2,1,12.88,2,1,13.93,100,1,12.73,100,1,14,100,1,12.67,100,1,14.2,900,3,12.47,100,1,14.26,700,1,12.46,100,1,14.27,700,1,12.43,700,1,14.3,200,2,12.42,700,1,14.34,200,2,12.37,700,1,14.44,100,1
2025-07-17T13:46:09.540851349Z,2025-07-17T13:46:09.541016899Z,160,2,1108,C,A,0,14.2,700,130,165550,69578535,ARL,47376925,13.25,11,1,13.67,100,1,12.99,100,1,13.78,2,1,12.88,2,1,13.93,100,1,12.73,100,1,14,100,1,12.67,100,1,14.2,200,2,12.47,100,1,14.26,700,1,12.46,100,1,14.27,700,1,12.43,700,1,14.3,200,2,12.42,700,1,14.34,200,2,12.37,700,1,14.44,100,1
2025-07-17T13:46:09.540892810Z,2025-07-17T13:46:09.541058233Z,160,2,1108,A,A,0,14.36,700,130,165423,69578537,ARL,84607761,13.25,11,1,13.67,100,1,12.99,100,1,13.78,2,1,12.88,2,1,13.93,100,1,12.73,100,1,14,100,1,12.67,100,1,14.2,200,2,12.47,100,1,14.26,700,1,12.46,100,1,14.27,700,1,12.43,700,1,14.3,200,2,12.42,700,1,14.34,200,2,12.37,700,1,14.36,700,1
2025-07-17T13:46:09.540932260Z,2025-07-17T13:46:09.541097538Z,160,2,1108,A,A,0,15.59,100,130,165278,69578539,ARL,84607765,13.25,11,1,13.67,100,1,12.99,100,1,13.78,2,1,12.88,2,1,13.93,100,1,12.73,100,1,14,100,1,12.67,100,1,14.2,200,2,12.47,100,1,14.26,700,1,12.46,100,1,14.27,700,1,12.43,700,1,14.3,200,2,12.42,700,1,14.34,200,2,12.37,700,1,14.36,700,1
2025-07-17T13:46:09.540944549Z,2025-07-17T13:46:09.541109881Z,160,2,1108,C,A,0,15.28,100,130,165332,69578540,ARL,43373085,13.25,11,1,13.67,100,1,12.99,100,1,13.78,2,1,12.88,2,1,13.93,100,1,12.73,100,1,14,100,1,12.67,100,1,14.2,200,2,12.47,100,1,14.26,700,1,12.46,100,1,14.27,700,1,12.43,700,1,14.3,200,2,12.42,700,1,14.34,200,2,12.37,700,1,14.36,700,1
2025-07-17T13:46:09.541269186Z,2025-07-17T13:46:09.541434576Z,160,2,1108,C,A,0,14.44,100,0,165390,69578543,ARL,43373009,13.25,11,1,13.67,100,1,12.99,100,1,13.78,2,1,12.88,2,1,13.93,100,1,12.73,100,1,14,100,1,12.67,100,1,14.2,200,2,12.47,100,1,14.26,700,1,12.46,100,1,14.27,700,1,12.43,700,1,14.3,200,2,12.42,700,1,14.34,200,2,12.37,700,1,14.36,700,1
2025-07-17T13:46:09.541269186Z,2025-07-17T13:46:09.541434576Z,160,2,1108,A,A,0,14.49,100,130,165390,69578543,ARL,84607785,13.25,11,1,13.67,100,1,12.99,100,1,13.78,2,1,12.88,2,1,13.93,100,1,12.73,100,1,14,100,1,12.67,100,1,14.2,200,2,12.47,100,1,14.26,700,1,12.46,100,1,14.27,700,1,12.43,700,1,14.3,200,2,12.42,700,1,14.34,200,2,12.37,700,1,14.36,700,1
2025-07-17T13:46:09.541327298Z,2025-07-17T13:46:09.541492629Z,160,2,1108,C,A,0,14,100,130,165331,69578544,ARL,43663233,13.25,11,1,13.67,100,1,12.99,100,1,13.78,2,1,12.88,2,1,13.93,100,1,12.73,100,1,14.2,200,2,12.67,100,1,14.26,700,1,12.47,100,1,14.27,700,1,12.46,100,1,14.3,200,2,12.43,700,1,14.34,200,2,12.42,700,1,14.36,700,1,12.37,700,1,14.46,700,1
2025-07-17T13:46:09.541629920Z,2025-07-17T13:46:09.541795256Z,160,2,1108,C,A,0,14.34,100,0,165336,69578547,ARL,43755821,13.25,11,1,13.67,100,1,12.99,100,1,13.78,2,1,12.88,2,1,13.93,100,1,12.73,100,1,14.2,200,2,12.67,100,1,14.26,700,1,12.47,100,1,14.27,700,1,12.46,100,1,14.3,200,2,12.43,700,1,14.34,100,1,12.42,700,1,14.36,700,1,12.37,700,1,14.46,700,1
2025-07-17T13:46:09.541629920Z,2025-07-17T13:46:09.541795256Z,160,2,1108,A,A,0,14.63,100,130,165336,69578547,ARL,84607801,13.25,11,1,13.67,100,1,12.99,100,1,13.78,2,1,12.88,2,1,13.93,100,1,12.73,100,1,14.2,200,2,12.67,100,1,14.26,700,1,12.47,100,1,14.27,700,1,12.46,100,1,14.3,200,2,12.43,700,1,14.34,100,1,12.42,700,1,14.36,700,1,12.37,700,1,14.46,700,1
2025-07-17T13:46:09.541680473Z,2025-07-17T13:46:09.541846554Z,160,2,1108,C,A,0,14.74,100,0,166081,69578550,ARL,43357029,13.25,11,1,13.67,100,1,12.99,100,1,13.78,2,1,12.88,2,1,13.93,100,1,12.73,100,1,14.2,200,2,12.67,100,1,14.26,700,1,12.47,100,1,14.27,700,1,12.46,100,1,14.3,200,2,12.43,700,1,14.34,100,1,12.42,700,1,14.36,700,1,12.37,700,1,14.46,700,1
2025-07-17T13:46:09.541680473Z,2025-07-17T13:46:09.541846554Z,160,2,1108,A,A,0,15.04,100,130,166081,69578550,ARL,84607805,13.25,11,1,13.67,100,1,12.99,100,1,13.78,2,1,12.88,2,1,13.93,100,1,12.73,100,1,14.2,200,2,12.67,100,1,14.26,700,1,12.47,100,1,14.27,700,1,12.46,100,1,14.3,200,2,12.43,700,1,14.34,100,1,12.42,700,1,14.36,700,1,12.37,700,1,14.46,700,1
2025-07-17T13:46:09.541682402Z,2025-07-17T13:46:09.541847519Z,160,2,1108,A,A,0,14.28,100,130,165117,69578551,ARL,84607809,13.25,11,1,13.67,100,1,12.99,100,1,13.78,2,1,12.88,2,1,13.93,100,1,12.73,100,1,14.2,200,2,12.67,100,1,14.26,700,1,12.47,100,1,14.27,700,1,12.46,100,1,14.28,100,1,12.43,700,1,14.3,200,2,12.42,700,1,14.34,100,1,12.37,700,1,14.36,700,1
2025-07-17T13:46:09.542796050Z,2025-07-17T13:46:09.542961756Z,160,2,1108,C,A,0,15.41,100,0,165706,69578574,ARL,43826805,13.25,11,1,13.67,100,1,12.99,100,1,13.78,2,1,12.88,2,1,13.93,100,1,12.73,100,1,14.2,200,2,12.67,100,1,14.26,700,1,12.47,100,1,14.27,700,1,12.46,100,1,14.28,100,1,12.43,700,1,14.3,200,2,12.42,700,1,14.34,100,1,12.37,700,1,14.36,700,1
2025-07-17T13:46:09.542796050Z,2025-07-17T13:46:09.542961756Z,160,2,1108,A,A,0,15.73,100,130,165706,69578574,ARL,84607837,13.25,11,1,13.67,100,1,12.99,100,1,13.78,2,1,12.88,2,1,13.93,100,1,12.73,100,1,14.2,200,2,12.67,100,1,14.26,700,1,12.47,100,1,14.27,700,1,12.46,100,1,14.28,100,1,12.43,700,1,14.3,200,2,12.42,700,1,14.34,100,1,12.37,700,1,14.36,700,1
2025-07-17T13:46:09.543344724Z,2025-07-17T13:46:09.543510155Z,160,2,1108,C,A,0,17.02,100,0,165431,69578598,ARL,44082969,13.25,11,1,13.67,100,1,12.99,100,1,13.78,2,1,12.88,2,1,13.93,100,1,12.73,100,1,14.2,200,2,12.67,100,1,14.26,700,1,12.47,100,1,14.27,700,1,12.46,100,1,14.28,100,1,12.43,700,1,14.3,200,2,12.42,700,1,14.34,100,1,12.37,700,1,14.36,700,1
2025-07-17T13:46:09.543344724Z,2025-07-17T13:46:09.543510155Z,160,2,1108,A,A,0,17.37,100,130,165431,69578598,ARL,84607861,13.25,11,1,13.67,100,1,12.99,100,1,13.78,2,1,12.88,2,1,13.93,100,1,12.73,100,1,14.2,200,2,12.67,100,1,14.26,700,1,12.47,100,1,14.27,700,1,12.46,100,1,14.28,100,1,12.43,700,1,14.3,200,2,12.42,700,1,14.34,100,1,12.37,700,1,14.36,700,1
2025-07-17T13:46:09.546381306Z,2025-07-17T13:46:09.546546482Z,160,2,1108,C,A,0,14.2,100,130,165176,69578814,ARL,43554141,13.25,11,1,13.67,100,1,12.99,100,1,13.78,2,1,12.88,2,1,13.93,100,1,12.73,100,1,14.2,100,1,12.67,100,1,14.26,700,1,12.47,100,1,14.27,700,1,12.46,100,1,14.28,100,1,12.43,700,1,14.3,200,2,12.42,700,1,14.34,100,1,12.37,700,1,14.36,700,1
2025-07-17T13:46:09.546491223Z,2025-07-17T13:46:09.546656996Z,160,2,1108,A,A,0,14.47,100,130,165773,69578831,ARL,84608321,13.25,11,1,13.67,100,1,12.99,100,1,13.78,2,1,12.88,2,1,13.93,100,1,12.73,100,1,14.2,100,1,12.67,100,1,14.26,700,1,12.47,100,1,14.27,700,1,12.46,100,1,14.28,100,1,12.43,700,1,14.3,200,2,12.42,700,1,14.34,100,1,12.37,700,1,14.36,700,1
2025-07-17T13:46:09.560753276Z,2025-07-17T13:46:09.560918620Z,160,2,1108,C,A,0,13.67,100,130,165344,69579444,ARL,43953649,13.25,11,1,13.78,2,1,12.99,100,1,13.93,100,1,12.88,2,1,14.2,100,1,12.73,100,1,14.26,700,1,12.67,100,1,14.27,700,1,12.47,100,1,14.28,100,1,12.46,100,1,14.3,200,2,12.43,700,1,14.34,100,1,12.42,700,1,14.36,700,1,12.37,700,1,14.46,700,1
2025-07-17T13:46:09.560789009Z,2025-07-17T13:46:09.560953850Z,160,2,1108,C,A,0,14.36,700,130,164841,69579446,ARL,84607761,13.25,11,1,13.78,2,1,12.99,100,1,13.93,100,1,12.88,2,1,14.2,100,1,12.73,100,1,14.26,700,1,12.67,100,1,14.27,700,1,12.47,100,1,14.28,100,1,12.46,100,1,14.3,200,2,12.43,700,1,14.34,100,1,12.42,700,1,14.46,700,1,12.37,700,1,14.47,100,1
2025-07-17T13:46:09.560803559Z,2025-07-17T13:46:09.560968819Z,160,2,1108,A,A,0,13.94,100,130,165260,69579448,ARL,84609305,13.25,11,1,13.78,2,1,12.99,100,1,13.93,100,1,12.88,2,1,13.94,100,1,12.73,100,1,14.2,100,1,12.67,100,1,14.26,700,1,12.47,100,1,14.27,700,1,12.46,100,1,14.28,100,1,12.43,700,1,14.3,200,2,12.42,700,1,14.34,100,1,12.37,700,1,14.46,700,1
2025-07-17T13:46:09.560815603Z,2025-07-17T13:46:09.560981020Z,160,2,1108,C,A,0,14.27,700,130,165417,69579449,ARL,44491681,13.25,11,1,13.78,2,1,12.99,100,1,13.93,100,1,12.88,2,1,13.94,100,1,12.73,100,1,14.2,100,1,12.67,100,1,14.26,700,1,12.47,100,1,14.28,100,1,12.46,100,1,14.3,200,2,12.43,700,1,14.34,100,1,12.42,700,1,14.46,700,1,12.37,700,1,14.47,100,1
2025-07-17T13:46:09.560825413Z,2025-07-17T13:46:09.560990769Z,160,2,1108,A,A,0,15.89,100,130,165356,69579450,ARL,84609309,13.25,11,1,13.78,2,1,12.99,100,1,13.93,100,1,12.88,2,1,13.94,100,1,12.73,100,1,14.2,100,1,12.67,100,1,14.26,700,1,12.47,100,1,14.28,100,1,12.46,100,1,14.3,200,2,12.43,700,1,14.34,100,1,12.42,700,1,14.46,700,1,12.37,700,1,14.47,100,1
2025-07-17T13:46:09.560837771Z,2025-07-17T13:46:09.561002700Z,160,2,1108,C,A,0,15.59,100,130,164929,69579453,ARL,84607765,13.25,11,1,13.78,2,1,12.99,100,1,13.93,100,1,12.88,2,1,13.94,100,1,12.73,100,1,14.2,100,1,12.67,100,1,14.26,700,1,12.47,100,1,14.28,100,1,12.46,100,1,14.3,200,2,12.43,700,1,14.34,100,1,12.42,700,1,14.46,700,1,12.37,700,1,14.47,100,1
2025-07-17T13:46:09.560893546Z,2025-07-17T13:46:09.561059021Z,160,2,1108,A,A,0,14.7,700,130,165475,69579455,ARL,84609321,13.25,11,1,13.78,2,1,12.99,100,1,13.93,100,1,12.88,2,1,13.94,100,1,12.73,100,1,14.2,100,1,12.67,100,1,14.26,700,1,12.47,100,1,14.28,100,1,12.46,100,1,14.3,200,2,12.43,700,1,14.34,100,1,12.42,700,1,14.46,700,1,12.37,700,1,14.47,100,1
2025-07-17T13:46:09.561543868Z,2025-07-17T13:46:09.561710911Z,160,2,1108,C,A,0,14.26,700,128,167043,69579488,ARL,44598153,13.25,11,1,13.78,2,1,12.99,100,1,13.93,100,1,12.88,2,1,13.94,100,1,12.73,100,1,14.2,100,1,12.67,100,1,14.28,100,1,12.47,100,1,14.3,200,2,12.46,100,1,14.34,100,1,12.43,700,1,14.46,700,1,12.42,700,1,14.47,100,1,12.37,700,1,14.49,100,1
2025-07-17T13:46:09.561788417Z,2025-07-17T13:46:09.561954989Z,160,2,1108,C,A,0,15.04,100,0,166572,69579536,ARL,84607805,13.25,11,1,13.78,2,1,12.99,100,1,13.93,100,1,12.88,2,1,13.94,100,1,12.73,100,1,14.2,100,1,12.67,100,1,14.28,100,1,12.47,100,1,14.3,200,2,12.46,100,1,14.34,100,1,12.43,700,1,14.46,700,1,12.42,700,1,14.47,100,1,12.37,700,1,14.49,100,1
2025-07-17T13:46:09.561788417Z,2025-07-17T13:46:09.561954989Z,160,2,1108,A,A,0,15.33,100,0,166572,69579536,ARL,84609385,13.25,11,1,13.78,2,1,12.99,100,1,13.93,100,1,12.88,2,1,13.94,100,1,12.73,100,1,14.2,100,1,12.67,100,1,14.28,100,1,12.47,100,1,14.3,200,2,12.46,100,1,14.34,100,1,12.43,700,1,14.46,700,1,12.42,700,1,14.47,100,1,12.37,700,1,14.49,100,1
2025-07-17T13:46:09.561788902Z,2025-07-17T13:46:09.561954989Z,160,2,1108,C,A,0,14.63,100,0,166087,69579537,ARL,84607801,13.25,11,1,13.78,2,1,12.99,100,1,13.93,100,1,12.88,2,1,13.94,100,1,12.73,100,1,14.2,100,1,12.67,100,1,14.28,100,1,12.47,100,1,14.3,200,2,12.46,100,1,14.34,100,1,12.43,700,1,14.46,700,1,12.42,700,1,14.47,100,1,12.37,700,1,14.49,100,1
2025-07-17T13:46:09.561788902Z,2025-07-17T13:46:09.561954989Z,160,2,1108,A,A,0,14.91,100,130,166087,69579537,ARL,84609389,13.25,11,1,13.78,2,1,12.99,100,1,13.93,100,1,12.88,2,1,13.94,100,1,12.73,100,1,14.2,100,1,12.67,100,1,14.28,100,1,12.47,100,1,14.3,200,2,12.46,100,1,14.34,100,1,12.43,700,1,14.46,700,1,12.42,700,1,14.47,100,1,12.37,700,1,14.49,100,1
2025-07-17T13:46:09.561992206Z,2025-07-17T13:46:09.562157451Z,160,2,1108,A,A,0,14.67,700,130,165245,69579579,ARL,84609409,13.25,11,1,13.78,2,1,12.99,100,1,13.93,100,1,12.88,2,1,13.94,100,1,12.73,100,1,14.2,100,1,12.67,100,1,14.28,100,1,12.47,100,1,14.3,200,2,12.46,100,1,14.34,100,1,12.43,700,1,14.46,700,1,12.42,700,1,14.47,100,1,12.37,700,1,14.49,100,1
2025-07-17T13:46:09.563617017Z,2025-07-17T13:46:09.563782397Z,160,2,1108,C,A,0,17.37,100,0,165380,69579787,ARL,84607861,13.25,11,1,13.78,2,1,12.99,100,1,13.93,100,1,12.88,2,1,13.94,100,1,12.73,100,1,14.2,100,1,12.67,100,1,14.28,100,1,12.47,100,1,14.3,200,2,12.46,100,1,14.34,100,1,12.43,700,1,14.46,700,1,12.42,700,1,14.47,100,1,12.37,700,1,14.49,100,1
2025-07-17T13:46:09.563617017Z,2025-07-17T13:46:09.563782397Z,160,2,1108,A,A,0,17.7,100,130,165380,69579787,ARL,84609557,13.25,11,1,13.78,2,1,12.99,100,1,13.93,100,1,12.88,2,1,13.94,100,1,12.73,100,1,14.2,100,1,12.67,100,1,14.28,100,1,12.47,100,1,14.3,200,2,12.46,100,1,14.34,100,1,12.43,700,1,14.46,700,1,12.42,700,1,14.47,100,1,12.37,700,1,14.49,100,1
2025-07-17T13:46:09.565213822Z,2025-07-17T13:46:09.565379544Z,160,2,1108,C,A,0,13.78,2,0,165722,69579892,ARL,58709197,13.25,11,1,13.93,100,1,12.99,100,1,13.94,100,1,12.88,2,1,14.2,100,1,12.73,100,1,14.28,100,1,12.67,100,1,14.3,200,2,12.47,100,1,14.34,100,1,12.46,100,1,14.46,700,1,12.43,700,1,14.47,100,1,12.42,700,1,14.49,100,1,12.37,700,1,14.67,700,1
2025-07-17T13:46:09.565213822Z,2025-07-17T13:46:09.565379544Z,160,2,1108,A,A,0,13.93,2,130,165722,69579892,ARL,84609637,13.25,11,1,13.93,102,2,12.99,100,1,13.94,100,1,12.88,2,1,14.2,100,1,12.73,100,1,14.28,100,1,12.67,100,1,14.3,200,2,12.47,100,1,14.34,100,1,12.46,100,1,14.46,700,1,12.43,700,1,14.47,100,1,12.42,700,1,14.49,100,1,12.37,700,1,14.67,700,1
2025-07-17T13:46:09.565237899Z,2025-07-17T13:46:09.565403598Z,160,2,1108,C,A,0,15.73,100,0,165699,69579893,ARL,84607837,13.25,11,1,13.93,102,2,12.99,100,1,13.94,100,1,12.88,2,1,14.2,100,1,12.73,100,1,14.28,100,1,12.67,100,1,14.3,200,2,12.47,100,1,14.34,100,1,12.46,100,1,14.46,700,1,12.43,700,1,14.47,100,1,12.42,700,1,14.49,100,1,12.37,700,1,14.67,700,1
2025-07-17T13:46:09.565237899Z,2025-07-17T13:46:09.565403598Z,160,2,1108,A,A,0,16.02,100,130,165699,69579893,ARL,84609645,13.25,11,1,13.93,102,2,12.99,100,1,13.94,100,1,12.88,2,1,14.2,100,1,12.73,100,1,14.28,100,1,12.67,100,1,14.3,200,2,12.47,100,1,14.34,100,1,12.46,100,1,14.46,700,1,12.43,700,1,14.47,100,1,12.42,700,1,14.49,100,1,12.37,700,1,14.67,700,1
2025-07-17T13:46:09.566522227Z,2025-07-17T13:46:09.566687064Z,160,2,1108,C,A,0,13.94,100,130,164837,69579922,ARL,84609305,13.25,11,1,13.93,102,2,12.99,100,1,14.2,100,1,12.88,2,1,14.28,100,1,12.73,100,1,14.3,200,2,12.67,100,1,14.34,100,1,12.47,100,1,14.46,700,1,12.46,100,1,14.47,100,1,12.43,700,1,14.49,100,1,12.42,700,1,14.67,700,1,12.37,700,1,14.7,700,1
2025-07-17T13:46:09.566571131Z,2025-07-17T13:46:09.566736503Z,160,2,1108,A,A,0,14.21,100,130,165372,69579923,ARL,84609733,13.25,11,1,13.93,102,2,12.99,100,1,14.2,100,1,12.88,2,1,14.21,100,1,12.73,100,1,14.28,100,1,12.67,100,1,14.3,200,2,12.47,100,1,14.34,100,1,12.46,100,1,14.46,700,1,12.43,700,1,14.47,100,1,12.42,700,1,14.49,100,1,12.37,700,1,14.67,700,1
2025-07-17T13:46:09.583569619Z,2025-07-17T13:46:09.583735074Z,160,2,1108,C,A,0,14.74,100,0,165455,69580598,ARL,43852129,13.25,11,1,13.93,102,2,12.99,100,1,14.2,100,1,12.88,2,1,14.21,100,1,12.73,100,1,14.28,100,1,12.67,100,1,14.3,200,2,12.47,100,1,14.34,100,1,12.46,100,1,14.46,700,1,12.43,700,1,14.47,100,1,12.42,700,1,14.49,100,1,12.37,700,1,14.67,700,1
2025-07-17T13:46:09.583569619Z,2025-07-17T13:46:09.583735074Z,160,2,1108,A,A,0,15.33,100,130,165455,69580598,ARL,84611025,13.25,11,1,13.93,102,2,12.99,100,1,14.2,100,1,12.88,2,1,14.21,100,1,12.73,100,1,14.28,100,1,12.67,100,1,14.3,200,2,12.47,100,1,14.34,100,1,12.46,100,1,14.46,700,1,12.43,700,1,14.47,100,1,12.42,700,1,14.49,100,1,12.37,700,1,14.67,700,1
2025-07-17T13:46:09.591386919Z,2025-07-17T13:46:09.591552337Z,160,2,1108,C,A,0,14.49,100,0,165418,69581249,ARL,84607785,13.25,11,1,13.93,102,2,12.99,100,1,14.2,100,1,12.88,2,1,14.21,100,1,12.73,100,1,14.28,100,1,12.67,100,1,14.3,200,2,12.47,100,1,14.34,100,1,12.46,100,1,14.46,700,1,12.43,700,1,14.47,100,1,12.42,700,1,14.67,700,1,12.37,700,1,14.7,700,1
2025-07-17T13:46:09.591386919Z,2025-07-17T13:46:09.591552337Z,160,2,1108,A,A,0,15.01,100,130,165418,69581249,ARL,84611613,13.25,11,1,13.93,102,2,12.99,100,1,14.2,100,1,12.88,2,1,14.21,100,1,12.73,100,1,14.28,100,1,12.67,100,1,14.3,200,2,12.47,100,1,14.34,100,1,12.46,100,1,14.46,700,1,12.43,700,1,14.47,100,1,12.42,700,1,14.67,700,1,12.37,700,1,14.7,700,1
2025-07-17T13:46:09.595500037Z,2025-07-17T13:46:09.595667047Z,160,2,1108,A,A,0,14.63,700,128,167010,69582059,ARL,84612081,13.25,11,1,13.93,102,2,12.99,100,1,14.2,100,1,12.88,2,1,14.21,100,1,12.73,100,1,14.28,100,1,12.67,100,1,14.3,200,2,12.47,100,1,14.34,100,1,12.46,100,1,14.46,700,1,12.43,700,1,14.47,100,1,12.42,700,1,14.63,700,1,12.37,700,1,14.67,700,1
2025-07-17T13:46:09.610126066Z,2025-07-17T13:46:09.610291566Z,160,2,1108,C,A,0,14.34,100,0,165500,69582709,ARL,44088637,13.25,11,1,13.93,102,2,12.99,100,1,14.2,100,1,12.88,2,1,14.21,100,1,12.73,100,1,14.28,100,1,12.67,100,1,14.3,200,2,12.47,100,1,14.46,700,1,12.46,100,1,14.47,100,1,12.43,700,1,14.63,700,1,12.42,700,1,14.67,700,1,12.37,700,1,14.7,700,1
2025-07-17T13:46:09.610126066Z,2025-07-17T13:46:09.610291566Z,160,2,1108,A,A,0,14.91,100,130,165500,69582709,ARL,84612773,13.25,11,1,13.93,102,2,12.99,100,1,14.2,100,1,12.88,2,1,14.21,100,1,12.73,100,1,14.28,100,1,12.67,100,1,14.3,200,2,12.47,100,1,14.46,700,1,12.46,100,1,14.47,100,1,12.43,700,1,14.63,700,1,12.42,700,1,14.67,700,1,12.37,700,1,14.7,700,1
2025-07-17T13:46:09.812773551Z,2025-07-17T13:46:09.812938843Z,160,2,1108,A,A,0,14.76,100,130,165292,69586965,ARL,84618189,13.25,11,1,13.93,102,2,12.99,100,1,14.2,100,1,12.88,2,1,14.21,100,1,12.73,100,1,14.28,100,1,12.67,100,1,14.3,200,2,12.47,100,1,14.46,700,1,12.46,100,1,14.47,100,1,12.43,700,1,14.63,700,1,12.42,700,1,14.67,700,1,12.37,700,1,14.7,700,1
2025-07-17T13:46:09.812784722Z,2025-07-17T13:46:09.812950020Z,160,2,1108,C,A,0,14.2,100,130,165298,69586966,ARL,43804081,13.25,11,1,13.93,102,2,12.99,100,1,14.21,100,1,12.88,2,1,14.28,100,1,12.73,100,1,14.3,200,2,12.67,100,1,14.46,700,1,12.47,100,1,14.47,100,1,12.46,100,1,14.63,700,1,12.43,700,1,14.67,700,1,12.42,700,1,14.7,700,1,12.37,700,1,14.76,100,1
2025-07-17T13:46:09.936730596Z,2025-07-17T13:46:09.936895839Z,160,2,1108,C,A,0,13.93,100,130,165243,69592193,ARL,44066417,13.25,11,1,13.93,2,1,12.99,100,1,14.21,100,1,12.88,2,1,14.28,100,1,12.73,100,1,14.3,200,2,12.67,100,1,14.46,700,1,12.47,100,1,14.47,100,1,12.46,100,1,14.63,700,1,12.43,700,1,14.67,700,1,12.42,700,1,14.7,700,1,12.37,700,1,14.76,100,1
2025-07-17T13:46:09.936731544Z,2025-07-17T13:46:09.936896832Z,160,2,1108,A,A,0,14.48,100,130,165288,69592194,ARL,84624129,13.25,11,1,13.93,2,1,12.99,100,1,14.21,100,1,12.88,2,1,14.28,100,1,12.73,100,1,14.3,200,2,12.67,100,1,14.46,700,1,12.47,100,1,14.47,100,1,12.46,100,1,14.48,100,1,12.43,700,1,14.63,700,1,12.42,700,1,14.67,700,1,12.37,700,1,14.7,700,1
2025-07-17T13:46:09.937457145Z,2025-07-17T13:46:09.937622396Z,160,2,1108,C,A,0,15.01,100,0,165251,69592231,ARL,84611613,13.25,11,1,13.93,2,1,12.99,100,1,14.21,100,1,12.88,2,1,14.28,100,1,12.73,100,1,14.3,200,2,12.67,100,1,14.46,700,1,12.47,100,1,14.47,100,1,12.46,100,1,14.48,100,1,12.43,700,1,14.63,700,1,12.42,700,1,14.67,700,1,12.37,700,1,14.7,700,1
2025-07-17T13:46:09.937457145Z,2025-07-17T13:46:09.937622396Z,160,2,1108,A,A,0,15.06,100,130,165251,69592231,ARL,84624201,13.25,11,1,13.93,2,1,12.99,100,1,14.21,100,1,12.88,2,1,14.28,100,1,12.73,100,1,14.3,200,2,12.67,100,1,14.46,700,1,12.47,100,1,14.47,100,1,12.46,100,1,14.48,100,1,12.43,700,1,14.63,700,1,12.42,700,1,14.67,700,1,12.37,700,1,14.7,700,1
2025-07-17T13:46:10.046795728Z,2025-07-17T13:46:10.046960966Z,160,2,1108,C,A,0,14.7,700,130,165238,69596523,ARL,84609321,13.25,11,1,13.93,2,1,12.99,100,1,14.21,100,1,12.88,2,1,14.28,100,1,12.73,100,1,14.3,200,2,12.67,100,1,14.46,700,1,12.47,100,1,14.47,100,1,12.46,100,1,14.48,100,1,12.43,700,1,14.63,700,1,12.42,700,1,14.67,700,1,12.37,700,1,14.76,100,1
2025-07-17T13:46:10.046796743Z,2025-07-17T13:46:10.046962793Z,160,2,1108,C,A,0,14.63,700,130,166050,69596524,ARL,84612081,13.25,11,1,13.93,2,1,12.99,100,1,14.21,100,1,12.88,2,1,14.28,100,1,12.73,100,1,14.3,200,2,12.67,100,1,14.46,700,1,12.47,100,1,14.47,100,1,12.46,100,1,14.48,100,1,12.43,700,1,14.67,700,1,12.42,700,1,14.76,100,1,12.37,700,1,14.91,200,2
2025-07-17T13:46:10.046834863Z,2025-07-17T13:46:10.047001176Z,160,2,1108,A,A,0,14.99,700,0,166313,69596525,ARL,84628757,13.25,11,1,13.93,2,1,12.99,100,1,14.21,100,1,12.88,2,1,14.28,100,1,12.73,100,1,14.3,200,2,12.67,100,1,14.46,700,1,12.47,100,1,14.47,100,1,12.46,100,1,14.48,100,1,12.43,700,1,14.67,700,1,12.42,700,1,14.76,100,1,12.37,700,1,14.91,200,2
2025-07-17T13:46:10.046835277Z,2025-07-17T13:46:10.047001176Z,160,2,1108,A,A,0,14.91,700,130,165899,69596526,ARL,84628761,13.25,11,1,13.93,2,1,12.99,100,1,14.21,100,1,12.88,2,1,14.28,100,1,12.73,100,1,14.3,200,2,12.67,100,1,14.46,700,1,12.47,100,1,14.47,100,1,12.46,100,1,14.48,100,1,12.43,700,1,14.67,700,1,12.42,700,1,14.76,100,1,12.37,700,1,14.91,900,3
2025-07-17T13:46:10.046864551Z,2025-07-17T13:46:10.047030471Z,160,2,1108,A,A,0,16.2,100,130,165920,69596527,ARL,84628765,13.25,11,1,13.93,2,1,12.99,100,1,14.21,100,1,12.88,2,1,14.28,100,1,12.73,100,1,14.3,200,2,12.67,100,1,14.46,700,1,12.47,100,1,14.47,100,1,12.46,100,1,14.48,100,1,12.43,700,1,14.67,700,1,12.42,700,1,14.76,100,1,12.37,700,1,14.91,900,3
2025-07-17T13:46:10.046877789Z,2025-07-17T13:46:10.047042954Z,160,2,1108,C,A,0,15.89,100,130,165165,69596529,ARL,84609309,13.25,11,1,13.93,2,1,12.99,100,1,14.21,100,1,12.88,2,1,14.28,100,1,12.73,100,1,14.3,200,2,12.67,100,1,14.46,700,1,12.47,100,1,14.47,100,1,12.46,100,1,14.48,100,1,12.43,700,1,14.67,700,1,12.42,700,1,14.76,100,1,12.37,700,1,14.91,900,3
2025-07-17T13:46:10.046924268Z,2025-07-17T13:46:10.047089640Z,160,2,1108,C,A,0,13.93,2,0,165372,69596531,ARL,84609637,13.25,11,1,14.21,100,1,12.99,100,1,14.28,100,1,12.88,2,1,14.3,200,2,12.73,100,1,14.46,700,1,12.67,100,1,14.47,100,1,12.47,100,1,14.48,100,1,12.46,100,1,14.67,700,1,12.43,700,1,14.76,100,1,12.42,700,1,14.91,900,3,12.37,700,1,14.99,700,1
2025-07-17T13:46:10.046924268Z,2025-07-17T13:46:10.047089640Z,160,2,1108,A,A,0,14.2,2,130,165372,69596531,ARL,84628773,13.25,11,1,14.2,2,1,12.99,100,1,14.21,100,1,12.88,2,1,14.28,100,1,12.73,100,1,14.3,200,2,12.67,100,1,14.46,700,1,12.47,100,1,14.47,100,1,12.46,100,1,14.48,100,1,12.43,700,1,14.67,700,1,12.42,700,1,14.76,100,1,12.37,700,1,14.91,900,3
2025-07-17T13:46:10.047264301Z,2025-07-17T13:46:10.047429477Z,160,2,1108,C,A,0,14.28,100,130,165176,69596542,ARL,84607809,13.25,11,1,14.2,2,1,12.99,100,1,14.21,100,1,12.88,2,1,14.3,200,2,12.73,100,1,14.46,700,1,12.67,100,1,14.47,100,1,12.47,100,1,14.48,100,1,12.46,100,1,14.67,700,1,12.43,700,1,14.76,100,1,12.42,700,1,14.91,900,3,12.37,700,1,14.99,700,1
2025-07-17T13:46:10.047313929Z,2025-07-17T13:46:10.047479201Z,160,2,1108,C,A,0,14.67,700,130,165272,69596543,ARL,84609409,13.25,11,1,14.2,2,1,12.99,100,1,14.21,100,1,12.88,2,1,14.3,200,2,12.73,100,1,14.46,700,1,12.67,100,1,14.47,100,1,12.47,100,1,14.48,100,1,12.46,100,1,14.76,100,1,12.43,700,1,14.91,900,3,12.42,700,1,14.99,700,1,12.37,700,1,15.06,100,1
2025-07-17T13:46:10.047618250Z,2025-07-17T13:46:10.047784342Z,160,2,1108,A,A,0,14.83,100,128,166092,69596548,ARL,84628793,13.25,11,1,14.2,2,1,12.99,100,1,14.21,100,1,12.88,2,1,14.3,200,2,12.73,100,1,14.46,700,1,12.67,100,1,14.47,100,1,12.47,100,1,14.48,100,1,12.46,100,1,14.76,100,1,12.43,700,1,14.83,100,1,12.42,700,1,14.91,900,3,12.37,700,1,14.99,700,1
2025-07-17T13:46:10.047640842Z,2025-07-17T13:46:10.047806230Z,160,2,1108,C,A,0,14.46,700,130,165388,69596550,ARL,44548325,13.25,11,1,14.2,2,1,12.99,100,1,14.21,100,1,12.88,2,1,14.3,200,2,12.73,100,1,14.47,100,1,12.67,100,1,14.48,100,1,12.47,100,1,14.76,100,1,12.46,100,1,14.83,100,1,12.43,700,1,14.91,900,3,12.42,700,1,14.99,700,1,12.37,700,1,15.06,100,1
2025-07-17T13:46:10.047719954Z,2025-07-17T13:46:10.047885265Z,160,2,1108,A,A,0,14.95,700,130,165311,69596551,ARL,84628797,13.25,11,1,14.2,2,1,12.99,100,1,14.21,100,1,12.88,2,1,14.3,200,2,12.73,100,1,14.47,100,1,12.67,100,1,14.48,100,1,12.47,100,1,14.76,100,1,12.46,100,1,14.83,100,1,12.43,700,1,14.91,900,3,12.42,700,1,14.95,700,1,12.37,700,1,14.99,700,1
2025-07-17T13:46:10.047763743Z,2025-07-17T13:46:10.047929072Z,160,2,1108,C,A,0,14.91,100,0,165329,69596552,ARL,84609389,13.25,11,1,14.2,2,1,12.99,100,1,14.21,100,1,12.88,2,1,14.3,200,2,12.73,100,1,14.47,100,1,12.67,100,1,14.48,100,1,12.47,100,1,14.76,100,1,12.46,100,1,14.83,100,1,12.43,700,1,14.91,800,2,12.42,700,1,14.95,700,1,12.37,700,1,14.99,700,1
2025-07-17T13:46:10.047763743Z,2025-07-17T13:46:10.047929072Z,160,2,1108,A,A,0,15.2,100,130,165329,69596552,ARL,84628801,13.25,11,1,14.2,2,1,12.99,100,1,14.21,100,1,12.88,2,1,14.3,200,2,12.73,100,1,14.47,100,1,12.67,100,1,14.48,100,1,12.47,100,1,14.76,100,1,12.46,100,1,14.83,100,1,12.43,700,1,14.91,800,2,12.42,700,1,14.95,700,1,12.37,700,1,14.99,700,1
2025-07-17T13:46:10.047817649Z,2025-07-17T13:46:10.047983286Z,160,2,1108,C,A,0,15.06,100,0,165637,69596553,ARL,84624201,13.25,11,1,14.2,2,1,12.99,100,1,14.21,100,1,12.88,2,1,14.3,200,2,12.73,100,1,14.47,100,1,12.67,100,1,14.48,100,1,12.47,100,1,14.76,100,1,12.46,100,1,14.83,100,1,12.43,700,1,14.91,800,2,12.42,700,1,14.95,700,1,12.37,700,1,14.99,700,1
2025-07-17T13:46:10.047817649Z,2025-07-17T13:46:10.047983286Z,160,2,1108,A,A,0,15.3,100,130,165637,69596553,ARL,84628813,13.25,11,1,14.2,2,1,12.99,100,1,14.21,100,1,12.88,2,1,14.3,200,2,12.73,100,1,14.47,100,1,12.67,100,1,14.48,100,1,12.47,100,1,14.76,100,1,12.46,100,1,14.83,100,1,12.43,700,1,14.91,800,2,12.42,700,1,14.95,700,1,12.37,700,1,14.99,700,1
2025-07-17T13:46:10.048363798Z,2025-07-17T13:46:10.048529147Z,160,2,1108,A,A,0,15.14,700,130,165349,69596568,ARL,84628829,13.25,11,1,14.2,2,1,12.99,100,1,14.21,100,1,12.88,2,1,14.3,200,2,12.73,100,1,14.47,100,1,12.67,100,1,14.48,100,1,12.47,100,1,14.76,100,1,12.46,100,1,14.83,100,1,12.43,700,1,14.91,800,2,12.42,700,1,14.95,700,1,12.37,700,1,14.99,700,1
2025-07-17T13:46:10.048674815Z,2025-07-17T13:46:10.048840949Z,160,2,1108,C,A,0,15.33,100,0,166134,69596577,ARL,84609385,13.25,11,1,14.2,2,1,12.99,100,1,14.21,100,1,12.88,2,1,14.3,200,2,12.73,100,1,14.47,100,1,12.67,100,1,14.48,100,1,12.47,100,1,14.76,100,1,12.46,100,1,14.83,100,1,12.43,700,1,14.91,800,2,12.42,700,1,14.95,700,1,12.37,700,1,14.99,700,1
2025-07-17T13:46:10.048674815Z,2025-07-17T13:46:10.048840949Z,160,2,1108,A,A,0,15.64,100,130,166134,69596577,ARL,84628833,13.25,11,1,14.2,2,1,12.99,100,1,14.21,100,1,12.88,2,1,14.3,200,2,12.73,100,1,14.47,100,1,12.67,100,1,14.48,100,1,12.47,100,1,14.76,100,1,12.46,100,1,14.83,100,1,12.43,700,1,14.91,800,2,12.42,700,1,14.95,700,1,12.37,700,1,14.99,700,1
2025-07-17T13:46:10.051769303Z,2025-07-17T13:46:10.051935025Z,160,2,1108,C,A,0,17.7,100,0,165722,69596649,ARL,84609557,13.25,11,1,14.2,2,1,12.99,100,1,14.21,100,1,12.88,2,1,14.3,200,2,12.73,100,1,14.47,100,1,12.67,100,1,14.48,100,1,12.47,100,1,14.76,100,1,12.46,100,1,14.83,100,1,12.43,700,1,14.91,800,2,12.42,700,1,14.95,700,1,12.37,700,1,14.99,700,1
2025-07-17T13:46:10.051769303Z,2025-07-17T13:46:10.051935025Z,160,2,1108,A,A,0,18.05,100,130,165722,69596649,ARL,84628913,13.25,11,1,14.2,2,1,12.99,100,1,14.21,100,1,12.88,2,1,14.3,200,2,12.73,100,1,14.47,100,1,12.67,100,1,14.48,100,1,12.47,100,1,14.76,100,1,12.46,100,1,14.83,100,1,12.43,700,1,14.91,800,2,12.42,700,1,14.95,700,1,12.37,700,1,14.99,700,1
2025-07-17T13:46:10.054167322Z,2025-07-17T13:46:10.054332558Z,160,2,1108,C,A,0,16.02,100,0,165236,69596777,ARL,84609645,13.25,11,1,14.2,2,1,12.99,100,1,14.21,100,1,12.88,2,1,14.3,200,2,12.73,100,1,14.47,100,1,12.67,100,1,14.48,100,1,12.47,100,1,14.76,100,1,12.46,100,1,14.83,100,1,12.43,700,1,14.91,800,2,12.42,700,1,14.95,700,1,12.37,700,1,14.99,700,1
2025-07-17T13:46:10.054167322Z,2025-07-17T13:46:10.054332558Z,160,2,1108,A,A,0,16.35,100,130,165236,69596777,ARL,84629065,13.25,11,1,14.2,2,1,12.99,100,1,14.21,100,1,12.88,2,1,14.3,200,2,12.73,100,1,14.47,100,1,12.67,100,1,14.48,100,1,12.47,100,1,14.76,100,1,12.46,100,1,14.83,100,1,12.43,700,1,14.91,800,2,12.42,700,1,14.95,700,1,12.37,700,1,14.99,700,1
2025-07-17T13:46:10.055269067Z,2025-07-17T13:46:10.055434148Z,160,2,1108,C,A,0,14.21,100,130,165081,69596798,ARL,84609733,13.25,11,1,14.2,2,1,12.99,100,1,14.3,200,2,12.88,2,1,14.47,100,1,12.73,100,1,14.48,100,1,12.67,100,1,14.76,100,1,12.47,100,1,14.83,100,1,12.46,100,1,14.91,800,2,12.43,700,1,14.95,700,1,12.42,700,1,14.99,700,1,12.37,700,1,15.14,700,1
2025-07-17T13:46:10.055317945Z,2025-07-17T13:46:10.055483249Z,160,2,1108,A,A,0,14.48,100,130,165304,69596799,ARL,84629093,13.25,11,1,14.2,2,1,12.99,100,1,14.3,200,2,12.88,2,1,14.47,100,1,12.73,100,1,14.48,200,2,12.67,100,1,14.76,100,1,12.47,100,1,14.83,100,1,12.46,100,1,14.91,800,2,12.43,700,1,14.95,700,1,12.42,700,1,14.99,700,1,12.37,700,1,15.14,700,1
2025-07-17T13:46:10.061246123Z,2025-07-17T13:46:10.061411059Z,160,2,1108,C,A,0,14.48,100,130,164936,69596987,ARL,84629093,13.25,11,1,14.2,2,1,12.99,100,1,14.3,200,2,12.88,2,1,14.47,100,1,12.73,100,1,14.48,100,1,12.67,100,1,14.76,100,1,12.47,100,1,14.83,100,1,12.46,100,1,14.91,800,2,12.43,700,1,14.95,700,1,12.42,700,1,14.99,700,1,12.37,700,1,15.14,700,1
2025-07-17T13:46:10.061294728Z,2025-07-17T13:46:10.061459915Z,160,2,1108,A,A,0,14.59,100,130,165187,69596990,ARL,84629329,13.25,11,1,14.2,2,1,12.99,100,1,14.3,200,2,12.88,2,1,14.47,100,1,12.73,100,1,14.48,100,1,12.67,100,1,14.59,100,1,12.47,100,1,14.76,100,1,12.46,100,1,14.83,100,1,12.43,700,1,14.91,800,2,12.42,700,1,14.95,700,1,12.37,700,1,14.99,700,1
2025-07-17T13:46:10.087725560Z,2025-07-17T13:46:10.087891846Z,160,2,1108,C,A,0,15.33,100,0,166286,69597697,ARL,84611025,13.25,11,1,14.2,2,1,12.99,100,1,14.3,200,2,12.88,2,1,14.47,100,1,12.73,100,1,14.48,100,1,12.67,100,1,14.59,100,1,12.47,100,1,14.76,100,1,12.46,100,1,14.83,100,1,12.43,700,1,14.91,800,2,12.42,700,1,14.95,700,1,12.37,700,1,14.99,700,1
2025-07-17T13:46:10.087725560Z,2025-07-17T13:46:10.087891846Z,160,2,1108,A,A,0,15.73,100,128,166286,69597697,ARL,84629953,13.25,11,1,14.2,2,1,12.99,100,1,14.3,200,2,12.88,2,1,14.47,100,1,12.73,100,1,14.48,100,1,12.67,100,1,14.59,100,1,12.47,100,1,14.76,100,1,12.46,100,1,14.83,100,1,12.43,700,1,14.91,800,2,12.42,700,1,14.95,700,1,12.37,700,1,14.99,700,1
2025-07-17T13:46:10.098029439Z,2025-07-17T13:46:10.098194757Z,160,2,1108,C,A,0,15.3,100,0,165318,69597813,ARL,84628813,13.25,11,1,14.2,2,1,12.99,100,1,14.3,200,2,12.88,2,1,14.47,100,1,12.73,100,1,14.48,100,1,12.67,100,1,14.59,100,1,12.47,100,1,14.76,100,1,12.46,100,1,14.83,100,1,12.43,700,1,14.91,800,2,12.42,700,1,14.95,700,1,12.37,700,1,14.99,700,1
2025-07-17T13:46:10.098029439Z,2025-07-17T13:46:10.098194757Z,160,2,1108,A,A,0,15.41,100,130,165318,69597813,ARL,84630217,13.25,11,1,14.2,2,1,12.99,100,1,14.3,200,2,12.88,2,1,14.47,100,1,12.73,100,1,14.48,100,1,12.67,100,1,14.59,100,1,12.47,100,1,14.76,100,1,12.46,100,1,14.83,100,1,12.43,700,1,14.91,800,2,12.42,700,1,14.95,700,1,12.37,700,1,14.99,700,1
2025-07-17T13:46:10.109069598Z,2025-07-17T13:46:10.109235050Z,160,2,1108,C,A,0,14.91,100,0,165452,69598154,ARL,84612773,13.25,11,1,14.2,2,1,12.99,100,1,14.3,200,2,12.88,2,1,14.47,100,1,12.73,100,1,14.48,100,1,12.67,100,1,14.59,100,1,12.47,100,1,14.76,100,1,12.46,100,1,14.83,100,1,12.43,700,1,14.91,700,1,12.42,700,1,14.95,700,1,12.37,700,1,14.99,700,1
2025-07-17T13:46:10.109069598Z,2025-07-17T13:46:10.109235050Z,160,2,1108,A,A,0,15.31,100,130,165452,69598154,ARL,84630849,13.25,11,1,14.2,2,1,12.99,100,1,14.3,200,2,12.88,2,1,14.47,100,1,12.73,100,1,14.48,100,1,12.67,100,1,14.59,100,1,12.47,100,1,14.76,100,1,12.46,100,1,14.83,100,1,12.43,700,1,14.91,700,1,12.42,700,1,14.95,700,1,12.37,700,1,14.99,700,1
2025-07-17T13:46:10.551316402Z,2025-07-17T13:46:10.551481906Z,160,2,1108,C,A,0,14.47,100,0,165504,69614455,ARL,84608321,13.25,11,1,14.2,2,1,12.99,100,1,14.3,200,2,12.88,2,1,14.48,100,1,12.73,100,1,14.59,100,1,12.67,100,1,14.76,100,1,12.47,100,1,14.83,100,1,12.46,100,1,14.91,700,1,12.43,700,1,14.95,700,1,12.42,700,1,14.99,700,1,12.37,700,1,15.14,700,1
2025-07-17T13:46:10.551316402Z,2025-07-17T13:46:10.551481906Z,160,2,1108,A,A,0,15.09,100,130,165504,69614455,ARL,84650629,13.25,11,1,14.2,2,1,12.99,100,1,14.3,200,2,12.88,2,1,14.48,100,1,12.73,100,1,14.59,100,1,12.67,100,1,14.76,100,1,12.47,100,1,14.83,100,1,12.46,100,1,14.91,700,1,12.43,700,1,14.95,700,1,12.42,700,1,14.99,700,1,12.37,700,1,15.09,100,1
2025-07-17T13:46:10.904672934Z,2025-07-17T13:46:10.904838107Z,160,2,1108,A,A,0,15.16,100,130,165173,69628781,ARL,84668677,13.25,11,1,14.2,2,1,12.99,100,1,14.3,200,2,12.88,2,1,14.48,100,1,12.73,100,1,14.59,100,1,12.67,100,1,14.76,100,1,12.47,100,1,14.83,100,1,12.46,100,1,14.91,700,1,12.43,700,1,14.95,700,1,12.42,700,1,14.99,700,1,12.37,700,1,15.09,100,1
2025-07-17T13:46:10.904693578Z,2025-07-17T13:46:10.904858553Z,160,2,1108,C,A,0,14.76,100,130,164975,69628783,ARL,84618189,13.25,11,1,14.2,2,1,12.99,100,1,14.3,200,2,12.88,2,1,14.48,100,1,12.73,100,1,14.59,100,1,12.67,100,1,14.83,100,1,12.47,100,1,14.91,700,1,12.46,100,1,14.95,700,1,12.43,700,1,14.99,700,1,12.42,700,1,15.09,100,1,12.37,700,1,15.14,700,1
2025-07-17T13:46:11.840717150Z,2025-07-17T13:46:11.840882444Z,160,2,1108,A,A,0,14.87,100,130,165294,69663346,ARL,84708037,13.25,11,1,14.2,2,1,12.99,100,1,14.3,200,2,12.88,2,1,14.48,100,1,12.73,100,1,14.59,100,1,12.67,100,1,14.83,100,1,12.47,100,1,14.87,100,1,12.46,100,1,14.91,700,1,12.43,700,1,14.95,700,1,12.42,700,1,14.99,700,1,12.37,700,1,15.09,100,1
2025-07-17T13:46:11.840729407Z,2025-07-17T13:46:11.840894787Z,160,2,1108,C,A,0,14.48,100,130,165380,69663347,ARL,84624129,13.25,11,1,14.2,2,1,12.99,100,1,14.3,200,2,12.88,2,1,14.59,100,1,12.73,100,1,14.83,100,1,12.67,100,1,14.87,100,1,12.47,100,1,14.91,700,1,12.46,100,1,14.95,700,1,12.43,700,1,14.99,700,1,12.42,700,1,15.09,100,1,12.37,700,1,15.14,700,1
2025-07-17T13:46:23.920647302Z,2025-07-17T13:46:23.920813185Z,160,2,1108,C,B,0,12.88,2,0,165883,70104076,ARL,58709193,13.25,11,1,14.2,2,1,12.99,100,1,14.3,200,2,12.73,100,1,14.59,100,1,12.67,100,1,14.83,100,1,12.47,100,1,14.87,100,1,12.46,100,1,14.91,700,1,12.43,700,1,14.95,700,1,12.42,700,1,14.99,700,1,12.37,700,1,15.09,100,1,12.36,200,2,15.14,700,1
2025-07-17T13:46:23.920647302Z,2025-07-17T13:46:23.920813185Z,160,2,1108,A,B,0,13.12,2,130,165883,70104076,ARL,85194077,13.25,11,1,14.2,2,1,13.12,2,1,14.3,200,2,12.99,100,1,14.59,100,1,12.73,100,1,14.83,100,1,12.67,100,1,14.87,100,1,12.47,100,1,14.91,700,1,12.46,100,1,14.95,700,1,12.43,700,1,14.99,700,1,12.42,700,1,15.09,100,1,12.37,700,1,15.14,700,1
2025-07-17T13:46:45.786413307Z,2025-07-17T13:46:45.786579604Z,160,2,1108,C,B,0,13.12,2,0,166297,70834235,ARL,85194077,13.25,11,1,14.2,2,1,12.99,100,1,14.3,200,2,12.73,100,1,14.59,100,1,12.67,100,1,14.83,100,1,12.47,100,1,14.87,100,1,12.46,100,1,14.91,700,1,12.43,700,1,14.95,700,1,12.42,700,1,14.99,700,1,12.37,700,1,15.09,100,1,12.36,200,2,15.14,700,1
2025-07-17T13:46:45.786413307Z,2025-07-17T13:46:45.786579604Z,160,2,1108,A,B,0,13.2,2,130,166297,70834235,ARL,86056033,13.25,11,1,14.2,2,1,13.2,2,1,14.3,200,2,12.99,100,1,14.59,100,1,12.73,100,1,14.83,100,1,12.67,100,1,14.87,100,1,12.47,100,1,14.91,700,1,12.46,100,1,14.95,700,1,12.43,700,1,14.99,700,1,12.42,700,1,15.09,100,1,12.37,700,1,15.14,700,1
2025-07-17T13:47:34.987001473Z,2025-07-17T13:47:34.987167177Z,160,2,1108,C,B,0,13.2,2,0,165704,72269967,ARL,86056033,13.25,11,1,14.2,2,1,12.99,100,1,14.3,200,2,12.73,100,1,14.59,100,1,12.67,100,1,14.83,100,1,12.47,100,1,14.87,100,1,12.46,100,1,14.91,700,1,12.43,700,1,14.95,700,1,12.42,700,1,14.99,700,1,12.37,700,1,15.09,100,1,12.36,200,2,15.14,700,1
2025-07-17T13:47:34.987001473Z,2025-07-17T13:47:34.987167177Z,160,2,1108,A,B,0,13.26,2,130,165704,72269967,ARL,87750309,13.26,2,1,14.2,2,1,13.25,11,1,14.3,200,2,12.99,100,1,14.59,100,1,12.73,100,1,14.83,100,1,12.67,100,1,14.87,100,1,12.47,100,1,14.91,700,1,12.46,100,1,14.95,700,1,12.43,700,1,14.99,700,1,12.42,700,1,15.09,100,1,12.37,700,1,15.14,700,1
2025-07-17T13:49:46.533420775Z,2025-07-17T13:49:46.533586484Z,160,2,1108,C,A,0,14.3,100,0,165709,76393090,ARL,77910357,13.26,2,1,14.2,2,1,13.25,11,1,14.3,100,1,12.99,100,1,14.59,100,1,12.73,100,1,14.83,100,1,12.67,100,1,14.87,100,1,12.47,100,1,14.91,700,1,12.46,100,1,14.95,700,1,12.43,700,1,14.99,700,1,12.42,700,1,15.09,100,1,12.37,700,1,15.14,700,1
2025-07-17T13:49:46.533420775Z,2025-07-17T13:49:46.533586484Z,160,2,1108,A,A,0,15.26,100,130,165709,76393090,ARL,92510725,13.26,2,1,14.2,2,1,13.25,11,1,14.3,100,1,12.99,100,1,14.59,100,1,12.73,100,1,14.83,100,1,12.67,100,1,14.87,100,1,12.47,100,1,14.91,700,1,12.46,100,1,14.95,700,1,12.43,700,1,14.99,700,1,12.42,700,1,15.09,100,1,12.37,700,1,15.14,700,1
2025-07-17T13:49:46.533566805Z,2025-07-17T13:49:46.533732414Z,160,2,1108,C,A,0,14.3,100,0,165609,76393092,ARL,74589605,13.26,2,1,14.2,2,1,13.25,11,1,14.59,100,1,12.99,100,1,14.83,100,1,12.73,100,1,14.87,100,1,12.67,100,1,14.91,700,1,12.47,100,1,14.95,700,1,12.46,100,1,14.99,700,1,12.43,700,1,15.09,100,1,12.42,700,1,15.14,700,1,12.37,700,1,15.16,100,1
2025-07-17T13:49:46.533566805Z,2025-07-17T13:49:46.533732414Z,160,2,1108,A,A,0,15.26,100,130,165609,76393092,ARL,92510729,13.26,2,1,14.2,2,1,13.25,11,1,14.59,100,1,12.99,100,1,14.83,100,1,12.73,100,1,14.87,100,1,12.67,100,1,14.91,700,1,12.47,100,1,14.95,700,1,12.46,100,1,14.99,700,1,12.43,700,1,15.09,100,1,12.42,700,1,15.14,700,1,12.37,700,1,15.16,100,1
2025-07-17T13:49:46.533603070Z,2025-07-17T13:49:46.533768662Z,160,2,1108,C,A,0,14.91,700,130,165592,76393093,ARL,84628761,13.26,2,1,14.2,2,1,13.25,11,1,14.59,100,1,12.99,100,1,14.83,100,1,12.73,100,1,14.87,100,1,12.67,100,1,14.95,700,1,12.47,100,1,14.99,700,1,12.46,100,1,15.09,100,1,12.43,700,1,15.14,700,1,12.42,700,1,15.16,100,1,12.37,700,1,15.2,100,1
2025-07-17T13:49:46.533644528Z,2025-07-17T13:49:46.533810238Z,160,2,1108,A,A,0,15.07,700,130,165710,76393094,ARL,92510741,13.26,2,1,14.2,2,1,13.25,11,1,14.59,100,1,12.99,100,1,14.83,100,1,12.73,100,1,14.87,100,1,12.67,100,1,14.95,700,1,12.47,100,1,14.99,700,1,12.46,100,1,15.07,700,1,12.43,700,1,15.09,100,1,12.42,700,1,15.14,700,1,12.37,700,1,15.16,100,1
2025-07-17T13:49:46.534323177Z,2025-07-17T13:49:46.534488891Z,160,2,1108,C,A,0,15.41,100,0,165714,76393099,ARL,84630217,13.26,2,1,14.2,2,1,13.25,11,1,14.59,100,1,12.99,100,1,14.83,100,1,12.73,100,1,14.87,100,1,12.67,100,1,14.95,700,1,12.47,100,1,14.99,700,1,12.46,100,1,15.07,700,1,12.43,700,1,15.09,100,1,12.42,700,1,15.14,700,1,12.37,700,1,15.16,100,1
2025-07-17T13:49:46.534323177Z,2025-07-17T13:49:46.534488891Z,160,2,1108,A,A,0,15.46,100,130,165714,76393099,ARL,92510753,13.26,2,1,14.2,2,1,13.25,11,1,14.59,100,1,12.99,100,1,14.83,100,1,12.73,100,1,14.87,100,1,12.67,100,1,14.95,700,1,12.47,100,1,14.99,700,1,12.46,100,1,15.07,700,1,12.43,700,1,15.09,100,1,12.42,700,1,15.14,700,1,12.37,700,1,15.16,100,1
2025-07-17T13:49:46.534390219Z,2025-07-17T13:49:46.534555834Z,160,2,1108,C,A,0,15.2,100,0,165615,76393100,ARL,84628801,13.26,2,1,14.2,2,1,13.25,11,1,14.59,100,1,12.99,100,1,14.83,100,1,12.73,100,1,14.87,100,1,12.67,100,1,14.95,700,1,12.47,100,1,14.99,700,1,12.46,100,1,15.07,700,1,12.43,700,1,15.09,100,1,12.42,700,1,15.14,700,1,12.37,700,1,15.16,100,1
2025-07-17T13:49:46.534390219Z,2025-07-17T13:49:46.534555834Z,160,2,1108,A,A,0,15.36,100,130,165615,76393100,ARL,92510761,13.26,2,1,14.2,2,1,13.25,11,1,14.59,100,1,12.99,100,1,14.83,100,1,12.73,100,1,14.87,100,1,12.67,100,1,14.95,700,1,12.47,100,1,14.99,700,1,12.46,100,1,15.07,700,1,12.43,700,1,15.09,100,1,12.42,700,1,15.14,700,1,12.37,700,1,15.16,100,1
2025-07-17T13:49:46.535017084Z,2025-07-17T13:49:46.535182699Z,160,2,1108,C,A,0,16.35,100,0,165615,76393115,ARL,84629065,13.26,2,1,14.2,2,1,13.25,11,1,14.59,100,1,12.99,100,1,14.83,100,1,12.73,100,1,14.87,100,1,12.67,100,1,14.95,700,1,12.47,100,1,14.99,700,1,12.46,100,1,15.07,700,1,12.43,700,1,15.09,100,1,12.42,700,1,15.14,700,1,12.37,700,1,15.16,100,1
2025-07-17T13:49:46.535017084Z,2025-07-17T13:49:46.535182699Z,160,2,1108,A,A,0,16.51,100,130,165615,76393115,ARL,92510813,13.26,2,1,14.2,2,1,13.25,11,1,14.59,100,1,12.99,100,1,14.83,100,1,12.73,100,1,14.87,100,1,12.67,100,1,14.95,700,1,12.47,100,1,14.99,700,1,12.46,100,1,15.07,700,1,12.43,700,1,15.09,100,1,12.42,700,1,15.14,700,1,12.37,700,1,15.16,100,1
2025-07-17T13:49:46.535572067Z,2025-07-17T13:49:46.535737854Z,160,2,1108,C,A,0,18.05,100,0,165787,76393138,ARL,84628913,13.26,2,1,14.2,2,1,13.25,11,1,14.59,100,1,12.99,100,1,14.83,100,1,12.73,100,1,14.87,100,1,12.67,100,1,14.95,700,1,12.47,100,1,14.99,700,1,12.46,100,1,15.07,700,1,12.43,700,1,15.09,100,1,12.42,700,1,15.14,700,1,12.37,700,1,15.16,100,1
