ts_event,ts_recv,r_type,publisher,instrument_id,action,side,depth,price,size,flags,ts_in_delta,sequence,symbol,order_id,bid_px_00,bid_sz_00,bid_ct_00,ask_px_00,ask_sz_00,ask_ct_00,bid_px_01,bid_sz_01,bid_ct_01,ask_px_01,ask_sz_01,ask_ct_01,bid_px_02,bid_sz_02,bid_ct_02,ask_px_02,ask_sz_02,ask_ct_02,bid_px_03,bid_sz_03,bid_ct_03,ask_px_03,ask_sz_03,ask_ct_03,bid_px_04,bid_sz_04,bid_ct_04,ask_px_04,ask_sz_04,ask_ct_04,bid_px_05,bid_sz_05,bid_ct_05,ask_px_05,ask_sz_05,ask_ct_05,bid_px_06,bid_sz_06,bid_ct_06,ask_px_06,ask_sz_06,ask_ct_06,bid_px_07,bid_sz_07,bid_ct_07,ask_px_07,ask_sz_07,ask_ct_07,bid_px_08,bid_sz_08,bid_ct_08,ask_px_08,ask_sz_08,ask_ct_08,bid_px_09,bid_sz_09,bid_ct_09,ask_px_09,ask_sz_09,ask_ct_09
2025-07-17T16:02:43.844636465Z,2025-07-17T16:02:43.844801951Z,160,2,1108,C,A,0,14.81,100,0,165486,272014698,ARL,325718517,13.12,200,2,13.92,2,1,13.11,100,1,13.98,200,2,13.03,100,1,14.12,100,1,13,2,1,14.28,100,1,12.73,100,1,14.45,100,1,12.71,100,1,14.56,800,2,12.5,700,1,14.6,700,1,12.46,200,2,14.63,100,1,12.43,700,1,14.68,1400,2,12.42,700,1,14.73,200,2
2025-07-17T16:02:43.844636465Z,2025-07-17T16:02:43.844801951Z,160,2,1108,A,A,0,14.96,100,130,165486,272014698,ARL,326158997,13.12,200,2,13.92,2,1,13.11,100,1,13.98,200,2,13.03,100,1,14.12,100,1,13,2,1,14.28,100,1,12.73,100,1,14.45,100,1,12.71,100,1,14.56,800,2,12.5,700,1,14.6,700,1,12.46,200,2,14.63,100,1,12.43,700,1,14.68,1400,2,12.42,700,1,14.73,200,2
2025-07-17T16:02:43.846861336Z,2025-07-17T16:02:43.847026795Z,160,2,1108,C,A,0,13.92,2,0,165459,272014713,ARL,325297093,13.12,200,2,13.98,200,2,13.11,100,1,14.12,100,1,13.03,100,1,14.28,100,1,13,2,1,14.45,100,1,12.73,100,1,14.56,800,2,12.71,100,1,14.6,700,1,12.5,700,1,14.63,100,1,12.46,200,2,14.68,1400,2,12.43,700,1,14.73,200,2,12.42,700,1,14.92,100,1
2025-07-17T16:02:43.846861336Z,2025-07-17T16:02:43.847026795Z,160,2,1108,A,A,0,14.03,2,130,165459,272014713,ARL,326159041,13.12,200,2,13.98,200,2,13.11,100,1,14.03,2,1,13.03,100,1,14.12,100,1,13,2,1,14.28,100,1,12.73,100,1,14.45,100,1,12.71,100,1,14.56,800,2,12.5,700,1,14.6,700,1,12.46,200,2,14.63,100,1,12.43,700,1,14.68,1400,2,12.42,700,1,14.73,200,2
2025-07-17T16:02:43.847666979Z,2025-07-17T16:02:43.847832258Z,160,2,1108,C,A,0,14.73,100,0,165279,272014721,ARL,325714613,13.12,200,2,13.98,200,2,13.11,100,1,14.03,2,1,13.03,100,1,14.12,100,1,13,2,1,14.28,100,1,12.73,100,1,14.45,100,1,12.71,100,1,14.56,800,2,12.5,700,1,14.6,700,1,12.46,200,2,14.63,100,1,12.43,700,1,14.68,1400,2,12.42,700,1,14.73,100,1
2025-07-17T16:02:43.847666979Z,2025-07-17T16:02:43.847832258Z,160,2,1108,A,A,0,14.87,100,130,165279,272014721,ARL,326159049,13.12,200,2,13.98,200,2,13.11,100,1,14.03,2,1,13.03,100,1,14.12,100,1,13,2,1,14.28,100,1,12.73,100,1,14.45,100,1,12.71,100,1,14.56,800,2,12.5,700,1,14.6,700,1,12.46,200,2,14.63,100,1,12.43,700,1,14.68,1400,2,12.42,700,1,14.73,100,1
2025-07-17T16:02:43.847981726Z,2025-07-17T16:02:43.848147198Z,160,2,1108,C,A,0,14.73,100,0,165472,272014724,ARL,325714577,13.12,200,2,13.98,200,2,13.11,100,1,14.03,2,1,13.03,100,1,14.12,100,1,13,2,1,14.28,100,1,12.73,100,1,14.45,100,1,12.71,100,1,14.56,800,2,12.5,700,1,14.6,700,1,12.46,200,2,14.63,100,1,12.43,700,1,14.68,1400,2,12.42,700,1,14.87,100,1
2025-07-17T16:02:43.847981726Z,2025-07-17T16:02:43.848147198Z,160,2,1108,A,A,0,14.87,100,130,165472,272014724,ARL,326159061,13.12,200,2,13.98,200,2,13.11,100,1,14.03,2,1,13.03,100,1,14.12,100,1,13,2,1,14.28,100,1,12.73,100,1,14.45,100,1,12.71,100,1,14.56,800,2,12.5,700,1,14.6,700,1,12.46,200,2,14.63,100,1,12.43,700,1,14.68,1400,2,12.42,700,1,14.87,200,2
2025-07-17T16:02:43.860034354Z,2025-07-17T16:02:43.860199647Z,160,2,1108,C,A,0,14.12,100,130,165293,272014788,ARL,325718637,13.12,200,2,13.98,200,2,13.11,100,1,14.03,2,1,13.03,100,1,14.28,100,1,13,2,1,14.45,100,1,12.73,100,1,14.56,800,2,12.71,100,1,14.6,700,1,12.5,700,1,14.63,100,1,12.46,200,2,14.68,1400,2,12.43,700,1,14.87,200,2,12.42,700,1,14.92,100,1
2025-07-17T16:02:43.860087215Z,2025-07-17T16:02:43.860252446Z,160,2,1108,A,A,0,14.26,100,130,165231,272014789,ARL,326159201,13.12,200,2,13.98,200,2,13.11,100,1,14.03,2,1,13.03,100,1,14.26,100,1,13,2,1,14.28,100,1,12.73,100,1,14.45,100,1,12.71,100,1,14.56,800,2,12.5,700,1,14.6,700,1,12.46,200,2,14.63,100,1,12.43,700,1,14.68,1400,2,12.42,700,1,14.87,200,2
2025-07-17T16:02:43.893011012Z,2025-07-17T16:02:43.893176312Z,160,2,1108,C,A,0,14.92,100,0,165300,272014986,ARL,326158869,13.12,200,2,13.98,200,2,13.11,100,1,14.03,2,1,13.03,100,1,14.26,100,1,13,2,1,14.28,100,1,12.73,100,1,14.45,100,1,12.71,100,1,14.56,800,2,12.5,700,1,14.6,700,1,12.46,200,2,14.63,100,1,12.43,700,1,14.68,1400,2,12.42,700,1,14.87,200,2
2025-07-17T16:02:43.893011012Z,2025-07-17T16:02:43.893176312Z,160,2,1108,A,A,0,15.06,100,130,165300,272014986,ARL,326159425,13.12,200,2,13.98,200,2,13.11,100,1,14.03,2,1,13.03,100,1,14.26,100,1,13,2,1,14.28,100,1,12.73,100,1,14.45,100,1,12.71,100,1,14.56,800,2,12.5,700,1,14.6,700,1,12.46,200,2,14.63,100,1,12.43,700,1,14.68,1400,2,12.42,700,1,14.87,200,2
2025-07-17T16:02:43.946801538Z,2025-07-17T16:02:43.946967137Z,160,2,1108,C,A,0,14.63,100,0,165599,272015584,ARL,325714653,13.12,200,2,13.98,200,2,13.11,100,1,14.03,2,1,13.03,100,1,14.26,100,1,13,2,1,14.28,100,1,12.73,100,1,14.45,100,1,12.71,100,1,14.56,800,2,12.5,700,1,14.6,700,1,12.46,200,2,14.68,1400,2,12.43,700,1,14.87,200,2,12.42,700,1,14.96,200,2
2025-07-17T16:02:43.946801538Z,2025-07-17T16:02:43.946967137Z,160,2,1108,A,A,0,14.77,100,130,165599,272015584,ARL,326160141,13.12,200,2,13.98,200,2,13.11,100,1,14.03,2,1,13.03,100,1,14.26,100,1,13,2,1,14.28,100,1,12.73,100,1,14.45,100,1,12.71,100,1,14.56,800,2,12.5,700,1,14.6,700,1,12.46,200,2,14.68,1400,2,12.43,700,1,14.77,100,1,12.42,700,1,14.87,200,2
2025-07-17T16:02:44.664054457Z,2025-07-17T16:02:44.664219784Z,160,2,1108,A,A,0,13.99,100,130,165327,272021808,ARL,326167529,13.12,200,2,13.98,200,2,13.11,100,1,13.99,100,1,13.03,100,1,14.03,2,1,13,2,1,14.26,100,1,12.73,100,1,14.28,100,1,12.71,100,1,14.45,100,1,12.5,700,1,14.56,800,2,12.46,200,2,14.6,700,1,12.43,700,1,14.68,1400,2,12.42,700,1,14.77,100,1
2025-07-17T16:03:02.985818199Z,2025-07-17T16:03:02.985987598Z,160,2,1108,C,A,0,14.87,100,0,169399,272331833,ARL,326159049,13.12,200,2,13.98,200,2,13.11,100,1,13.99,100,1,13.03,100,1,14.03,2,1,13,2,1,14.26,100,1,12.73,100,1,14.28,100,1,12.71,100,1,14.45,100,1,12.5,700,1,14.56,800,2,12.46,200,2,14.6,700,1,12.43,700,1,14.68,1400,2,12.42,700,1,14.77,100,1
2025-07-17T16:03:02.985818199Z,2025-07-17T16:03:02.985987598Z,160,2,1108,A,A,0,14.7,100,128,169399,272331833,ARL,326551237,13.12,200,2,13.98,200,2,13.11,100,1,13.99,100,1,13.03,100,1,14.03,2,1,13,2,1,14.26,100,1,12.73,100,1,14.28,100,1,12.71,100,1,14.45,100,1,12.5,700,1,14.56,800,2,12.46,200,2,14.6,700,1,12.43,700,1,14.68,1400,2,12.42,700,1,14.7,100,1
2025-07-17T16:03:02.987797728Z,2025-07-17T16:03:02.987969729Z,160,2,1108,C,A,0,14.87,100,0,172001,272332718,ARL,326159061,13.12,200,2,13.98,200,2,13.11,100,1,13.99,100,1,13.03,100,1,14.03,2,1,13,2,1,14.26,100,1,12.73,100,1,14.28,100,1,12.71,100,1,14.45,100,1,12.5,700,1,14.56,800,2,12.46,200,2,14.6,700,1,12.43,700,1,14.68,1400,2,12.42,700,1,14.7,100,1
2025-07-17T16:03:02.987797728Z,2025-07-17T16:03:02.987969729Z,160,2,1108,A,A,0,14.7,100,128,172001,272332718,ARL,326551829,13.12,200,2,13.98,200,2,13.11,100,1,13.99,100,1,13.03,100,1,14.03,2,1,13,2,1,14.26,100,1,12.73,100,1,14.28,100,1,12.71,100,1,14.45,100,1,12.5,700,1,14.56,800,2,12.46,200,2,14.6,700,1,12.43,700,1,14.68,1400,2,12.42,700,1,14.7,200,2
2025-07-17T16:03:10.807281669Z,2025-07-17T16:03:10.807446975Z,160,2,1108,A,A,0,13.72,15,130,165306,272474575,ARL,326729677,13.12,200,2,13.72,15,1,13.11,100,1,13.98,200,2,13.03,100,1,13.99,100,1,13,2,1,14.03,2,1,12.73,100,1,14.26,100,1,12.71,100,1,14.28,100,1,12.5,700,1,14.45,100,1,12.46,200,2,14.56,800,2,12.43,700,1,14.6,700,1,12.42,700,1,14.68,1400,2
2025-07-17T16:03:10.807548848Z,2025-07-17T16:03:10.807714421Z,160,2,1108,C,A,0,13.99,100,0,165573,272474576,ARL,326167529,13.12,200,2,13.72,15,1,13.11,100,1,13.98,200,2,13.03,100,1,14.03,2,1,13,2,1,14.26,100,1,12.73,100,1,14.28,100,1,12.71,100,1,14.45,100,1,12.5,700,1,14.56,800,2,12.46,200,2,14.6,700,1,12.43,700,1,14.68,1400,2,12.42,700,1,14.7,200,2
2025-07-17T16:03:10.807548848Z,2025-07-17T16:03:10.807714421Z,160,2,1108,A,A,0,13.73,100,130,165573,272474576,ARL,326729685,13.12,200,2,13.72,15,1,13.11,100,1,13.73,100,1,13.03,100,1,13.98,200,2,13,2,1,14.03,2,1,12.73,100,1,14.26,100,1,12.71,100,1,14.28,100,1,12.5,700,1,14.45,100,1,12.46,200,2,14.56,800,2,12.43,700,1,14.6,700,1,12.42,700,1,14.68,1400,2
2025-07-17T16:03:10.808290914Z,2025-07-17T16:03:10.808457278Z,160,2,1108,C,A,0,15.06,100,0,166364,272474580,ARL,326159425,13.12,200,2,13.72,15,1,13.11,100,1,13.73,100,1,13.03,100,1,13.98,200,2,13,2,1,14.03,2,1,12.73,100,1,14.26,100,1,12.71,100,1,14.28,100,1,12.5,700,1,14.45,100,1,12.46,200,2,14.56,800,2,12.43,700,1,14.6,700,1,12.42,700,1,14.68,1400,2
2025-07-17T16:03:10.808290914Z,2025-07-17T16:03:10.808457278Z,160,2,1108,A,A,0,14.79,100,128,166364,272474580,ARL,326729705,13.12,200,2,13.72,15,1,13.11,100,1,13.73,100,1,13.03,100,1,13.98,200,2,13,2,1,14.03,2,1,12.73,100,1,14.26,100,1,12.71,100,1,14.28,100,1,12.5,700,1,14.45,100,1,12.46,200,2,14.56,800,2,12.43,700,1,14.6,700,1,12.42,700,1,14.68,1400,2
2025-07-17T16:03:10.809541651Z,2025-07-17T16:03:10.809707274Z,160,2,1108,C,A,0,14.96,100,0,165623,272474585,ARL,326158881,13.12,200,2,13.72,15,1,13.11,100,1,13.73,100,1,13.03,100,1,13.98,200,2,13,2,1,14.03,2,1,12.73,100,1,14.26,100,1,12.71,100,1,14.28,100,1,12.5,700,1,14.45,100,1,12.46,200,2,14.56,800,2,12.43,700,1,14.6,700,1,12.42,700,1,14.68,1400,2
2025-07-17T16:03:10.809541651Z,2025-07-17T16:03:10.809707274Z,160,2,1108,A,A,0,14.7,100,130,165623,272474585,ARL,326729721,13.12,200,2,13.72,15,1,13.11,100,1,13.73,100,1,13.03,100,1,13.98,200,2,13,2,1,14.03,2,1,12.73,100,1,14.26,100,1,12.71,100,1,14.28,100,1,12.5,700,1,14.45,100,1,12.46,200,2,14.56,800,2,12.43,700,1,14.6,700,1,12.42,700,1,14.68,1400,2
2025-07-17T16:03:10.809771527Z,2025-07-17T16:03:10.809936821Z,160,2,1108,C,A,0,14.77,100,130,165294,272474594,ARL,326160141,13.12,200,2,13.72,15,1,13.11,100,1,13.73,100,1,13.03,100,1,13.98,200,2,13,2,1,14.03,2,1,12.73,100,1,14.26,100,1,12.71,100,1,14.28,100,1,12.5,700,1,14.45,100,1,12.46,200,2,14.56,800,2,12.43,700,1,14.6,700,1,12.42,700,1,14.68,1400,2
2025-07-17T16:03:10.809798084Z,2025-07-17T16:03:10.809963577Z,160,2,1108,C,A,0,17.76,100,0,165493,272474595,ARL,326158953,13.12,200,2,13.72,15,1,13.11,100,1,13.73,100,1,13.03,100,1,13.98,200,2,13,2,1,14.03,2,1,12.73,100,1,14.26,100,1,12.71,100,1,14.28,100,1,12.5,700,1,14.45,100,1,12.46,200,2,14.56,800,2,12.43,700,1,14.6,700,1,12.42,700,1,14.68,1400,2
2025-07-17T16:03:10.809798084Z,2025-07-17T16:03:10.809963577Z,160,2,1108,A,A,0,17.44,100,130,165493,272474595,ARL,326729725,13.12,200,2,13.72,15,1,13.11,100,1,13.73,100,1,13.03,100,1,13.98,200,2,13,2,1,14.03,2,1,12.73,100,1,14.26,100,1,12.71,100,1,14.28,100,1,12.5,700,1,14.45,100,1,12.46,200,2,14.56,800,2,12.43,700,1,14.6,700,1,12.42,700,1,14.68,1400,2
2025-07-17T16:03:10.809894317Z,2025-07-17T16:03:10.810059442Z,160,2,1108,A,A,0,14.52,100,130,165125,272474597,ARL,326729729,13.12,200,2,13.72,15,1,13.11,100,1,13.73,100,1,13.03,100,1,13.98,200,2,13,2,1,14.03,2,1,12.73,100,1,14.26,100,1,12.71,100,1,14.28,100,1,12.5,700,1,14.45,100,1,12.46,200,2,14.52,100,1,12.43,700,1,14.56,800,2,12.42,700,1,14.6,700,1
2025-07-17T16:03:10.810312923Z,2025-07-17T16:03:10.810478524Z,160,2,1108,C,A,0,16.08,100,0,165601,272474600,ARL,326158989,13.12,200,2,13.72,15,1,13.11,100,1,13.73,100,1,13.03,100,1,13.98,200,2,13,2,1,14.03,2,1,12.73,100,1,14.26,100,1,12.71,100,1,14.28,100,1,12.5,700,1,14.45,100,1,12.46,200,2,14.52,100,1,12.43,700,1,14.56,800,2,12.42,700,1,14.6,700,1
2025-07-17T16:03:10.810312923Z,2025-07-17T16:03:10.810478524Z,160,2,1108,A,A,0,15.79,100,130,165601,272474600,ARL,326729733,13.12,200,2,13.72,15,1,13.11,100,1,13.73,100,1,13.03,100,1,13.98,200,2,13,2,1,14.03,2,1,12.73,100,1,14.26,100,1,12.71,100,1,14.28,100,1,12.5,700,1,14.45,100,1,12.46,200,2,14.52,100,1,12.43,700,1,14.56,800,2,12.42,700,1,14.6,700,1
2025-07-17T16:03:10.814480532Z,2025-07-17T16:03:10.814646270Z,160,2,1108,C,A,0,14.96,100,0,165738,272474635,ARL,326158997,13.12,200,2,13.72,15,1,13.11,100,1,13.73,100,1,13.03,100,1,13.98,200,2,13,2,1,14.03,2,1,12.73,100,1,14.26,100,1,12.71,100,1,14.28,100,1,12.5,700,1,14.45,100,1,12.46,200,2,14.52,100,1,12.43,700,1,14.56,800,2,12.42,700,1,14.6,700,1
2025-07-17T16:03:10.814480532Z,2025-07-17T16:03:10.814646270Z,160,2,1108,A,A,0,14.7,100,130,165738,272474635,ARL,326729821,13.12,200,2,13.72,15,1,13.11,100,1,13.73,100,1,13.03,100,1,13.98,200,2,13,2,1,14.03,2,1,12.73,100,1,14.26,100,1,12.71,100,1,14.28,100,1,12.5,700,1,14.45,100,1,12.46,200,2,14.52,100,1,12.43,700,1,14.56,800,2,12.42,700,1,14.6,700,1
2025-07-17T16:03:10.817700664Z,2025-07-17T16:03:10.817866066Z,160,2,1108,C,A,0,14.26,100,130,165402,272474675,ARL,326159201,13.12,200,2,13.72,15,1,13.11,100,1,13.73,100,1,13.03,100,1,13.98,200,2,13,2,1,14.03,2,1,12.73,100,1,14.28,100,1,12.71,100,1,14.45,100,1,12.5,700,1,14.52,100,1,12.46,200,2,14.56,800,2,12.43,700,1,14.6,700,1,12.42,700,1,14.68,1400,2
2025-07-17T16:03:10.817754737Z,2025-07-17T16:03:10.817919970Z,160,2,1108,A,A,0,14,100,130,165233,272474676,ARL,326729929,13.12,200,2,13.72,15,1,13.11,100,1,13.73,100,1,13.03,100,1,13.98,200,2,13,2,1,14,100,1,12.73,100,1,14.03,2,1,12.71,100,1,14.28,100,1,12.5,700,1,14.45,100,1,12.46,200,2,14.52,100,1,12.43,700,1,14.56,800,2,12.42,700,1,14.6,700,1
2025-07-17T16:03:10.843172549Z,2025-07-17T16:03:10.843337845Z,160,2,1108,A,A,0,15.66,100,130,165296,272474826,ARL,326730513,13.12,200,2,13.72,15,1,13.11,100,1,13.73,100,1,13.03,100,1,13.98,200,2,13,2,1,14,100,1,12.73,100,1,14.03,2,1,12.71,100,1,14.28,100,1,12.5,700,1,14.45,100,1,12.46,200,2,14.52,100,1,12.43,700,1,14.56,800,2,12.42,700,1,14.6,700,1
2025-07-17T16:03:10.843184785Z,2025-07-17T16:03:10.843350160Z,160,2,1108,C,A,0,15.94,100,130,165375,272474827,ARL,325714909,13.12,200,2,13.72,15,1,13.11,100,1,13.73,100,1,13.03,100,1,13.98,200,2,13,2,1,14,100,1,12.73,100,1,14.03,2,1,12.71,100,1,14.28,100,1,12.5,700,1,14.45,100,1,12.46,200,2,14.52,100,1,12.43,700,1,14.56,800,2,12.42,700,1,14.6,700,1
2025-07-17T16:03:10.843448998Z,2025-07-17T16:03:10.843615537Z,160,2,1108,C,A,0,13.98,100,0,166539,272474828,ARL,325719357,13.12,200,2,13.72,15,1,13.11,100,1,13.73,100,1,13.03,100,1,13.98,100,1,13,2,1,14,100,1,12.73,100,1,14.03,2,1,12.71,100,1,14.28,100,1,12.5,700,1,14.45,100,1,12.46,200,2,14.52,100,1,12.43,700,1,14.56,800,2,12.42,700,1,14.6,700,1
2025-07-17T16:03:10.843449402Z,2025-07-17T16:03:10.843615537Z,160,2,1108,C,A,0,13.98,100,130,166135,272474829,ARL,325719353,13.12,200,2,13.72,15,1,13.11,100,1,13.73,100,1,13.03,100,1,14,100,1,13,2,1,14.03,2,1,12.73,100,1,14.28,100,1,12.71,100,1,14.45,100,1,12.5,700,1,14.52,100,1,12.46,200,2,14.56,800,2,12.43,700,1,14.6,700,1,12.42,700,1,14.68,1400,2
2025-07-17T16:03:10.843462898Z,2025-07-17T16:03:10.843628246Z,160,2,1108,A,A,0,13.87,100,130,165348,272474830,ARL,326730517,13.12,200,2,13.72,15,1,13.11,100,1,13.73,100,1,13.03,100,1,13.87,100,1,13,2,1,14,100,1,12.73,100,1,14.03,2,1,12.71,100,1,14.28,100,1,12.5,700,1,14.45,100,1,12.46,200,2,14.52,100,1,12.43,700,1,14.56,800,2,12.42,700,1,14.6,700,1
2025-07-17T16:03:10.843464369Z,2025-07-17T16:03:10.843629633Z,160,2,1108,A,A,0,13.87,100,130,165264,272474831,ARL,326730521,13.12,200,2,13.72,15,1,13.11,100,1,13.73,100,1,13.03,100,1,13.87,200,2,13,2,1,14,100,1,12.73,100,1,14.03,2,1,12.71,100,1,14.28,100,1,12.5,700,1,14.45,100,1,12.46,200,2,14.52,100,1,12.43,700,1,14.56,800,2,12.42,700,1,14.6,700,1
2025-07-17T16:03:16.348023740Z,2025-07-17T16:03:16.348189077Z,160,2,1108,A,A,0,13.69,15,130,165337,272557172,ARL,326835877,13.12,200,2,13.69,15,1,13.11,100,1,13.72,15,1,13.03,100,1,13.73,100,1,13,2,1,13.87,200,2,12.73,100,1,14,100,1,12.71,100,1,14.03,2,1,12.5,700,1,14.28,100,1,12.46,200,2,14.45,100,1,12.43,700,1,14.52,100,1,12.42,700,1,14.56,800,2
2025-07-17T16:03:16.348302787Z,2025-07-17T16:03:16.348468824Z,160,2,1108,C,A,0,14.7,100,0,166037,272557230,ARL,326551829,13.12,200,2,13.69,15,1,13.11,100,1,13.72,15,1,13.03,100,1,13.73,100,1,13,2,1,13.87,200,2,12.73,100,1,14,100,1,12.71,100,1,14.03,2,1,12.5,700,1,14.28,100,1,12.46,200,2,14.45,100,1,12.43,700,1,14.52,100,1,12.42,700,1,14.56,800,2
2025-07-17T16:03:16.348302787Z,2025-07-17T16:03:16.348468824Z,160,2,1108,A,A,0,14.58,100,130,166037,272557230,ARL,326835885,13.12,200,2,13.69,15,1,13.11,100,1,13.72,15,1,13.03,100,1,13.73,100,1,13,2,1,13.87,200,2,12.73,100,1,14,100,1,12.71,100,1,14.03,2,1,12.5,700,1,14.28,100,1,12.46,200,2,14.45,100,1,12.43,700,1,14.52,100,1,12.42,700,1,14.56,800,2
2025-07-17T16:03:16.349513354Z,2025-07-17T16:03:16.349679949Z,160,2,1108,C,A,0,14.7,100,0,166595,272557430,ARL,326551237,13.12,200,2,13.69,15,1,13.11,100,1,13.72,15,1,13.03,100,1,13.73,100,1,13,2,1,13.87,200,2,12.73,100,1,14,100,1,12.71,100,1,14.03,2,1,12.5,700,1,14.28,100,1,12.46,200,2,14.45,100,1,12.43,700,1,14.52,100,1,12.42,700,1,14.56,800,2
2025-07-17T16:03:16.349513354Z,2025-07-17T16:03:16.349679949Z,160,2,1108,A,A,0,14.58,100,130,166595,272557430,ARL,326836085,13.12,200,2,13.69,15,1,13.11,100,1,13.72,15,1,13.03,100,1,13.73,100,1,13,2,1,13.87,200,2,12.73,100,1,14,100,1,12.71,100,1,14.03,2,1,12.5,700,1,14.28,100,1,12.46,200,2,14.45,100,1,12.43,700,1,14.52,100,1,12.42,700,1,14.56,800,2
2025-07-17T16:03:16.351845457Z,2025-07-17T16:03:16.352011831Z,160,2,1108,C,A,0,13.73,100,0,166374,272557789,ARL,326729685,13.12,200,2,13.69,15,1,13.11,100,1,13.72,15,1,13.03,100,1,13.87,200,2,13,2,1,14,100,1,12.73,100,1,14.03,2,1,12.71,100,1,14.28,100,1,12.5,700,1,14.45,100,1,12.46,200,2,14.52,100,1,12.43,700,1,14.56,800,2,12.42,700,1,14.58,200,2
2025-07-17T16:03:16.351845457Z,2025-07-17T16:03:16.352011831Z,160,2,1108,A,A,0,13.7,100,130,166374,272557789,ARL,326836533,13.12,200,2,13.69,15,1,13.11,100,1,13.7,100,1,13.03,100,1,13.72,15,1,13,2,1,13.87,200,2,12.73,100,1,14,100,1,12.71,100,1,14.03,2,1,12.5,700,1,14.28,100,1,12.46,200,2,14.45,100,1,12.43,700,1,14.52,100,1,12.42,700,1,14.56,800,2
2025-07-17T16:03:16.365819243Z,2025-07-17T16:03:16.365985162Z,160,2,1108,C,A,0,15.38,100,0,165919,272559024,ARL,325714965,13.12,200,2,13.69,15,1,13.11,100,1,13.7,100,1,13.03,100,1,13.72,15,1,13,2,1,13.87,200,2,12.73,100,1,14,100,1,12.71,100,1,14.03,2,1,12.5,700,1,14.28,100,1,12.46,200,2,14.45,100,1,12.43,700,1,14.52,100,1,12.42,700,1,14.56,800,2
2025-07-17T16:03:16.365819243Z,2025-07-17T16:03:16.365985162Z,160,2,1108,A,A,0,15.07,100,130,165919,272559024,ARL,326837501,13.12,200,2,13.69,15,1,13.11,100,1,13.7,100,1,13.03,100,1,13.72,15,1,13,2,1,13.87,200,2,12.73,100,1,14,100,1,12.71,100,1,14.03,2,1,12.5,700,1,14.28,100,1,12.46,200,2,14.45,100,1,12.43,700,1,14.52,100,1,12.42,700,1,14.56,800,2
2025-07-17T16:03:18.804159952Z,2025-07-17T16:03:18.804325078Z,160,2,1108,C,A,0,13.69,15,130,165126,272609485,ARL,326835877,13.12,200,2,13.7,100,1,13.11,100,1,13.72,15,1,13.03,100,1,13.87,200,2,13,2,1,14,100,1,12.73,100,1,14.03,2,1,12.71,100,1,14.28,100,1,12.5,700,1,14.45,100,1,12.46,200,2,14.52,100,1,12.43,700,1,14.56,800,2,12.42,700,1,14.58,200,2
2025-07-17T16:03:18.804202246Z,2025-07-17T16:03:18.804367560Z,160,2,1108,C,A,0,13.7,100,130,165314,272609486,ARL,326836533,13.12,200,2,13.72,15,1,13.11,100,1,13.87,200,2,13.03,100,1,14,100,1,13,2,1,14.03,2,1,12.73,100,1,14.28,100,1,12.71,100,1,14.45,100,1,12.5,700,1,14.52,100,1,12.46,200,2,14.56,800,2,12.43,700,1,14.58,200,2,12.42,700,1,14.6,700,1
2025-07-17T16:03:18.804933488Z,2025-07-17T16:03:18.805099118Z,160,2,1108,C,A,0,14.79,100,0,165630,272609510,ARL,326729705,13.12,200,2,13.72,15,1,13.11,100,1,13.87,200,2,13.03,100,1,14,100,1,13,2,1,14.03,2,1,12.73,100,1,14.28,100,1,12.71,100,1,14.45,100,1,12.5,700,1,14.52,100,1,12.46,200,2,14.56,800,2,12.43,700,1,14.58,200,2,12.42,700,1,14.6,700,1
2025-07-17T16:03:18.804933488Z,2025-07-17T16:03:18.805099118Z,160,2,1108,A,A,0,14.95,100,130,165630,272609510,ARL,326892717,13.12,200,2,13.72,15,1,13.11,100,1,13.87,200,2,13.03,100,1,14,100,1,13,2,1,14.03,2,1,12.73,100,1,14.28,100,1,12.71,100,1,14.45,100,1,12.5,700,1,14.52,100,1,12.46,200,2,14.56,800,2,12.43,700,1,14.58,200,2,12.42,700,1,14.6,700,1
2025-07-17T16:03:18.805126035Z,2025-07-17T16:03:18.805291629Z,160,2,1108,C,A,0,14.7,100,0,165594,272609526,ARL,326729721,13.12,200,2,13.72,15,1,13.11,100,1,13.87,200,2,13.03,100,1,14,100,1,13,2,1,14.03,2,1,12.73,100,1,14.28,100,1,12.71,100,1,14.45,100,1,12.5,700,1,14.52,100,1,12.46,200,2,14.56,800,2,12.43,700,1,14.58,200,2,12.42,700,1,14.6,700,1
2025-07-17T16:03:18.805126035Z,2025-07-17T16:03:18.805291629Z,160,2,1108,A,A,0,14.85,100,130,165594,272609526,ARL,326892721,13.12,200,2,13.72,15,1,13.11,100,1,13.87,200,2,13.03,100,1,14,100,1,13,2,1,14.03,2,1,12.73,100,1,14.28,100,1,12.71,100,1,14.45,100,1,12.5,700,1,14.52,100,1,12.46,200,2,14.56,800,2,12.43,700,1,14.58,200,2,12.42,700,1,14.6,700,1
2025-07-17T16:03:18.805283236Z,2025-07-17T16:03:18.805449089Z,160,2,1108,C,A,0,13.72,15,130,165853,272609541,ARL,326729677,13.12,200,2,13.87,200,2,13.11,100,1,14,100,1,13.03,100,1,14.03,2,1,13,2,1,14.28,100,1,12.73,100,1,14.45,100,1,12.71,100,1,14.52,100,1,12.5,700,1,14.56,800,2,12.46,200,2,14.58,200,2,12.43,700,1,14.6,700,1,12.42,700,1,14.68,1400,2
2025-07-17T16:03:18.806370373Z,2025-07-17T16:03:18.806535903Z,160,2,1108,C,A,0,14.58,100,0,165530,272609577,ARL,326835885,13.12,200,2,13.87,200,2,13.11,100,1,14,100,1,13.03,100,1,14.03,2,1,13,2,1,14.28,100,1,12.73,100,1,14.45,100,1,12.71,100,1,14.52,100,1,12.5,700,1,14.56,800,2,12.46,200,2,14.58,100,1,12.43,700,1,14.6,700,1,12.42,700,1,14.68,1400,2
2025-07-17T16:03:18.806370373Z,2025-07-17T16:03:18.806535903Z,160,2,1108,A,A,0,14.76,100,130,165530,272609577,ARL,326892817,13.12,200,2,13.87,200,2,13.11,100,1,14,100,1,13.03,100,1,14.03,2,1,13,2,1,14.28,100,1,12.73,100,1,14.45,100,1,12.71,100,1,14.52,100,1,12.5,700,1,14.56,800,2,12.46,200,2,14.58,100,1,12.43,700,1,14.6,700,1,12.42,700,1,14.68,1400,2
2025-07-17T16:03:18.806637004Z,2025-07-17T16:03:18.806802589Z,160,2,1108,C,A,0,14.58,100,0,165585,272609583,ARL,326836085,13.12,200,2,13.87,200,2,13.11,100,1,14,100,1,13.03,100,1,14.03,2,1,13,2,1,14.28,100,1,12.73,100,1,14.45,100,1,12.71,100,1,14.52,100,1,12.5,700,1,14.56,800,2,12.46,200,2,14.6,700,1,12.43,700,1,14.68,1400,2,12.42,700,1,14.7,100,1
2025-07-17T16:03:18.806637004Z,2025-07-17T16:03:18.806802589Z,160,2,1108,A,A,0,14.76,100,130,165585,272609583,ARL,326892825,13.12,200,2,13.87,200,2,13.11,100,1,14,100,1,13.03,100,1,14.03,2,1,13,2,1,14.28,100,1,12.73,100,1,14.45,100,1,12.71,100,1,14.52,100,1,12.5,700,1,14.56,800,2,12.46,200,2,14.6,700,1,12.43,700,1,14.68,1400,2,12.42,700,1,14.7,100,1
2025-07-17T16:03:18.809540733Z,2025-07-17T16:03:18.809706334Z,160,2,1108,C,A,0,14.52,100,0,165601,272609656,ARL,326729729,13.12,200,2,13.87,200,2,13.11,100,1,14,100,1,13.03,100,1,14.03,2,1,13,2,1,14.28,100,1,12.73,100,1,14.45,100,1,12.71,100,1,14.56,800,2,12.5,700,1,14.6,700,1,12.46,200,2,14.68,1400,2,12.43,700,1,14.7,100,1,12.42,700,1,14.76,200,2
2025-07-17T16:03:18.809540733Z,2025-07-17T16:03:18.809706334Z,160,2,1108,A,A,0,14.66,100,130,165601,272609656,ARL,326892885,13.12,200,2,13.87,200,2,13.11,100,1,14,100,1,13.03,100,1,14.03,2,1,13,2,1,14.28,100,1,12.73,100,1,14.45,100,1,12.71,100,1,14.56,800,2,12.5,700,1,14.6,700,1,12.46,200,2,14.66,100,1,12.43,700,1,14.68,1400,2,12.42,700,1,14.7,100,1
2025-07-17T16:03:18.809683187Z,2025-07-17T16:03:18.809848665Z,160,2,1108,C,A,0,15.79,100,0,165478,272609658,ARL,326729733,13.12,200,2,13.87,200,2,13.11,100,1,14,100,1,13.03,100,1,14.03,2,1,13,2,1,14.28,100,1,12.73,100,1,14.45,100,1,12.71,100,1,14.56,800,2,12.5,700,1,14.6,700,1,12.46,200,2,14.66,100,1,12.43,700,1,14.68,1400,2,12.42,700,1,14.7,100,1
2025-07-17T16:03:18.809683187Z,2025-07-17T16:03:18.809848665Z,160,2,1108,A,A,0,15.96,100,130,165478,272609658,ARL,326892889,13.12,200,2,13.87,200,2,13.11,100,1,14,100,1,13.03,100,1,14.03,2,1,13,2,1,14.28,100,1,12.73,100,1,14.45,100,1,12.71,100,1,14.56,800,2,12.5,700,1,14.6,700,1,12.46,200,2,14.66,100,1,12.43,700,1,14.68,1400,2,12.42,700,1,14.7,100,1
2025-07-17T16:03:18.811941680Z,2025-07-17T16:03:18.812107206Z,160,2,1108,C,A,0,17.44,100,0,165526,272609679,ARL,326729725,13.12,200,2,13.87,200,2,13.11,100,1,14,100,1,13.03,100,1,14.03,2,1,13,2,1,14.28,100,1,12.73,100,1,14.45,100,1,12.71,100,1,14.56,800,2,12.5,700,1,14.6,700,1,12.46,200,2,14.66,100,1,12.43,700,1,14.68,1400,2,12.42,700,1,14.7,100,1
2025-07-17T16:03:18.811941680Z,2025-07-17T16:03:18.812107206Z,160,2,1108,A,A,0,17.62,100,130,165526,272609679,ARL,326892921,13.12,200,2,13.87,200,2,13.11,100,1,14,100,1,13.03,100,1,14.03,2,1,13,2,1,14.28,100,1,12.73,100,1,14.45,100,1,12.71,100,1,14.56,800,2,12.5,700,1,14.6,700,1,12.46,200,2,14.66,100,1,12.43,700,1,14.68,1400,2,12.42,700,1,14.7,100,1
2025-07-17T16:03:18.818080239Z,2025-07-17T16:03:18.818245629Z,160,2,1108,C,A,0,14,100,130,165390,272609768,ARL,326729929,13.12,200,2,13.87,200,2,13.11,100,1,14.03,2,1,13.03,100,1,14.28,100,1,13,2,1,14.45,100,1,12.73,100,1,14.56,800,2,12.71,100,1,14.6,700,1,12.5,700,1,14.66,100,1,12.46,200,2,14.68,1400,2,12.43,700,1,14.7,100,1,12.42,700,1,14.76,200,2
2025-07-17T16:03:18.818135688Z,2025-07-17T16:03:18.818301143Z,160,2,1108,A,A,0,14.15,100,130,165455,272609769,ARL,326893213,13.12,200,2,13.87,200,2,13.11,100,1,14.03,2,1,13.03,100,1,14.15,100,1,13,2,1,14.28,100,1,12.73,100,1,14.45,100,1,12.71,100,1,14.56,800,2,12.5,700,1,14.6,700,1,12.46,200,2,14.66,100,1,12.43,700,1,14.68,1400,2,12.42,700,1,14.7,100,1
2025-07-17T16:03:18.868254768Z,2025-07-17T16:03:18.868420503Z,160,2,1108,C,A,0,14.7,100,0,165735,272610397,ARL,326729821,13.12,200,2,13.87,200,2,13.11,100,1,14.03,2,1,13.03,100,1,14.15,100,1,13,2,1,14.28,100,1,12.73,100,1,14.45,100,1,12.71,100,1,14.56,800,2,12.5,700,1,14.6,700,1,12.46,200,2,14.66,100,1,12.43,700,1,14.68,1400,2,12.42,700,1,14.76,200,2
2025-07-17T16:03:18.868254768Z,2025-07-17T16:03:18.868420503Z,160,2,1108,A,A,0,14.85,100,130,165735,272610397,ARL,326893961,13.12,200,2,13.87,200,2,13.11,100,1,14.03,2,1,13.03,100,1,14.15,100,1,13,2,1,14.28,100,1,12.73,100,1,14.45,100,1,12.71,100,1,14.56,800,2,12.5,700,1,14.6,700,1,12.46,200,2,14.66,100,1,12.43,700,1,14.68,1400,2,12.42,700,1,14.76,200,2
2025-07-17T16:03:19.191054306Z,2025-07-17T16:03:19.191219507Z,160,2,1108,A,A,0,13.88,100,130,165201,272614303,ARL,326899125,13.12,200,2,13.87,200,2,13.11,100,1,13.88,100,1,13.03,100,1,14.03,2,1,13,2,1,14.15,100,1,12.73,100,1,14.28,100,1,12.71,100,1,14.45,100,1,12.5,700,1,14.56,800,2,12.46,200,2,14.6,700,1,12.43,700,1,14.66,100,1,12.42,700,1,14.68,1400,2
2025-07-17T16:03:27.436158395Z,2025-07-17T16:03:27.436323951Z,160,2,1108,A,A,0,14.25,53,130,165556,272788767,ARL,327112281,13.12,200,2,13.87,200,2,13.11,100,1,13.88,100,1,13.03,100,1,14.03,2,1,13,2,1,14.15,100,1,12.73,100,1,14.25,53,1,12.71,100,1,14.28,100,1,12.5,700,1,14.45,100,1,12.46,200,2,14.56,800,2,12.43,700,1,14.6,700,1,12.42,700,1,14.66,100,1
2025-07-17T16:03:27.436715001Z,2025-07-17T16:03:27.436880768Z,160,2,1108,C,B,0,12.23,100,0,165767,272788774,ARL,291964745,13.12,200,2,13.87,200,2,13.11,100,1,13.88,100,1,13.03,100,1,14.03,2,1,13,2,1,14.15,100,1,12.73,100,1,14.25,53,1,12.71,100,1,14.28,100,1,12.5,700,1,14.45,100,1,12.46,200,2,14.56,800,2,12.43,700,1,14.6,700,1,12.42,700,1,14.66,100,1
2025-07-17T16:03:27.436715001Z,2025-07-17T16:03:27.436880768Z,160,2,1108,A,B,0,12.1,100,130,165767,272788774,ARL,327112289,13.12,200,2,13.87,200,2,13.11,100,1,13.88,100,1,13.03,100,1,14.03,2,1,13,2,1,14.15,100,1,12.73,100,1,14.25,53,1,12.71,100,1,14.28,100,1,12.5,700,1,14.45,100,1,12.46,200,2,14.56,800,2,12.43,700,1,14.6,700,1,12.42,700,1,14.66,100,1
2025-07-17T16:03:27.438400828Z,2025-07-17T16:03:27.438566971Z,160,2,1108,C,B,0,12.34,100,0,166143,272788792,ARL,285586113,13.12,200,2,13.87,200,2,13.11,100,1,13.88,100,1,13.03,100,1,14.03,2,1,13,2,1,14.15,100,1,12.73,100,1,14.25,53,1,12.71,100,1,14.28,100,1,12.5,700,1,14.45,100,1,12.46,200,2,14.56,800,2,12.43,700,1,14.6,700,1,12.42,700,1,14.66,100,1
2025-07-17T16:03:27.438400828Z,2025-07-17T16:03:27.438566971Z,160,2,1108,A,B,0,12.2,100,130,166143,272788792,ARL,327112385,13.12,200,2,13.87,200,2,13.11,100,1,13.88,100,1,13.03,100,1,14.03,2,1,13,2,1,14.15,100,1,12.73,100,1,14.25,53,1,12.71,100,1,14.28,100,1,12.5,700,1,14.45,100,1,12.46,200,2,14.56,800,2,12.43,700,1,14.6,700,1,12.42,700,1,14.66,100,1
2025-07-17T16:03:27.438437969Z,2025-07-17T16:03:27.438603564Z,160,2,1108,C,B,0,12.34,100,0,165595,272788793,ARL,285586189,13.12,200,2,13.87,200,2,13.11,100,1,13.88,100,1,13.03,100,1,14.03,2,1,13,2,1,14.15,100,1,12.73,100,1,14.25,53,1,12.71,100,1,14.28,100,1,12.5,700,1,14.45,100,1,12.46,200,2,14.56,800,2,12.43,700,1,14.6,700,1,12.42,700,1,14.66,100,1
2025-07-17T16:03:27.438437969Z,2025-07-17T16:03:27.438603564Z,160,2,1108,A,B,0,12.2,100,130,165595,272788793,ARL,327112393,13.12,200,2,13.87,200,2,13.11,100,1,13.88,100,1,13.03,100,1,14.03,2,1,13,2,1,14.15,100,1,12.73,100,1,14.25,53,1,12.71,100,1,14.28,100,1,12.5,700,1,14.45,100,1,12.46,200,2,14.56,800,2,12.43,700,1,14.6,700,1,12.42,700,1,14.66,100,1
2025-07-17T16:03:27.453845141Z,2025-07-17T16:03:27.454010355Z,160,2,1108,C,B,0,13.03,100,130,165214,272788897,ARL,285586293,13.12,200,2,13.87,200,2,13.11,100,1,13.88,100,1,13,2,1,14.03,2,1,12.73,100,1,14.15,100,1,12.71,100,1,14.25,53,1,12.5,700,1,14.28,100,1,12.46,200,2,14.45,100,1,12.43,700,1,14.56,800,2,12.42,700,1,14.6,700,1,12.37,700,1,14.66,100,1
2025-07-17T16:03:27.453894425Z,2025-07-17T16:03:27.454059719Z,160,2,1108,A,B,0,12.95,100,130,165294,272788898,ARL,327112565,13.12,200,2,13.87,200,2,13.11,100,1,13.88,100,1,13,2,1,14.03,2,1,12.95,100,1,14.15,100,1,12.73,100,1,14.25,53,1,12.71,100,1,14.28,100,1,12.5,700,1,14.45,100,1,12.46,200,2,14.56,800,2,12.43,700,1,14.6,700,1,12.42,700,1,14.66,100,1
2025-07-17T16:03:27.454726901Z,2025-07-17T16:03:27.454892321Z,160,2,1108,C,B,0,12.95,100,130,165420,272788942,ARL,327112565,13.12,200,2,13.87,200,2,13.11,100,1,13.88,100,1,13,2,1,14.03,2,1,12.73,100,1,14.15,100,1,12.71,100,1,14.25,53,1,12.5,700,1,14.28,100,1,12.46,200,2,14.45,100,1,12.43,700,1,14.56,800,2,12.42,700,1,14.6,700,1,12.37,700,1,14.66,100,1
2025-07-17T16:03:27.454773691Z,2025-07-17T16:03:27.454939600Z,160,2,1108,A,B,0,12.86,100,130,165909,272788943,ARL,327112577,13.12,200,2,13.87,200,2,13.11,100,1,13.88,100,1,13,2,1,14.03,2,1,12.86,100,1,14.15,100,1,12.73,100,1,14.25,53,1,12.71,100,1,14.28,100,1,12.5,700,1,14.45,100,1,12.46,200,2,14.56,800,2,12.43,700,1,14.6,700,1,12.42,700,1,14.66,100,1
2025-07-17T16:03:27.517585374Z,2025-07-17T16:03:27.517751270Z,160,2,1108,C,B,0,12.46,100,130,165896,272790695,ARL,285587281,13.12,200,2,13.87,200,2,13.11,100,1,13.88,100,1,13,2,1,14.03,2,1,12.86,100,1,14.15,100,1,12.73,100,1,14.25,53,1,12.71,100,1,14.28,100,1,12.5,700,1,14.45,100,1,12.46,100,1,14.56,800,2,12.43,700,1,14.6,700,1,12.42,700,1,14.66,100,1
2025-07-17T16:03:27.517699408Z,2025-07-17T16:03:27.517864675Z,160,2,1108,A,B,0,12.33,100,130,165267,272790696,ARL,327114465,13.12,200,2,13.87,200,2,13.11,100,1,13.88,100,1,13,2,1,14.03,2,1,12.86,100,1,14.15,100,1,12.73,100,1,14.25,53,1,12.71,100,1,14.28,100,1,12.5,700,1,14.45,100,1,12.46,100,1,14.56,800,2,12.43,700,1,14.6,700,1,12.42,700,1,14.66,100,1
2025-07-17T16:03:27.536178718Z,2025-07-17T16:03:27.536343943Z,160,2,1108,C,A,0,14.25,53,130,165225,272791410,ARL,327112281,13.12,200,2,13.87,200,2,13.11,100,1,13.88,100,1,13,2,1,14.03,2,1,12.86,100,1,14.15,100,1,12.73,100,1,14.28,100,1,12.71,100,1,14.45,100,1,12.5,700,1,14.56,800,2,12.46,100,1,14.6,700,1,12.43,700,1,14.66,100,1,12.42,700,1,14.68,1400,2
2025-07-17T16:03:56.548182793Z,2025-07-17T16:03:56.548348047Z,160,2,1108,A,A,0,13.8,15,130,165254,273208310,ARL,327675057,13.12,200,2,13.8,15,1,13.11,100,1,13.87,200,2,13,2,1,13.88,100,1,12.86,100,1,14.03,2,1,12.73,100,1,14.15,100,1,12.71,100,1,14.28,100,1,12.5,700,1,14.45,100,1,12.46,100,1,14.56,800,2,12.43,700,1,14.6,700,1,12.42,700,1,14.66,100,1
2025-07-17T16:03:56.548446336Z,2025-07-17T16:03:56.548611716Z,160,2,1108,C,A,0,13.88,100,0,165380,273208316,ARL,326899125,13.12,200,2,13.8,15,1,13.11,100,1,13.87,200,2,13,2,1,14.03,2,1,12.86,100,1,14.15,100,1,12.73,100,1,14.28,100,1,12.71,100,1,14.45,100,1,12.5,700,1,14.56,800,2,12.46,100,1,14.6,700,1,12.43,700,1,14.66,100,1,12.42,700,1,14.68,1400,2
2025-07-17T16:03:56.548446336Z,2025-07-17T16:03:56.548611716Z,160,2,1108,A,A,0,13.81,100,130,165380,273208316,ARL,327675065,13.12,200,2,13.8,15,1,13.11,100,1,13.81,100,1,13,2,1,13.87,200,2,12.86,100,1,14.03,2,1,12.73,100,1,14.15,100,1,12.71,100,1,14.28,100,1,12.5,700,1,14.45,100,1,12.46,100,1,14.56,800,2,12.43,700,1,14.6,700,1,12.42,700,1,14.66,100,1
2025-07-17T16:03:56.549188993Z,2025-07-17T16:03:56.549354405Z,160,2,1108,C,A,0,14.95,100,0,165412,273208325,ARL,326892717,13.12,200,2,13.8,15,1,13.11,100,1,13.81,100,1,13,2,1,13.87,200,2,12.86,100,1,14.03,2,1,12.73,100,1,14.15,100,1,12.71,100,1,14.28,100,1,12.5,700,1,14.45,100,1,12.46,100,1,14.56,800,2,12.43,700,1,14.6,700,1,12.42,700,1,14.66,100,1
2025-07-17T16:03:56.549188993Z,2025-07-17T16:03:56.549354405Z,160,2,1108,A,A,0,14.88,100,130,165412,273208325,ARL,327675093,13.12,200,2,13.8,15,1,13.11,100,1,13.81,100,1,13,2,1,13.87,200,2,12.86,100,1,14.03,2,1,12.73,100,1,14.15,100,1,12.71,100,1,14.28,100,1,12.5,700,1,14.45,100,1,12.46,100,1,14.56,800,2,12.43,700,1,14.6,700,1,12.42,700,1,14.66,100,1
2025-07-17T16:04:06.233692491Z,2025-07-17T16:04:06.233858611Z,160,2,1108,C,A,0,14.76,100,0,166120,273345719,ARL,326892825,13.12,200,2,13.8,15,1,13.11,100,1,13.81,100,1,13,2,1,13.87,200,2,12.86,100,1,14.03,2,1,12.73,100,1,14.15,100,1,12.71,100,1,14.28,100,1,12.5,700,1,14.45,100,1,12.46,100,1,14.56,800,2,12.43,700,1,14.6,700,1,12.42,700,1,14.66,100,1
2025-07-17T16:04:06.233692491Z,2025-07-17T16:04:06.233858611Z,160,2,1108,A,A,0,14.64,100,130,166120,273345719,ARL,327856297,13.12,200,2,13.8,15,1,13.11,100,1,13.81,100,1,13,2,1,13.87,200,2,12.86,100,1,14.03,2,1,12.73,100,1,14.15,100,1,12.71,100,1,14.28,100,1,12.5,700,1,14.45,100,1,12.46,100,1,14.56,800,2,12.43,700,1,14.6,700,1,12.42,700,1,14.64,100,1
2025-07-17T16:04:06.234433294Z,2025-07-17T16:04:06.234600198Z,160,2,1108,C,A,0,14.76,100,0,166904,273345721,ARL,326892817,13.12,200,2,13.8,15,1,13.11,100,1,13.81,100,1,13,2,1,13.87,200,2,12.86,100,1,14.03,2,1,12.73,100,1,14.15,100,1,12.71,100,1,14.28,100,1,12.5,700,1,14.45,100,1,12.46,100,1,14.56,800,2,12.43,700,1,14.6,700,1,12.42,700,1,14.64,100,1
2025-07-17T16:04:06.234433294Z,2025-07-17T16:04:06.234600198Z,160,2,1108,A,A,0,14.64,100,130,166904,273345721,ARL,327856309,13.12,200,2,13.8,15,1,13.11,100,1,13.81,100,1,13,2,1,13.87,200,2,12.86,100,1,14.03,2,1,12.73,100,1,14.15,100,1,12.71,100,1,14.28,100,1,12.5,700,1,14.45,100,1,12.46,100,1,14.56,800,2,12.43,700,1,14.6,700,1,12.42,700,1,14.64,200,2
2025-07-17T16:04:06.510748731Z,2025-07-17T16:04:06.510914101Z,160,2,1108,A,A,0,13.72,15,130,165370,273352664,ARL,327863853,13.12,200,2,13.72,15,1,13.11,100,1,13.8,15,1,13,2,1,13.81,100,1,12.86,100,1,13.87,200,2,12.73,100,1,14.03,2,1,12.71,100,1,14.15,100,1,12.5,700,1,14.28,100,1,12.46,100,1,14.45,100,1,12.43,700,1,14.56,800,2,12.42,700,1,14.6,700,1
2025-07-17T16:04:06.512244746Z,2025-07-17T16:04:06.512413102Z,160,2,1108,C,A,0,13.81,100,0,168356,273352888,ARL,327675065,13.12,200,2,13.72,15,1,13.11,100,1,13.8,15,1,13,2,1,13.87,200,2,12.86,100,1,14.03,2,1,12.73,100,1,14.15,100,1,12.71,100,1,14.28,100,1,12.5,700,1,14.45,100,1,12.46,100,1,14.56,800,2,12.43,700,1,14.6,700,1,12.42,700,1,14.64,200,2
2025-07-17T16:04:06.512244746Z,2025-07-17T16:04:06.512413102Z,160,2,1108,A,A,0,13.73,100,128,168356,273352888,ARL,327864137,13.12,200,2,13.72,15,1,13.11,100,1,13.73,100,1,13,2,1,13.8,15,1,12.86,100,1,13.87,200,2,12.73,100,1,14.03,2,1,12.71,100,1,14.15,100,1,12.5,700,1,14.28,100,1,12.46,100,1,14.45,100,1,12.43,700,1,14.56,800,2,12.42,700,1,14.6,700,1
2025-07-17T16:04:06.513497276Z,2025-07-17T16:04:06.513675299Z,160,2,1108,C,A,0,14.88,100,0,178023,273353923,ARL,327675093,13.12,200,2,13.72,15,1,13.11,100,1,13.73,100,1,13,2,1,13.8,15,1,12.86,100,1,13.87,200,2,12.73,100,1,14.03,2,1,12.71,100,1,14.15,100,1,12.5,700,1,14.28,100,1,12.46,100,1,14.45,100,1,12.43,700,1,14.56,800,2,12.42,700,1,14.6,700,1
2025-07-17T16:04:06.513497276Z,2025-07-17T16:04:06.513675299Z,160,2,1108,A,A,0,14.79,100,128,178023,273353923,ARL,327864893,13.12,200,2,13.72,15,1,13.11,100,1,13.73,100,1,13,2,1,13.8,15,1,12.86,100,1,13.87,200,2,12.73,100,1,14.03,2,1,12.71,100,1,14.15,100,1,12.5,700,1,14.28,100,1,12.46,100,1,14.45,100,1,12.43,700,1,14.56,800,2,12.42,700,1,14.6,700,1
2025-07-17T16:04:06.522687474Z,2025-07-17T16:04:06.522853161Z,160,2,1108,C,A,0,14.85,100,0,165687,273357758,ARL,326892721,13.12,200,2,13.72,15,1,13.11,100,1,13.73,100,1,13,2,1,13.8,15,1,12.86,100,1,13.87,200,2,12.73,100,1,14.03,2,1,12.71,100,1,14.15,100,1,12.5,700,1,14.28,100,1,12.46,100,1,14.45,100,1,12.43,700,1,14.56,800,2,12.42,700,1,14.6,700,1
2025-07-17T16:04:06.522687474Z,2025-07-17T16:04:06.522853161Z,160,2,1108,A,A,0,14.7,100,130,165687,273357758,ARL,327868421,13.12,200,2,13.72,15,1,13.11,100,1,13.73,100,1,13,2,1,13.8,15,1,12.86,100,1,13.87,200,2,12.73,100,1,14.03,2,1,12.71,100,1,14.15,100,1,12.5,700,1,14.28,100,1,12.46,100,1,14.45,100,1,12.43,700,1,14.56,800,2,12.42,700,1,14.6,700,1
2025-07-17T16:04:06.525385108Z,2025-07-17T16:04:06.525550815Z,160,2,1108,C,A,0,14.15,100,130,165707,273358260,ARL,326893213,13.12,200,2,13.72,15,1,13.11,100,1,13.73,100,1,13,2,1,13.8,15,1,12.86,100,1,13.87,200,2,12.73,100,1,14.03,2,1,12.71,100,1,14.28,100,1,12.5,700,1,14.45,100,1,12.46,100,1,14.56,800,2,12.43,700,1,14.6,700,1,12.42,700,1,14.64,200,2
2025-07-17T16:04:06.525442486Z,2025-07-17T16:04:06.525608746Z,160,2,1108,A,A,0,14,100,128,166260,273358273,ARL,327869193,13.12,200,2,13.72,15,1,13.11,100,1,13.73,100,1,13,2,1,13.8,15,1,12.86,100,1,13.87,200,2,12.73,100,1,14,100,1,12.71,100,1,14.03,2,1,12.5,700,1,14.28,100,1,12.46,100,1,14.45,100,1,12.43,700,1,14.56,800,2,12.42,700,1,14.6,700,1
2025-07-17T16:04:06.528043934Z,2025-07-17T16:04:06.528210755Z,160,2,1108,C,A,0,14.66,100,130,166821,273358598,ARL,326892885,13.12,200,2,13.72,15,1,13.11,100,1,13.73,100,1,13,2,1,13.8,15,1,12.86,100,1,13.87,200,2,12.73,100,1,14,100,1,12.71,100,1,14.03,2,1,12.5,700,1,14.28,100,1,12.46,100,1,14.45,100,1,12.43,700,1,14.56,800,2,12.42,700,1,14.6,700,1
2025-07-17T16:04:06.528161631Z,2025-07-17T16:04:06.528329048Z,160,2,1108,A,A,0,14.52,100,128,167417,273358642,ARL,327869529,13.12,200,2,13.72,15,1,13.11,100,1,13.73,100,1,13,2,1,13.8,15,1,12.86,100,1,13.87,200,2,12.73,100,1,14,100,1,12.71,100,1,14.03,2,1,12.5,700,1,14.28,100,1,12.46,100,1,14.45,100,1,12.43,700,1,14.52,100,1,12.42,700,1,14.56,800,2
2025-07-17T16:04:06.543314706Z,2025-07-17T16:04:06.543480312Z,160,2,1108,C,A,0,17.62,100,0,165606,273359491,ARL,326892921,13.12,200,2,13.72,15,1,13.11,100,1,13.73,100,1,13,2,1,13.8,15,1,12.86,100,1,13.87,200,2,12.73,100,1,14,100,1,12.71,100,1,14.03,2,1,12.5,700,1,14.28,100,1,12.46,100,1,14.45,100,1,12.43,700,1,14.52,100,1,12.42,700,1,14.56,800,2
2025-07-17T16:04:06.543314706Z,2025-07-17T16:04:06.543480312Z,160,2,1108,A,A,0,17.44,100,130,165606,273359491,ARL,327870217,13.12,200,2,13.72,15,1,13.11,100,1,13.73,100,1,13,2,1,13.8,15,1,12.86,100,1,13.87,200,2,12.73,100,1,14,100,1,12.71,100,1,14.03,2,1,12.5,700,1,14.28,100,1,12.46,100,1,14.45,100,1,12.43,700,1,14.52,100,1,12.42,700,1,14.56,800,2
2025-07-17T16:04:06.548778200Z,2025-07-17T16:04:06.548945239Z,160,2,1108,C,A,0,15.96,100,0,167039,273359672,ARL,326892889,13.12,200,2,13.72,15,1,13.11,100,1,13.73,100,1,13,2,1,13.8,15,1,12.86,100,1,13.87,200,2,12.73,100,1,14,100,1,12.71,100,1,14.03,2,1,12.5,700,1,14.28,100,1,12.46,100,1,14.45,100,1,12.43,700,1,14.52,100,1,12.42,700,1,14.56,800,2
2025-07-17T16:04:06.548778200Z,2025-07-17T16:04:06.548945239Z,160,2,1108,A,A,0,15.79,100,130,167039,273359672,ARL,327870361,13.12,200,2,13.72,15,1,13.11,100,1,13.73,100,1,13,2,1,13.8,15,1,12.86,100,1,13.87,200,2,12.73,100,1,14,100,1,12.71,100,1,14.03,2,1,12.5,700,1,14.28,100,1,12.46,100,1,14.45,100,1,12.43,700,1,14.52,100,1,12.42,700,1,14.56,800,2
2025-07-17T16:04:06.647944313Z,2025-07-17T16:04:06.648109829Z,160,2,1108,C,A,0,14.85,100,0,165516,273361957,ARL,326893961,13.12,200,2,13.72,15,1,13.11,100,1,13.73,100,1,13,2,1,13.8,15,1,12.86,100,1,13.87,200,2,12.73,100,1,14,100,1,12.71,100,1,14.03,2,1,12.5,700,1,14.28,100,1,12.46,100,1,14.45,100,1,12.43,700,1,14.52,100,1,12.42,700,1,14.56,800,2
2025-07-17T16:04:06.647944313Z,2025-07-17T16:04:06.648109829Z,160,2,1108,A,A,0,14.7,100,130,165516,273361957,ARL,327873009,13.12,200,2,13.72,15,1,13.11,100,1,13.73,100,1,13,2,1,13.8,15,1,12.86,100,1,13.87,200,2,12.73,100,1,14,100,1,12.71,100,1,14.03,2,1,12.5,700,1,14.28,100,1,12.46,100,1,14.45,100,1,12.43,700,1,14.52,100,1,12.42,700,1,14.56,800,2
2025-07-17T16:04:06.805335354Z,2025-07-17T16:04:06.805500523Z,160,2,1108,C,A,0,13.72,15,130,165169,273364089,ARL,327863853,13.12,200,2,13.73,100,1,13.11,100,1,13.8,15,1,13,2,1,13.87,200,2,12.86,100,1,14,100,1,12.73,100,1,14.03,2,1,12.71,100,1,14.28,100,1,12.5,700,1,14.45,100,1,12.46,100,1,14.52,100,1,12.43,700,1,14.56,800,2,12.42,700,1,14.6,700,1
2025-07-17T16:04:06.806052396Z,2025-07-17T16:04:06.806217584Z,160,2,1108,C,A,0,13.8,15,130,165188,273364090,ARL,327675057,13.12,200,2,13.73,100,1,13.11,100,1,13.87,200,2,13,2,1,14,100,1,12.86,100,1,14.03,2,1,12.73,100,1,14.28,100,1,12.71,100,1,14.45,100,1,12.5,700,1,14.52,100,1,12.46,100,1,14.56,800,2,12.43,700,1,14.6,700,1,12.42,700,1,14.64,200,2
2025-07-17T16:04:21.276976977Z,2025-07-17T16:04:21.277142662Z,160,2,1108,A,A,0,13.77,100,130,165685,273687857,ARL,328239293,13.12,200,2,13.73,100,1,13.11,100,1,13.77,100,1,13,2,1,13.87,200,2,12.86,100,1,14,100,1,12.73,100,1,14.03,2,1,12.71,100,1,14.28,100,1,12.5,700,1,14.45,100,1,12.46,100,1,14.52,100,1,12.43,700,1,14.56,800,2,12.42,700,1,14.6,700,1
2025-07-17T16:04:27.790889618Z,2025-07-17T16:04:27.791055146Z,160,2,1108,C,A,0,14.03,2,0,165528,273775264,ARL,326159041,13.12,200,2,13.73,100,1,13.11,100,1,13.77,100,1,13,2,1,13.87,200,2,12.86,100,1,14,100,1,12.73,100,1,14.28,100,1,12.71,100,1,14.45,100,1,12.5,700,1,14.52,100,1,12.46,100,1,14.56,800,2,12.43,700,1,14.6,700,1,12.42,700,1,14.64,200,2
2025-07-17T16:04:27.790889618Z,2025-07-17T16:04:27.791055146Z,160,2,1108,A,A,0,13.94,2,130,165528,273775264,ARL,328351217,13.12,200,2,13.73,100,1,13.11,100,1,13.77,100,1,13,2,1,13.87,200,2,12.86,100,1,13.94,2,1,12.73,100,1,14,100,1,12.71,100,1,14.28,100,1,12.5,700,1,14.45,100,1,12.46,100,1,14.52,100,1,12.43,700,1,14.56,800,2,12.42,700,1,14.6,700,1
2025-07-17T16:04:31.231887784Z,2025-07-17T16:04:31.232053154Z,160,2,1108,A,A,0,13.68,15,130,165370,273846737,ARL,328437797,13.12,200,2,13.68,15,1,13.11,100,1,13.73,100,1,13,2,1,13.77,100,1,12.86,100,1,13.87,200,2,12.73,100,1,13.94,2,1,12.71,100,1,14,100,1,12.5,700,1,14.28,100,1,12.46,100,1,14.45,100,1,12.43,700,1,14.52,100,1,12.42,700,1,14.56,800,2
2025-07-17T16:04:31.232440773Z,2025-07-17T16:04:31.232606440Z,160,2,1108,A,A,0,13.72,100,130,165667,273846745,ARL,328437805,13.12,200,2,13.68,15,1,13.11,100,1,13.72,100,1,13,2,1,13.73,100,1,12.86,100,1,13.77,100,1,12.73,100,1,13.87,200,2,12.71,100,1,13.94,2,1,12.5,700,1,14,100,1,12.46,100,1,14.28,100,1,12.43,700,1,14.45,100,1,12.42,700,1,14.52,100,1
2025-07-17T16:04:31.246515467Z,2025-07-17T16:04:31.246681162Z,160,2,1108,C,A,0,13.77,100,130,165695,273847000,ARL,328239293,13.12,200,2,13.68,15,1,13.11,100,1,13.72,100,1,13,2,1,13.73,100,1,12.86,100,1,13.87,200,2,12.73,100,1,13.94,2,1,12.71,100,1,14,100,1,12.5,700,1,14.28,100,1,12.46,100,1,14.45,100,1,12.43,700,1,14.52,100,1,12.42,700,1,14.56,800,2
2025-07-17T16:04:32.836635838Z,2025-07-17T16:04:32.836802111Z,160,2,1108,C,A,0,13.73,100,0,166273,273882084,ARL,327864137,13.12,200,2,13.68,15,1,13.11,100,1,13.72,100,1,13,2,1,13.87,200,2,12.86,100,1,13.94,2,1,12.73,100,1,14,100,1,12.71,100,1,14.28,100,1,12.5,700,1,14.45,100,1,12.46,100,1,14.52,100,1,12.43,700,1,14.56,800,2,12.42,700,1,14.6,700,1
2025-07-17T16:04:32.836635838Z,2025-07-17T16:04:32.836802111Z,160,2,1108,A,A,0,13.69,100,130,166273,273882084,ARL,328489153,13.12,200,2,13.68,15,1,13.11,100,1,13.69,100,1,13,2,1,13.72,100,1,12.86,100,1,13.87,200,2,12.73,100,1,13.94,2,1,12.71,100,1,14,100,1,12.5,700,1,14.28,100,1,12.46,100,1,14.45,100,1,12.43,700,1,14.52,100,1,12.42,700,1,14.56,800,2
2025-07-17T16:04:32.837000154Z,2025-07-17T16:04:32.837165431Z,160,2,1108,C,B,0,13.12,100,130,165277,273882201,ARL,325718833,13.12,100,1,13.68,15,1,13.11,100,1,13.69,100,1,13,2,1,13.72,100,1,12.86,100,1,13.87,200,2,12.73,100,1,13.94,2,1,12.71,100,1,14,100,1,12.5,700,1,14.28,100,1,12.46,100,1,14.45,100,1,12.43,700,1,14.52,100,1,12.42,700,1,14.56,800,2
2025-07-17T16:04:32.837002825Z,2025-07-17T16:04:32.837169083Z,160,2,1108,C,B,0,13.12,100,128,166258,273882202,ARL,325718837,13.11,100,1,13.68,15,1,13,2,1,13.69,100,1,12.86,100,1,13.72,100,1,12.73,100,1,13.87,200,2,12.71,100,1,13.94,2,1,12.5,700,1,14,100,1,12.46,100,1,14.28,100,1,12.43,700,1,14.45,100,1,12.42,700,1,14.52,100,1,12.37,700,1,14.56,800,2
2025-07-17T16:04:32.837013456Z,2025-07-17T16:04:32.837179568Z,160,2,1108,A,B,0,12.98,100,130,166112,273882207,ARL,328489377,13.11,100,1,13.68,15,1,13,2,1,13.69,100,1,12.98,100,1,13.72,100,1,12.86,100,1,13.87,200,2,12.73,100,1,13.94,2,1,12.71,100,1,14,100,1,12.5,700,1,14.28,100,1,12.46,100,1,14.45,100,1,12.43,700,1,14.52,100,1,12.42,700,1,14.56,800,2
2025-07-17T16:04:32.837016087Z,2025-07-17T16:04:32.837181582Z,160,2,1108,A,B,0,12.98,100,130,165495,273882208,ARL,328489385,13.11,100,1,13.68,15,1,13,2,1,13.69,100,1,12.98,200,2,13.72,100,1,12.86,100,1,13.87,200,2,12.73,100,1,13.94,2,1,12.71,100,1,14,100,1,12.5,700,1,14.28,100,1,12.46,100,1,14.45,100,1,12.43,700,1,14.52,100,1,12.42,700,1,14.56,800,2
2025-07-17T16:04:32.837369811Z,2025-07-17T16:04:32.837536434Z,160,2,1108,C,A,0,14.79,100,0,166623,273882286,ARL,327864893,13.11,100,1,13.68,15,1,13,2,1,13.69,100,1,12.98,200,2,13.72,100,1,12.86,100,1,13.87,200,2,12.73,100,1,13.94,2,1,12.71,100,1,14,100,1,12.5,700,1,14.28,100,1,12.46,100,1,14.45,100,1,12.43,700,1,14.52,100,1,12.42,700,1,14.56,800,2
2025-07-17T16:04:32.837369811Z,2025-07-17T16:04:32.837536434Z,160,2,1108,A,A,0,14.75,100,128,166623,273882286,ARL,328489481,13.11,100,1,13.68,15,1,13,2,1,13.69,100,1,12.98,200,2,13.72,100,1,12.86,100,1,13.87,200,2,12.73,100,1,13.94,2,1,12.71,100,1,14,100,1,12.5,700,1,14.28,100,1,12.46,100,1,14.45,100,1,12.43,700,1,14.52,100,1,12.42,700,1,14.56,800,2
2025-07-17T16:04:36.810551890Z,2025-07-17T16:04:36.810717146Z,160,2,1108,A,A,0,13.65,15,130,165256,273963456,ARL,328603377,13.11,100,1,13.65,15,1,13,2,1,13.68,15,1,12.98,200,2,13.69,100,1,12.86,100,1,13.72,100,1,12.73,100,1,13.87,200,2,12.71,100,1,13.94,2,1,12.5,700,1,14,100,1,12.46,100,1,14.28,100,1,12.43,700,1,14.45,100,1,12.42,700,1,14.52,100,1
2025-07-17T16:04:37.026771973Z,2025-07-17T16:04:37.026937493Z,160,2,1108,A,A,0,13.69,100,130,165520,273965417,ARL,328606289,13.11,100,1,13.65,15,1,13,2,1,13.68,15,1,12.98,200,2,13.69,200,2,12.86,100,1,13.72,100,1,12.73,100,1,13.87,200,2,12.71,100,1,13.94,2,1,12.5,700,1,14,100,1,12.46,100,1,14.28,100,1,12.43,700,1,14.45,100,1,12.42,700,1,14.52,100,1
2025-07-17T16:04:37.033389265Z,2025-07-17T16:04:37.033554557Z,160,2,1108,C,A,0,13.72,100,130,165292,273965562,ARL,328437805,13.11,100,1,13.65,15,1,13,2,1,13.68,15,1,12.98,200,2,13.69,200,2,12.86,100,1,13.87,200,2,12.73,100,1,13.94,2,1,12.71,100,1,14,100,1,12.5,700,1,14.28,100,1,12.46,100,1,14.45,100,1,12.43,700,1,14.52,100,1,12.42,700,1,14.56,800,2
2025-07-17T16:04:37.542795711Z,2025-07-17T16:04:37.542961161Z,160,2,1108,C,A,0,13.69,100,0,165450,273971021,ARL,328489153,13.11,100,1,13.65,15,1,13,2,1,13.68,15,1,12.98,200,2,13.69,100,1,12.86,100,1,13.87,200,2,12.73,100,1,13.94,2,1,12.71,100,1,14,100,1,12.5,700,1,14.28,100,1,12.46,100,1,14.45,100,1,12.43,700,1,14.52,100,1,12.42,700,1,14.56,800,2
2025-07-17T16:04:37.542795711Z,2025-07-17T16:04:37.542961161Z,160,2,1108,A,A,0,13.66,100,130,165450,273971021,ARL,328614509,13.11,100,1,13.65,15,1,13,2,1,13.66,100,1,12.98,200,2,13.68,15,1,12.86,100,1,13.69,100,1,12.73,100,1,13.87,200,2,12.71,100,1,13.94,2,1,12.5,700,1,14,100,1,12.46,100,1,14.28,100,1,12.43,700,1,14.45,100,1,12.42,700,1,14.52,100,1
2025-07-17T16:04:37.543063240Z,2025-07-17T16:04:37.543230680Z,160,2,1108,C,A,0,13.87,100,0,167440,273971035,ARL,326730517,13.11,100,1,13.65,15,1,13,2,1,13.66,100,1,12.98,200,2,13.68,15,1,12.86,100,1,13.69,100,1,12.73,100,1,13.87,100,1,12.71,100,1,13.94,2,1,12.5,700,1,14,100,1,12.46,100,1,14.28,100,1,12.43,700,1,14.45,100,1,12.42,700,1,14.52,100,1
2025-07-17T16:04:37.543064690Z,2025-07-17T16:04:37.543230680Z,160,2,1108,C,A,0,13.87,100,130,165990,273971037,ARL,326730521,13.11,100,1,13.65,15,1,13,2,1,13.66,100,1,12.98,200,2,13.68,15,1,12.86,100,1,13.69,100,1,12.73,100,1,13.94,2,1,12.71,100,1,14,100,1,12.5,700,1,14.28,100,1,12.46,100,1,14.45,100,1,12.43,700,1,14.52,100,1,12.42,700,1,14.56,800,2
2025-07-17T16:04:37.543077174Z,2025-07-17T16:04:37.543242390Z,160,2,1108,A,A,0,13.8,100,130,165216,273971040,ARL,328614525,13.11,100,1,13.65,15,1,13,2,1,13.66,100,1,12.98,200,2,13.68,15,1,12.86,100,1,13.69,100,1,12.73,100,1,13.8,100,1,12.71,100,1,13.94,2,1,12.5,700,1,14,100,1,12.46,100,1,14.28,100,1,12.43,700,1,14.45,100,1,12.42,700,1,14.52,100,1
2025-07-17T16:04:37.543078532Z,2025-07-17T16:04:37.543244193Z,160,2,1108,A,A,0,13.8,100,130,165661,273971041,ARL,328614529,13.11,100,1,13.65,15,1,13,2,1,13.66,100,1,12.98,200,2,13.68,15,1,12.86,100,1,13.69,100,1,12.73,100,1,13.8,200,2,12.71,100,1,13.94,2,1,12.5,700,1,14,100,1,12.46,100,1,14.28,100,1,12.43,700,1,14.45,100,1,12.42,700,1,14.52,100,1
2025-07-17T16:04:37.549519006Z,2025-07-17T16:04:37.549684713Z,160,2,1108,C,A,0,14,100,130,165707,273973481,ARL,327869193,13.11,100,1,13.65,15,1,13,2,1,13.66,100,1,12.98,200,2,13.68,15,1,12.86,100,1,13.69,100,1,12.73,100,1,13.8,200,2,12.71,100,1,13.94,2,1,12.5,700,1,14.28,100,1,12.46,100,1,14.45,100,1,12.43,700,1,14.52,100,1,12.42,700,1,14.56,800,2
2025-07-17T16:04:37.549570649Z,2025-07-17T16:04:37.549735824Z,160,2,1108,A,A,0,13.93,100,130,165175,273973485,ARL,328616925,13.11,100,1,13.65,15,1,13,2,1,13.66,100,1,12.98,200,2,13.68,15,1,12.86,100,1,13.69,100,1,12.73,100,1,13.8,200,2,12.71,100,1,13.93,100,1,12.5,700,1,13.94,2,1,12.46,100,1,14.28,100,1,12.43,700,1,14.45,100,1,12.42,700,1,14.52,100,1
2025-07-17T16:04:44.524360626Z,2025-07-17T16:04:44.524526545Z,160,2,1108,C,A,0,13.68,15,130,165919,274066152,ARL,328437797,13.11,100,1,13.65,15,1,13,2,1,13.66,100,1,12.98,200,2,13.69,100,1,12.86,100,1,13.8,200,2,12.73,100,1,13.93,100,1,12.71,100,1,13.94,2,1,12.5,700,1,14.28,100,1,12.46,100,1,14.45,100,1,12.43,700,1,14.52,100,1,12.42,700,1,14.56,800,2
2025-07-17T16:04:45.527835033Z,2025-07-17T16:04:45.528000143Z,160,2,1108,A,A,0,13.63,15,130,165110,274088918,ARL,328780565,13.11,100,1,13.63,15,1,13,2,1,13.65,15,1,12.98,200,2,13.66,100,1,12.86,100,1,13.69,100,1,12.73,100,1,13.8,200,2,12.71,100,1,13.93,100,1,12.5,700,1,13.94,2,1,12.46,100,1,14.28,100,1,12.43,700,1,14.45,100,1,12.42,700,1,14.52,100,1
2025-07-17T16:04:45.528464092Z,2025-07-17T16:04:45.528629613Z,160,2,1108,C,A,0,14.64,100,0,165521,274088922,ARL,327856309,13.11,100,1,13.63,15,1,13,2,1,13.65,15,1,12.98,200,2,13.66,100,1,12.86,100,1,13.69,100,1,12.73,100,1,13.8,200,2,12.71,100,1,13.93,100,1,12.5,700,1,13.94,2,1,12.46,100,1,14.28,100,1,12.43,700,1,14.45,100,1,12.42,700,1,14.52,100,1
2025-07-17T16:04:45.528464092Z,2025-07-17T16:04:45.528629613Z,160,2,1108,A,A,0,14.52,100,130,165521,274088922,ARL,328780577,13.11,100,1,13.63,15,1,13,2,1,13.65,15,1,12.98,200,2,13.66,100,1,12.86,100,1,13.69,100,1,12.73,100,1,13.8,200,2,12.71,100,1,13.93,100,1,12.5,700,1,13.94,2,1,12.46,100,1,14.28,100,1,12.43,700,1,14.45,100,1,12.42,700,1,14.52,200,2
2025-07-17T16:04:45.530252804Z,2025-07-17T16:04:45.530418278Z,160,2,1108,C,A,0,14.64,100,0,165474,274088937,ARL,327856297,13.11,100,1,13.63,15,1,13,2,1,13.65,15,1,12.98,200,2,13.66,100,1,12.86,100,1,13.69,100,1,12.73,100,1,13.8,200,2,12.71,100,1,13.93,100,1,12.5,700,1,13.94,2,1,12.46,100,1,14.28,100,1,12.43,700,1,14.45,100,1,12.42,700,1,14.52,200,2
2025-07-17T16:04:45.530252804Z,2025-07-17T16:04:45.530418278Z,160,2,1108,A,A,0,14.52,100,130,165474,274088937,ARL,328780597,13.11,100,1,13.63,15,1,13,2,1,13.65,15,1,12.98,200,2,13.66,100,1,12.86,100,1,13.69,100,1,12.73,100,1,13.8,200,2,12.71,100,1,13.93,100,1,12.5,700,1,13.94,2,1,12.46,100,1,14.28,100,1,12.43,700,1,14.45,100,1,12.42,700,1,14.52,300,3
2025-07-17T16:04:45.532901874Z,2025-07-17T16:04:45.533067029Z,160,2,1108,C,A,0,13.66,100,0,165155,274088955,ARL,328614509,13.11,100,1,13.63,15,1,13,2,1,13.65,15,1,12.98,200,2,13.69,100,1,12.86,100,1,13.8,200,2,12.73,100,1,13.93,100,1,12.71,100,1,13.94,2,1,12.5,700,1,14.28,100,1,12.46,100,1,14.45,100,1,12.43,700,1,14.52,300,3,12.42,700,1,14.56,800,2
2025-07-17T16:04:45.532901874Z,2025-07-17T16:04:45.533067029Z,160,2,1108,A,A,0,13.64,100,130,165155,274088955,ARL,328780669,13.11,100,1,13.63,15,1,13,2,1,13.64,100,1,12.98,200,2,13.65,15,1,12.86,100,1,13.69,100,1,12.73,100,1,13.8,200,2,12.71,100,1,13.93,100,1,12.5,700,1,13.94,2,1,12.46,100,1,14.28,100,1,12.43,700,1,14.45,100,1,12.42,700,1,14.52,300,3
2025-07-17T16:04:45.533639142Z,2025-07-17T16:04:45.533804768Z,160,2,1108,C,A,0,14.75,100,0,165626,274088957,ARL,328489481,13.11,100,1,13.63,15,1,13,2,1,13.64,100,1,12.98,200,2,13.65,15,1,12.86,100,1,13.69,100,1,12.73,100,1,13.8,200,2,12.71,100,1,13.93,100,1,12.5,700,1,13.94,2,1,12.46,100,1,14.28,100,1,12.43,700,1,14.45,100,1,12.42,700,1,14.52,300,3
2025-07-17T16:04:45.533639142Z,2025-07-17T16:04:45.533804768Z,160,2,1108,A,A,0,14.7,100,130,165626,274088957,ARL,328780685,13.11,100,1,13.63,15,1,13,2,1,13.64,100,1,12.98,200,2,13.65,15,1,12.86,100,1,13.69,100,1,12.73,100,1,13.8,200,2,12.71,100,1,13.93,100,1,12.5,700,1,13.94,2,1,12.46,100,1,14.28,100,1,12.43,700,1,14.45,100,1,12.42,700,1,14.52,300,3
2025-07-17T16:04:45.533705428Z,2025-07-17T16:04:45.533870711Z,160,2,1108,A,A,0,13.67,100,130,165283,274088959,ARL,328780689,13.11,100,1,13.63,15,1,13,2,1,13.64,100,1,12.98,200,2,13.65,15,1,12.86,100,1,13.67,100,1,12.73,100,1,13.69,100,1,12.71,100,1,13.8,200,2,12.5,700,1,13.93,100,1,12.46,100,1,13.94,2,1,12.43,700,1,14.28,100,1,12.42,700,1,14.45,100,1
2025-07-17T16:04:45.562972204Z,2025-07-17T16:04:45.563137443Z,160,2,1108,C,A,0,13.69,100,130,165239,274089319,ARL,328606289,13.11,100,1,13.63,15,1,13,2,1,13.64,100,1,12.98,200,2,13.65,15,1,12.86,100,1,13.67,100,1,12.73,100,1,13.8,200,2,12.71,100,1,13.93,100,1,12.5,700,1,13.94,2,1,12.46,100,1,14.28,100,1,12.43,700,1,14.45,100,1,12.42,700,1,14.52,300,3
2025-07-17T16:04:56.809584701Z,2025-07-17T16:04:56.809749973Z,160,2,1108,C,A,0,13.65,15,130,165272,274293432,ARL,328603377,13.11,100,1,13.63,15,1,13,2,1,13.64,100,1,12.98,200,2,13.67,100,1,12.86,100,1,13.8,200,2,12.73,100,1,13.93,100,1,12.71,100,1,13.94,2,1,12.5,700,1,14.28,100,1,12.46,100,1,14.45,100,1,12.43,700,1,14.52,300,3,12.42,700,1,14.56,800,2
2025-07-17T16:04:57.826913717Z,2025-07-17T16:04:57.827079009Z,160,2,1108,A,A,0,13.61,15,130,165292,274310244,ARL,329068341,13.11,100,1,13.61,15,1,13,2,1,13.63,15,1,12.98,200,2,13.64,100,1,12.86,100,1,13.67,100,1,12.73,100,1,13.8,200,2,12.71,100,1,13.93,100,1,12.5,700,1,13.94,2,1,12.46,100,1,14.28,100,1,12.43,700,1,14.45,100,1,12.42,700,1,14.52,300,3
2025-07-17T16:04:57.970451236Z,2025-07-17T16:04:57.970616610Z,160,2,1108,C,A,0,13.64,100,0,165374,274316281,ARL,328780669,13.11,100,1,13.61,15,1,13,2,1,13.63,15,1,12.98,200,2,13.67,100,1,12.86,100,1,13.8,200,2,12.73,100,1,13.93,100,1,12.71,100,1,13.94,2,1,12.5,700,1,14.28,100,1,12.46,100,1,14.45,100,1,12.43,700,1,14.52,300,3,12.42,700,1,14.56,800,2
2025-07-17T16:04:57.970451236Z,2025-07-17T16:04:57.970616610Z,160,2,1108,A,A,0,13.62,100,130,165374,274316281,ARL,329074609,13.11,100,1,13.61,15,1,13,2,1,13.62,100,1,12.98,200,2,13.63,15,1,12.86,100,1,13.67,100,1,12.73,100,1,13.8,200,2,12.71,100,1,13.93,100,1,12.5,700,1,13.94,2,1,12.46,100,1,14.28,100,1,12.43,700,1,14.45,100,1,12.42,700,1,14.52,300,3
2025-07-17T16:04:57.971193734Z,2025-07-17T16:04:57.971360344Z,160,2,1108,C,A,0,14.45,100,128,166610,274316507,ARL,325714601,13.11,100,1,13.61,15,1,13,2,1,13.62,100,1,12.98,200,2,13.63,15,1,12.86,100,1,13.67,100,1,12.73,100,1,13.8,200,2,12.71,100,1,13.93,100,1,12.5,700,1,13.94,2,1,12.46,100,1,14.28,100,1,12.43,700,1,14.52,300,3,12.42,700,1,14.56,800,2
2025-07-17T16:04:57.971552262Z,2025-07-17T16:04:57.971717511Z,160,2,1108,A,A,0,14.23,100,130,165249,274316527,ARL,329074833,13.11,100,1,13.61,15,1,13,2,1,13.62,100,1,12.98,200,2,13.63,15,1,12.86,100,1,13.67,100,1,12.73,100,1,13.8,200,2,12.71,100,1,13.93,100,1,12.5,700,1,13.94,2,1,12.46,100,1,14.23,100,1,12.43,700,1,14.28,100,1,12.42,700,1,14.52,300,3
2025-07-17T16:04:57.991966904Z,2025-07-17T16:04:57.992131878Z,160,2,1108,C,A,0,13.61,15,130,164974,274318490,ARL,329068341,13.11,100,1,13.62,100,1,13,2,1,13.63,15,1,12.98,200,2,13.67,100,1,12.86,100,1,13.8,200,2,12.73,100,1,13.93,100,1,12.71,100,1,13.94,2,1,12.5,700,1,14.23,100,1,12.46,100,1,14.28,100,1,12.43,700,1,14.52,300,3,12.42,700,1,14.56,800,2
2025-07-17T16:04:57.992976406Z,2025-07-17T16:04:57.993141438Z,160,2,1108,C,A,0,13.62,100,130,165032,274318579,ARL,329074609,13.11,100,1,13.63,15,1,13,2,1,13.67,100,1,12.98,200,2,13.8,200,2,12.86,100,1,13.93,100,1,12.73,100,1,13.94,2,1,12.71,100,1,14.23,100,1,12.5,700,1,14.28,100,1,12.46,100,1,14.52,300,3,12.43,700,1,14.56,800,2,12.42,700,1,14.6,700,1
2025-07-17T16:04:57.993143873Z,2025-07-17T16:04:57.993309561Z,160,2,1108,C,A,0,13.63,15,130,165688,274318603,ARL,328780565,13.11,100,1,13.67,100,1,13,2,1,13.8,200,2,12.98,200,2,13.93,100,1,12.86,100,1,13.94,2,1,12.73,100,1,14.23,100,1,12.71,100,1,14.28,100,1,12.5,700,1,14.52,300,3,12.46,100,1,14.56,800,2,12.43,700,1,14.6,700,1,12.42,700,1,14.68,1400,2
2025-07-17T16:04:58.002094377Z,2025-07-17T16:04:58.002259715Z,160,2,1108,C,A,0,13.67,100,130,165338,274319058,ARL,328780689,13.11,100,1,13.8,200,2,13,2,1,13.93,100,1,12.98,200,2,13.94,2,1,12.86,100,1,14.23,100,1,12.73,100,1,14.28,100,1,12.71,100,1,14.52,300,3,12.5,700,1,14.56,800,2,12.46,100,1,14.6,700,1,12.43,700,1,14.68,1400,2,12.42,700,1,14.7,300,3
2025-07-17T16:04:58.002823841Z,2025-07-17T16:04:58.002989430Z,160,2,1108,C,A,0,14.7,100,0,165589,274319069,ARL,328780685,13.11,100,1,13.8,200,2,13,2,1,13.93,100,1,12.98,200,2,13.94,2,1,12.86,100,1,14.23,100,1,12.73,100,1,14.28,100,1,12.71,100,1,14.52,300,3,12.5,700,1,14.56,800,2,12.46,100,1,14.6,700,1,12.43,700,1,14.68,1400,2,12.42,700,1,14.7,200,2
2025-07-17T16:04:58.002823841Z,2025-07-17T16:04:58.002989430Z,160,2,1108,A,A,0,14.87,100,130,165589,274319069,ARL,329078553,13.11,100,1,13.8,200,2,13,2,1,13.93,100,1,12.98,200,2,13.94,2,1,12.86,100,1,14.23,100,1,12.73,100,1,14.28,100,1,12.71,100,1,14.52,300,3,12.5,700,1,14.56,800,2,12.46,100,1,14.6,700,1,12.43,700,1,14.68,1400,2,12.42,700,1,14.7,200,2
2025-07-17T16:04:58.013739242Z,2025-07-17T16:04:58.013904697Z,160,2,1108,C,A,0,13.93,100,130,165455,274319298,ARL,328616925,13.11,100,1,13.8,200,2,13,2,1,13.94,2,1,12.98,200,2,14.23,100,1,12.86,100,1,14.28,100,1,12.73,100,1,14.52,300,3,12.71,100,1,14.56,800,2,12.5,700,1,14.6,700,1,12.46,100,1,14.68,1400,2,12.43,700,1,14.7,200,2,12.42,700,1,14.87,100,1
2025-07-17T16:04:58.013793974Z,2025-07-17T16:04:58.013959233Z,160,2,1108,A,A,0,14.08,100,130,165259,274319304,ARL,329078953,13.11,100,1,13.8,200,2,13,2,1,13.94,2,1,12.98,200,2,14.08,100,1,12.86,100,1,14.23,100,1,12.73,100,1,14.28,100,1,12.71,100,1,14.52,300,3,12.5,700,1,14.56,800,2,12.46,100,1,14.6,700,1,12.43,700,1,14.68,1400,2,12.42,700,1,14.7,200,2
2025-07-17T16:04:58.536452621Z,2025-07-17T16:04:58.536617917Z,160,2,1108,A,A,0,13.81,100,130,165296,274326535,ARL,329088265,13.11,100,1,13.8,200,2,13,2,1,13.81,100,1,12.98,200,2,13.94,2,1,12.86,100,1,14.08,100,1,12.73,100,1,14.23,100,1,12.71,100,1,14.28,100,1,12.5,700,1,14.52,300,3,12.46,100,1,14.56,800,2,12.43,700,1,14.6,700,1,12.42,700,1,14.68,1400,2
2025-07-17T16:05:46.593966383Z,2025-07-17T16:05:46.594131664Z,160,2,1108,A,A,0,13.76,100,130,165281,275083968,ARL,330066537,13.11,100,1,13.76,100,1,13,2,1,13.8,200,2,12.98,200,2,13.81,100,1,12.86,100,1,13.94,2,1,12.73,100,1,14.08,100,1,12.71,100,1,14.23,100,1,12.5,700,1,14.28,100,1,12.46,100,1,14.52,300,3,12.43,700,1,14.56,800,2,12.42,700,1,14.6,700,1
2025-07-17T16:05:46.594705962Z,2025-07-17T16:05:46.594871336Z,160,2,1108,C,A,0,14.87,100,0,165374,275083970,ARL,329078553,13.11,100,1,13.76,100,1,13,2,1,13.8,200,2,12.98,200,2,13.81,100,1,12.86,100,1,13.94,2,1,12.73,100,1,14.08,100,1,12.71,100,1,14.23,100,1,12.5,700,1,14.28,100,1,12.46,100,1,14.52,300,3,12.43,700,1,14.56,800,2,12.42,700,1,14.6,700,1
2025-07-17T16:05:46.594705962Z,2025-07-17T16:05:46.594871336Z,160,2,1108,A,A,0,14.83,100,130,165374,275083970,ARL,330066553,13.11,100,1,13.76,100,1,13,2,1,13.8,200,2,12.98,200,2,13.81,100,1,12.86,100,1,13.94,2,1,12.73,100,1,14.08,100,1,12.71,100,1,14.23,100,1,12.5,700,1,14.28,100,1,12.46,100,1,14.52,300,3,12.43,700,1,14.56,800,2,12.42,700,1,14.6,700,1
2025-07-17T16:05:46.995837526Z,2025-07-17T16:05:46.996003552Z,160,2,1108,C,A,0,13.81,100,0,166026,275092978,ARL,329088265,13.11,100,1,13.76,100,1,13,2,1,13.8,200,2,12.98,200,2,13.94,2,1,12.86,100,1,14.08,100,1,12.73,100,1,14.23,100,1,12.71,100,1,14.28,100,1,12.5,700,1,14.52,300,3,12.46,100,1,14.56,800,2,12.43,700,1,14.6,700,1,12.42,700,1,14.68,1400,2
2025-07-17T16:05:46.995837526Z,2025-07-17T16:05:46.996003552Z,160,2,1108,A,A,0,13.77,100,130,166026,275092978,ARL,330075425,13.11,100,1,13.76,100,1,13,2,1,13.77,100,1,12.98,200,2,13.8,200,2,12.86,100,1,13.94,2,1,12.73,100,1,14.08,100,1,12.71,100,1,14.23,100,1,12.5,700,1,14.28,100,1,12.46,100,1,14.52,300,3,12.43,700,1,14.56,800,2,12.42,700,1,14.6,700,1
2025-07-17T16:05:50.680167632Z,2025-07-17T16:05:50.680333151Z,160,2,1108,A,A,0,13.68,15,130,165519,275152014,ARL,330143813,13.11,100,1,13.68,15,1,13,2,1,13.76,100,1,12.98,200,2,13.77,100,1,12.86,100,1,13.8,200,2,12.73,100,1,13.94,2,1,12.71,100,1,14.08,100,1,12.5,700,1,14.23,100,1,12.46,100,1,14.28,100,1,12.43,700,1,14.52,300,3,12.42,700,1,14.56,800,2
2025-07-17T16:05:50.697005084Z,2025-07-17T16:05:50.697170320Z,160,2,1108,A,A,0,13.72,100,130,165236,275152383,ARL,330144301,13.11,100,1,13.68,15,1,13,2,1,13.72,100,1,12.98,200,2,13.76,100,1,12.86,100,1,13.77,100,1,12.73,100,1,13.8,200,2,12.71,100,1,13.94,2,1,12.5,700,1,14.08,100,1,12.46,100,1,14.23,100,1,12.43,700,1,14.28,100,1,12.42,700,1,14.52,300,3
2025-07-17T16:05:50.697739933Z,2025-07-17T16:05:50.697905372Z,160,2,1108,C,A,0,14.83,100,0,165439,275152385,ARL,330066553,13.11,100,1,13.68,15,1,13,2,1,13.72,100,1,12.98,200,2,13.76,100,1,12.86,100,1,13.77,100,1,12.73,100,1,13.8,200,2,12.71,100,1,13.94,2,1,12.5,700,1,14.08,100,1,12.46,100,1,14.23,100,1,12.43,700,1,14.28,100,1,12.42,700,1,14.52,300,3
2025-07-17T16:05:50.697739933Z,2025-07-17T16:05:50.697905372Z,160,2,1108,A,A,0,14.78,100,130,165439,275152385,ARL,330144321,13.11,100,1,13.68,15,1,13,2,1,13.72,100,1,12.98,200,2,13.76,100,1,12.86,100,1,13.77,100,1,12.73,100,1,13.8,200,2,12.71,100,1,13.94,2,1,12.5,700,1,14.08,100,1,12.46,100,1,14.23,100,1,12.43,700,1,14.28,100,1,12.42,700,1,14.52,300,3
2025-07-17T16:05:50.704366332Z,2025-07-17T16:05:50.704531748Z,160,2,1108,C,A,0,13.76,100,130,165416,275152443,ARL,330066537,13.11,100,1,13.68,15,1,13,2,1,13.72,100,1,12.98,200,2,13.77,100,1,12.86,100,1,13.8,200,2,12.73,100,1,13.94,2,1,12.71,100,1,14.08,100,1,12.5,700,1,14.23,100,1,12.46,100,1,14.28,100,1,12.43,700,1,14.52,300,3,12.42,700,1,14.56,800,2
2025-07-17T16:05:50.708714027Z,2025-07-17T16:05:50.708879311Z,160,2,1108,C,A,0,14.08,100,130,165284,275152465,ARL,329078953,13.11,100,1,13.68,15,1,13,2,1,13.72,100,1,12.98,200,2,13.77,100,1,12.86,100,1,13.8,200,2,12.73,100,1,13.94,2,1,12.71,100,1,14.23,100,1,12.5,700,1,14.28,100,1,12.46,100,1,14.52,300,3,12.43,700,1,14.56,800,2,12.42,700,1,14.6,700,1
2025-07-17T16:05:50.708766050Z,2025-07-17T16:05:50.708931189Z,160,2,1108,A,A,0,13.99,100,130,165139,275152466,ARL,330144513,13.11,100,1,13.68,15,1,13,2,1,13.72,100,1,12.98,200,2,13.77,100,1,12.86,100,1,13.8,200,2,12.73,100,1,13.94,2,1,12.71,100,1,13.99,100,1,12.5,700,1,14.23,100,1,12.46,100,1,14.28,100,1,12.43,700,1,14.52,300,3,12.42,700,1,14.56,800,2
2025-07-17T16:05:50.913310799Z,2025-07-17T16:05:50.913476268Z,160,2,1108,C,A,0,13.77,100,0,165469,275159685,ARL,330075425,13.11,100,1,13.68,15,1,13,2,1,13.72,100,1,12.98,200,2,13.8,200,2,12.86,100,1,13.94,2,1,12.73,100,1,13.99,100,1,12.71,100,1,14.23,100,1,12.5,700,1,14.28,100,1,12.46,100,1,14.52,300,3,12.43,700,1,14.56,800,2,12.42,700,1,14.6,700,1
2025-07-17T16:05:50.913310799Z,2025-07-17T16:05:50.913476268Z,160,2,1108,A,A,0,13.69,100,130,165469,275159685,ARL,330151389,13.11,100,1,13.68,15,1,13,2,1,13.69,100,1,12.98,200,2,13.72,100,1,12.86,100,1,13.8,200,2,12.73,100,1,13.94,2,1,12.71,100,1,13.99,100,1,12.5,700,1,14.23,100,1,12.46,100,1,14.28,100,1,12.43,700,1,14.52,300,3,12.42,700,1,14.56,800,2
2025-07-17T16:05:59.704790753Z,2025-07-17T16:05:59.704955970Z,160,2,1108,A,A,0,13.64,15,130,165217,275325555,ARL,330357473,13.11,100,1,13.64,15,1,13,2,1,13.68,15,1,12.98,200,2,13.69,100,1,12.86,100,1,13.72,100,1,12.73,100,1,13.8,200,2,12.71,100,1,13.94,2,1,12.5,700,1,13.99,100,1,12.46,100,1,14.23,100,1,12.43,700,1,14.28,100,1,12.42,700,1,14.52,300,3
2025-07-17T16:05:59.714925412Z,2025-07-17T16:05:59.715090662Z,160,2,1108,A,A,0,13.68,100,130,165250,275325807,ARL,330357633,13.11,100,1,13.64,15,1,13,2,1,13.68,115,2,12.98,200,2,13.69,100,1,12.86,100,1,13.72,100,1,12.73,100,1,13.8,200,2,12.71,100,1,13.94,2,1,12.5,700,1,13.99,100,1,12.46,100,1,14.23,100,1,12.43,700,1,14.28,100,1,12.42,700,1,14.52,300,3
2025-07-17T16:05:59.722730507Z,2025-07-17T16:05:59.722895750Z,160,2,1108,C,A,0,13.72,100,130,165243,275325854,ARL,330144301,13.11,100,1,13.64,15,1,13,2,1,13.68,115,2,12.98,200,2,13.69,100,1,12.86,100,1,13.8,200,2,12.73,100,1,13.94,2,1,12.71,100,1,13.99,100,1,12.5,700,1,14.23,100,1,12.46,100,1,14.28,100,1,12.43,700,1,14.52,300,3,12.42,700,1,14.56,800,2
2025-07-17T16:05:59.802596747Z,2025-07-17T16:05:59.802762087Z,160,2,1108,C,A,0,13.69,100,0,165340,275327082,ARL,330151389,13.11,100,1,13.64,15,1,13,2,1,13.68,115,2,12.98,200,2,13.8,200,2,12.86,100,1,13.94,2,1,12.73,100,1,13.99,100,1,12.71,100,1,14.23,100,1,12.5,700,1,14.28,100,1,12.46,100,1,14.52,300,3,12.43,700,1,14.56,800,2,12.42,700,1,14.6,700,1
2025-07-17T16:05:59.802596747Z,2025-07-17T16:05:59.802762087Z,160,2,1108,A,A,0,13.65,100,130,165340,275327082,ARL,330359197,13.11,100,1,13.64,15,1,13,2,1,13.65,100,1,12.98,200,2,13.68,115,2,12.86,100,1,13.8,200,2,12.73,100,1,13.94,2,1,12.71,100,1,13.99,100,1,12.5,700,1,14.23,100,1,12.46,100,1,14.28,100,1,12.43,700,1,14.52,300,3,12.42,700,1,14.56,800,2
2025-07-17T16:05:59.803338996Z,2025-07-17T16:05:59.803504658Z,160,2,1108,C,A,0,14.78,100,0,165662,275327093,ARL,330144321,13.11,100,1,13.64,15,1,13,2,1,13.65,100,1,12.98,200,2,13.68,115,2,12.86,100,1,13.8,200,2,12.73,100,1,13.94,2,1,12.71,100,1,13.99,100,1,12.5,700,1,14.23,100,1,12.46,100,1,14.28,100,1,12.43,700,1,14.52,300,3,12.42,700,1,14.56,800,2
2025-07-17T16:05:59.803338996Z,2025-07-17T16:05:59.803504658Z,160,2,1108,A,A,0,14.71,100,130,165662,275327093,ARL,330359225,13.11,100,1,13.64,15,1,13,2,1,13.65,100,1,12.98,200,2,13.68,115,2,12.86,100,1,13.8,200,2,12.73,100,1,13.94,2,1,12.71,100,1,13.99,100,1,12.5,700,1,14.23,100,1,12.46,100,1,14.28,100,1,12.43,700,1,14.52,300,3,12.42,700,1,14.56,800,2
2025-07-17T16:05:59.827622529Z,2025-07-17T16:05:59.827787837Z,160,2,1108,C,A,0,13.99,100,130,165308,275327416,ARL,330144513,13.11,100,1,13.64,15,1,13,2,1,13.65,100,1,12.98,200,2,13.68,115,2,12.86,100,1,13.8,200,2,12.73,100,1,13.94,2,1,12.71,100,1,14.23,100,1,12.5,700,1,14.28,100,1,12.46,100,1,14.52,300,3,12.43,700,1,14.56,800,2,12.42,700,1,14.6,700,1
2025-07-17T16:05:59.827674437Z,2025-07-17T16:05:59.827839802Z,160,2,1108,A,A,0,13.92,100,130,165365,275327417,ARL,330359625,13.11,100,1,13.64,15,1,13,2,1,13.65,100,1,12.98,200,2,13.68,115,2,12.86,100,1,13.8,200,2,12.73,100,1,13.92,100,1,12.71,100,1,13.94,2,1,12.5,700,1,14.23,100,1,12.46,100,1,14.28,100,1,12.43,700,1,14.52,300,3,12.42,700,1,14.56,800,2
2025-07-17T16:06:02.724280161Z,2025-07-17T16:06:02.724446337Z,160,2,1108,C,A,0,13.68,15,128,166176,275430576,ARL,330143813,13.11,100,1,13.64,15,1,13,2,1,13.65,100,1,12.98,200,2,13.68,100,1,12.86,100,1,13.8,200,2,12.73,100,1,13.92,100,1,12.71,100,1,13.94,2,1,12.5,700,1,14.23,100,1,12.46,100,1,14.28,100,1,12.43,700,1,14.52,300,3,12.42,700,1,14.56,800,2
2025-07-17T16:06:03.729212428Z,2025-07-17T16:06:03.729377770Z,160,2,1108,A,A,0,13.62,15,130,165342,275517342,ARL,330577045,13.11,100,1,13.62,15,1,13,2,1,13.64,15,1,12.98,200,2,13.65,100,1,12.86,100,1,13.68,100,1,12.73,100,1,13.8,200,2,12.71,100,1,13.92,100,1,12.5,700,1,13.94,2,1,12.46,100,1,14.23,100,1,12.43,700,1,14.28,100,1,12.42,700,1,14.52,300,3
2025-07-17T16:06:03.738332427Z,2025-07-17T16:06:03.738497645Z,160,2,1108,A,A,0,13.65,100,130,165218,275517997,ARL,330577773,13.11,100,1,13.62,15,1,13,2,1,13.64,15,1,12.98,200,2,13.65,200,2,12.86,100,1,13.68,100,1,12.73,100,1,13.8,200,2,12.71,100,1,13.92,100,1,12.5,700,1,13.94,2,1,12.46,100,1,14.23,100,1,12.43,700,1,14.28,100,1,12.42,700,1,14.52,300,3
2025-07-17T16:06:03.747330178Z,2025-07-17T16:06:03.747495669Z,160,2,1108,C,A,0,13.68,100,130,165491,275518621,ARL,330357633,13.11,100,1,13.62,15,1,13,2,1,13.64,15,1,12.98,200,2,13.65,200,2,12.86,100,1,13.8,200,2,12.73,100,1,13.92,100,1,12.71,100,1,13.94,2,1,12.5,700,1,14.23,100,1,12.46,100,1,14.28,100,1,12.43,700,1,14.52,300,3,12.42,700,1,14.56,800,2
2025-07-17T16:06:03.887107153Z,2025-07-17T16:06:03.887274670Z,160,2,1108,C,A,0,13.65,100,0,167517,275532429,ARL,330359197,13.11,100,1,13.62,15,1,13,2,1,13.64,15,1,12.98,200,2,13.65,100,1,12.86,100,1,13.8,200,2,12.73,100,1,13.92,100,1,12.71,100,1,13.94,2,1,12.5,700,1,14.23,100,1,12.46,100,1,14.28,100,1,12.43,700,1,14.52,300,3,12.42,700,1,14.56,800,2
2025-07-17T16:06:03.887107153Z,2025-07-17T16:06:03.887274670Z,160,2,1108,A,A,0,13.63,100,130,167517,275532429,ARL,330592465,13.11,100,1,13.62,15,1,13,2,1,13.63,100,1,12.98,200,2,13.64,15,1,12.86,100,1,13.65,100,1,12.73,100,1,13.8,200,2,12.71,100,1,13.92,100,1,12.5,700,1,13.94,2,1,12.46,100,1,14.23,100,1,12.43,700,1,14.28,100,1,12.42,700,1,14.52,300,3
2025-07-17T16:06:07.509885114Z,2025-07-17T16:06:07.510050758Z,160,2,1108,C,A,0,13.64,15,130,165644,275647392,ARL,330357473,13.11,100,1,13.62,15,1,13,2,1,13.63,100,1,12.98,200,2,13.65,100,1,12.86,100,1,13.8,200,2,12.73,100,1,13.92,100,1,12.71,100,1,13.94,2,1,12.5,700,1,14.23,100,1,12.46,100,1,14.28,100,1,12.43,700,1,14.52,300,3,12.42,700,1,14.56,800,2
2025-07-17T16:06:09.884978592Z,2025-07-17T16:06:09.885143909Z,160,2,1108,A,A,0,13.6,15,130,165317,275699092,ARL,330788421,13.11,100,1,13.6,15,1,13,2,1,13.62,15,1,12.98,200,2,13.63,100,1,12.86,100,1,13.65,100,1,12.73,100,1,13.8,200,2,12.71,100,1,13.92,100,1,12.5,700,1,13.94,2,1,12.46,100,1,14.23,100,1,12.43,700,1,14.28,100,1,12.42,700,1,14.52,300,3
2025-07-17T16:06:09.967442600Z,2025-07-17T16:06:09.967608061Z,160,2,1108,C,A,0,13.63,100,0,165461,275700261,ARL,330592465,13.11,100,1,13.6,15,1,13,2,1,13.62,15,1,12.98,200,2,13.65,100,1,12.86,100,1,13.8,200,2,12.73,100,1,13.92,100,1,12.71,100,1,13.94,2,1,12.5,700,1,14.23,100,1,12.46,100,1,14.28,100,1,12.43,700,1,14.52,300,3,12.42,700,1,14.56,800,2
2025-07-17T16:06:09.967442600Z,2025-07-17T16:06:09.967608061Z,160,2,1108,A,A,0,13.61,100,130,165461,275700261,ARL,330789481,13.11,100,1,13.6,15,1,13,2,1,13.61,100,1,12.98,200,2,13.62,15,1,12.86,100,1,13.65,100,1,12.73,100,1,13.8,200,2,12.71,100,1,13.92,100,1,12.5,700,1,13.94,2,1,12.46,100,1,14.23,100,1,12.43,700,1,14.28,100,1,12.42,700,1,14.52,300,3
2025-07-17T16:06:09.968186617Z,2025-07-17T16:06:09.968352066Z,160,2,1108,C,A,0,14.71,100,0,165449,275700270,ARL,330359225,13.11,100,1,13.6,15,1,13,2,1,13.61,100,1,12.98,200,2,13.62,15,1,12.86,100,1,13.65,100,1,12.73,100,1,13.8,200,2,12.71,100,1,13.92,100,1,12.5,700,1,13.94,2,1,12.46,100,1,14.23,100,1,12.43,700,1,14.28,100,1,12.42,700,1,14.52,300,3
2025-07-17T16:06:09.968186617Z,2025-07-17T16:06:09.968352066Z,160,2,1108,A,A,0,14.67,100,130,165449,275700270,ARL,330789501,13.11,100,1,13.6,15,1,13,2,1,13.61,100,1,12.98,200,2,13.62,15,1,12.86,100,1,13.65,100,1,12.73,100,1,13.8,200,2,12.71,100,1,13.92,100,1,12.5,700,1,13.94,2,1,12.46,100,1,14.23,100,1,12.43,700,1,14.28,100,1,12.42,700,1,14.52,300,3
2025-07-17T16:06:09.969875190Z,2025-07-17T16:06:09.970040686Z,160,2,1108,C,A,0,17.44,100,0,165496,275700282,ARL,327870217,13.11,100,1,13.6,15,1,13,2,1,13.61,100,1,12.98,200,2,13.62,15,1,12.86,100,1,13.65,100,1,12.73,100,1,13.8,200,2,12.71,100,1,13.92,100,1,12.5,700,1,13.94,2,1,12.46,100,1,14.23,100,1,12.43,700,1,14.28,100,1,12.42,700,1,14.52,300,3
2025-07-17T16:06:09.969875190Z,2025-07-17T16:06:09.970040686Z,160,2,1108,A,A,0,17.29,100,130,165496,275700282,ARL,330789509,13.11,100,1,13.6,15,1,13,2,1,13.61,100,1,12.98,200,2,13.62,15,1,12.86,100,1,13.65,100,1,12.73,100,1,13.8,200,2,12.71,100,1,13.92,100,1,12.5,700,1,13.94,2,1,12.46,100,1,14.23,100,1,12.43,700,1,14.28,100,1,12.42,700,1,14.52,300,3
2025-07-17T16:06:20.470724464Z,2025-07-17T16:06:20.470889851Z,160,2,1108,A,A,0,13.63,100,130,165387,275896138,ARL,331018065,13.11,100,1,13.6,15,1,13,2,1,13.61,100,1,12.98,200,2,13.62,15,1,12.86,100,1,13.63,100,1,12.73,100,1,13.65,100,1,12.71,100,1,13.8,200,2,12.5,700,1,13.92,100,1,12.46,100,1,13.94,2,1,12.43,700,1,14.23,100,1,12.42,700,1,14.28,100,1
2025-07-17T16:06:20.477432988Z,2025-07-17T16:06:20.477598578Z,160,2,1108,C,A,0,13.65,100,130,165590,275896242,ARL,330577773,13.11,100,1,13.6,15,1,13,2,1,13.61,100,1,12.98,200,2,13.62,15,1,12.86,100,1,13.63,100,1,12.73,100,1,13.8,200,2,12.71,100,1,13.92,100,1,12.5,700,1,13.94,2,1,12.46,100,1,14.23,100,1,12.43,700,1,14.28,100,1,12.42,700,1,14.52,300,3
2025-07-17T16:06:20.810998706Z,2025-07-17T16:06:20.811164178Z,160,2,1108,C,A,0,13.62,15,130,165472,275900161,ARL,330577045,13.11,100,1,13.6,15,1,13,2,1,13.61,100,1,12.98,200,2,13.63,100,1,12.86,100,1,13.8,200,2,12.73,100,1,13.92,100,1,12.71,100,1,13.94,2,1,12.5,700,1,14.23,100,1,12.46,100,1,14.28,100,1,12.43,700,1,14.52,300,3,12.42,700,1,14.56,800,2
2025-07-17T16:06:22.151057292Z,2025-07-17T16:06:22.151222819Z,160,2,1108,A,A,0,13.58,15,130,165527,275926927,ARL,331050981,13.11,100,1,13.58,15,1,13,2,1,13.6,15,1,12.98,200,2,13.61,100,1,12.86,100,1,13.63,100,1,12.73,100,1,13.8,200,2,12.71,100,1,13.92,100,1,12.5,700,1,13.94,2,1,12.46,100,1,14.23,100,1,12.43,700,1,14.28,100,1,12.42,700,1,14.52,300,3
2025-07-17T16:06:22.151326300Z,2025-07-17T16:06:22.151491832Z,160,2,1108,C,A,0,13.61,100,0,165532,275926940,ARL,330789481,13.11,100,1,13.58,15,1,13,2,1,13.6,15,1,12.98,200,2,13.63,100,1,12.86,100,1,13.8,200,2,12.73,100,1,13.92,100,1,12.71,100,1,13.94,2,1,12.5,700,1,14.23,100,1,12.46,100,1,14.28,100,1,12.43,700,1,14.52,300,3,12.42,700,1,14.56,800,2
2025-07-17T16:06:22.151326300Z,2025-07-17T16:06:22.151491832Z,160,2,1108,A,A,0,13.59,100,130,165532,275926940,ARL,331050989,13.11,100,1,13.58,15,1,13,2,1,13.59,100,1,12.98,200,2,13.6,15,1,12.86,100,1,13.63,100,1,12.73,100,1,13.8,200,2,12.71,100,1,13.92,100,1,12.5,700,1,13.94,2,1,12.46,100,1,14.23,100,1,12.43,700,1,14.28,100,1,12.42,700,1,14.52,300,3
2025-07-17T16:06:22.151595415Z,2025-07-17T16:06:22.151761329Z,160,2,1108,C,A,0,13.8,100,0,165914,275926966,ARL,328614525,13.11,100,1,13.58,15,1,13,2,1,13.59,100,1,12.98,200,2,13.6,15,1,12.86,100,1,13.63,100,1,12.73,100,1,13.8,100,1,12.71,100,1,13.92,100,1,12.5,700,1,13.94,2,1,12.46,100,1,14.23,100,1,12.43,700,1,14.28,100,1,12.42,700,1,14.52,300,3
2025-07-17T16:06:22.151595781Z,2025-07-17T16:06:22.151761329Z,160,2,1108,C,A,0,13.8,100,130,165548,275926967,ARL,328614529,13.11,100,1,13.58,15,1,13,2,1,13.59,100,1,12.98,200,2,13.6,15,1,12.86,100,1,13.63,100,1,12.73,100,1,13.92,100,1,12.71,100,1,13.94,2,1,12.5,700,1,14.23,100,1,12.46,100,1,14.28,100,1,12.43,700,1,14.52,300,3,12.42,700,1,14.56,800,2
2025-07-17T16:06:22.152983326Z,2025-07-17T16:06:22.153148893Z,160,2,1108,C,A,0,15.79,100,0,165567,275927034,ARL,327870361,13.11,100,1,13.58,15,1,13,2,1,13.59,100,1,12.98,200,2,13.6,15,1,12.86,100,1,13.63,100,1,12.73,100,1,13.92,100,1,12.71,100,1,13.94,2,1,12.5,700,1,14.23,100,1,12.46,100,1,14.28,100,1,12.43,700,1,14.52,300,3,12.42,700,1,14.56,800,2
2025-07-17T16:06:22.152983326Z,2025-07-17T16:06:22.153148893Z,160,2,1108,A,A,0,15.63,100,130,165567,275927034,ARL,331051145,13.11,100,1,13.58,15,1,13,2,1,13.59,100,1,12.98,200,2,13.6,15,1,12.86,100,1,13.63,100,1,12.73,100,1,13.92,100,1,12.71,100,1,13.94,2,1,12.5,700,1,14.23,100,1,12.46,100,1,14.28,100,1,12.43,700,1,14.52,300,3,12.42,700,1,14.56,800,2
2025-07-17T16:06:22.153749481Z,2025-07-17T16:06:22.153916169Z,160,2,1108,C,A,0,14.7,100,0,166688,275927046,ARL,327868421,13.11,100,1,13.58,15,1,13,2,1,13.59,100,1,12.98,200,2,13.6,15,1,12.86,100,1,13.63,100,1,12.73,100,1,13.92,100,1,12.71,100,1,13.94,2,1,12.5,700,1,14.23,100,1,12.46,100,1,14.28,100,1,12.43,700,1,14.52,300,3,12.42,700,1,14.56,800,2
2025-07-17T16:06:22.153749481Z,2025-07-17T16:06:22.153916169Z,160,2,1108,A,A,0,14.55,100,130,166688,275927046,ARL,331051173,13.11,100,1,13.58,15,1,13,2,1,13.59,100,1,12.98,200,2,13.6,15,1,12.86,100,1,13.63,100,1,12.73,100,1,13.92,100,1,12.71,100,1,13.94,2,1,12.5,700,1,14.23,100,1,12.46,100,1,14.28,100,1,12.43,700,1,14.52,300,3,12.42,700,1,14.55,100,1
2025-07-17T16:06:22.155905240Z,2025-07-17T16:06:22.156070698Z,160,2,1108,C,A,0,14.52,100,0,165458,275927117,ARL,327869529,13.11,100,1,13.58,15,1,13,2,1,13.59,100,1,12.98,200,2,13.6,15,1,12.86,100,1,13.63,100,1,12.73,100,1,13.92,100,1,12.71,100,1,13.94,2,1,12.5,700,1,14.23,100,1,12.46,100,1,14.28,100,1,12.43,700,1,14.52,200,2,12.42,700,1,14.55,100,1
2025-07-17T16:06:22.155905240Z,2025-07-17T16:06:22.156070698Z,160,2,1108,A,A,0,14.38,100,130,165458,275927117,ARL,331051369,13.11,100,1,13.58,15,1,13,2,1,13.59,100,1,12.98,200,2,13.6,15,1,12.86,100,1,13.63,100,1,12.73,100,1,13.92,100,1,12.71,100,1,13.94,2,1,12.5,700,1,14.23,100,1,12.46,100,1,14.28,100,1,12.43,700,1,14.38,100,1,12.42,700,1,14.52,200,2
2025-07-17T16:06:22.177879233Z,2025-07-17T16:06:22.178044675Z,160,2,1108,C,A,0,14.7,100,0,165442,275927444,ARL,327873009,13.11,100,1,13.58,15,1,13,2,1,13.59,100,1,12.98,200,2,13.6,15,1,12.86,100,1,13.63,100,1,12.73,100,1,13.92,100,1,12.71,100,1,13.94,2,1,12.5,700,1,14.23,100,1,12.46,100,1,14.28,100,1,12.43,700,1,14.38,100,1,12.42,700,1,14.52,200,2
2025-07-17T16:06:22.177879233Z,2025-07-17T16:06:22.178044675Z,160,2,1108,A,A,0,14.55,100,130,165442,275927444,ARL,331052197,13.11,100,1,13.58,15,1,13,2,1,13.59,100,1,12.98,200,2,13.6,15,1,12.86,100,1,13.63,100,1,12.73,100,1,13.92,100,1,12.71,100,1,13.94,2,1,12.5,700,1,14.23,100,1,12.46,100,1,14.28,100,1,12.43,700,1,14.38,100,1,12.42,700,1,14.52,200,2
2025-07-17T16:06:24.519345743Z,2025-07-17T16:06:24.519511128Z,160,2,1108,A,A,0,13.6,100,130,165385,275968354,ARL,331104725,13.11,100,1,13.58,15,1,13,2,1,13.59,100,1,12.98,200,2,13.6,115,2,12.86,100,1,13.63,100,1,12.73,100,1,13.92,100,1,12.71,100,1,13.94,2,1,12.5,700,1,14.23,100,1,12.46,100,1,14.28,100,1,12.43,700,1,14.38,100,1,12.42,700,1,14.52,200,2
2025-07-17T16:06:24.526194457Z,2025-07-17T16:06:24.526359716Z,160,2,1108,C,A,0,13.63,100,130,165259,275968393,ARL,331018065,13.11,100,1,13.58,15,1,13,2,1,13.59,100,1,12.98,200,2,13.6,115,2,12.86,100,1,13.92,100,1,12.73,100,1,13.94,2,1,12.71,100,1,14.23,100,1,12.5,700,1,14.28,100,1,12.46,100,1,14.38,100,1,12.43,700,1,14.52,200,2,12.42,700,1,14.55,200,2
2025-07-17T16:06:26.610180184Z,2025-07-17T16:06:26.610345800Z,160,2,1108,C,A,0,13.94,2,0,165616,276013080,ARL,328351217,13.11,100,1,13.58,15,1,13,2,1,13.59,100,1,12.98,200,2,13.6,115,2,12.86,100,1,13.92,100,1,12.73,100,1,14.23,100,1,12.71,100,1,14.28,100,1,12.5,700,1,14.38,100,1,12.46,100,1,14.52,200,2,12.43,700,1,14.55,200,2,12.42,700,1,14.56,800,2
2025-07-17T16:06:26.610180184Z,2025-07-17T16:06:26.610345800Z,160,2,1108,A,A,0,13.85,2,130,165616,276013080,ARL,331155889,13.11,100,1,13.58,15,1,13,2,1,13.59,100,1,12.98,200,2,13.6,115,2,12.86,100,1,13.85,2,1,12.73,100,1,13.92,100,1,12.71,100,1,14.23,100,1,12.5,700,1,14.28,100,1,12.46,100,1,14.38,100,1,12.43,700,1,14.52,200,2,12.42,700,1,14.55,200,2
2025-07-17T16:06:30.625711923Z,2025-07-17T16:06:30.625877214Z,160,2,1108,A,A,0,14.27,700,130,165291,276103282,ARL,331257169,13.11,100,1,13.58,15,1,13,2,1,13.59,100,1,12.98,200,2,13.6,115,2,12.86,100,1,13.85,2,1,12.73,100,1,13.92,100,1,12.71,100,1,14.23,100,1,12.5,700,1,14.27,700,1,12.46,100,1,14.28,100,1,12.43,700,1,14.38,100,1,12.42,700,1,14.52,200,2
2025-07-17T16:06:30.625790910Z,2025-07-17T16:06:30.625956307Z,160,2,1108,C,A,0,14.68,700,130,165397,276103283,ARL,325716945,13.11,100,1,13.58,15,1,13,2,1,13.59,100,1,12.98,200,2,13.6,115,2,12.86,100,1,13.85,2,1,12.73,100,1,13.92,100,1,12.71,100,1,14.23,100,1,12.5,700,1,14.27,700,1,12.46,100,1,14.28,100,1,12.43,700,1,14.38,100,1,12.42,700,1,14.52,200,2
2025-07-17T16:06:31.127662311Z,2025-07-17T16:06:31.127827805Z,160,2,1108,A,A,0,14.48,700,130,165494,276118990,ARL,331272997,13.11,100,1,13.58,15,1,13,2,1,13.59,100,1,12.98,200,2,13.6,115,2,12.86,100,1,13.85,2,1,12.73,100,1,13.92,100,1,12.71,100,1,14.23,100,1,12.5,700,1,14.27,700,1,12.46,100,1,14.28,100,1,12.43,700,1,14.38,100,1,12.42,700,1,14.48,700,1
2025-07-17T16:06:31.128416336Z,2025-07-17T16:06:31.128581831Z,160,2,1108,C,A,0,14.68,700,130,165495,276119017,ARL,289932801,13.11,100,1,13.58,15,1,13,2,1,13.59,100,1,12.98,200,2,13.6,115,2,12.86,100,1,13.85,2,1,12.73,100,1,13.92,100,1,12.71,100,1,14.23,100,1,12.5,700,1,14.27,700,1,12.46,100,1,14.28,100,1,12.43,700,1,14.38,100,1,12.42,700,1,14.48,700,1
2025-07-17T16:06:31.990483799Z,2025-07-17T16:06:31.990649229Z,160,2,1108,C,A,0,13.6,15,130,165430,276135226,ARL,330788421,13.11,100,1,13.58,15,1,13,2,1,13.59,100,1,12.98,200,2,13.6,100,1,12.86,100,1,13.85,2,1,12.73,100,1,13.92,100,1,12.71,100,1,14.23,100,1,12.5,700,1,14.27,700,1,12.46,100,1,14.28,100,1,12.43,700,1,14.38,100,1,12.42,700,1,14.48,700,1
2025-07-17T16:06:42.812641697Z,2025-07-17T16:06:42.812807096Z,160,2,1108,A,A,0,13.56,15,130,165399,276276783,ARL,331488089,13.11,100,1,13.56,15,1,13,2,1,13.58,15,1,12.98,200,2,13.59,100,1,12.86,100,1,13.6,100,1,12.73,100,1,13.85,2,1,12.71,100,1,13.92,100,1,12.5,700,1,14.23,100,1,12.46,100,1,14.27,700,1,12.43,700,1,14.28,100,1,12.42,700,1,14.38,100,1
2025-07-17T16:06:43.012799164Z,2025-07-17T16:06:43.012965957Z,160,2,1108,C,A,0,13.59,100,0,166793,276279311,ARL,331050989,13.11,100,1,13.56,15,1,13,2,1,13.58,15,1,12.98,200,2,13.6,100,1,12.86,100,1,13.85,2,1,12.73,100,1,13.92,100,1,12.71,100,1,14.23,100,1,12.5,700,1,14.27,700,1,12.46,100,1,14.28,100,1,12.43,700,1,14.38,100,1,12.42,700,1,14.48,700,1
2025-07-17T16:06:43.012799164Z,2025-07-17T16:06:43.012965957Z,160,2,1108,A,A,0,13.57,100,128,166793,276279311,ARL,331491049,13.11,100,1,13.56,15,1,13,2,1,13.57,100,1,12.98,200,2,13.58,15,1,12.86,100,1,13.6,100,1,12.73,100,1,13.85,2,1,12.71,100,1,13.92,100,1,12.5,700,1,14.23,100,1,12.46,100,1,14.27,700,1,12.43,700,1,14.28,100,1,12.42,700,1,14.38,100,1
2025-07-17T16:06:43.013550575Z,2025-07-17T16:06:43.013716205Z,160,2,1108,C,A,0,14.67,100,0,165630,276279331,ARL,330789501,13.11,100,1,13.56,15,1,13,2,1,13.57,100,1,12.98,200,2,13.58,15,1,12.86,100,1,13.6,100,1,12.73,100,1,13.85,2,1,12.71,100,1,13.92,100,1,12.5,700,1,14.23,100,1,12.46,100,1,14.27,700,1,12.43,700,1,14.28,100,1,12.42,700,1,14.38,100,1
2025-07-17T16:06:43.013550575Z,2025-07-17T16:06:43.013716205Z,160,2,1108,A,A,0,14.62,100,130,165630,276279331,ARL,331491077,13.11,100,1,13.56,15,1,13,2,1,13.57,100,1,12.98,200,2,13.58,15,1,12.86,100,1,13.6,100,1,12.73,100,1,13.85,2,1,12.71,100,1,13.92,100,1,12.5,700,1,14.23,100,1,12.46,100,1,14.27,700,1,12.43,700,1,14.28,100,1,12.42,700,1,14.38,100,1
2025-07-17T16:06:43.024490355Z,2025-07-17T16:06:43.024656023Z,160,2,1108,C,A,0,13.92,100,130,165668,276279620,ARL,330359625,13.11,100,1,13.56,15,1,13,2,1,13.57,100,1,12.98,200,2,13.58,15,1,12.86,100,1,13.6,100,1,12.73,100,1,13.85,2,1,12.71,100,1,14.23,100,1,12.5,700,1,14.27,700,1,12.46,100,1,14.28,100,1,12.43,700,1,14.38,100,1,12.42,700,1,14.48,700,1
2025-07-17T16:06:43.024543099Z,2025-07-17T16:06:43.024708304Z,160,2,1108,A,A,0,13.84,100,130,165205,276279621,ARL,331491269,13.11,100,1,13.56,15,1,13,2,1,13.57,100,1,12.98,200,2,13.58,15,1,12.86,100,1,13.6,100,1,12.73,100,1,13.84,100,1,12.71,100,1,13.85,2,1,12.5,700,1,14.23,100,1,12.46,100,1,14.27,700,1,12.43,700,1,14.28,100,1,12.42,700,1,14.38,100,1
2025-07-17T16:06:49.613776144Z,2025-07-17T16:06:49.613941821Z,160,2,1108,C,A,0,13.58,15,130,165677,276382302,ARL,331050981,13.11,100,1,13.56,15,1,13,2,1,13.57,100,1,12.98,200,2,13.6,100,1,12.86,100,1,13.84,100,1,12.73,100,1,13.85,2,1,12.71,100,1,14.23,100,1,12.5,700,1,14.27,700,1,12.46,100,1,14.28,100,1,12.43,700,1,14.38,100,1,12.42,700,1,14.48,700,1
2025-07-17T16:06:50.618504506Z,2025-07-17T16:06:50.618669843Z,160,2,1108,A,A,0,13.54,15,130,165337,276408477,ARL,331666961,13.11,100,1,13.54,15,1,13,2,1,13.56,15,1,12.98,200,2,13.57,100,1,12.86,100,1,13.6,100,1,12.73,100,1,13.84,100,1,12.71,100,1,13.85,2,1,12.5,700,1,14.23,100,1,12.46,100,1,14.27,700,1,12.43,700,1,14.28,100,1,12.42,700,1,14.38,100,1
2025-07-17T16:06:50.626272828Z,2025-07-17T16:06:50.626438205Z,160,2,1108,A,A,0,13.58,100,130,165377,276408566,ARL,331667121,13.11,100,1,13.54,15,1,13,2,1,13.56,15,1,12.98,200,2,13.57,100,1,12.86,100,1,13.58,100,1,12.73,100,1,13.6,100,1,12.71,100,1,13.84,100,1,12.5,700,1,13.85,2,1,12.46,100,1,14.23,100,1,12.43,700,1,14.27,700,1,12.42,700,1,14.28,100,1
2025-07-17T16:06:50.632947998Z,2025-07-17T16:06:50.633113557Z,160,2,1108,C,A,0,13.6,100,130,165559,276408644,ARL,331104725,13.11,100,1,13.54,15,1,13,2,1,13.56,15,1,12.98,200,2,13.57,100,1,12.86,100,1,13.58,100,1,12.73,100,1,13.84,100,1,12.71,100,1,13.85,2,1,12.5,700,1,14.23,100,1,12.46,100,1,14.27,700,1,12.43,700,1,14.28,100,1,12.42,700,1,14.38,100,1
2025-07-17T16:06:51.754410704Z,2025-07-17T16:06:51.754576322Z,160,2,1108,C,A,0,13.57,100,0,165618,276428315,ARL,331491049,13.11,100,1,13.54,15,1,13,2,1,13.56,15,1,12.98,200,2,13.58,100,1,12.86,100,1,13.84,100,1,12.73,100,1,13.85,2,1,12.71,100,1,14.23,100,1,12.5,700,1,14.27,700,1,12.46,100,1,14.28,100,1,12.43,700,1,14.38,100,1,12.42,700,1,14.48,700,1
2025-07-17T16:06:51.754410704Z,2025-07-17T16:06:51.754576322Z,160,2,1108,A,A,0,13.55,100,130,165618,276428315,ARL,331694265,13.11,100,1,13.54,15,1,13,2,1,13.55,100,1,12.98,200,2,13.56,15,1,12.86,100,1,13.58,100,1,12.73,100,1,13.84,100,1,12.71,100,1,13.85,2,1,12.5,700,1,14.23,100,1,12.46,100,1,14.27,700,1,12.43,700,1,14.28,100,1,12.42,700,1,14.38,100,1
2025-07-17T16:06:51.757237300Z,2025-07-17T16:06:51.757403109Z,160,2,1108,C,B,0,13,2,0,165809,276428333,ARL,325967705,13.11,100,1,13.54,15,1,12.98,200,2,13.55,100,1,12.86,100,1,13.56,15,1,12.73,100,1,13.58,100,1,12.71,100,1,13.84,100,1,12.5,700,1,13.85,2,1,12.46,100,1,14.23,100,1,12.43,700,1,14.27,700,1,12.42,700,1,14.28,100,1,12.37,700,1,14.38,100,1
2025-07-17T16:06:51.757237300Z,2025-07-17T16:06:51.757403109Z,160,2,1108,A,B,0,12.9,2,130,165809,276428333,ARL,331694297,13.11,100,1,13.54,15,1,12.98,200,2,13.55,100,1,12.9,2,1,13.56,15,1,12.86,100,1,13.58,100,1,12.73,100,1,13.84,100,1,12.71,100,1,13.85,2,1,12.5,700,1,14.23,100,1,12.46,100,1,14.27,700,1,12.43,700,1,14.28,100,1,12.42,700,1,14.38,100,1
2025-07-17T16:06:55.056135380Z,2025-07-17T16:06:55.056300861Z,160,2,1108,C,A,0,13.54,15,130,165481,276516227,ARL,331666961,13.11,100,1,13.55,100,1,12.98,200,2,13.56,15,1,12.9,2,1,13.58,100,1,12.86,100,1,13.84,100,1,12.73,100,1,13.85,2,1,12.71,100,1,14.23,100,1,12.5,700,1,14.27,700,1,12.46,100,1,14.28,100,1,12.43,700,1,14.38,100,1,12.42,700,1,14.48,700,1
2025-07-17T16:06:55.056301001Z,2025-07-17T16:06:55.056466231Z,160,2,1108,C,A,0,13.56,15,130,165230,276516239,ARL,331488089,13.11,100,1,13.55,100,1,12.98,200,2,13.58,100,1,12.9,2,1,13.84,100,1,12.86,100,1,13.85,2,1,12.73,100,1,14.23,100,1,12.71,100,1,14.27,700,1,12.5,700,1,14.28,100,1,12.46,100,1,14.38,100,1,12.43,700,1,14.48,700,1,12.42,700,1,14.52,200,2
2025-07-17T16:07:00.010829521Z,2025-07-17T16:07:00.010995558Z,160,2,1108,C,A,0,13.55,100,130,166037,276611719,ARL,331694265,13.11,100,1,13.58,100,1,12.98,200,2,13.84,100,1,12.9,2,1,13.85,2,1,12.86,100,1,14.23,100,1,12.73,100,1,14.27,700,1,12.71,100,1,14.28,100,1,12.5,700,1,14.38,100,1,12.46,100,1,14.48,700,1,12.43,700,1,14.52,200,2,12.42,700,1,14.55,200,2
2025-07-17T16:07:00.023683961Z,2025-07-17T16:07:00.023849180Z,160,2,1108,C,A,0,13.58,100,130,165219,276613073,ARL,331667121,13.11,100,1,13.84,100,1,12.98,200,2,13.85,2,1,12.9,2,1,14.23,100,1,12.86,100,1,14.27,700,1,12.73,100,1,14.28,100,1,12.71,100,1,14.38,100,1,12.5,700,1,14.48,700,1,12.46,100,1,14.52,200,2,12.43,700,1,14.55,200,2,12.42,700,1,14.56,800,2
2025-07-17T16:07:00.023752163Z,2025-07-17T16:07:00.023917543Z,160,2,1108,C,A,0,14.27,700,130,165380,276613077,ARL,331257169,13.11,100,1,13.84,100,1,12.98,200,2,13.85,2,1,12.9,2,1,14.23,100,1,12.86,100,1,14.28,100,1,12.73,100,1,14.38,100,1,12.71,100,1,14.48,700,1,12.5,700,1,14.52,200,2,12.46,100,1,14.55,200,2,12.43,700,1,14.56,800,2,12.42,700,1,14.6,700,1
2025-07-17T16:07:00.023815326Z,2025-07-17T16:07:00.023980805Z,160,2,1108,A,A,0,14.51,700,130,165479,276613078,ARL,331926981,13.11,100,1,13.84,100,1,12.98,200,2,13.85,2,1,12.9,2,1,14.23,100,1,12.86,100,1,14.28,100,1,12.73,100,1,14.38,100,1,12.71,100,1,14.48,700,1,12.5,700,1,14.51,700,1,12.46,100,1,14.52,200,2,12.43,700,1,14.55,200,2,12.42,700,1,14.56,800,2
2025-07-17T16:07:00.024424816Z,2025-07-17T16:07:00.024590283Z,160,2,1108,C,A,0,14.62,100,0,165467,276613110,ARL,331491077,13.11,100,1,13.84,100,1,12.98,200,2,13.85,2,1,12.9,2,1,14.23,100,1,12.86,100,1,14.28,100,1,12.73,100,1,14.38,100,1,12.71,100,1,14.48,700,1,12.5,700,1,14.51,700,1,12.46,100,1,14.52,200,2,12.43,700,1,14.55,200,2,12.42,700,1,14.56,800,2
2025-07-17T16:07:00.024424816Z,2025-07-17T16:07:00.024590283Z,160,2,1108,A,A,0,14.88,100,130,165467,276613110,ARL,331927017,13.11,100,1,13.84,100,1,12.98,200,2,13.85,2,1,12.9,2,1,14.23,100,1,12.86,100,1,14.28,100,1,12.73,100,1,14.38,100,1,12.71,100,1,14.48,700,1,12.5,700,1,14.51,700,1,12.46,100,1,14.52,200,2,12.43,700,1,14.55,200,2,12.42,700,1,14.56,800,2
2025-07-17T16:07:00.025064913Z,2025-07-17T16:07:00.025231164Z,160,2,1108,C,A,0,14.23,100,130,166251,276613157,ARL,329074833,13.11,100,1,13.84,100,1,12.98,200,2,13.85,2,1,12.9,2,1,14.28,100,1,12.86,100,1,14.38,100,1,12.73,100,1,14.48,700,1,12.71,100,1,14.51,700,1,12.5,700,1,14.52,200,2,12.46,100,1,14.55,200,2,12.43,700,1,14.56,800,2,12.42,700,1,14.6,700,1
2025-07-17T16:07:00.025422082Z,2025-07-17T16:07:00.025587549Z,160,2,1108,A,A,0,14.46,100,130,165467,276613175,ARL,331927161,13.11,100,1,13.84,100,1,12.98,200,2,13.85,2,1,12.9,2,1,14.28,100,1,12.86,100,1,14.38,100,1,12.73,100,1,14.46,100,1,12.71,100,1,14.48,700,1,12.5,700,1,14.51,700,1,12.46,100,1,14.52,200,2,12.43,700,1,14.55,200,2,12.42,700,1,14.56,800,2
2025-07-17T16:07:00.025628157Z,2025-07-17T16:07:00.025793260Z,160,2,1108,A,A,0,13.59,100,130,165103,276613194,ARL,331927177,13.11,100,1,13.59,100,1,12.98,200,2,13.84,100,1,12.9,2,1,13.85,2,1,12.86,100,1,14.28,100,1,12.73,100,1,14.38,100,1,12.71,100,1,14.46,100,1,12.5,700,1,14.48,700,1,12.46,100,1,14.51,700,1,12.43,700,1,14.52,200,2,12.42,700,1,14.55,200,2
2025-07-17T16:07:00.026833761Z,2025-07-17T16:07:00.026998695Z,160,2,1108,C,A,0,13.59,100,130,164934,276613224,ARL,331927177,13.11,100,1,13.84,100,1,12.98,200,2,13.85,2,1,12.9,2,1,14.28,100,1,12.86,100,1,14.38,100,1,12.73,100,1,14.46,100,1,12.71,100,1,14.48,700,1,12.5,700,1,14.51,700,1,12.46,100,1,14.52,200,2,12.43,700,1,14.55,200,2,12.42,700,1,14.56,800,2
2025-07-17T16:07:00.032596898Z,2025-07-17T16:07:00.032762182Z,160,2,1108,C,A,0,14.38,100,130,165284,276613329,ARL,331051369,13.11,100,1,13.84,100,1,12.98,200,2,13.85,2,1,12.9,2,1,14.28,100,1,12.86,100,1,14.46,100,1,12.73,100,1,14.48,700,1,12.71,100,1,14.51,700,1,12.5,700,1,14.52,200,2,12.46,100,1,14.55,200,2,12.43,700,1,14.56,800,2,12.42,700,1,14.6,700,1
2025-07-17T16:07:00.032711777Z,2025-07-17T16:07:00.032876947Z,160,2,1108,A,A,0,14.63,100,130,165170,276613336,ARL,331927477,13.11,100,1,13.84,100,1,12.98,200,2,13.85,2,1,12.9,2,1,14.28,100,1,12.86,100,1,14.46,100,1,12.73,100,1,14.48,700,1,12.71,100,1,14.51,700,1,12.5,700,1,14.52,200,2,12.46,100,1,14.55,200,2,12.43,700,1,14.56,800,2,12.42,700,1,14.6,700,1
2025-07-17T16:07:00.045359807Z,2025-07-17T16:07:00.045525047Z,160,2,1108,C,A,0,13.84,100,130,165240,276613663,ARL,331491269,13.11,100,1,13.85,2,1,12.98,200,2,14.28,100,1,12.9,2,1,14.46,100,1,12.86,100,1,14.48,700,1,12.73,100,1,14.51,700,1,12.71,100,1,14.52,200,2,12.5,700,1,14.55,200,2,12.46,100,1,14.56,800,2,12.43,700,1,14.6,700,1,12.42,700,1,14.63,100,1
2025-07-17T16:07:00.045394317Z,2025-07-17T16:07:00.045559272Z,160,2,1108,C,A,0,14.51,700,130,164955,276613664,ARL,331926981,13.11,100,1,13.85,2,1,12.98,200,2,14.28,100,1,12.9,2,1,14.46,100,1,12.86,100,1,14.48,700,1,12.73,100,1,14.52,200,2,12.71,100,1,14.55,200,2,12.5,700,1,14.56,800,2,12.46,100,1,14.6,700,1,12.43,700,1,14.63,100,1,12.42,700,1,14.88,100,1
2025-07-17T16:07:00.045409635Z,2025-07-17T16:07:00.045574786Z,160,2,1108,A,A,0,14.09,100,130,165151,276613665,ARL,331927857,13.11,100,1,13.85,2,1,12.98,200,2,14.09,100,1,12.9,2,1,14.28,100,1,12.86,100,1,14.46,100,1,12.73,100,1,14.48,700,1,12.71,100,1,14.52,200,2,12.5,700,1,14.55,200,2,12.46,100,1,14.56,800,2,12.43,700,1,14.6,700,1,12.42,700,1,14.63,100,1
2025-07-17T16:07:00.046672908Z,2025-07-17T16:07:00.046838602Z,160,2,1108,C,A,0,14.09,100,130,165694,276613680,ARL,331927857,13.11,100,1,13.85,2,1,12.98,200,2,14.28,100,1,12.9,2,1,14.46,100,1,12.86,100,1,14.48,700,1,12.73,100,1,14.52,200,2,12.71,100,1,14.55,200,2,12.5,700,1,14.56,800,2,12.46,100,1,14.6,700,1,12.43,700,1,14.63,100,1,12.42,700,1,14.88,100,1
2025-07-17T16:07:00.046721624Z,2025-07-17T16:07:00.046887005Z,160,2,1108,A,A,0,13.86,100,130,165381,276613681,ARL,331927877,13.11,100,1,13.85,2,1,12.98,200,2,13.86,100,1,12.9,2,1,14.28,100,1,12.86,100,1,14.46,100,1,12.73,100,1,14.48,700,1,12.71,100,1,14.52,200,2,12.5,700,1,14.55,200,2,12.46,100,1,14.56,800,2,12.43,700,1,14.6,700,1,12.42,700,1,14.63,100,1
2025-07-17T16:07:00.047544064Z,2025-07-17T16:07:00.047708936Z,160,2,1108,C,A,0,13.86,100,130,164872,276613692,ARL,331927877,13.11,100,1,13.85,2,1,12.98,200,2,14.28,100,1,12.9,2,1,14.46,100,1,12.86,100,1,14.48,700,1,12.73,100,1,14.52,200,2,12.71,100,1,14.55,200,2,12.5,700,1,14.56,800,2,12.46,100,1,14.6,700,1,12.43,700,1,14.63,100,1,12.42,700,1,14.88,100,1
2025-07-17T16:07:00.047590313Z,2025-07-17T16:07:00.047755498Z,160,2,1108,A,A,0,14.12,100,130,165185,276613693,ARL,331927921,13.11,100,1,13.85,2,1,12.98,200,2,14.12,100,1,12.9,2,1,14.28,100,1,12.86,100,1,14.46,100,1,12.73,100,1,14.48,700,1,12.71,100,1,14.52,200,2,12.5,700,1,14.55,200,2,12.46,100,1,14.56,800,2,12.43,700,1,14.6,700,1,12.42,700,1,14.63,100,1
2025-07-17T16:07:00.053283700Z,2025-07-17T16:07:00.053448670Z,160,2,1108,C,A,0,14.12,100,130,164970,276613731,ARL,331927921,13.11,100,1,13.85,2,1,12.98,200,2,14.28,100,1,12.9,2,1,14.46,100,1,12.86,100,1,14.48,700,1,12.73,100,1,14.52,200,2,12.71,100,1,14.55,200,2,12.5,700,1,14.56,800,2,12.46,100,1,14.6,700,1,12.43,700,1,14.63,100,1,12.42,700,1,14.88,100,1
2025-07-17T16:07:00.053329959Z,2025-07-17T16:07:00.053495095Z,160,2,1108,A,A,0,14.26,100,130,165136,276613732,ARL,331928009,13.11,100,1,13.85,2,1,12.98,200,2,14.26,100,1,12.9,2,1,14.28,100,1,12.86,100,1,14.46,100,1,12.73,100,1,14.48,700,1,12.71,100,1,14.52,200,2,12.5,700,1,14.55,200,2,12.46,100,1,14.56,800,2,12.43,700,1,14.6,700,1,12.42,700,1,14.63,100,1
2025-07-17T16:07:00.057644427Z,2025-07-17T16:07:00.057809857Z,160,2,1108,C,A,0,14.55,100,0,165430,276613800,ARL,331052197,13.11,100,1,13.85,2,1,12.98,200,2,14.26,100,1,12.9,2,1,14.28,100,1,12.86,100,1,14.46,100,1,12.73,100,1,14.48,700,1,12.71,100,1,14.52,200,2,12.5,700,1,14.55,100,1,12.46,100,1,14.56,800,2,12.43,700,1,14.6,700,1,12.42,700,1,14.63,100,1
2025-07-17T16:07:00.057644427Z,2025-07-17T16:07:00.057809857Z,160,2,1108,A,A,0,14.96,100,130,165430,276613800,ARL,331928129,13.11,100,1,13.85,2,1,12.98,200,2,14.26,100,1,12.9,2,1,14.28,100,1,12.86,100,1,14.46,100,1,12.73,100,1,14.48,700,1,12.71,100,1,14.52,200,2,12.5,700,1,14.55,100,1,12.46,100,1,14.56,800,2,12.43,700,1,14.6,700,1,12.42,700,1,14.63,100,1
2025-07-17T16:07:00.070325784Z,2025-07-17T16:07:00.070490835Z,160,2,1108,C,A,0,14.26,100,130,165051,276614087,ARL,331928009,13.11,100,1,13.85,2,1,12.98,200,2,14.28,100,1,12.9,2,1,14.46,100,1,12.86,100,1,14.48,700,1,12.73,100,1,14.52,200,2,12.71,100,1,14.55,100,1,12.5,700,1,14.56,800,2,12.46,100,1,14.6,700,1,12.43,700,1,14.63,100,1,12.42,700,1,14.88,100,1
2025-07-17T16:07:00.070373975Z,2025-07-17T16:07:00.070539222Z,160,2,1108,A,A,0,14.14,100,130,165247,276614089,ARL,331929033,13.11,100,1,13.85,2,1,12.98,200,2,14.14,100,1,12.9,2,1,14.28,100,1,12.86,100,1,14.46,100,1,12.73,100,1,14.48,700,1,12.71,100,1,14.52,200,2,12.5,700,1,14.55,100,1,12.46,100,1,14.56,800,2,12.43,700,1,14.6,700,1,12.42,700,1,14.63,100,1
2025-07-17T16:07:00.071194493Z,2025-07-17T16:07:00.071359350Z,160,2,1108,C,A,0,14.14,100,130,164857,276614094,ARL,331929033,13.11,100,1,13.85,2,1,12.98,200,2,14.28,100,1,12.9,2,1,14.46,100,1,12.86,100,1,14.48,700,1,12.73,100,1,14.52,200,2,12.71,100,1,14.55,100,1,12.5,700,1,14.56,800,2,12.46,100,1,14.6,700,1,12.43,700,1,14.63,100,1,12.42,700,1,14.88,100,1
2025-07-17T16:07:00.071239867Z,2025-07-17T16:07:00.071405105Z,160,2,1108,A,A,0,14.26,100,130,165238,276614095,ARL,331929041,13.11,100,1,13.85,2,1,12.98,200,2,14.26,100,1,12.9,2,1,14.28,100,1,12.86,100,1,14.46,100,1,12.73,100,1,14.48,700,1,12.71,100,1,14.52,200,2,12.5,700,1,14.55,100,1,12.46,100,1,14.56,800,2,12.43,700,1,14.6,700,1,12.42,700,1,14.63,100,1
2025-07-17T16:07:00.074415631Z,2025-07-17T16:07:00.074580946Z,160,2,1108,C,A,0,14.88,100,0,165315,276614119,ARL,331927017,13.11,100,1,13.85,2,1,12.98,200,2,14.26,100,1,12.9,2,1,14.28,100,1,12.86,100,1,14.46,100,1,12.73,100,1,14.48,700,1,12.71,100,1,14.52,200,2,12.5,700,1,14.55,100,1,12.46,100,1,14.56,800,2,12.43,700,1,14.6,700,1,12.42,700,1,14.63,100,1
2025-07-17T16:07:00.074415631Z,2025-07-17T16:07:00.074580946Z,160,2,1108,A,A,0,15.06,100,130,165315,276614119,ARL,331929065,13.11,100,1,13.85,2,1,12.98,200,2,14.26,100,1,12.9,2,1,14.28,100,1,12.86,100,1,14.46,100,1,12.73,100,1,14.48,700,1,12.71,100,1,14.52,200,2,12.5,700,1,14.55,100,1,12.46,100,1,14.56,800,2,12.43,700,1,14.6,700,1,12.42,700,1,14.63,100,1
2025-07-17T16:07:00.084965637Z,2025-07-17T16:07:00.085131263Z,160,2,1108,C,A,0,15.07,100,0,165626,276614295,ARL,326837501,13.11,100,1,13.85,2,1,12.98,200,2,14.26,100,1,12.9,2,1,14.28,100,1,12.86,100,1,14.46,100,1,12.73,100,1,14.48,700,1,12.71,100,1,14.52,200,2,12.5,700,1,14.55,100,1,12.46,100,1,14.56,800,2,12.43,700,1,14.6,700,1,12.42,700,1,14.63,100,1
2025-07-17T16:07:00.084965637Z,2025-07-17T16:07:00.085131263Z,160,2,1108,A,A,0,15.38,100,130,165626,276614295,ARL,331929445,13.11,100,1,13.85,2,1,12.98,200,2,14.26,100,1,12.9,2,1,14.28,100,1,12.86,100,1,14.46,100,1,12.73,100,1,14.48,700,1,12.71,100,1,14.52,200,2,12.5,700,1,14.55,100,1,12.46,100,1,14.56,800,2,12.43,700,1,14.6,700,1,12.42,700,1,14.63,100,1
2025-07-17T16:07:00.090194106Z,2025-07-17T16:07:00.090359757Z,160,2,1108,C,A,0,14.55,100,0,165651,276614378,ARL,331051173,13.11,100,1,13.85,2,1,12.98,200,2,14.26,100,1,12.9,2,1,14.28,100,1,12.86,100,1,14.46,100,1,12.73,100,1,14.48,700,1,12.71,100,1,14.52,200,2,12.5,700,1,14.56,800,2,12.46,100,1,14.6,700,1,12.43,700,1,14.63,100,1,12.42,700,1,14.96,100,1
2025-07-17T16:07:00.090194106Z,2025-07-17T16:07:00.090359757Z,160,2,1108,A,A,0,14.96,100,130,165651,276614378,ARL,331929633,13.11,100,1,13.85,2,1,12.98,200,2,14.26,100,1,12.9,2,1,14.28,100,1,12.86,100,1,14.46,100,1,12.73,100,1,14.48,700,1,12.71,100,1,14.52,200,2,12.5,700,1,14.56,800,2,12.46,100,1,14.6,700,1,12.43,700,1,14.63,100,1,12.42,700,1,14.96,200,2
2025-07-17T16:07:00.101927028Z,2025-07-17T16:07:00.102092147Z,160,2,1108,A,A,0,14.68,700,130,165119,276614699,ARL,331929977,13.11,100,1,13.85,2,1,12.98,200,2,14.26,100,1,12.9,2,1,14.28,100,1,12.86,100,1,14.46,100,1,12.73,100,1,14.48,700,1,12.71,100,1,14.52,200,2,12.5,700,1,14.56,800,2,12.46,100,1,14.6,700,1,12.43,700,1,14.63,100,1,12.42,700,1,14.68,700,1
2025-07-17T16:07:00.287416733Z,2025-07-17T16:07:00.287582448Z,160,2,1108,C,A,0,17.29,100,0,165715,276617288,ARL,330789509,13.11,100,1,13.85,2,1,12.98,200,2,14.26,100,1,12.9,2,1,14.28,100,1,12.86,100,1,14.46,100,1,12.73,100,1,14.48,700,1,12.71,100,1,14.52,200,2,12.5,700,1,14.56,800,2,12.46,100,1,14.6,700,1,12.43,700,1,14.63,100,1,12.42,700,1,14.68,700,1
2025-07-17T16:07:00.287416733Z,2025-07-17T16:07:00.287582448Z,160,2,1108,A,A,0,17.76,100,130,165715,276617288,ARL,331934277,13.11,100,1,13.85,2,1,12.98,200,2,14.26,100,1,12.9,2,1,14.28,100,1,12.86,100,1,14.46,100,1,12.73,100,1,14.48,700,1,12.71,100,1,14.52,200,2,12.5,700,1,14.56,800,2,12.46,100,1,14.6,700,1,12.43,700,1,14.63,100,1,12.42,700,1,14.68,700,1
2025-07-17T16:07:00.293454856Z,2025-07-17T16:07:00.293620434Z,160,2,1108,C,A,0,15.63,100,0,165578,276617317,ARL,331051145,13.11,100,1,13.85,2,1,12.98,200,2,14.26,100,1,12.9,2,1,14.28,100,1,12.86,100,1,14.46,100,1,12.73,100,1,14.48,700,1,12.71,100,1,14.52,200,2,12.5,700,1,14.56,800,2,12.46,100,1,14.6,700,1,12.43,700,1,14.63,100,1,12.42,700,1,14.68,700,1
2025-07-17T16:07:00.293454856Z,2025-07-17T16:07:00.293620434Z,160,2,1108,A,A,0,16.08,100,130,165578,276617317,ARL,331934377,13.11,100,1,13.85,2,1,12.98,200,2,14.26,100,1,12.9,2,1,14.28,100,1,12.86,100,1,14.46,100,1,12.73,100,1,14.48,700,1,12.71,100,1,14.52,200,2,12.5,700,1,14.56,800,2,12.46,100,1,14.6,700,1,12.43,700,1,14.63,100,1,12.42,700,1,14.68,700,1
2025-07-17T16:07:00.494492099Z,2025-07-17T16:07:00.494657495Z,160,2,1108,A,A,0,13.86,100,130,165396,276622423,ARL,331942821,13.11,100,1,13.85,2,1,12.98,200,2,13.86,100,1,12.9,2,1,14.26,100,1,12.86,100,1,14.28,100,1,12.73,100,1,14.46,100,1,12.71,100,1,14.48,700,1,12.5,700,1,14.52,200,2,12.46,100,1,14.56,800,2,12.43,700,1,14.6,700,1,12.42,700,1,14.63,100,1
2025-07-17T16:07:00.495152219Z,2025-07-17T16:07:00.495318245Z,160,2,1108,C,B,0,12.36,100,0,166026,276622452,ARL,288723817,13.11,100,1,13.85,2,1,12.98,200,2,13.86,100,1,12.9,2,1,14.26,100,1,12.86,100,1,14.28,100,1,12.73,100,1,14.46,100,1,12.71,100,1,14.48,700,1,12.5,700,1,14.52,200,2,12.46,100,1,14.56,800,2,12.43,700,1,14.6,700,1,12.42,700,1,14.63,100,1
2025-07-17T16:07:00.495152219Z,2025-07-17T16:07:00.495318245Z,160,2,1108,A,B,0,12.49,100,130,166026,276622452,ARL,331942901,13.11,100,1,13.85,2,1,12.98,200,2,13.86,100,1,12.9,2,1,14.26,100,1,12.86,100,1,14.28,100,1,12.73,100,1,14.46,100,1,12.71,100,1,14.48,700,1,12.5,700,1,14.52,200,2,12.49,100,1,14.56,800,2,12.46,100,1,14.6,700,1,12.43,700,1,14.63,100,1
2025-07-17T16:07:00.495233001Z,2025-07-17T16:07:00.495398644Z,160,2,1108,C,A,0,15.06,100,0,165643,276622455,ARL,331929065,13.11,100,1,13.85,2,1,12.98,200,2,13.86,100,1,12.9,2,1,14.26,100,1,12.86,100,1,14.28,100,1,12.73,100,1,14.46,100,1,12.71,100,1,14.48,700,1,12.5,700,1,14.52,200,2,12.49,100,1,14.56,800,2,12.46,100,1,14.6,700,1,12.43,700,1,14.63,100,1
2025-07-17T16:07:00.495233001Z,2025-07-17T16:07:00.495398644Z,160,2,1108,A,A,0,14.93,100,130,165643,276622455,ARL,331942913,13.11,100,1,13.85,2,1,12.98,200,2,13.86,100,1,12.9,2,1,14.26,100,1,12.86,100,1,14.28,100,1,12.73,100,1,14.46,100,1,12.71,100,1,14.48,700,1,12.5,700,1,14.52,200,2,12.49,100,1,14.56,800,2,12.46,100,1,14.6,700,1,12.43,700,1,14.63,100,1
2025-07-17T16:07:00.495823953Z,2025-07-17T16:07:00.495989598Z,160,2,1108,C,B,0,12.36,100,0,165645,276622469,ARL,288723813,13.11,100,1,13.85,2,1,12.98,200,2,13.86,100,1,12.9,2,1,14.26,100,1,12.86,100,1,14.28,100,1,12.73,100,1,14.46,100,1,12.71,100,1,14.48,700,1,12.5,700,1,14.52,200,2,12.49,100,1,14.56,800,2,12.46,100,1,14.6,700,1,12.43,700,1,14.63,100,1
2025-07-17T16:07:00.495823953Z,2025-07-17T16:07:00.495989598Z,160,2,1108,A,B,0,12.49,100,130,165645,276622469,ARL,331942945,13.11,100,1,13.85,2,1,12.98,200,2,13.86,100,1,12.9,2,1,14.26,100,1,12.86,100,1,14.28,100,1,12.73,100,1,14.46,100,1,12.71,100,1,14.48,700,1,12.5,700,1,14.52,200,2,12.49,200,2,14.56,800,2,12.46,100,1,14.6,700,1,12.43,700,1,14.63,100,1
2025-07-17T16:07:00.496317847Z,2025-07-17T16:07:00.496483460Z,160,2,1108,C,A,0,17.76,100,0,165613,276622478,ARL,331934277,13.11,100,1,13.85,2,1,12.98,200,2,13.86,100,1,12.9,2,1,14.26,100,1,12.86,100,1,14.28,100,1,12.73,100,1,14.46,100,1,12.71,100,1,14.48,700,1,12.5,700,1,14.52,200,2,12.49,200,2,14.56,800,2,12.46,100,1,14.6,700,1,12.43,700,1,14.63,100,1
2025-07-17T16:07:00.496317847Z,2025-07-17T16:07:00.496483460Z,160,2,1108,A,A,0,17.61,100,130,165613,276622478,ARL,331942981,13.11,100,1,13.85,2,1,12.98,200,2,13.86,100,1,12.9,2,1,14.26,100,1,12.86,100,1,14.28,100,1,12.73,100,1,14.46,100,1,12.71,100,1,14.48,700,1,12.5,700,1,14.52,200,2,12.49,200,2,14.56,800,2,12.46,100,1,14.6,700,1,12.43,700,1,14.63,100,1
2025-07-17T16:07:00.499501052Z,2025-07-17T16:07:00.499666149Z,160,2,1108,C,A,0,14.26,100,130,165097,276622569,ARL,331929041,13.11,100,1,13.85,2,1,12.98,200,2,13.86,100,1,12.9,2,1,14.28,100,1,12.86,100,1,14.46,100,1,12.73,100,1,14.48,700,1,12.71,100,1,14.52,200,2,12.5,700,1,14.56,800,2,12.49,200,2,14.6,700,1,12.46,100,1,14.63,100,1,12.43,700,1,14.68,700,1
2025-07-17T16:07:00.499549738Z,2025-07-17T16:07:00.499714918Z,160,2,1108,A,A,0,14.14,100,130,165180,276622571,ARL,331943133,13.11,100,1,13.85,2,1,12.98,200,2,13.86,100,1,12.9,2,1,14.14,100,1,12.86,100,1,14.28,100,1,12.73,100,1,14.46,100,1,12.71,100,1,14.48,700,1,12.5,700,1,14.52,200,2,12.49,200,2,14.56,800,2,12.46,100,1,14.6,700,1,12.43,700,1,14.63,100,1
2025-07-17T16:07:22.814776694Z,2025-07-17T16:07:22.814941809Z,160,2,1108,A,A,0,13.69,15,130,165115,276946179,ARL,332385317,13.11,100,1,13.69,15,1,12.98,200,2,13.85,2,1,12.9,2,1,13.86,100,1,12.86,100,1,14.14,100,1,12.73,100,1,14.28,100,1,12.71,100,1,14.46,100,1,12.5,700,1,14.48,700,1,12.49,200,2,14.52,200,2,12.46,100,1,14.56,800,2,12.43,700,1,14.6,700,1
2025-07-17T16:07:22.814891345Z,2025-07-17T16:07:22.815057507Z,160,2,1108,C,A,0,13.86,100,0,166162,276946183,ARL,331942821,13.11,100,1,13.69,15,1,12.98,200,2,13.85,2,1,12.9,2,1,14.14,100,1,12.86,100,1,14.28,100,1,12.73,100,1,14.46,100,1,12.71,100,1,14.48,700,1,12.5,700,1,14.52,200,2,12.49,200,2,14.56,800,2,12.46,100,1,14.6,700,1,12.43,700,1,14.63,100,1
2025-07-17T16:07:22.814891345Z,2025-07-17T16:07:22.815057507Z,160,2,1108,A,A,0,13.7,100,130,166162,276946183,ARL,332385325,13.11,100,1,13.69,15,1,12.98,200,2,13.7,100,1,12.9,2,1,13.85,2,1,12.86,100,1,14.14,100,1,12.73,100,1,14.28,100,1,12.71,100,1,14.46,100,1,12.5,700,1,14.48,700,1,12.49,200,2,14.52,200,2,12.46,100,1,14.56,800,2,12.43,700,1,14.6,700,1
2025-07-17T16:07:22.815625345Z,2025-07-17T16:07:22.815790890Z,160,2,1108,C,A,0,14.93,100,0,165545,276946264,ARL,331942913,13.11,100,1,13.69,15,1,12.98,200,2,13.7,100,1,12.9,2,1,13.85,2,1,12.86,100,1,14.14,100,1,12.73,100,1,14.28,100,1,12.71,100,1,14.46,100,1,12.5,700,1,14.48,700,1,12.49,200,2,14.52,200,2,12.46,100,1,14.56,800,2,12.43,700,1,14.6,700,1
2025-07-17T16:07:22.815625345Z,2025-07-17T16:07:22.815790890Z,160,2,1108,A,A,0,14.76,100,130,165545,276946264,ARL,332385501,13.11,100,1,13.69,15,1,12.98,200,2,13.7,100,1,12.9,2,1,13.85,2,1,12.86,100,1,14.14,100,1,12.73,100,1,14.28,100,1,12.71,100,1,14.46,100,1,12.5,700,1,14.48,700,1,12.49,200,2,14.52,200,2,12.46,100,1,14.56,800,2,12.43,700,1,14.6,700,1
2025-07-17T16:07:22.817341789Z,2025-07-17T16:07:22.817507809Z,160,2,1108,C,A,0,14.96,100,0,166020,276946309,ARL,331929633,13.11,100,1,13.69,15,1,12.98,200,2,13.7,100,1,12.9,2,1,13.85,2,1,12.86,100,1,14.14,100,1,12.73,100,1,14.28,100,1,12.71,100,1,14.46,100,1,12.5,700,1,14.48,700,1,12.49,200,2,14.52,200,2,12.46,100,1,14.56,800,2,12.43,700,1,14.6,700,1
2025-07-17T16:07:22.817341789Z,2025-07-17T16:07:22.817507809Z,160,2,1108,A,A,0,14.66,100,130,166020,276946309,ARL,332385565,13.11,100,1,13.69,15,1,12.98,200,2,13.7,100,1,12.9,2,1,13.85,2,1,12.86,100,1,14.14,100,1,12.73,100,1,14.28,100,1,12.71,100,1,14.46,100,1,12.5,700,1,14.48,700,1,12.49,200,2,14.52,200,2,12.46,100,1,14.56,800,2,12.43,700,1,14.6,700,1
2025-07-17T16:07:22.817459170Z,2025-07-17T16:07:22.817624699Z,160,2,1108,C,A,0,15.38,100,0,165529,276946313,ARL,331929445,13.11,100,1,13.69,15,1,12.98,200,2,13.7,100,1,12.9,2,1,13.85,2,1,12.86,100,1,14.14,100,1,12.73,100,1,14.28,100,1,12.71,100,1,14.46,100,1,12.5,700,1,14.48,700,1,12.49,200,2,14.52,200,2,12.46,100,1,14.56,800,2,12.43,700,1,14.6,700,1
2025-07-17T16:07:22.817459170Z,2025-07-17T16:07:22.817624699Z,160,2,1108,A,A,0,15.07,100,130,165529,276946313,ARL,332385569,13.11,100,1,13.69,15,1,12.98,200,2,13.7,100,1,12.9,2,1,13.85,2,1,12.86,100,1,14.14,100,1,12.73,100,1,14.28,100,1,12.71,100,1,14.46,100,1,12.5,700,1,14.48,700,1,12.49,200,2,14.52,200,2,12.46,100,1,14.56,800,2,12.43,700,1,14.6,700,1
2025-07-17T16:07:22.818400003Z,2025-07-17T16:07:22.818565766Z,160,2,1108,C,A,0,16.08,100,0,165763,276946327,ARL,331934377,13.11,100,1,13.69,15,1,12.98,200,2,13.7,100,1,12.9,2,1,13.85,2,1,12.86,100,1,14.14,100,1,12.73,100,1,14.28,100,1,12.71,100,1,14.46,100,1,12.5,700,1,14.48,700,1,12.49,200,2,14.52,200,2,12.46,100,1,14.56,800,2,12.43,700,1,14.6,700,1
2025-07-17T16:07:22.818400003Z,2025-07-17T16:07:22.818565766Z,160,2,1108,A,A,0,15.76,100,130,165763,276946327,ARL,332385585,13.11,100,1,13.69,15,1,12.98,200,2,13.7,100,1,12.9,2,1,13.85,2,1,12.86,100,1,14.14,100,1,12.73,100,1,14.28,100,1,12.71,100,1,14.46,100,1,12.5,700,1,14.48,700,1,12.49,200,2,14.52,200,2,12.46,100,1,14.56,800,2,12.43,700,1,14.6,700,1
2025-07-17T16:07:22.819545360Z,2025-07-17T16:07:22.819710983Z,160,2,1108,C,A,0,17.61,100,0,165623,276946336,ARL,331942981,13.11,100,1,13.69,15,1,12.98,200,2,13.7,100,1,12.9,2,1,13.85,2,1,12.86,100,1,14.14,100,1,12.73,100,1,14.28,100,1,12.71,100,1,14.46,100,1,12.5,700,1,14.48,700,1,12.49,200,2,14.52,200,2,12.46,100,1,14.56,800,2,12.43,700,1,14.6,700,1
2025-07-17T16:07:22.819545360Z,2025-07-17T16:07:22.819710983Z,160,2,1108,A,A,0,17.4,100,130,165623,276946336,ARL,332385593,13.11,100,1,13.69,15,1,12.98,200,2,13.7,100,1,12.9,2,1,13.85,2,1,12.86,100,1,14.14,100,1,12.73,100,1,14.28,100,1,12.71,100,1,14.46,100,1,12.5,700,1,14.48,700,1,12.49,200,2,14.52,200,2,12.46,100,1,14.56,800,2,12.43,700,1,14.6,700,1
2025-07-17T16:07:22.819606945Z,2025-07-17T16:07:22.819772408Z,160,2,1108,C,A,0,14.63,100,0,165463,276946337,ARL,331927477,13.11,100,1,13.69,15,1,12.98,200,2,13.7,100,1,12.9,2,1,13.85,2,1,12.86,100,1,14.14,100,1,12.73,100,1,14.28,100,1,12.71,100,1,14.46,100,1,12.5,700,1,14.48,700,1,12.49,200,2,14.52,200,2,12.46,100,1,14.56,800,2,12.43,700,1,14.6,700,1
2025-07-17T16:07:22.819606945Z,2025-07-17T16:07:22.819772408Z,160,2,1108,A,A,0,14.49,100,130,165463,276946337,ARL,332385597,13.11,100,1,13.69,15,1,12.98,200,2,13.7,100,1,12.9,2,1,13.85,2,1,12.86,100,1,14.14,100,1,12.73,100,1,14.28,100,1,12.71,100,1,14.46,100,1,12.5,700,1,14.48,700,1,12.49,200,2,14.49,100,1,12.46,100,1,14.52,200,2,12.43,700,1,14.56,800,2
2025-07-17T16:07:22.821000003Z,2025-07-17T16:07:22.821165451Z,160,2,1108,C,A,0,14.14,100,130,165448,276946343,ARL,331943133,13.11,100,1,13.69,15,1,12.98,200,2,13.7,100,1,12.9,2,1,13.85,2,1,12.86,100,1,14.28,100,1,12.73,100,1,14.46,100,1,12.71,100,1,14.48,700,1,12.5,700,1,14.49,100,1,12.49,200,2,14.52,200,2,12.46,100,1,14.56,800,2,12.43,700,1,14.6,700,1
2025-07-17T16:07:22.821052982Z,2025-07-17T16:07:22.821218207Z,160,2,1108,A,A,0,13.97,100,130,165225,276946344,ARL,332385613,13.11,100,1,13.69,15,1,12.98,200,2,13.7,100,1,12.9,2,1,13.85,2,1,12.86,100,1,13.97,100,1,12.73,100,1,14.28,100,1,12.71,100,1,14.46,100,1,12.5,700,1,14.48,700,1,12.49,200,2,14.49,100,1,12.46,100,1,14.52,200,2,12.43,700,1,14.56,800,2
2025-07-17T16:07:22.831949887Z,2025-07-17T16:07:22.832119220Z,160,2,1108,C,A,0,14.96,100,0,169333,276946801,ARL,331928129,13.11,100,1,13.69,15,1,12.98,200,2,13.7,100,1,12.9,2,1,13.85,2,1,12.86,100,1,13.97,100,1,12.73,100,1,14.28,100,1,12.71,100,1,14.46,100,1,12.5,700,1,14.48,700,1,12.49,200,2,14.49,100,1,12.46,100,1,14.52,200,2,12.43,700,1,14.56,800,2
2025-07-17T16:07:22.831949887Z,2025-07-17T16:07:22.832119220Z,160,2,1108,A,A,0,14.66,100,128,169333,276946801,ARL,332386121,13.11,100,1,13.69,15,1,12.98,200,2,13.7,100,1,12.9,2,1,13.85,2,1,12.86,100,1,13.97,100,1,12.73,100,1,14.28,100,1,12.71,100,1,14.46,100,1,12.5,700,1,14.48,700,1,12.49,200,2,14.49,100,1,12.46,100,1,14.52,200,2,12.43,700,1,14.56,800,2
2025-07-17T16:07:28.273658191Z,2025-07-17T16:07:28.273823608Z,160,2,1108,C,A,0,13.69,15,130,165417,277012951,ARL,332385317,13.11,100,1,13.7,100,1,12.98,200,2,13.85,2,1,12.9,2,1,13.97,100,1,12.86,100,1,14.28,100,1,12.73,100,1,14.46,100,1,12.71,100,1,14.48,700,1,12.5,700,1,14.49,100,1,12.49,200,2,14.52,200,2,12.46,100,1,14.56,800,2,12.43,700,1,14.6,700,1
2025-07-17T16:07:28.700815737Z,2025-07-17T16:07:28.700981149Z,160,2,1108,C,A,0,13.7,100,130,165412,277019711,ARL,332385325,13.11,100,1,13.85,2,1,12.98,200,2,13.97,100,1,12.9,2,1,14.28,100,1,12.86,100,1,14.46,100,1,12.73,100,1,14.48,700,1,12.71,100,1,14.49,100,1,12.5,700,1,14.52,200,2,12.49,200,2,14.56,800,2,12.46,100,1,14.6,700,1,12.43,700,1,14.66,200,2
2025-07-17T16:07:28.701230409Z,2025-07-17T16:07:28.701396669Z,160,2,1108,C,B,0,12.9,2,0,166260,277019718,ARL,331694297,13.11,100,1,13.85,2,1,12.98,200,2,13.97,100,1,12.86,100,1,14.28,100,1,12.73,100,1,14.46,100,1,12.71,100,1,14.48,700,1,12.5,700,1,14.49,100,1,12.49,200,2,14.52,200,2,12.46,100,1,14.56,800,2,12.43,700,1,14.6,700,1,12.42,700,1,14.66,200,2
2025-07-17T16:07:28.701230409Z,2025-07-17T16:07:28.701396669Z,160,2,1108,A,B,0,13.01,2,130,166260,277019718,ARL,332494213,13.11,100,1,13.85,2,1,13.01,2,1,13.97,100,1,12.98,200,2,14.28,100,1,12.86,100,1,14.46,100,1,12.73,100,1,14.48,700,1,12.71,100,1,14.49,100,1,12.5,700,1,14.52,200,2,12.49,200,2,14.56,800,2,12.46,100,1,14.6,700,1,12.43,700,1,14.66,200,2
2025-07-17T16:07:28.701547540Z,2025-07-17T16:07:28.701713232Z,160,2,1108,C,A,0,14.76,100,0,165692,277019720,ARL,332385501,13.11,100,1,13.85,2,1,13.01,2,1,13.97,100,1,12.98,200,2,14.28,100,1,12.86,100,1,14.46,100,1,12.73,100,1,14.48,700,1,12.71,100,1,14.49,100,1,12.5,700,1,14.52,200,2,12.49,200,2,14.56,800,2,12.46,100,1,14.6,700,1,12.43,700,1,14.66,200,2
2025-07-17T16:07:28.701547540Z,2025-07-17T16:07:28.701713232Z,160,2,1108,A,A,0,14.82,100,130,165692,277019720,ARL,332494229,13.11,100,1,13.85,2,1,13.01,2,1,13.97,100,1,12.98,200,2,14.28,100,1,12.86,100,1,14.46,100,1,12.73,100,1,14.48,700,1,12.71,100,1,14.49,100,1,12.5,700,1,14.52,200,2,12.49,200,2,14.56,800,2,12.46,100,1,14.6,700,1,12.43,700,1,14.66,200,2
2025-07-17T16:07:28.702000772Z,2025-07-17T16:07:28.702166297Z,160,2,1108,C,A,0,15.76,100,0,165525,277019722,ARL,332385585,13.11,100,1,13.85,2,1,13.01,2,1,13.97,100,1,12.98,200,2,14.28,100,1,12.86,100,1,14.46,100,1,12.73,100,1,14.48,700,1,12.71,100,1,14.49,100,1,12.5,700,1,14.52,200,2,12.49,200,2,14.56,800,2,12.46,100,1,14.6,700,1,12.43,700,1,14.66,200,2
2025-07-17T16:07:28.702000772Z,2025-07-17T16:07:28.702166297Z,160,2,1108,A,A,0,16.01,100,130,165525,277019722,ARL,332494245,13.11,100,1,13.85,2,1,13.01,2,1,13.97,100,1,12.98,200,2,14.28,100,1,12.86,100,1,14.46,100,1,12.73,100,1,14.48,700,1,12.71,100,1,14.49,100,1,12.5,700,1,14.52,200,2,12.49,200,2,14.56,800,2,12.46,100,1,14.6,700,1,12.43,700,1,14.66,200,2
2025-07-17T16:07:28.702476699Z,2025-07-17T16:07:28.702642020Z,160,2,1108,C,A,0,14.66,100,0,165321,277019729,ARL,332386121,13.11,100,1,13.85,2,1,13.01,2,1,13.97,100,1,12.98,200,2,14.28,100,1,12.86,100,1,14.46,100,1,12.73,100,1,14.48,700,1,12.71,100,1,14.49,100,1,12.5,700,1,14.52,200,2,12.49,200,2,14.56,800,2,12.46,100,1,14.6,700,1,12.43,700,1,14.66,100,1
2025-07-17T16:07:28.702476699Z,2025-07-17T16:07:28.702642020Z,160,2,1108,A,A,0,14.95,100,130,165321,277019729,ARL,332494281,13.11,100,1,13.85,2,1,13.01,2,1,13.97,100,1,12.98,200,2,14.28,100,1,12.86,100,1,14.46,100,1,12.73,100,1,14.48,700,1,12.71,100,1,14.49,100,1,12.5,700,1,14.52,200,2,12.49,200,2,14.56,800,2,12.46,100,1,14.6,700,1,12.43,700,1,14.66,100,1
2025-07-17T16:07:28.703357714Z,2025-07-17T16:07:28.703523092Z,160,2,1108,C,A,0,14.66,100,0,165378,277019733,ARL,332385565,13.11,100,1,13.85,2,1,13.01,2,1,13.97,100,1,12.98,200,2,14.28,100,1,12.86,100,1,14.46,100,1,12.73,100,1,14.48,700,1,12.71,100,1,14.49,100,1,12.5,700,1,14.52,200,2,12.49,200,2,14.56,800,2,12.46,100,1,14.6,700,1,12.43,700,1,14.68,700,1
2025-07-17T16:07:28.703357714Z,2025-07-17T16:07:28.703523092Z,160,2,1108,A,A,0,14.95,100,130,165378,277019733,ARL,332494285,13.11,100,1,13.85,2,1,13.01,2,1,13.97,100,1,12.98,200,2,14.28,100,1,12.86,100,1,14.46,100,1,12.73,100,1,14.48,700,1,12.71,100,1,14.49,100,1,12.5,700,1,14.52,200,2,12.49,200,2,14.56,800,2,12.46,100,1,14.6,700,1,12.43,700,1,14.68,700,1
2025-07-17T16:07:28.703754662Z,2025-07-17T16:07:28.703920336Z,160,2,1108,C,A,0,15.07,100,0,165674,277019735,ARL,332385569,13.11,100,1,13.85,2,1,13.01,2,1,13.97,100,1,12.98,200,2,14.28,100,1,12.86,100,1,14.46,100,1,12.73,100,1,14.48,700,1,12.71,100,1,14.49,100,1,12.5,700,1,14.52,200,2,12.49,200,2,14.56,800,2,12.46,100,1,14.6,700,1,12.43,700,1,14.68,700,1
2025-07-17T16:07:28.703754662Z,2025-07-17T16:07:28.703920336Z,160,2,1108,A,A,0,15.37,100,130,165674,277019735,ARL,332494289,13.11,100,1,13.85,2,1,13.01,2,1,13.97,100,1,12.98,200,2,14.28,100,1,12.86,100,1,14.46,100,1,12.73,100,1,14.48,700,1,12.71,100,1,14.49,100,1,12.5,700,1,14.52,200,2,12.49,200,2,14.56,800,2,12.46,100,1,14.6,700,1,12.43,700,1,14.68,700,1
2025-07-17T16:07:28.704032725Z,2025-07-17T16:07:28.704198103Z,160,2,1108,C,A,0,17.4,100,0,165378,277019738,ARL,332385593,13.11,100,1,13.85,2,1,13.01,2,1,13.97,100,1,12.98,200,2,14.28,100,1,12.86,100,1,14.46,100,1,12.73,100,1,14.48,700,1,12.71,100,1,14.49,100,1,12.5,700,1,14.52,200,2,12.49,200,2,14.56,800,2,12.46,100,1,14.6,700,1,12.43,700,1,14.68,700,1
2025-07-17T16:07:28.704032725Z,2025-07-17T16:07:28.704198103Z,160,2,1108,A,A,0,17.75,100,130,165378,277019738,ARL,332494297,13.11,100,1,13.85,2,1,13.01,2,1,13.97,100,1,12.98,200,2,14.28,100,1,12.86,100,1,14.46,100,1,12.73,100,1,14.48,700,1,12.71,100,1,14.49,100,1,12.5,700,1,14.52,200,2,12.49,200,2,14.56,800,2,12.46,100,1,14.6,700,1,12.43,700,1,14.68,700,1
2025-07-17T16:07:28.724036175Z,2025-07-17T16:07:28.724201840Z,160,2,1108,C,A,0,13.97,100,130,165665,277019926,ARL,332385613,13.11,100,1,13.85,2,1,13.01,2,1,14.28,100,1,12.98,200,2,14.46,100,1,12.86,100,1,14.48,700,1,12.73,100,1,14.49,100,1,12.71,100,1,14.52,200,2,12.5,700,1,14.56,800,2,12.49,200,2,14.6,700,1,12.46,100,1,14.68,700,1,12.43,700,1,14.82,100,1
2025-07-17T16:07:28.724085453Z,2025-07-17T16:07:28.724250835Z,160,2,1108,A,A,0,14.2,100,130,165382,277019929,ARL,332494893,13.11,100,1,13.85,2,1,13.01,2,1,14.2,100,1,12.98,200,2,14.28,100,1,12.86,100,1,14.46,100,1,12.73,100,1,14.48,700,1,12.71,100,1,14.49,100,1,12.5,700,1,14.52,200,2,12.49,200,2,14.56,800,2,12.46,100,1,14.6,700,1,12.43,700,1,14.68,700,1
2025-07-17T16:07:28.751662660Z,2025-07-17T16:07:28.751828120Z,160,2,1108,C,A,0,14.82,100,0,165460,277020284,ARL,332494229,13.11,100,1,13.85,2,1,13.01,2,1,14.2,100,1,12.98,200,2,14.28,100,1,12.86,100,1,14.46,100,1,12.73,100,1,14.48,700,1,12.71,100,1,14.49,100,1,12.5,700,1,14.52,200,2,12.49,200,2,14.56,800,2,12.46,100,1,14.6,700,1,12.43,700,1,14.68,700,1
2025-07-17T16:07:28.751662660Z,2025-07-17T16:07:28.751828120Z,160,2,1108,A,A,0,15.05,100,130,165460,277020284,ARL,332495781,13.11,100,1,13.85,2,1,13.01,2,1,14.2,100,1,12.98,200,2,14.28,100,1,12.86,100,1,14.46,100,1,12.73,100,1,14.48,700,1,12.71,100,1,14.49,100,1,12.5,700,1,14.52,200,2,12.49,200,2,14.56,800,2,12.46,100,1,14.6,700,1,12.43,700,1,14.68,700,1
2025-07-17T16:07:28.830995364Z,2025-07-17T16:07:28.831160987Z,160,2,1108,C,A,0,14.49,100,130,165623,277021007,ARL,332385597,13.11,100,1,13.85,2,1,13.01,2,1,14.2,100,1,12.98,200,2,14.28,100,1,12.86,100,1,14.46,100,1,12.73,100,1,14.48,700,1,12.71,100,1,14.52,200,2,12.5,700,1,14.56,800,2,12.49,200,2,14.6,700,1,12.46,100,1,14.68,700,1,12.43,700,1,14.95,200,2
2025-07-17T16:07:28.831125667Z,2025-07-17T16:07:28.831291377Z,160,2,1108,A,A,0,14.77,100,130,165710,277021012,ARL,332497653,13.11,100,1,13.85,2,1,13.01,2,1,14.2,100,1,12.98,200,2,14.28,100,1,12.86,100,1,14.46,100,1,12.73,100,1,14.48,700,1,12.71,100,1,14.52,200,2,12.5,700,1,14.56,800,2,12.49,200,2,14.6,700,1,12.46,100,1,14.68,700,1,12.43,700,1,14.77,100,1
2025-07-17T16:07:29.214500816Z,2025-07-17T16:07:29.214667270Z,160,2,1108,A,A,0,13.86,100,128,166454,277029015,ARL,332508813,13.11,100,1,13.85,2,1,13.01,2,1,13.86,100,1,12.98,200,2,14.2,100,1,12.86,100,1,14.28,100,1,12.73,100,1,14.46,100,1,12.71,100,1,14.48,700,1,12.5,700,1,14.52,200,2,12.49,200,2,14.56,800,2,12.46,100,1,14.6,700,1,12.43,700,1,14.68,700,1
2025-07-17T16:07:29.215292291Z,2025-07-17T16:07:29.215458844Z,160,2,1108,C,A,0,15.05,100,0,166553,277029273,ARL,332495781,13.11,100,1,13.85,2,1,13.01,2,1,13.86,100,1,12.98,200,2,14.2,100,1,12.86,100,1,14.28,100,1,12.73,100,1,14.46,100,1,12.71,100,1,14.48,700,1,12.5,700,1,14.52,200,2,12.49,200,2,14.56,800,2,12.46,100,1,14.6,700,1,12.43,700,1,14.68,700,1
2025-07-17T16:07:29.215292291Z,2025-07-17T16:07:29.215458844Z,160,2,1108,A,A,0,14.93,100,128,166553,277029273,ARL,332508997,13.11,100,1,13.85,2,1,13.01,2,1,13.86,100,1,12.98,200,2,14.2,100,1,12.86,100,1,14.28,100,1,12.73,100,1,14.46,100,1,12.71,100,1,14.48,700,1,12.5,700,1,14.52,200,2,12.49,200,2,14.56,800,2,12.46,100,1,14.6,700,1,12.43,700,1,14.68,700,1
2025-07-17T16:08:20.816087447Z,2025-07-17T16:08:20.816252850Z,160,2,1108,A,A,0,13.68,15,130,165403,277732167,ARL,333436357,13.11,100,1,13.68,15,1,13.01,2,1,13.85,2,1,12.98,200,2,13.86,100,1,12.86,100,1,14.2,100,1,12.73,100,1,14.28,100,1,12.71,100,1,14.46,100,1,12.5,700,1,14.48,700,1,12.49,200,2,14.52,200,2,12.46,100,1,14.56,800,2,12.43,700,1,14.6,700,1
2025-07-17T16:08:20.816200644Z,2025-07-17T16:08:20.816366205Z,160,2,1108,C,A,0,13.86,100,0,165561,277732170,ARL,332508813,13.11,100,1,13.68,15,1,13.01,2,1,13.85,2,1,12.98,200,2,14.2,100,1,12.86,100,1,14.28,100,1,12.73,100,1,14.46,100,1,12.71,100,1,14.48,700,1,12.5,700,1,14.52,200,2,12.49,200,2,14.56,800,2,12.46,100,1,14.6,700,1,12.43,700,1,14.68,700,1
2025-07-17T16:08:20.816200644Z,2025-07-17T16:08:20.816366205Z,160,2,1108,A,A,0,13.69,100,130,165561,277732170,ARL,333436361,13.11,100,1,13.68,15,1,13.01,2,1,13.69,100,1,12.98,200,2,13.85,2,1,12.86,100,1,14.2,100,1,12.73,100,1,14.28,100,1,12.71,100,1,14.46,100,1,12.5,700,1,14.48,700,1,12.49,200,2,14.52,200,2,12.46,100,1,14.56,800,2,12.43,700,1,14.6,700,1
2025-07-17T16:08:20.816932150Z,2025-07-17T16:08:20.817097587Z,160,2,1108,C,A,0,14.93,100,0,165437,277732194,ARL,332508997,13.11,100,1,13.68,15,1,13.01,2,1,13.69,100,1,12.98,200,2,13.85,2,1,12.86,100,1,14.2,100,1,12.73,100,1,14.28,100,1,12.71,100,1,14.46,100,1,12.5,700,1,14.48,700,1,12.49,200,2,14.52,200,2,12.46,100,1,14.56,800,2,12.43,700,1,14.6,700,1
2025-07-17T16:08:20.816932150Z,2025-07-17T16:08:20.817097587Z,160,2,1108,A,A,0,14.75,100,130,165437,277732194,ARL,333436397,13.11,100,1,13.68,15,1,13.01,2,1,13.69,100,1,12.98,200,2,13.85,2,1,12.86,100,1,14.2,100,1,12.73,100,1,14.28,100,1,12.71,100,1,14.46,100,1,12.5,700,1,14.48,700,1,12.49,200,2,14.52,200,2,12.46,100,1,14.56,800,2,12.43,700,1,14.6,700,1
2025-07-17T16:08:20.818559377Z,2025-07-17T16:08:20.818725102Z,160,2,1108,C,A,0,15.37,100,0,165725,277732213,ARL,332494289,13.11,100,1,13.68,15,1,13.01,2,1,13.69,100,1,12.98,200,2,13.85,2,1,12.86,100,1,14.2,100,1,12.73,100,1,14.28,100,1,12.71,100,1,14.46,100,1,12.5,700,1,14.48,700,1,12.49,200,2,14.52,200,2,12.46,100,1,14.56,800,2,12.43,700,1,14.6,700,1
2025-07-17T16:08:20.818559377Z,2025-07-17T16:08:20.818725102Z,160,2,1108,A,A,0,15.06,100,130,165725,277732213,ARL,333436421,13.11,100,1,13.68,15,1,13.01,2,1,13.69,100,1,12.98,200,2,13.85,2,1,12.86,100,1,14.2,100,1,12.73,100,1,14.28,100,1,12.71,100,1,14.46,100,1,12.5,700,1,14.48,700,1,12.49,200,2,14.52,200,2,12.46,100,1,14.56,800,2,12.43,700,1,14.6,700,1
2025-07-17T16:08:20.818965359Z,2025-07-17T16:08:20.819130820Z,160,2,1108,C,A,0,14.95,100,0,165461,277732216,ARL,332494285,13.11,100,1,13.68,15,1,13.01,2,1,13.69,100,1,12.98,200,2,13.85,2,1,12.86,100,1,14.2,100,1,12.73,100,1,14.28,100,1,12.71,100,1,14.46,100,1,12.5,700,1,14.48,700,1,12.49,200,2,14.52,200,2,12.46,100,1,14.56,800,2,12.43,700,1,14.6,700,1
2025-07-17T16:08:20.818965359Z,2025-07-17T16:08:20.819130820Z,160,2,1108,A,A,0,14.65,100,130,165461,277732216,ARL,333436425,13.11,100,1,13.68,15,1,13.01,2,1,13.69,100,1,12.98,200,2,13.85,2,1,12.86,100,1,14.2,100,1,12.73,100,1,14.28,100,1,12.71,100,1,14.46,100,1,12.5,700,1,14.48,700,1,12.49,200,2,14.52,200,2,12.46,100,1,14.56,800,2,12.43,700,1,14.6,700,1
2025-07-17T16:08:20.819601669Z,2025-07-17T16:08:20.819767091Z,160,2,1108,C,A,0,17.75,100,0,165422,277732221,ARL,332494297,13.11,100,1,13.68,15,1,13.01,2,1,13.69,100,1,12.98,200,2,13.85,2,1,12.86,100,1,14.2,100,1,12.73,100,1,14.28,100,1,12.71,100,1,14.46,100,1,12.5,700,1,14.48,700,1,12.49,200,2,14.52,200,2,12.46,100,1,14.56,800,2,12.43,700,1,14.6,700,1
2025-07-17T16:08:20.819601669Z,2025-07-17T16:08:20.819767091Z,160,2,1108,A,A,0,17.39,100,130,165422,277732221,ARL,333436441,13.11,100,1,13.68,15,1,13.01,2,1,13.69,100,1,12.98,200,2,13.85,2,1,12.86,100,1,14.2,100,1,12.73,100,1,14.28,100,1,12.71,100,1,14.46,100,1,12.5,700,1,14.48,700,1,12.49,200,2,14.52,200,2,12.46,100,1,14.56,800,2,12.43,700,1,14.6,700,1
2025-07-17T16:08:20.820500575Z,2025-07-17T16:08:20.820666169Z,160,2,1108,C,A,0,16.01,100,0,165594,277732228,ARL,332494245,13.11,100,1,13.68,15,1,13.01,2,1,13.69,100,1,12.98,200,2,13.85,2,1,12.86,100,1,14.2,100,1,12.73,100,1,14.28,100,1,12.71,100,1,14.46,100,1,12.5,700,1,14.48,700,1,12.49,200,2,14.52,200,2,12.46,100,1,14.56,800,2,12.43,700,1,14.6,700,1
2025-07-17T16:08:20.820500575Z,2025-07-17T16:08:20.820666169Z,160,2,1108,A,A,0,15.75,100,130,165594,277732228,ARL,333436449,13.11,100,1,13.68,15,1,13.01,2,1,13.69,100,1,12.98,200,2,13.85,2,1,12.86,100,1,14.2,100,1,12.73,100,1,14.28,100,1,12.71,100,1,14.46,100,1,12.5,700,1,14.48,700,1,12.49,200,2,14.52,200,2,12.46,100,1,14.56,800,2,12.43,700,1,14.6,700,1
2025-07-17T16:08:20.821924168Z,2025-07-17T16:08:20.822089544Z,160,2,1108,C,A,0,14.2,100,130,165376,277732239,ARL,332494893,13.11,100,1,13.68,15,1,13.01,2,1,13.69,100,1,12.98,200,2,13.85,2,1,12.86,100,1,14.28,100,1,12.73,100,1,14.46,100,1,12.71,100,1,14.48,700,1,12.5,700,1,14.52,200,2,12.49,200,2,14.56,800,2,12.46,100,1,14.6,700,1,12.43,700,1,14.65,100,1
2025-07-17T16:08:20.821974299Z,2025-07-17T16:08:20.822139541Z,160,2,1108,A,A,0,13.96,100,130,165242,277732240,ARL,333436473,13.11,100,1,13.68,15,1,13.01,2,1,13.69,100,1,12.98,200,2,13.85,2,1,12.86,100,1,13.96,100,1,12.73,100,1,14.28,100,1,12.71,100,1,14.46,100,1,12.5,700,1,14.48,700,1,12.49,200,2,14.52,200,2,12.46,100,1,14.56,800,2,12.43,700,1,14.6,700,1
2025-07-17T16:08:20.829945074Z,2025-07-17T16:08:20.830110499Z,160,2,1108,C,A,0,14.95,100,0,165425,277732299,ARL,332494281,13.11,100,1,13.68,15,1,13.01,2,1,13.69,100,1,12.98,200,2,13.85,2,1,12.86,100,1,13.96,100,1,12.73,100,1,14.28,100,1,12.71,100,1,14.46,100,1,12.5,700,1,14.48,700,1,12.49,200,2,14.52,200,2,12.46,100,1,14.56,800,2,12.43,700,1,14.6,700,1
2025-07-17T16:08:20.829945074Z,2025-07-17T16:08:20.830110499Z,160,2,1108,A,A,0,14.65,100,130,165425,277732299,ARL,333436589,13.11,100,1,13.68,15,1,13.01,2,1,13.69,100,1,12.98,200,2,13.85,2,1,12.86,100,1,13.96,100,1,12.73,100,1,14.28,100,1,12.71,100,1,14.46,100,1,12.5,700,1,14.48,700,1,12.49,200,2,14.52,200,2,12.46,100,1,14.56,800,2,12.43,700,1,14.6,700,1
2025-07-17T16:08:20.966063681Z,2025-07-17T16:08:20.966229266Z,160,2,1108,C,A,0,14.77,100,0,165585,277733304,ARL,332497653,13.11,100,1,13.68,15,1,13.01,2,1,13.69,100,1,12.98,200,2,13.85,2,1,12.86,100,1,13.96,100,1,12.73,100,1,14.28,100,1,12.71,100,1,14.46,100,1,12.5,700,1,14.48,700,1,12.49,200,2,14.52,200,2,12.46,100,1,14.56,800,2,12.43,700,1,14.6,700,1
2025-07-17T16:08:20.966063681Z,2025-07-17T16:08:20.966229266Z,160,2,1108,A,A,0,14.48,100,130,165585,277733304,ARL,333438545,13.11,100,1,13.68,15,1,13.01,2,1,13.69,100,1,12.98,200,2,13.85,2,1,12.86,100,1,13.96,100,1,12.73,100,1,14.28,100,1,12.71,100,1,14.46,100,1,12.5,700,1,14.48,800,2,12.49,200,2,14.52,200,2,12.46,100,1,14.56,800,2,12.43,700,1,14.6,700,1
2025-07-17T16:08:22.998002821Z,2025-07-17T16:08:22.998168186Z,160,2,1108,C,A,0,13.68,15,130,165365,277766492,ARL,333436357,13.11,100,1,13.69,100,1,13.01,2,1,13.85,2,1,12.98,200,2,13.96,100,1,12.86,100,1,14.28,100,1,12.73,100,1,14.46,100,1,12.71,100,1,14.48,800,2,12.5,700,1,14.52,200,2,12.49,200,2,14.56,800,2,12.46,100,1,14.6,700,1,12.43,700,1,14.65,200,2
2025-07-17T16:08:27.482344236Z,2025-07-17T16:08:27.482509684Z,160,2,1108,C,A,0,13.69,100,130,165448,277841171,ARL,333436361,13.11,100,1,13.85,2,1,13.01,2,1,13.96,100,1,12.98,200,2,14.28,100,1,12.86,100,1,14.46,100,1,12.73,100,1,14.48,800,2,12.71,100,1,14.52,200,2,12.5,700,1,14.56,800,2,12.49,200,2,14.6,700,1,12.46,100,1,14.65,200,2,12.43,700,1,14.68,700,1
2025-07-17T16:08:27.483075481Z,2025-07-17T16:08:27.483241007Z,160,2,1108,C,A,0,14.75,100,0,165526,277841175,ARL,333436397,13.11,100,1,13.85,2,1,13.01,2,1,13.96,100,1,12.98,200,2,14.28,100,1,12.86,100,1,14.46,100,1,12.73,100,1,14.48,800,2,12.71,100,1,14.52,200,2,12.5,700,1,14.56,800,2,12.49,200,2,14.6,700,1,12.46,100,1,14.65,200,2,12.43,700,1,14.68,700,1
2025-07-17T16:08:27.483075481Z,2025-07-17T16:08:27.483241007Z,160,2,1108,A,A,0,14.99,100,130,165526,277841175,ARL,333581389,13.11,100,1,13.85,2,1,13.01,2,1,13.96,100,1,12.98,200,2,14.28,100,1,12.86,100,1,14.46,100,1,12.73,100,1,14.48,800,2,12.71,100,1,14.52,200,2,12.5,700,1,14.56,800,2,12.49,200,2,14.6,700,1,12.46,100,1,14.65,200,2,12.43,700,1,14.68,700,1
2025-07-17T16:08:27.483420069Z,2025-07-17T16:08:27.483585892Z,160,2,1108,C,A,0,14.52,100,0,165823,277841178,ARL,328780577,13.11,100,1,13.85,2,1,13.01,2,1,13.96,100,1,12.98,200,2,14.28,100,1,12.86,100,1,14.46,100,1,12.73,100,1,14.48,800,2,12.71,100,1,14.52,100,1,12.5,700,1,14.56,800,2,12.49,200,2,14.6,700,1,12.46,100,1,14.65,200,2,12.43,700,1,14.68,700,1
2025-07-17T16:08:27.483420069Z,2025-07-17T16:08:27.483585892Z,160,2,1108,A,A,0,14.74,100,130,165823,277841178,ARL,333581393,13.11,100,1,13.85,2,1,13.01,2,1,13.96,100,1,12.98,200,2,14.28,100,1,12.86,100,1,14.46,100,1,12.73,100,1,14.48,800,2,12.71,100,1,14.52,100,1,12.5,700,1,14.56,800,2,12.49,200,2,14.6,700,1,12.46,100,1,14.65,200,2,12.43,700,1,14.68,700,1
2025-07-17T16:08:27.483913735Z,2025-07-17T16:08:27.484079224Z,160,2,1108,C,A,0,14.65,100,0,165489,277841218,ARL,333436589,13.11,100,1,13.85,2,1,13.01,2,1,13.96,100,1,12.98,200,2,14.28,100,1,12.86,100,1,14.46,100,1,12.73,100,1,14.48,800,2,12.71,100,1,14.52,100,1,12.5,700,1,14.56,800,2,12.49,200,2,14.6,700,1,12.46,100,1,14.65,100,1,12.43,700,1,14.68,700,1
2025-07-17T16:08:27.483913735Z,2025-07-17T16:08:27.484079224Z,160,2,1108,A,A,0,14.94,100,130,165489,277841218,ARL,333581409,13.11,100,1,13.85,2,1,13.01,2,1,13.96,100,1,12.98,200,2,14.28,100,1,12.86,100,1,14.46,100,1,12.73,100,1,14.48,800,2,12.71,100,1,14.52,100,1,12.5,700,1,14.56,800,2,12.49,200,2,14.6,700,1,12.46,100,1,14.65,100,1,12.43,700,1,14.68,700,1
2025-07-17T16:08:27.484693568Z,2025-07-17T16:08:27.484859188Z,160,2,1108,C,A,0,17.39,100,0,165620,277841226,ARL,333436441,13.11,100,1,13.85,2,1,13.01,2,1,13.96,100,1,12.98,200,2,14.28,100,1,12.86,100,1,14.46,100,1,12.73,100,1,14.48,800,2,12.71,100,1,14.52,100,1,12.5,700,1,14.56,800,2,12.49,200,2,14.6,700,1,12.46,100,1,14.65,100,1,12.43,700,1,14.68,700,1
2025-07-17T16:08:27.484693568Z,2025-07-17T16:08:27.484859188Z,160,2,1108,A,A,0,17.73,100,130,165620,277841226,ARL,333581425,13.11,100,1,13.85,2,1,13.01,2,1,13.96,100,1,12.98,200,2,14.28,100,1,12.86,100,1,14.46,100,1,12.73,100,1,14.48,800,2,12.71,100,1,14.52,100,1,12.5,700,1,14.56,800,2,12.49,200,2,14.6,700,1,12.46,100,1,14.65,100,1,12.43,700,1,14.68,700,1
2025-07-17T16:08:27.484800296Z,2025-07-17T16:08:27.484965957Z,160,2,1108,C,A,0,14.65,100,0,165661,277841228,ARL,333436425,13.11,100,1,13.85,2,1,13.01,2,1,13.96,100,1,12.98,200,2,14.28,100,1,12.86,100,1,14.46,100,1,12.73,100,1,14.48,800,2,12.71,100,1,14.52,100,1,12.5,700,1,14.56,800,2,12.49,200,2,14.6,700,1,12.46,100,1,14.68,700,1,12.43,700,1,14.74,100,1
2025-07-17T16:08:27.484800296Z,2025-07-17T16:08:27.484965957Z,160,2,1108,A,A,0,14.94,100,130,165661,277841228,ARL,333581429,13.11,100,1,13.85,2,1,13.01,2,1,13.96,100,1,12.98,200,2,14.28,100,1,12.86,100,1,14.46,100,1,12.73,100,1,14.48,800,2,12.71,100,1,14.52,100,1,12.5,700,1,14.56,800,2,12.49,200,2,14.6,700,1,12.46,100,1,14.68,700,1,12.43,700,1,14.74,100,1
2025-07-17T16:08:27.484813280Z,2025-07-17T16:08:27.484978859Z,160,2,1108,C,A,0,15.75,100,0,165579,277841229,ARL,333436449,13.11,100,1,13.85,2,1,13.01,2,1,13.96,100,1,12.98,200,2,14.28,100,1,12.86,100,1,14.46,100,1,12.73,100,1,14.48,800,2,12.71,100,1,14.52,100,1,12.5,700,1,14.56,800,2,12.49,200,2,14.6,700,1,12.46,100,1,14.68,700,1,12.43,700,1,14.74,100,1
2025-07-17T16:08:27.484813280Z,2025-07-17T16:08:27.484978859Z,160,2,1108,A,A,0,16.06,100,130,165579,277841229,ARL,333581433,13.11,100,1,13.85,2,1,13.01,2,1,13.96,100,1,12.98,200,2,14.28,100,1,12.86,100,1,14.46,100,1,12.73,100,1,14.48,800,2,12.71,100,1,14.52,100,1,12.5,700,1,14.56,800,2,12.49,200,2,14.6,700,1,12.46,100,1,14.68,700,1,12.43,700,1,14.74,100,1
2025-07-17T16:08:27.485186411Z,2025-07-17T16:08:27.485352204Z,160,2,1108,C,A,0,15.06,100,0,165793,277841231,ARL,333436421,13.11,100,1,13.85,2,1,13.01,2,1,13.96,100,1,12.98,200,2,14.28,100,1,12.86,100,1,14.46,100,1,12.73,100,1,14.48,800,2,12.71,100,1,14.52,100,1,12.5,700,1,14.56,800,2,12.49,200,2,14.6,700,1,12.46,100,1,14.68,700,1,12.43,700,1,14.74,100,1
2025-07-17T16:08:27.485186411Z,2025-07-17T16:08:27.485352204Z,160,2,1108,A,A,0,15.36,100,130,165793,277841231,ARL,333581441,13.11,100,1,13.85,2,1,13.01,2,1,13.96,100,1,12.98,200,2,14.28,100,1,12.86,100,1,14.46,100,1,12.73,100,1,14.48,800,2,12.71,100,1,14.52,100,1,12.5,700,1,14.56,800,2,12.49,200,2,14.6,700,1,12.46,100,1,14.68,700,1,12.43,700,1,14.74,100,1
2025-07-17T16:08:27.487097702Z,2025-07-17T16:08:27.487263276Z,160,2,1108,C,A,0,14.52,100,0,165574,277841319,ARL,328780597,13.11,100,1,13.85,2,1,13.01,2,1,13.96,100,1,12.98,200,2,14.28,100,1,12.86,100,1,14.46,100,1,12.73,100,1,14.48,800,2,12.71,100,1,14.56,800,2,12.5,700,1,14.6,700,1,12.49,200,2,14.68,700,1,12.46,100,1,14.74,100,1,12.43,700,1,14.94,200,2
2025-07-17T16:08:27.487097702Z,2025-07-17T16:08:27.487263276Z,160,2,1108,A,A,0,14.74,100,130,165574,277841319,ARL,333581481,13.11,100,1,13.85,2,1,13.01,2,1,13.96,100,1,12.98,200,2,14.28,100,1,12.86,100,1,14.46,100,1,12.73,100,1,14.48,800,2,12.71,100,1,14.56,800,2,12.5,700,1,14.6,700,1,12.49,200,2,14.68,700,1,12.46,100,1,14.74,200,2,12.43,700,1,14.94,200,2
2025-07-17T16:08:27.492093401Z,2025-07-17T16:08:27.492258906Z,160,2,1108,C,A,0,14.48,100,130,165505,277841396,ARL,333438545,13.11,100,1,13.85,2,1,13.01,2,1,13.96,100,1,12.98,200,2,14.28,100,1,12.86,100,1,14.46,100,1,12.73,100,1,14.48,700,1,12.71,100,1,14.56,800,2,12.5,700,1,14.6,700,1,12.49,200,2,14.68,700,1,12.46,100,1,14.74,200,2,12.43,700,1,14.94,200,2
2025-07-17T16:08:27.492220454Z,2025-07-17T16:08:27.492385750Z,160,2,1108,A,A,0,14.75,100,130,165296,277841397,ARL,333581569,13.11,100,1,13.85,2,1,13.01,2,1,13.96,100,1,12.98,200,2,14.28,100,1,12.86,100,1,14.46,100,1,12.73,100,1,14.48,700,1,12.71,100,1,14.56,800,2,12.5,700,1,14.6,700,1,12.49,200,2,14.68,700,1,12.46,100,1,14.74,200,2,12.43,700,1,14.75,100,1
2025-07-17T16:08:27.496770678Z,2025-07-17T16:08:27.496936122Z,160,2,1108,C,A,0,13.96,100,130,165444,277841427,ARL,333436473,13.11,100,1,13.85,2,1,13.01,2,1,14.28,100,1,12.98,200,2,14.46,100,1,12.86,100,1,14.48,700,1,12.73,100,1,14.56,800,2,12.71,100,1,14.6,700,1,12.5,700,1,14.68,700,1,12.49,200,2,14.74,200,2,12.46,100,1,14.75,100,1,12.43,700,1,14.94,200,2
2025-07-17T16:08:27.496822540Z,2025-07-17T16:08:27.496987832Z,160,2,1108,A,A,0,14.19,100,130,165292,277841428,ARL,333581625,13.11,100,1,13.85,2,1,13.01,2,1,14.19,100,1,12.98,200,2,14.28,100,1,12.86,100,1,14.46,100,1,12.73,100,1,14.48,700,1,12.71,100,1,14.56,800,2,12.5,700,1,14.6,700,1,12.49,200,2,14.68,700,1,12.46,100,1,14.74,200,2,12.43,700,1,14.75,100,1
2025-07-17T16:08:27.500928061Z,2025-07-17T16:08:27.501093618Z,160,2,1108,C,A,0,13.85,2,0,165557,277841469,ARL,331155889,13.11,100,1,14.19,100,1,13.01,2,1,14.28,100,1,12.98,200,2,14.46,100,1,12.86,100,1,14.48,700,1,12.73,100,1,14.56,800,2,12.71,100,1,14.6,700,1,12.5,700,1,14.68,700,1,12.49,200,2,14.74,200,2,12.46,100,1,14.75,100,1,12.43,700,1,14.94,200,2
2025-07-17T16:08:27.500928061Z,2025-07-17T16:08:27.501093618Z,160,2,1108,A,A,0,13.98,2,130,165557,277841469,ARL,333581677,13.11,100,1,13.98,2,1,13.01,2,1,14.19,100,1,12.98,200,2,14.28,100,1,12.86,100,1,14.46,100,1,12.73,100,1,14.48,700,1,12.71,100,1,14.56,800,2,12.5,700,1,14.6,700,1,12.49,200,2,14.68,700,1,12.46,100,1,14.74,200,2,12.43,700,1,14.75,100,1
2025-07-17T16:08:27.516449334Z,2025-07-17T16:08:27.516614373Z,160,2,1108,C,A,0,14.19,100,130,165039,277841551,ARL,333581625,13.11,100,1,13.98,2,1,13.01,2,1,14.28,100,1,12.98,200,2,14.46,100,1,12.86,100,1,14.48,700,1,12.73,100,1,14.56,800,2,12.71,100,1,14.6,700,1,12.5,700,1,14.68,700,1,12.49,200,2,14.74,200,2,12.46,100,1,14.75,100,1,12.43,700,1,14.94,200,2
2025-07-17T16:08:27.516496962Z,2025-07-17T16:08:27.516662099Z,160,2,1108,A,A,0,14.26,100,130,165137,277841552,ARL,333581765,13.11,100,1,13.98,2,1,13.01,2,1,14.26,100,1,12.98,200,2,14.28,100,1,12.86,100,1,14.46,100,1,12.73,100,1,14.48,700,1,12.71,100,1,14.56,800,2,12.5,700,1,14.6,700,1,12.49,200,2,14.68,700,1,12.46,100,1,14.74,200,2,12.43,700,1,14.75,100,1
2025-07-17T16:08:27.533773259Z,2025-07-17T16:08:27.533938450Z,160,2,1108,C,A,0,14.99,100,0,165191,277841588,ARL,333581389,13.11,100,1,13.98,2,1,13.01,2,1,14.26,100,1,12.98,200,2,14.28,100,1,12.86,100,1,14.46,100,1,12.73,100,1,14.48,700,1,12.71,100,1,14.56,800,2,12.5,700,1,14.6,700,1,12.49,200,2,14.68,700,1,12.46,100,1,14.74,200,2,12.43,700,1,14.75,100,1
2025-07-17T16:08:27.533773259Z,2025-07-17T16:08:27.533938450Z,160,2,1108,A,A,0,15.04,100,130,165191,277841588,ARL,333581845,13.11,100,1,13.98,2,1,13.01,2,1,14.26,100,1,12.98,200,2,14.28,100,1,12.86,100,1,14.46,100,1,12.73,100,1,14.48,700,1,12.71,100,1,14.56,800,2,12.5,700,1,14.6,700,1,12.49,200,2,14.68,700,1,12.46,100,1,14.74,200,2,12.43,700,1,14.75,100,1
2025-07-17T16:08:27.987513451Z,2025-07-17T16:08:27.987678739Z,160,2,1108,A,A,0,13.99,100,130,165288,277846288,ARL,333590057,13.11,100,1,13.98,2,1,13.01,2,1,13.99,100,1,12.98,200,2,14.26,100,1,12.86,100,1,14.28,100,1,12.73,100,1,14.46,100,1,12.71,100,1,14.48,700,1,12.5,700,1,14.56,800,2,12.49,200,2,14.6,700,1,12.46,100,1,14.68,700,1,12.43,700,1,14.74,200,2
2025-07-17T16:08:58.024814068Z,2025-07-17T16:08:58.024979382Z,160,2,1108,A,A,0,13.81,15,130,165314,278261182,ARL,334141429,13.11,100,1,13.81,15,1,13.01,2,1,13.98,2,1,12.98,200,2,13.99,100,1,12.86,100,1,14.26,100,1,12.73,100,1,14.28,100,1,12.71,100,1,14.46,100,1,12.5,700,1,14.48,700,1,12.49,200,2,14.56,800,2,12.46,100,1,14.6,700,1,12.43,700,1,14.68,700,1
2025-07-17T16:09:00.222509491Z,2025-07-17T16:09:00.222675234Z,160,2,1108,C,A,0,13.99,100,0,165743,278295684,ARL,333590057,13.11,100,1,13.81,15,1,13.01,2,1,13.98,2,1,12.98,200,2,14.26,100,1,12.86,100,1,14.28,100,1,12.73,100,1,14.46,100,1,12.71,100,1,14.48,700,1,12.5,700,1,14.56,800,2,12.49,200,2,14.6,700,1,12.46,100,1,14.68,700,1,12.43,700,1,14.74,200,2
2025-07-17T16:09:00.222509491Z,2025-07-17T16:09:00.222675234Z,160,2,1108,A,A,0,13.82,100,130,165743,278295684,ARL,334189729,13.11,100,1,13.81,15,1,13.01,2,1,13.82,100,1,12.98,200,2,13.98,2,1,12.86,100,1,14.26,100,1,12.73,100,1,14.28,100,1,12.71,100,1,14.46,100,1,12.5,700,1,14.48,700,1,12.49,200,2,14.56,800,2,12.46,100,1,14.6,700,1,12.43,700,1,14.68,700,1
2025-07-17T16:09:00.223269382Z,2025-07-17T16:09:00.223436757Z,160,2,1108,C,A,0,15.04,100,0,167375,278295848,ARL,333581845,13.11,100,1,13.81,15,1,13.01,2,1,13.82,100,1,12.98,200,2,13.98,2,1,12.86,100,1,14.26,100,1,12.73,100,1,14.28,100,1,12.71,100,1,14.46,100,1,12.5,700,1,14.48,700,1,12.49,200,2,14.56,800,2,12.46,100,1,14.6,700,1,12.43,700,1,14.68,700,1
2025-07-17T16:09:00.223269382Z,2025-07-17T16:09:00.223436757Z,160,2,1108,A,A,0,14.89,100,128,167375,278295848,ARL,334189777,13.11,100,1,13.81,15,1,13.01,2,1,13.82,100,1,12.98,200,2,13.98,2,1,12.86,100,1,14.26,100,1,12.73,100,1,14.28,100,1,12.71,100,1,14.46,100,1,12.5,700,1,14.48,700,1,12.49,200,2,14.56,800,2,12.46,100,1,14.6,700,1,12.43,700,1,14.68,700,1
2025-07-17T16:09:00.226338384Z,2025-07-17T16:09:00.226504346Z,160,2,1108,C,A,0,14.75,100,0,165962,278296281,ARL,333581569,13.11,100,1,13.81,15,1,13.01,2,1,13.82,100,1,12.98,200,2,13.98,2,1,12.86,100,1,14.26,100,1,12.73,100,1,14.28,100,1,12.71,100,1,14.46,100,1,12.5,700,1,14.48,700,1,12.49,200,2,14.56,800,2,12.46,100,1,14.6,700,1,12.43,700,1,14.68,700,1
2025-07-17T16:09:00.226338384Z,2025-07-17T16:09:00.226504346Z,160,2,1108,A,A,0,14.61,100,130,165962,278296281,ARL,334190189,13.11,100,1,13.81,15,1,13.01,2,1,13.82,100,1,12.98,200,2,13.98,2,1,12.86,100,1,14.26,100,1,12.73,100,1,14.28,100,1,12.71,100,1,14.46,100,1,12.5,700,1,14.48,700,1,12.49,200,2,14.56,800,2,12.46,100,1,14.6,700,1,12.43,700,1,14.61,100,1
2025-07-17T16:09:00.227763275Z,2025-07-17T16:09:00.227929061Z,160,2,1108,C,A,0,14.26,100,130,165786,278296402,ARL,333581765,13.11,100,1,13.81,15,1,13.01,2,1,13.82,100,1,12.98,200,2,13.98,2,1,12.86,100,1,14.28,100,1,12.73,100,1,14.46,100,1,12.71,100,1,14.48,700,1,12.5,700,1,14.56,800,2,12.49,200,2,14.6,700,1,12.46,100,1,14.61,100,1,12.43,700,1,14.68,700,1
2025-07-17T16:09:00.227818153Z,2025-07-17T16:09:00.227983483Z,160,2,1108,A,A,0,14.1,100,130,165330,278296411,ARL,334190225,13.11,100,1,13.81,15,1,13.01,2,1,13.82,100,1,12.98,200,2,13.98,2,1,12.86,100,1,14.1,100,1,12.73,100,1,14.28,100,1,12.71,100,1,14.46,100,1,12.5,700,1,14.48,700,1,12.49,200,2,14.56,800,2,12.46,100,1,14.6,700,1,12.43,700,1,14.61,100,1
2025-07-17T16:09:00.232743323Z,2025-07-17T16:09:00.232908882Z,160,2,1108,C,A,0,14.94,100,0,165559,278296544,ARL,333581429,13.11,100,1,13.81,15,1,13.01,2,1,13.82,100,1,12.98,200,2,13.98,2,1,12.86,100,1,14.1,100,1,12.73,100,1,14.28,100,1,12.71,100,1,14.46,100,1,12.5,700,1,14.48,700,1,12.49,200,2,14.56,800,2,12.46,100,1,14.6,700,1,12.43,700,1,14.61,100,1
2025-07-17T16:09:00.232743323Z,2025-07-17T16:09:00.232908882Z,160,2,1108,A,A,0,14.79,100,130,165559,278296544,ARL,334190353,13.11,100,1,13.81,15,1,13.01,2,1,13.82,100,1,12.98,200,2,13.98,2,1,12.86,100,1,14.1,100,1,12.73,100,1,14.28,100,1,12.71,100,1,14.46,100,1,12.5,700,1,14.48,700,1,12.49,200,2,14.56,800,2,12.46,100,1,14.6,700,1,12.43,700,1,14.61,100,1
2025-07-17T16:09:00.326127587Z,2025-07-17T16:09:00.326293286Z,160,2,1108,C,A,0,17.73,100,0,165699,278298302,ARL,333581425,13.11,100,1,13.81,15,1,13.01,2,1,13.82,100,1,12.98,200,2,13.98,2,1,12.86,100,1,14.1,100,1,12.73,100,1,14.28,100,1,12.71,100,1,14.46,100,1,12.5,700,1,14.48,700,1,12.49,200,2,14.56,800,2,12.46,100,1,14.6,700,1,12.43,700,1,14.61,100,1
2025-07-17T16:09:00.326127587Z,2025-07-17T16:09:00.326293286Z,160,2,1108,A,A,0,17.56,100,130,165699,278298302,ARL,334192253,13.11,100,1,13.81,15,1,13.01,2,1,13.82,100,1,12.98,200,2,13.98,2,1,12.86,100,1,14.1,100,1,12.73,100,1,14.28,100,1,12.71,100,1,14.46,100,1,12.5,700,1,14.48,700,1,12.49,200,2,14.56,800,2,12.46,100,1,14.6,700,1,12.43,700,1,14.61,100,1
2025-07-17T16:09:00.335442266Z,2025-07-17T16:09:00.335607827Z,160,2,1108,C,A,0,16.06,100,0,165561,278298372,ARL,333581433,13.11,100,1,13.81,15,1,13.01,2,1,13.82,100,1,12.98,200,2,13.98,2,1,12.86,100,1,14.1,100,1,12.73,100,1,14.28,100,1,12.71,100,1,14.46,100,1,12.5,700,1,14.48,700,1,12.49,200,2,14.56,800,2,12.46,100,1,14.6,700,1,12.43,700,1,14.61,100,1
2025-07-17T16:09:00.335442266Z,2025-07-17T16:09:00.335607827Z,160,2,1108,A,A,0,15.9,100,130,165561,278298372,ARL,334192405,13.11,100,1,13.81,15,1,13.01,2,1,13.82,100,1,12.98,200,2,13.98,2,1,12.86,100,1,14.1,100,1,12.73,100,1,14.28,100,1,12.71,100,1,14.46,100,1,12.5,700,1,14.48,700,1,12.49,200,2,14.56,800,2,12.46,100,1,14.6,700,1,12.43,700,1,14.61,100,1
2025-07-17T16:09:00.695610142Z,2025-07-17T16:09:00.695776010Z,160,2,1108,C,A,0,14.94,100,0,165868,278304343,ARL,333581409,13.11,100,1,13.81,15,1,13.01,2,1,13.82,100,1,12.98,200,2,13.98,2,1,12.86,100,1,14.1,100,1,12.73,100,1,14.28,100,1,12.71,100,1,14.46,100,1,12.5,700,1,14.48,700,1,12.49,200,2,14.56,800,2,12.46,100,1,14.6,700,1,12.43,700,1,14.61,100,1
2025-07-17T16:09:00.695610142Z,2025-07-17T16:09:00.695776010Z,160,2,1108,A,A,0,14.79,100,130,165868,278304343,ARL,334199009,13.11,100,1,13.81,15,1,13.01,2,1,13.82,100,1,12.98,200,2,13.98,2,1,12.86,100,1,14.1,100,1,12.73,100,1,14.28,100,1,12.71,100,1,14.46,100,1,12.5,700,1,14.48,700,1,12.49,200,2,14.56,800,2,12.46,100,1,14.6,700,1,12.43,700,1,14.61,100,1
2025-07-17T16:09:08.719524374Z,2025-07-17T16:09:08.719690693Z,160,2,1108,A,A,0,13.75,15,130,166319,278436950,ARL,334366613,13.11,100,1,13.75,15,1,13.01,2,1,13.81,15,1,12.98,200,2,13.82,100,1,12.86,100,1,13.98,2,1,12.73,100,1,14.1,100,1,12.71,100,1,14.28,100,1,12.5,700,1,14.46,100,1,12.49,200,2,14.48,700,1,12.46,100,1,14.56,800,2,12.43,700,1,14.6,700,1
2025-07-17T16:09:08.719706070Z,2025-07-17T16:09:08.719871410Z,160,2,1108,C,A,0,13.82,100,0,165340,278436967,ARL,334189729,13.11,100,1,13.75,15,1,13.01,2,1,13.81,15,1,12.98,200,2,13.98,2,1,12.86,100,1,14.1,100,1,12.73,100,1,14.28,100,1,12.71,100,1,14.46,100,1,12.5,700,1,14.48,700,1,12.49,200,2,14.56,800,2,12.46,100,1,14.6,700,1,12.43,700,1,14.61,100,1
2025-07-17T16:09:08.719706070Z,2025-07-17T16:09:08.719871410Z,160,2,1108,A,A,0,13.76,100,130,165340,278436967,ARL,334366617,13.11,100,1,13.75,15,1,13.01,2,1,13.76,100,1,12.98,200,2,13.81,15,1,12.86,100,1,13.98,2,1,12.73,100,1,14.1,100,1,12.71,100,1,14.28,100,1,12.5,700,1,14.46,100,1,12.49,200,2,14.48,700,1,12.46,100,1,14.56,800,2,12.43,700,1,14.6,700,1
2025-07-17T16:09:08.720442245Z,2025-07-17T16:09:08.720607932Z,160,2,1108,C,A,0,14.89,100,0,165687,278436994,ARL,334189777,13.11,100,1,13.75,15,1,13.01,2,1,13.76,100,1,12.98,200,2,13.81,15,1,12.86,100,1,13.98,2,1,12.73,100,1,14.1,100,1,12.71,100,1,14.28,100,1,12.5,700,1,14.46,100,1,12.49,200,2,14.48,700,1,12.46,100,1,14.56,800,2,12.43,700,1,14.6,700,1
2025-07-17T16:09:08.720442245Z,2025-07-17T16:09:08.720607932Z,160,2,1108,A,A,0,14.83,100,130,165687,278436994,ARL,334366645,13.11,100,1,13.75,15,1,13.01,2,1,13.76,100,1,12.98,200,2,13.81,15,1,12.86,100,1,13.98,2,1,12.73,100,1,14.1,100,1,12.71,100,1,14.28,100,1,12.5,700,1,14.46,100,1,12.49,200,2,14.48,700,1,12.46,100,1,14.56,800,2,12.43,700,1,14.6,700,1
2025-07-17T16:09:18.819135505Z,2025-07-17T16:09:18.819300735Z,160,2,1108,C,A,0,13.81,15,130,165230,278596985,ARL,334141429,13.11,100,1,13.75,15,1,13.01,2,1,13.76,100,1,12.98,200,2,13.98,2,1,12.86,100,1,14.1,100,1,12.73,100,1,14.28,100,1,12.71,100,1,14.46,100,1,12.5,700,1,14.48,700,1,12.49,200,2,14.56,800,2,12.46,100,1,14.6,700,1,12.43,700,1,14.61,100,1
2025-07-17T16:09:19.927039122Z,2025-07-17T16:09:19.927205023Z,160,2,1108,A,A,0,13.73,15,130,165901,278621672,ARL,334583329,13.11,100,1,13.73,15,1,13.01,2,1,13.75,15,1,12.98,200,2,13.76,100,1,12.86,100,1,13.98,2,1,12.73,100,1,14.1,100,1,12.71,100,1,14.28,100,1,12.5,700,1,14.46,100,1,12.49,200,2,14.48,700,1,12.46,100,1,14.56,800,2,12.43,700,1,14.6,700,1
2025-07-17T16:09:19.927745104Z,2025-07-17T16:09:19.927910703Z,160,2,1108,C,A,0,14.74,100,0,165599,278621693,ARL,333581393,13.11,100,1,13.73,15,1,13.01,2,1,13.75,15,1,12.98,200,2,13.76,100,1,12.86,100,1,13.98,2,1,12.73,100,1,14.1,100,1,12.71,100,1,14.28,100,1,12.5,700,1,14.46,100,1,12.49,200,2,14.48,700,1,12.46,100,1,14.56,800,2,12.43,700,1,14.6,700,1
2025-07-17T16:09:19.927745104Z,2025-07-17T16:09:19.927910703Z,160,2,1108,A,A,0,14.62,100,130,165599,278621693,ARL,334583349,13.11,100,1,13.73,15,1,13.01,2,1,13.75,15,1,12.98,200,2,13.76,100,1,12.86,100,1,13.98,2,1,12.73,100,1,14.1,100,1,12.71,100,1,14.28,100,1,12.5,700,1,14.46,100,1,12.49,200,2,14.48,700,1,12.46,100,1,14.56,800,2,12.43,700,1,14.6,700,1
2025-07-17T16:09:19.928153837Z,2025-07-17T16:09:19.928319369Z,160,2,1108,C,A,0,14.74,100,0,165532,278621695,ARL,333581481,13.11,100,1,13.73,15,1,13.01,2,1,13.75,15,1,12.98,200,2,13.76,100,1,12.86,100,1,13.98,2,1,12.73,100,1,14.1,100,1,12.71,100,1,14.28,100,1,12.5,700,1,14.46,100,1,12.49,200,2,14.48,700,1,12.46,100,1,14.56,800,2,12.43,700,1,14.6,700,1
2025-07-17T16:09:19.928153837Z,2025-07-17T16:09:19.928319369Z,160,2,1108,A,A,0,14.62,100,130,165532,278621695,ARL,334583361,13.11,100,1,13.73,15,1,13.01,2,1,13.75,15,1,12.98,200,2,13.76,100,1,12.86,100,1,13.98,2,1,12.73,100,1,14.1,100,1,12.71,100,1,14.28,100,1,12.5,700,1,14.46,100,1,12.49,200,2,14.48,700,1,12.46,100,1,14.56,800,2,12.43,700,1,14.6,700,1
2025-07-17T16:09:20.284695585Z,2025-07-17T16:09:20.284861075Z,160,2,1108,C,A,0,13.76,100,0,165490,278629057,ARL,334366617,13.11,100,1,13.73,15,1,13.01,2,1,13.75,15,1,12.98,200,2,13.98,2,1,12.86,100,1,14.1,100,1,12.73,100,1,14.28,100,1,12.71,100,1,14.46,100,1,12.5,700,1,14.48,700,1,12.49,200,2,14.56,800,2,12.46,100,1,14.6,700,1,12.43,700,1,14.61,100,1
2025-07-17T16:09:20.284695585Z,2025-07-17T16:09:20.284861075Z,160,2,1108,A,A,0,13.74,100,130,165490,278629057,ARL,334593569,13.11,100,1,13.73,15,1,13.01,2,1,13.74,100,1,12.98,200,2,13.75,15,1,12.86,100,1,13.98,2,1,12.73,100,1,14.1,100,1,12.71,100,1,14.28,100,1,12.5,700,1,14.46,100,1,12.49,200,2,14.48,700,1,12.46,100,1,14.56,800,2,12.43,700,1,14.6,700,1
2025-07-17T16:09:20.293106270Z,2025-07-17T16:09:20.293271620Z,160,2,1108,C,A,0,14.1,100,130,165350,278629219,ARL,334190225,13.11,100,1,13.73,15,1,13.01,2,1,13.74,100,1,12.98,200,2,13.75,15,1,12.86,100,1,13.98,2,1,12.73,100,1,14.28,100,1,12.71,100,1,14.46,100,1,12.5,700,1,14.48,700,1,12.49,200,2,14.56,800,2,12.46,100,1,14.6,700,1,12.43,700,1,14.61,100,1
2025-07-17T16:09:20.293161454Z,2025-07-17T16:09:20.293326641Z,160,2,1108,A,A,0,14.01,100,130,165187,278629220,ARL,334593753,13.11,100,1,13.73,15,1,13.01,2,1,13.74,100,1,12.98,200,2,13.75,15,1,12.86,100,1,13.98,2,1,12.73,100,1,14.01,100,1,12.71,100,1,14.28,100,1,12.5,700,1,14.46,100,1,12.49,200,2,14.48,700,1,12.46,100,1,14.56,800,2,12.43,700,1,14.6,700,1
2025-07-17T16:09:20.818648795Z,2025-07-17T16:09:20.818813935Z,160,2,1108,C,A,0,13.73,15,130,165140,278640667,ARL,334583329,13.11,100,1,13.74,100,1,13.01,2,1,13.75,15,1,12.98,200,2,13.98,2,1,12.86,100,1,14.01,100,1,12.73,100,1,14.28,100,1,12.71,100,1,14.46,100,1,12.5,700,1,14.48,700,1,12.49,200,2,14.56,800,2,12.46,100,1,14.6,700,1,12.43,700,1,14.61,100,1
2025-07-17T16:09:20.818761228Z,2025-07-17T16:09:20.818926356Z,160,2,1108,C,A,0,13.75,15,130,165128,278640670,ARL,334366613,13.11,100,1,13.74,100,1,13.01,2,1,13.98,2,1,12.98,200,2,14.01,100,1,12.86,100,1,14.28,100,1,12.73,100,1,14.46,100,1,12.71,100,1,14.48,700,1,12.5,700,1,14.56,800,2,12.49,200,2,14.6,700,1,12.46,100,1,14.61,100,1,12.43,700,1,14.62,200,2
2025-07-17T16:09:28.985956629Z,2025-07-17T16:09:28.986122432Z,160,2,1108,C,A,0,13.98,2,0,165803,278784943,ARL,333581677,13.11,100,1,13.74,100,1,13.01,2,1,14.01,100,1,12.98,200,2,14.28,100,1,12.86,100,1,14.46,100,1,12.73,100,1,14.48,700,1,12.71,100,1,14.56,800,2,12.5,700,1,14.6,700,1,12.49,200,2,14.61,100,1,12.46,100,1,14.62,200,2,12.43,700,1,14.68,700,1
2025-07-17T16:09:28.985956629Z,2025-07-17T16:09:28.986122432Z,160,2,1108,A,A,0,13.9,2,130,165803,278784943,ARL,334804177,13.11,100,1,13.74,100,1,13.01,2,1,13.9,2,1,12.98,200,2,14.01,100,1,12.86,100,1,14.28,100,1,12.73,100,1,14.46,100,1,12.71,100,1,14.48,700,1,12.5,700,1,14.56,800,2,12.49,200,2,14.6,700,1,12.46,100,1,14.61,100,1,12.43,700,1,14.62,200,2
2025-07-17T16:09:40.821522565Z,2025-07-17T16:09:40.821687905Z,160,2,1108,A,A,0,13.7,15,130,165340,278938091,ARL,335003269,13.11,100,1,13.7,15,1,13.01,2,1,13.74,100,1,12.98,200,2,13.9,2,1,12.86,100,1,14.01,100,1,12.73,100,1,14.28,100,1,12.71,100,1,14.46,100,1,12.5,700,1,14.48,700,1,12.49,200,2,14.56,800,2,12.46,100,1,14.6,700,1,12.43,700,1,14.61,100,1
2025-07-17T16:09:40.853439053Z,2025-07-17T16:09:40.853604577Z,160,2,1108,C,A,0,13.74,100,0,165524,278938747,ARL,334593569,13.11,100,1,13.7,15,1,13.01,2,1,13.9,2,1,12.98,200,2,14.01,100,1,12.86,100,1,14.28,100,1,12.73,100,1,14.46,100,1,12.71,100,1,14.48,700,1,12.5,700,1,14.56,800,2,12.49,200,2,14.6,700,1,12.46,100,1,14.61,100,1,12.43,700,1,14.62,200,2
2025-07-17T16:09:40.853439053Z,2025-07-17T16:09:40.853604577Z,160,2,1108,A,A,0,13.71,100,130,165524,278938747,ARL,335003813,13.11,100,1,13.7,15,1,13.01,2,1,13.71,100,1,12.98,200,2,13.9,2,1,12.86,100,1,14.01,100,1,12.73,100,1,14.28,100,1,12.71,100,1,14.46,100,1,12.5,700,1,14.48,700,1,12.49,200,2,14.56,800,2,12.46,100,1,14.6,700,1,12.43,700,1,14.61,100,1
2025-07-17T16:09:40.854190408Z,2025-07-17T16:09:40.854356022Z,160,2,1108,C,A,0,14.83,100,0,165614,278938765,ARL,334366645,13.11,100,1,13.7,15,1,13.01,2,1,13.71,100,1,12.98,200,2,13.9,2,1,12.86,100,1,14.01,100,1,12.73,100,1,14.28,100,1,12.71,100,1,14.46,100,1,12.5,700,1,14.48,700,1,12.49,200,2,14.56,800,2,12.46,100,1,14.6,700,1,12.43,700,1,14.61,100,1
2025-07-17T16:09:40.854190408Z,2025-07-17T16:09:40.854356022Z,160,2,1108,A,A,0,14.77,100,130,165614,278938765,ARL,335003845,13.11,100,1,13.7,15,1,13.01,2,1,13.71,100,1,12.98,200,2,13.9,2,1,12.86,100,1,14.01,100,1,12.73,100,1,14.28,100,1,12.71,100,1,14.46,100,1,12.5,700,1,14.48,700,1,12.49,200,2,14.56,800,2,12.46,100,1,14.6,700,1,12.43,700,1,14.61,100,1
2025-07-17T16:09:40.855558831Z,2025-07-17T16:09:40.855724422Z,160,2,1108,C,A,0,17.56,100,0,165591,278938788,ARL,334192253,13.11,100,1,13.7,15,1,13.01,2,1,13.71,100,1,12.98,200,2,13.9,2,1,12.86,100,1,14.01,100,1,12.73,100,1,14.28,100,1,12.71,100,1,14.46,100,1,12.5,700,1,14.48,700,1,12.49,200,2,14.56,800,2,12.46,100,1,14.6,700,1,12.43,700,1,14.61,100,1
2025-07-17T16:09:40.855558831Z,2025-07-17T16:09:40.855724422Z,160,2,1108,A,A,0,17.42,100,130,165591,278938788,ARL,335003849,13.11,100,1,13.7,15,1,13.01,2,1,13.71,100,1,12.98,200,2,13.9,2,1,12.86,100,1,14.01,100,1,12.73,100,1,14.28,100,1,12.71,100,1,14.46,100,1,12.5,700,1,14.48,700,1,12.49,200,2,14.56,800,2,12.46,100,1,14.6,700,1,12.43,700,1,14.61,100,1
2025-07-17T16:09:50.820783486Z,2025-07-17T16:09:50.820949131Z,160,2,1108,A,A,0,13.67,15,130,165645,279081140,ARL,335178437,13.11,100,1,13.67,15,1,13.01,2,1,13.7,15,1,12.98,200,2,13.71,100,1,12.86,100,1,13.9,2,1,12.73,100,1,14.01,100,1,12.71,100,1,14.28,100,1,12.5,700,1,14.46,100,1,12.49,200,2,14.48,700,1,12.46,100,1,14.56,800,2,12.43,700,1,14.6,700,1
2025-07-17T16:09:52.678611805Z,2025-07-17T16:09:52.678777358Z,160,2,1108,C,A,0,13.71,100,0,165553,279109959,ARL,335003813,13.11,100,1,13.67,15,1,13.01,2,1,13.7,15,1,12.98,200,2,13.9,2,1,12.86,100,1,14.01,100,1,12.73,100,1,14.28,100,1,12.71,100,1,14.46,100,1,12.5,700,1,14.48,700,1,12.49,200,2,14.56,800,2,12.46,100,1,14.6,700,1,12.43,700,1,14.61,100,1
2025-07-17T16:09:52.678611805Z,2025-07-17T16:09:52.678777358Z,160,2,1108,A,A,0,13.68,100,130,165553,279109959,ARL,335220349,13.11,100,1,13.67,15,1,13.01,2,1,13.68,100,1,12.98,200,2,13.7,15,1,12.86,100,1,13.9,2,1,12.73,100,1,14.01,100,1,12.71,100,1,14.28,100,1,12.5,700,1,14.46,100,1,12.49,200,2,14.48,700,1,12.46,100,1,14.56,800,2,12.43,700,1,14.6,700,1
2025-07-17T16:09:52.679678566Z,2025-07-17T16:09:52.679844338Z,160,2,1108,C,A,0,15.9,100,0,165772,279109991,ARL,334192405,13.11,100,1,13.67,15,1,13.01,2,1,13.68,100,1,12.98,200,2,13.7,15,1,12.86,100,1,13.9,2,1,12.73,100,1,14.01,100,1,12.71,100,1,14.28,100,1,12.5,700,1,14.46,100,1,12.49,200,2,14.48,700,1,12.46,100,1,14.56,800,2,12.43,700,1,14.6,700,1
2025-07-17T16:09:52.679678566Z,2025-07-17T16:09:52.679844338Z,160,2,1108,A,A,0,15.74,100,130,165772,279109991,ARL,335220497,13.11,100,1,13.67,15,1,13.01,2,1,13.68,100,1,12.98,200,2,13.7,15,1,12.86,100,1,13.9,2,1,12.73,100,1,14.01,100,1,12.71,100,1,14.28,100,1,12.5,700,1,14.46,100,1,12.49,200,2,14.48,700,1,12.46,100,1,14.56,800,2,12.43,700,1,14.6,700,1
2025-07-17T16:09:52.679769832Z,2025-07-17T16:09:52.679936826Z,160,2,1108,C,A,0,14.79,100,0,166994,279109996,ARL,334190353,13.11,100,1,13.67,15,1,13.01,2,1,13.68,100,1,12.98,200,2,13.7,15,1,12.86,100,1,13.9,2,1,12.73,100,1,14.01,100,1,12.71,100,1,14.28,100,1,12.5,700,1,14.46,100,1,12.49,200,2,14.48,700,1,12.46,100,1,14.56,800,2,12.43,700,1,14.6,700,1
2025-07-17T16:09:52.679769832Z,2025-07-17T16:09:52.679936826Z,160,2,1108,A,A,0,14.64,100,130,166994,279109996,ARL,335220525,13.11,100,1,13.67,15,1,13.01,2,1,13.68,100,1,12.98,200,2,13.7,15,1,12.86,100,1,13.9,2,1,12.73,100,1,14.01,100,1,12.71,100,1,14.28,100,1,12.5,700,1,14.46,100,1,12.49,200,2,14.48,700,1,12.46,100,1,14.56,800,2,12.43,700,1,14.6,700,1
2025-07-17T16:09:52.680672148Z,2025-07-17T16:09:52.680837736Z,160,2,1108,C,A,0,15.36,100,0,165588,279110032,ARL,333581441,13.11,100,1,13.67,15,1,13.01,2,1,13.68,100,1,12.98,200,2,13.7,15,1,12.86,100,1,13.9,2,1,12.73,100,1,14.01,100,1,12.71,100,1,14.28,100,1,12.5,700,1,14.46,100,1,12.49,200,2,14.48,700,1,12.46,100,1,14.56,800,2,12.43,700,1,14.6,700,1
2025-07-17T16:09:52.680672148Z,2025-07-17T16:09:52.680837736Z,160,2,1108,A,A,0,15.05,100,130,165588,279110032,ARL,335220549,13.11,100,1,13.67,15,1,13.01,2,1,13.68,100,1,12.98,200,2,13.7,15,1,12.86,100,1,13.9,2,1,12.73,100,1,14.01,100,1,12.71,100,1,14.28,100,1,12.5,700,1,14.46,100,1,12.49,200,2,14.48,700,1,12.46,100,1,14.56,800,2,12.43,700,1,14.6,700,1
2025-07-17T16:09:52.681844377Z,2025-07-17T16:09:52.682009938Z,160,2,1108,C,A,0,14.61,100,130,165561,279110066,ARL,334190189,13.11,100,1,13.67,15,1,13.01,2,1,13.68,100,1,12.98,200,2,13.7,15,1,12.86,100,1,13.9,2,1,12.73,100,1,14.01,100,1,12.71,100,1,14.28,100,1,12.5,700,1,14.46,100,1,12.49,200,2,14.48,700,1,12.46,100,1,14.56,800,2,12.43,700,1,14.6,700,1
2025-07-17T16:09:52.681961200Z,2025-07-17T16:09:52.682127530Z,160,2,1108,A,A,0,14.47,100,130,166330,279110068,ARL,335220561,13.11,100,1,13.67,15,1,13.01,2,1,13.68,100,1,12.98,200,2,13.7,15,1,12.86,100,1,13.9,2,1,12.73,100,1,14.01,100,1,12.71,100,1,14.28,100,1,12.5,700,1,14.46,100,1,12.49,200,2,14.47,100,1,12.46,100,1,14.48,700,1,12.43,700,1,14.56,800,2
2025-07-17T16:09:52.683757265Z,2025-07-17T16:09:52.683922707Z,160,2,1108,C,A,0,14.79,100,0,165442,279110090,ARL,334199009,13.11,100,1,13.67,15,1,13.01,2,1,13.68,100,1,12.98,200,2,13.7,15,1,12.86,100,1,13.9,2,1,12.73,100,1,14.01,100,1,12.71,100,1,14.28,100,1,12.5,700,1,14.46,100,1,12.49,200,2,14.47,100,1,12.46,100,1,14.48,700,1,12.43,700,1,14.56,800,2
2025-07-17T16:09:52.683757265Z,2025-07-17T16:09:52.683922707Z,160,2,1108,A,A,0,14.64,100,130,165442,279110090,ARL,335220629,13.11,100,1,13.67,15,1,13.01,2,1,13.68,100,1,12.98,200,2,13.7,15,1,12.86,100,1,13.9,2,1,12.73,100,1,14.01,100,1,12.71,100,1,14.28,100,1,12.5,700,1,14.46,100,1,12.49,200,2,14.47,100,1,12.46,100,1,14.48,700,1,12.43,700,1,14.56,800,2
2025-07-17T16:10:04.521306513Z,2025-07-17T16:10:04.521471804Z,160,2,1108,C,A,0,13.67,15,130,165291,279306715,ARL,335178437,13.11,100,1,13.68,100,1,13.01,2,1,13.7,15,1,12.98,200,2,13.9,2,1,12.86,100,1,14.01,100,1,12.73,100,1,14.28,100,1,12.71,100,1,14.46,100,1,12.5,700,1,14.47,100,1,12.49,200,2,14.48,700,1,12.46,100,1,14.56,800,2,12.43,700,1,14.6,700,1
2025-07-17T16:10:04.561688313Z,2025-07-17T16:10:04.561854856Z,160,2,1108,C,A,0,13.7,15,128,166543,279312083,ARL,335003269,13.11,100,1,13.68,100,1,13.01,2,1,13.9,2,1,12.98,200,2,14.01,100,1,12.86,100,1,14.28,100,1,12.73,100,1,14.46,100,1,12.71,100,1,14.47,100,1,12.5,700,1,14.48,700,1,12.49,200,2,14.56,800,2,12.46,100,1,14.6,700,1,12.43,700,1,14.62,200,2
2025-07-17T16:10:32.822495087Z,2025-07-17T16:10:32.822660498Z,160,2,1108,A,A,0,13.65,15,130,165411,279705339,ARL,335996705,13.11,100,1,13.65,15,1,13.01,2,1,13.68,100,1,12.98,200,2,13.9,2,1,12.86,100,1,14.01,100,1,12.73,100,1,14.28,100,1,12.71,100,1,14.46,100,1,12.5,700,1,14.47,100,1,12.49,200,2,14.48,700,1,12.46,100,1,14.56,800,2,12.43,700,1,14.6,700,1
2025-07-17T16:10:32.822757517Z,2025-07-17T16:10:32.822923138Z,160,2,1108,C,A,0,13.68,100,0,165621,279705347,ARL,335220349,13.11,100,1,13.65,15,1,13.01,2,1,13.9,2,1,12.98,200,2,14.01,100,1,12.86,100,1,14.28,100,1,12.73,100,1,14.46,100,1,12.71,100,1,14.47,100,1,12.5,700,1,14.48,700,1,12.49,200,2,14.56,800,2,12.46,100,1,14.6,700,1,12.43,700,1,14.62,200,2
2025-07-17T16:10:32.822757517Z,2025-07-17T16:10:32.822923138Z,160,2,1108,A,A,0,13.66,100,130,165621,279705347,ARL,335996709,13.11,100,1,13.65,15,1,13.01,2,1,13.66,100,1,12.98,200,2,13.9,2,1,12.86,100,1,14.01,100,1,12.73,100,1,14.28,100,1,12.71,100,1,14.46,100,1,12.5,700,1,14.47,100,1,12.49,200,2,14.48,700,1,12.46,100,1,14.56,800,2,12.43,700,1,14.6,700,1
2025-07-17T16:10:32.823491276Z,2025-07-17T16:10:32.823656903Z,160,2,1108,C,A,0,14.77,100,0,165627,279705362,ARL,335003845,13.11,100,1,13.65,15,1,13.01,2,1,13.66,100,1,12.98,200,2,13.9,2,1,12.86,100,1,14.01,100,1,12.73,100,1,14.28,100,1,12.71,100,1,14.46,100,1,12.5,700,1,14.47,100,1,12.49,200,2,14.48,700,1,12.46,100,1,14.56,800,2,12.43,700,1,14.6,700,1
2025-07-17T16:10:32.823491276Z,2025-07-17T16:10:32.823656903Z,160,2,1108,A,A,0,14.72,100,130,165627,279705362,ARL,335996725,13.11,100,1,13.65,15,1,13.01,2,1,13.66,100,1,12.98,200,2,13.9,2,1,12.86,100,1,14.01,100,1,12.73,100,1,14.28,100,1,12.71,100,1,14.46,100,1,12.5,700,1,14.47,100,1,12.49,200,2,14.48,700,1,12.46,100,1,14.56,800,2,12.43,700,1,14.6,700,1
2025-07-17T16:10:32.830032662Z,2025-07-17T16:10:32.830200844Z,160,2,1108,C,A,0,14.01,100,130,168182,279705485,ARL,334593753,13.11,100,1,13.65,15,1,13.01,2,1,13.66,100,1,12.98,200,2,13.9,2,1,12.86,100,1,14.28,100,1,12.73,100,1,14.46,100,1,12.71,100,1,14.47,100,1,12.5,700,1,14.48,700,1,12.49,200,2,14.56,800,2,12.46,100,1,14.6,700,1,12.43,700,1,14.62,200,2
2025-07-17T16:10:32.830085472Z,2025-07-17T16:10:32.830250720Z,160,2,1108,A,A,0,13.93,100,130,165248,279705486,ARL,335996777,13.11,100,1,13.65,15,1,13.01,2,1,13.66,100,1,12.98,200,2,13.9,2,1,12.86,100,1,13.93,100,1,12.73,100,1,14.28,100,1,12.71,100,1,14.46,100,1,12.5,700,1,14.47,100,1,12.49,200,2,14.48,700,1,12.46,100,1,14.56,800,2,12.43,700,1,14.6,700,1
2025-07-17T16:10:42.822189504Z,2025-07-17T16:10:42.822354869Z,160,2,1108,A,A,0,13.63,15,130,165365,279834760,ARL,336161333,13.11,100,1,13.63,15,1,13.01,2,1,13.65,15,1,12.98,200,2,13.66,100,1,12.86,100,1,13.9,2,1,12.73,100,1,13.93,100,1,12.71,100,1,14.28,100,1,12.5,700,1,14.46,100,1,12.49,200,2,14.47,100,1,12.46,100,1,14.48,700,1,12.43,700,1,14.56,800,2
2025-07-17T16:10:42.822258887Z,2025-07-17T16:10:42.822424663Z,160,2,1108,C,A,0,13.66,100,0,165776,279834761,ARL,335996709,13.11,100,1,13.63,15,1,13.01,2,1,13.65,15,1,12.98,200,2,13.9,2,1,12.86,100,1,13.93,100,1,12.73,100,1,14.28,100,1,12.71,100,1,14.46,100,1,12.5,700,1,14.47,100,1,12.49,200,2,14.48,700,1,12.46,100,1,14.56,800,2,12.43,700,1,14.6,700,1
2025-07-17T16:10:42.822258887Z,2025-07-17T16:10:42.822424663Z,160,2,1108,A,A,0,13.64,100,130,165776,279834761,ARL,336161337,13.11,100,1,13.63,15,1,13.01,2,1,13.64,100,1,12.98,200,2,13.65,15,1,12.86,100,1,13.9,2,1,12.73,100,1,13.93,100,1,12.71,100,1,14.28,100,1,12.5,700,1,14.46,100,1,12.49,200,2,14.47,100,1,12.46,100,1,14.48,700,1,12.43,700,1,14.56,800,2
2025-07-17T16:10:42.822998664Z,2025-07-17T16:10:42.823163929Z,160,2,1108,C,A,0,14.46,100,130,165265,279834765,ARL,331927161,13.11,100,1,13.63,15,1,13.01,2,1,13.64,100,1,12.98,200,2,13.65,15,1,12.86,100,1,13.9,2,1,12.73,100,1,13.93,100,1,12.71,100,1,14.28,100,1,12.5,700,1,14.47,100,1,12.49,200,2,14.48,700,1,12.46,100,1,14.56,800,2,12.43,700,1,14.6,700,1
2025-07-17T16:10:42.823352130Z,2025-07-17T16:10:42.823517444Z,160,2,1108,A,A,0,14.25,100,130,165314,279834767,ARL,336161365,13.11,100,1,13.63,15,1,13.01,2,1,13.64,100,1,12.98,200,2,13.65,15,1,12.86,100,1,13.9,2,1,12.73,100,1,13.93,100,1,12.71,100,1,14.25,100,1,12.5,700,1,14.28,100,1,12.49,200,2,14.47,100,1,12.46,100,1,14.48,700,1,12.43,700,1,14.56,800,2
2025-07-17T16:10:46.533890361Z,2025-07-17T16:10:46.534055942Z,160,2,1108,C,A,0,14.62,100,0,165581,279921726,ARL,334583349,13.11,100,1,13.63,15,1,13.01,2,1,13.64,100,1,12.98,200,2,13.65,15,1,12.86,100,1,13.9,2,1,12.73,100,1,13.93,100,1,12.71,100,1,14.25,100,1,12.5,700,1,14.28,100,1,12.49,200,2,14.47,100,1,12.46,100,1,14.48,700,1,12.43,700,1,14.56,800,2
2025-07-17T16:10:46.533890361Z,2025-07-17T16:10:46.534055942Z,160,2,1108,A,A,0,14.51,100,130,165581,279921726,ARL,336259225,13.11,100,1,13.63,15,1,13.01,2,1,13.64,100,1,12.98,200,2,13.65,15,1,12.86,100,1,13.9,2,1,12.73,100,1,13.93,100,1,12.71,100,1,14.25,100,1,12.5,700,1,14.28,100,1,12.49,200,2,14.47,100,1,12.46,100,1,14.48,700,1,12.43,700,1,14.51,100,1
2025-07-17T16:10:46.537992315Z,2025-07-17T16:10:46.538158874Z,160,2,1108,C,A,0,13.65,15,128,166559,279921911,ARL,335996705,13.11,100,1,13.63,15,1,13.01,2,1,13.64,100,1,12.98,200,2,13.9,2,1,12.86,100,1,13.93,100,1,12.73,100,1,14.25,100,1,12.71,100,1,14.28,100,1,12.5,700,1,14.47,100,1,12.49,200,2,14.48,700,1,12.46,100,1,14.51,100,1,12.43,700,1,14.56,800,2
2025-07-17T16:10:46.561080616Z,2025-07-17T16:10:46.561246030Z,160,2,1108,C,A,0,14.62,100,0,165414,279924883,ARL,334583361,13.11,100,1,13.63,15,1,13.01,2,1,13.64,100,1,12.98,200,2,13.9,2,1,12.86,100,1,13.93,100,1,12.73,100,1,14.25,100,1,12.71,100,1,14.28,100,1,12.5,700,1,14.47,100,1,12.49,200,2,14.48,700,1,12.46,100,1,14.51,100,1,12.43,700,1,14.56,800,2
2025-07-17T16:10:46.561080616Z,2025-07-17T16:10:46.561246030Z,160,2,1108,A,A,0,14.51,100,130,165414,279924883,ARL,336261905,13.11,100,1,13.63,15,1,13.01,2,1,13.64,100,1,12.98,200,2,13.9,2,1,12.86,100,1,13.93,100,1,12.73,100,1,14.25,100,1,12.71,100,1,14.28,100,1,12.5,700,1,14.47,100,1,12.49,200,2,14.48,700,1,12.46,100,1,14.51,200,2,12.43,700,1,14.56,800,2
2025-07-17T16:10:47.543238729Z,2025-07-17T16:10:47.543404001Z,160,2,1108,A,A,0,13.61,15,130,165272,279938097,ARL,336278197,13.11,100,1,13.61,15,1,13.01,2,1,13.63,15,1,12.98,200,2,13.64,100,1,12.86,100,1,13.9,2,1,12.73,100,1,13.93,100,1,12.71,100,1,14.25,100,1,12.5,700,1,14.28,100,1,12.49,200,2,14.47,100,1,12.46,100,1,14.48,700,1,12.43,700,1,14.51,200,2
2025-07-17T16:10:48.657290980Z,2025-07-17T16:10:48.657456395Z,160,2,1108,C,A,0,13.64,100,0,165415,279952266,ARL,336161337,13.11,100,1,13.61,15,1,13.01,2,1,13.63,15,1,12.98,200,2,13.9,2,1,12.86,100,1,13.93,100,1,12.73,100,1,14.25,100,1,12.71,100,1,14.28,100,1,12.5,700,1,14.47,100,1,12.49,200,2,14.48,700,1,12.46,100,1,14.51,200,2,12.43,700,1,14.56,800,2
2025-07-17T16:10:48.657290980Z,2025-07-17T16:10:48.657456395Z,160,2,1108,A,A,0,13.62,100,130,165415,279952266,ARL,336295769,13.11,100,1,13.61,15,1,13.01,2,1,13.62,100,1,12.98,200,2,13.63,15,1,12.86,100,1,13.9,2,1,12.73,100,1,13.93,100,1,12.71,100,1,14.25,100,1,12.5,700,1,14.28,100,1,12.49,200,2,14.47,100,1,12.46,100,1,14.48,700,1,12.43,700,1,14.51,200,2
2025-07-17T16:10:48.658033954Z,2025-07-17T16:10:48.658199425Z,160,2,1108,C,A,0,14.72,100,0,165471,279952282,ARL,335996725,13.11,100,1,13.61,15,1,13.01,2,1,13.62,100,1,12.98,200,2,13.63,15,1,12.86,100,1,13.9,2,1,12.73,100,1,13.93,100,1,12.71,100,1,14.25,100,1,12.5,700,1,14.28,100,1,12.49,200,2,14.47,100,1,12.46,100,1,14.48,700,1,12.43,700,1,14.51,200,2
2025-07-17T16:10:48.658033954Z,2025-07-17T16:10:48.658199425Z,160,2,1108,A,A,0,14.68,100,130,165471,279952282,ARL,336295845,13.11,100,1,13.61,15,1,13.01,2,1,13.62,100,1,12.98,200,2,13.63,15,1,12.86,100,1,13.9,2,1,12.73,100,1,13.93,100,1,12.71,100,1,14.25,100,1,12.5,700,1,14.28,100,1,12.49,200,2,14.47,100,1,12.46,100,1,14.48,700,1,12.43,700,1,14.51,200,2
2025-07-17T16:10:51.058878264Z,2025-07-17T16:10:51.059044292Z,160,2,1108,C,A,0,13.61,15,128,166028,280001840,ARL,336278197,13.11,100,1,13.62,100,1,13.01,2,1,13.63,15,1,12.98,200,2,13.9,2,1,12.86,100,1,13.93,100,1,12.73,100,1,14.25,100,1,12.71,100,1,14.28,100,1,12.5,700,1,14.47,100,1,12.49,200,2,14.48,700,1,12.46,100,1,14.51,200,2,12.43,700,1,14.56,800,2
2025-07-17T16:10:51.059016199Z,2025-07-17T16:10:51.059183923Z,160,2,1108,C,A,0,13.63,15,128,167724,280001873,ARL,336161333,13.11,100,1,13.62,100,1,13.01,2,1,13.9,2,1,12.98,200,2,13.93,100,1,12.86,100,1,14.25,100,1,12.73,100,1,14.28,100,1,12.71,100,1,14.47,100,1,12.5,700,1,14.48,700,1,12.49,200,2,14.51,200,2,12.46,100,1,14.56,800,2,12.43,700,1,14.6,700,1
2025-07-17T16:10:51.059443298Z,2025-07-17T16:10:51.059608753Z,160,2,1108,C,A,0,13.62,100,130,165455,280001952,ARL,336295769,13.11,100,1,13.9,2,1,13.01,2,1,13.93,100,1,12.98,200,2,14.25,100,1,12.86,100,1,14.28,100,1,12.73,100,1,14.47,100,1,12.71,100,1,14.48,700,1,12.5,700,1,14.51,200,2,12.49,200,2,14.56,800,2,12.46,100,1,14.6,700,1,12.43,700,1,14.64,200,2
2025-07-17T16:10:51.170545251Z,2025-07-17T16:10:51.170710609Z,160,2,1108,A,A,0,13.91,100,130,165358,280003702,ARL,336351081,13.11,100,1,13.9,2,1,13.01,2,1,13.91,100,1,12.98,200,2,13.93,100,1,12.86,100,1,14.25,100,1,12.73,100,1,14.28,100,1,12.71,100,1,14.47,100,1,12.5,700,1,14.48,700,1,12.49,200,2,14.51,200,2,12.46,100,1,14.56,800,2,12.43,700,1,14.6,700,1
2025-07-17T16:10:52.958288317Z,2025-07-17T16:10:52.958453641Z,160,2,1108,A,A,0,13.6,15,130,165324,280050139,ARL,336402845,13.11,100,1,13.6,15,1,13.01,2,1,13.9,2,1,12.98,200,2,13.91,100,1,12.86,100,1,13.93,100,1,12.73,100,1,14.25,100,1,12.71,100,1,14.28,100,1,12.5,700,1,14.47,100,1,12.49,200,2,14.48,700,1,12.46,100,1,14.51,200,2,12.43,700,1,14.56,800,2
2025-07-17T16:10:53.101871639Z,2025-07-17T16:10:53.102037173Z,160,2,1108,C,A,0,13.91,100,0,165534,280057228,ARL,336351081,13.11,100,1,13.6,15,1,13.01,2,1,13.9,2,1,12.98,200,2,13.93,100,1,12.86,100,1,14.25,100,1,12.73,100,1,14.28,100,1,12.71,100,1,14.47,100,1,12.5,700,1,14.48,700,1,12.49,200,2,14.51,200,2,12.46,100,1,14.56,800,2,12.43,700,1,14.6,700,1
2025-07-17T16:10:53.101871639Z,2025-07-17T16:10:53.102037173Z,160,2,1108,A,A,0,13.61,100,130,165534,280057228,ARL,336410125,13.11,100,1,13.6,15,1,13.01,2,1,13.61,100,1,12.98,200,2,13.9,2,1,12.86,100,1,13.93,100,1,12.73,100,1,14.25,100,1,12.71,100,1,14.28,100,1,12.5,700,1,14.47,100,1,12.49,200,2,14.48,700,1,12.46,100,1,14.51,200,2,12.43,700,1,14.56,800,2
2025-07-17T16:10:54.959141873Z,2025-07-17T16:10:54.959307592Z,160,2,1108,C,A,0,13.9,2,0,165719,280084546,ARL,334804177,13.11,100,1,13.6,15,1,13.01,2,1,13.61,100,1,12.98,200,2,13.93,100,1,12.86,100,1,14.25,100,1,12.73,100,1,14.28,100,1,12.71,100,1,14.47,100,1,12.5,700,1,14.48,700,1,12.49,200,2,14.51,200,2,12.46,100,1,14.56,800,2,12.43,700,1,14.6,700,1
2025-07-17T16:10:54.959141873Z,2025-07-17T16:10:54.959307592Z,160,2,1108,A,A,0,13.82,2,130,165719,280084546,ARL,336447325,13.11,100,1,13.6,15,1,13.01,2,1,13.61,100,1,12.98,200,2,13.82,2,1,12.86,100,1,13.93,100,1,12.73,100,1,14.25,100,1,12.71,100,1,14.28,100,1,12.5,700,1,14.47,100,1,12.49,200,2,14.48,700,1,12.46,100,1,14.51,200,2,12.43,700,1,14.56,800,2
2025-07-17T16:10:59.517870358Z,2025-07-17T16:10:59.518035805Z,160,2,1108,A,A,0,13.58,15,130,165447,280173685,ARL,336555153,13.11,100,1,13.58,15,1,13.01,2,1,13.6,15,1,12.98,200,2,13.61,100,1,12.86,100,1,13.82,2,1,12.73,100,1,13.93,100,1,12.71,100,1,14.25,100,1,12.5,700,1,14.28,100,1,12.49,200,2,14.47,100,1,12.46,100,1,14.48,700,1,12.43,700,1,14.51,200,2
2025-07-17T16:11:00.215719725Z,2025-07-17T16:11:00.215885294Z,160,2,1108,C,A,0,13.61,100,0,165569,280184406,ARL,336410125,13.11,100,1,13.58,15,1,13.01,2,1,13.6,15,1,12.98,200,2,13.82,2,1,12.86,100,1,13.93,100,1,12.73,100,1,14.25,100,1,12.71,100,1,14.28,100,1,12.5,700,1,14.47,100,1,12.49,200,2,14.48,700,1,12.46,100,1,14.51,200,2,12.43,700,1,14.56,800,2
2025-07-17T16:11:00.215719725Z,2025-07-17T16:11:00.215885294Z,160,2,1108,A,A,0,13.59,100,130,165569,280184406,ARL,336567189,13.11,100,1,13.58,15,1,13.01,2,1,13.59,100,1,12.98,200,2,13.6,15,1,12.86,100,1,13.82,2,1,12.73,100,1,13.93,100,1,12.71,100,1,14.25,100,1,12.5,700,1,14.28,100,1,12.49,200,2,14.47,100,1,12.46,100,1,14.48,700,1,12.43,700,1,14.51,200,2
2025-07-17T16:11:00.216456547Z,2025-07-17T16:11:00.216622121Z,160,2,1108,C,A,0,14.68,100,0,165574,280184418,ARL,336295845,13.11,100,1,13.58,15,1,13.01,2,1,13.59,100,1,12.98,200,2,13.6,15,1,12.86,100,1,13.82,2,1,12.73,100,1,13.93,100,1,12.71,100,1,14.25,100,1,12.5,700,1,14.28,100,1,12.49,200,2,14.47,100,1,12.46,100,1,14.48,700,1,12.43,700,1,14.51,200,2
2025-07-17T16:11:00.216456547Z,2025-07-17T16:11:00.216622121Z,160,2,1108,A,A,0,14.64,100,130,165574,280184418,ARL,336567213,13.11,100,1,13.58,15,1,13.01,2,1,13.59,100,1,12.98,200,2,13.6,15,1,12.86,100,1,13.82,2,1,12.73,100,1,13.93,100,1,12.71,100,1,14.25,100,1,12.5,700,1,14.28,100,1,12.49,200,2,14.47,100,1,12.46,100,1,14.48,700,1,12.43,700,1,14.51,200,2
2025-07-17T16:11:00.228833925Z,2025-07-17T16:11:00.228999377Z,160,2,1108,C,A,0,13.93,100,130,165452,280184613,ARL,335996777,13.11,100,1,13.58,15,1,13.01,2,1,13.59,100,1,12.98,200,2,13.6,15,1,12.86,100,1,13.82,2,1,12.73,100,1,14.25,100,1,12.71,100,1,14.28,100,1,12.5,700,1,14.47,100,1,12.49,200,2,14.48,700,1,12.46,100,1,14.51,200,2,12.43,700,1,14.56,800,2
2025-07-17T16:11:00.228885790Z,2025-07-17T16:11:00.229051124Z,160,2,1108,A,A,0,13.86,100,130,165334,280184614,ARL,336567333,13.11,100,1,13.58,15,1,13.01,2,1,13.59,100,1,12.98,200,2,13.6,15,1,12.86,100,1,13.82,2,1,12.73,100,1,13.86,100,1,12.71,100,1,14.25,100,1,12.5,700,1,14.28,100,1,12.49,200,2,14.47,100,1,12.46,100,1,14.48,700,1,12.43,700,1,14.51,200,2
2025-07-17T16:11:00.312921679Z,2025-07-17T16:11:00.313087129Z,160,2,1108,C,A,0,17.42,100,0,165450,280188038,ARL,335003849,13.11,100,1,13.58,15,1,13.01,2,1,13.59,100,1,12.98,200,2,13.6,15,1,12.86,100,1,13.82,2,1,12.73,100,1,13.86,100,1,12.71,100,1,14.25,100,1,12.5,700,1,14.28,100,1,12.49,200,2,14.47,100,1,12.46,100,1,14.48,700,1,12.43,700,1,14.51,200,2
2025-07-17T16:11:00.312921679Z,2025-07-17T16:11:00.313087129Z,160,2,1108,A,A,0,17.26,100,130,165450,280188038,ARL,336570921,13.11,100,1,13.58,15,1,13.01,2,1,13.59,100,1,12.98,200,2,13.6,15,1,12.86,100,1,13.82,2,1,12.73,100,1,13.86,100,1,12.71,100,1,14.25,100,1,12.5,700,1,14.28,100,1,12.49,200,2,14.47,100,1,12.46,100,1,14.48,700,1,12.43,700,1,14.51,200,2
2025-07-17T16:11:00.366645846Z,2025-07-17T16:11:00.366811541Z,160,2,1108,A,A,0,13.62,1,130,165695,280189435,ARL,336572049,13.11,100,1,13.58,15,1,13.01,2,1,13.59,100,1,12.98,200,2,13.6,15,1,12.86,100,1,13.62,1,1,12.73,100,1,13.82,2,1,12.71,100,1,13.86,100,1,12.5,700,1,14.25,100,1,12.49,200,2,14.28,100,1,12.46,100,1,14.47,100,1,12.43,700,1,14.48,700,1
2025-07-17T16:11:00.367209243Z,2025-07-17T16:11:00.367374773Z,160,2,1108,C,B,0,12.49,100,0,165530,280189439,ARL,331942945,13.11,100,1,13.58,15,1,13.01,2,1,13.59,100,1,12.98,200,2,13.6,15,1,12.86,100,1,13.62,1,1,12.73,100,1,13.82,2,1,12.71,100,1,13.86,100,1,12.5,700,1,14.25,100,1,12.49,100,1,14.28,100,1,12.46,100,1,14.47,100,1,12.43,700,1,14.48,700,1
2025-07-17T16:11:00.367209243Z,2025-07-17T16:11:00.367374773Z,160,2,1108,A,B,0,12.36,100,130,165530,280189439,ARL,336572057,13.11,100,1,13.58,15,1,13.01,2,1,13.59,100,1,12.98,200,2,13.6,15,1,12.86,100,1,13.62,1,1,12.73,100,1,13.82,2,1,12.71,100,1,13.86,100,1,12.5,700,1,14.25,100,1,12.49,100,1,14.28,100,1,12.46,100,1,14.47,100,1,12.43,700,1,14.48,700,1
2025-07-17T16:11:00.367319059Z,2025-07-17T16:11:00.367485094Z,160,2,1108,C,B,0,12.49,100,0,166035,280189441,ARL,331942901,13.11,100,1,13.58,15,1,13.01,2,1,13.59,100,1,12.98,200,2,13.6,15,1,12.86,100,1,13.62,1,1,12.73,100,1,13.82,2,1,12.71,100,1,13.86,100,1,12.5,700,1,14.25,100,1,12.46,100,1,14.28,100,1,12.43,700,1,14.47,100,1,12.42,700,1,14.48,700,1
2025-07-17T16:11:00.367319059Z,2025-07-17T16:11:00.367485094Z,160,2,1108,A,B,0,12.36,100,130,166035,280189441,ARL,336572069,13.11,100,1,13.58,15,1,13.01,2,1,13.59,100,1,12.98,200,2,13.6,15,1,12.86,100,1,13.62,1,1,12.73,100,1,13.82,2,1,12.71,100,1,13.86,100,1,12.5,700,1,14.25,100,1,12.46,100,1,14.28,100,1,12.43,700,1,14.47,100,1,12.42,700,1,14.48,700,1
2025-07-17T16:11:00.466703632Z,2025-07-17T16:11:00.466868624Z,160,2,1108,C,A,0,13.62,1,130,164992,280191783,ARL,336572049,13.11,100,1,13.58,15,1,13.01,2,1,13.59,100,1,12.98,200,2,13.6,15,1,12.86,100,1,13.82,2,1,12.73,100,1,13.86,100,1,12.71,100,1,14.25,100,1,12.5,700,1,14.28,100,1,12.46,100,1,14.47,100,1,12.43,700,1,14.48,700,1,12.42,700,1,14.51,200,2
2025-07-17T16:11:06.626666474Z,2025-07-17T16:11:06.626831799Z,160,2,1108,A,A,0,14.27,700,130,165325,280342316,ARL,336747457,13.11,100,1,13.58,15,1,13.01,2,1,13.59,100,1,12.98,200,2,13.6,15,1,12.86,100,1,13.82,2,1,12.73,100,1,13.86,100,1,12.71,100,1,14.25,100,1,12.5,700,1,14.27,700,1,12.46,100,1,14.28,100,1,12.43,700,1,14.47,100,1,12.42,700,1,14.48,700,1
2025-07-17T16:11:06.626741446Z,2025-07-17T16:11:06.626906700Z,160,2,1108,C,A,0,14.68,700,130,165254,280342318,ARL,331929977,13.11,100,1,13.58,15,1,13.01,2,1,13.59,100,1,12.98,200,2,13.6,15,1,12.86,100,1,13.82,2,1,12.73,100,1,13.86,100,1,12.71,100,1,14.25,100,1,12.5,700,1,14.27,700,1,12.46,100,1,14.28,100,1,12.43,700,1,14.47,100,1,12.42,700,1,14.48,700,1
2025-07-17T16:11:08.307868957Z,2025-07-17T16:11:08.308034538Z,160,2,1108,C,A,0,13.6,15,130,165581,280374785,ARL,336402845,13.11,100,1,13.58,15,1,13.01,2,1,13.59,100,1,12.98,200,2,13.82,2,1,12.86,100,1,13.86,100,1,12.73,100,1,14.25,100,1,12.71,100,1,14.27,700,1,12.5,700,1,14.28,100,1,12.46,100,1,14.47,100,1,12.43,700,1,14.48,700,1,12.42,700,1,14.51,200,2
2025-07-17T16:11:09.568370995Z,2025-07-17T16:11:09.568536292Z,160,2,1108,A,A,0,13.56,15,130,165297,280401189,ARL,336816813,13.11,100,1,13.56,15,1,13.01,2,1,13.58,15,1,12.98,200,2,13.59,100,1,12.86,100,1,13.82,2,1,12.73,100,1,13.86,100,1,12.71,100,1,14.25,100,1,12.5,700,1,14.27,700,1,12.46,100,1,14.28,100,1,12.43,700,1,14.47,100,1,12.42,700,1,14.48,700,1
2025-07-17T16:11:10.341788521Z,2025-07-17T16:11:10.341953971Z,160,2,1108,C,A,0,13.59,100,0,165450,280411396,ARL,336567189,13.11,100,1,13.56,15,1,13.01,2,1,13.58,15,1,12.98,200,2,13.82,2,1,12.86,100,1,13.86,100,1,12.73,100,1,14.25,100,1,12.71,100,1,14.27,700,1,12.5,700,1,14.28,100,1,12.46,100,1,14.47,100,1,12.43,700,1,14.48,700,1,12.42,700,1,14.51,200,2
2025-07-17T16:11:10.341788521Z,2025-07-17T16:11:10.341953971Z,160,2,1108,A,A,0,13.57,100,130,165450,280411396,ARL,336828765,13.11,100,1,13.56,15,1,13.01,2,1,13.57,100,1,12.98,200,2,13.58,15,1,12.86,100,1,13.82,2,1,12.73,100,1,13.86,100,1,12.71,100,1,14.25,100,1,12.5,700,1,14.27,700,1,12.46,100,1,14.28,100,1,12.43,700,1,14.47,100,1,12.42,700,1,14.48,700,1
2025-07-17T16:11:14.610535763Z,2025-07-17T16:11:14.610701450Z,160,2,1108,C,A,0,13.58,15,130,165687,280482371,ARL,336555153,13.11,100,1,13.56,15,1,13.01,2,1,13.57,100,1,12.98,200,2,13.82,2,1,12.86,100,1,13.86,100,1,12.73,100,1,14.25,100,1,12.71,100,1,14.27,700,1,12.5,700,1,14.28,100,1,12.46,100,1,14.47,100,1,12.43,700,1,14.48,700,1,12.42,700,1,14.51,200,2
2025-07-17T16:11:16.025292936Z,2025-07-17T16:11:16.025458231Z,160,2,1108,C,A,0,13.56,15,130,165295,280514282,ARL,336816813,13.11,100,1,13.57,100,1,13.01,2,1,13.82,2,1,12.98,200,2,13.86,100,1,12.86,100,1,14.25,100,1,12.73,100,1,14.27,700,1,12.71,100,1,14.28,100,1,12.5,700,1,14.47,100,1,12.46,100,1,14.48,700,1,12.43,700,1,14.51,200,2,12.42,700,1,14.56,800,2
2025-07-17T16:11:50.026672014Z,2025-07-17T16:11:50.026837358Z,160,2,1108,A,A,0,13.55,15,130,165344,281078802,ARL,337690189,13.11,100,1,13.55,15,1,13.01,2,1,13.57,100,1,12.98,200,2,13.82,2,1,12.86,100,1,13.86,100,1,12.73,100,1,14.25,100,1,12.71,100,1,14.27,700,1,12.5,700,1,14.28,100,1,12.46,100,1,14.47,100,1,12.43,700,1,14.48,700,1,12.42,700,1,14.51,200,2
2025-07-17T16:11:50.026839463Z,2025-07-17T16:11:50.027004977Z,160,2,1108,C,A,0,13.57,100,0,165514,281078803,ARL,336828765,13.11,100,1,13.55,15,1,13.01,2,1,13.82,2,1,12.98,200,2,13.86,100,1,12.86,100,1,14.25,100,1,12.73,100,1,14.27,700,1,12.71,100,1,14.28,100,1,12.5,700,1,14.47,100,1,12.46,100,1,14.48,700,1,12.43,700,1,14.51,200,2,12.42,700,1,14.56,800,2
2025-07-17T16:11:50.026839463Z,2025-07-17T16:11:50.027004977Z,160,2,1108,A,A,0,13.56,100,130,165514,281078803,ARL,337690193,13.11,100,1,13.55,15,1,13.01,2,1,13.56,100,1,12.98,200,2,13.82,2,1,12.86,100,1,13.86,100,1,12.73,100,1,14.25,100,1,12.71,100,1,14.27,700,1,12.5,700,1,14.28,100,1,12.46,100,1,14.47,100,1,12.43,700,1,14.48,700,1,12.42,700,1,14.51,200,2
2025-07-17T16:11:50.032845393Z,2025-07-17T16:11:50.033010798Z,160,2,1108,C,A,0,15.74,100,0,165405,281078903,ARL,335220497,13.11,100,1,13.55,15,1,13.01,2,1,13.56,100,1,12.98,200,2,13.82,2,1,12.86,100,1,13.86,100,1,12.73,100,1,14.25,100,1,12.71,100,1,14.27,700,1,12.5,700,1,14.28,100,1,12.46,100,1,14.47,100,1,12.43,700,1,14.48,700,1,12.42,700,1,14.51,200,2
2025-07-17T16:11:50.032845393Z,2025-07-17T16:11:50.033010798Z,160,2,1108,A,A,0,15.6,100,130,165405,281078903,ARL,337690641,13.11,100,1,13.55,15,1,13.01,2,1,13.56,100,1,12.98,200,2,13.82,2,1,12.86,100,1,13.86,100,1,12.73,100,1,14.25,100,1,12.71,100,1,14.27,700,1,12.5,700,1,14.28,100,1,12.46,100,1,14.47,100,1,12.43,700,1,14.48,700,1,12.42,700,1,14.51,200,2
2025-07-17T16:11:53.859743991Z,2025-07-17T16:11:53.859909462Z,160,2,1108,A,A,0,13.53,15,130,165471,281142794,ARL,337772837,13.11,100,1,13.53,15,1,13.01,2,1,13.55,15,1,12.98,200,2,13.56,100,1,12.86,100,1,13.82,2,1,12.73,100,1,13.86,100,1,12.71,100,1,14.25,100,1,12.5,700,1,14.27,700,1,12.46,100,1,14.28,100,1,12.43,700,1,14.47,100,1,12.42,700,1,14.48,700,1
2025-07-17T16:11:54.662361841Z,2025-07-17T16:11:54.662527332Z,160,2,1108,C,A,0,13.56,100,0,165491,281156215,ARL,337690193,13.11,100,1,13.53,15,1,13.01,2,1,13.55,15,1,12.98,200,2,13.82,2,1,12.86,100,1,13.86,100,1,12.73,100,1,14.25,100,1,12.71,100,1,14.27,700,1,12.5,700,1,14.28,100,1,12.46,100,1,14.47,100,1,12.43,700,1,14.48,700,1,12.42,700,1,14.51,200,2
2025-07-17T16:11:54.662361841Z,2025-07-17T16:11:54.662527332Z,160,2,1108,A,A,0,13.54,100,130,165491,281156215,ARL,337790717,13.11,100,1,13.53,15,1,13.01,2,1,13.54,100,1,12.98,200,2,13.55,15,1,12.86,100,1,13.82,2,1,12.73,100,1,13.86,100,1,12.71,100,1,14.25,100,1,12.5,700,1,14.27,700,1,12.46,100,1,14.28,100,1,12.43,700,1,14.47,100,1,12.42,700,1,14.48,700,1
2025-07-17T16:11:54.663112543Z,2025-07-17T16:11:54.663278200Z,160,2,1108,C,A,0,14.64,100,0,165657,281156222,ARL,336567213,13.11,100,1,13.53,15,1,13.01,2,1,13.54,100,1,12.98,200,2,13.55,15,1,12.86,100,1,13.82,2,1,12.73,100,1,13.86,100,1,12.71,100,1,14.25,100,1,12.5,700,1,14.27,700,1,12.46,100,1,14.28,100,1,12.43,700,1,14.47,100,1,12.42,700,1,14.48,700,1
2025-07-17T16:11:54.663112543Z,2025-07-17T16:11:54.663278200Z,160,2,1108,A,A,0,14.59,100,130,165657,281156222,ARL,337790737,13.11,100,1,13.53,15,1,13.01,2,1,13.54,100,1,12.98,200,2,13.55,15,1,12.86,100,1,13.82,2,1,12.73,100,1,13.86,100,1,12.71,100,1,14.25,100,1,12.5,700,1,14.27,700,1,12.46,100,1,14.28,100,1,12.43,700,1,14.47,100,1,12.42,700,1,14.48,700,1
2025-07-17T16:11:54.663968656Z,2025-07-17T16:11:54.664134026Z,160,2,1108,C,A,0,14.64,100,0,165370,281156223,ARL,335220525,13.11,100,1,13.53,15,1,13.01,2,1,13.54,100,1,12.98,200,2,13.55,15,1,12.86,100,1,13.82,2,1,12.73,100,1,13.86,100,1,12.71,100,1,14.25,100,1,12.5,700,1,14.27,700,1,12.46,100,1,14.28,100,1,12.43,700,1,14.47,100,1,12.42,700,1,14.48,700,1
2025-07-17T16:11:54.663968656Z,2025-07-17T16:11:54.664134026Z,160,2,1108,A,A,0,14.49,100,130,165370,281156223,ARL,337790745,13.11,100,1,13.53,15,1,13.01,2,1,13.54,100,1,12.98,200,2,13.55,15,1,12.86,100,1,13.82,2,1,12.73,100,1,13.86,100,1,12.71,100,1,14.25,100,1,12.5,700,1,14.27,700,1,12.46,100,1,14.28,100,1,12.43,700,1,14.47,100,1,12.42,700,1,14.48,700,1
2025-07-17T16:11:54.666160990Z,2025-07-17T16:11:54.666326600Z,160,2,1108,C,A,0,14.47,100,0,165610,281156243,ARL,335220561,13.11,100,1,13.53,15,1,13.01,2,1,13.54,100,1,12.98,200,2,13.55,15,1,12.86,100,1,13.82,2,1,12.73,100,1,13.86,100,1,12.71,100,1,14.25,100,1,12.5,700,1,14.27,700,1,12.46,100,1,14.28,100,1,12.43,700,1,14.48,700,1,12.42,700,1,14.49,100,1
2025-07-17T16:11:54.666160990Z,2025-07-17T16:11:54.666326600Z,160,2,1108,A,A,0,14.33,100,130,165610,281156243,ARL,337790761,13.11,100,1,13.53,15,1,13.01,2,1,13.54,100,1,12.98,200,2,13.55,15,1,12.86,100,1,13.82,2,1,12.73,100,1,13.86,100,1,12.71,100,1,14.25,100,1,12.5,700,1,14.27,700,1,12.46,100,1,14.28,100,1,12.43,700,1,14.33,100,1,12.42,700,1,14.48,700,1
2025-07-17T16:11:54.667339002Z,2025-07-17T16:11:54.667504546Z,160,2,1108,C,A,0,14.64,100,0,165544,281156250,ARL,335220629,13.11,100,1,13.53,15,1,13.01,2,1,13.54,100,1,12.98,200,2,13.55,15,1,12.86,100,1,13.82,2,1,12.73,100,1,13.86,100,1,12.71,100,1,14.25,100,1,12.5,700,1,14.27,700,1,12.46,100,1,14.28,100,1,12.43,700,1,14.33,100,1,12.42,700,1,14.48,700,1
2025-07-17T16:11:54.667339002Z,2025-07-17T16:11:54.667504546Z,160,2,1108,A,A,0,14.49,100,130,165544,281156250,ARL,337790777,13.11,100,1,13.53,15,1,13.01,2,1,13.54,100,1,12.98,200,2,13.55,15,1,12.86,100,1,13.82,2,1,12.73,100,1,13.86,100,1,12.71,100,1,14.25,100,1,12.5,700,1,14.27,700,1,12.46,100,1,14.28,100,1,12.43,700,1,14.33,100,1,12.42,700,1,14.48,700,1
2025-07-17T16:11:59.382350338Z,2025-07-17T16:11:59.382515678Z,160,2,1108,C,A,0,13.55,15,130,165340,281270010,ARL,337690189,13.11,100,1,13.53,15,1,13.01,2,1,13.54,100,1,12.98,200,2,13.82,2,1,12.86,100,1,13.86,100,1,12.73,100,1,14.25,100,1,12.71,100,1,14.27,700,1,12.5,700,1,14.28,100,1,12.46,100,1,14.33,100,1,12.43,700,1,14.48,700,1,12.42,700,1,14.49,200,2
2025-07-17T16:12:02.981913204Z,2025-07-17T16:12:02.982078719Z,160,2,1108,A,A,0,13.51,15,130,165515,281348152,ARL,338041605,13.11,100,1,13.51,15,1,13.01,2,1,13.53,15,1,12.98,200,2,13.54,100,1,12.86,100,1,13.82,2,1,12.73,100,1,13.86,100,1,12.71,100,1,14.25,100,1,12.5,700,1,14.27,700,1,12.46,100,1,14.28,100,1,12.43,700,1,14.33,100,1,12.42,700,1,14.48,700,1
2025-07-17T16:12:03.063997054Z,2025-07-17T16:12:03.064162605Z,160,2,1108,C,A,0,13.54,100,0,165551,281351122,ARL,337790717,13.11,100,1,13.51,15,1,13.01,2,1,13.53,15,1,12.98,200,2,13.82,2,1,12.86,100,1,13.86,100,1,12.73,100,1,14.25,100,1,12.71,100,1,14.27,700,1,12.5,700,1,14.28,100,1,12.46,100,1,14.33,100,1,12.43,700,1,14.48,700,1,12.42,700,1,14.49,200,2
2025-07-17T16:12:03.063997054Z,2025-07-17T16:12:03.064162605Z,160,2,1108,A,A,0,13.52,100,130,165551,281351122,ARL,338044041,13.11,100,1,13.51,15,1,13.01,2,1,13.52,100,1,12.98,200,2,13.53,15,1,12.86,100,1,13.82,2,1,12.73,100,1,13.86,100,1,12.71,100,1,14.25,100,1,12.5,700,1,14.27,700,1,12.46,100,1,14.28,100,1,12.43,700,1,14.33,100,1,12.42,700,1,14.48,700,1
2025-07-17T16:12:03.068301745Z,2025-07-17T16:12:03.068467146Z,160,2,1108,C,B,0,13.01,2,0,165401,281351235,ARL,332494213,13.11,100,1,13.51,15,1,12.98,200,2,13.52,100,1,12.86,100,1,13.53,15,1,12.73,100,1,13.82,2,1,12.71,100,1,13.86,100,1,12.5,700,1,14.25,100,1,12.46,100,1,14.27,700,1,12.43,700,1,14.28,100,1,12.42,700,1,14.33,100,1,12.37,700,1,14.48,700,1
2025-07-17T16:12:03.068301745Z,2025-07-17T16:12:03.068467146Z,160,2,1108,A,B,0,12.92,2,130,165401,281351235,ARL,338044113,13.11,100,1,13.51,15,1,12.98,200,2,13.52,100,1,12.92,2,1,13.53,15,1,12.86,100,1,13.82,2,1,12.73,100,1,13.86,100,1,12.71,100,1,14.25,100,1,12.5,700,1,14.27,700,1,12.46,100,1,14.28,100,1,12.43,700,1,14.33,100,1,12.42,700,1,14.48,700,1
2025-07-17T16:12:03.075034550Z,2025-07-17T16:12:03.075200038Z,160,2,1108,C,A,0,13.86,100,130,165488,281351372,ARL,336567333,13.11,100,1,13.51,15,1,12.98,200,2,13.52,100,1,12.92,2,1,13.53,15,1,12.86,100,1,13.82,2,1,12.73,100,1,14.25,100,1,12.71,100,1,14.27,700,1,12.5,700,1,14.28,100,1,12.46,100,1,14.33,100,1,12.43,700,1,14.48,700,1,12.42,700,1,14.49,200,2
2025-07-17T16:12:03.075095341Z,2025-07-17T16:12:03.075260529Z,160,2,1108,A,A,0,13.79,100,130,165188,281351373,ARL,338044233,13.11,100,1,13.51,15,1,12.98,200,2,13.52,100,1,12.92,2,1,13.53,15,1,12.86,100,1,13.79,100,1,12.73,100,1,13.82,2,1,12.71,100,1,14.25,100,1,12.5,700,1,14.27,700,1,12.46,100,1,14.28,100,1,12.43,700,1,14.33,100,1,12.42,700,1,14.48,700,1
2025-07-17T16:12:06.775011783Z,2025-07-17T16:12:06.775177637Z,160,2,1108,C,A,0,14.51,100,0,165854,281422697,ARL,336259225,13.11,100,1,13.51,15,1,12.98,200,2,13.52,100,1,12.92,2,1,13.53,15,1,12.86,100,1,13.79,100,1,12.73,100,1,13.82,2,1,12.71,100,1,14.25,100,1,12.5,700,1,14.27,700,1,12.46,100,1,14.28,100,1,12.43,700,1,14.33,100,1,12.42,700,1,14.48,700,1
2025-07-17T16:12:06.775011783Z,2025-07-17T16:12:06.775177637Z,160,2,1108,A,A,0,14.4,100,130,165854,281422697,ARL,338139585,13.11,100,1,13.51,15,1,12.98,200,2,13.52,100,1,12.92,2,1,13.53,15,1,12.86,100,1,13.79,100,1,12.73,100,1,13.82,2,1,12.71,100,1,14.25,100,1,12.5,700,1,14.27,700,1,12.46,100,1,14.28,100,1,12.43,700,1,14.33,100,1,12.42,700,1,14.4,100,1
2025-07-17T16:12:06.775449017Z,2025-07-17T16:12:06.775614536Z,160,2,1108,C,A,0,14.51,100,0,165519,281422702,ARL,336261905,13.11,100,1,13.51,15,1,12.98,200,2,13.52,100,1,12.92,2,1,13.53,15,1,12.86,100,1,13.79,100,1,12.73,100,1,13.82,2,1,12.71,100,1,14.25,100,1,12.5,700,1,14.27,700,1,12.46,100,1,14.28,100,1,12.43,700,1,14.33,100,1,12.42,700,1,14.4,100,1
2025-07-17T16:12:06.775449017Z,2025-07-17T16:12:06.775614536Z,160,2,1108,A,A,0,14.4,100,130,165519,281422702,ARL,338139601,13.11,100,1,13.51,15,1,12.98,200,2,13.52,100,1,12.92,2,1,13.53,15,1,12.86,100,1,13.79,100,1,12.73,100,1,13.82,2,1,12.71,100,1,14.25,100,1,12.5,700,1,14.27,700,1,12.46,100,1,14.28,100,1,12.43,700,1,14.33,100,1,12.42,700,1,14.4,200,2
2025-07-17T16:12:06.779540143Z,2025-07-17T16:12:06.779705717Z,160,2,1108,C,A,0,13.53,15,130,165574,281422782,ARL,337772837,13.11,100,1,13.51,15,1,12.98,200,2,13.52,100,1,12.92,2,1,13.79,100,1,12.86,100,1,13.82,2,1,12.73,100,1,14.25,100,1,12.71,100,1,14.27,700,1,12.5,700,1,14.28,100,1,12.46,100,1,14.33,100,1,12.43,700,1,14.4,200,2,12.42,700,1,14.48,700,1
2025-07-17T16:12:07.784533539Z,2025-07-17T16:12:07.784698893Z,160,2,1108,A,A,0,13.49,15,130,165354,281443568,ARL,338167057,13.11,100,1,13.49,15,1,12.98,200,2,13.51,15,1,12.92,2,1,13.52,100,1,12.86,100,1,13.79,100,1,12.73,100,1,13.82,2,1,12.71,100,1,14.25,100,1,12.5,700,1,14.27,700,1,12.46,100,1,14.28,100,1,12.43,700,1,14.33,100,1,12.42,700,1,14.4,200,2
2025-07-17T16:12:08.585029039Z,2025-07-17T16:12:08.585194585Z,160,2,1108,C,A,0,13.52,100,0,165546,281451898,ARL,338044041,13.11,100,1,13.49,15,1,12.98,200,2,13.51,15,1,12.92,2,1,13.79,100,1,12.86,100,1,13.82,2,1,12.73,100,1,14.25,100,1,12.71,100,1,14.27,700,1,12.5,700,1,14.28,100,1,12.46,100,1,14.33,100,1,12.43,700,1,14.4,200,2,12.42,700,1,14.48,700,1
2025-07-17T16:12:08.585029039Z,2025-07-17T16:12:08.585194585Z,160,2,1108,A,A,0,13.5,100,130,165546,281451898,ARL,338180793,13.11,100,1,13.49,15,1,12.98,200,2,13.5,100,1,12.92,2,1,13.51,15,1,12.86,100,1,13.79,100,1,12.73,100,1,13.82,2,1,12.71,100,1,14.25,100,1,12.5,700,1,14.27,700,1,12.46,100,1,14.28,100,1,12.43,700,1,14.33,100,1,12.42,700,1,14.4,200,2
2025-07-17T16:12:08.585776508Z,2025-07-17T16:12:08.585942049Z,160,2,1108,C,A,0,14.59,100,0,165541,281451903,ARL,337790737,13.11,100,1,13.49,15,1,12.98,200,2,13.5,100,1,12.92,2,1,13.51,15,1,12.86,100,1,13.79,100,1,12.73,100,1,13.82,2,1,12.71,100,1,14.25,100,1,12.5,700,1,14.27,700,1,12.46,100,1,14.28,100,1,12.43,700,1,14.33,100,1,12.42,700,1,14.4,200,2
2025-07-17T16:12:08.585776508Z,2025-07-17T16:12:08.585942049Z,160,2,1108,A,A,0,14.55,100,130,165541,281451903,ARL,338180841,13.11,100,1,13.49,15,1,12.98,200,2,13.5,100,1,12.92,2,1,13.51,15,1,12.86,100,1,13.79,100,1,12.73,100,1,13.82,2,1,12.71,100,1,14.25,100,1,12.5,700,1,14.27,700,1,12.46,100,1,14.28,100,1,12.43,700,1,14.33,100,1,12.42,700,1,14.4,200,2
2025-07-17T16:12:18.789756367Z,2025-07-17T16:12:18.789922022Z,160,2,1108,C,A,0,13.82,2,0,165655,281613266,ARL,336447325,13.11,100,1,13.49,15,1,12.98,200,2,13.5,100,1,12.92,2,1,13.51,15,1,12.86,100,1,13.79,100,1,12.73,100,1,14.25,100,1,12.71,100,1,14.27,700,1,12.5,700,1,14.28,100,1,12.46,100,1,14.33,100,1,12.43,700,1,14.4,200,2,12.42,700,1,14.48,700,1
2025-07-17T16:12:18.789756367Z,2025-07-17T16:12:18.789922022Z,160,2,1108,A,A,0,13.74,2,130,165655,281613266,ARL,338371797,13.11,100,1,13.49,15,1,12.98,200,2,13.5,100,1,12.92,2,1,13.51,15,1,12.86,100,1,13.74,2,1,12.73,100,1,13.79,100,1,12.71,100,1,14.25,100,1,12.5,700,1,14.27,700,1,12.46,100,1,14.28,100,1,12.43,700,1,14.33,100,1,12.42,700,1,14.4,200,2
2025-07-17T16:12:19.370820933Z,2025-07-17T16:12:19.370986404Z,160,2,1108,A,A,0,14.27,700,130,165471,281622545,ARL,338382329,13.11,100,1,13.49,15,1,12.98,200,2,13.5,100,1,12.92,2,1,13.51,15,1,12.86,100,1,13.74,2,1,12.73,100,1,13.79,100,1,12.71,100,1,14.25,100,1,12.5,700,1,14.27,1400,2,12.46,100,1,14.28,100,1,12.43,700,1,14.33,100,1,12.42,700,1,14.4,200,2
2025-07-17T16:12:19.370875240Z,2025-07-17T16:12:19.371041049Z,160,2,1108,C,A,0,14.6,700,130,165809,281622547,ARL,282920685,13.11,100,1,13.49,15,1,12.98,200,2,13.5,100,1,12.92,2,1,13.51,15,1,12.86,100,1,13.74,2,1,12.73,100,1,13.79,100,1,12.71,100,1,14.25,100,1,12.5,700,1,14.27,1400,2,12.46,100,1,14.28,100,1,12.43,700,1,14.33,100,1,12.42,700,1,14.4,200,2
2025-07-17T16:12:19.696521343Z,2025-07-17T16:12:19.696689718Z,160,2,1108,C,A,0,13.49,15,128,168375,281630053,ARL,338167057,13.11,100,1,13.5,100,1,12.98,200,2,13.51,15,1,12.92,2,1,13.74,2,1,12.86,100,1,13.79,100,1,12.73,100,1,14.25,100,1,12.71,100,1,14.27,1400,2,12.5,700,1,14.28,100,1,12.46,100,1,14.33,100,1,12.43,700,1,14.4,200,2,12.42,700,1,14.48,700,1
2025-07-17T16:12:19.711591494Z,2025-07-17T16:12:19.711773364Z,160,2,1108,C,A,0,13.51,15,128,181870,281634812,ARL,338041605,13.11,100,1,13.5,100,1,12.98,200,2,13.74,2,1,12.92,2,1,13.79,100,1,12.86,100,1,14.25,100,1,12.73,100,1,14.27,1400,2,12.71,100,1,14.28,100,1,12.5,700,1,14.33,100,1,12.46,100,1,14.4,200,2,12.43,700,1,14.48,700,1,12.42,700,1,14.49,200,2
2025-07-17T16:12:32.761112078Z,2025-07-17T16:12:32.761277424Z,160,2,1108,A,A,0,13.48,15,130,165346,281880398,ARL,338707945,13.11,100,1,13.48,15,1,12.98,200,2,13.5,100,1,12.92,2,1,13.74,2,1,12.86,100,1,13.79,100,1,12.73,100,1,14.25,100,1,12.71,100,1,14.27,1400,2,12.5,700,1,14.28,100,1,12.46,100,1,14.33,100,1,12.43,700,1,14.4,200,2,12.42,700,1,14.48,700,1
2025-07-17T16:12:32.761246859Z,2025-07-17T16:12:32.761413202Z,160,2,1108,C,A,0,13.5,100,0,166343,281880409,ARL,338180793,13.11,100,1,13.48,15,1,12.98,200,2,13.74,2,1,12.92,2,1,13.79,100,1,12.86,100,1,14.25,100,1,12.73,100,1,14.27,1400,2,12.71,100,1,14.28,100,1,12.5,700,1,14.33,100,1,12.46,100,1,14.4,200,2,12.43,700,1,14.48,700,1,12.42,700,1,14.49,200,2
2025-07-17T16:12:32.761246859Z,2025-07-17T16:12:32.761413202Z,160,2,1108,A,A,0,13.49,100,130,166343,281880409,ARL,338707949,13.11,100,1,13.48,15,1,12.98,200,2,13.49,100,1,12.92,2,1,13.74,2,1,12.86,100,1,13.79,100,1,12.73,100,1,14.25,100,1,12.71,100,1,14.27,1400,2,12.5,700,1,14.28,100,1,12.46,100,1,14.33,100,1,12.43,700,1,14.4,200,2,12.42,700,1,14.48,700,1
2025-07-17T16:12:32.778890447Z,2025-07-17T16:12:32.779055996Z,160,2,1108,C,A,0,15.12,100,0,165549,281880579,ARL,296387089,13.11,100,1,13.48,15,1,12.98,200,2,13.49,100,1,12.92,2,1,13.74,2,1,12.86,100,1,13.79,100,1,12.73,100,1,14.25,100,1,12.71,100,1,14.27,1400,2,12.5,700,1,14.28,100,1,12.46,100,1,14.33,100,1,12.43,700,1,14.4,200,2,12.42,700,1,14.48,700,1
2025-07-17T16:12:32.778890447Z,2025-07-17T16:12:32.779055996Z,160,2,1108,A,A,0,14.84,100,130,165549,281880579,ARL,338708241,13.11,100,1,13.48,15,1,12.98,200,2,13.49,100,1,12.92,2,1,13.74,2,1,12.86,100,1,13.79,100,1,12.73,100,1,14.25,100,1,12.71,100,1,14.27,1400,2,12.5,700,1,14.28,100,1,12.46,100,1,14.33,100,1,12.43,700,1,14.4,200,2,12.42,700,1,14.48,700,1
2025-07-17T16:12:32.804152457Z,2025-07-17T16:12:32.804318005Z,160,2,1108,A,A,0,15.38,100,130,165548,281880972,ARL,338709513,13.11,100,1,13.48,15,1,12.98,200,2,13.49,100,1,12.92,2,1,13.74,2,1,12.86,100,1,13.79,100,1,12.73,100,1,14.25,100,1,12.71,100,1,14.27,1400,2,12.5,700,1,14.28,100,1,12.46,100,1,14.33,100,1,12.43,700,1,14.4,200,2,12.42,700,1,14.48,700,1
2025-07-17T16:12:32.804166092Z,2025-07-17T16:12:32.804332586Z,160,2,1108,C,A,0,15.66,100,130,166494,281880973,ARL,326730513,13.11,100,1,13.48,15,1,12.98,200,2,13.49,100,1,12.92,2,1,13.74,2,1,12.86,100,1,13.79,100,1,12.73,100,1,14.25,100,1,12.71,100,1,14.27,1400,2,12.5,700,1,14.28,100,1,12.46,100,1,14.33,100,1,12.43,700,1,14.4,200,2,12.42,700,1,14.48,700,1
2025-07-17T16:12:40.992898990Z,2025-07-17T16:12:40.993064296Z,160,2,1108,C,A,0,13.49,100,130,165306,282007871,ARL,338707949,13.11,100,1,13.48,15,1,12.98,200,2,13.74,2,1,12.92,2,1,13.79,100,1,12.86,100,1,14.25,100,1,12.73,100,1,14.27,1400,2,12.71,100,1,14.28,100,1,12.5,700,1,14.33,100,1,12.46,100,1,14.4,200,2,12.43,700,1,14.48,700,1,12.42,700,1,14.49,200,2
2025-07-17T16:12:40.993167418Z,2025-07-17T16:12:40.993332664Z,160,2,1108,C,A,0,14.27,700,130,165246,282007875,ARL,338382329,13.11,100,1,13.48,15,1,12.98,200,2,13.74,2,1,12.92,2,1,13.79,100,1,12.86,100,1,14.25,100,1,12.73,100,1,14.27,700,1,12.71,100,1,14.28,100,1,12.5,700,1,14.33,100,1,12.46,100,1,14.4,200,2,12.43,700,1,14.48,700,1,12.42,700,1,14.49,200,2
2025-07-17T16:12:40.993168470Z,2025-07-17T16:12:40.993333790Z,160,2,1108,C,A,0,14.27,700,130,165320,282007876,ARL,336747457,13.11,100,1,13.48,15,1,12.98,200,2,13.74,2,1,12.92,2,1,13.79,100,1,12.86,100,1,14.25,100,1,12.73,100,1,14.28,100,1,12.71,100,1,14.33,100,1,12.5,700,1,14.4,200,2,12.46,100,1,14.48,700,1,12.43,700,1,14.49,200,2,12.42,700,1,14.55,100,1
2025-07-17T16:12:40.993214193Z,2025-07-17T16:12:40.993379626Z,160,2,1108,A,A,0,14.54,700,130,165433,282007877,ARL,338864169,13.11,100,1,13.48,15,1,12.98,200,2,13.74,2,1,12.92,2,1,13.79,100,1,12.86,100,1,14.25,100,1,12.73,100,1,14.28,100,1,12.71,100,1,14.33,100,1,12.5,700,1,14.4,200,2,12.46,100,1,14.48,700,1,12.43,700,1,14.49,200,2,12.42,700,1,14.54,700,1
2025-07-17T16:12:40.993227993Z,2025-07-17T16:12:40.993393440Z,160,2,1108,A,A,0,14.47,700,130,165447,282007878,ARL,338864173,13.11,100,1,13.48,15,1,12.98,200,2,13.74,2,1,12.92,2,1,13.79,100,1,12.86,100,1,14.25,100,1,12.73,100,1,14.28,100,1,12.71,100,1,14.33,100,1,12.5,700,1,14.4,200,2,12.46,100,1,14.47,700,1,12.43,700,1,14.48,700,1,12.42,700,1,14.49,200,2
2025-07-17T16:12:40.993266591Z,2025-07-17T16:12:40.993432115Z,160,2,1108,A,A,0,15.71,100,130,165524,282007879,ARL,338864177,13.11,100,1,13.48,15,1,12.98,200,2,13.74,2,1,12.92,2,1,13.79,100,1,12.86,100,1,14.25,100,1,12.73,100,1,14.28,100,1,12.71,100,1,14.33,100,1,12.5,700,1,14.4,200,2,12.46,100,1,14.47,700,1,12.43,700,1,14.48,700,1,12.42,700,1,14.49,200,2
2025-07-17T16:12:40.993279810Z,2025-07-17T16:12:40.993445042Z,160,2,1108,C,A,0,15.38,100,130,165232,282007880,ARL,338709513,13.11,100,1,13.48,15,1,12.98,200,2,13.74,2,1,12.92,2,1,13.79,100,1,12.86,100,1,14.25,100,1,12.73,100,1,14.28,100,1,12.71,100,1,14.33,100,1,12.5,700,1,14.4,200,2,12.46,100,1,14.47,700,1,12.43,700,1,14.48,700,1,12.42,700,1,14.49,200,2
2025-07-17T16:12:40.993652511Z,2025-07-17T16:12:40.993818130Z,160,2,1108,C,A,0,14.55,100,0,165619,282007882,ARL,338180841,13.11,100,1,13.48,15,1,12.98,200,2,13.74,2,1,12.92,2,1,13.79,100,1,12.86,100,1,14.25,100,1,12.73,100,1,14.28,100,1,12.71,100,1,14.33,100,1,12.5,700,1,14.4,200,2,12.46,100,1,14.47,700,1,12.43,700,1,14.48,700,1,12.42,700,1,14.49,200,2
2025-07-17T16:12:40.993652511Z,2025-07-17T16:12:40.993818130Z,160,2,1108,A,A,0,14.85,100,130,165619,282007882,ARL,338864189,13.11,100,1,13.48,15,1,12.98,200,2,13.74,2,1,12.92,2,1,13.79,100,1,12.86,100,1,14.25,100,1,12.73,100,1,14.28,100,1,12.71,100,1,14.33,100,1,12.5,700,1,14.4,200,2,12.46,100,1,14.47,700,1,12.43,700,1,14.48,700,1,12.42,700,1,14.49,200,2
2025-07-17T16:12:40.994617858Z,2025-07-17T16:12:40.994783297Z,160,2,1108,C,A,0,14.49,100,0,165439,282007892,ARL,337790745,13.11,100,1,13.48,15,1,12.98,200,2,13.74,2,1,12.92,2,1,13.79,100,1,12.86,100,1,14.25,100,1,12.73,100,1,14.28,100,1,12.71,100,1,14.33,100,1,12.5,700,1,14.4,200,2,12.46,100,1,14.47,700,1,12.43,700,1,14.48,700,1,12.42,700,1,14.49,100,1
2025-07-17T16:12:40.994617858Z,2025-07-17T16:12:40.994783297Z,160,2,1108,A,A,0,14.76,100,130,165439,282007892,ARL,338864217,13.11,100,1,13.48,15,1,12.98,200,2,13.74,2,1,12.92,2,1,13.79,100,1,12.86,100,1,14.25,100,1,12.73,100,1,14.28,100,1,12.71,100,1,14.33,100,1,12.5,700,1,14.4,200,2,12.46,100,1,14.47,700,1,12.43,700,1,14.48,700,1,12.42,700,1,14.49,100,1
2025-07-17T16:12:40.994913404Z,2025-07-17T16:12:40.995078856Z,160,2,1108,C,A,0,14.84,100,0,165452,282007894,ARL,338708241,13.11,100,1,13.48,15,1,12.98,200,2,13.74,2,1,12.92,2,1,13.79,100,1,12.86,100,1,14.25,100,1,12.73,100,1,14.28,100,1,12.71,100,1,14.33,100,1,12.5,700,1,14.4,200,2,12.46,100,1,14.47,700,1,12.43,700,1,14.48,700,1,12.42,700,1,14.49,100,1
2025-07-17T16:12:40.994913404Z,2025-07-17T16:12:40.995078856Z,160,2,1108,A,A,0,15.17,100,130,165452,282007894,ARL,338864221,13.11,100,1,13.48,15,1,12.98,200,2,13.74,2,1,12.92,2,1,13.79,100,1,12.86,100,1,14.25,100,1,12.73,100,1,14.28,100,1,12.71,100,1,14.33,100,1,12.5,700,1,14.4,200,2,12.46,100,1,14.47,700,1,12.43,700,1,14.48,700,1,12.42,700,1,14.49,100,1
2025-07-17T16:12:40.995183768Z,2025-07-17T16:12:40.995349303Z,160,2,1108,C,A,0,15.6,100,0,165535,282007898,ARL,337690641,13.11,100,1,13.48,15,1,12.98,200,2,13.74,2,1,12.92,2,1,13.79,100,1,12.86,100,1,14.25,100,1,12.73,100,1,14.28,100,1,12.71,100,1,14.33,100,1,12.5,700,1,14.4,200,2,12.46,100,1,14.47,700,1,12.43,700,1,14.48,700,1,12.42,700,1,14.49,100,1
2025-07-17T16:12:40.995183768Z,2025-07-17T16:12:40.995349303Z,160,2,1108,A,A,0,15.86,100,130,165535,282007898,ARL,338864245,13.11,100,1,13.48,15,1,12.98,200,2,13.74,2,1,12.92,2,1,13.79,100,1,12.86,100,1,14.25,100,1,12.73,100,1,14.28,100,1,12.71,100,1,14.33,100,1,12.5,700,1,14.4,200,2,12.46,100,1,14.47,700,1,12.43,700,1,14.48,700,1,12.42,700,1,14.49,100,1
2025-07-17T16:12:40.996294601Z,2025-07-17T16:12:40.996460080Z,160,2,1108,C,A,0,17.26,100,0,165479,282007909,ARL,336570921,13.11,100,1,13.48,15,1,12.98,200,2,13.74,2,1,12.92,2,1,13.79,100,1,12.86,100,1,14.25,100,1,12.73,100,1,14.28,100,1,12.71,100,1,14.33,100,1,12.5,700,1,14.4,200,2,12.46,100,1,14.47,700,1,12.43,700,1,14.48,700,1,12.42,700,1,14.49,100,1
2025-07-17T16:12:40.996294601Z,2025-07-17T16:12:40.996460080Z,160,2,1108,A,A,0,17.52,100,130,165479,282007909,ARL,338864289,13.11,100,1,13.48,15,1,12.98,200,2,13.74,2,1,12.92,2,1,13.79,100,1,12.86,100,1,14.25,100,1,12.73,100,1,14.28,100,1,12.71,100,1,14.33,100,1,12.5,700,1,14.4,200,2,12.46,100,1,14.47,700,1,12.43,700,1,14.48,700,1,12.42,700,1,14.49,100,1
