ts_event,ts_recv,r_type,publisher,instrument_id,action,side,depth,price,size,flags,ts_in_delta,sequence,symbol,order_id,bid_px_00,bid_sz_00,bid_ct_00,ask_px_00,ask_sz_00,ask_ct_00,bid_px_01,bid_sz_01,bid_ct_01,ask_px_01,ask_sz_01,ask_ct_01,bid_px_02,bid_sz_02,bid_ct_02,ask_px_02,ask_sz_02,ask_ct_02,bid_px_03,bid_sz_03,bid_ct_03,ask_px_03,ask_sz_03,ask_ct_03,bid_px_04,bid_sz_04,bid_ct_04,ask_px_04,ask_sz_04,ask_ct_04,bid_px_05,bid_sz_05,bid_ct_05,ask_px_05,ask_sz_05,ask_ct_05,bid_px_06,bid_sz_06,bid_ct_06,ask_px_06,ask_sz_06,ask_ct_06,bid_px_07,bid_sz_07,bid_ct_07,ask_px_07,ask_sz_07,ask_ct_07,bid_px_08,bid_sz_08,bid_ct_08,ask_px_08,ask_sz_08,ask_ct_08,bid_px_09,bid_sz_09,bid_ct_09,ask_px_09,ask_sz_09,ask_ct_09
2025-07-17T15:45:07.080706110Z,2025-07-17T15:45:07.080872245Z,160,2,1108,A,A,0,15.06,100,130,166135,254245511,ARL,303330485,13.26,100,1,14.03,100,1,13.04,2,1,14.07,2,1,13.03,100,1,14.28,100,1,12.73,100,1,14.4,100,1,12.71,100,1,14.56,800,2,12.5,700,1,14.6,700,1,12.46,200,2,14.64,100,1,12.43,700,1,14.66,100,1,12.42,700,1,14.68,1400,2,12.37,700,1,14.81,200,2
2025-07-17T15:45:07.081407507Z,2025-07-17T15:45:07.081578064Z,160,2,1108,C,A,0,14.81,100,0,170557,254245568,ARL,301747001,13.26,100,1,14.03,100,1,13.04,2,1,14.07,2,1,13.03,100,1,14.28,100,1,12.73,100,1,14.4,100,1,12.71,100,1,14.56,800,2,12.5,700,1,14.6,700,1,12.46,200,2,14.64,100,1,12.43,700,1,14.66,100,1,12.42,700,1,14.68,1400,2,12.37,700,1,14.81,100,1
2025-07-17T15:45:07.081407507Z,2025-07-17T15:45:07.081578064Z,160,2,1108,A,A,0,14.96,100,128,170557,254245568,ARL,303330509,13.26,100,1,14.03,100,1,13.04,2,1,14.07,2,1,13.03,100,1,14.28,100,1,12.73,100,1,14.4,100,1,12.71,100,1,14.56,800,2,12.5,700,1,14.6,700,1,12.46,200,2,14.64,100,1,12.43,700,1,14.66,100,1,12.42,700,1,14.68,1400,2,12.37,700,1,14.81,100,1
2025-07-17T15:45:07.081441134Z,2025-07-17T15:45:07.081607970Z,160,2,1108,C,A,0,14.66,100,0,166836,254245576,ARL,302205309,13.26,100,1,14.03,100,1,13.04,2,1,14.07,2,1,13.03,100,1,14.28,100,1,12.73,100,1,14.4,100,1,12.71,100,1,14.56,800,2,12.5,700,1,14.6,700,1,12.46,200,2,14.64,100,1,12.43,700,1,14.68,1400,2,12.42,700,1,14.81,100,1,12.37,700,1,14.89,100,1
2025-07-17T15:45:07.081441134Z,2025-07-17T15:45:07.081607970Z,160,2,1108,A,A,0,14.89,100,130,166836,254245576,ARL,303330521,13.26,100,1,14.03,100,1,13.04,2,1,14.07,2,1,13.03,100,1,14.28,100,1,12.73,100,1,14.4,100,1,12.71,100,1,14.56,800,2,12.5,700,1,14.6,700,1,12.46,200,2,14.64,100,1,12.43,700,1,14.68,1400,2,12.42,700,1,14.81,100,1,12.37,700,1,14.89,200,2
2025-07-17T15:45:07.083732443Z,2025-07-17T15:45:07.083898999Z,160,2,1108,C,A,0,17.42,100,0,166556,254246327,ARL,302764137,13.26,100,1,14.03,100,1,13.04,2,1,14.07,2,1,13.03,100,1,14.28,100,1,12.73,100,1,14.4,100,1,12.71,100,1,14.56,800,2,12.5,700,1,14.6,700,1,12.46,200,2,14.64,100,1,12.43,700,1,14.68,1400,2,12.42,700,1,14.81,100,1,12.37,700,1,14.89,200,2
2025-07-17T15:45:07.083732443Z,2025-07-17T15:45:07.083898999Z,160,2,1108,A,A,0,17.76,100,130,166556,254246327,ARL,303331309,13.26,100,1,14.03,100,1,13.04,2,1,14.07,2,1,13.03,100,1,14.28,100,1,12.73,100,1,14.4,100,1,12.71,100,1,14.56,800,2,12.5,700,1,14.6,700,1,12.46,200,2,14.64,100,1,12.43,700,1,14.68,1400,2,12.42,700,1,14.81,100,1,12.37,700,1,14.89,200,2
2025-07-17T15:45:07.085057258Z,2025-07-17T15:45:07.085222525Z,160,2,1108,C,A,0,14.03,100,130,165267,254246434,ARL,302466157,13.26,100,1,14.07,2,1,13.04,2,1,14.28,100,1,13.03,100,1,14.4,100,1,12.73,100,1,14.56,800,2,12.71,100,1,14.6,700,1,12.5,700,1,14.64,100,1,12.46,200,2,14.68,1400,2,12.43,700,1,14.81,100,1,12.42,700,1,14.89,200,2,12.37,700,1,14.96,100,1
2025-07-17T15:45:07.085109545Z,2025-07-17T15:45:07.085274852Z,160,2,1108,A,A,0,14.26,100,130,165307,254246437,ARL,303331401,13.26,100,1,14.07,2,1,13.04,2,1,14.26,100,1,13.03,100,1,14.28,100,1,12.73,100,1,14.4,100,1,12.71,100,1,14.56,800,2,12.5,700,1,14.6,700,1,12.46,200,2,14.64,100,1,12.43,700,1,14.68,1400,2,12.42,700,1,14.81,100,1,12.37,700,1,14.89,200,2
2025-07-17T15:45:07.086368957Z,2025-07-17T15:45:07.086534700Z,160,2,1108,C,A,0,14.64,100,130,165743,254246501,ARL,301747005,13.26,100,1,14.07,2,1,13.04,2,1,14.26,100,1,13.03,100,1,14.28,100,1,12.73,100,1,14.4,100,1,12.71,100,1,14.56,800,2,12.5,700,1,14.6,700,1,12.46,200,2,14.68,1400,2,12.43,700,1,14.81,100,1,12.42,700,1,14.89,200,2,12.37,700,1,14.96,100,1
2025-07-17T15:45:07.086494745Z,2025-07-17T15:45:07.086660325Z,160,2,1108,A,A,0,14.78,100,130,165580,254246502,ARL,303331425,13.26,100,1,14.07,2,1,13.04,2,1,14.26,100,1,13.03,100,1,14.28,100,1,12.73,100,1,14.4,100,1,12.71,100,1,14.56,800,2,12.5,700,1,14.6,700,1,12.46,200,2,14.68,1400,2,12.43,700,1,14.78,100,1,12.42,700,1,14.81,100,1,12.37,700,1,14.89,200,2
2025-07-17T15:45:07.087223859Z,2025-07-17T15:45:07.087389466Z,160,2,1108,C,A,0,15.77,100,0,165607,254246529,ARL,302764121,13.26,100,1,14.07,2,1,13.04,2,1,14.26,100,1,13.03,100,1,14.28,100,1,12.73,100,1,14.4,100,1,12.71,100,1,14.56,800,2,12.5,700,1,14.6,700,1,12.46,200,2,14.68,1400,2,12.43,700,1,14.78,100,1,12.42,700,1,14.81,100,1,12.37,700,1,14.89,200,2
2025-07-17T15:45:07.087223859Z,2025-07-17T15:45:07.087389466Z,160,2,1108,A,A,0,16.08,100,130,165607,254246529,ARL,303331429,13.26,100,1,14.07,2,1,13.04,2,1,14.26,100,1,13.03,100,1,14.28,100,1,12.73,100,1,14.4,100,1,12.71,100,1,14.56,800,2,12.5,700,1,14.6,700,1,12.46,200,2,14.68,1400,2,12.43,700,1,14.78,100,1,12.42,700,1,14.81,100,1,12.37,700,1,14.89,200,2
2025-07-17T15:45:07.133812895Z,2025-07-17T15:45:07.133978488Z,160,2,1108,C,A,0,14.81,100,0,165593,254250625,ARL,301747957,13.26,100,1,14.07,2,1,13.04,2,1,14.26,100,1,13.03,100,1,14.28,100,1,12.73,100,1,14.4,100,1,12.71,100,1,14.56,800,2,12.5,700,1,14.6,700,1,12.46,200,2,14.68,1400,2,12.43,700,1,14.78,100,1,12.42,700,1,14.89,200,2,12.37,700,1,14.96,100,1
2025-07-17T15:45:07.133812895Z,2025-07-17T15:45:07.133978488Z,160,2,1108,A,A,0,14.96,100,130,165593,254250625,ARL,303334253,13.26,100,1,14.07,2,1,13.04,2,1,14.26,100,1,13.03,100,1,14.28,100,1,12.73,100,1,14.4,100,1,12.71,100,1,14.56,800,2,12.5,700,1,14.6,700,1,12.46,200,2,14.68,1400,2,12.43,700,1,14.78,100,1,12.42,700,1,14.89,200,2,12.37,700,1,14.96,200,2
2025-07-17T15:45:07.469796155Z,2025-07-17T15:45:07.469961302Z,160,2,1108,A,A,0,14.08,100,130,165147,254258029,ARL,303340405,13.26,100,1,14.07,2,1,13.04,2,1,14.08,100,1,13.03,100,1,14.26,100,1,12.73,100,1,14.28,100,1,12.71,100,1,14.4,100,1,12.5,700,1,14.56,800,2,12.46,200,2,14.6,700,1,12.43,700,1,14.68,1400,2,12.42,700,1,14.78,100,1,12.37,700,1,14.89,200,2
2025-07-17T15:45:08.094603115Z,2025-07-17T15:45:08.094768552Z,160,2,1108,C,A,0,14.89,100,0,165437,254266885,ARL,303330521,13.26,100,1,14.07,2,1,13.04,2,1,14.08,100,1,13.03,100,1,14.26,100,1,12.73,100,1,14.28,100,1,12.71,100,1,14.4,100,1,12.5,700,1,14.56,800,2,12.46,200,2,14.6,700,1,12.43,700,1,14.68,1400,2,12.42,700,1,14.78,100,1,12.37,700,1,14.89,100,1
2025-07-17T15:45:08.094603115Z,2025-07-17T15:45:08.094768552Z,160,2,1108,A,A,0,15.1,100,130,165437,254266885,ARL,303349309,13.26,100,1,14.07,2,1,13.04,2,1,14.08,100,1,13.03,100,1,14.26,100,1,12.73,100,1,14.28,100,1,12.71,100,1,14.4,100,1,12.5,700,1,14.56,800,2,12.46,200,2,14.6,700,1,12.43,700,1,14.68,1400,2,12.42,700,1,14.78,100,1,12.37,700,1,14.89,100,1
2025-07-17T15:45:08.103141155Z,2025-07-17T15:45:08.103306644Z,160,2,1108,C,A,0,14.89,100,0,165489,254266971,ARL,303330477,13.26,100,1,14.07,2,1,13.04,2,1,14.08,100,1,13.03,100,1,14.26,100,1,12.73,100,1,14.28,100,1,12.71,100,1,14.4,100,1,12.5,700,1,14.56,800,2,12.46,200,2,14.6,700,1,12.43,700,1,14.68,1400,2,12.42,700,1,14.78,100,1,12.37,700,1,14.96,200,2
2025-07-17T15:45:08.103141155Z,2025-07-17T15:45:08.103306644Z,160,2,1108,A,A,0,15.1,100,130,165489,254266971,ARL,303349377,13.26,100,1,14.07,2,1,13.04,2,1,14.08,100,1,13.03,100,1,14.26,100,1,12.73,100,1,14.28,100,1,12.71,100,1,14.4,100,1,12.5,700,1,14.56,800,2,12.46,200,2,14.6,700,1,12.43,700,1,14.68,1400,2,12.42,700,1,14.78,100,1,12.37,700,1,14.96,200,2
2025-07-17T15:45:24.186842413Z,2025-07-17T15:45:24.187008278Z,160,2,1108,C,A,0,15.1,100,0,165865,254547413,ARL,303349309,13.26,100,1,14.07,2,1,13.04,2,1,14.08,100,1,13.03,100,1,14.26,100,1,12.73,100,1,14.28,100,1,12.71,100,1,14.4,100,1,12.5,700,1,14.56,800,2,12.46,200,2,14.6,700,1,12.43,700,1,14.68,1400,2,12.42,700,1,14.78,100,1,12.37,700,1,14.96,200,2
2025-07-17T15:45:24.186842413Z,2025-07-17T15:45:24.187008278Z,160,2,1108,A,A,0,14.88,100,130,165865,254547413,ARL,303682385,13.26,100,1,14.07,2,1,13.04,2,1,14.08,100,1,13.03,100,1,14.26,100,1,12.73,100,1,14.28,100,1,12.71,100,1,14.4,100,1,12.5,700,1,14.56,800,2,12.46,200,2,14.6,700,1,12.43,700,1,14.68,1400,2,12.42,700,1,14.78,100,1,12.37,700,1,14.88,100,1
2025-07-17T15:45:24.187276389Z,2025-07-17T15:45:24.187441892Z,160,2,1108,C,A,0,15.1,100,0,165503,254547415,ARL,303349377,13.26,100,1,14.07,2,1,13.04,2,1,14.08,100,1,13.03,100,1,14.26,100,1,12.73,100,1,14.28,100,1,12.71,100,1,14.4,100,1,12.5,700,1,14.56,800,2,12.46,200,2,14.6,700,1,12.43,700,1,14.68,1400,2,12.42,700,1,14.78,100,1,12.37,700,1,14.88,100,1
2025-07-17T15:45:24.187276389Z,2025-07-17T15:45:24.187441892Z,160,2,1108,A,A,0,14.88,100,130,165503,254547415,ARL,303682389,13.26,100,1,14.07,2,1,13.04,2,1,14.08,100,1,13.03,100,1,14.26,100,1,12.73,100,1,14.28,100,1,12.71,100,1,14.4,100,1,12.5,700,1,14.56,800,2,12.46,200,2,14.6,700,1,12.43,700,1,14.68,1400,2,12.42,700,1,14.78,100,1,12.37,700,1,14.88,200,2
2025-07-17T15:45:37.509289536Z,2025-07-17T15:45:37.509454888Z,160,2,1108,A,A,0,13.94,15,130,165352,254851462,ARL,304056997,13.26,100,1,13.94,15,1,13.04,2,1,14.07,2,1,13.03,100,1,14.08,100,1,12.73,100,1,14.26,100,1,12.71,100,1,14.28,100,1,12.5,700,1,14.4,100,1,12.46,200,2,14.56,800,2,12.43,700,1,14.6,700,1,12.42,700,1,14.68,1400,2,12.37,700,1,14.78,100,1
2025-07-17T15:45:37.997967775Z,2025-07-17T15:45:37.998133497Z,160,2,1108,C,A,0,14.08,100,0,165722,254864588,ARL,303340405,13.26,100,1,13.94,15,1,13.04,2,1,14.07,2,1,13.03,100,1,14.26,100,1,12.73,100,1,14.28,100,1,12.71,100,1,14.4,100,1,12.5,700,1,14.56,800,2,12.46,200,2,14.6,700,1,12.43,700,1,14.68,1400,2,12.42,700,1,14.78,100,1,12.37,700,1,14.88,200,2
2025-07-17T15:45:37.997967775Z,2025-07-17T15:45:37.998133497Z,160,2,1108,A,A,0,13.95,100,130,165722,254864588,ARL,304072245,13.26,100,1,13.94,15,1,13.04,2,1,13.95,100,1,13.03,100,1,14.07,2,1,12.73,100,1,14.26,100,1,12.71,100,1,14.28,100,1,12.5,700,1,14.4,100,1,12.46,200,2,14.56,800,2,12.43,700,1,14.6,700,1,12.42,700,1,14.68,1400,2,12.37,700,1,14.78,100,1
2025-07-17T15:45:44.700428155Z,2025-07-17T15:45:44.700593408Z,160,2,1108,A,A,0,13.89,15,130,165253,254999429,ARL,304238913,13.26,100,1,13.89,15,1,13.04,2,1,13.94,15,1,13.03,100,1,13.95,100,1,12.73,100,1,14.07,2,1,12.71,100,1,14.26,100,1,12.5,700,1,14.28,100,1,12.46,200,2,14.4,100,1,12.43,700,1,14.56,800,2,12.42,700,1,14.6,700,1,12.37,700,1,14.68,1400,2
2025-07-17T15:45:45.262371701Z,2025-07-17T15:45:45.262537122Z,160,2,1108,C,A,0,13.95,100,0,165421,255010979,ARL,304072245,13.26,100,1,13.89,15,1,13.04,2,1,13.94,15,1,13.03,100,1,14.07,2,1,12.73,100,1,14.26,100,1,12.71,100,1,14.28,100,1,12.5,700,1,14.4,100,1,12.46,200,2,14.56,800,2,12.43,700,1,14.6,700,1,12.42,700,1,14.68,1400,2,12.37,700,1,14.78,100,1
2025-07-17T15:45:45.262371701Z,2025-07-17T15:45:45.262537122Z,160,2,1108,A,A,0,13.9,100,130,165421,255010979,ARL,304252313,13.26,100,1,13.89,15,1,13.04,2,1,13.9,100,1,13.03,100,1,13.94,15,1,12.73,100,1,14.07,2,1,12.71,100,1,14.26,100,1,12.5,700,1,14.28,100,1,12.46,200,2,14.4,100,1,12.43,700,1,14.56,800,2,12.42,700,1,14.6,700,1,12.37,700,1,14.68,1400,2
2025-07-17T15:45:45.263123432Z,2025-07-17T15:45:45.263289023Z,160,2,1108,C,A,0,15.06,100,0,165591,255010987,ARL,303330485,13.26,100,1,13.89,15,1,13.04,2,1,13.9,100,1,13.03,100,1,13.94,15,1,12.73,100,1,14.07,2,1,12.71,100,1,14.26,100,1,12.5,700,1,14.28,100,1,12.46,200,2,14.4,100,1,12.43,700,1,14.56,800,2,12.42,700,1,14.6,700,1,12.37,700,1,14.68,1400,2
2025-07-17T15:45:45.263123432Z,2025-07-17T15:45:45.263289023Z,160,2,1108,A,A,0,14.98,100,130,165591,255010987,ARL,304252333,13.26,100,1,13.89,15,1,13.04,2,1,13.9,100,1,13.03,100,1,13.94,15,1,12.73,100,1,14.07,2,1,12.71,100,1,14.26,100,1,12.5,700,1,14.28,100,1,12.46,200,2,14.4,100,1,12.43,700,1,14.56,800,2,12.42,700,1,14.6,700,1,12.37,700,1,14.68,1400,2
2025-07-17T15:45:45.274194870Z,2025-07-17T15:45:45.274360382Z,160,2,1108,C,A,0,14.26,100,130,165512,255011158,ARL,303331401,13.26,100,1,13.89,15,1,13.04,2,1,13.9,100,1,13.03,100,1,13.94,15,1,12.73,100,1,14.07,2,1,12.71,100,1,14.28,100,1,12.5,700,1,14.4,100,1,12.46,200,2,14.56,800,2,12.43,700,1,14.6,700,1,12.42,700,1,14.68,1400,2,12.37,700,1,14.78,100,1
2025-07-17T15:45:45.274245387Z,2025-07-17T15:45:45.274410721Z,160,2,1108,A,A,0,14.18,100,130,165334,255011161,ARL,304252469,13.26,100,1,13.89,15,1,13.04,2,1,13.9,100,1,13.03,100,1,13.94,15,1,12.73,100,1,14.07,2,1,12.71,100,1,14.18,100,1,12.5,700,1,14.28,100,1,12.46,200,2,14.4,100,1,12.43,700,1,14.56,800,2,12.42,700,1,14.6,700,1,12.37,700,1,14.68,1400,2
2025-07-17T15:45:58.419617935Z,2025-07-17T15:45:58.419783333Z,160,2,1108,C,A,0,13.94,15,130,165398,255183198,ARL,304056997,13.26,100,1,13.89,15,1,13.04,2,1,13.9,100,1,13.03,100,1,14.07,2,1,12.73,100,1,14.18,100,1,12.71,100,1,14.28,100,1,12.5,700,1,14.4,100,1,12.46,200,2,14.56,800,2,12.43,700,1,14.6,700,1,12.42,700,1,14.68,1400,2,12.37,700,1,14.78,100,1
2025-07-17T15:45:58.420113307Z,2025-07-17T15:45:58.420278691Z,160,2,1108,C,A,0,14.88,100,0,165384,255183203,ARL,303682389,13.26,100,1,13.89,15,1,13.04,2,1,13.9,100,1,13.03,100,1,14.07,2,1,12.73,100,1,14.18,100,1,12.71,100,1,14.28,100,1,12.5,700,1,14.4,100,1,12.46,200,2,14.56,800,2,12.43,700,1,14.6,700,1,12.42,700,1,14.68,1400,2,12.37,700,1,14.78,100,1
2025-07-17T15:45:58.420113307Z,2025-07-17T15:45:58.420278691Z,160,2,1108,A,A,0,14.77,100,130,165384,255183203,ARL,304503585,13.26,100,1,13.89,15,1,13.04,2,1,13.9,100,1,13.03,100,1,14.07,2,1,12.73,100,1,14.18,100,1,12.71,100,1,14.28,100,1,12.5,700,1,14.4,100,1,12.46,200,2,14.56,800,2,12.43,700,1,14.6,700,1,12.42,700,1,14.68,1400,2,12.37,700,1,14.77,100,1
2025-07-17T15:45:58.420590199Z,2025-07-17T15:45:58.420755889Z,160,2,1108,C,A,0,14.88,100,0,165690,255183204,ARL,303682385,13.26,100,1,13.89,15,1,13.04,2,1,13.9,100,1,13.03,100,1,14.07,2,1,12.73,100,1,14.18,100,1,12.71,100,1,14.28,100,1,12.5,700,1,14.4,100,1,12.46,200,2,14.56,800,2,12.43,700,1,14.6,700,1,12.42,700,1,14.68,1400,2,12.37,700,1,14.77,100,1
2025-07-17T15:45:58.420590199Z,2025-07-17T15:45:58.420755889Z,160,2,1108,A,A,0,14.77,100,130,165690,255183204,ARL,304503593,13.26,100,1,13.89,15,1,13.04,2,1,13.9,100,1,13.03,100,1,14.07,2,1,12.73,100,1,14.18,100,1,12.71,100,1,14.28,100,1,12.5,700,1,14.4,100,1,12.46,200,2,14.56,800,2,12.43,700,1,14.6,700,1,12.42,700,1,14.68,1400,2,12.37,700,1,14.77,200,2
2025-07-17T15:45:58.782726994Z,2025-07-17T15:45:58.782892109Z,160,2,1108,C,A,0,13.89,15,130,165115,255189425,ARL,304238913,13.26,100,1,13.9,100,1,13.04,2,1,14.07,2,1,13.03,100,1,14.18,100,1,12.73,100,1,14.28,100,1,12.71,100,1,14.4,100,1,12.5,700,1,14.56,800,2,12.46,200,2,14.6,700,1,12.43,700,1,14.68,1400,2,12.42,700,1,14.77,200,2,12.37,700,1,14.78,100,1
2025-07-17T15:46:16.782892334Z,2025-07-17T15:46:16.783057616Z,160,2,1108,A,A,0,13.88,15,130,165282,255552962,ARL,304949689,13.26,100,1,13.88,15,1,13.04,2,1,13.9,100,1,13.03,100,1,14.07,2,1,12.73,100,1,14.18,100,1,12.71,100,1,14.28,100,1,12.5,700,1,14.4,100,1,12.46,200,2,14.56,800,2,12.43,700,1,14.6,700,1,12.42,700,1,14.68,1400,2,12.37,700,1,14.77,200,2
2025-07-17T15:46:16.783160795Z,2025-07-17T15:46:16.783326241Z,160,2,1108,C,A,0,13.9,100,0,165446,255552970,ARL,304252313,13.26,100,1,13.88,15,1,13.04,2,1,14.07,2,1,13.03,100,1,14.18,100,1,12.73,100,1,14.28,100,1,12.71,100,1,14.4,100,1,12.5,700,1,14.56,800,2,12.46,200,2,14.6,700,1,12.43,700,1,14.68,1400,2,12.42,700,1,14.77,200,2,12.37,700,1,14.78,100,1
2025-07-17T15:46:16.783160795Z,2025-07-17T15:46:16.783326241Z,160,2,1108,A,A,0,13.89,100,130,165446,255552970,ARL,304949697,13.26,100,1,13.88,15,1,13.04,2,1,13.89,100,1,13.03,100,1,14.07,2,1,12.73,100,1,14.18,100,1,12.71,100,1,14.28,100,1,12.5,700,1,14.4,100,1,12.46,200,2,14.56,800,2,12.43,700,1,14.6,700,1,12.42,700,1,14.68,1400,2,12.37,700,1,14.77,200,2
2025-07-17T15:46:18.782732218Z,2025-07-17T15:46:18.782897570Z,160,2,1108,C,A,0,13.88,15,130,165352,255587336,ARL,304949689,13.26,100,1,13.89,100,1,13.04,2,1,14.07,2,1,13.03,100,1,14.18,100,1,12.73,100,1,14.28,100,1,12.71,100,1,14.4,100,1,12.5,700,1,14.56,800,2,12.46,200,2,14.6,700,1,12.43,700,1,14.68,1400,2,12.42,700,1,14.77,200,2,12.37,700,1,14.78,100,1
2025-07-17T15:46:28.474001551Z,2025-07-17T15:46:28.474166897Z,160,2,1108,C,A,0,13.89,100,130,165346,255746167,ARL,304949697,13.26,100,1,14.07,2,1,13.04,2,1,14.18,100,1,13.03,100,1,14.28,100,1,12.73,100,1,14.4,100,1,12.71,100,1,14.56,800,2,12.5,700,1,14.6,700,1,12.46,200,2,14.68,1400,2,12.43,700,1,14.77,200,2,12.42,700,1,14.78,100,1,12.37,700,1,14.96,200,2
2025-07-17T15:46:28.474561156Z,2025-07-17T15:46:28.474726594Z,160,2,1108,C,A,0,14.77,100,0,165438,255746173,ARL,304503593,13.26,100,1,14.07,2,1,13.04,2,1,14.18,100,1,13.03,100,1,14.28,100,1,12.73,100,1,14.4,100,1,12.71,100,1,14.56,800,2,12.5,700,1,14.6,700,1,12.46,200,2,14.68,1400,2,12.43,700,1,14.77,100,1,12.42,700,1,14.78,100,1,12.37,700,1,14.96,200,2
2025-07-17T15:46:28.474561156Z,2025-07-17T15:46:28.474726594Z,160,2,1108,A,A,0,14.88,100,130,165438,255746173,ARL,305184937,13.26,100,1,14.07,2,1,13.04,2,1,14.18,100,1,13.03,100,1,14.28,100,1,12.73,100,1,14.4,100,1,12.71,100,1,14.56,800,2,12.5,700,1,14.6,700,1,12.46,200,2,14.68,1400,2,12.43,700,1,14.77,100,1,12.42,700,1,14.78,100,1,12.37,700,1,14.88,100,1
2025-07-17T15:46:28.474730225Z,2025-07-17T15:46:28.474896460Z,160,2,1108,C,A,0,14.77,100,0,166235,255746176,ARL,304503585,13.26,100,1,14.07,2,1,13.04,2,1,14.18,100,1,13.03,100,1,14.28,100,1,12.73,100,1,14.4,100,1,12.71,100,1,14.56,800,2,12.5,700,1,14.6,700,1,12.46,200,2,14.68,1400,2,12.43,700,1,14.78,100,1,12.42,700,1,14.88,100,1,12.37,700,1,14.96,200,2
2025-07-17T15:46:28.474730225Z,2025-07-17T15:46:28.474896460Z,160,2,1108,A,A,0,14.88,100,130,166235,255746176,ARL,305184953,13.26,100,1,14.07,2,1,13.04,2,1,14.18,100,1,13.03,100,1,14.28,100,1,12.73,100,1,14.4,100,1,12.71,100,1,14.56,800,2,12.5,700,1,14.6,700,1,12.46,200,2,14.68,1400,2,12.43,700,1,14.78,100,1,12.42,700,1,14.88,200,2,12.37,700,1,14.96,200,2
2025-07-17T15:46:28.474736101Z,2025-07-17T15:46:28.474902154Z,160,2,1108,C,A,0,14.98,100,0,166053,255746178,ARL,304252333,13.26,100,1,14.07,2,1,13.04,2,1,14.18,100,1,13.03,100,1,14.28,100,1,12.73,100,1,14.4,100,1,12.71,100,1,14.56,800,2,12.5,700,1,14.6,700,1,12.46,200,2,14.68,1400,2,12.43,700,1,14.78,100,1,12.42,700,1,14.88,200,2,12.37,700,1,14.96,200,2
2025-07-17T15:46:28.474736101Z,2025-07-17T15:46:28.474902154Z,160,2,1108,A,A,0,15.03,100,128,166053,255746178,ARL,305184957,13.26,100,1,14.07,2,1,13.04,2,1,14.18,100,1,13.03,100,1,14.28,100,1,12.73,100,1,14.4,100,1,12.71,100,1,14.56,800,2,12.5,700,1,14.6,700,1,12.46,200,2,14.68,1400,2,12.43,700,1,14.78,100,1,12.42,700,1,14.88,200,2,12.37,700,1,14.96,200,2
2025-07-17T15:46:28.492716775Z,2025-07-17T15:46:28.492881980Z,160,2,1108,C,A,0,14.18,100,130,165205,255746619,ARL,304252469,13.26,100,1,14.07,2,1,13.04,2,1,14.28,100,1,13.03,100,1,14.4,100,1,12.73,100,1,14.56,800,2,12.71,100,1,14.6,700,1,12.5,700,1,14.68,1400,2,12.46,200,2,14.78,100,1,12.43,700,1,14.88,200,2,12.42,700,1,14.96,200,2,12.37,700,1,15.03,100,1
2025-07-17T15:46:28.492765859Z,2025-07-17T15:46:28.492931279Z,160,2,1108,A,A,0,14.26,100,130,165420,255746621,ARL,305185529,13.26,100,1,14.07,2,1,13.04,2,1,14.26,100,1,13.03,100,1,14.28,100,1,12.73,100,1,14.4,100,1,12.71,100,1,14.56,800,2,12.5,700,1,14.6,700,1,12.46,200,2,14.68,1400,2,12.43,700,1,14.78,100,1,12.42,700,1,14.88,200,2,12.37,700,1,14.96,200,2
2025-07-17T15:46:28.646108242Z,2025-07-17T15:46:28.646273467Z,160,2,1108,A,A,0,14.08,100,130,165225,255748568,ARL,305187077,13.26,100,1,14.07,2,1,13.04,2,1,14.08,100,1,13.03,100,1,14.26,100,1,12.73,100,1,14.28,100,1,12.71,100,1,14.4,100,1,12.5,700,1,14.56,800,2,12.46,200,2,14.6,700,1,12.43,700,1,14.68,1400,2,12.42,700,1,14.78,100,1,12.37,700,1,14.88,200,2
2025-07-17T15:46:57.523859388Z,2025-07-17T15:46:57.524024658Z,160,2,1108,A,A,0,13.92,15,130,165270,256268482,ARL,305862145,13.26,100,1,13.92,15,1,13.04,2,1,14.07,2,1,13.03,100,1,14.08,100,1,12.73,100,1,14.26,100,1,12.71,100,1,14.28,100,1,12.5,700,1,14.4,100,1,12.46,200,2,14.56,800,2,12.43,700,1,14.6,700,1,12.42,700,1,14.68,1400,2,12.37,700,1,14.78,100,1
2025-07-17T15:46:57.932677299Z,2025-07-17T15:46:57.932842994Z,160,2,1108,C,A,0,14.08,100,0,165695,256280751,ARL,305187077,13.26,100,1,13.92,15,1,13.04,2,1,14.07,2,1,13.03,100,1,14.26,100,1,12.73,100,1,14.28,100,1,12.71,100,1,14.4,100,1,12.5,700,1,14.56,800,2,12.46,200,2,14.6,700,1,12.43,700,1,14.68,1400,2,12.42,700,1,14.78,100,1,12.37,700,1,14.88,200,2
2025-07-17T15:46:57.932677299Z,2025-07-17T15:46:57.932842994Z,160,2,1108,A,A,0,13.93,100,130,165695,256280751,ARL,305878881,13.26,100,1,13.92,15,1,13.04,2,1,13.93,100,1,13.03,100,1,14.07,2,1,12.73,100,1,14.26,100,1,12.71,100,1,14.28,100,1,12.5,700,1,14.4,100,1,12.46,200,2,14.56,800,2,12.43,700,1,14.6,700,1,12.42,700,1,14.68,1400,2,12.37,700,1,14.78,100,1
2025-07-17T15:47:06.609290857Z,2025-07-17T15:47:06.609456251Z,160,2,1108,A,A,0,13.88,15,130,165394,256488374,ARL,306121113,13.26,100,1,13.88,15,1,13.04,2,1,13.92,15,1,13.03,100,1,13.93,100,1,12.73,100,1,14.07,2,1,12.71,100,1,14.26,100,1,12.5,700,1,14.28,100,1,12.46,200,2,14.4,100,1,12.43,700,1,14.56,800,2,12.42,700,1,14.6,700,1,12.37,700,1,14.68,1400,2
2025-07-17T15:47:08.787529505Z,2025-07-17T15:47:08.787695144Z,160,2,1108,C,A,0,13.93,100,0,165639,256532991,ARL,305878881,13.26,100,1,13.88,15,1,13.04,2,1,13.92,15,1,13.03,100,1,14.07,2,1,12.73,100,1,14.26,100,1,12.71,100,1,14.28,100,1,12.5,700,1,14.4,100,1,12.46,200,2,14.56,800,2,12.43,700,1,14.6,700,1,12.42,700,1,14.68,1400,2,12.37,700,1,14.78,100,1
2025-07-17T15:47:08.787529505Z,2025-07-17T15:47:08.787695144Z,160,2,1108,A,A,0,13.89,100,130,165639,256532991,ARL,306170837,13.26,100,1,13.88,15,1,13.04,2,1,13.89,100,1,13.03,100,1,13.92,15,1,12.73,100,1,14.07,2,1,12.71,100,1,14.26,100,1,12.5,700,1,14.28,100,1,12.46,200,2,14.4,100,1,12.43,700,1,14.56,800,2,12.42,700,1,14.6,700,1,12.37,700,1,14.68,1400,2
2025-07-17T15:47:08.788275184Z,2025-07-17T15:47:08.788440762Z,160,2,1108,C,A,0,15.03,100,0,165578,256533005,ARL,305184957,13.26,100,1,13.88,15,1,13.04,2,1,13.89,100,1,13.03,100,1,13.92,15,1,12.73,100,1,14.07,2,1,12.71,100,1,14.26,100,1,12.5,700,1,14.28,100,1,12.46,200,2,14.4,100,1,12.43,700,1,14.56,800,2,12.42,700,1,14.6,700,1,12.37,700,1,14.68,1400,2
2025-07-17T15:47:08.788275184Z,2025-07-17T15:47:08.788440762Z,160,2,1108,A,A,0,14.97,100,130,165578,256533005,ARL,306170869,13.26,100,1,13.88,15,1,13.04,2,1,13.89,100,1,13.03,100,1,13.92,15,1,12.73,100,1,14.07,2,1,12.71,100,1,14.26,100,1,12.5,700,1,14.28,100,1,12.46,200,2,14.4,100,1,12.43,700,1,14.56,800,2,12.42,700,1,14.6,700,1,12.37,700,1,14.68,1400,2
2025-07-17T15:47:08.805818249Z,2025-07-17T15:47:08.805983406Z,160,2,1108,C,A,0,14.26,100,130,165157,256533442,ARL,305185529,13.26,100,1,13.88,15,1,13.04,2,1,13.89,100,1,13.03,100,1,13.92,15,1,12.73,100,1,14.07,2,1,12.71,100,1,14.28,100,1,12.5,700,1,14.4,100,1,12.46,200,2,14.56,800,2,12.43,700,1,14.6,700,1,12.42,700,1,14.68,1400,2,12.37,700,1,14.78,100,1
2025-07-17T15:47:08.805868059Z,2025-07-17T15:47:08.806033773Z,160,2,1108,A,A,0,14.17,100,130,165714,256533443,ARL,306171457,13.26,100,1,13.88,15,1,13.04,2,1,13.89,100,1,13.03,100,1,13.92,15,1,12.73,100,1,14.07,2,1,12.71,100,1,14.17,100,1,12.5,700,1,14.28,100,1,12.46,200,2,14.4,100,1,12.43,700,1,14.56,800,2,12.42,700,1,14.6,700,1,12.37,700,1,14.68,1400,2
2025-07-17T15:47:13.121288953Z,2025-07-17T15:47:13.121454355Z,160,2,1108,C,A,0,13.88,15,130,165402,256612694,ARL,306121113,13.26,100,1,13.89,100,1,13.04,2,1,13.92,15,1,13.03,100,1,14.07,2,1,12.73,100,1,14.17,100,1,12.71,100,1,14.28,100,1,12.5,700,1,14.4,100,1,12.46,200,2,14.56,800,2,12.43,700,1,14.6,700,1,12.42,700,1,14.68,1400,2,12.37,700,1,14.78,100,1
2025-07-17T15:47:13.122396816Z,2025-07-17T15:47:13.122562533Z,160,2,1108,C,A,0,13.92,15,130,165717,256612757,ARL,305862145,13.26,100,1,13.89,100,1,13.04,2,1,14.07,2,1,13.03,100,1,14.17,100,1,12.73,100,1,14.28,100,1,12.71,100,1,14.4,100,1,12.5,700,1,14.56,800,2,12.46,200,2,14.6,700,1,12.43,700,1,14.68,1400,2,12.42,700,1,14.78,100,1,12.37,700,1,14.88,200,2
2025-07-17T15:47:24.786310694Z,2025-07-17T15:47:24.786476266Z,160,2,1108,A,A,0,13.87,15,130,165572,256812416,ARL,306519385,13.26,100,1,13.87,15,1,13.04,2,1,13.89,100,1,13.03,100,1,14.07,2,1,12.73,100,1,14.17,100,1,12.71,100,1,14.28,100,1,12.5,700,1,14.4,100,1,12.46,200,2,14.56,800,2,12.43,700,1,14.6,700,1,12.42,700,1,14.68,1400,2,12.37,700,1,14.78,100,1
2025-07-17T15:47:24.786580061Z,2025-07-17T15:47:24.786745657Z,160,2,1108,C,A,0,13.89,100,0,165596,256812420,ARL,306170837,13.26,100,1,13.87,15,1,13.04,2,1,14.07,2,1,13.03,100,1,14.17,100,1,12.73,100,1,14.28,100,1,12.71,100,1,14.4,100,1,12.5,700,1,14.56,800,2,12.46,200,2,14.6,700,1,12.43,700,1,14.68,1400,2,12.42,700,1,14.78,100,1,12.37,700,1,14.88,200,2
2025-07-17T15:47:24.786580061Z,2025-07-17T15:47:24.786745657Z,160,2,1108,A,A,0,13.88,100,130,165596,256812420,ARL,306519397,13.26,100,1,13.87,15,1,13.04,2,1,13.88,100,1,13.03,100,1,14.07,2,1,12.73,100,1,14.17,100,1,12.71,100,1,14.28,100,1,12.5,700,1,14.4,100,1,12.46,200,2,14.56,800,2,12.43,700,1,14.6,700,1,12.42,700,1,14.68,1400,2,12.37,700,1,14.78,100,1
2025-07-17T15:47:24.786759805Z,2025-07-17T15:47:24.786925729Z,160,2,1108,C,A,0,14.88,100,0,165924,256812422,ARL,305184937,13.26,100,1,13.87,15,1,13.04,2,1,13.88,100,1,13.03,100,1,14.07,2,1,12.73,100,1,14.17,100,1,12.71,100,1,14.28,100,1,12.5,700,1,14.4,100,1,12.46,200,2,14.56,800,2,12.43,700,1,14.6,700,1,12.42,700,1,14.68,1400,2,12.37,700,1,14.78,100,1
2025-07-17T15:47:24.786759805Z,2025-07-17T15:47:24.786925729Z,160,2,1108,A,A,0,14.77,100,130,165924,256812422,ARL,306519409,13.26,100,1,13.87,15,1,13.04,2,1,13.88,100,1,13.03,100,1,14.07,2,1,12.73,100,1,14.17,100,1,12.71,100,1,14.28,100,1,12.5,700,1,14.4,100,1,12.46,200,2,14.56,800,2,12.43,700,1,14.6,700,1,12.42,700,1,14.68,1400,2,12.37,700,1,14.77,100,1
2025-07-17T15:47:24.800449950Z,2025-07-17T15:47:24.800616004Z,160,2,1108,C,A,0,14.88,100,0,166054,256812578,ARL,305184953,13.26,100,1,13.87,15,1,13.04,2,1,13.88,100,1,13.03,100,1,14.07,2,1,12.73,100,1,14.17,100,1,12.71,100,1,14.28,100,1,12.5,700,1,14.4,100,1,12.46,200,2,14.56,800,2,12.43,700,1,14.6,700,1,12.42,700,1,14.68,1400,2,12.37,700,1,14.77,100,1
2025-07-17T15:47:24.800449950Z,2025-07-17T15:47:24.800616004Z,160,2,1108,A,A,0,14.75,100,130,166054,256812578,ARL,306519741,13.26,100,1,13.87,15,1,13.04,2,1,13.88,100,1,13.03,100,1,14.07,2,1,12.73,100,1,14.17,100,1,12.71,100,1,14.28,100,1,12.5,700,1,14.4,100,1,12.46,200,2,14.56,800,2,12.43,700,1,14.6,700,1,12.42,700,1,14.68,1400,2,12.37,700,1,14.75,100,1
2025-07-17T15:47:27.860107552Z,2025-07-17T15:47:27.860272892Z,160,2,1108,A,A,0,13.83,15,130,165340,256866835,ARL,306587393,13.26,100,1,13.83,15,1,13.04,2,1,13.87,15,1,13.03,100,1,13.88,100,1,12.73,100,1,14.07,2,1,12.71,100,1,14.17,100,1,12.5,700,1,14.28,100,1,12.46,200,2,14.4,100,1,12.43,700,1,14.56,800,2,12.42,700,1,14.6,700,1,12.37,700,1,14.68,1400,2
2025-07-17T15:47:31.406863918Z,2025-07-17T15:47:31.407029312Z,160,2,1108,C,A,0,13.88,100,0,165394,256910124,ARL,306519397,13.26,100,1,13.83,15,1,13.04,2,1,13.87,15,1,13.03,100,1,14.07,2,1,12.73,100,1,14.17,100,1,12.71,100,1,14.28,100,1,12.5,700,1,14.4,100,1,12.46,200,2,14.56,800,2,12.43,700,1,14.6,700,1,12.42,700,1,14.68,1400,2,12.37,700,1,14.75,100,1
2025-07-17T15:47:31.406863918Z,2025-07-17T15:47:31.407029312Z,160,2,1108,A,A,0,13.84,100,130,165394,256910124,ARL,306647425,13.26,100,1,13.83,15,1,13.04,2,1,13.84,100,1,13.03,100,1,13.87,15,1,12.73,100,1,14.07,2,1,12.71,100,1,14.17,100,1,12.5,700,1,14.28,100,1,12.46,200,2,14.4,100,1,12.43,700,1,14.56,800,2,12.42,700,1,14.6,700,1,12.37,700,1,14.68,1400,2
2025-07-17T15:47:31.407605685Z,2025-07-17T15:47:31.407771110Z,160,2,1108,C,A,0,14.97,100,0,165425,256910129,ARL,306170869,13.26,100,1,13.83,15,1,13.04,2,1,13.84,100,1,13.03,100,1,13.87,15,1,12.73,100,1,14.07,2,1,12.71,100,1,14.17,100,1,12.5,700,1,14.28,100,1,12.46,200,2,14.4,100,1,12.43,700,1,14.56,800,2,12.42,700,1,14.6,700,1,12.37,700,1,14.68,1400,2
2025-07-17T15:47:31.407605685Z,2025-07-17T15:47:31.407771110Z,160,2,1108,A,A,0,14.91,100,130,165425,256910129,ARL,306647445,13.26,100,1,13.83,15,1,13.04,2,1,13.84,100,1,13.03,100,1,13.87,15,1,12.73,100,1,14.07,2,1,12.71,100,1,14.17,100,1,12.5,700,1,14.28,100,1,12.46,200,2,14.4,100,1,12.43,700,1,14.56,800,2,12.42,700,1,14.6,700,1,12.37,700,1,14.68,1400,2
2025-07-17T15:47:31.413325908Z,2025-07-17T15:47:31.413491477Z,160,2,1108,C,A,0,14.78,100,0,165569,256910184,ARL,303331425,13.26,100,1,13.83,15,1,13.04,2,1,13.84,100,1,13.03,100,1,13.87,15,1,12.73,100,1,14.07,2,1,12.71,100,1,14.17,100,1,12.5,700,1,14.28,100,1,12.46,200,2,14.4,100,1,12.43,700,1,14.56,800,2,12.42,700,1,14.6,700,1,12.37,700,1,14.68,1400,2
2025-07-17T15:47:31.413325908Z,2025-07-17T15:47:31.413491477Z,160,2,1108,A,A,0,14.64,100,130,165569,256910184,ARL,306647521,13.26,100,1,13.83,15,1,13.04,2,1,13.84,100,1,13.03,100,1,13.87,15,1,12.73,100,1,14.07,2,1,12.71,100,1,14.17,100,1,12.5,700,1,14.28,100,1,12.46,200,2,14.4,100,1,12.43,700,1,14.56,800,2,12.42,700,1,14.6,700,1,12.37,700,1,14.64,100,1
2025-07-17T15:47:31.433320466Z,2025-07-17T15:47:31.433486283Z,160,2,1108,C,A,0,14.96,100,0,165817,256910721,ARL,303330509,13.26,100,1,13.83,15,1,13.04,2,1,13.84,100,1,13.03,100,1,13.87,15,1,12.73,100,1,14.07,2,1,12.71,100,1,14.17,100,1,12.5,700,1,14.28,100,1,12.46,200,2,14.4,100,1,12.43,700,1,14.56,800,2,12.42,700,1,14.6,700,1,12.37,700,1,14.64,100,1
2025-07-17T15:47:31.433320466Z,2025-07-17T15:47:31.433486283Z,160,2,1108,A,A,0,14.81,100,130,165817,256910721,ARL,306649913,13.26,100,1,13.83,15,1,13.04,2,1,13.84,100,1,13.03,100,1,13.87,15,1,12.73,100,1,14.07,2,1,12.71,100,1,14.17,100,1,12.5,700,1,14.28,100,1,12.46,200,2,14.4,100,1,12.43,700,1,14.56,800,2,12.42,700,1,14.6,700,1,12.37,700,1,14.64,100,1
2025-07-17T15:47:31.573963059Z,2025-07-17T15:47:31.574128504Z,160,2,1108,C,A,0,16.08,100,0,165445,256912087,ARL,303331429,13.26,100,1,13.83,15,1,13.04,2,1,13.84,100,1,13.03,100,1,13.87,15,1,12.73,100,1,14.07,2,1,12.71,100,1,14.17,100,1,12.5,700,1,14.28,100,1,12.46,200,2,14.4,100,1,12.43,700,1,14.56,800,2,12.42,700,1,14.6,700,1,12.37,700,1,14.64,100,1
2025-07-17T15:47:31.573963059Z,2025-07-17T15:47:31.574128504Z,160,2,1108,A,A,0,15.92,100,130,165445,256912087,ARL,306652001,13.26,100,1,13.83,15,1,13.04,2,1,13.84,100,1,13.03,100,1,13.87,15,1,12.73,100,1,14.07,2,1,12.71,100,1,14.17,100,1,12.5,700,1,14.28,100,1,12.46,200,2,14.4,100,1,12.43,700,1,14.56,800,2,12.42,700,1,14.6,700,1,12.37,700,1,14.64,100,1
2025-07-17T15:47:31.575209032Z,2025-07-17T15:47:31.575374481Z,160,2,1108,C,A,0,17.76,100,0,165449,256912094,ARL,303331309,13.26,100,1,13.83,15,1,13.04,2,1,13.84,100,1,13.03,100,1,13.87,15,1,12.73,100,1,14.07,2,1,12.71,100,1,14.17,100,1,12.5,700,1,14.28,100,1,12.46,200,2,14.4,100,1,12.43,700,1,14.56,800,2,12.42,700,1,14.6,700,1,12.37,700,1,14.64,100,1
2025-07-17T15:47:31.575209032Z,2025-07-17T15:47:31.575374481Z,160,2,1108,A,A,0,17.58,100,130,165449,256912094,ARL,306652017,13.26,100,1,13.83,15,1,13.04,2,1,13.84,100,1,13.03,100,1,13.87,15,1,12.73,100,1,14.07,2,1,12.71,100,1,14.17,100,1,12.5,700,1,14.28,100,1,12.46,200,2,14.4,100,1,12.43,700,1,14.56,800,2,12.42,700,1,14.6,700,1,12.37,700,1,14.64,100,1
2025-07-17T15:47:31.739930142Z,2025-07-17T15:47:31.740095714Z,160,2,1108,C,A,0,14.96,100,0,165572,256914067,ARL,303334253,13.26,100,1,13.83,15,1,13.04,2,1,13.84,100,1,13.03,100,1,13.87,15,1,12.73,100,1,14.07,2,1,12.71,100,1,14.17,100,1,12.5,700,1,14.28,100,1,12.46,200,2,14.4,100,1,12.43,700,1,14.56,800,2,12.42,700,1,14.6,700,1,12.37,700,1,14.64,100,1
2025-07-17T15:47:31.739930142Z,2025-07-17T15:47:31.740095714Z,160,2,1108,A,A,0,14.81,100,130,165572,256914067,ARL,306653713,13.26,100,1,13.83,15,1,13.04,2,1,13.84,100,1,13.03,100,1,13.87,15,1,12.73,100,1,14.07,2,1,12.71,100,1,14.17,100,1,12.5,700,1,14.28,100,1,12.46,200,2,14.4,100,1,12.43,700,1,14.56,800,2,12.42,700,1,14.6,700,1,12.37,700,1,14.64,100,1
2025-07-17T15:47:37.159424166Z,2025-07-17T15:47:37.159589804Z,160,2,1108,C,A,0,13.87,15,130,165638,256983942,ARL,306519385,13.26,100,1,13.83,15,1,13.04,2,1,13.84,100,1,13.03,100,1,14.07,2,1,12.73,100,1,14.17,100,1,12.71,100,1,14.28,100,1,12.5,700,1,14.4,100,1,12.46,200,2,14.56,800,2,12.43,700,1,14.6,700,1,12.42,700,1,14.64,100,1,12.37,700,1,14.68,1400,2
2025-07-17T15:47:37.171834941Z,2025-07-17T15:47:37.172000440Z,160,2,1108,A,A,0,13.85,100,130,165499,256984053,ARL,306749753,13.26,100,1,13.83,15,1,13.04,2,1,13.84,100,1,13.03,100,1,13.85,100,1,12.73,100,1,14.07,2,1,12.71,100,1,14.17,100,1,12.5,700,1,14.28,100,1,12.46,200,2,14.4,100,1,12.43,700,1,14.56,800,2,12.42,700,1,14.6,700,1,12.37,700,1,14.64,100,1
2025-07-17T15:47:38.161015969Z,2025-07-17T15:47:38.161181283Z,160,2,1108,A,A,0,13.79,15,130,165314,256998606,ARL,306770041,13.26,100,1,13.79,15,1,13.04,2,1,13.83,15,1,13.03,100,1,13.84,100,1,12.73,100,1,13.85,100,1,12.71,100,1,14.07,2,1,12.5,700,1,14.17,100,1,12.46,200,2,14.28,100,1,12.43,700,1,14.4,100,1,12.42,700,1,14.56,800,2,12.37,700,1,14.6,700,1
2025-07-17T15:47:38.794795887Z,2025-07-17T15:47:38.794962245Z,160,2,1108,C,A,0,13.84,100,0,166358,257010989,ARL,306647425,13.26,100,1,13.79,15,1,13.04,2,1,13.83,15,1,13.03,100,1,13.85,100,1,12.73,100,1,14.07,2,1,12.71,100,1,14.17,100,1,12.5,700,1,14.28,100,1,12.46,200,2,14.4,100,1,12.43,700,1,14.56,800,2,12.42,700,1,14.6,700,1,12.37,700,1,14.64,100,1
2025-07-17T15:47:38.794795887Z,2025-07-17T15:47:38.794962245Z,160,2,1108,A,A,0,13.8,100,128,166358,257010989,ARL,306784133,13.26,100,1,13.79,15,1,13.04,2,1,13.8,100,1,13.03,100,1,13.83,15,1,12.73,100,1,13.85,100,1,12.71,100,1,14.07,2,1,12.5,700,1,14.17,100,1,12.46,200,2,14.28,100,1,12.43,700,1,14.4,100,1,12.42,700,1,14.56,800,2,12.37,700,1,14.6,700,1
2025-07-17T15:47:38.795557785Z,2025-07-17T15:47:38.795723570Z,160,2,1108,C,A,0,14.91,100,0,165785,257011058,ARL,306647445,13.26,100,1,13.79,15,1,13.04,2,1,13.8,100,1,13.03,100,1,13.83,15,1,12.73,100,1,13.85,100,1,12.71,100,1,14.07,2,1,12.5,700,1,14.17,100,1,12.46,200,2,14.28,100,1,12.43,700,1,14.4,100,1,12.42,700,1,14.56,800,2,12.37,700,1,14.6,700,1
2025-07-17T15:47:38.795557785Z,2025-07-17T15:47:38.795723570Z,160,2,1108,A,A,0,14.87,100,130,165785,257011058,ARL,306784201,13.26,100,1,13.79,15,1,13.04,2,1,13.8,100,1,13.03,100,1,13.83,15,1,12.73,100,1,13.85,100,1,12.71,100,1,14.07,2,1,12.5,700,1,14.17,100,1,12.46,200,2,14.28,100,1,12.43,700,1,14.4,100,1,12.42,700,1,14.56,800,2,12.37,700,1,14.6,700,1
2025-07-17T15:47:38.804458744Z,2025-07-17T15:47:38.804624258Z,160,2,1108,C,A,0,14.17,100,130,165514,257011716,ARL,306171457,13.26,100,1,13.79,15,1,13.04,2,1,13.8,100,1,13.03,100,1,13.83,15,1,12.73,100,1,13.85,100,1,12.71,100,1,14.07,2,1,12.5,700,1,14.28,100,1,12.46,200,2,14.4,100,1,12.43,700,1,14.56,800,2,12.42,700,1,14.6,700,1,12.37,700,1,14.64,100,1
2025-07-17T15:47:38.804513793Z,2025-07-17T15:47:38.804679592Z,160,2,1108,A,A,0,14.08,100,130,165799,257011717,ARL,306784853,13.26,100,1,13.79,15,1,13.04,2,1,13.8,100,1,13.03,100,1,13.83,15,1,12.73,100,1,13.85,100,1,12.71,100,1,14.07,2,1,12.5,700,1,14.08,100,1,12.46,200,2,14.28,100,1,12.43,700,1,14.4,100,1,12.42,700,1,14.56,800,2,12.37,700,1,14.6,700,1
2025-07-17T15:47:39.092305947Z,2025-07-17T15:47:39.092472059Z,160,2,1108,C,A,0,13.79,15,130,166112,257018687,ARL,306770041,13.26,100,1,13.8,100,1,13.04,2,1,13.83,15,1,13.03,100,1,13.85,100,1,12.73,100,1,14.07,2,1,12.71,100,1,14.08,100,1,12.5,700,1,14.28,100,1,12.46,200,2,14.4,100,1,12.43,700,1,14.56,800,2,12.42,700,1,14.6,700,1,12.37,700,1,14.64,100,1
2025-07-17T15:47:39.095755335Z,2025-07-17T15:47:39.095920859Z,160,2,1108,C,A,0,13.83,15,130,165524,257018796,ARL,306587393,13.26,100,1,13.8,100,1,13.04,2,1,13.85,100,1,13.03,100,1,14.07,2,1,12.73,100,1,14.08,100,1,12.71,100,1,14.28,100,1,12.5,700,1,14.4,100,1,12.46,200,2,14.56,800,2,12.43,700,1,14.6,700,1,12.42,700,1,14.64,100,1,12.37,700,1,14.68,1400,2
2025-07-17T15:48:08.909201576Z,2025-07-17T15:48:08.909366905Z,160,2,1108,A,A,0,13.83,100,130,165329,257603755,ARL,307567929,13.26,100,1,13.8,100,1,13.04,2,1,13.83,100,1,13.03,100,1,13.85,100,1,12.73,100,1,14.07,2,1,12.71,100,1,14.08,100,1,12.5,700,1,14.28,100,1,12.46,200,2,14.4,100,1,12.43,700,1,14.56,800,2,12.42,700,1,14.6,700,1,12.37,700,1,14.64,100,1
2025-07-17T15:48:08.916555821Z,2025-07-17T15:48:08.916721098Z,160,2,1108,C,A,0,13.85,100,130,165277,257604057,ARL,306749753,13.26,100,1,13.8,100,1,13.04,2,1,13.83,100,1,13.03,100,1,14.07,2,1,12.73,100,1,14.08,100,1,12.71,100,1,14.28,100,1,12.5,700,1,14.4,100,1,12.46,200,2,14.56,800,2,12.43,700,1,14.6,700,1,12.42,700,1,14.64,100,1,12.37,700,1,14.68,1400,2
2025-07-17T15:48:09.653308042Z,2025-07-17T15:48:09.653473465Z,160,2,1108,A,A,0,13.78,15,130,165423,257621095,ARL,307587873,13.26,100,1,13.78,15,1,13.04,2,1,13.8,100,1,13.03,100,1,13.83,100,1,12.73,100,1,14.07,2,1,12.71,100,1,14.08,100,1,12.5,700,1,14.28,100,1,12.46,200,2,14.4,100,1,12.43,700,1,14.56,800,2,12.42,700,1,14.6,700,1,12.37,700,1,14.64,100,1
2025-07-17T15:48:11.166517494Z,2025-07-17T15:48:11.166689254Z,160,2,1108,C,A,0,13.78,15,128,171760,257644020,ARL,307587873,13.26,100,1,13.8,100,1,13.04,2,1,13.83,100,1,13.03,100,1,14.07,2,1,12.73,100,1,14.08,100,1,12.71,100,1,14.28,100,1,12.5,700,1,14.4,100,1,12.46,200,2,14.56,800,2,12.43,700,1,14.6,700,1,12.42,700,1,14.64,100,1,12.37,700,1,14.68,1400,2
2025-07-17T15:48:13.508913083Z,2025-07-17T15:48:13.509078553Z,160,2,1108,A,A,0,13.78,15,130,165470,257727039,ARL,307714769,13.26,100,1,13.78,15,1,13.04,2,1,13.8,100,1,13.03,100,1,13.83,100,1,12.73,100,1,14.07,2,1,12.71,100,1,14.08,100,1,12.5,700,1,14.28,100,1,12.46,200,2,14.4,100,1,12.43,700,1,14.56,800,2,12.42,700,1,14.6,700,1,12.37,700,1,14.64,100,1
2025-07-17T15:48:13.525788139Z,2025-07-17T15:48:13.525953545Z,160,2,1108,A,A,0,13.81,100,130,165406,257727301,ARL,307715101,13.26,100,1,13.78,15,1,13.04,2,1,13.8,100,1,13.03,100,1,13.81,100,1,12.73,100,1,13.83,100,1,12.71,100,1,14.07,2,1,12.5,700,1,14.08,100,1,12.46,200,2,14.28,100,1,12.43,700,1,14.4,100,1,12.42,700,1,14.56,800,2,12.37,700,1,14.6,700,1
2025-07-17T15:48:13.532443045Z,2025-07-17T15:48:13.532608874Z,160,2,1108,C,A,0,13.83,100,130,165829,257727457,ARL,307567929,13.26,100,1,13.78,15,1,13.04,2,1,13.8,100,1,13.03,100,1,13.81,100,1,12.73,100,1,14.07,2,1,12.71,100,1,14.08,100,1,12.5,700,1,14.28,100,1,12.46,200,2,14.4,100,1,12.43,700,1,14.56,800,2,12.42,700,1,14.6,700,1,12.37,700,1,14.64,100,1
2025-07-17T15:48:15.568378275Z,2025-07-17T15:48:15.568544154Z,160,2,1108,C,A,0,13.8,100,0,165879,257757458,ARL,306784133,13.26,100,1,13.78,15,1,13.04,2,1,13.81,100,1,13.03,100,1,14.07,2,1,12.73,100,1,14.08,100,1,12.71,100,1,14.28,100,1,12.5,700,1,14.4,100,1,12.46,200,2,14.56,800,2,12.43,700,1,14.6,700,1,12.42,700,1,14.64,100,1,12.37,700,1,14.68,1400,2
2025-07-17T15:48:15.568378275Z,2025-07-17T15:48:15.568544154Z,160,2,1108,A,A,0,13.79,100,130,165879,257757458,ARL,307753241,13.26,100,1,13.78,15,1,13.04,2,1,13.79,100,1,13.03,100,1,13.81,100,1,12.73,100,1,14.07,2,1,12.71,100,1,14.08,100,1,12.5,700,1,14.28,100,1,12.46,200,2,14.4,100,1,12.43,700,1,14.56,800,2,12.42,700,1,14.6,700,1,12.37,700,1,14.64,100,1
2025-07-17T15:48:24.009190157Z,2025-07-17T15:48:24.009355346Z,160,2,1108,A,A,0,13.75,15,130,165189,257928318,ARL,307964605,13.26,100,1,13.75,15,1,13.04,2,1,13.78,15,1,13.03,100,1,13.79,100,1,12.73,100,1,13.81,100,1,12.71,100,1,14.07,2,1,12.5,700,1,14.08,100,1,12.46,200,2,14.28,100,1,12.43,700,1,14.4,100,1,12.42,700,1,14.56,800,2,12.37,700,1,14.6,700,1
2025-07-17T15:48:24.009357442Z,2025-07-17T15:48:24.009522633Z,160,2,1108,A,A,0,13.79,100,130,165191,257928319,ARL,307964609,13.26,100,1,13.75,15,1,13.04,2,1,13.78,15,1,13.03,100,1,13.79,200,2,12.73,100,1,13.81,100,1,12.71,100,1,14.07,2,1,12.5,700,1,14.08,100,1,12.46,200,2,14.28,100,1,12.43,700,1,14.4,100,1,12.42,700,1,14.56,800,2,12.37,700,1,14.6,700,1
2025-07-17T15:48:24.009778967Z,2025-07-17T15:48:24.009944381Z,160,2,1108,C,A,0,13.79,100,0,165414,257928325,ARL,307753241,13.26,100,1,13.75,15,1,13.04,2,1,13.78,15,1,13.03,100,1,13.79,100,1,12.73,100,1,13.81,100,1,12.71,100,1,14.07,2,1,12.5,700,1,14.08,100,1,12.46,200,2,14.28,100,1,12.43,700,1,14.4,100,1,12.42,700,1,14.56,800,2,12.37,700,1,14.6,700,1
2025-07-17T15:48:24.009778967Z,2025-07-17T15:48:24.009944381Z,160,2,1108,A,A,0,13.76,100,130,165414,257928325,ARL,307964621,13.26,100,1,13.75,15,1,13.04,2,1,13.76,100,1,13.03,100,1,13.78,15,1,12.73,100,1,13.79,100,1,12.71,100,1,13.81,100,1,12.5,700,1,14.07,2,1,12.46,200,2,14.08,100,1,12.43,700,1,14.28,100,1,12.42,700,1,14.4,100,1,12.37,700,1,14.56,800,2
2025-07-17T15:48:24.009808793Z,2025-07-17T15:48:24.009974166Z,160,2,1108,C,A,0,13.81,100,130,165373,257928326,ARL,307715101,13.26,100,1,13.75,15,1,13.04,2,1,13.76,100,1,13.03,100,1,13.78,15,1,12.73,100,1,13.79,100,1,12.71,100,1,14.07,2,1,12.5,700,1,14.08,100,1,12.46,200,2,14.28,100,1,12.43,700,1,14.4,100,1,12.42,700,1,14.56,800,2,12.37,700,1,14.6,700,1
2025-07-17T15:48:24.010390029Z,2025-07-17T15:48:24.010555416Z,160,2,1108,C,A,0,14.77,100,0,165387,257928333,ARL,306519409,13.26,100,1,13.75,15,1,13.04,2,1,13.76,100,1,13.03,100,1,13.78,15,1,12.73,100,1,13.79,100,1,12.71,100,1,14.07,2,1,12.5,700,1,14.08,100,1,12.46,200,2,14.28,100,1,12.43,700,1,14.4,100,1,12.42,700,1,14.56,800,2,12.37,700,1,14.6,700,1
2025-07-17T15:48:24.010390029Z,2025-07-17T15:48:24.010555416Z,160,2,1108,A,A,0,14.65,100,130,165387,257928333,ARL,307964661,13.26,100,1,13.75,15,1,13.04,2,1,13.76,100,1,13.03,100,1,13.78,15,1,12.73,100,1,13.79,100,1,12.71,100,1,14.07,2,1,12.5,700,1,14.08,100,1,12.46,200,2,14.28,100,1,12.43,700,1,14.4,100,1,12.42,700,1,14.56,800,2,12.37,700,1,14.6,700,1
2025-07-17T15:48:24.010512050Z,2025-07-17T15:48:24.010677522Z,160,2,1108,C,A,0,14.87,100,0,165472,257928340,ARL,306784201,13.26,100,1,13.75,15,1,13.04,2,1,13.76,100,1,13.03,100,1,13.78,15,1,12.73,100,1,13.79,100,1,12.71,100,1,14.07,2,1,12.5,700,1,14.08,100,1,12.46,200,2,14.28,100,1,12.43,700,1,14.4,100,1,12.42,700,1,14.56,800,2,12.37,700,1,14.6,700,1
2025-07-17T15:48:24.010512050Z,2025-07-17T15:48:24.010677522Z,160,2,1108,A,A,0,14.83,100,130,165472,257928340,ARL,307964665,13.26,100,1,13.75,15,1,13.04,2,1,13.76,100,1,13.03,100,1,13.78,15,1,12.73,100,1,13.79,100,1,12.71,100,1,14.07,2,1,12.5,700,1,14.08,100,1,12.46,200,2,14.28,100,1,12.43,700,1,14.4,100,1,12.42,700,1,14.56,800,2,12.37,700,1,14.6,700,1
2025-07-17T15:48:42.009788565Z,2025-07-17T15:48:42.009954046Z,160,2,1108,C,A,0,13.78,15,130,165481,258199397,ARL,307714769,13.26,100,1,13.75,15,1,13.04,2,1,13.76,100,1,13.03,100,1,13.79,100,1,12.73,100,1,14.07,2,1,12.71,100,1,14.08,100,1,12.5,700,1,14.28,100,1,12.46,200,2,14.4,100,1,12.43,700,1,14.56,800,2,12.42,700,1,14.6,700,1,12.37,700,1,14.64,100,1
2025-07-17T15:48:42.011680742Z,2025-07-17T15:48:42.011846392Z,160,2,1108,C,A,0,14.75,100,0,165650,258199535,ARL,306519741,13.26,100,1,13.75,15,1,13.04,2,1,13.76,100,1,13.03,100,1,13.79,100,1,12.73,100,1,14.07,2,1,12.71,100,1,14.08,100,1,12.5,700,1,14.28,100,1,12.46,200,2,14.4,100,1,12.43,700,1,14.56,800,2,12.42,700,1,14.6,700,1,12.37,700,1,14.64,100,1
2025-07-17T15:48:42.011680742Z,2025-07-17T15:48:42.011846392Z,160,2,1108,A,A,0,14.64,100,130,165650,258199535,ARL,308296381,13.26,100,1,13.75,15,1,13.04,2,1,13.76,100,1,13.03,100,1,13.79,100,1,12.73,100,1,14.07,2,1,12.71,100,1,14.08,100,1,12.5,700,1,14.28,100,1,12.46,200,2,14.4,100,1,12.43,700,1,14.56,800,2,12.42,700,1,14.6,700,1,12.37,700,1,14.64,200,2
2025-07-17T15:48:42.016595806Z,2025-07-17T15:48:42.016761374Z,160,2,1108,A,A,0,13.77,100,130,165568,258199787,ARL,308296741,13.26,100,1,13.75,15,1,13.04,2,1,13.76,100,1,13.03,100,1,13.77,100,1,12.73,100,1,13.79,100,1,12.71,100,1,14.07,2,1,12.5,700,1,14.08,100,1,12.46,200,2,14.28,100,1,12.43,700,1,14.4,100,1,12.42,700,1,14.56,800,2,12.37,700,1,14.6,700,1
2025-07-17T15:48:42.023266760Z,2025-07-17T15:48:42.023432407Z,160,2,1108,C,A,0,13.79,100,130,165647,258199990,ARL,307964609,13.26,100,1,13.75,15,1,13.04,2,1,13.76,100,1,13.03,100,1,13.77,100,1,12.73,100,1,14.07,2,1,12.71,100,1,14.08,100,1,12.5,700,1,14.28,100,1,12.46,200,2,14.4,100,1,12.43,700,1,14.56,800,2,12.42,700,1,14.6,700,1,12.37,700,1,14.64,200,2
2025-07-17T15:48:46.749922127Z,2025-07-17T15:48:46.750088490Z,160,2,1108,A,A,0,13.73,15,128,166363,258260871,ARL,308374537,13.26,100,1,13.73,15,1,13.04,2,1,13.75,15,1,13.03,100,1,13.76,100,1,12.73,100,1,13.77,100,1,12.71,100,1,14.07,2,1,12.5,700,1,14.08,100,1,12.46,200,2,14.28,100,1,12.43,700,1,14.4,100,1,12.42,700,1,14.56,800,2,12.37,700,1,14.6,700,1
2025-07-17T15:48:46.758385367Z,2025-07-17T15:48:46.758551033Z,160,2,1108,C,A,0,13.76,100,0,165666,258261154,ARL,307964621,13.26,100,1,13.73,15,1,13.04,2,1,13.75,15,1,13.03,100,1,13.77,100,1,12.73,100,1,14.07,2,1,12.71,100,1,14.08,100,1,12.5,700,1,14.28,100,1,12.46,200,2,14.4,100,1,12.43,700,1,14.56,800,2,12.42,700,1,14.6,700,1,12.37,700,1,14.64,200,2
2025-07-17T15:48:46.758385367Z,2025-07-17T15:48:46.758551033Z,160,2,1108,A,A,0,13.74,100,130,165666,258261154,ARL,308374881,13.26,100,1,13.73,15,1,13.04,2,1,13.74,100,1,13.03,100,1,13.75,15,1,12.73,100,1,13.77,100,1,12.71,100,1,14.07,2,1,12.5,700,1,14.08,100,1,12.46,200,2,14.28,100,1,12.43,700,1,14.4,100,1,12.42,700,1,14.56,800,2,12.37,700,1,14.6,700,1
2025-07-17T15:48:46.773503306Z,2025-07-17T15:48:46.773668988Z,160,2,1108,C,A,0,14.08,100,130,165682,258261538,ARL,306784853,13.26,100,1,13.73,15,1,13.04,2,1,13.74,100,1,13.03,100,1,13.75,15,1,12.73,100,1,13.77,100,1,12.71,100,1,14.07,2,1,12.5,700,1,14.28,100,1,12.46,200,2,14.4,100,1,12.43,700,1,14.56,800,2,12.42,700,1,14.6,700,1,12.37,700,1,14.64,200,2
2025-07-17T15:48:46.773555566Z,2025-07-17T15:48:46.773720726Z,160,2,1108,A,A,0,14.01,100,130,165160,258261539,ARL,308375185,13.26,100,1,13.73,15,1,13.04,2,1,13.74,100,1,13.03,100,1,13.75,15,1,12.73,100,1,13.77,100,1,12.71,100,1,14.01,100,1,12.5,700,1,14.07,2,1,12.46,200,2,14.28,100,1,12.43,700,1,14.4,100,1,12.42,700,1,14.56,800,2,12.37,700,1,14.6,700,1
2025-07-17T15:49:02.010329052Z,2025-07-17T15:49:02.010494480Z,160,2,1108,A,A,0,13.75,100,130,165428,258502869,ARL,308705489,13.26,100,1,13.73,15,1,13.04,2,1,13.74,100,1,13.03,100,1,13.75,115,2,12.73,100,1,13.77,100,1,12.71,100,1,14.01,100,1,12.5,700,1,14.07,2,1,12.46,200,2,14.28,100,1,12.43,700,1,14.4,100,1,12.42,700,1,14.56,800,2,12.37,700,1,14.6,700,1
2025-07-17T15:49:02.019824230Z,2025-07-17T15:49:02.019989567Z,160,2,1108,C,A,0,13.77,100,130,165337,258502929,ARL,308296741,13.26,100,1,13.73,15,1,13.04,2,1,13.74,100,1,13.03,100,1,13.75,115,2,12.73,100,1,14.01,100,1,12.71,100,1,14.07,2,1,12.5,700,1,14.28,100,1,12.46,200,2,14.4,100,1,12.43,700,1,14.56,800,2,12.42,700,1,14.6,700,1,12.37,700,1,14.64,200,2
2025-07-17T15:49:03.405840358Z,2025-07-17T15:49:03.406005590Z,160,2,1108,C,A,0,13.75,15,130,165232,258527308,ARL,307964605,13.26,100,1,13.73,15,1,13.04,2,1,13.74,100,1,13.03,100,1,13.75,100,1,12.73,100,1,14.01,100,1,12.71,100,1,14.07,2,1,12.5,700,1,14.28,100,1,12.46,200,2,14.4,100,1,12.43,700,1,14.56,800,2,12.42,700,1,14.6,700,1,12.37,700,1,14.64,200,2
2025-07-17T15:49:04.713831675Z,2025-07-17T15:49:04.713997925Z,160,2,1108,A,A,0,13.71,15,128,166250,258547335,ARL,308763065,13.26,100,1,13.71,15,1,13.04,2,1,13.73,15,1,13.03,100,1,13.74,100,1,12.73,100,1,13.75,100,1,12.71,100,1,14.01,100,1,12.5,700,1,14.07,2,1,12.46,200,2,14.28,100,1,12.43,700,1,14.4,100,1,12.42,700,1,14.56,800,2,12.37,700,1,14.6,700,1
2025-07-17T15:49:06.012946379Z,2025-07-17T15:49:06.013111941Z,160,2,1108,A,A,0,13.73,100,130,165562,258567259,ARL,308786185,13.26,100,1,13.71,15,1,13.04,2,1,13.73,115,2,13.03,100,1,13.74,100,1,12.73,100,1,13.75,100,1,12.71,100,1,14.01,100,1,12.5,700,1,14.07,2,1,12.46,200,2,14.28,100,1,12.43,700,1,14.4,100,1,12.42,700,1,14.56,800,2,12.37,700,1,14.6,700,1
2025-07-17T15:49:06.023126600Z,2025-07-17T15:49:06.023292147Z,160,2,1108,C,A,0,13.75,100,130,165547,258567405,ARL,308705489,13.26,100,1,13.71,15,1,13.04,2,1,13.73,115,2,13.03,100,1,13.74,100,1,12.73,100,1,14.01,100,1,12.71,100,1,14.07,2,1,12.5,700,1,14.28,100,1,12.46,200,2,14.4,100,1,12.43,700,1,14.56,800,2,12.42,700,1,14.6,700,1,12.37,700,1,14.64,200,2
2025-07-17T15:49:06.344191321Z,2025-07-17T15:49:06.344356890Z,160,2,1108,C,A,0,13.74,100,0,165569,258574949,ARL,308374881,13.26,100,1,13.71,15,1,13.04,2,1,13.73,115,2,13.03,100,1,14.01,100,1,12.73,100,1,14.07,2,1,12.71,100,1,14.28,100,1,12.5,700,1,14.4,100,1,12.46,200,2,14.56,800,2,12.43,700,1,14.6,700,1,12.42,700,1,14.64,200,2,12.37,700,1,14.65,100,1
2025-07-17T15:49:06.344191321Z,2025-07-17T15:49:06.344356890Z,160,2,1108,A,A,0,13.72,100,130,165569,258574949,ARL,308797069,13.26,100,1,13.71,15,1,13.04,2,1,13.72,100,1,13.03,100,1,13.73,115,2,12.73,100,1,14.01,100,1,12.71,100,1,14.07,2,1,12.5,700,1,14.28,100,1,12.46,200,2,14.4,100,1,12.43,700,1,14.56,800,2,12.42,700,1,14.6,700,1,12.37,700,1,14.64,200,2
2025-07-17T15:49:06.344938975Z,2025-07-17T15:49:06.345104491Z,160,2,1108,C,A,0,14.83,100,0,165516,258575013,ARL,307964665,13.26,100,1,13.71,15,1,13.04,2,1,13.72,100,1,13.03,100,1,13.73,115,2,12.73,100,1,14.01,100,1,12.71,100,1,14.07,2,1,12.5,700,1,14.28,100,1,12.46,200,2,14.4,100,1,12.43,700,1,14.56,800,2,12.42,700,1,14.6,700,1,12.37,700,1,14.64,200,2
2025-07-17T15:49:06.344938975Z,2025-07-17T15:49:06.345104491Z,160,2,1108,A,A,0,14.78,100,130,165516,258575013,ARL,308797245,13.26,100,1,13.71,15,1,13.04,2,1,13.72,100,1,13.03,100,1,13.73,115,2,12.73,100,1,14.01,100,1,12.71,100,1,14.07,2,1,12.5,700,1,14.28,100,1,12.46,200,2,14.4,100,1,12.43,700,1,14.56,800,2,12.42,700,1,14.6,700,1,12.37,700,1,14.64,200,2
2025-07-17T15:49:06.362779870Z,2025-07-17T15:49:06.362945410Z,160,2,1108,C,A,0,17.58,100,0,165540,258575963,ARL,306652017,13.26,100,1,13.71,15,1,13.04,2,1,13.72,100,1,13.03,100,1,13.73,115,2,12.73,100,1,14.01,100,1,12.71,100,1,14.07,2,1,12.5,700,1,14.28,100,1,12.46,200,2,14.4,100,1,12.43,700,1,14.56,800,2,12.42,700,1,14.6,700,1,12.37,700,1,14.64,200,2
2025-07-17T15:49:06.362779870Z,2025-07-17T15:49:06.362945410Z,160,2,1108,A,A,0,17.43,100,130,165540,258575963,ARL,308799373,13.26,100,1,13.71,15,1,13.04,2,1,13.72,100,1,13.03,100,1,13.73,115,2,12.73,100,1,14.01,100,1,12.71,100,1,14.07,2,1,12.5,700,1,14.28,100,1,12.46,200,2,14.4,100,1,12.43,700,1,14.56,800,2,12.42,700,1,14.6,700,1,12.37,700,1,14.64,200,2
2025-07-17T15:49:10.459152457Z,2025-07-17T15:49:10.459317885Z,160,2,1108,C,A,0,13.73,15,130,165428,258636400,ARL,308374537,13.26,100,1,13.71,15,1,13.04,2,1,13.72,100,1,13.03,100,1,13.73,100,1,12.73,100,1,14.01,100,1,12.71,100,1,14.07,2,1,12.5,700,1,14.28,100,1,12.46,200,2,14.4,100,1,12.43,700,1,14.56,800,2,12.42,700,1,14.6,700,1,12.37,700,1,14.64,200,2
2025-07-17T15:49:11.460432218Z,2025-07-17T15:49:11.460597600Z,160,2,1108,A,A,0,13.69,15,130,165382,258650544,ARL,308893737,13.26,100,1,13.69,15,1,13.04,2,1,13.71,15,1,13.03,100,1,13.72,100,1,12.73,100,1,13.73,100,1,12.71,100,1,14.01,100,1,12.5,700,1,14.07,2,1,12.46,200,2,14.28,100,1,12.43,700,1,14.4,100,1,12.42,700,1,14.56,800,2,12.37,700,1,14.6,700,1
2025-07-17T15:49:11.891477604Z,2025-07-17T15:49:11.891643099Z,160,2,1108,C,A,0,13.72,100,0,165495,258658721,ARL,308797069,13.26,100,1,13.69,15,1,13.04,2,1,13.71,15,1,13.03,100,1,13.73,100,1,12.73,100,1,14.01,100,1,12.71,100,1,14.07,2,1,12.5,700,1,14.28,100,1,12.46,200,2,14.4,100,1,12.43,700,1,14.56,800,2,12.42,700,1,14.6,700,1,12.37,700,1,14.64,200,2
2025-07-17T15:49:11.891477604Z,2025-07-17T15:49:11.891643099Z,160,2,1108,A,A,0,13.7,100,130,165495,258658721,ARL,308901793,13.26,100,1,13.69,15,1,13.04,2,1,13.7,100,1,13.03,100,1,13.71,15,1,12.73,100,1,13.73,100,1,12.71,100,1,14.01,100,1,12.5,700,1,14.07,2,1,12.46,200,2,14.28,100,1,12.43,700,1,14.4,100,1,12.42,700,1,14.56,800,2,12.37,700,1,14.6,700,1
2025-07-17T15:49:11.893823458Z,2025-07-17T15:49:11.893989071Z,160,2,1108,C,A,0,14.81,100,0,165613,258658835,ARL,306649913,13.26,100,1,13.69,15,1,13.04,2,1,13.7,100,1,13.03,100,1,13.71,15,1,12.73,100,1,13.73,100,1,12.71,100,1,14.01,100,1,12.5,700,1,14.07,2,1,12.46,200,2,14.28,100,1,12.43,700,1,14.4,100,1,12.42,700,1,14.56,800,2,12.37,700,1,14.6,700,1
2025-07-17T15:49:11.893823458Z,2025-07-17T15:49:11.893989071Z,160,2,1108,A,A,0,14.66,100,130,165613,258658835,ARL,308901981,13.26,100,1,13.69,15,1,13.04,2,1,13.7,100,1,13.03,100,1,13.71,15,1,12.73,100,1,13.73,100,1,12.71,100,1,14.01,100,1,12.5,700,1,14.07,2,1,12.46,200,2,14.28,100,1,12.43,700,1,14.4,100,1,12.42,700,1,14.56,800,2,12.37,700,1,14.6,700,1
2025-07-17T15:49:11.904065674Z,2025-07-17T15:49:11.904231149Z,160,2,1108,C,A,0,15.92,100,0,165475,258659039,ARL,306652001,13.26,100,1,13.69,15,1,13.04,2,1,13.7,100,1,13.03,100,1,13.71,15,1,12.73,100,1,13.73,100,1,12.71,100,1,14.01,100,1,12.5,700,1,14.07,2,1,12.46,200,2,14.28,100,1,12.43,700,1,14.4,100,1,12.42,700,1,14.56,800,2,12.37,700,1,14.6,700,1
2025-07-17T15:49:11.904065674Z,2025-07-17T15:49:11.904231149Z,160,2,1108,A,A,0,15.76,100,130,165475,258659039,ARL,308902229,13.26,100,1,13.69,15,1,13.04,2,1,13.7,100,1,13.03,100,1,13.71,15,1,12.73,100,1,13.73,100,1,12.71,100,1,14.01,100,1,12.5,700,1,14.07,2,1,12.46,200,2,14.28,100,1,12.43,700,1,14.4,100,1,12.42,700,1,14.56,800,2,12.37,700,1,14.6,700,1
2025-07-17T15:49:11.935356090Z,2025-07-17T15:49:11.935521687Z,160,2,1108,C,A,0,14.81,100,0,165597,258659320,ARL,306653713,13.26,100,1,13.69,15,1,13.04,2,1,13.7,100,1,13.03,100,1,13.71,15,1,12.73,100,1,13.73,100,1,12.71,100,1,14.01,100,1,12.5,700,1,14.07,2,1,12.46,200,2,14.28,100,1,12.43,700,1,14.4,100,1,12.42,700,1,14.56,800,2,12.37,700,1,14.6,700,1
2025-07-17T15:49:11.935356090Z,2025-07-17T15:49:11.935521687Z,160,2,1108,A,A,0,14.66,100,130,165597,258659320,ARL,308903001,13.26,100,1,13.69,15,1,13.04,2,1,13.7,100,1,13.03,100,1,13.71,15,1,12.73,100,1,13.73,100,1,12.71,100,1,14.01,100,1,12.5,700,1,14.07,2,1,12.46,200,2,14.28,100,1,12.43,700,1,14.4,100,1,12.42,700,1,14.56,800,2,12.37,700,1,14.6,700,1
2025-07-17T15:49:11.948535655Z,2025-07-17T15:49:11.948701049Z,160,2,1108,C,A,0,14.64,100,130,165394,258659496,ARL,306647521,13.26,100,1,13.69,15,1,13.04,2,1,13.7,100,1,13.03,100,1,13.71,15,1,12.73,100,1,13.73,100,1,12.71,100,1,14.01,100,1,12.5,700,1,14.07,2,1,12.46,200,2,14.28,100,1,12.43,700,1,14.4,100,1,12.42,700,1,14.56,800,2,12.37,700,1,14.6,700,1
2025-07-17T15:49:11.948663655Z,2025-07-17T15:49:11.948829112Z,160,2,1108,A,A,0,14.5,100,130,165457,258659499,ARL,308903349,13.26,100,1,13.69,15,1,13.04,2,1,13.7,100,1,13.03,100,1,13.71,15,1,12.73,100,1,13.73,100,1,12.71,100,1,14.01,100,1,12.5,700,1,14.07,2,1,12.46,200,2,14.28,100,1,12.43,700,1,14.4,100,1,12.42,700,1,14.5,100,1,12.37,700,1,14.56,800,2
2025-07-17T15:49:12.221056085Z,2025-07-17T15:49:12.221221367Z,160,2,1108,A,A,0,13.71,100,130,165282,258663292,ARL,308909249,13.26,100,1,13.69,15,1,13.04,2,1,13.7,100,1,13.03,100,1,13.71,115,2,12.73,100,1,13.73,100,1,12.71,100,1,14.01,100,1,12.5,700,1,14.07,2,1,12.46,200,2,14.28,100,1,12.43,700,1,14.4,100,1,12.42,700,1,14.5,100,1,12.37,700,1,14.56,800,2
2025-07-17T15:49:12.227821500Z,2025-07-17T15:49:12.227986905Z,160,2,1108,C,A,0,13.73,100,130,165405,258663378,ARL,308786185,13.26,100,1,13.69,15,1,13.04,2,1,13.7,100,1,13.03,100,1,13.71,115,2,12.73,100,1,14.01,100,1,12.71,100,1,14.07,2,1,12.5,700,1,14.28,100,1,12.46,200,2,14.4,100,1,12.43,700,1,14.5,100,1,12.42,700,1,14.56,800,2,12.37,700,1,14.6,700,1
2025-07-17T15:49:14.463063539Z,2025-07-17T15:49:14.463229121Z,160,2,1108,C,A,0,13.71,15,130,165582,258702625,ARL,308763065,13.26,100,1,13.69,15,1,13.04,2,1,13.7,100,1,13.03,100,1,13.71,100,1,12.73,100,1,14.01,100,1,12.71,100,1,14.07,2,1,12.5,700,1,14.28,100,1,12.46,200,2,14.4,100,1,12.43,700,1,14.5,100,1,12.42,700,1,14.56,800,2,12.37,700,1,14.6,700,1
2025-07-17T15:49:15.466199239Z,2025-07-17T15:49:15.466365122Z,160,2,1108,A,A,0,13.67,15,130,165883,258716863,ARL,308980305,13.26,100,1,13.67,15,1,13.04,2,1,13.69,15,1,13.03,100,1,13.7,100,1,12.73,100,1,13.71,100,1,12.71,100,1,14.01,100,1,12.5,700,1,14.07,2,1,12.46,200,2,14.28,100,1,12.43,700,1,14.4,100,1,12.42,700,1,14.5,100,1,12.37,700,1,14.56,800,2
2025-07-17T15:49:16.350859152Z,2025-07-17T15:49:16.351024588Z,160,2,1108,C,A,0,13.7,100,0,165436,258727929,ARL,308901793,13.26,100,1,13.67,15,1,13.04,2,1,13.69,15,1,13.03,100,1,13.71,100,1,12.73,100,1,14.01,100,1,12.71,100,1,14.07,2,1,12.5,700,1,14.28,100,1,12.46,200,2,14.4,100,1,12.43,700,1,14.5,100,1,12.42,700,1,14.56,800,2,12.37,700,1,14.6,700,1
2025-07-17T15:49:16.350859152Z,2025-07-17T15:49:16.351024588Z,160,2,1108,A,A,0,13.68,100,130,165436,258727929,ARL,308998225,13.26,100,1,13.67,15,1,13.04,2,1,13.68,100,1,13.03,100,1,13.69,15,1,12.73,100,1,13.71,100,1,12.71,100,1,14.01,100,1,12.5,700,1,14.07,2,1,12.46,200,2,14.28,100,1,12.43,700,1,14.4,100,1,12.42,700,1,14.5,100,1,12.37,700,1,14.56,800,2
2025-07-17T15:49:16.351594042Z,2025-07-17T15:49:16.351759618Z,160,2,1108,C,A,0,14.78,100,0,165576,258727956,ARL,308797245,13.26,100,1,13.67,15,1,13.04,2,1,13.68,100,1,13.03,100,1,13.69,15,1,12.73,100,1,13.71,100,1,12.71,100,1,14.01,100,1,12.5,700,1,14.07,2,1,12.46,200,2,14.28,100,1,12.43,700,1,14.4,100,1,12.42,700,1,14.5,100,1,12.37,700,1,14.56,800,2
2025-07-17T15:49:16.351594042Z,2025-07-17T15:49:16.351759618Z,160,2,1108,A,A,0,14.74,100,130,165576,258727956,ARL,308998341,13.26,100,1,13.67,15,1,13.04,2,1,13.68,100,1,13.03,100,1,13.69,15,1,12.73,100,1,13.71,100,1,12.71,100,1,14.01,100,1,12.5,700,1,14.07,2,1,12.46,200,2,14.28,100,1,12.43,700,1,14.4,100,1,12.42,700,1,14.5,100,1,12.37,700,1,14.56,800,2
2025-07-17T15:49:16.493946243Z,2025-07-17T15:49:16.494111490Z,160,2,1108,A,A,0,13.69,100,130,165247,258729266,ARL,309001525,13.26,100,1,13.67,15,1,13.04,2,1,13.68,100,1,13.03,100,1,13.69,115,2,12.73,100,1,13.71,100,1,12.71,100,1,14.01,100,1,12.5,700,1,14.07,2,1,12.46,200,2,14.28,100,1,12.43,700,1,14.4,100,1,12.42,700,1,14.5,100,1,12.37,700,1,14.56,800,2
2025-07-17T15:49:16.557759633Z,2025-07-17T15:49:16.557924863Z,160,2,1108,C,A,0,13.71,100,130,165230,258730034,ARL,308909249,13.26,100,1,13.67,15,1,13.04,2,1,13.68,100,1,13.03,100,1,13.69,115,2,12.73,100,1,14.01,100,1,12.71,100,1,14.07,2,1,12.5,700,1,14.28,100,1,12.46,200,2,14.4,100,1,12.43,700,1,14.5,100,1,12.42,700,1,14.56,800,2,12.37,700,1,14.6,700,1
2025-07-17T15:49:21.185984774Z,2025-07-17T15:49:21.186150487Z,160,2,1108,C,A,0,14.07,2,0,165713,258786552,ARL,296478973,13.26,100,1,13.67,15,1,13.04,2,1,13.68,100,1,13.03,100,1,13.69,115,2,12.73,100,1,14.01,100,1,12.71,100,1,14.28,100,1,12.5,700,1,14.4,100,1,12.46,200,2,14.5,100,1,12.43,700,1,14.56,800,2,12.42,700,1,14.6,700,1,12.37,700,1,14.64,100,1
2025-07-17T15:49:21.185984774Z,2025-07-17T15:49:21.186150487Z,160,2,1108,A,A,0,13.98,2,130,165713,258786552,ARL,309091513,13.26,100,1,13.67,15,1,13.04,2,1,13.68,100,1,13.03,100,1,13.69,115,2,12.73,100,1,13.98,2,1,12.71,100,1,14.01,100,1,12.5,700,1,14.28,100,1,12.46,200,2,14.4,100,1,12.43,700,1,14.5,100,1,12.42,700,1,14.56,800,2,12.37,700,1,14.6,700,1
2025-07-17T15:49:24.282985894Z,2025-07-17T15:49:24.283152112Z,160,2,1108,C,A,0,13.69,15,130,166218,258838460,ARL,308893737,13.26,100,1,13.67,15,1,13.04,2,1,13.68,100,1,13.03,100,1,13.69,100,1,12.73,100,1,13.98,2,1,12.71,100,1,14.01,100,1,12.5,700,1,14.28,100,1,12.46,200,2,14.4,100,1,12.43,700,1,14.5,100,1,12.42,700,1,14.56,800,2,12.37,700,1,14.6,700,1
2025-07-17T15:49:34.570031718Z,2025-07-17T15:49:34.570197134Z,160,2,1108,C,A,0,13.67,15,130,165416,258980876,ARL,308980305,13.26,100,1,13.68,100,1,13.04,2,1,13.69,100,1,13.03,100,1,13.98,2,1,12.73,100,1,14.01,100,1,12.71,100,1,14.28,100,1,12.5,700,1,14.4,100,1,12.46,200,2,14.5,100,1,12.43,700,1,14.56,800,2,12.42,700,1,14.6,700,1,12.37,700,1,14.64,100,1
2025-07-17T15:49:34.591347169Z,2025-07-17T15:49:34.591512915Z,160,2,1108,C,A,0,13.69,100,130,165746,258983321,ARL,309001525,13.26,100,1,13.68,100,1,13.04,2,1,13.98,2,1,13.03,100,1,14.01,100,1,12.73,100,1,14.28,100,1,12.71,100,1,14.4,100,1,12.5,700,1,14.5,100,1,12.46,200,2,14.56,800,2,12.43,700,1,14.6,700,1,12.42,700,1,14.64,100,1,12.37,700,1,14.65,100,1
2025-07-17T15:49:38.609851985Z,2025-07-17T15:49:38.610017394Z,160,2,1108,A,A,0,13.72,100,130,165409,259031220,ARL,309410565,13.26,100,1,13.68,100,1,13.04,2,1,13.72,100,1,13.03,100,1,13.98,2,1,12.73,100,1,14.01,100,1,12.71,100,1,14.28,100,1,12.5,700,1,14.4,100,1,12.46,200,2,14.5,100,1,12.43,700,1,14.56,800,2,12.42,700,1,14.6,700,1,12.37,700,1,14.64,100,1
2025-07-17T15:49:38.609907720Z,2025-07-17T15:49:38.610073334Z,160,2,1108,C,B,0,13.26,100,130,165614,259031221,ARL,291975017,13.04,2,1,13.68,100,1,13.03,100,1,13.72,100,1,12.73,100,1,13.98,2,1,12.71,100,1,14.01,100,1,12.5,700,1,14.28,100,1,12.46,200,2,14.4,100,1,12.43,700,1,14.5,100,1,12.42,700,1,14.56,800,2,12.37,700,1,14.6,700,1,12.36,200,2,14.64,100,1
2025-07-17T15:49:39.068349660Z,2025-07-17T15:49:39.068515005Z,160,2,1108,A,B,0,13.02,100,130,165345,259035032,ARL,309415429,13.04,2,1,13.68,100,1,13.03,100,1,13.72,100,1,13.02,100,1,13.98,2,1,12.73,100,1,14.01,100,1,12.71,100,1,14.28,100,1,12.5,700,1,14.4,100,1,12.46,200,2,14.5,100,1,12.43,700,1,14.56,800,2,12.42,700,1,14.6,700,1,12.37,700,1,14.64,100,1
2025-07-17T15:49:44.788249210Z,2025-07-17T15:49:44.788414401Z,160,2,1108,A,A,0,13.67,15,130,165191,259105347,ARL,309524921,13.04,2,1,13.67,15,1,13.03,100,1,13.68,100,1,13.02,100,1,13.72,100,1,12.73,100,1,13.98,2,1,12.71,100,1,14.01,100,1,12.5,700,1,14.28,100,1,12.46,200,2,14.4,100,1,12.43,700,1,14.5,100,1,12.42,700,1,14.56,800,2,12.37,700,1,14.6,700,1
2025-07-17T15:49:44.788855587Z,2025-07-17T15:49:44.789020757Z,160,2,1108,A,A,0,13.7,100,130,165170,259105361,ARL,309524933,13.04,2,1,13.67,15,1,13.03,100,1,13.68,100,1,13.02,100,1,13.7,100,1,12.73,100,1,13.72,100,1,12.71,100,1,13.98,2,1,12.5,700,1,14.01,100,1,12.46,200,2,14.28,100,1,12.43,700,1,14.4,100,1,12.42,700,1,14.5,100,1,12.37,700,1,14.56,800,2
2025-07-17T15:49:44.789537536Z,2025-07-17T15:49:44.789702916Z,160,2,1108,C,A,0,13.72,100,130,165380,259105380,ARL,309410565,13.04,2,1,13.67,15,1,13.03,100,1,13.68,100,1,13.02,100,1,13.7,100,1,12.73,100,1,13.98,2,1,12.71,100,1,14.01,100,1,12.5,700,1,14.28,100,1,12.46,200,2,14.4,100,1,12.43,700,1,14.5,100,1,12.42,700,1,14.56,800,2,12.37,700,1,14.6,700,1
2025-07-17T15:49:54.788493605Z,2025-07-17T15:49:54.788658841Z,160,2,1108,A,A,0,13.65,15,130,165236,259253294,ARL,309707269,13.04,2,1,13.65,15,1,13.03,100,1,13.67,15,1,13.02,100,1,13.68,100,1,12.73,100,1,13.7,100,1,12.71,100,1,13.98,2,1,12.5,700,1,14.01,100,1,12.46,200,2,14.28,100,1,12.43,700,1,14.4,100,1,12.42,700,1,14.5,100,1,12.37,700,1,14.56,800,2
2025-07-17T15:49:54.799370442Z,2025-07-17T15:49:54.799535744Z,160,2,1108,A,A,0,13.68,100,130,165302,259253527,ARL,309707413,13.04,2,1,13.65,15,1,13.03,100,1,13.67,15,1,13.02,100,1,13.68,200,2,12.73,100,1,13.7,100,1,12.71,100,1,13.98,2,1,12.5,700,1,14.01,100,1,12.46,200,2,14.28,100,1,12.43,700,1,14.4,100,1,12.42,700,1,14.5,100,1,12.37,700,1,14.56,800,2
2025-07-17T15:49:54.820469390Z,2025-07-17T15:49:54.820634917Z,160,2,1108,C,A,0,13.7,100,130,165527,259253732,ARL,309524933,13.04,2,1,13.65,15,1,13.03,100,1,13.67,15,1,13.02,100,1,13.68,200,2,12.73,100,1,13.98,2,1,12.71,100,1,14.01,100,1,12.5,700,1,14.28,100,1,12.46,200,2,14.4,100,1,12.43,700,1,14.5,100,1,12.42,700,1,14.56,800,2,12.37,700,1,14.6,700,1
2025-07-17T15:49:59.511938438Z,2025-07-17T15:49:59.512104064Z,160,2,1108,C,A,0,13.68,100,0,165626,259313537,ARL,308998225,13.04,2,1,13.65,15,1,13.03,100,1,13.67,15,1,13.02,100,1,13.68,100,1,12.73,100,1,13.98,2,1,12.71,100,1,14.01,100,1,12.5,700,1,14.28,100,1,12.46,200,2,14.4,100,1,12.43,700,1,14.5,100,1,12.42,700,1,14.56,800,2,12.37,700,1,14.6,700,1
2025-07-17T15:49:59.511938438Z,2025-07-17T15:49:59.512104064Z,160,2,1108,A,A,0,13.66,100,130,165626,259313537,ARL,309782481,13.04,2,1,13.65,15,1,13.03,100,1,13.66,100,1,13.02,100,1,13.67,15,1,12.73,100,1,13.68,100,1,12.71,100,1,13.98,2,1,12.5,700,1,14.01,100,1,12.46,200,2,14.28,100,1,12.43,700,1,14.4,100,1,12.42,700,1,14.5,100,1,12.37,700,1,14.56,800,2
2025-07-17T15:49:59.533897369Z,2025-07-17T15:49:59.534062634Z,160,2,1108,C,A,0,14.01,100,130,165265,259314032,ARL,308375185,13.04,2,1,13.65,15,1,13.03,100,1,13.66,100,1,13.02,100,1,13.67,15,1,12.73,100,1,13.68,100,1,12.71,100,1,13.98,2,1,12.5,700,1,14.28,100,1,12.46,200,2,14.4,100,1,12.43,700,1,14.5,100,1,12.42,700,1,14.56,800,2,12.37,700,1,14.6,700,1
2025-07-17T15:49:59.533948952Z,2025-07-17T15:49:59.534115275Z,160,2,1108,A,A,0,13.93,100,130,166323,259314033,ARL,309782973,13.04,2,1,13.65,15,1,13.03,100,1,13.66,100,1,13.02,100,1,13.67,15,1,12.73,100,1,13.68,100,1,12.71,100,1,13.93,100,1,12.5,700,1,13.98,2,1,12.46,200,2,14.28,100,1,12.43,700,1,14.4,100,1,12.42,700,1,14.5,100,1,12.37,700,1,14.56,800,2
2025-07-17T15:50:00.547239401Z,2025-07-17T15:50:00.547404972Z,160,2,1108,C,A,0,13.67,15,130,165571,259349868,ARL,309524921,13.04,2,1,13.65,15,1,13.03,100,1,13.66,100,1,13.02,100,1,13.68,100,1,12.73,100,1,13.93,100,1,12.71,100,1,13.98,2,1,12.5,700,1,14.28,100,1,12.46,200,2,14.4,100,1,12.43,700,1,14.5,100,1,12.42,700,1,14.56,800,2,12.37,700,1,14.6,700,1
2025-07-17T15:50:00.555363249Z,2025-07-17T15:50:00.555536688Z,160,2,1108,C,A,0,14.65,100,0,173439,259353226,ARL,307964661,13.04,2,1,13.65,15,1,13.03,100,1,13.66,100,1,13.02,100,1,13.68,100,1,12.73,100,1,13.93,100,1,12.71,100,1,13.98,2,1,12.5,700,1,14.28,100,1,12.46,200,2,14.4,100,1,12.43,700,1,14.5,100,1,12.42,700,1,14.56,800,2,12.37,700,1,14.6,700,1
2025-07-17T15:50:00.555363249Z,2025-07-17T15:50:00.555536688Z,160,2,1108,A,A,0,14.54,100,128,173439,259353226,ARL,309823025,13.04,2,1,13.65,15,1,13.03,100,1,13.66,100,1,13.02,100,1,13.68,100,1,12.73,100,1,13.93,100,1,12.71,100,1,13.98,2,1,12.5,700,1,14.28,100,1,12.46,200,2,14.4,100,1,12.43,700,1,14.5,100,1,12.42,700,1,14.54,100,1,12.37,700,1,14.56,800,2
2025-07-17T15:50:03.412257475Z,2025-07-17T15:50:03.412422880Z,160,2,1108,A,A,0,13.63,15,130,165405,259413272,ARL,309899025,13.04,2,1,13.63,15,1,13.03,100,1,13.65,15,1,13.02,100,1,13.66,100,1,12.73,100,1,13.68,100,1,12.71,100,1,13.93,100,1,12.5,700,1,13.98,2,1,12.46,200,2,14.28,100,1,12.43,700,1,14.4,100,1,12.42,700,1,14.5,100,1,12.37,700,1,14.54,100,1
2025-07-17T15:50:03.415361851Z,2025-07-17T15:50:03.415527372Z,160,2,1108,C,A,0,14.64,100,0,165521,259413427,ARL,308296381,13.04,2,1,13.63,15,1,13.03,100,1,13.65,15,1,13.02,100,1,13.66,100,1,12.73,100,1,13.68,100,1,12.71,100,1,13.93,100,1,12.5,700,1,13.98,2,1,12.46,200,2,14.28,100,1,12.43,700,1,14.4,100,1,12.42,700,1,14.5,100,1,12.37,700,1,14.54,100,1
2025-07-17T15:50:03.415361851Z,2025-07-17T15:50:03.415527372Z,160,2,1108,A,A,0,14.53,100,130,165521,259413427,ARL,309899141,13.04,2,1,13.63,15,1,13.03,100,1,13.65,15,1,13.02,100,1,13.66,100,1,12.73,100,1,13.68,100,1,12.71,100,1,13.93,100,1,12.5,700,1,13.98,2,1,12.46,200,2,14.28,100,1,12.43,700,1,14.4,100,1,12.42,700,1,14.5,100,1,12.37,700,1,14.53,100,1
2025-07-17T15:50:03.824126753Z,2025-07-17T15:50:03.824292152Z,160,2,1108,C,A,0,13.66,100,0,165399,259418661,ARL,309782481,13.04,2,1,13.63,15,1,13.03,100,1,13.65,15,1,13.02,100,1,13.68,100,1,12.73,100,1,13.93,100,1,12.71,100,1,13.98,2,1,12.5,700,1,14.28,100,1,12.46,200,2,14.4,100,1,12.43,700,1,14.5,100,1,12.42,700,1,14.53,100,1,12.37,700,1,14.54,100,1
2025-07-17T15:50:03.824126753Z,2025-07-17T15:50:03.824292152Z,160,2,1108,A,A,0,13.64,100,130,165399,259418661,ARL,309903973,13.04,2,1,13.63,15,1,13.03,100,1,13.64,100,1,13.02,100,1,13.65,15,1,12.73,100,1,13.68,100,1,12.71,100,1,13.93,100,1,12.5,700,1,13.98,2,1,12.46,200,2,14.28,100,1,12.43,700,1,14.4,100,1,12.42,700,1,14.5,100,1,12.37,700,1,14.53,100,1
2025-07-17T15:50:03.824863026Z,2025-07-17T15:50:03.825028460Z,160,2,1108,C,A,0,14.74,100,0,165434,259418664,ARL,308998341,13.04,2,1,13.63,15,1,13.03,100,1,13.64,100,1,13.02,100,1,13.65,15,1,12.73,100,1,13.68,100,1,12.71,100,1,13.93,100,1,12.5,700,1,13.98,2,1,12.46,200,2,14.28,100,1,12.43,700,1,14.4,100,1,12.42,700,1,14.5,100,1,12.37,700,1,14.53,100,1
2025-07-17T15:50:03.824863026Z,2025-07-17T15:50:03.825028460Z,160,2,1108,A,A,0,14.7,100,130,165434,259418664,ARL,309903993,13.04,2,1,13.63,15,1,13.03,100,1,13.64,100,1,13.02,100,1,13.65,15,1,12.73,100,1,13.68,100,1,12.71,100,1,13.93,100,1,12.5,700,1,13.98,2,1,12.46,200,2,14.28,100,1,12.43,700,1,14.4,100,1,12.42,700,1,14.5,100,1,12.37,700,1,14.53,100,1
2025-07-17T15:50:04.484733438Z,2025-07-17T15:50:04.484898759Z,160,2,1108,A,A,0,13.66,100,130,165321,259433904,ARL,309922345,13.04,2,1,13.63,15,1,13.03,100,1,13.64,100,1,13.02,100,1,13.65,15,1,12.73,100,1,13.66,100,1,12.71,100,1,13.68,100,1,12.5,700,1,13.93,100,1,12.46,200,2,13.98,2,1,12.43,700,1,14.28,100,1,12.42,700,1,14.4,100,1,12.37,700,1,14.5,100,1
2025-07-17T15:50:04.524563568Z,2025-07-17T15:50:04.524729039Z,160,2,1108,C,A,0,13.68,100,130,165471,259434652,ARL,309707413,13.04,2,1,13.63,15,1,13.03,100,1,13.64,100,1,13.02,100,1,13.65,15,1,12.73,100,1,13.66,100,1,12.71,100,1,13.93,100,1,12.5,700,1,13.98,2,1,12.46,200,2,14.28,100,1,12.43,700,1,14.4,100,1,12.42,700,1,14.5,100,1,12.37,700,1,14.53,100,1
2025-07-17T15:50:06.787661846Z,2025-07-17T15:50:06.787826975Z,160,2,1108,C,A,0,13.63,15,130,165129,259472951,ARL,309899025,13.04,2,1,13.64,100,1,13.03,100,1,13.65,15,1,13.02,100,1,13.66,100,1,12.73,100,1,13.93,100,1,12.71,100,1,13.98,2,1,12.5,700,1,14.28,100,1,12.46,200,2,14.4,100,1,12.43,700,1,14.5,100,1,12.42,700,1,14.53,100,1,12.37,700,1,14.54,100,1
2025-07-17T15:50:09.185334126Z,2025-07-17T15:50:09.185499367Z,160,2,1108,A,A,0,13.61,15,130,165241,259516855,ARL,310030465,13.04,2,1,13.61,15,1,13.03,100,1,13.64,100,1,13.02,100,1,13.65,15,1,12.73,100,1,13.66,100,1,12.71,100,1,13.93,100,1,12.5,700,1,13.98,2,1,12.46,200,2,14.28,100,1,12.43,700,1,14.4,100,1,12.42,700,1,14.5,100,1,12.37,700,1,14.53,100,1
2025-07-17T15:50:09.198311198Z,2025-07-17T15:50:09.198476437Z,160,2,1108,A,A,0,13.64,100,130,165239,259517754,ARL,310031625,13.04,2,1,13.61,15,1,13.03,100,1,13.64,200,2,13.02,100,1,13.65,15,1,12.73,100,1,13.66,100,1,12.71,100,1,13.93,100,1,12.5,700,1,13.98,2,1,12.46,200,2,14.28,100,1,12.43,700,1,14.4,100,1,12.42,700,1,14.5,100,1,12.37,700,1,14.53,100,1
2025-07-17T15:50:09.205322092Z,2025-07-17T15:50:09.205487416Z,160,2,1108,C,A,0,13.66,100,130,165324,259517973,ARL,309922345,13.04,2,1,13.61,15,1,13.03,100,1,13.64,200,2,13.02,100,1,13.65,15,1,12.73,100,1,13.93,100,1,12.71,100,1,13.98,2,1,12.5,700,1,14.28,100,1,12.46,200,2,14.4,100,1,12.43,700,1,14.5,100,1,12.42,700,1,14.53,100,1,12.37,700,1,14.54,100,1
2025-07-17T15:50:09.330572653Z,2025-07-17T15:50:09.330738153Z,160,2,1108,C,A,0,13.64,100,0,165500,259522708,ARL,309903973,13.04,2,1,13.61,15,1,13.03,100,1,13.64,100,1,13.02,100,1,13.65,15,1,12.73,100,1,13.93,100,1,12.71,100,1,13.98,2,1,12.5,700,1,14.28,100,1,12.46,200,2,14.4,100,1,12.43,700,1,14.5,100,1,12.42,700,1,14.53,100,1,12.37,700,1,14.54,100,1
2025-07-17T15:50:09.330572653Z,2025-07-17T15:50:09.330738153Z,160,2,1108,A,A,0,13.62,100,130,165500,259522708,ARL,310037965,13.04,2,1,13.61,15,1,13.03,100,1,13.62,100,1,13.02,100,1,13.64,100,1,12.73,100,1,13.65,15,1,12.71,100,1,13.93,100,1,12.5,700,1,13.98,2,1,12.46,200,2,14.28,100,1,12.43,700,1,14.4,100,1,12.42,700,1,14.5,100,1,12.37,700,1,14.53,100,1
2025-07-17T15:50:20.204373858Z,2025-07-17T15:50:20.204539185Z,160,2,1108,C,A,0,13.65,15,130,165327,259737768,ARL,309707269,13.04,2,1,13.61,15,1,13.03,100,1,13.62,100,1,13.02,100,1,13.64,100,1,12.73,100,1,13.93,100,1,12.71,100,1,13.98,2,1,12.5,700,1,14.28,100,1,12.46,200,2,14.4,100,1,12.43,700,1,14.5,100,1,12.42,700,1,14.53,100,1,12.37,700,1,14.54,100,1
2025-07-17T15:50:25.935412900Z,2025-07-17T15:50:25.935579034Z,160,2,1108,A,A,0,13.59,15,128,166134,259828644,ARL,310424077,13.04,2,1,13.59,15,1,13.03,100,1,13.61,15,1,13.02,100,1,13.62,100,1,12.73,100,1,13.64,100,1,12.71,100,1,13.93,100,1,12.5,700,1,13.98,2,1,12.46,200,2,14.28,100,1,12.43,700,1,14.4,100,1,12.42,700,1,14.5,100,1,12.37,700,1,14.53,100,1
2025-07-17T15:50:26.954662143Z,2025-07-17T15:50:26.954828150Z,160,2,1108,C,A,0,13.62,100,0,166007,259847181,ARL,310037965,13.04,2,1,13.59,15,1,13.03,100,1,13.61,15,1,13.02,100,1,13.64,100,1,12.73,100,1,13.93,100,1,12.71,100,1,13.98,2,1,12.5,700,1,14.28,100,1,12.46,200,2,14.4,100,1,12.43,700,1,14.5,100,1,12.42,700,1,14.53,100,1,12.37,700,1,14.54,100,1
2025-07-17T15:50:26.954662143Z,2025-07-17T15:50:26.954828150Z,160,2,1108,A,A,0,13.6,100,130,166007,259847181,ARL,310446249,13.04,2,1,13.59,15,1,13.03,100,1,13.6,100,1,13.02,100,1,13.61,15,1,12.73,100,1,13.64,100,1,12.71,100,1,13.93,100,1,12.5,700,1,13.98,2,1,12.46,200,2,14.28,100,1,12.43,700,1,14.4,100,1,12.42,700,1,14.5,100,1,12.37,700,1,14.53,100,1
2025-07-17T15:50:26.955400327Z,2025-07-17T15:50:26.955565904Z,160,2,1108,C,A,0,14.7,100,0,165577,259847190,ARL,309903993,13.04,2,1,13.59,15,1,13.03,100,1,13.6,100,1,13.02,100,1,13.61,15,1,12.73,100,1,13.64,100,1,12.71,100,1,13.93,100,1,12.5,700,1,13.98,2,1,12.46,200,2,14.28,100,1,12.43,700,1,14.4,100,1,12.42,700,1,14.5,100,1,12.37,700,1,14.53,100,1
2025-07-17T15:50:26.955400327Z,2025-07-17T15:50:26.955565904Z,160,2,1108,A,A,0,14.65,100,130,165577,259847190,ARL,310446269,13.04,2,1,13.59,15,1,13.03,100,1,13.6,100,1,13.02,100,1,13.61,15,1,12.73,100,1,13.64,100,1,12.71,100,1,13.93,100,1,12.5,700,1,13.98,2,1,12.46,200,2,14.28,100,1,12.43,700,1,14.4,100,1,12.42,700,1,14.5,100,1,12.37,700,1,14.53,100,1
2025-07-17T15:50:26.956094101Z,2025-07-17T15:50:26.956259508Z,160,2,1108,C,A,0,17.43,100,0,165407,259847199,ARL,308799373,13.04,2,1,13.59,15,1,13.03,100,1,13.6,100,1,13.02,100,1,13.61,15,1,12.73,100,1,13.64,100,1,12.71,100,1,13.93,100,1,12.5,700,1,13.98,2,1,12.46,200,2,14.28,100,1,12.43,700,1,14.4,100,1,12.42,700,1,14.5,100,1,12.37,700,1,14.53,100,1
2025-07-17T15:50:26.956094101Z,2025-07-17T15:50:26.956259508Z,160,2,1108,A,A,0,17.28,100,130,165407,259847199,ARL,310446293,13.04,2,1,13.59,15,1,13.03,100,1,13.6,100,1,13.02,100,1,13.61,15,1,12.73,100,1,13.64,100,1,12.71,100,1,13.93,100,1,12.5,700,1,13.98,2,1,12.46,200,2,14.28,100,1,12.43,700,1,14.4,100,1,12.42,700,1,14.5,100,1,12.37,700,1,14.53,100,1
2025-07-17T15:50:26.982879448Z,2025-07-17T15:50:26.983044736Z,160,2,1108,A,A,0,15.51,100,130,165288,259847556,ARL,310447441,13.04,2,1,13.59,15,1,13.03,100,1,13.6,100,1,13.02,100,1,13.61,15,1,12.73,100,1,13.64,100,1,12.71,100,1,13.93,100,1,12.5,700,1,13.98,2,1,12.46,200,2,14.28,100,1,12.43,700,1,14.4,100,1,12.42,700,1,14.5,100,1,12.37,700,1,14.53,100,1
2025-07-17T15:50:26.982892468Z,2025-07-17T15:50:26.983057675Z,160,2,1108,C,A,0,15.78,100,130,165207,259847557,ARL,282776733,13.04,2,1,13.59,15,1,13.03,100,1,13.6,100,1,13.02,100,1,13.61,15,1,12.73,100,1,13.64,100,1,12.71,100,1,13.93,100,1,12.5,700,1,13.98,2,1,12.46,200,2,14.28,100,1,12.43,700,1,14.4,100,1,12.42,700,1,14.5,100,1,12.37,700,1,14.53,100,1
2025-07-17T15:50:30.046714265Z,2025-07-17T15:50:30.046879569Z,160,2,1108,C,A,0,13.59,15,130,165304,259916670,ARL,310424077,13.04,2,1,13.6,100,1,13.03,100,1,13.61,15,1,13.02,100,1,13.64,100,1,12.73,100,1,13.93,100,1,12.71,100,1,13.98,2,1,12.5,700,1,14.28,100,1,12.46,200,2,14.4,100,1,12.43,700,1,14.5,100,1,12.42,700,1,14.53,100,1,12.37,700,1,14.54,100,1
2025-07-17T15:50:30.046849726Z,2025-07-17T15:50:30.047015114Z,160,2,1108,C,A,0,13.61,15,130,165388,259916674,ARL,310030465,13.04,2,1,13.6,100,1,13.03,100,1,13.64,100,1,13.02,100,1,13.93,100,1,12.73,100,1,13.98,2,1,12.71,100,1,14.28,100,1,12.5,700,1,14.4,100,1,12.46,200,2,14.5,100,1,12.43,700,1,14.53,100,1,12.42,700,1,14.54,100,1,12.37,700,1,14.56,800,2
2025-07-17T15:51:37.985992174Z,2025-07-17T15:51:37.986158330Z,160,2,1108,C,A,0,13.98,2,0,166156,261130345,ARL,309091513,13.04,2,1,13.6,100,1,13.03,100,1,13.64,100,1,13.02,100,1,13.93,100,1,12.73,100,1,14.28,100,1,12.71,100,1,14.4,100,1,12.5,700,1,14.5,100,1,12.46,200,2,14.53,100,1,12.43,700,1,14.54,100,1,12.42,700,1,14.56,800,2,12.37,700,1,14.6,700,1
2025-07-17T15:51:37.985992174Z,2025-07-17T15:51:37.986158330Z,160,2,1108,A,A,0,13.89,2,130,166156,261130345,ARL,311979125,13.04,2,1,13.6,100,1,13.03,100,1,13.64,100,1,13.02,100,1,13.89,2,1,12.73,100,1,13.93,100,1,12.71,100,1,14.28,100,1,12.5,700,1,14.4,100,1,12.46,200,2,14.5,100,1,12.43,700,1,14.53,100,1,12.42,700,1,14.54,100,1,12.37,700,1,14.56,800,2
2025-07-17T15:52:16.372269170Z,2025-07-17T15:52:16.372434625Z,160,2,1108,C,A,0,13.6,100,130,165455,261713790,ARL,310446249,13.04,2,1,13.64,100,1,13.03,100,1,13.89,2,1,13.02,100,1,13.93,100,1,12.73,100,1,14.28,100,1,12.71,100,1,14.4,100,1,12.5,700,1,14.5,100,1,12.46,200,2,14.53,100,1,12.43,700,1,14.54,100,1,12.42,700,1,14.56,800,2,12.37,700,1,14.6,700,1
2025-07-17T15:52:16.373023186Z,2025-07-17T15:52:16.373188791Z,160,2,1108,C,A,0,14.65,100,0,165605,261713830,ARL,310446269,13.04,2,1,13.64,100,1,13.03,100,1,13.89,2,1,13.02,100,1,13.93,100,1,12.73,100,1,14.28,100,1,12.71,100,1,14.4,100,1,12.5,700,1,14.5,100,1,12.46,200,2,14.53,100,1,12.43,700,1,14.54,100,1,12.42,700,1,14.56,800,2,12.37,700,1,14.6,700,1
2025-07-17T15:52:16.373023186Z,2025-07-17T15:52:16.373188791Z,160,2,1108,A,A,0,14.7,100,130,165605,261713830,ARL,312771573,13.04,2,1,13.64,100,1,13.03,100,1,13.89,2,1,13.02,100,1,13.93,100,1,12.73,100,1,14.28,100,1,12.71,100,1,14.4,100,1,12.5,700,1,14.5,100,1,12.46,200,2,14.53,100,1,12.43,700,1,14.54,100,1,12.42,700,1,14.56,800,2,12.37,700,1,14.6,700,1
2025-07-17T15:52:16.374186508Z,2025-07-17T15:52:16.374353159Z,160,2,1108,C,A,0,13.64,100,130,166651,261713870,ARL,310031625,13.04,2,1,13.89,2,1,13.03,100,1,13.93,100,1,13.02,100,1,14.28,100,1,12.73,100,1,14.4,100,1,12.71,100,1,14.5,100,1,12.5,700,1,14.53,100,1,12.46,200,2,14.54,100,1,12.43,700,1,14.56,800,2,12.42,700,1,14.6,700,1,12.37,700,1,14.66,200,2
2025-07-17T15:52:16.374312976Z,2025-07-17T15:52:16.374480183Z,160,2,1108,A,A,0,15.86,100,128,167207,261713880,ARL,312771645,13.04,2,1,13.89,2,1,13.03,100,1,13.93,100,1,13.02,100,1,14.28,100,1,12.73,100,1,14.4,100,1,12.71,100,1,14.5,100,1,12.5,700,1,14.53,100,1,12.46,200,2,14.54,100,1,12.43,700,1,14.56,800,2,12.42,700,1,14.6,700,1,12.37,700,1,14.66,200,2
2025-07-17T15:52:16.374327668Z,2025-07-17T15:52:16.374493650Z,160,2,1108,C,A,0,15.51,100,130,165982,261713884,ARL,310447441,13.04,2,1,13.89,2,1,13.03,100,1,13.93,100,1,13.02,100,1,14.28,100,1,12.73,100,1,14.4,100,1,12.71,100,1,14.5,100,1,12.5,700,1,14.53,100,1,12.46,200,2,14.54,100,1,12.43,700,1,14.56,800,2,12.42,700,1,14.6,700,1,12.37,700,1,14.66,200,2
2025-07-17T15:52:16.375222836Z,2025-07-17T15:52:16.375388285Z,160,2,1108,C,A,0,14.54,100,0,165449,261713944,ARL,309823025,13.04,2,1,13.89,2,1,13.03,100,1,13.93,100,1,13.02,100,1,14.28,100,1,12.73,100,1,14.4,100,1,12.71,100,1,14.5,100,1,12.5,700,1,14.53,100,1,12.46,200,2,14.56,800,2,12.43,700,1,14.6,700,1,12.42,700,1,14.66,200,2,12.37,700,1,14.68,1400,2
2025-07-17T15:52:16.375222836Z,2025-07-17T15:52:16.375388285Z,160,2,1108,A,A,0,14.81,100,130,165449,261713944,ARL,312771781,13.04,2,1,13.89,2,1,13.03,100,1,13.93,100,1,13.02,100,1,14.28,100,1,12.73,100,1,14.4,100,1,12.71,100,1,14.5,100,1,12.5,700,1,14.53,100,1,12.46,200,2,14.56,800,2,12.43,700,1,14.6,700,1,12.42,700,1,14.66,200,2,12.37,700,1,14.68,1400,2
2025-07-17T15:52:16.375248654Z,2025-07-17T15:52:16.375414247Z,160,2,1108,C,A,0,14.66,100,0,165593,261713945,ARL,308901981,13.04,2,1,13.89,2,1,13.03,100,1,13.93,100,1,13.02,100,1,14.28,100,1,12.73,100,1,14.4,100,1,12.71,100,1,14.5,100,1,12.5,700,1,14.53,100,1,12.46,200,2,14.56,800,2,12.43,700,1,14.6,700,1,12.42,700,1,14.66,100,1,12.37,700,1,14.68,1400,2
2025-07-17T15:52:16.375248654Z,2025-07-17T15:52:16.375414247Z,160,2,1108,A,A,0,14.89,100,130,165593,261713945,ARL,312771785,13.04,2,1,13.89,2,1,13.03,100,1,13.93,100,1,13.02,100,1,14.28,100,1,12.73,100,1,14.4,100,1,12.71,100,1,14.5,100,1,12.5,700,1,14.53,100,1,12.46,200,2,14.56,800,2,12.43,700,1,14.6,700,1,12.42,700,1,14.66,100,1,12.37,700,1,14.68,1400,2
2025-07-17T15:52:16.375662552Z,2025-07-17T15:52:16.375828154Z,160,2,1108,C,A,0,14.53,100,0,165602,261713959,ARL,309899141,13.04,2,1,13.89,2,1,13.03,100,1,13.93,100,1,13.02,100,1,14.28,100,1,12.73,100,1,14.4,100,1,12.71,100,1,14.5,100,1,12.5,700,1,14.56,800,2,12.46,200,2,14.6,700,1,12.43,700,1,14.66,100,1,12.42,700,1,14.68,1400,2,12.37,700,1,14.7,100,1
2025-07-17T15:52:16.375662552Z,2025-07-17T15:52:16.375828154Z,160,2,1108,A,A,0,14.76,100,130,165602,261713959,ARL,312771829,13.04,2,1,13.89,2,1,13.03,100,1,13.93,100,1,13.02,100,1,14.28,100,1,12.73,100,1,14.4,100,1,12.71,100,1,14.5,100,1,12.5,700,1,14.56,800,2,12.46,200,2,14.6,700,1,12.43,700,1,14.66,100,1,12.42,700,1,14.68,1400,2,12.37,700,1,14.7,100,1
2025-07-17T15:52:16.377179230Z,2025-07-17T15:52:16.377345053Z,160,2,1108,C,A,0,17.28,100,0,165823,261714104,ARL,310446293,13.04,2,1,13.89,2,1,13.03,100,1,13.93,100,1,13.02,100,1,14.28,100,1,12.73,100,1,14.4,100,1,12.71,100,1,14.5,100,1,12.5,700,1,14.56,800,2,12.46,200,2,14.6,700,1,12.43,700,1,14.66,100,1,12.42,700,1,14.68,1400,2,12.37,700,1,14.7,100,1
2025-07-17T15:52:16.377179230Z,2025-07-17T15:52:16.377345053Z,160,2,1108,A,A,0,17.7,100,130,165823,261714104,ARL,312772009,13.04,2,1,13.89,2,1,13.03,100,1,13.93,100,1,13.02,100,1,14.28,100,1,12.73,100,1,14.4,100,1,12.71,100,1,14.5,100,1,12.5,700,1,14.56,800,2,12.46,200,2,14.6,700,1,12.43,700,1,14.66,100,1,12.42,700,1,14.68,1400,2,12.37,700,1,14.7,100,1
2025-07-17T15:52:16.378073674Z,2025-07-17T15:52:16.378239114Z,160,2,1108,C,A,0,15.76,100,0,165440,261714140,ARL,308902229,13.04,2,1,13.89,2,1,13.03,100,1,13.93,100,1,13.02,100,1,14.28,100,1,12.73,100,1,14.4,100,1,12.71,100,1,14.5,100,1,12.5,700,1,14.56,800,2,12.46,200,2,14.6,700,1,12.43,700,1,14.66,100,1,12.42,700,1,14.68,1400,2,12.37,700,1,14.7,100,1
2025-07-17T15:52:16.378073674Z,2025-07-17T15:52:16.378239114Z,160,2,1108,A,A,0,16.02,100,130,165440,261714140,ARL,312772057,13.04,2,1,13.89,2,1,13.03,100,1,13.93,100,1,13.02,100,1,14.28,100,1,12.73,100,1,14.4,100,1,12.71,100,1,14.5,100,1,12.5,700,1,14.56,800,2,12.46,200,2,14.6,700,1,12.43,700,1,14.66,100,1,12.42,700,1,14.68,1400,2,12.37,700,1,14.7,100,1
2025-07-17T15:52:16.378220434Z,2025-07-17T15:52:16.378385943Z,160,2,1108,C,A,0,14.5,100,0,165509,261714145,ARL,308903349,13.04,2,1,13.89,2,1,13.03,100,1,13.93,100,1,13.02,100,1,14.28,100,1,12.73,100,1,14.4,100,1,12.71,100,1,14.56,800,2,12.5,700,1,14.6,700,1,12.46,200,2,14.66,100,1,12.43,700,1,14.68,1400,2,12.42,700,1,14.7,100,1,12.37,700,1,14.76,100,1
2025-07-17T15:52:16.378220434Z,2025-07-17T15:52:16.378385943Z,160,2,1108,A,A,0,14.72,100,130,165509,261714145,ARL,312772061,13.04,2,1,13.89,2,1,13.03,100,1,13.93,100,1,13.02,100,1,14.28,100,1,12.73,100,1,14.4,100,1,12.71,100,1,14.56,800,2,12.5,700,1,14.6,700,1,12.46,200,2,14.66,100,1,12.43,700,1,14.68,1400,2,12.42,700,1,14.7,100,1,12.37,700,1,14.72,100,1
2025-07-17T15:52:16.378705201Z,2025-07-17T15:52:16.378870638Z,160,2,1108,A,B,0,13.27,10,130,165437,261714171,ARL,312772069,13.27,10,1,13.89,2,1,13.04,2,1,13.93,100,1,13.03,100,1,14.28,100,1,13.02,100,1,14.4,100,1,12.73,100,1,14.56,800,2,12.71,100,1,14.6,700,1,12.5,700,1,14.66,100,1,12.46,200,2,14.68,1400,2,12.43,700,1,14.7,100,1,12.42,700,1,14.72,100,1
2025-07-17T15:52:16.378707041Z,2025-07-17T15:52:16.378872385Z,160,2,1108,A,A,0,13.86,15,130,165344,261714172,ARL,312772073,13.27,10,1,13.86,15,1,13.04,2,1,13.89,2,1,13.03,100,1,13.93,100,1,13.02,100,1,14.28,100,1,12.73,100,1,14.4,100,1,12.71,100,1,14.56,800,2,12.5,700,1,14.6,700,1,12.46,200,2,14.66,100,1,12.43,700,1,14.68,1400,2,12.42,700,1,14.7,100,1
2025-07-17T15:52:16.378962330Z,2025-07-17T15:52:16.379127782Z,160,2,1108,C,B,0,13.02,100,0,165452,261714185,ARL,309415429,13.27,10,1,13.86,15,1,13.04,2,1,13.89,2,1,13.03,100,1,13.93,100,1,12.73,100,1,14.28,100,1,12.71,100,1,14.4,100,1,12.5,700,1,14.56,800,2,12.46,200,2,14.6,700,1,12.43,700,1,14.66,100,1,12.42,700,1,14.68,1400,2,12.37,700,1,14.7,100,1
2025-07-17T15:52:16.378962330Z,2025-07-17T15:52:16.379127782Z,160,2,1108,A,B,0,13.26,100,130,165452,261714185,ARL,312772077,13.27,10,1,13.86,15,1,13.26,100,1,13.89,2,1,13.04,2,1,13.93,100,1,13.03,100,1,14.28,100,1,12.73,100,1,14.4,100,1,12.71,100,1,14.56,800,2,12.5,700,1,14.6,700,1,12.46,200,2,14.66,100,1,12.43,700,1,14.68,1400,2,12.42,700,1,14.7,100,1
2025-07-17T15:52:16.388859982Z,2025-07-17T15:52:16.389025469Z,160,2,1108,C,A,0,13.93,100,130,165487,261714477,ARL,309782973,13.27,10,1,13.86,15,1,13.26,100,1,13.89,2,1,13.04,2,1,14.28,100,1,13.03,100,1,14.4,100,1,12.73,100,1,14.56,800,2,12.71,100,1,14.6,700,1,12.5,700,1,14.66,100,1,12.46,200,2,14.68,1400,2,12.43,700,1,14.7,100,1,12.42,700,1,14.72,100,1
2025-07-17T15:52:16.388917108Z,2025-07-17T15:52:16.389082451Z,160,2,1108,A,A,0,14.19,100,130,165343,261714481,ARL,312772501,13.27,10,1,13.86,15,1,13.26,100,1,13.89,2,1,13.04,2,1,14.19,100,1,13.03,100,1,14.28,100,1,12.73,100,1,14.4,100,1,12.71,100,1,14.56,800,2,12.5,700,1,14.6,700,1,12.46,200,2,14.66,100,1,12.43,700,1,14.68,1400,2,12.42,700,1,14.7,100,1
2025-07-17T15:52:16.396008715Z,2025-07-17T15:52:16.396174502Z,160,2,1108,C,A,0,14.66,100,0,165787,261714603,ARL,308903001,13.27,10,1,13.86,15,1,13.26,100,1,13.89,2,1,13.04,2,1,14.19,100,1,13.03,100,1,14.28,100,1,12.73,100,1,14.4,100,1,12.71,100,1,14.56,800,2,12.5,700,1,14.6,700,1,12.46,200,2,14.68,1400,2,12.43,700,1,14.7,100,1,12.42,700,1,14.72,100,1
2025-07-17T15:52:16.396008715Z,2025-07-17T15:52:16.396174502Z,160,2,1108,A,A,0,14.96,100,130,165787,261714603,ARL,312772869,13.27,10,1,13.86,15,1,13.26,100,1,13.89,2,1,13.04,2,1,14.19,100,1,13.03,100,1,14.28,100,1,12.73,100,1,14.4,100,1,12.71,100,1,14.56,800,2,12.5,700,1,14.6,700,1,12.46,200,2,14.68,1400,2,12.43,700,1,14.7,100,1,12.42,700,1,14.72,100,1
2025-07-17T15:52:16.397512710Z,2025-07-17T15:52:16.397677681Z,160,2,1108,C,A,0,14.19,100,130,164971,261714619,ARL,312772501,13.27,10,1,13.86,15,1,13.26,100,1,13.89,2,1,13.04,2,1,14.28,100,1,13.03,100,1,14.4,100,1,12.73,100,1,14.56,800,2,12.71,100,1,14.6,700,1,12.5,700,1,14.68,1400,2,12.46,200,2,14.7,100,1,12.43,700,1,14.72,100,1,12.42,700,1,14.76,100,1
2025-07-17T15:52:16.397561691Z,2025-07-17T15:52:16.397727042Z,160,2,1108,A,A,0,14.26,100,130,165351,261714620,ARL,312772901,13.27,10,1,13.86,15,1,13.26,100,1,13.89,2,1,13.04,2,1,14.26,100,1,13.03,100,1,14.28,100,1,12.73,100,1,14.4,100,1,12.71,100,1,14.56,800,2,12.5,700,1,14.6,700,1,12.46,200,2,14.68,1400,2,12.43,700,1,14.7,100,1,12.42,700,1,14.72,100,1
2025-07-17T15:52:16.423972000Z,2025-07-17T15:52:16.424137423Z,160,2,1108,C,A,0,14.7,100,0,165423,261714976,ARL,312771573,13.27,10,1,13.86,15,1,13.26,100,1,13.89,2,1,13.04,2,1,14.26,100,1,13.03,100,1,14.28,100,1,12.73,100,1,14.4,100,1,12.71,100,1,14.56,800,2,12.5,700,1,14.6,700,1,12.46,200,2,14.68,1400,2,12.43,700,1,14.72,100,1,12.42,700,1,14.76,100,1
2025-07-17T15:52:16.423972000Z,2025-07-17T15:52:16.424137423Z,160,2,1108,A,A,0,15.06,100,130,165423,261714976,ARL,312773353,13.27,10,1,13.86,15,1,13.26,100,1,13.89,2,1,13.04,2,1,14.26,100,1,13.03,100,1,14.28,100,1,12.73,100,1,14.4,100,1,12.71,100,1,14.56,800,2,12.5,700,1,14.6,700,1,12.46,200,2,14.68,1400,2,12.43,700,1,14.72,100,1,12.42,700,1,14.76,100,1
2025-07-17T15:52:16.464616142Z,2025-07-17T15:52:16.464781343Z,160,2,1108,A,A,0,13.87,100,130,165201,261715303,ARL,312773881,13.27,10,1,13.86,15,1,13.26,100,1,13.87,100,1,13.04,2,1,13.89,2,1,13.03,100,1,14.26,100,1,12.73,100,1,14.28,100,1,12.71,100,1,14.4,100,1,12.5,700,1,14.56,800,2,12.46,200,2,14.6,700,1,12.43,700,1,14.68,1400,2,12.42,700,1,14.72,100,1
2025-07-17T15:52:16.473391480Z,2025-07-17T15:52:16.473556948Z,160,2,1108,C,A,0,15.06,100,0,165468,261715409,ARL,312773353,13.27,10,1,13.86,15,1,13.26,100,1,13.87,100,1,13.04,2,1,13.89,2,1,13.03,100,1,14.26,100,1,12.73,100,1,14.28,100,1,12.71,100,1,14.4,100,1,12.5,700,1,14.56,800,2,12.46,200,2,14.6,700,1,12.43,700,1,14.68,1400,2,12.42,700,1,14.72,100,1
2025-07-17T15:52:16.473391480Z,2025-07-17T15:52:16.473556948Z,160,2,1108,A,A,0,14.95,100,130,165468,261715409,ARL,312774001,13.27,10,1,13.86,15,1,13.26,100,1,13.87,100,1,13.04,2,1,13.89,2,1,13.03,100,1,14.26,100,1,12.73,100,1,14.28,100,1,12.71,100,1,14.4,100,1,12.5,700,1,14.56,800,2,12.46,200,2,14.6,700,1,12.43,700,1,14.68,1400,2,12.42,700,1,14.72,100,1
2025-07-17T15:52:16.479925781Z,2025-07-17T15:52:16.480090894Z,160,2,1108,C,A,0,14.26,100,130,165113,261715467,ARL,312772901,13.27,10,1,13.86,15,1,13.26,100,1,13.87,100,1,13.04,2,1,13.89,2,1,13.03,100,1,14.28,100,1,12.73,100,1,14.4,100,1,12.71,100,1,14.56,800,2,12.5,700,1,14.6,700,1,12.46,200,2,14.68,1400,2,12.43,700,1,14.72,100,1,12.42,700,1,14.76,100,1
2025-07-17T15:52:16.479974840Z,2025-07-17T15:52:16.480140131Z,160,2,1108,A,A,0,14.15,100,130,165291,261715468,ARL,312774033,13.27,10,1,13.86,15,1,13.26,100,1,13.87,100,1,13.04,2,1,13.89,2,1,13.03,100,1,14.15,100,1,12.73,100,1,14.28,100,1,12.71,100,1,14.4,100,1,12.5,700,1,14.56,800,2,12.46,200,2,14.6,700,1,12.43,700,1,14.68,1400,2,12.42,700,1,14.72,100,1
2025-07-17T15:52:28.787151494Z,2025-07-17T15:52:28.787316865Z,160,2,1108,C,B,0,13.27,10,130,165371,261883294,ARL,312772069,13.26,100,1,13.86,15,1,13.04,2,1,13.87,100,1,13.03,100,1,13.89,2,1,12.73,100,1,14.15,100,1,12.71,100,1,14.28,100,1,12.5,700,1,14.4,100,1,12.46,200,2,14.56,800,2,12.43,700,1,14.6,700,1,12.42,700,1,14.68,1400,2,12.37,700,1,14.72,100,1
2025-07-17T15:52:28.787152437Z,2025-07-17T15:52:28.787317827Z,160,2,1108,C,A,0,13.86,15,130,165390,261883295,ARL,312772073,13.26,100,1,13.87,100,1,13.04,2,1,13.89,2,1,13.03,100,1,14.15,100,1,12.73,100,1,14.28,100,1,12.71,100,1,14.4,100,1,12.5,700,1,14.56,800,2,12.46,200,2,14.6,700,1,12.43,700,1,14.68,1400,2,12.42,700,1,14.72,100,1,12.37,700,1,14.76,100,1
2025-07-17T15:52:43.128203357Z,2025-07-17T15:52:43.128371033Z,160,2,1108,C,A,0,13.89,2,0,167676,262115170,ARL,311979125,13.26,100,1,13.87,100,1,13.04,2,1,14.15,100,1,13.03,100,1,14.28,100,1,12.73,100,1,14.4,100,1,12.71,100,1,14.56,800,2,12.5,700,1,14.6,700,1,12.46,200,2,14.68,1400,2,12.43,700,1,14.72,100,1,12.42,700,1,14.76,100,1,12.37,700,1,14.81,100,1
2025-07-17T15:52:43.128203357Z,2025-07-17T15:52:43.128371033Z,160,2,1108,A,A,0,13.99,2,128,167676,262115170,ARL,313336713,13.26,100,1,13.87,100,1,13.04,2,1,13.99,2,1,13.03,100,1,14.15,100,1,12.73,100,1,14.28,100,1,12.71,100,1,14.4,100,1,12.5,700,1,14.56,800,2,12.46,200,2,14.6,700,1,12.43,700,1,14.68,1400,2,12.42,700,1,14.72,100,1,12.37,700,1,14.76,100,1
2025-07-17T15:54:24.908318259Z,2025-07-17T15:54:24.908483782Z,160,2,1108,A,B,0,13.29,10,130,165523,263863872,ARL,315581981,13.29,10,1,13.87,100,1,13.26,100,1,13.99,2,1,13.04,2,1,14.15,100,1,13.03,100,1,14.28,100,1,12.73,100,1,14.4,100,1,12.71,100,1,14.56,800,2,12.5,700,1,14.6,700,1,12.46,200,2,14.68,1400,2,12.43,700,1,14.72,100,1,12.42,700,1,14.76,100,1
2025-07-17T15:54:26.792313320Z,2025-07-17T15:54:26.792478456Z,160,2,1108,C,B,0,13.29,10,130,165136,263895481,ARL,315581981,13.26,100,1,13.87,100,1,13.04,2,1,13.99,2,1,13.03,100,1,14.15,100,1,12.73,100,1,14.28,100,1,12.71,100,1,14.4,100,1,12.5,700,1,14.56,800,2,12.46,200,2,14.6,700,1,12.43,700,1,14.68,1400,2,12.42,700,1,14.72,100,1,12.37,700,1,14.76,100,1
2025-07-17T15:54:52.985950259Z,2025-07-17T15:54:52.986116083Z,160,2,1108,C,A,0,13.99,2,0,165824,264262615,ARL,313336713,13.26,100,1,13.87,100,1,13.04,2,1,14.15,100,1,13.03,100,1,14.28,100,1,12.73,100,1,14.4,100,1,12.71,100,1,14.56,800,2,12.5,700,1,14.6,700,1,12.46,200,2,14.68,1400,2,12.43,700,1,14.72,100,1,12.42,700,1,14.76,100,1,12.37,700,1,14.81,100,1
2025-07-17T15:54:52.985950259Z,2025-07-17T15:54:52.986116083Z,160,2,1108,A,A,0,14.1,2,130,165824,264262615,ARL,316098525,13.26,100,1,13.87,100,1,13.04,2,1,14.1,2,1,13.03,100,1,14.15,100,1,12.73,100,1,14.28,100,1,12.71,100,1,14.4,100,1,12.5,700,1,14.56,800,2,12.46,200,2,14.6,700,1,12.43,700,1,14.68,1400,2,12.42,700,1,14.72,100,1,12.37,700,1,14.76,100,1
2025-07-17T15:55:33.673432762Z,2025-07-17T15:55:33.673598252Z,160,2,1108,A,B,0,13.29,10,130,165490,264905534,ARL,316911465,13.29,10,1,13.87,100,1,13.26,100,1,14.1,2,1,13.04,2,1,14.15,100,1,13.03,100,1,14.28,100,1,12.73,100,1,14.4,100,1,12.71,100,1,14.56,800,2,12.5,700,1,14.6,700,1,12.46,200,2,14.68,1400,2,12.43,700,1,14.72,100,1,12.42,700,1,14.76,100,1
2025-07-17T15:55:34.257251787Z,2025-07-17T15:55:34.257417204Z,160,2,1108,C,B,0,13.26,100,0,165417,264919835,ARL,312772077,13.29,10,1,13.87,100,1,13.04,2,1,14.1,2,1,13.03,100,1,14.15,100,1,12.73,100,1,14.28,100,1,12.71,100,1,14.4,100,1,12.5,700,1,14.56,800,2,12.46,200,2,14.6,700,1,12.43,700,1,14.68,1400,2,12.42,700,1,14.72,100,1,12.37,700,1,14.76,100,1
2025-07-17T15:55:34.257251787Z,2025-07-17T15:55:34.257417204Z,160,2,1108,A,B,0,13.28,100,130,165417,264919835,ARL,316924721,13.29,10,1,13.87,100,1,13.28,100,1,14.1,2,1,13.04,2,1,14.15,100,1,13.03,100,1,14.28,100,1,12.73,100,1,14.4,100,1,12.71,100,1,14.56,800,2,12.5,700,1,14.6,700,1,12.46,200,2,14.68,1400,2,12.43,700,1,14.72,100,1,12.42,700,1,14.76,100,1
2025-07-17T15:55:40.197584524Z,2025-07-17T15:55:40.197750400Z,160,2,1108,C,B,0,13.29,10,130,165876,265015966,ARL,316911465,13.28,100,1,13.87,100,1,13.04,2,1,14.1,2,1,13.03,100,1,14.15,100,1,12.73,100,1,14.28,100,1,12.71,100,1,14.4,100,1,12.5,700,1,14.56,800,2,12.46,200,2,14.6,700,1,12.43,700,1,14.68,1400,2,12.42,700,1,14.72,100,1,12.37,700,1,14.76,100,1
2025-07-17T15:57:51.328698198Z,2025-07-17T15:57:51.328863560Z,160,2,1108,C,A,0,13.87,100,130,165362,267272430,ARL,312773881,13.28,100,1,14.1,2,1,13.04,2,1,14.15,100,1,13.03,100,1,14.28,100,1,12.73,100,1,14.4,100,1,12.71,100,1,14.56,800,2,12.5,700,1,14.6,700,1,12.46,200,2,14.68,1400,2,12.43,700,1,14.72,100,1,12.42,700,1,14.76,100,1,12.37,700,1,14.81,100,1
2025-07-17T15:57:51.329447325Z,2025-07-17T15:57:51.329613584Z,160,2,1108,C,A,0,14.95,100,0,166259,267272438,ARL,312774001,13.28,100,1,14.1,2,1,13.04,2,1,14.15,100,1,13.03,100,1,14.28,100,1,12.73,100,1,14.4,100,1,12.71,100,1,14.56,800,2,12.5,700,1,14.6,700,1,12.46,200,2,14.68,1400,2,12.43,700,1,14.72,100,1,12.42,700,1,14.76,100,1,12.37,700,1,14.81,100,1
2025-07-17T15:57:51.329447325Z,2025-07-17T15:57:51.329613584Z,160,2,1108,A,A,0,15,100,130,166259,267272438,ARL,319985021,13.28,100,1,14.1,2,1,13.04,2,1,14.15,100,1,13.03,100,1,14.28,100,1,12.73,100,1,14.4,100,1,12.71,100,1,14.56,800,2,12.5,700,1,14.6,700,1,12.46,200,2,14.68,1400,2,12.43,700,1,14.72,100,1,12.42,700,1,14.76,100,1,12.37,700,1,14.81,100,1
2025-07-17T15:57:51.329692071Z,2025-07-17T15:57:51.329857672Z,160,2,1108,C,A,0,14.76,100,0,165601,267272442,ARL,312771829,13.28,100,1,14.1,2,1,13.04,2,1,14.15,100,1,13.03,100,1,14.28,100,1,12.73,100,1,14.4,100,1,12.71,100,1,14.56,800,2,12.5,700,1,14.6,700,1,12.46,200,2,14.68,1400,2,12.43,700,1,14.72,100,1,12.42,700,1,14.81,100,1,12.37,700,1,14.89,100,1
2025-07-17T15:57:51.329692071Z,2025-07-17T15:57:51.329857672Z,160,2,1108,A,A,0,14.89,100,130,165601,267272442,ARL,319985025,13.28,100,1,14.1,2,1,13.04,2,1,14.15,100,1,13.03,100,1,14.28,100,1,12.73,100,1,14.4,100,1,12.71,100,1,14.56,800,2,12.5,700,1,14.6,700,1,12.46,200,2,14.68,1400,2,12.43,700,1,14.72,100,1,12.42,700,1,14.81,100,1,12.37,700,1,14.89,200,2
2025-07-17T15:57:51.339162512Z,2025-07-17T15:57:51.339328219Z,160,2,1108,C,A,0,14.15,100,130,165707,267272660,ARL,312774033,13.28,100,1,14.1,2,1,13.04,2,1,14.28,100,1,13.03,100,1,14.4,100,1,12.73,100,1,14.56,800,2,12.71,100,1,14.6,700,1,12.5,700,1,14.68,1400,2,12.46,200,2,14.72,100,1,12.43,700,1,14.81,100,1,12.42,700,1,14.89,200,2,12.37,700,1,14.96,100,1
2025-07-17T15:57:51.339216923Z,2025-07-17T15:57:51.339382098Z,160,2,1108,A,A,0,14.26,100,130,165175,267272665,ARL,319985165,13.28,100,1,14.1,2,1,13.04,2,1,14.26,100,1,13.03,100,1,14.28,100,1,12.73,100,1,14.4,100,1,12.71,100,1,14.56,800,2,12.5,700,1,14.6,700,1,12.46,200,2,14.68,1400,2,12.43,700,1,14.72,100,1,12.42,700,1,14.81,100,1,12.37,700,1,14.89,200,2
2025-07-17T15:57:51.379570470Z,2025-07-17T15:57:51.379736852Z,160,2,1108,C,A,0,15,100,0,166382,267273071,ARL,319985021,13.28,100,1,14.1,2,1,13.04,2,1,14.26,100,1,13.03,100,1,14.28,100,1,12.73,100,1,14.4,100,1,12.71,100,1,14.56,800,2,12.5,700,1,14.6,700,1,12.46,200,2,14.68,1400,2,12.43,700,1,14.72,100,1,12.42,700,1,14.81,100,1,12.37,700,1,14.89,200,2
2025-07-17T15:57:51.379570470Z,2025-07-17T15:57:51.379736852Z,160,2,1108,A,A,0,15.06,100,128,166382,267273071,ARL,319985497,13.28,100,1,14.1,2,1,13.04,2,1,14.26,100,1,13.03,100,1,14.28,100,1,12.73,100,1,14.4,100,1,12.71,100,1,14.56,800,2,12.5,700,1,14.6,700,1,12.46,200,2,14.68,1400,2,12.43,700,1,14.72,100,1,12.42,700,1,14.81,100,1,12.37,700,1,14.89,200,2
2025-07-17T15:57:52.378204338Z,2025-07-17T15:57:52.378369524Z,160,2,1108,A,A,0,14.11,100,130,165186,267283873,ARL,320000233,13.28,100,1,14.1,2,1,13.04,2,1,14.11,100,1,13.03,100,1,14.26,100,1,12.73,100,1,14.28,100,1,12.71,100,1,14.4,100,1,12.5,700,1,14.56,800,2,12.46,200,2,14.6,700,1,12.43,700,1,14.68,1400,2,12.42,700,1,14.72,100,1,12.37,700,1,14.81,100,1
2025-07-17T15:58:14.483743947Z,2025-07-17T15:58:14.483909354Z,160,2,1108,A,A,0,13.76,4,130,165407,267657011,ARL,320484625,13.28,100,1,13.76,4,1,13.04,2,1,14.1,2,1,13.03,100,1,14.11,100,1,12.73,100,1,14.26,100,1,12.71,100,1,14.28,100,1,12.5,700,1,14.4,100,1,12.46,200,2,14.56,800,2,12.43,700,1,14.6,700,1,12.42,700,1,14.68,1400,2,12.37,700,1,14.72,100,1
2025-07-17T15:58:14.483999049Z,2025-07-17T15:58:14.484164551Z,160,2,1108,C,A,0,14.11,100,0,165502,267657013,ARL,320000233,13.28,100,1,13.76,4,1,13.04,2,1,14.1,2,1,13.03,100,1,14.26,100,1,12.73,100,1,14.28,100,1,12.71,100,1,14.4,100,1,12.5,700,1,14.56,800,2,12.46,200,2,14.6,700,1,12.43,700,1,14.68,1400,2,12.42,700,1,14.72,100,1,12.37,700,1,14.81,100,1
2025-07-17T15:58:14.483999049Z,2025-07-17T15:58:14.484164551Z,160,2,1108,A,A,0,13.77,100,130,165502,267657013,ARL,320484637,13.28,100,1,13.76,4,1,13.04,2,1,13.77,100,1,13.03,100,1,14.1,2,1,12.73,100,1,14.26,100,1,12.71,100,1,14.28,100,1,12.5,700,1,14.4,100,1,12.46,200,2,14.56,800,2,12.43,700,1,14.6,700,1,12.42,700,1,14.68,1400,2,12.37,700,1,14.72,100,1
2025-07-17T15:58:14.484017806Z,2025-07-17T15:58:14.484183413Z,160,2,1108,C,B,0,13.28,100,130,165607,267657014,ARL,316924721,13.04,2,1,13.76,4,1,13.03,100,1,13.77,100,1,12.73,100,1,14.1,2,1,12.71,100,1,14.26,100,1,12.5,700,1,14.28,100,1,12.46,200,2,14.4,100,1,12.43,700,1,14.56,800,2,12.42,700,1,14.6,700,1,12.37,700,1,14.68,1400,2,12.36,200,2,14.72,100,1
2025-07-17T15:58:14.484147359Z,2025-07-17T15:58:14.484312532Z,160,2,1108,A,A,0,13.79,100,130,165173,267657020,ARL,320484661,13.04,2,1,13.76,4,1,13.03,100,1,13.77,100,1,12.73,100,1,13.79,100,1,12.71,100,1,14.1,2,1,12.5,700,1,14.26,100,1,12.46,200,2,14.28,100,1,12.43,700,1,14.4,100,1,12.42,700,1,14.56,800,2,12.37,700,1,14.6,700,1,12.36,200,2,14.68,1400,2
2025-07-17T15:58:14.484736787Z,2025-07-17T15:58:14.484902175Z,160,2,1108,C,A,0,15.06,100,0,165388,267657063,ARL,319985497,13.04,2,1,13.76,4,1,13.03,100,1,13.77,100,1,12.73,100,1,13.79,100,1,12.71,100,1,14.1,2,1,12.5,700,1,14.26,100,1,12.46,200,2,14.28,100,1,12.43,700,1,14.4,100,1,12.42,700,1,14.56,800,2,12.37,700,1,14.6,700,1,12.36,200,2,14.68,1400,2
2025-07-17T15:58:14.484736787Z,2025-07-17T15:58:14.484902175Z,160,2,1108,A,A,0,14.84,100,130,165388,267657063,ARL,320484709,13.04,2,1,13.76,4,1,13.03,100,1,13.77,100,1,12.73,100,1,13.79,100,1,12.71,100,1,14.1,2,1,12.5,700,1,14.26,100,1,12.46,200,2,14.28,100,1,12.43,700,1,14.4,100,1,12.42,700,1,14.56,800,2,12.37,700,1,14.6,700,1,12.36,200,2,14.68,1400,2
2025-07-17T15:58:14.484761664Z,2025-07-17T15:58:14.484927848Z,160,2,1108,C,A,0,13.76,4,128,166184,267657070,ARL,320484625,13.04,2,1,13.77,100,1,13.03,100,1,13.79,100,1,12.73,100,1,14.1,2,1,12.71,100,1,14.26,100,1,12.5,700,1,14.28,100,1,12.46,200,2,14.4,100,1,12.43,700,1,14.56,800,2,12.42,700,1,14.6,700,1,12.37,700,1,14.68,1400,2,12.36,200,2,14.72,100,1
2025-07-17T15:58:14.484798779Z,2025-07-17T15:58:14.484963870Z,160,2,1108,C,A,0,13.77,100,130,165091,267657073,ARL,320484637,13.04,2,1,13.79,100,1,13.03,100,1,14.1,2,1,12.73,100,1,14.26,100,1,12.71,100,1,14.28,100,1,12.5,700,1,14.4,100,1,12.46,200,2,14.56,800,2,12.43,700,1,14.6,700,1,12.42,700,1,14.68,1400,2,12.37,700,1,14.72,100,1,12.36,200,2,14.81,100,1
2025-07-17T15:58:14.485227487Z,2025-07-17T15:58:14.485392903Z,160,2,1108,C,A,0,14.81,100,0,165416,267657092,ARL,312771781,13.04,2,1,13.79,100,1,13.03,100,1,14.1,2,1,12.73,100,1,14.26,100,1,12.71,100,1,14.28,100,1,12.5,700,1,14.4,100,1,12.46,200,2,14.56,800,2,12.43,700,1,14.6,700,1,12.42,700,1,14.68,1400,2,12.37,700,1,14.72,100,1,12.36,200,2,14.84,100,1
2025-07-17T15:58:14.485227487Z,2025-07-17T15:58:14.485392903Z,160,2,1108,A,A,0,14.68,100,130,165416,267657092,ARL,320484781,13.04,2,1,13.79,100,1,13.03,100,1,14.1,2,1,12.73,100,1,14.26,100,1,12.71,100,1,14.28,100,1,12.5,700,1,14.4,100,1,12.46,200,2,14.56,800,2,12.43,700,1,14.6,700,1,12.42,700,1,14.68,1500,3,12.37,700,1,14.72,100,1,12.36,200,2,14.84,100,1
2025-07-17T15:58:14.485666254Z,2025-07-17T15:58:14.485831602Z,160,2,1108,C,A,0,16.02,100,0,165348,267657097,ARL,312772057,13.04,2,1,13.79,100,1,13.03,100,1,14.1,2,1,12.73,100,1,14.26,100,1,12.71,100,1,14.28,100,1,12.5,700,1,14.4,100,1,12.46,200,2,14.56,800,2,12.43,700,1,14.6,700,1,12.42,700,1,14.68,1500,3,12.37,700,1,14.72,100,1,12.36,200,2,14.84,100,1
2025-07-17T15:58:14.485666254Z,2025-07-17T15:58:14.485831602Z,160,2,1108,A,A,0,15.86,100,130,165348,267657097,ARL,320484817,13.04,2,1,13.79,100,1,13.03,100,1,14.1,2,1,12.73,100,1,14.26,100,1,12.71,100,1,14.28,100,1,12.5,700,1,14.4,100,1,12.46,200,2,14.56,800,2,12.43,700,1,14.6,700,1,12.42,700,1,14.68,1500,3,12.37,700,1,14.72,100,1,12.36,200,2,14.84,100,1
2025-07-17T15:58:14.485685308Z,2025-07-17T15:58:14.485850874Z,160,2,1108,C,A,0,14.96,100,0,165566,267657098,ARL,312772869,13.04,2,1,13.79,100,1,13.03,100,1,14.1,2,1,12.73,100,1,14.26,100,1,12.71,100,1,14.28,100,1,12.5,700,1,14.4,100,1,12.46,200,2,14.56,800,2,12.43,700,1,14.6,700,1,12.42,700,1,14.68,1500,3,12.37,700,1,14.72,100,1,12.36,200,2,14.84,100,1
2025-07-17T15:58:14.485685308Z,2025-07-17T15:58:14.485850874Z,160,2,1108,A,A,0,14.76,100,130,165566,267657098,ARL,320484821,13.04,2,1,13.79,100,1,13.03,100,1,14.1,2,1,12.73,100,1,14.26,100,1,12.71,100,1,14.28,100,1,12.5,700,1,14.4,100,1,12.46,200,2,14.56,800,2,12.43,700,1,14.6,700,1,12.42,700,1,14.68,1500,3,12.37,700,1,14.72,100,1,12.36,200,2,14.76,100,1
2025-07-17T15:58:14.485824228Z,2025-07-17T15:58:14.485989643Z,160,2,1108,C,A,0,14.89,100,0,165415,267657101,ARL,319985025,13.04,2,1,13.79,100,1,13.03,100,1,14.1,2,1,12.73,100,1,14.26,100,1,12.71,100,1,14.28,100,1,12.5,700,1,14.4,100,1,12.46,200,2,14.56,800,2,12.43,700,1,14.6,700,1,12.42,700,1,14.68,1500,3,12.37,700,1,14.72,100,1,12.36,200,2,14.76,100,1
2025-07-17T15:58:14.485824228Z,2025-07-17T15:58:14.485989643Z,160,2,1108,A,A,0,14.69,100,130,165415,267657101,ARL,320484825,13.04,2,1,13.79,100,1,13.03,100,1,14.1,2,1,12.73,100,1,14.26,100,1,12.71,100,1,14.28,100,1,12.5,700,1,14.4,100,1,12.46,200,2,14.56,800,2,12.43,700,1,14.6,700,1,12.42,700,1,14.68,1500,3,12.37,700,1,14.69,100,1,12.36,200,2,14.72,100,1
2025-07-17T15:58:14.486240860Z,2025-07-17T15:58:14.486406355Z,160,2,1108,C,A,0,17.7,100,0,165495,267657116,ARL,312772009,13.04,2,1,13.79,100,1,13.03,100,1,14.1,2,1,12.73,100,1,14.26,100,1,12.71,100,1,14.28,100,1,12.5,700,1,14.4,100,1,12.46,200,2,14.56,800,2,12.43,700,1,14.6,700,1,12.42,700,1,14.68,1500,3,12.37,700,1,14.69,100,1,12.36,200,2,14.72,100,1
2025-07-17T15:58:14.486240860Z,2025-07-17T15:58:14.486406355Z,160,2,1108,A,A,0,17.52,100,130,165495,267657116,ARL,320484837,13.04,2,1,13.79,100,1,13.03,100,1,14.1,2,1,12.73,100,1,14.26,100,1,12.71,100,1,14.28,100,1,12.5,700,1,14.4,100,1,12.46,200,2,14.56,800,2,12.43,700,1,14.6,700,1,12.42,700,1,14.68,1500,3,12.37,700,1,14.69,100,1,12.36,200,2,14.72,100,1
2025-07-17T15:58:14.508012098Z,2025-07-17T15:58:14.508177256Z,160,2,1108,C,A,0,14.26,100,130,165158,267657330,ARL,319985165,13.04,2,1,13.79,100,1,13.03,100,1,14.1,2,1,12.73,100,1,14.28,100,1,12.71,100,1,14.4,100,1,12.5,700,1,14.56,800,2,12.46,200,2,14.6,700,1,12.43,700,1,14.68,1500,3,12.42,700,1,14.69,100,1,12.37,700,1,14.72,100,1,12.36,200,2,14.76,100,1
2025-07-17T15:58:14.508062605Z,2025-07-17T15:58:14.508227890Z,160,2,1108,A,A,0,14.05,100,130,165285,267657333,ARL,320484985,13.04,2,1,13.79,100,1,13.03,100,1,14.05,100,1,12.73,100,1,14.1,2,1,12.71,100,1,14.28,100,1,12.5,700,1,14.4,100,1,12.46,200,2,14.56,800,2,12.43,700,1,14.6,700,1,12.42,700,1,14.68,1500,3,12.37,700,1,14.69,100,1,12.36,200,2,14.72,100,1
2025-07-17T15:58:14.529391743Z,2025-07-17T15:58:14.529557108Z,160,2,1108,A,B,0,13.02,100,130,165365,267657561,ARL,320485385,13.04,2,1,13.79,100,1,13.03,100,1,14.05,100,1,13.02,100,1,14.1,2,1,12.73,100,1,14.28,100,1,12.71,100,1,14.4,100,1,12.5,700,1,14.56,800,2,12.46,200,2,14.6,700,1,12.43,700,1,14.68,1500,3,12.42,700,1,14.69,100,1,12.37,700,1,14.72,100,1
2025-07-17T15:58:14.529413184Z,2025-07-17T15:58:14.529578291Z,160,2,1108,A,A,0,13.8,100,130,165107,267657562,ARL,320485389,13.04,2,1,13.79,100,1,13.03,100,1,13.8,100,1,13.02,100,1,14.05,100,1,12.73,100,1,14.1,2,1,12.71,100,1,14.28,100,1,12.5,700,1,14.4,100,1,12.46,200,2,14.56,800,2,12.43,700,1,14.6,700,1,12.42,700,1,14.68,1500,3,12.37,700,1,14.69,100,1
2025-07-17T15:58:14.659734381Z,2025-07-17T15:58:14.659899426Z,160,2,1108,C,A,0,13.79,100,130,165045,267658873,ARL,320484661,13.04,2,1,13.8,100,1,13.03,100,1,14.05,100,1,13.02,100,1,14.1,2,1,12.73,100,1,14.28,100,1,12.71,100,1,14.4,100,1,12.5,700,1,14.56,800,2,12.46,200,2,14.6,700,1,12.43,700,1,14.68,1500,3,12.42,700,1,14.69,100,1,12.37,700,1,14.72,100,1
2025-07-17T15:58:14.659773896Z,2025-07-17T15:58:14.659939230Z,160,2,1108,C,A,0,13.8,100,130,165334,267658879,ARL,320485389,13.04,2,1,14.05,100,1,13.03,100,1,14.1,2,1,13.02,100,1,14.28,100,1,12.73,100,1,14.4,100,1,12.71,100,1,14.56,800,2,12.5,700,1,14.6,700,1,12.46,200,2,14.68,1500,3,12.43,700,1,14.69,100,1,12.42,700,1,14.72,100,1,12.37,700,1,14.76,100,1
2025-07-17T15:58:14.660502341Z,2025-07-17T15:58:14.660667636Z,160,2,1108,C,A,0,14.84,100,0,165295,267658892,ARL,320484709,13.04,2,1,14.05,100,1,13.03,100,1,14.1,2,1,13.02,100,1,14.28,100,1,12.73,100,1,14.4,100,1,12.71,100,1,14.56,800,2,12.5,700,1,14.6,700,1,12.46,200,2,14.68,1500,3,12.43,700,1,14.69,100,1,12.42,700,1,14.72,100,1,12.37,700,1,14.76,100,1
2025-07-17T15:58:14.660502341Z,2025-07-17T15:58:14.660667636Z,160,2,1108,A,A,0,14.91,100,130,165295,267658892,ARL,320486925,13.04,2,1,14.05,100,1,13.03,100,1,14.1,2,1,13.02,100,1,14.28,100,1,12.73,100,1,14.4,100,1,12.71,100,1,14.56,800,2,12.5,700,1,14.6,700,1,12.46,200,2,14.68,1500,3,12.43,700,1,14.69,100,1,12.42,700,1,14.72,100,1,12.37,700,1,14.76,100,1
2025-07-17T15:58:14.664213722Z,2025-07-17T15:58:14.664378962Z,160,2,1108,C,A,0,17.52,100,0,165240,267658928,ARL,320484837,13.04,2,1,14.05,100,1,13.03,100,1,14.1,2,1,13.02,100,1,14.28,100,1,12.73,100,1,14.4,100,1,12.71,100,1,14.56,800,2,12.5,700,1,14.6,700,1,12.46,200,2,14.68,1500,3,12.43,700,1,14.69,100,1,12.42,700,1,14.72,100,1,12.37,700,1,14.76,100,1
2025-07-17T15:58:14.664213722Z,2025-07-17T15:58:14.664378962Z,160,2,1108,A,A,0,17.76,100,130,165240,267658928,ARL,320486937,13.04,2,1,14.05,100,1,13.03,100,1,14.1,2,1,13.02,100,1,14.28,100,1,12.73,100,1,14.4,100,1,12.71,100,1,14.56,800,2,12.5,700,1,14.6,700,1,12.46,200,2,14.68,1500,3,12.43,700,1,14.69,100,1,12.42,700,1,14.72,100,1,12.37,700,1,14.76,100,1
2025-07-17T15:58:14.664774078Z,2025-07-17T15:58:14.664939310Z,160,2,1108,C,A,0,15.86,100,0,165232,267658931,ARL,320484817,13.04,2,1,14.05,100,1,13.03,100,1,14.1,2,1,13.02,100,1,14.28,100,1,12.73,100,1,14.4,100,1,12.71,100,1,14.56,800,2,12.5,700,1,14.6,700,1,12.46,200,2,14.68,1500,3,12.43,700,1,14.69,100,1,12.42,700,1,14.72,100,1,12.37,700,1,14.76,100,1
2025-07-17T15:58:14.664774078Z,2025-07-17T15:58:14.664939310Z,160,2,1108,A,A,0,16.08,100,130,165232,267658931,ARL,320486945,13.04,2,1,14.05,100,1,13.03,100,1,14.1,2,1,13.02,100,1,14.28,100,1,12.73,100,1,14.4,100,1,12.71,100,1,14.56,800,2,12.5,700,1,14.6,700,1,12.46,200,2,14.68,1500,3,12.43,700,1,14.69,100,1,12.42,700,1,14.72,100,1,12.37,700,1,14.76,100,1
2025-07-17T15:58:14.672150755Z,2025-07-17T15:58:14.672315806Z,160,2,1108,C,A,0,14.05,100,130,165051,267658982,ARL,320484985,13.04,2,1,14.1,2,1,13.03,100,1,14.28,100,1,13.02,100,1,14.4,100,1,12.73,100,1,14.56,800,2,12.71,100,1,14.6,700,1,12.5,700,1,14.68,1500,3,12.46,200,2,14.69,100,1,12.43,700,1,14.72,100,1,12.42,700,1,14.76,100,1,12.37,700,1,14.89,100,1
2025-07-17T15:58:14.672200872Z,2025-07-17T15:58:14.672365974Z,160,2,1108,A,A,0,14.12,100,130,165102,267658983,ARL,320487017,13.04,2,1,14.1,2,1,13.03,100,1,14.12,100,1,13.02,100,1,14.28,100,1,12.73,100,1,14.4,100,1,12.71,100,1,14.56,800,2,12.5,700,1,14.6,700,1,12.46,200,2,14.68,1500,3,12.43,700,1,14.69,100,1,12.42,700,1,14.72,100,1,12.37,700,1,14.76,100,1
2025-07-17T15:58:14.673019194Z,2025-07-17T15:58:14.673184116Z,160,2,1108,C,A,0,14.12,100,130,164922,267658989,ARL,320487017,13.04,2,1,14.1,2,1,13.03,100,1,14.28,100,1,13.02,100,1,14.4,100,1,12.73,100,1,14.56,800,2,12.71,100,1,14.6,700,1,12.5,700,1,14.68,1500,3,12.46,200,2,14.69,100,1,12.43,700,1,14.72,100,1,12.42,700,1,14.76,100,1,12.37,700,1,14.89,100,1
2025-07-17T15:58:14.673065320Z,2025-07-17T15:58:14.673230480Z,160,2,1108,A,A,0,14.26,100,130,165160,267658990,ARL,320487025,13.04,2,1,14.1,2,1,13.03,100,1,14.26,100,1,13.02,100,1,14.28,100,1,12.73,100,1,14.4,100,1,12.71,100,1,14.56,800,2,12.5,700,1,14.6,700,1,12.46,200,2,14.68,1500,3,12.43,700,1,14.69,100,1,12.42,700,1,14.72,100,1,12.37,700,1,14.76,100,1
2025-07-17T15:58:14.682780396Z,2025-07-17T15:58:14.682945541Z,160,2,1108,C,A,0,14.76,100,0,165145,267659018,ARL,320484821,13.04,2,1,14.1,2,1,13.03,100,1,14.26,100,1,13.02,100,1,14.28,100,1,12.73,100,1,14.4,100,1,12.71,100,1,14.56,800,2,12.5,700,1,14.6,700,1,12.46,200,2,14.68,1500,3,12.43,700,1,14.69,100,1,12.42,700,1,14.72,100,1,12.37,700,1,14.89,100,1
2025-07-17T15:58:14.682780396Z,2025-07-17T15:58:14.682945541Z,160,2,1108,A,A,0,14.96,100,130,165145,267659018,ARL,320487105,13.04,2,1,14.1,2,1,13.03,100,1,14.26,100,1,13.02,100,1,14.28,100,1,12.73,100,1,14.4,100,1,12.71,100,1,14.56,800,2,12.5,700,1,14.6,700,1,12.46,200,2,14.68,1500,3,12.43,700,1,14.69,100,1,12.42,700,1,14.72,100,1,12.37,700,1,14.89,100,1
2025-07-17T15:58:14.710622495Z,2025-07-17T15:58:14.710787891Z,160,2,1108,C,A,0,14.91,100,0,165396,267659178,ARL,320486925,13.04,2,1,14.1,2,1,13.03,100,1,14.26,100,1,13.02,100,1,14.28,100,1,12.73,100,1,14.4,100,1,12.71,100,1,14.56,800,2,12.5,700,1,14.6,700,1,12.46,200,2,14.68,1500,3,12.43,700,1,14.69,100,1,12.42,700,1,14.72,100,1,12.37,700,1,14.89,100,1
2025-07-17T15:58:14.710622495Z,2025-07-17T15:58:14.710787891Z,160,2,1108,A,A,0,15.06,100,130,165396,267659178,ARL,320487357,13.04,2,1,14.1,2,1,13.03,100,1,14.26,100,1,13.02,100,1,14.28,100,1,12.73,100,1,14.4,100,1,12.71,100,1,14.56,800,2,12.5,700,1,14.6,700,1,12.46,200,2,14.68,1500,3,12.43,700,1,14.69,100,1,12.42,700,1,14.72,100,1,12.37,700,1,14.89,100,1
2025-07-17T15:58:15.563904700Z,2025-07-17T15:58:15.564070256Z,160,2,1108,C,A,0,14.68,100,0,165556,267672469,ARL,320484781,13.04,2,1,14.1,2,1,13.03,100,1,14.26,100,1,13.02,100,1,14.28,100,1,12.73,100,1,14.4,100,1,12.71,100,1,14.56,800,2,12.5,700,1,14.6,700,1,12.46,200,2,14.68,1400,2,12.43,700,1,14.69,100,1,12.42,700,1,14.72,100,1,12.37,700,1,14.89,100,1
2025-07-17T15:58:15.563904700Z,2025-07-17T15:58:15.564070256Z,160,2,1108,A,A,0,14.87,100,130,165556,267672469,ARL,320504473,13.04,2,1,14.1,2,1,13.03,100,1,14.26,100,1,13.02,100,1,14.28,100,1,12.73,100,1,14.4,100,1,12.71,100,1,14.56,800,2,12.5,700,1,14.6,700,1,12.46,200,2,14.68,1400,2,12.43,700,1,14.69,100,1,12.42,700,1,14.72,100,1,12.37,700,1,14.87,100,1
2025-07-17T15:58:15.577554368Z,2025-07-17T15:58:15.577719796Z,160,2,1108,C,A,0,14.69,100,0,165428,267672549,ARL,320484825,13.04,2,1,14.1,2,1,13.03,100,1,14.26,100,1,13.02,100,1,14.28,100,1,12.73,100,1,14.4,100,1,12.71,100,1,14.56,800,2,12.5,700,1,14.6,700,1,12.46,200,2,14.68,1400,2,12.43,700,1,14.72,100,1,12.42,700,1,14.87,100,1,12.37,700,1,14.89,100,1
2025-07-17T15:58:15.577554368Z,2025-07-17T15:58:15.577719796Z,160,2,1108,A,A,0,14.88,100,130,165428,267672549,ARL,320504609,13.04,2,1,14.1,2,1,13.03,100,1,14.26,100,1,13.02,100,1,14.28,100,1,12.73,100,1,14.4,100,1,12.71,100,1,14.56,800,2,12.5,700,1,14.6,700,1,12.46,200,2,14.68,1400,2,12.43,700,1,14.72,100,1,12.42,700,1,14.87,100,1,12.37,700,1,14.88,100,1
2025-07-17T15:58:16.501915292Z,2025-07-17T15:58:16.502080515Z,160,2,1108,A,A,0,14.11,100,130,165223,267685252,ARL,320519893,13.04,2,1,14.1,2,1,13.03,100,1,14.11,100,1,13.02,100,1,14.26,100,1,12.73,100,1,14.28,100,1,12.71,100,1,14.4,100,1,12.5,700,1,14.56,800,2,12.46,200,2,14.6,700,1,12.43,700,1,14.68,1400,2,12.42,700,1,14.72,100,1,12.37,700,1,14.87,100,1
2025-07-17T15:58:19.965034325Z,2025-07-17T15:58:19.965200980Z,160,2,1108,A,A,0,13.94,15,130,166655,267738403,ARL,320588689,13.04,2,1,13.94,15,1,13.03,100,1,14.1,2,1,13.02,100,1,14.11,100,1,12.73,100,1,14.26,100,1,12.71,100,1,14.28,100,1,12.5,700,1,14.4,100,1,12.46,200,2,14.56,800,2,12.43,700,1,14.6,700,1,12.42,700,1,14.68,1400,2,12.37,700,1,14.72,100,1
2025-07-17T15:58:20.237668047Z,2025-07-17T15:58:20.237833402Z,160,2,1108,C,A,0,14.11,100,0,165355,267745213,ARL,320519893,13.04,2,1,13.94,15,1,13.03,100,1,14.1,2,1,13.02,100,1,14.26,100,1,12.73,100,1,14.28,100,1,12.71,100,1,14.4,100,1,12.5,700,1,14.56,800,2,12.46,200,2,14.6,700,1,12.43,700,1,14.68,1400,2,12.42,700,1,14.72,100,1,12.37,700,1,14.87,100,1
2025-07-17T15:58:20.237668047Z,2025-07-17T15:58:20.237833402Z,160,2,1108,A,A,0,13.95,100,130,165355,267745213,ARL,320595817,13.04,2,1,13.94,15,1,13.03,100,1,13.95,100,1,13.02,100,1,14.1,2,1,12.73,100,1,14.26,100,1,12.71,100,1,14.28,100,1,12.5,700,1,14.4,100,1,12.46,200,2,14.56,800,2,12.43,700,1,14.6,700,1,12.42,700,1,14.68,1400,2,12.37,700,1,14.72,100,1
2025-07-17T15:58:20.705344578Z,2025-07-17T15:58:20.705512171Z,160,2,1108,C,A,0,13.94,15,128,167593,267754327,ARL,320588689,13.04,2,1,13.95,100,1,13.03,100,1,14.1,2,1,13.02,100,1,14.26,100,1,12.73,100,1,14.28,100,1,12.71,100,1,14.4,100,1,12.5,700,1,14.56,800,2,12.46,200,2,14.6,700,1,12.43,700,1,14.68,1400,2,12.42,700,1,14.72,100,1,12.37,700,1,14.87,100,1
2025-07-17T15:58:30.799887713Z,2025-07-17T15:58:30.800053062Z,160,2,1108,A,A,0,13.89,15,130,165349,267913947,ARL,320833897,13.04,2,1,13.89,15,1,13.03,100,1,13.95,100,1,13.02,100,1,14.1,2,1,12.73,100,1,14.26,100,1,12.71,100,1,14.28,100,1,12.5,700,1,14.4,100,1,12.46,200,2,14.56,800,2,12.43,700,1,14.6,700,1,12.42,700,1,14.68,1400,2,12.37,700,1,14.72,100,1
2025-07-17T15:58:30.905491759Z,2025-07-17T15:58:30.905657319Z,160,2,1108,C,A,0,13.95,100,0,165560,267919515,ARL,320595817,13.04,2,1,13.89,15,1,13.03,100,1,14.1,2,1,13.02,100,1,14.26,100,1,12.73,100,1,14.28,100,1,12.71,100,1,14.4,100,1,12.5,700,1,14.56,800,2,12.46,200,2,14.6,700,1,12.43,700,1,14.68,1400,2,12.42,700,1,14.72,100,1,12.37,700,1,14.87,100,1
2025-07-17T15:58:30.905491759Z,2025-07-17T15:58:30.905657319Z,160,2,1108,A,A,0,13.9,100,130,165560,267919515,ARL,320839125,13.04,2,1,13.89,15,1,13.03,100,1,13.9,100,1,13.02,100,1,14.1,2,1,12.73,100,1,14.26,100,1,12.71,100,1,14.28,100,1,12.5,700,1,14.4,100,1,12.46,200,2,14.56,800,2,12.43,700,1,14.6,700,1,12.42,700,1,14.68,1400,2,12.37,700,1,14.72,100,1
2025-07-17T15:58:30.906246950Z,2025-07-17T15:58:30.906412286Z,160,2,1108,C,A,0,15.06,100,0,165336,267919540,ARL,320487357,13.04,2,1,13.89,15,1,13.03,100,1,13.9,100,1,13.02,100,1,14.1,2,1,12.73,100,1,14.26,100,1,12.71,100,1,14.28,100,1,12.5,700,1,14.4,100,1,12.46,200,2,14.56,800,2,12.43,700,1,14.6,700,1,12.42,700,1,14.68,1400,2,12.37,700,1,14.72,100,1
2025-07-17T15:58:30.906246950Z,2025-07-17T15:58:30.906412286Z,160,2,1108,A,A,0,14.98,100,130,165336,267919540,ARL,320839149,13.04,2,1,13.89,15,1,13.03,100,1,13.9,100,1,13.02,100,1,14.1,2,1,12.73,100,1,14.26,100,1,12.71,100,1,14.28,100,1,12.5,700,1,14.4,100,1,12.46,200,2,14.56,800,2,12.43,700,1,14.6,700,1,12.42,700,1,14.68,1400,2,12.37,700,1,14.72,100,1
2025-07-17T15:58:30.916561264Z,2025-07-17T15:58:30.916726353Z,160,2,1108,C,A,0,14.26,100,130,165089,267919917,ARL,320487025,13.04,2,1,13.89,15,1,13.03,100,1,13.9,100,1,13.02,100,1,14.1,2,1,12.73,100,1,14.28,100,1,12.71,100,1,14.4,100,1,12.5,700,1,14.56,800,2,12.46,200,2,14.6,700,1,12.43,700,1,14.68,1400,2,12.42,700,1,14.72,100,1,12.37,700,1,14.87,100,1
2025-07-17T15:58:30.916619122Z,2025-07-17T15:58:30.916784278Z,160,2,1108,A,A,0,14.18,100,130,165156,267919919,ARL,320839577,13.04,2,1,13.89,15,1,13.03,100,1,13.9,100,1,13.02,100,1,14.1,2,1,12.73,100,1,14.18,100,1,12.71,100,1,14.28,100,1,12.5,700,1,14.4,100,1,12.46,200,2,14.56,800,2,12.43,700,1,14.6,700,1,12.42,700,1,14.68,1400,2,12.37,700,1,14.72,100,1
2025-07-17T15:58:31.124222733Z,2025-07-17T15:58:31.124388717Z,160,2,1108,C,A,0,14.87,100,0,165984,267925564,ARL,320504473,13.04,2,1,13.89,15,1,13.03,100,1,13.9,100,1,13.02,100,1,14.1,2,1,12.73,100,1,14.18,100,1,12.71,100,1,14.28,100,1,12.5,700,1,14.4,100,1,12.46,200,2,14.56,800,2,12.43,700,1,14.6,700,1,12.42,700,1,14.68,1400,2,12.37,700,1,14.72,100,1
2025-07-17T15:58:31.124222733Z,2025-07-17T15:58:31.124388717Z,160,2,1108,A,A,0,14.76,100,130,165984,267925564,ARL,320845893,13.04,2,1,13.89,15,1,13.03,100,1,13.9,100,1,13.02,100,1,14.1,2,1,12.73,100,1,14.18,100,1,12.71,100,1,14.28,100,1,12.5,700,1,14.4,100,1,12.46,200,2,14.56,800,2,12.43,700,1,14.6,700,1,12.42,700,1,14.68,1400,2,12.37,700,1,14.72,100,1
2025-07-17T15:58:31.136273403Z,2025-07-17T15:58:31.136439248Z,160,2,1108,C,A,0,14.88,100,0,165845,267925951,ARL,320504609,13.04,2,1,13.89,15,1,13.03,100,1,13.9,100,1,13.02,100,1,14.1,2,1,12.73,100,1,14.18,100,1,12.71,100,1,14.28,100,1,12.5,700,1,14.4,100,1,12.46,200,2,14.56,800,2,12.43,700,1,14.6,700,1,12.42,700,1,14.68,1400,2,12.37,700,1,14.72,100,1
2025-07-17T15:58:31.136273403Z,2025-07-17T15:58:31.136439248Z,160,2,1108,A,A,0,14.77,100,130,165845,267925951,ARL,320846429,13.04,2,1,13.89,15,1,13.03,100,1,13.9,100,1,13.02,100,1,14.1,2,1,12.73,100,1,14.18,100,1,12.71,100,1,14.28,100,1,12.5,700,1,14.4,100,1,12.46,200,2,14.56,800,2,12.43,700,1,14.6,700,1,12.42,700,1,14.68,1400,2,12.37,700,1,14.72,100,1
2025-07-17T15:58:40.799787018Z,2025-07-17T15:58:40.799952243Z,160,2,1108,A,A,0,13.83,15,130,165225,268074431,ARL,321038033,13.04,2,1,13.83,15,1,13.03,100,1,13.89,15,1,13.02,100,1,13.9,100,1,12.73,100,1,14.1,2,1,12.71,100,1,14.18,100,1,12.5,700,1,14.28,100,1,12.46,200,2,14.4,100,1,12.43,700,1,14.56,800,2,12.42,700,1,14.6,700,1,12.37,700,1,14.68,1400,2
2025-07-17T15:58:43.690078924Z,2025-07-17T15:58:43.690244473Z,160,2,1108,C,A,0,13.9,100,0,165549,268115228,ARL,320839125,13.04,2,1,13.83,15,1,13.03,100,1,13.89,15,1,13.02,100,1,14.1,2,1,12.73,100,1,14.18,100,1,12.71,100,1,14.28,100,1,12.5,700,1,14.4,100,1,12.46,200,2,14.56,800,2,12.43,700,1,14.6,700,1,12.42,700,1,14.68,1400,2,12.37,700,1,14.72,100,1
2025-07-17T15:58:43.690078924Z,2025-07-17T15:58:43.690244473Z,160,2,1108,A,A,0,13.84,100,130,165549,268115228,ARL,321096769,13.04,2,1,13.83,15,1,13.03,100,1,13.84,100,1,13.02,100,1,13.89,15,1,12.73,100,1,14.1,2,1,12.71,100,1,14.18,100,1,12.5,700,1,14.28,100,1,12.46,200,2,14.4,100,1,12.43,700,1,14.56,800,2,12.42,700,1,14.6,700,1,12.37,700,1,14.68,1400,2
2025-07-17T15:58:43.690823184Z,2025-07-17T15:58:43.690988921Z,160,2,1108,C,A,0,14.98,100,0,165737,268115235,ARL,320839149,13.04,2,1,13.83,15,1,13.03,100,1,13.84,100,1,13.02,100,1,13.89,15,1,12.73,100,1,14.1,2,1,12.71,100,1,14.18,100,1,12.5,700,1,14.28,100,1,12.46,200,2,14.4,100,1,12.43,700,1,14.56,800,2,12.42,700,1,14.6,700,1,12.37,700,1,14.68,1400,2
2025-07-17T15:58:43.690823184Z,2025-07-17T15:58:43.690988921Z,160,2,1108,A,A,0,14.91,100,130,165737,268115235,ARL,321096793,13.04,2,1,13.83,15,1,13.03,100,1,13.84,100,1,13.02,100,1,13.89,15,1,12.73,100,1,14.1,2,1,12.71,100,1,14.18,100,1,12.5,700,1,14.28,100,1,12.46,200,2,14.4,100,1,12.43,700,1,14.56,800,2,12.42,700,1,14.6,700,1,12.37,700,1,14.68,1400,2
2025-07-17T15:58:43.693228946Z,2025-07-17T15:58:43.693394500Z,160,2,1108,C,A,0,17.76,100,0,165554,268115265,ARL,320486937,13.04,2,1,13.83,15,1,13.03,100,1,13.84,100,1,13.02,100,1,13.89,15,1,12.73,100,1,14.1,2,1,12.71,100,1,14.18,100,1,12.5,700,1,14.28,100,1,12.46,200,2,14.4,100,1,12.43,700,1,14.56,800,2,12.42,700,1,14.6,700,1,12.37,700,1,14.68,1400,2
2025-07-17T15:58:43.693228946Z,2025-07-17T15:58:43.693394500Z,160,2,1108,A,A,0,17.58,100,130,165554,268115265,ARL,321096825,13.04,2,1,13.83,15,1,13.03,100,1,13.84,100,1,13.02,100,1,13.89,15,1,12.73,100,1,14.1,2,1,12.71,100,1,14.18,100,1,12.5,700,1,14.28,100,1,12.46,200,2,14.4,100,1,12.43,700,1,14.56,800,2,12.42,700,1,14.6,700,1,12.37,700,1,14.68,1400,2
2025-07-17T15:58:43.694890264Z,2025-07-17T15:58:43.695055785Z,160,2,1108,C,A,0,16.08,100,0,165521,268115287,ARL,320486945,13.04,2,1,13.83,15,1,13.03,100,1,13.84,100,1,13.02,100,1,13.89,15,1,12.73,100,1,14.1,2,1,12.71,100,1,14.18,100,1,12.5,700,1,14.28,100,1,12.46,200,2,14.4,100,1,12.43,700,1,14.56,800,2,12.42,700,1,14.6,700,1,12.37,700,1,14.68,1400,2
2025-07-17T15:58:43.694890264Z,2025-07-17T15:58:43.695055785Z,160,2,1108,A,A,0,15.92,100,130,165521,268115287,ARL,321096889,13.04,2,1,13.83,15,1,13.03,100,1,13.84,100,1,13.02,100,1,13.89,15,1,12.73,100,1,14.1,2,1,12.71,100,1,14.18,100,1,12.5,700,1,14.28,100,1,12.46,200,2,14.4,100,1,12.43,700,1,14.56,800,2,12.42,700,1,14.6,700,1,12.37,700,1,14.68,1400,2
2025-07-17T15:58:43.716271172Z,2025-07-17T15:58:43.716437124Z,160,2,1108,C,A,0,14.96,100,0,165952,268115456,ARL,320487105,13.04,2,1,13.83,15,1,13.03,100,1,13.84,100,1,13.02,100,1,13.89,15,1,12.73,100,1,14.1,2,1,12.71,100,1,14.18,100,1,12.5,700,1,14.28,100,1,12.46,200,2,14.4,100,1,12.43,700,1,14.56,800,2,12.42,700,1,14.6,700,1,12.37,700,1,14.68,1400,2
2025-07-17T15:58:43.716271172Z,2025-07-17T15:58:43.716437124Z,160,2,1108,A,A,0,14.81,100,130,165952,268115456,ARL,321097197,13.04,2,1,13.83,15,1,13.03,100,1,13.84,100,1,13.02,100,1,13.89,15,1,12.73,100,1,14.1,2,1,12.71,100,1,14.18,100,1,12.5,700,1,14.28,100,1,12.46,200,2,14.4,100,1,12.43,700,1,14.56,800,2,12.42,700,1,14.6,700,1,12.37,700,1,14.68,1400,2
2025-07-17T15:58:44.903574654Z,2025-07-17T15:58:44.903740109Z,160,2,1108,A,A,0,13.83,100,130,165455,268129040,ARL,321114473,13.04,2,1,13.83,115,2,13.03,100,1,13.84,100,1,13.02,100,1,13.89,15,1,12.73,100,1,14.1,2,1,12.71,100,1,14.18,100,1,12.5,700,1,14.28,100,1,12.46,200,2,14.4,100,1,12.43,700,1,14.56,800,2,12.42,700,1,14.6,700,1,12.37,700,1,14.68,1400,2
2025-07-17T15:58:44.923948853Z,2025-07-17T15:58:44.924114268Z,160,2,1108,C,A,0,14.18,100,130,165415,268129217,ARL,320839577,13.04,2,1,13.83,115,2,13.03,100,1,13.84,100,1,13.02,100,1,13.89,15,1,12.73,100,1,14.1,2,1,12.71,100,1,14.28,100,1,12.5,700,1,14.4,100,1,12.46,200,2,14.56,800,2,12.43,700,1,14.6,700,1,12.42,700,1,14.68,1400,2,12.37,700,1,14.72,100,1
2025-07-17T15:58:44.924000519Z,2025-07-17T15:58:44.924165875Z,160,2,1108,A,A,0,14.11,100,130,165356,268129218,ARL,321114729,13.04,2,1,13.83,115,2,13.03,100,1,13.84,100,1,13.02,100,1,13.89,15,1,12.73,100,1,14.1,2,1,12.71,100,1,14.11,100,1,12.5,700,1,14.28,100,1,12.46,200,2,14.4,100,1,12.43,700,1,14.56,800,2,12.42,700,1,14.6,700,1,12.37,700,1,14.68,1400,2
2025-07-17T15:58:51.241176997Z,2025-07-17T15:58:51.241342265Z,160,2,1108,C,A,0,13.89,15,130,165268,268212338,ARL,320833897,13.04,2,1,13.83,115,2,13.03,100,1,13.84,100,1,13.02,100,1,14.1,2,1,12.73,100,1,14.11,100,1,12.71,100,1,14.28,100,1,12.5,700,1,14.4,100,1,12.46,200,2,14.56,800,2,12.43,700,1,14.6,700,1,12.42,700,1,14.68,1400,2,12.37,700,1,14.72,100,1
2025-07-17T15:58:51.253961905Z,2025-07-17T15:58:51.254127339Z,160,2,1108,A,A,0,13.8,100,130,165434,268212497,ARL,321225725,13.04,2,1,13.8,100,1,13.03,100,1,13.83,115,2,13.02,100,1,13.84,100,1,12.73,100,1,14.1,2,1,12.71,100,1,14.11,100,1,12.5,700,1,14.28,100,1,12.46,200,2,14.4,100,1,12.43,700,1,14.56,800,2,12.42,700,1,14.6,700,1,12.37,700,1,14.68,1400,2
2025-07-17T15:58:51.254706004Z,2025-07-17T15:58:51.254871890Z,160,2,1108,C,A,0,14.91,100,0,165886,268212499,ARL,321096793,13.04,2,1,13.8,100,1,13.03,100,1,13.83,115,2,13.02,100,1,13.84,100,1,12.73,100,1,14.1,2,1,12.71,100,1,14.11,100,1,12.5,700,1,14.28,100,1,12.46,200,2,14.4,100,1,12.43,700,1,14.56,800,2,12.42,700,1,14.6,700,1,12.37,700,1,14.68,1400,2
2025-07-17T15:58:51.254706004Z,2025-07-17T15:58:51.254871890Z,160,2,1108,A,A,0,14.87,100,130,165886,268212499,ARL,321225745,13.04,2,1,13.8,100,1,13.03,100,1,13.83,115,2,13.02,100,1,13.84,100,1,12.73,100,1,14.1,2,1,12.71,100,1,14.11,100,1,12.5,700,1,14.28,100,1,12.46,200,2,14.4,100,1,12.43,700,1,14.56,800,2,12.42,700,1,14.6,700,1,12.37,700,1,14.68,1400,2
2025-07-17T15:58:51.260587778Z,2025-07-17T15:58:51.260753179Z,160,2,1108,C,A,0,13.83,100,130,165401,268212534,ARL,321114473,13.04,2,1,13.8,100,1,13.03,100,1,13.83,15,1,13.02,100,1,13.84,100,1,12.73,100,1,14.1,2,1,12.71,100,1,14.11,100,1,12.5,700,1,14.28,100,1,12.46,200,2,14.4,100,1,12.43,700,1,14.56,800,2,12.42,700,1,14.6,700,1,12.37,700,1,14.68,1400,2
2025-07-17T15:58:53.579462029Z,2025-07-17T15:58:53.579628288Z,160,2,1108,C,A,0,13.83,15,130,166259,268250290,ARL,321038033,13.04,2,1,13.8,100,1,13.03,100,1,13.84,100,1,13.02,100,1,14.1,2,1,12.73,100,1,14.11,100,1,12.71,100,1,14.28,100,1,12.5,700,1,14.4,100,1,12.46,200,2,14.56,800,2,12.43,700,1,14.6,700,1,12.42,700,1,14.68,1400,2,12.37,700,1,14.72,100,1
2025-07-17T15:58:53.580052014Z,2025-07-17T15:58:53.580217445Z,160,2,1108,C,A,0,13.84,100,0,165431,268250346,ARL,321096769,13.04,2,1,13.8,100,1,13.03,100,1,14.1,2,1,13.02,100,1,14.11,100,1,12.73,100,1,14.28,100,1,12.71,100,1,14.4,100,1,12.5,700,1,14.56,800,2,12.46,200,2,14.6,700,1,12.43,700,1,14.68,1400,2,12.42,700,1,14.72,100,1,12.37,700,1,14.76,100,1
2025-07-17T15:58:53.580052014Z,2025-07-17T15:58:53.580217445Z,160,2,1108,A,A,0,13.81,100,130,165431,268250346,ARL,321272581,13.04,2,1,13.8,100,1,13.03,100,1,13.81,100,1,13.02,100,1,14.1,2,1,12.73,100,1,14.11,100,1,12.71,100,1,14.28,100,1,12.5,700,1,14.4,100,1,12.46,200,2,14.56,800,2,12.43,700,1,14.6,700,1,12.42,700,1,14.68,1400,2,12.37,700,1,14.72,100,1
2025-07-17T15:58:54.583958582Z,2025-07-17T15:58:54.584124215Z,160,2,1108,C,A,0,14.77,100,0,165633,268265585,ARL,320846429,13.04,2,1,13.8,100,1,13.03,100,1,13.81,100,1,13.02,100,1,14.1,2,1,12.73,100,1,14.11,100,1,12.71,100,1,14.28,100,1,12.5,700,1,14.4,100,1,12.46,200,2,14.56,800,2,12.43,700,1,14.6,700,1,12.42,700,1,14.68,1400,2,12.37,700,1,14.72,100,1
2025-07-17T15:58:54.583958582Z,2025-07-17T15:58:54.584124215Z,160,2,1108,A,A,0,14.65,100,130,165633,268265585,ARL,321293737,13.04,2,1,13.8,100,1,13.03,100,1,13.81,100,1,13.02,100,1,14.1,2,1,12.73,100,1,14.11,100,1,12.71,100,1,14.28,100,1,12.5,700,1,14.4,100,1,12.46,200,2,14.56,800,2,12.43,700,1,14.6,700,1,12.42,700,1,14.65,100,1,12.37,700,1,14.68,1400,2
2025-07-17T15:58:54.584094980Z,2025-07-17T15:58:54.584260712Z,160,2,1108,C,A,0,14.76,100,0,165732,268265586,ARL,320845893,13.04,2,1,13.8,100,1,13.03,100,1,13.81,100,1,13.02,100,1,14.1,2,1,12.73,100,1,14.11,100,1,12.71,100,1,14.28,100,1,12.5,700,1,14.4,100,1,12.46,200,2,14.56,800,2,12.43,700,1,14.6,700,1,12.42,700,1,14.65,100,1,12.37,700,1,14.68,1400,2
2025-07-17T15:58:54.584094980Z,2025-07-17T15:58:54.584260712Z,160,2,1108,A,A,0,14.64,100,130,165732,268265586,ARL,321293741,13.04,2,1,13.8,100,1,13.03,100,1,13.81,100,1,13.02,100,1,14.1,2,1,12.73,100,1,14.11,100,1,12.71,100,1,14.28,100,1,12.5,700,1,14.4,100,1,12.46,200,2,14.56,800,2,12.43,700,1,14.6,700,1,12.42,700,1,14.64,100,1,12.37,700,1,14.65,100,1
2025-07-17T15:58:55.304938318Z,2025-07-17T15:58:55.305104029Z,160,2,1108,A,A,0,13.78,100,130,165711,268277940,ARL,321309865,13.04,2,1,13.78,100,1,13.03,100,1,13.8,100,1,13.02,100,1,13.81,100,1,12.73,100,1,14.1,2,1,12.71,100,1,14.11,100,1,12.5,700,1,14.28,100,1,12.46,200,2,14.4,100,1,12.43,700,1,14.56,800,2,12.42,700,1,14.6,700,1,12.37,700,1,14.64,100,1
2025-07-17T15:58:55.307342971Z,2025-07-17T15:58:55.307508305Z,160,2,1108,C,A,0,14.72,100,130,165334,268277999,ARL,312772061,13.04,2,1,13.78,100,1,13.03,100,1,13.8,100,1,13.02,100,1,13.81,100,1,12.73,100,1,14.1,2,1,12.71,100,1,14.11,100,1,12.5,700,1,14.28,100,1,12.46,200,2,14.4,100,1,12.43,700,1,14.56,800,2,12.42,700,1,14.6,700,1,12.37,700,1,14.64,100,1
2025-07-17T15:58:55.307472032Z,2025-07-17T15:58:55.307637209Z,160,2,1108,A,A,0,14.58,100,130,165177,268278004,ARL,321309941,13.04,2,1,13.78,100,1,13.03,100,1,13.8,100,1,13.02,100,1,13.81,100,1,12.73,100,1,14.1,2,1,12.71,100,1,14.11,100,1,12.5,700,1,14.28,100,1,12.46,200,2,14.4,100,1,12.43,700,1,14.56,800,2,12.42,700,1,14.58,100,1,12.37,700,1,14.6,700,1
2025-07-17T15:58:55.311734700Z,2025-07-17T15:58:55.311899965Z,160,2,1108,C,A,0,13.8,100,130,165265,268278030,ARL,321225725,13.04,2,1,13.78,100,1,13.03,100,1,13.81,100,1,13.02,100,1,14.1,2,1,12.73,100,1,14.11,100,1,12.71,100,1,14.28,100,1,12.5,700,1,14.4,100,1,12.46,200,2,14.56,800,2,12.43,700,1,14.58,100,1,12.42,700,1,14.6,700,1,12.37,700,1,14.64,100,1
2025-07-17T15:58:58.668086788Z,2025-07-17T15:58:58.668252306Z,160,2,1108,C,A,0,13.81,100,0,165518,268321684,ARL,321272581,13.04,2,1,13.78,100,1,13.03,100,1,14.1,2,1,13.02,100,1,14.11,100,1,12.73,100,1,14.28,100,1,12.71,100,1,14.4,100,1,12.5,700,1,14.56,800,2,12.46,200,2,14.58,100,1,12.43,700,1,14.6,700,1,12.42,700,1,14.64,100,1,12.37,700,1,14.65,100,1
2025-07-17T15:58:58.668086788Z,2025-07-17T15:58:58.668252306Z,160,2,1108,A,A,0,13.79,100,130,165518,268321684,ARL,321364281,13.04,2,1,13.78,100,1,13.03,100,1,13.79,100,1,13.02,100,1,14.1,2,1,12.73,100,1,14.11,100,1,12.71,100,1,14.28,100,1,12.5,700,1,14.4,100,1,12.46,200,2,14.56,800,2,12.43,700,1,14.58,100,1,12.42,700,1,14.6,700,1,12.37,700,1,14.64,100,1
2025-07-17T15:59:03.613527621Z,2025-07-17T15:59:03.613692913Z,160,2,1108,A,A,0,13.72,15,130,165292,268437919,ARL,321500117,13.04,2,1,13.72,15,1,13.03,100,1,13.78,100,1,13.02,100,1,13.79,100,1,12.73,100,1,14.1,2,1,12.71,100,1,14.11,100,1,12.5,700,1,14.28,100,1,12.46,200,2,14.4,100,1,12.43,700,1,14.56,800,2,12.42,700,1,14.58,100,1,12.37,700,1,14.6,700,1
2025-07-17T15:59:03.626181384Z,2025-07-17T15:59:03.626346616Z,160,2,1108,A,A,0,13.76,100,130,165232,268438110,ARL,321500317,13.04,2,1,13.72,15,1,13.03,100,1,13.76,100,1,13.02,100,1,13.78,100,1,12.73,100,1,13.79,100,1,12.71,100,1,14.1,2,1,12.5,700,1,14.11,100,1,12.46,200,2,14.28,100,1,12.43,700,1,14.4,100,1,12.42,700,1,14.56,800,2,12.37,700,1,14.58,100,1
2025-07-17T15:59:03.626920954Z,2025-07-17T15:59:03.627086888Z,160,2,1108,C,A,0,14.87,100,0,165934,268438112,ARL,321225745,13.04,2,1,13.72,15,1,13.03,100,1,13.76,100,1,13.02,100,1,13.78,100,1,12.73,100,1,13.79,100,1,12.71,100,1,14.1,2,1,12.5,700,1,14.11,100,1,12.46,200,2,14.28,100,1,12.43,700,1,14.4,100,1,12.42,700,1,14.56,800,2,12.37,700,1,14.58,100,1
2025-07-17T15:59:03.626920954Z,2025-07-17T15:59:03.627086888Z,160,2,1108,A,A,0,14.83,100,130,165934,268438112,ARL,321500333,13.04,2,1,13.72,15,1,13.03,100,1,13.76,100,1,13.02,100,1,13.78,100,1,12.73,100,1,13.79,100,1,12.71,100,1,14.1,2,1,12.5,700,1,14.11,100,1,12.46,200,2,14.28,100,1,12.43,700,1,14.4,100,1,12.42,700,1,14.56,800,2,12.37,700,1,14.58,100,1
2025-07-17T15:59:03.628779364Z,2025-07-17T15:59:03.628945278Z,160,2,1108,C,A,0,14.89,100,0,165914,268438129,ARL,312771785,13.04,2,1,13.72,15,1,13.03,100,1,13.76,100,1,13.02,100,1,13.78,100,1,12.73,100,1,13.79,100,1,12.71,100,1,14.1,2,1,12.5,700,1,14.11,100,1,12.46,200,2,14.28,100,1,12.43,700,1,14.4,100,1,12.42,700,1,14.56,800,2,12.37,700,1,14.58,100,1
2025-07-17T15:59:03.628779364Z,2025-07-17T15:59:03.628945278Z,160,2,1108,A,A,0,14.73,100,130,165914,268438129,ARL,321500349,13.04,2,1,13.72,15,1,13.03,100,1,13.76,100,1,13.02,100,1,13.78,100,1,12.73,100,1,13.79,100,1,12.71,100,1,14.1,2,1,12.5,700,1,14.11,100,1,12.46,200,2,14.28,100,1,12.43,700,1,14.4,100,1,12.42,700,1,14.56,800,2,12.37,700,1,14.58,100,1
2025-07-17T15:59:03.632928023Z,2025-07-17T15:59:03.633093258Z,160,2,1108,C,A,0,13.78,100,130,165235,268438149,ARL,321309865,13.04,2,1,13.72,15,1,13.03,100,1,13.76,100,1,13.02,100,1,13.79,100,1,12.73,100,1,14.1,2,1,12.71,100,1,14.11,100,1,12.5,700,1,14.28,100,1,12.46,200,2,14.4,100,1,12.43,700,1,14.56,800,2,12.42,700,1,14.58,100,1,12.37,700,1,14.6,700,1
2025-07-17T15:59:03.649116452Z,2025-07-17T15:59:03.649282063Z,160,2,1108,C,A,0,14.11,100,130,165611,268438330,ARL,321114729,13.04,2,1,13.72,15,1,13.03,100,1,13.76,100,1,13.02,100,1,13.79,100,1,12.73,100,1,14.1,2,1,12.71,100,1,14.28,100,1,12.5,700,1,14.4,100,1,12.46,200,2,14.56,800,2,12.43,700,1,14.58,100,1,12.42,700,1,14.6,700,1,12.37,700,1,14.64,100,1
2025-07-17T15:59:03.649167617Z,2025-07-17T15:59:03.649332873Z,160,2,1108,A,A,0,14.04,100,130,165256,268438331,ARL,321500957,13.04,2,1,13.72,15,1,13.03,100,1,13.76,100,1,13.02,100,1,13.79,100,1,12.73,100,1,14.04,100,1,12.71,100,1,14.1,2,1,12.5,700,1,14.28,100,1,12.46,200,2,14.4,100,1,12.43,700,1,14.56,800,2,12.42,700,1,14.58,100,1,12.37,700,1,14.6,700,1
2025-07-17T15:59:04.223835151Z,2025-07-17T15:59:04.224000805Z,160,2,1108,C,A,0,13.79,100,0,165654,268447989,ARL,321364281,13.04,2,1,13.72,15,1,13.03,100,1,13.76,100,1,13.02,100,1,14.04,100,1,12.73,100,1,14.1,2,1,12.71,100,1,14.28,100,1,12.5,700,1,14.4,100,1,12.46,200,2,14.56,800,2,12.43,700,1,14.58,100,1,12.42,700,1,14.6,700,1,12.37,700,1,14.64,100,1
2025-07-17T15:59:04.223835151Z,2025-07-17T15:59:04.224000805Z,160,2,1108,A,A,0,13.73,100,130,165654,268447989,ARL,321511377,13.04,2,1,13.72,15,1,13.03,100,1,13.73,100,1,13.02,100,1,13.76,100,1,12.73,100,1,14.04,100,1,12.71,100,1,14.1,2,1,12.5,700,1,14.28,100,1,12.46,200,2,14.4,100,1,12.43,700,1,14.56,800,2,12.42,700,1,14.58,100,1,12.37,700,1,14.6,700,1
2025-07-17T15:59:04.224583946Z,2025-07-17T15:59:04.224749333Z,160,2,1108,C,A,0,14.83,100,0,165387,268448014,ARL,321500333,13.04,2,1,13.72,15,1,13.03,100,1,13.73,100,1,13.02,100,1,13.76,100,1,12.73,100,1,14.04,100,1,12.71,100,1,14.1,2,1,12.5,700,1,14.28,100,1,12.46,200,2,14.4,100,1,12.43,700,1,14.56,800,2,12.42,700,1,14.58,100,1,12.37,700,1,14.6,700,1
2025-07-17T15:59:04.224583946Z,2025-07-17T15:59:04.224749333Z,160,2,1108,A,A,0,14.79,100,130,165387,268448014,ARL,321511477,13.04,2,1,13.72,15,1,13.03,100,1,13.73,100,1,13.02,100,1,13.76,100,1,12.73,100,1,14.04,100,1,12.71,100,1,14.1,2,1,12.5,700,1,14.28,100,1,12.46,200,2,14.4,100,1,12.43,700,1,14.56,800,2,12.42,700,1,14.58,100,1,12.37,700,1,14.6,700,1
2025-07-17T15:59:04.799833206Z,2025-07-17T15:59:04.799998642Z,160,2,1108,C,A,0,13.72,15,130,165436,268457531,ARL,321500117,13.04,2,1,13.73,100,1,13.03,100,1,13.76,100,1,13.02,100,1,14.04,100,1,12.73,100,1,14.1,2,1,12.71,100,1,14.28,100,1,12.5,700,1,14.4,100,1,12.46,200,2,14.56,800,2,12.43,700,1,14.58,100,1,12.42,700,1,14.6,700,1,12.37,700,1,14.64,100,1
2025-07-17T16:00:13.989771852Z,2025-07-17T16:00:13.989937414Z,160,2,1108,C,A,0,14.1,2,0,165562,269514876,ARL,316098525,13.04,2,1,13.73,100,1,13.03,100,1,13.76,100,1,13.02,100,1,14.04,100,1,12.73,100,1,14.28,100,1,12.71,100,1,14.4,100,1,12.5,700,1,14.56,800,2,12.46,200,2,14.58,100,1,12.43,700,1,14.6,700,1,12.42,700,1,14.64,100,1,12.37,700,1,14.65,100,1
2025-07-17T16:00:13.989771852Z,2025-07-17T16:00:13.989937414Z,160,2,1108,A,A,0,14.01,2,130,165562,269514876,ARL,322898193,13.04,2,1,13.73,100,1,13.03,100,1,13.76,100,1,13.02,100,1,14.01,2,1,12.73,100,1,14.04,100,1,12.71,100,1,14.28,100,1,12.5,700,1,14.4,100,1,12.46,200,2,14.56,800,2,12.43,700,1,14.58,100,1,12.42,700,1,14.6,700,1,12.37,700,1,14.64,100,1
2025-07-17T16:00:28.802849928Z,2025-07-17T16:00:28.803015930Z,160,2,1108,A,A,0,13.72,15,130,166002,269765653,ARL,323238809,13.04,2,1,13.72,15,1,13.03,100,1,13.73,100,1,13.02,100,1,13.76,100,1,12.73,100,1,14.01,2,1,12.71,100,1,14.04,100,1,12.5,700,1,14.28,100,1,12.46,200,2,14.4,100,1,12.43,700,1,14.56,800,2,12.42,700,1,14.58,100,1,12.37,700,1,14.6,700,1
2025-07-17T16:00:32.549247168Z,2025-07-17T16:00:32.549412616Z,160,2,1108,A,A,0,13.74,100,130,165448,269878282,ARL,323370569,13.04,2,1,13.72,15,1,13.03,100,1,13.73,100,1,13.02,100,1,13.74,100,1,12.73,100,1,13.76,100,1,12.71,100,1,14.01,2,1,12.5,700,1,14.04,100,1,12.46,200,2,14.28,100,1,12.43,700,1,14.4,100,1,12.42,700,1,14.56,800,2,12.37,700,1,14.58,100,1
2025-07-17T16:00:32.560823786Z,2025-07-17T16:00:32.560989093Z,160,2,1108,C,A,0,13.76,100,130,165307,269878639,ARL,321500317,13.04,2,1,13.72,15,1,13.03,100,1,13.73,100,1,13.02,100,1,13.74,100,1,12.73,100,1,14.01,2,1,12.71,100,1,14.04,100,1,12.5,700,1,14.28,100,1,12.46,200,2,14.4,100,1,12.43,700,1,14.56,800,2,12.42,700,1,14.58,100,1,12.37,700,1,14.6,700,1
2025-07-17T16:00:35.512999155Z,2025-07-17T16:00:35.513164458Z,160,2,1108,A,A,0,13.69,15,130,165303,269940539,ARL,323455221,13.04,2,1,13.69,15,1,13.03,100,1,13.72,15,1,13.02,100,1,13.73,100,1,12.73,100,1,13.74,100,1,12.71,100,1,14.01,2,1,12.5,700,1,14.04,100,1,12.46,200,2,14.28,100,1,12.43,700,1,14.4,100,1,12.42,700,1,14.56,800,2,12.37,700,1,14.58,100,1
2025-07-17T16:00:42.614063415Z,2025-07-17T16:00:42.614229184Z,160,2,1108,C,A,0,13.73,100,0,165769,270051089,ARL,321511377,13.04,2,1,13.69,15,1,13.03,100,1,13.72,15,1,13.02,100,1,13.74,100,1,12.73,100,1,14.01,2,1,12.71,100,1,14.04,100,1,12.5,700,1,14.28,100,1,12.46,200,2,14.4,100,1,12.43,700,1,14.56,800,2,12.42,700,1,14.58,100,1,12.37,700,1,14.6,700,1
2025-07-17T16:00:42.614063415Z,2025-07-17T16:00:42.614229184Z,160,2,1108,A,A,0,13.7,100,130,165769,270051089,ARL,323599605,13.04,2,1,13.69,15,1,13.03,100,1,13.7,100,1,13.02,100,1,13.72,15,1,12.73,100,1,13.74,100,1,12.71,100,1,14.01,2,1,12.5,700,1,14.04,100,1,12.46,200,2,14.28,100,1,12.43,700,1,14.4,100,1,12.42,700,1,14.56,800,2,12.37,700,1,14.58,100,1
2025-07-17T16:00:42.614088947Z,2025-07-17T16:00:42.614254199Z,160,2,1108,A,A,0,13.72,100,130,165252,270051090,ARL,323599609,13.04,2,1,13.69,15,1,13.03,100,1,13.7,100,1,13.02,100,1,13.72,115,2,12.73,100,1,13.74,100,1,12.71,100,1,14.01,2,1,12.5,700,1,14.04,100,1,12.46,200,2,14.28,100,1,12.43,700,1,14.4,100,1,12.42,700,1,14.56,800,2,12.37,700,1,14.58,100,1
2025-07-17T16:00:42.614231125Z,2025-07-17T16:00:42.614396214Z,160,2,1108,C,A,0,13.74,100,130,165089,270051092,ARL,323370569,13.04,2,1,13.69,15,1,13.03,100,1,13.7,100,1,13.02,100,1,13.72,115,2,12.73,100,1,14.01,2,1,12.71,100,1,14.04,100,1,12.5,700,1,14.28,100,1,12.46,200,2,14.4,100,1,12.43,700,1,14.56,800,2,12.42,700,1,14.58,100,1,12.37,700,1,14.6,700,1
2025-07-17T16:00:42.616013371Z,2025-07-17T16:00:42.616178962Z,160,2,1108,C,A,0,14.81,100,0,165591,270051093,ARL,321097197,13.04,2,1,13.69,15,1,13.03,100,1,13.7,100,1,13.02,100,1,13.72,115,2,12.73,100,1,14.01,2,1,12.71,100,1,14.04,100,1,12.5,700,1,14.28,100,1,12.46,200,2,14.4,100,1,12.43,700,1,14.56,800,2,12.42,700,1,14.58,100,1,12.37,700,1,14.6,700,1
2025-07-17T16:00:42.616013371Z,2025-07-17T16:00:42.616178962Z,160,2,1108,A,A,0,14.66,100,130,165591,270051093,ARL,323599625,13.04,2,1,13.69,15,1,13.03,100,1,13.7,100,1,13.02,100,1,13.72,115,2,12.73,100,1,14.01,2,1,12.71,100,1,14.04,100,1,12.5,700,1,14.28,100,1,12.46,200,2,14.4,100,1,12.43,700,1,14.56,800,2,12.42,700,1,14.58,100,1,12.37,700,1,14.6,700,1
2025-07-17T16:00:42.616156310Z,2025-07-17T16:00:42.616321879Z,160,2,1108,C,A,0,15.92,100,0,165569,270051094,ARL,321096889,13.04,2,1,13.69,15,1,13.03,100,1,13.7,100,1,13.02,100,1,13.72,115,2,12.73,100,1,14.01,2,1,12.71,100,1,14.04,100,1,12.5,700,1,14.28,100,1,12.46,200,2,14.4,100,1,12.43,700,1,14.56,800,2,12.42,700,1,14.58,100,1,12.37,700,1,14.6,700,1
2025-07-17T16:00:42.616156310Z,2025-07-17T16:00:42.616321879Z,160,2,1108,A,A,0,15.76,100,130,165569,270051094,ARL,323599629,13.04,2,1,13.69,15,1,13.03,100,1,13.7,100,1,13.02,100,1,13.72,115,2,12.73,100,1,14.01,2,1,12.71,100,1,14.04,100,1,12.5,700,1,14.28,100,1,12.46,200,2,14.4,100,1,12.43,700,1,14.56,800,2,12.42,700,1,14.58,100,1,12.37,700,1,14.6,700,1
2025-07-17T16:00:42.616186901Z,2025-07-17T16:00:42.616352247Z,160,2,1108,C,A,0,17.58,100,0,165346,270051095,ARL,321096825,13.04,2,1,13.69,15,1,13.03,100,1,13.7,100,1,13.02,100,1,13.72,115,2,12.73,100,1,14.01,2,1,12.71,100,1,14.04,100,1,12.5,700,1,14.28,100,1,12.46,200,2,14.4,100,1,12.43,700,1,14.56,800,2,12.42,700,1,14.58,100,1,12.37,700,1,14.6,700,1
2025-07-17T16:00:42.616186901Z,2025-07-17T16:00:42.616352247Z,160,2,1108,A,A,0,17.4,100,130,165346,270051095,ARL,323599633,13.04,2,1,13.69,15,1,13.03,100,1,13.7,100,1,13.02,100,1,13.72,115,2,12.73,100,1,14.01,2,1,12.71,100,1,14.04,100,1,12.5,700,1,14.28,100,1,12.46,200,2,14.4,100,1,12.43,700,1,14.56,800,2,12.42,700,1,14.58,100,1,12.37,700,1,14.6,700,1
2025-07-17T16:00:42.636595817Z,2025-07-17T16:00:42.636761176Z,160,2,1108,C,A,0,14.04,100,130,165359,270051179,ARL,321500957,13.04,2,1,13.69,15,1,13.03,100,1,13.7,100,1,13.02,100,1,13.72,115,2,12.73,100,1,14.01,2,1,12.71,100,1,14.28,100,1,12.5,700,1,14.4,100,1,12.46,200,2,14.56,800,2,12.43,700,1,14.58,100,1,12.42,700,1,14.6,700,1,12.37,700,1,14.64,100,1
2025-07-17T16:00:42.636649389Z,2025-07-17T16:00:42.636814704Z,160,2,1108,A,A,0,13.97,100,130,165315,270051181,ARL,323599765,13.04,2,1,13.69,15,1,13.03,100,1,13.7,100,1,13.02,100,1,13.72,115,2,12.73,100,1,13.97,100,1,12.71,100,1,14.01,2,1,12.5,700,1,14.28,100,1,12.46,200,2,14.4,100,1,12.43,700,1,14.56,800,2,12.42,700,1,14.58,100,1,12.37,700,1,14.6,700,1
2025-07-17T16:00:46.803097192Z,2025-07-17T16:00:46.803262460Z,160,2,1108,C,A,0,13.72,15,130,165268,270102799,ARL,323238809,13.04,2,1,13.69,15,1,13.03,100,1,13.7,100,1,13.02,100,1,13.72,100,1,12.73,100,1,13.97,100,1,12.71,100,1,14.01,2,1,12.5,700,1,14.28,100,1,12.46,200,2,14.4,100,1,12.43,700,1,14.56,800,2,12.42,700,1,14.58,100,1,12.37,700,1,14.6,700,1
2025-07-17T16:00:49.255465939Z,2025-07-17T16:00:49.255631264Z,160,2,1108,A,A,0,13.66,15,130,165325,270140405,ARL,323720189,13.04,2,1,13.66,15,1,13.03,100,1,13.69,15,1,13.02,100,1,13.7,100,1,12.73,100,1,13.72,100,1,12.71,100,1,13.97,100,1,12.5,700,1,14.01,2,1,12.46,200,2,14.28,100,1,12.43,700,1,14.4,100,1,12.42,700,1,14.56,800,2,12.37,700,1,14.58,100,1
2025-07-17T16:00:49.739479408Z,2025-07-17T16:00:49.739644604Z,160,2,1108,A,A,0,13.7,100,130,165196,270146528,ARL,323730309,13.04,2,1,13.66,15,1,13.03,100,1,13.69,15,1,13.02,100,1,13.7,200,2,12.73,100,1,13.72,100,1,12.71,100,1,13.97,100,1,12.5,700,1,14.01,2,1,12.46,200,2,14.28,100,1,12.43,700,1,14.4,100,1,12.42,700,1,14.56,800,2,12.37,700,1,14.58,100,1
2025-07-17T16:00:49.744872763Z,2025-07-17T16:00:49.745038261Z,160,2,1108,C,A,0,13.7,100,0,165498,270146577,ARL,323599605,13.04,2,1,13.66,15,1,13.03,100,1,13.69,15,1,13.02,100,1,13.7,100,1,12.73,100,1,13.72,100,1,12.71,100,1,13.97,100,1,12.5,700,1,14.01,2,1,12.46,200,2,14.28,100,1,12.43,700,1,14.4,100,1,12.42,700,1,14.56,800,2,12.37,700,1,14.58,100,1
2025-07-17T16:00:49.744872763Z,2025-07-17T16:00:49.745038261Z,160,2,1108,A,A,0,13.67,100,130,165498,270146577,ARL,323730353,13.04,2,1,13.66,15,1,13.03,100,1,13.67,100,1,13.02,100,1,13.69,15,1,12.73,100,1,13.7,100,1,12.71,100,1,13.72,100,1,12.5,700,1,13.97,100,1,12.46,200,2,14.01,2,1,12.43,700,1,14.28,100,1,12.42,700,1,14.4,100,1,12.37,700,1,14.56,800,2
2025-07-17T16:00:49.745613051Z,2025-07-17T16:00:49.745778725Z,160,2,1108,C,A,0,14.79,100,0,165674,270146581,ARL,321511477,13.04,2,1,13.66,15,1,13.03,100,1,13.67,100,1,13.02,100,1,13.69,15,1,12.73,100,1,13.7,100,1,12.71,100,1,13.72,100,1,12.5,700,1,13.97,100,1,12.46,200,2,14.01,2,1,12.43,700,1,14.28,100,1,12.42,700,1,14.4,100,1,12.37,700,1,14.56,800,2
2025-07-17T16:00:49.745613051Z,2025-07-17T16:00:49.745778725Z,160,2,1108,A,A,0,14.73,100,130,165674,270146581,ARL,323730369,13.04,2,1,13.66,15,1,13.03,100,1,13.67,100,1,13.02,100,1,13.69,15,1,12.73,100,1,13.7,100,1,12.71,100,1,13.72,100,1,12.5,700,1,13.97,100,1,12.46,200,2,14.01,2,1,12.43,700,1,14.28,100,1,12.42,700,1,14.4,100,1,12.37,700,1,14.56,800,2
2025-07-17T16:00:49.746256906Z,2025-07-17T16:00:49.746422142Z,160,2,1108,C,A,0,13.72,100,130,165236,270146586,ARL,323599609,13.04,2,1,13.66,15,1,13.03,100,1,13.67,100,1,13.02,100,1,13.69,15,1,12.73,100,1,13.7,100,1,12.71,100,1,13.97,100,1,12.5,700,1,14.01,2,1,12.46,200,2,14.28,100,1,12.43,700,1,14.4,100,1,12.42,700,1,14.56,800,2,12.37,700,1,14.58,100,1
2025-07-17T16:00:49.772466772Z,2025-07-17T16:00:49.772631967Z,160,2,1108,A,A,0,15.59,100,130,165195,270146838,ARL,323730697,13.04,2,1,13.66,15,1,13.03,100,1,13.67,100,1,13.02,100,1,13.69,15,1,12.73,100,1,13.7,100,1,12.71,100,1,13.97,100,1,12.5,700,1,14.01,2,1,12.46,200,2,14.28,100,1,12.43,700,1,14.4,100,1,12.42,700,1,14.56,800,2,12.37,700,1,14.58,100,1
2025-07-17T16:00:49.772479921Z,2025-07-17T16:00:49.772645303Z,160,2,1108,C,A,0,15.86,100,130,165382,270146839,ARL,312771645,13.04,2,1,13.66,15,1,13.03,100,1,13.67,100,1,13.02,100,1,13.69,15,1,12.73,100,1,13.7,100,1,12.71,100,1,13.97,100,1,12.5,700,1,14.01,2,1,12.46,200,2,14.28,100,1,12.43,700,1,14.4,100,1,12.42,700,1,14.56,800,2,12.37,700,1,14.58,100,1
2025-07-17T16:00:51.624646272Z,2025-07-17T16:00:51.624811889Z,160,2,1108,C,A,0,14.65,100,0,165617,270181394,ARL,321293737,13.04,2,1,13.66,15,1,13.03,100,1,13.67,100,1,13.02,100,1,13.69,15,1,12.73,100,1,13.7,100,1,12.71,100,1,13.97,100,1,12.5,700,1,14.01,2,1,12.46,200,2,14.28,100,1,12.43,700,1,14.4,100,1,12.42,700,1,14.56,800,2,12.37,700,1,14.58,100,1
2025-07-17T16:00:51.624646272Z,2025-07-17T16:00:51.624811889Z,160,2,1108,A,A,0,14.54,100,130,165617,270181394,ARL,323775433,13.04,2,1,13.66,15,1,13.03,100,1,13.67,100,1,13.02,100,1,13.69,15,1,12.73,100,1,13.7,100,1,12.71,100,1,13.97,100,1,12.5,700,1,14.01,2,1,12.46,200,2,14.28,100,1,12.43,700,1,14.4,100,1,12.42,700,1,14.54,100,1,12.37,700,1,14.56,800,2
2025-07-17T16:00:51.625206675Z,2025-07-17T16:00:51.625372516Z,160,2,1108,C,A,0,14.64,100,0,165841,270181399,ARL,321293741,13.04,2,1,13.66,15,1,13.03,100,1,13.67,100,1,13.02,100,1,13.69,15,1,12.73,100,1,13.7,100,1,12.71,100,1,13.97,100,1,12.5,700,1,14.01,2,1,12.46,200,2,14.28,100,1,12.43,700,1,14.4,100,1,12.42,700,1,14.54,100,1,12.37,700,1,14.56,800,2
2025-07-17T16:00:51.625206675Z,2025-07-17T16:00:51.625372516Z,160,2,1108,A,A,0,14.53,100,130,165841,270181399,ARL,323775457,13.04,2,1,13.66,15,1,13.03,100,1,13.67,100,1,13.02,100,1,13.69,15,1,12.73,100,1,13.7,100,1,12.71,100,1,13.97,100,1,12.5,700,1,14.01,2,1,12.46,200,2,14.28,100,1,12.43,700,1,14.4,100,1,12.42,700,1,14.53,100,1,12.37,700,1,14.54,100,1
2025-07-17T16:00:53.749169565Z,2025-07-17T16:00:53.749335010Z,160,2,1108,A,A,0,13.67,100,130,165445,270204567,ARL,323803301,13.04,2,1,13.66,15,1,13.03,100,1,13.67,200,2,13.02,100,1,13.69,15,1,12.73,100,1,13.7,100,1,12.71,100,1,13.97,100,1,12.5,700,1,14.01,2,1,12.46,200,2,14.28,100,1,12.43,700,1,14.4,100,1,12.42,700,1,14.53,100,1,12.37,700,1,14.54,100,1
2025-07-17T16:00:53.755801462Z,2025-07-17T16:00:53.755966680Z,160,2,1108,C,A,0,13.7,100,130,165218,270204616,ARL,323730309,13.04,2,1,13.66,15,1,13.03,100,1,13.67,200,2,13.02,100,1,13.69,15,1,12.73,100,1,13.97,100,1,12.71,100,1,14.01,2,1,12.5,700,1,14.28,100,1,12.46,200,2,14.4,100,1,12.43,700,1,14.53,100,1,12.42,700,1,14.54,100,1,12.37,700,1,14.56,800,2
2025-07-17T16:01:00.801177403Z,2025-07-17T16:01:00.801342739Z,160,2,1108,C,A,0,13.69,15,130,165336,270319932,ARL,323455221,13.04,2,1,13.66,15,1,13.03,100,1,13.67,200,2,13.02,100,1,13.97,100,1,12.73,100,1,14.01,2,1,12.71,100,1,14.28,100,1,12.5,700,1,14.4,100,1,12.46,200,2,14.53,100,1,12.43,700,1,14.54,100,1,12.42,700,1,14.56,800,2,12.37,700,1,14.58,100,1
2025-07-17T16:01:10.802712247Z,2025-07-17T16:01:10.802877570Z,160,2,1108,A,A,0,13.62,15,130,165323,270493149,ARL,324161541,13.04,2,1,13.62,15,1,13.03,100,1,13.66,15,1,13.02,100,1,13.67,200,2,12.73,100,1,13.97,100,1,12.71,100,1,14.01,2,1,12.5,700,1,14.28,100,1,12.46,200,2,14.4,100,1,12.43,700,1,14.53,100,1,12.42,700,1,14.54,100,1,12.37,700,1,14.56,800,2
2025-07-17T16:01:11.418671671Z,2025-07-17T16:01:11.418837472Z,160,2,1108,A,A,0,13.65,100,130,165801,270503944,ARL,324175569,13.04,2,1,13.62,15,1,13.03,100,1,13.65,100,1,13.02,100,1,13.66,15,1,12.73,100,1,13.67,200,2,12.71,100,1,13.97,100,1,12.5,700,1,14.01,2,1,12.46,200,2,14.28,100,1,12.43,700,1,14.4,100,1,12.42,700,1,14.53,100,1,12.37,700,1,14.54,100,1
2025-07-17T16:01:11.425757014Z,2025-07-17T16:01:11.425922184Z,160,2,1108,C,A,0,13.67,100,130,165170,270504009,ARL,323803301,13.04,2,1,13.62,15,1,13.03,100,1,13.65,100,1,13.02,100,1,13.66,15,1,12.73,100,1,13.67,100,1,12.71,100,1,13.97,100,1,12.5,700,1,14.01,2,1,12.46,200,2,14.28,100,1,12.43,700,1,14.4,100,1,12.42,700,1,14.53,100,1,12.37,700,1,14.54,100,1
2025-07-17T16:01:11.820588141Z,2025-07-17T16:01:11.820753616Z,160,2,1108,C,A,0,13.67,100,0,165475,270509970,ARL,323730353,13.04,2,1,13.62,15,1,13.03,100,1,13.65,100,1,13.02,100,1,13.66,15,1,12.73,100,1,13.97,100,1,12.71,100,1,14.01,2,1,12.5,700,1,14.28,100,1,12.46,200,2,14.4,100,1,12.43,700,1,14.53,100,1,12.42,700,1,14.54,100,1,12.37,700,1,14.56,800,2
2025-07-17T16:01:11.820588141Z,2025-07-17T16:01:11.820753616Z,160,2,1108,A,A,0,13.63,100,130,165475,270509970,ARL,324186213,13.04,2,1,13.62,15,1,13.03,100,1,13.63,100,1,13.02,100,1,13.65,100,1,12.73,100,1,13.66,15,1,12.71,100,1,13.97,100,1,12.5,700,1,14.01,2,1,12.46,200,2,14.28,100,1,12.43,700,1,14.4,100,1,12.42,700,1,14.53,100,1,12.37,700,1,14.54,100,1
2025-07-17T16:01:11.821349600Z,2025-07-17T16:01:11.821515043Z,160,2,1108,C,A,0,14.73,100,0,165443,270509983,ARL,323730369,13.04,2,1,13.62,15,1,13.03,100,1,13.63,100,1,13.02,100,1,13.65,100,1,12.73,100,1,13.66,15,1,12.71,100,1,13.97,100,1,12.5,700,1,14.01,2,1,12.46,200,2,14.28,100,1,12.43,700,1,14.4,100,1,12.42,700,1,14.53,100,1,12.37,700,1,14.54,100,1
2025-07-17T16:01:11.821349600Z,2025-07-17T16:01:11.821515043Z,160,2,1108,A,A,0,14.69,100,130,165443,270509983,ARL,324186233,13.04,2,1,13.62,15,1,13.03,100,1,13.63,100,1,13.02,100,1,13.65,100,1,12.73,100,1,13.66,15,1,12.71,100,1,13.97,100,1,12.5,700,1,14.01,2,1,12.46,200,2,14.28,100,1,12.43,700,1,14.4,100,1,12.42,700,1,14.53,100,1,12.37,700,1,14.54,100,1
2025-07-17T16:01:11.826234488Z,2025-07-17T16:01:11.826399871Z,160,2,1108,C,A,0,13.97,100,130,165383,270510142,ARL,323599765,13.04,2,1,13.62,15,1,13.03,100,1,13.63,100,1,13.02,100,1,13.65,100,1,12.73,100,1,13.66,15,1,12.71,100,1,14.01,2,1,12.5,700,1,14.28,100,1,12.46,200,2,14.4,100,1,12.43,700,1,14.53,100,1,12.42,700,1,14.54,100,1,12.37,700,1,14.56,800,2
2025-07-17T16:01:11.826286284Z,2025-07-17T16:01:11.826451447Z,160,2,1108,A,A,0,13.9,100,130,165163,270510143,ARL,324186721,13.04,2,1,13.62,15,1,13.03,100,1,13.63,100,1,13.02,100,1,13.65,100,1,12.73,100,1,13.66,15,1,12.71,100,1,13.9,100,1,12.5,700,1,14.01,2,1,12.46,200,2,14.28,100,1,12.43,700,1,14.4,100,1,12.42,700,1,14.53,100,1,12.37,700,1,14.54,100,1
2025-07-17T16:01:11.828464891Z,2025-07-17T16:01:11.828630414Z,160,2,1108,C,A,0,14.58,100,0,165523,270510182,ARL,321309941,13.04,2,1,13.62,15,1,13.03,100,1,13.63,100,1,13.02,100,1,13.65,100,1,12.73,100,1,13.66,15,1,12.71,100,1,13.9,100,1,12.5,700,1,14.01,2,1,12.46,200,2,14.28,100,1,12.43,700,1,14.4,100,1,12.42,700,1,14.53,100,1,12.37,700,1,14.54,100,1
2025-07-17T16:01:11.828464891Z,2025-07-17T16:01:11.828630414Z,160,2,1108,A,A,0,14.43,100,130,165523,270510182,ARL,324186781,13.04,2,1,13.62,15,1,13.03,100,1,13.63,100,1,13.02,100,1,13.65,100,1,12.73,100,1,13.66,15,1,12.71,100,1,13.9,100,1,12.5,700,1,14.01,2,1,12.46,200,2,14.28,100,1,12.43,700,1,14.4,100,1,12.42,700,1,14.43,100,1,12.37,700,1,14.53,100,1
2025-07-17T16:01:22.802353061Z,2025-07-17T16:01:22.802518536Z,160,2,1108,C,A,0,13.66,15,130,165475,270674903,ARL,323720189,13.04,2,1,13.62,15,1,13.03,100,1,13.63,100,1,13.02,100,1,13.65,100,1,12.73,100,1,13.9,100,1,12.71,100,1,14.01,2,1,12.5,700,1,14.28,100,1,12.46,200,2,14.4,100,1,12.43,700,1,14.43,100,1,12.42,700,1,14.53,100,1,12.37,700,1,14.54,100,1
2025-07-17T16:01:32.803839043Z,2025-07-17T16:01:32.804004639Z,160,2,1108,A,A,0,13.6,15,130,165596,270824320,ARL,324619361,13.04,2,1,13.6,15,1,13.03,100,1,13.62,15,1,13.02,100,1,13.63,100,1,12.73,100,1,13.65,100,1,12.71,100,1,13.9,100,1,12.5,700,1,14.01,2,1,12.46,200,2,14.28,100,1,12.43,700,1,14.4,100,1,12.42,700,1,14.43,100,1,12.37,700,1,14.53,100,1
2025-07-17T16:01:32.804108576Z,2025-07-17T16:01:32.804274168Z,160,2,1108,C,A,0,13.63,100,0,165592,270824323,ARL,324186213,13.04,2,1,13.6,15,1,13.03,100,1,13.62,15,1,13.02,100,1,13.65,100,1,12.73,100,1,13.9,100,1,12.71,100,1,14.01,2,1,12.5,700,1,14.28,100,1,12.46,200,2,14.4,100,1,12.43,700,1,14.43,100,1,12.42,700,1,14.53,100,1,12.37,700,1,14.54,100,1
2025-07-17T16:01:32.804108576Z,2025-07-17T16:01:32.804274168Z,160,2,1108,A,A,0,13.61,100,130,165592,270824323,ARL,324619369,13.04,2,1,13.6,15,1,13.03,100,1,13.61,100,1,13.02,100,1,13.62,15,1,12.73,100,1,13.65,100,1,12.71,100,1,13.9,100,1,12.5,700,1,14.01,2,1,12.46,200,2,14.28,100,1,12.43,700,1,14.4,100,1,12.42,700,1,14.43,100,1,12.37,700,1,14.53,100,1
2025-07-17T16:01:32.806134020Z,2025-07-17T16:01:32.806299464Z,160,2,1108,C,A,0,14.73,100,0,165444,270824400,ARL,321500349,13.04,2,1,13.6,15,1,13.03,100,1,13.61,100,1,13.02,100,1,13.62,15,1,12.73,100,1,13.65,100,1,12.71,100,1,13.9,100,1,12.5,700,1,14.01,2,1,12.46,200,2,14.28,100,1,12.43,700,1,14.4,100,1,12.42,700,1,14.43,100,1,12.37,700,1,14.53,100,1
2025-07-17T16:01:32.806134020Z,2025-07-17T16:01:32.806299464Z,160,2,1108,A,A,0,14.57,100,130,165444,270824400,ARL,324619409,13.04,2,1,13.6,15,1,13.03,100,1,13.61,100,1,13.02,100,1,13.62,15,1,12.73,100,1,13.65,100,1,12.71,100,1,13.9,100,1,12.5,700,1,14.01,2,1,12.46,200,2,14.28,100,1,12.43,700,1,14.4,100,1,12.42,700,1,14.43,100,1,12.37,700,1,14.53,100,1
2025-07-17T16:01:32.815748258Z,2025-07-17T16:01:32.815913520Z,160,2,1108,A,A,0,13.63,100,130,165262,270824657,ARL,324619837,13.04,2,1,13.6,15,1,13.03,100,1,13.61,100,1,13.02,100,1,13.62,15,1,12.73,100,1,13.63,100,1,12.71,100,1,13.65,100,1,12.5,700,1,13.9,100,1,12.46,200,2,14.01,2,1,12.43,700,1,14.28,100,1,12.42,700,1,14.4,100,1,12.37,700,1,14.43,100,1
2025-07-17T16:01:32.822443626Z,2025-07-17T16:01:32.822608966Z,160,2,1108,C,A,0,13.65,100,130,165340,270824747,ARL,324175569,13.04,2,1,13.6,15,1,13.03,100,1,13.61,100,1,13.02,100,1,13.62,15,1,12.73,100,1,13.63,100,1,12.71,100,1,13.9,100,1,12.5,700,1,14.01,2,1,12.46,200,2,14.28,100,1,12.43,700,1,14.4,100,1,12.42,700,1,14.43,100,1,12.37,700,1,14.53,100,1
2025-07-17T16:01:37.242525208Z,2025-07-17T16:01:37.242690420Z,160,2,1108,C,A,0,13.62,15,130,165212,270889017,ARL,324161541,13.04,2,1,13.6,15,1,13.03,100,1,13.61,100,1,13.02,100,1,13.63,100,1,12.73,100,1,13.9,100,1,12.71,100,1,14.01,2,1,12.5,700,1,14.28,100,1,12.46,200,2,14.4,100,1,12.43,700,1,14.43,100,1,12.42,700,1,14.53,100,1,12.37,700,1,14.54,100,1
2025-07-17T16:01:40.605632399Z,2025-07-17T16:01:40.605797765Z,160,2,1108,A,A,0,13.61,100,130,165366,270946497,ARL,324782841,13.04,2,1,13.6,15,1,13.03,100,1,13.61,200,2,13.02,100,1,13.63,100,1,12.73,100,1,13.9,100,1,12.71,100,1,14.01,2,1,12.5,700,1,14.28,100,1,12.46,200,2,14.4,100,1,12.43,700,1,14.43,100,1,12.42,700,1,14.53,100,1,12.37,700,1,14.54,100,1
2025-07-17T16:01:40.653572805Z,2025-07-17T16:01:40.653738176Z,160,2,1108,C,A,0,13.63,100,130,165371,270946779,ARL,324619837,13.04,2,1,13.6,15,1,13.03,100,1,13.61,200,2,13.02,100,1,13.9,100,1,12.73,100,1,14.01,2,1,12.71,100,1,14.28,100,1,12.5,700,1,14.4,100,1,12.46,200,2,14.43,100,1,12.43,700,1,14.53,100,1,12.42,700,1,14.54,100,1,12.37,700,1,14.56,800,2
2025-07-17T16:01:47.565825466Z,2025-07-17T16:01:47.565991684Z,160,2,1108,A,A,0,13.57,15,128,166218,271062350,ARL,324934601,13.04,2,1,13.57,15,1,13.03,100,1,13.6,15,1,13.02,100,1,13.61,200,2,12.73,100,1,13.9,100,1,12.71,100,1,14.01,2,1,12.5,700,1,14.28,100,1,12.46,200,2,14.4,100,1,12.43,700,1,14.43,100,1,12.42,700,1,14.53,100,1,12.37,700,1,14.54,100,1
2025-07-17T16:01:47.902804446Z,2025-07-17T16:01:47.902969773Z,160,2,1108,C,A,0,13.61,100,0,165327,271068098,ARL,324619369,13.04,2,1,13.57,15,1,13.03,100,1,13.6,15,1,13.02,100,1,13.61,100,1,12.73,100,1,13.9,100,1,12.71,100,1,14.01,2,1,12.5,700,1,14.28,100,1,12.46,200,2,14.4,100,1,12.43,700,1,14.43,100,1,12.42,700,1,14.53,100,1,12.37,700,1,14.54,100,1
2025-07-17T16:01:47.902804446Z,2025-07-17T16:01:47.902969773Z,160,2,1108,A,A,0,13.58,100,130,165327,271068098,ARL,324942229,13.04,2,1,13.57,15,1,13.03,100,1,13.58,100,1,13.02,100,1,13.6,15,1,12.73,100,1,13.61,100,1,12.71,100,1,13.9,100,1,12.5,700,1,14.01,2,1,12.46,200,2,14.28,100,1,12.43,700,1,14.4,100,1,12.42,700,1,14.43,100,1,12.37,700,1,14.53,100,1
2025-07-17T16:01:47.903546622Z,2025-07-17T16:01:47.903711757Z,160,2,1108,C,A,0,14.4,100,130,165135,271068105,ARL,289726421,13.04,2,1,13.57,15,1,13.03,100,1,13.58,100,1,13.02,100,1,13.6,15,1,12.73,100,1,13.61,100,1,12.71,100,1,13.9,100,1,12.5,700,1,14.01,2,1,12.46,200,2,14.28,100,1,12.43,700,1,14.43,100,1,12.42,700,1,14.53,100,1,12.37,700,1,14.54,100,1
2025-07-17T16:01:47.903548861Z,2025-07-17T16:01:47.903714323Z,160,2,1108,C,A,0,14.69,100,0,165462,271068106,ARL,324186233,13.04,2,1,13.57,15,1,13.03,100,1,13.58,100,1,13.02,100,1,13.6,15,1,12.73,100,1,13.61,100,1,12.71,100,1,13.9,100,1,12.5,700,1,14.01,2,1,12.46,200,2,14.28,100,1,12.43,700,1,14.43,100,1,12.42,700,1,14.53,100,1,12.37,700,1,14.54,100,1
2025-07-17T16:01:47.903548861Z,2025-07-17T16:01:47.903714323Z,160,2,1108,A,A,0,14.63,100,130,165462,271068106,ARL,324942257,13.04,2,1,13.57,15,1,13.03,100,1,13.58,100,1,13.02,100,1,13.6,15,1,12.73,100,1,13.61,100,1,12.71,100,1,13.9,100,1,12.5,700,1,14.01,2,1,12.46,200,2,14.28,100,1,12.43,700,1,14.43,100,1,12.42,700,1,14.53,100,1,12.37,700,1,14.54,100,1
2025-07-17T16:01:47.903902473Z,2025-07-17T16:01:47.904067686Z,160,2,1108,A,A,0,14.19,100,130,165213,271068115,ARL,324942273,13.04,2,1,13.57,15,1,13.03,100,1,13.58,100,1,13.02,100,1,13.6,15,1,12.73,100,1,13.61,100,1,12.71,100,1,13.9,100,1,12.5,700,1,14.01,2,1,12.46,200,2,14.19,100,1,12.43,700,1,14.28,100,1,12.42,700,1,14.43,100,1,12.37,700,1,14.53,100,1
2025-07-17T16:01:47.905189816Z,2025-07-17T16:01:47.905355779Z,160,2,1108,C,A,0,15.23,100,0,165963,271068134,ARL,282776017,13.04,2,1,13.57,15,1,13.03,100,1,13.58,100,1,13.02,100,1,13.6,15,1,12.73,100,1,13.61,100,1,12.71,100,1,13.9,100,1,12.5,700,1,14.01,2,1,12.46,200,2,14.19,100,1,12.43,700,1,14.28,100,1,12.42,700,1,14.43,100,1,12.37,700,1,14.53,100,1
2025-07-17T16:01:47.905189816Z,2025-07-17T16:01:47.905355779Z,160,2,1108,A,A,0,14.94,100,130,165963,271068134,ARL,324942277,13.04,2,1,13.57,15,1,13.03,100,1,13.58,100,1,13.02,100,1,13.6,15,1,12.73,100,1,13.61,100,1,12.71,100,1,13.9,100,1,12.5,700,1,14.01,2,1,12.46,200,2,14.19,100,1,12.43,700,1,14.28,100,1,12.42,700,1,14.43,100,1,12.37,700,1,14.53,100,1
2025-07-17T16:01:47.909314303Z,2025-07-17T16:01:47.909479724Z,160,2,1108,C,A,0,17.4,100,0,165421,271068173,ARL,323599633,13.04,2,1,13.57,15,1,13.03,100,1,13.58,100,1,13.02,100,1,13.6,15,1,12.73,100,1,13.61,100,1,12.71,100,1,13.9,100,1,12.5,700,1,14.01,2,1,12.46,200,2,14.19,100,1,12.43,700,1,14.28,100,1,12.42,700,1,14.43,100,1,12.37,700,1,14.53,100,1
2025-07-17T16:01:47.909314303Z,2025-07-17T16:01:47.909479724Z,160,2,1108,A,A,0,17.25,100,130,165421,271068173,ARL,324942361,13.04,2,1,13.57,15,1,13.03,100,1,13.58,100,1,13.02,100,1,13.6,15,1,12.73,100,1,13.61,100,1,12.71,100,1,13.9,100,1,12.5,700,1,14.01,2,1,12.46,200,2,14.19,100,1,12.43,700,1,14.28,100,1,12.42,700,1,14.43,100,1,12.37,700,1,14.53,100,1
2025-07-17T16:01:50.798934838Z,2025-07-17T16:01:50.799100504Z,160,2,1108,A,A,0,13.59,100,130,165666,271131418,ARL,325022101,13.04,2,1,13.57,15,1,13.03,100,1,13.58,100,1,13.02,100,1,13.59,100,1,12.73,100,1,13.6,15,1,12.71,100,1,13.61,100,1,12.5,700,1,13.9,100,1,12.46,200,2,14.01,2,1,12.43,700,1,14.19,100,1,12.42,700,1,14.28,100,1,12.37,700,1,14.43,100,1
2025-07-17T16:01:50.805488726Z,2025-07-17T16:01:50.805653961Z,160,2,1108,C,A,0,13.61,100,130,165235,271131583,ARL,324782841,13.04,2,1,13.57,15,1,13.03,100,1,13.58,100,1,13.02,100,1,13.59,100,1,12.73,100,1,13.6,15,1,12.71,100,1,13.9,100,1,12.5,700,1,14.01,2,1,12.46,200,2,14.19,100,1,12.43,700,1,14.28,100,1,12.42,700,1,14.43,100,1,12.37,700,1,14.53,100,1
2025-07-17T16:01:52.132898568Z,2025-07-17T16:01:52.133063761Z,160,2,1108,C,A,0,13.6,15,130,165193,271153294,ARL,324619361,13.04,2,1,13.57,15,1,13.03,100,1,13.58,100,1,13.02,100,1,13.59,100,1,12.73,100,1,13.9,100,1,12.71,100,1,14.01,2,1,12.5,700,1,14.19,100,1,12.46,200,2,14.28,100,1,12.43,700,1,14.43,100,1,12.42,700,1,14.53,100,1,12.37,700,1,14.54,100,1
2025-07-17T16:01:53.137336077Z,2025-07-17T16:01:53.137501962Z,160,2,1108,A,A,0,13.55,15,130,165885,271200452,ARL,325109165,13.04,2,1,13.55,15,1,13.03,100,1,13.57,15,1,13.02,100,1,13.58,100,1,12.73,100,1,13.59,100,1,12.71,100,1,13.9,100,1,12.5,700,1,14.01,2,1,12.46,200,2,14.19,100,1,12.43,700,1,14.28,100,1,12.42,700,1,14.43,100,1,12.37,700,1,14.53,100,1
2025-07-17T16:01:56.263988198Z,2025-07-17T16:01:56.264154095Z,160,2,1108,C,A,0,13.58,100,0,165897,271251019,ARL,324942229,13.04,2,1,13.55,15,1,13.03,100,1,13.57,15,1,13.02,100,1,13.59,100,1,12.73,100,1,13.9,100,1,12.71,100,1,14.01,2,1,12.5,700,1,14.19,100,1,12.46,200,2,14.28,100,1,12.43,700,1,14.43,100,1,12.42,700,1,14.53,100,1,12.37,700,1,14.54,100,1
2025-07-17T16:01:56.263988198Z,2025-07-17T16:01:56.264154095Z,160,2,1108,A,A,0,13.56,100,130,165897,271251019,ARL,325176181,13.04,2,1,13.55,15,1,13.03,100,1,13.56,100,1,13.02,100,1,13.57,15,1,12.73,100,1,13.59,100,1,12.71,100,1,13.9,100,1,12.5,700,1,14.01,2,1,12.46,200,2,14.19,100,1,12.43,700,1,14.28,100,1,12.42,700,1,14.43,100,1,12.37,700,1,14.53,100,1
2025-07-17T16:01:56.269458197Z,2025-07-17T16:01:56.269623788Z,160,2,1108,C,A,0,13.9,100,130,165591,271251357,ARL,324186721,13.04,2,1,13.55,15,1,13.03,100,1,13.56,100,1,13.02,100,1,13.57,15,1,12.73,100,1,13.59,100,1,12.71,100,1,14.01,2,1,12.5,700,1,14.19,100,1,12.46,200,2,14.28,100,1,12.43,700,1,14.43,100,1,12.42,700,1,14.53,100,1,12.37,700,1,14.54,100,1
2025-07-17T16:01:56.269508928Z,2025-07-17T16:01:56.269674232Z,160,2,1108,A,A,0,13.83,100,130,165304,271251358,ARL,325176373,13.04,2,1,13.55,15,1,13.03,100,1,13.56,100,1,13.02,100,1,13.57,15,1,12.73,100,1,13.59,100,1,12.71,100,1,13.83,100,1,12.5,700,1,14.01,2,1,12.46,200,2,14.19,100,1,12.43,700,1,14.28,100,1,12.42,700,1,14.43,100,1,12.37,700,1,14.53,100,1
2025-07-17T16:01:56.272175169Z,2025-07-17T16:01:56.272340730Z,160,2,1108,C,A,0,15.76,100,0,165561,271251490,ARL,323599629,13.04,2,1,13.55,15,1,13.03,100,1,13.56,100,1,13.02,100,1,13.57,15,1,12.73,100,1,13.59,100,1,12.71,100,1,13.83,100,1,12.5,700,1,14.01,2,1,12.46,200,2,14.19,100,1,12.43,700,1,14.28,100,1,12.42,700,1,14.43,100,1,12.37,700,1,14.53,100,1
2025-07-17T16:01:56.272175169Z,2025-07-17T16:01:56.272340730Z,160,2,1108,A,A,0,15.6,100,130,165561,271251490,ARL,325176677,13.04,2,1,13.55,15,1,13.03,100,1,13.56,100,1,13.02,100,1,13.57,15,1,12.73,100,1,13.59,100,1,12.71,100,1,13.83,100,1,12.5,700,1,14.01,2,1,12.46,200,2,14.19,100,1,12.43,700,1,14.28,100,1,12.42,700,1,14.43,100,1,12.37,700,1,14.53,100,1
2025-07-17T16:01:56.300723805Z,2025-07-17T16:01:56.300889378Z,160,2,1108,C,A,0,14.66,100,0,165573,271252044,ARL,323599625,13.04,2,1,13.55,15,1,13.03,100,1,13.56,100,1,13.02,100,1,13.57,15,1,12.73,100,1,13.59,100,1,12.71,100,1,13.83,100,1,12.5,700,1,14.01,2,1,12.46,200,2,14.19,100,1,12.43,700,1,14.28,100,1,12.42,700,1,14.43,100,1,12.37,700,1,14.53,100,1
2025-07-17T16:01:56.300723805Z,2025-07-17T16:01:56.300889378Z,160,2,1108,A,A,0,14.51,100,130,165573,271252044,ARL,325177757,13.04,2,1,13.55,15,1,13.03,100,1,13.56,100,1,13.02,100,1,13.57,15,1,12.73,100,1,13.59,100,1,12.71,100,1,13.83,100,1,12.5,700,1,14.01,2,1,12.46,200,2,14.19,100,1,12.43,700,1,14.28,100,1,12.42,700,1,14.43,100,1,12.37,700,1,14.51,100,1
2025-07-17T16:02:01.992379223Z,2025-07-17T16:02:01.992544607Z,160,2,1108,C,A,0,14.01,2,0,165384,271343251,ARL,322898193,13.04,2,1,13.55,15,1,13.03,100,1,13.56,100,1,13.02,100,1,13.57,15,1,12.73,100,1,13.59,100,1,12.71,100,1,13.83,100,1,12.5,700,1,14.19,100,1,12.46,200,2,14.28,100,1,12.43,700,1,14.43,100,1,12.42,700,1,14.51,100,1,12.37,700,1,14.53,100,1
2025-07-17T16:02:01.992379223Z,2025-07-17T16:02:01.992544607Z,160,2,1108,A,A,0,13.92,2,130,165384,271343251,ARL,325297093,13.04,2,1,13.55,15,1,13.03,100,1,13.56,100,1,13.02,100,1,13.57,15,1,12.73,100,1,13.59,100,1,12.71,100,1,13.83,100,1,12.5,700,1,13.92,2,1,12.46,200,2,14.19,100,1,12.43,700,1,14.28,100,1,12.42,700,1,14.43,100,1,12.37,700,1,14.51,100,1
2025-07-17T16:02:03.207555626Z,2025-07-17T16:02:03.207720826Z,160,2,1108,C,A,0,13.57,15,130,165200,271367066,ARL,324934601,13.04,2,1,13.55,15,1,13.03,100,1,13.56,100,1,13.02,100,1,13.59,100,1,12.73,100,1,13.83,100,1,12.71,100,1,13.92,2,1,12.5,700,1,14.19,100,1,12.46,200,2,14.28,100,1,12.43,700,1,14.43,100,1,12.42,700,1,14.51,100,1,12.37,700,1,14.53,100,1
2025-07-17T16:02:04.212791108Z,2025-07-17T16:02:04.212956339Z,160,2,1108,A,A,0,13.53,15,130,165231,271415821,ARL,325382429,13.04,2,1,13.53,15,1,13.03,100,1,13.55,15,1,13.02,100,1,13.56,100,1,12.73,100,1,13.59,100,1,12.71,100,1,13.83,100,1,12.5,700,1,13.92,2,1,12.46,200,2,14.19,100,1,12.43,700,1,14.28,100,1,12.42,700,1,14.43,100,1,12.37,700,1,14.51,100,1
2025-07-17T16:02:04.214183279Z,2025-07-17T16:02:04.214348814Z,160,2,1108,C,A,0,14.54,100,0,165535,271415834,ARL,323775433,13.04,2,1,13.53,15,1,13.03,100,1,13.55,15,1,13.02,100,1,13.56,100,1,12.73,100,1,13.59,100,1,12.71,100,1,13.83,100,1,12.5,700,1,13.92,2,1,12.46,200,2,14.19,100,1,12.43,700,1,14.28,100,1,12.42,700,1,14.43,100,1,12.37,700,1,14.51,100,1
2025-07-17T16:02:04.214183279Z,2025-07-17T16:02:04.214348814Z,160,2,1108,A,A,0,14.43,100,130,165535,271415834,ARL,325382437,13.04,2,1,13.53,15,1,13.03,100,1,13.55,15,1,13.02,100,1,13.56,100,1,12.73,100,1,13.59,100,1,12.71,100,1,13.83,100,1,12.5,700,1,13.92,2,1,12.46,200,2,14.19,100,1,12.43,700,1,14.28,100,1,12.42,700,1,14.43,200,2,12.37,700,1,14.51,100,1
2025-07-17T16:02:04.839967173Z,2025-07-17T16:02:04.840132668Z,160,2,1108,C,A,0,13.56,100,0,165495,271432190,ARL,325176181,13.04,2,1,13.53,15,1,13.03,100,1,13.55,15,1,13.02,100,1,13.59,100,1,12.73,100,1,13.83,100,1,12.71,100,1,13.92,2,1,12.5,700,1,14.19,100,1,12.46,200,2,14.28,100,1,12.43,700,1,14.43,200,2,12.42,700,1,14.51,100,1,12.37,700,1,14.53,100,1
2025-07-17T16:02:04.839967173Z,2025-07-17T16:02:04.840132668Z,160,2,1108,A,A,0,13.54,100,130,165495,271432190,ARL,325400045,13.04,2,1,13.53,15,1,13.03,100,1,13.54,100,1,13.02,100,1,13.55,15,1,12.73,100,1,13.59,100,1,12.71,100,1,13.83,100,1,12.5,700,1,13.92,2,1,12.46,200,2,14.19,100,1,12.43,700,1,14.28,100,1,12.42,700,1,14.43,200,2,12.37,700,1,14.51,100,1
2025-07-17T16:02:04.840006082Z,2025-07-17T16:02:04.840171240Z,160,2,1108,A,A,0,14.27,700,130,165158,271432192,ARL,325400053,13.04,2,1,13.53,15,1,13.03,100,1,13.54,100,1,13.02,100,1,13.55,15,1,12.73,100,1,13.59,100,1,12.71,100,1,13.83,100,1,12.5,700,1,13.92,2,1,12.46,200,2,14.19,100,1,12.43,700,1,14.27,700,1,12.42,700,1,14.28,100,1,12.37,700,1,14.43,200,2
2025-07-17T16:02:04.840045694Z,2025-07-17T16:02:04.840210880Z,160,2,1108,C,A,0,14.68,700,130,165186,271432193,ARL,283592941,13.04,2,1,13.53,15,1,13.03,100,1,13.54,100,1,13.02,100,1,13.55,15,1,12.73,100,1,13.59,100,1,12.71,100,1,13.83,100,1,12.5,700,1,13.92,2,1,12.46,200,2,14.19,100,1,12.43,700,1,14.27,700,1,12.42,700,1,14.28,100,1,12.37,700,1,14.43,200,2
2025-07-17T16:02:04.840711803Z,2025-07-17T16:02:04.840877603Z,160,2,1108,C,A,0,14.63,100,0,165800,271432231,ARL,324942257,13.04,2,1,13.53,15,1,13.03,100,1,13.54,100,1,13.02,100,1,13.55,15,1,12.73,100,1,13.59,100,1,12.71,100,1,13.83,100,1,12.5,700,1,13.92,2,1,12.46,200,2,14.19,100,1,12.43,700,1,14.27,700,1,12.42,700,1,14.28,100,1,12.37,700,1,14.43,200,2
2025-07-17T16:02:04.840711803Z,2025-07-17T16:02:04.840877603Z,160,2,1108,A,A,0,14.59,100,130,165800,271432231,ARL,325400105,13.04,2,1,13.53,15,1,13.03,100,1,13.54,100,1,13.02,100,1,13.55,15,1,12.73,100,1,13.59,100,1,12.71,100,1,13.83,100,1,12.5,700,1,13.92,2,1,12.46,200,2,14.19,100,1,12.43,700,1,14.27,700,1,12.42,700,1,14.28,100,1,12.37,700,1,14.43,200,2
2025-07-17T16:02:11.249125653Z,2025-07-17T16:02:11.249291142Z,160,2,1108,C,A,0,14.53,100,0,165489,271526467,ARL,323775457,13.04,2,1,13.53,15,1,13.03,100,1,13.54,100,1,13.02,100,1,13.55,15,1,12.73,100,1,13.59,100,1,12.71,100,1,13.83,100,1,12.5,700,1,13.92,2,1,12.46,200,2,14.19,100,1,12.43,700,1,14.27,700,1,12.42,700,1,14.28,100,1,12.37,700,1,14.43,200,2
2025-07-17T16:02:11.249125653Z,2025-07-17T16:02:11.249291142Z,160,2,1108,A,A,0,14.42,100,130,165489,271526467,ARL,325520705,13.04,2,1,13.53,15,1,13.03,100,1,13.54,100,1,13.02,100,1,13.55,15,1,12.73,100,1,13.59,100,1,12.71,100,1,13.83,100,1,12.5,700,1,13.92,2,1,12.46,200,2,14.19,100,1,12.43,700,1,14.27,700,1,12.42,700,1,14.28,100,1,12.37,700,1,14.42,100,1
2025-07-17T16:02:15.062605521Z,2025-07-17T16:02:15.062774661Z,160,2,1108,C,A,0,13.53,15,128,169140,271576282,ARL,325382429,13.04,2,1,13.54,100,1,13.03,100,1,13.55,15,1,13.02,100,1,13.59,100,1,12.73,100,1,13.83,100,1,12.71,100,1,13.92,2,1,12.5,700,1,14.19,100,1,12.46,200,2,14.27,700,1,12.43,700,1,14.28,100,1,12.42,700,1,14.42,100,1,12.37,700,1,14.43,200,2
2025-07-17T16:02:15.068283706Z,2025-07-17T16:02:15.068449048Z,160,2,1108,C,A,0,13.55,15,130,165342,271577104,ARL,325109165,13.04,2,1,13.54,100,1,13.03,100,1,13.59,100,1,13.02,100,1,13.83,100,1,12.73,100,1,13.92,2,1,12.71,100,1,14.19,100,1,12.5,700,1,14.27,700,1,12.46,200,2,14.28,100,1,12.43,700,1,14.42,100,1,12.42,700,1,14.43,200,2,12.37,700,1,14.51,100,1
2025-07-17T16:02:20.634863301Z,2025-07-17T16:02:20.635028489Z,160,2,1108,C,A,0,13.54,100,130,165188,271675842,ARL,325400045,13.04,2,1,13.59,100,1,13.03,100,1,13.83,100,1,13.02,100,1,13.92,2,1,12.73,100,1,14.19,100,1,12.71,100,1,14.27,700,1,12.5,700,1,14.28,100,1,12.46,200,2,14.42,100,1,12.43,700,1,14.43,200,2,12.42,700,1,14.51,100,1,12.37,700,1,14.56,800,2
2025-07-17T16:02:20.635616654Z,2025-07-17T16:02:20.635782472Z,160,2,1108,C,A,0,14.59,100,0,165818,271675858,ARL,325400105,13.04,2,1,13.59,100,1,13.03,100,1,13.83,100,1,13.02,100,1,13.92,2,1,12.73,100,1,14.19,100,1,12.71,100,1,14.27,700,1,12.5,700,1,14.28,100,1,12.46,200,2,14.42,100,1,12.43,700,1,14.43,200,2,12.42,700,1,14.51,100,1,12.37,700,1,14.56,800,2
2025-07-17T16:02:20.635616654Z,2025-07-17T16:02:20.635782472Z,160,2,1108,A,A,0,14.64,100,130,165818,271675858,ARL,325714169,13.04,2,1,13.59,100,1,13.03,100,1,13.83,100,1,13.02,100,1,13.92,2,1,12.73,100,1,14.19,100,1,12.71,100,1,14.27,700,1,12.5,700,1,14.28,100,1,12.46,200,2,14.42,100,1,12.43,700,1,14.43,200,2,12.42,700,1,14.51,100,1,12.37,700,1,14.56,800,2
2025-07-17T16:02:20.650301212Z,2025-07-17T16:02:20.650466751Z,160,2,1108,C,A,0,13.59,100,130,165539,271676032,ARL,325022101,13.04,2,1,13.83,100,1,13.03,100,1,13.92,2,1,13.02,100,1,14.19,100,1,12.73,100,1,14.27,700,1,12.71,100,1,14.28,100,1,12.5,700,1,14.42,100,1,12.46,200,2,14.43,200,2,12.43,700,1,14.51,100,1,12.42,700,1,14.56,800,2,12.37,700,1,14.57,100,1
2025-07-17T16:02:20.650335946Z,2025-07-17T16:02:20.650501448Z,160,2,1108,C,A,0,14.27,700,130,165502,271676033,ARL,325400053,13.04,2,1,13.83,100,1,13.03,100,1,13.92,2,1,13.02,100,1,14.19,100,1,12.73,100,1,14.28,100,1,12.71,100,1,14.42,100,1,12.5,700,1,14.43,200,2,12.46,200,2,14.51,100,1,12.43,700,1,14.56,800,2,12.42,700,1,14.57,100,1,12.37,700,1,14.6,700,1
2025-07-17T16:02:20.650381040Z,2025-07-17T16:02:20.650546483Z,160,2,1108,A,A,0,14.53,700,130,165443,271676035,ARL,325714545,13.04,2,1,13.83,100,1,13.03,100,1,13.92,2,1,13.02,100,1,14.19,100,1,12.73,100,1,14.28,100,1,12.71,100,1,14.42,100,1,12.5,700,1,14.43,200,2,12.46,200,2,14.51,100,1,12.43,700,1,14.53,700,1,12.42,700,1,14.56,800,2,12.37,700,1,14.57,100,1
2025-07-17T16:02:20.651020858Z,2025-07-17T16:02:20.651186537Z,160,2,1108,C,A,0,14.42,100,0,165679,271676048,ARL,325520705,13.04,2,1,13.83,100,1,13.03,100,1,13.92,2,1,13.02,100,1,14.19,100,1,12.73,100,1,14.28,100,1,12.71,100,1,14.43,200,2,12.5,700,1,14.51,100,1,12.46,200,2,14.53,700,1,12.43,700,1,14.56,800,2,12.42,700,1,14.57,100,1,12.37,700,1,14.6,700,1
2025-07-17T16:02:20.651020858Z,2025-07-17T16:02:20.651186537Z,160,2,1108,A,A,0,14.73,100,130,165679,271676048,ARL,325714577,13.04,2,1,13.83,100,1,13.03,100,1,13.92,2,1,13.02,100,1,14.19,100,1,12.73,100,1,14.28,100,1,12.71,100,1,14.43,200,2,12.5,700,1,14.51,100,1,12.46,200,2,14.53,700,1,12.43,700,1,14.56,800,2,12.42,700,1,14.57,100,1,12.37,700,1,14.6,700,1
2025-07-17T16:02:20.651035000Z,2025-07-17T16:02:20.651201182Z,160,2,1108,C,A,0,14.19,100,130,166182,271676049,ARL,324942273,13.04,2,1,13.83,100,1,13.03,100,1,13.92,2,1,13.02,100,1,14.28,100,1,12.73,100,1,14.43,200,2,12.71,100,1,14.51,100,1,12.5,700,1,14.53,700,1,12.46,200,2,14.56,800,2,12.43,700,1,14.57,100,1,12.42,700,1,14.6,700,1,12.37,700,1,14.64,100,1
2025-07-17T16:02:20.651293729Z,2025-07-17T16:02:20.651459317Z,160,2,1108,C,A,0,17.25,100,0,165588,271676055,ARL,324942361,13.04,2,1,13.83,100,1,13.03,100,1,13.92,2,1,13.02,100,1,14.28,100,1,12.73,100,1,14.43,200,2,12.71,100,1,14.51,100,1,12.5,700,1,14.53,700,1,12.46,200,2,14.56,800,2,12.43,700,1,14.57,100,1,12.42,700,1,14.6,700,1,12.37,700,1,14.64,100,1
2025-07-17T16:02:20.651293729Z,2025-07-17T16:02:20.651459317Z,160,2,1108,A,A,0,17.57,100,130,165588,271676055,ARL,325714589,13.04,2,1,13.83,100,1,13.03,100,1,13.92,2,1,13.02,100,1,14.28,100,1,12.73,100,1,14.43,200,2,12.71,100,1,14.51,100,1,12.5,700,1,14.53,700,1,12.46,200,2,14.56,800,2,12.43,700,1,14.57,100,1,12.42,700,1,14.6,700,1,12.37,700,1,14.64,100,1
2025-07-17T16:02:20.651393708Z,2025-07-17T16:02:20.651558948Z,160,2,1108,A,A,0,14.45,100,130,165240,271676057,ARL,325714601,13.04,2,1,13.83,100,1,13.03,100,1,13.92,2,1,13.02,100,1,14.28,100,1,12.73,100,1,14.43,200,2,12.71,100,1,14.45,100,1,12.5,700,1,14.51,100,1,12.46,200,2,14.53,700,1,12.43,700,1,14.56,800,2,12.42,700,1,14.57,100,1,12.37,700,1,14.6,700,1
2025-07-17T16:02:20.651618897Z,2025-07-17T16:02:20.651787813Z,160,2,1108,C,A,0,14.43,100,0,168916,271676089,ARL,325382437,13.04,2,1,13.83,100,1,13.03,100,1,13.92,2,1,13.02,100,1,14.28,100,1,12.73,100,1,14.43,100,1,12.71,100,1,14.45,100,1,12.5,700,1,14.51,100,1,12.46,200,2,14.53,700,1,12.43,700,1,14.56,800,2,12.42,700,1,14.57,100,1,12.37,700,1,14.6,700,1
2025-07-17T16:02:20.651618897Z,2025-07-17T16:02:20.651787813Z,160,2,1108,A,A,0,14.73,100,128,168916,271676089,ARL,325714613,13.04,2,1,13.83,100,1,13.03,100,1,13.92,2,1,13.02,100,1,14.28,100,1,12.73,100,1,14.43,100,1,12.71,100,1,14.45,100,1,12.5,700,1,14.51,100,1,12.46,200,2,14.53,700,1,12.43,700,1,14.56,800,2,12.42,700,1,14.57,100,1,12.37,700,1,14.6,700,1
2025-07-17T16:02:20.651854531Z,2025-07-17T16:02:20.652021618Z,160,2,1108,C,A,0,14.57,100,0,167087,271676104,ARL,324619409,13.04,2,1,13.83,100,1,13.03,100,1,13.92,2,1,13.02,100,1,14.28,100,1,12.73,100,1,14.43,100,1,12.71,100,1,14.45,100,1,12.5,700,1,14.51,100,1,12.46,200,2,14.53,700,1,12.43,700,1,14.56,800,2,12.42,700,1,14.6,700,1,12.37,700,1,14.64,100,1
2025-07-17T16:02:20.651854531Z,2025-07-17T16:02:20.652021618Z,160,2,1108,A,A,0,14.8,100,130,167087,271676104,ARL,325714629,13.04,2,1,13.83,100,1,13.03,100,1,13.92,2,1,13.02,100,1,14.28,100,1,12.73,100,1,14.43,100,1,12.71,100,1,14.45,100,1,12.5,700,1,14.51,100,1,12.46,200,2,14.53,700,1,12.43,700,1,14.56,800,2,12.42,700,1,14.6,700,1,12.37,700,1,14.64,100,1
2025-07-17T16:02:20.651932129Z,2025-07-17T16:02:20.652097288Z,160,2,1108,C,A,0,14.43,100,130,165159,271676110,ARL,324186781,13.04,2,1,13.83,100,1,13.03,100,1,13.92,2,1,13.02,100,1,14.28,100,1,12.73,100,1,14.45,100,1,12.71,100,1,14.51,100,1,12.5,700,1,14.53,700,1,12.46,200,2,14.56,800,2,12.43,700,1,14.6,700,1,12.42,700,1,14.64,100,1,12.37,700,1,14.68,700,1
2025-07-17T16:02:20.651994883Z,2025-07-17T16:02:20.652160470Z,160,2,1108,C,A,0,15.6,100,0,165587,271676111,ARL,325176677,13.04,2,1,13.83,100,1,13.03,100,1,13.92,2,1,13.02,100,1,14.28,100,1,12.73,100,1,14.45,100,1,12.71,100,1,14.51,100,1,12.5,700,1,14.53,700,1,12.46,200,2,14.56,800,2,12.43,700,1,14.6,700,1,12.42,700,1,14.64,100,1,12.37,700,1,14.68,700,1
2025-07-17T16:02:20.651994883Z,2025-07-17T16:02:20.652160470Z,160,2,1108,A,A,0,15.91,100,130,165587,271676111,ARL,325714633,13.04,2,1,13.83,100,1,13.03,100,1,13.92,2,1,13.02,100,1,14.28,100,1,12.73,100,1,14.45,100,1,12.71,100,1,14.51,100,1,12.5,700,1,14.53,700,1,12.46,200,2,14.56,800,2,12.43,700,1,14.6,700,1,12.42,700,1,14.64,100,1,12.37,700,1,14.68,700,1
2025-07-17T16:02:20.652094426Z,2025-07-17T16:02:20.652259931Z,160,2,1108,A,A,0,14.63,100,130,165505,271676118,ARL,325714653,13.04,2,1,13.83,100,1,13.03,100,1,13.92,2,1,13.02,100,1,14.28,100,1,12.73,100,1,14.45,100,1,12.71,100,1,14.51,100,1,12.5,700,1,14.53,700,1,12.46,200,2,14.56,800,2,12.43,700,1,14.6,700,1,12.42,700,1,14.63,100,1,12.37,700,1,14.64,100,1
2025-07-17T16:02:20.653460814Z,2025-07-17T16:02:20.653626391Z,160,2,1108,A,B,0,13.27,10,130,165577,271676147,ARL,325714717,13.27,10,1,13.83,100,1,13.04,2,1,13.92,2,1,13.03,100,1,14.28,100,1,13.02,100,1,14.45,100,1,12.73,100,1,14.51,100,1,12.71,100,1,14.53,700,1,12.5,700,1,14.56,800,2,12.46,200,2,14.6,700,1,12.43,700,1,14.63,100,1,12.42,700,1,14.64,100,1
2025-07-17T16:02:20.653461966Z,2025-07-17T16:02:20.653627232Z,160,2,1108,A,A,0,13.83,15,130,165266,271676148,ARL,325714721,13.27,10,1,13.83,115,2,13.04,2,1,13.92,2,1,13.03,100,1,14.28,100,1,13.02,100,1,14.45,100,1,12.73,100,1,14.51,100,1,12.71,100,1,14.53,700,1,12.5,700,1,14.56,800,2,12.46,200,2,14.6,700,1,12.43,700,1,14.63,100,1,12.42,700,1,14.64,100,1
2025-07-17T16:02:20.653721185Z,2025-07-17T16:02:20.653886896Z,160,2,1108,C,B,0,13.02,100,0,165711,271676153,ARL,320485385,13.27,10,1,13.83,115,2,13.04,2,1,13.92,2,1,13.03,100,1,14.28,100,1,12.73,100,1,14.45,100,1,12.71,100,1,14.51,100,1,12.5,700,1,14.53,700,1,12.46,200,2,14.56,800,2,12.43,700,1,14.6,700,1,12.42,700,1,14.63,100,1,12.37,700,1,14.64,100,1
2025-07-17T16:02:20.653721185Z,2025-07-17T16:02:20.653886896Z,160,2,1108,A,B,0,13.26,100,130,165711,271676153,ARL,325714729,13.27,10,1,13.83,115,2,13.26,100,1,13.92,2,1,13.04,2,1,14.28,100,1,13.03,100,1,14.45,100,1,12.73,100,1,14.51,100,1,12.71,100,1,14.53,700,1,12.5,700,1,14.56,800,2,12.46,200,2,14.6,700,1,12.43,700,1,14.63,100,1,12.42,700,1,14.64,100,1
2025-07-17T16:02:20.655111649Z,2025-07-17T16:02:20.655277066Z,160,2,1108,C,B,0,13.04,2,0,165417,271676165,ARL,293594281,13.27,10,1,13.83,115,2,13.26,100,1,13.92,2,1,13.03,100,1,14.28,100,1,12.73,100,1,14.45,100,1,12.71,100,1,14.51,100,1,12.5,700,1,14.53,700,1,12.46,200,2,14.56,800,2,12.43,700,1,14.6,700,1,12.42,700,1,14.63,100,1,12.37,700,1,14.64,100,1
2025-07-17T16:02:20.655111649Z,2025-07-17T16:02:20.655277066Z,160,2,1108,A,B,0,12.91,2,130,165417,271676165,ARL,325714741,13.27,10,1,13.83,115,2,13.26,100,1,13.92,2,1,13.03,100,1,14.28,100,1,12.91,2,1,14.45,100,1,12.73,100,1,14.51,100,1,12.71,100,1,14.53,700,1,12.5,700,1,14.56,800,2,12.46,200,2,14.6,700,1,12.43,700,1,14.63,100,1,12.42,700,1,14.64,100,1
2025-07-17T16:02:20.663209235Z,2025-07-17T16:02:20.663374576Z,160,2,1108,C,A,0,13.83,100,130,165341,271676274,ARL,325176373,13.27,10,1,13.83,15,1,13.26,100,1,13.92,2,1,13.03,100,1,14.28,100,1,12.91,2,1,14.45,100,1,12.73,100,1,14.51,100,1,12.71,100,1,14.53,700,1,12.5,700,1,14.56,800,2,12.46,200,2,14.6,700,1,12.43,700,1,14.63,100,1,12.42,700,1,14.64,100,1
2025-07-17T16:02:20.663241882Z,2025-07-17T16:02:20.663406861Z,160,2,1108,C,A,0,14.53,700,130,164979,271676275,ARL,325714545,13.27,10,1,13.83,15,1,13.26,100,1,13.92,2,1,13.03,100,1,14.28,100,1,12.91,2,1,14.45,100,1,12.73,100,1,14.51,100,1,12.71,100,1,14.56,800,2,12.5,700,1,14.6,700,1,12.46,200,2,14.63,100,1,12.43,700,1,14.64,100,1,12.42,700,1,14.68,700,1
2025-07-17T16:02:20.663261632Z,2025-07-17T16:02:20.663426974Z,160,2,1108,A,A,0,14.11,100,130,165342,271676276,ARL,325714905,13.27,10,1,13.83,15,1,13.26,100,1,13.92,2,1,13.03,100,1,14.11,100,1,12.91,2,1,14.28,100,1,12.73,100,1,14.45,100,1,12.71,100,1,14.51,100,1,12.5,700,1,14.56,800,2,12.46,200,2,14.6,700,1,12.43,700,1,14.63,100,1,12.42,700,1,14.64,100,1
2025-07-17T16:02:20.663394059Z,2025-07-17T16:02:20.663559466Z,160,2,1108,A,A,0,15.94,100,130,165407,271676277,ARL,325714909,13.27,10,1,13.83,15,1,13.26,100,1,13.92,2,1,13.03,100,1,14.11,100,1,12.91,2,1,14.28,100,1,12.73,100,1,14.45,100,1,12.71,100,1,14.51,100,1,12.5,700,1,14.56,800,2,12.46,200,2,14.6,700,1,12.43,700,1,14.63,100,1,12.42,700,1,14.64,100,1
2025-07-17T16:02:20.663407337Z,2025-07-17T16:02:20.663572634Z,160,2,1108,C,A,0,15.59,100,130,165297,271676278,ARL,323730697,13.27,10,1,13.83,15,1,13.26,100,1,13.92,2,1,13.03,100,1,14.11,100,1,12.91,2,1,14.28,100,1,12.73,100,1,14.45,100,1,12.71,100,1,14.51,100,1,12.5,700,1,14.56,800,2,12.46,200,2,14.6,700,1,12.43,700,1,14.63,100,1,12.42,700,1,14.64,100,1
2025-07-17T16:02:20.664790768Z,2025-07-17T16:02:20.664956400Z,160,2,1108,C,A,0,17.57,100,0,165632,271676310,ARL,325714589,13.27,10,1,13.83,15,1,13.26,100,1,13.92,2,1,13.03,100,1,14.11,100,1,12.91,2,1,14.28,100,1,12.73,100,1,14.45,100,1,12.71,100,1,14.51,100,1,12.5,700,1,14.56,800,2,12.46,200,2,14.6,700,1,12.43,700,1,14.63,100,1,12.42,700,1,14.64,100,1
2025-07-17T16:02:20.664790768Z,2025-07-17T16:02:20.664956400Z,160,2,1108,A,A,0,17.76,100,130,165632,271676310,ARL,325714949,13.27,10,1,13.83,15,1,13.26,100,1,13.92,2,1,13.03,100,1,14.11,100,1,12.91,2,1,14.28,100,1,12.73,100,1,14.45,100,1,12.71,100,1,14.51,100,1,12.5,700,1,14.56,800,2,12.46,200,2,14.6,700,1,12.43,700,1,14.63,100,1,12.42,700,1,14.64,100,1
2025-07-17T16:02:20.664963386Z,2025-07-17T16:02:20.665129279Z,160,2,1108,C,A,0,14.8,100,0,165893,271676320,ARL,325714629,13.27,10,1,13.83,15,1,13.26,100,1,13.92,2,1,13.03,100,1,14.11,100,1,12.91,2,1,14.28,100,1,12.73,100,1,14.45,100,1,12.71,100,1,14.51,100,1,12.5,700,1,14.56,800,2,12.46,200,2,14.6,700,1,12.43,700,1,14.63,100,1,12.42,700,1,14.64,100,1
2025-07-17T16:02:20.664963386Z,2025-07-17T16:02:20.665129279Z,160,2,1108,A,A,0,14.96,100,130,165893,271676320,ARL,325714953,13.27,10,1,13.83,15,1,13.26,100,1,13.92,2,1,13.03,100,1,14.11,100,1,12.91,2,1,14.28,100,1,12.73,100,1,14.45,100,1,12.71,100,1,14.51,100,1,12.5,700,1,14.56,800,2,12.46,200,2,14.6,700,1,12.43,700,1,14.63,100,1,12.42,700,1,14.64,100,1
2025-07-17T16:02:20.665034825Z,2025-07-17T16:02:20.665200392Z,160,2,1108,C,A,0,15.91,100,0,165567,271676330,ARL,325714633,13.27,10,1,13.83,15,1,13.26,100,1,13.92,2,1,13.03,100,1,14.11,100,1,12.91,2,1,14.28,100,1,12.73,100,1,14.45,100,1,12.71,100,1,14.51,100,1,12.5,700,1,14.56,800,2,12.46,200,2,14.6,700,1,12.43,700,1,14.63,100,1,12.42,700,1,14.64,100,1
2025-07-17T16:02:20.665034825Z,2025-07-17T16:02:20.665200392Z,160,2,1108,A,A,0,16.08,100,130,165567,271676330,ARL,325714957,13.27,10,1,13.83,15,1,13.26,100,1,13.92,2,1,13.03,100,1,14.11,100,1,12.91,2,1,14.28,100,1,12.73,100,1,14.45,100,1,12.71,100,1,14.51,100,1,12.5,700,1,14.56,800,2,12.46,200,2,14.6,700,1,12.43,700,1,14.63,100,1,12.42,700,1,14.64,100,1
2025-07-17T16:02:20.665292049Z,2025-07-17T16:02:20.665457595Z,160,2,1108,C,A,0,14.94,100,0,165546,271676355,ARL,324942277,13.27,10,1,13.83,15,1,13.26,100,1,13.92,2,1,13.03,100,1,14.11,100,1,12.91,2,1,14.28,100,1,12.73,100,1,14.45,100,1,12.71,100,1,14.51,100,1,12.5,700,1,14.56,800,2,12.46,200,2,14.6,700,1,12.43,700,1,14.63,100,1,12.42,700,1,14.64,100,1
2025-07-17T16:02:20.665292049Z,2025-07-17T16:02:20.665457595Z,160,2,1108,A,A,0,15.38,100,130,165546,271676355,ARL,325714965,13.27,10,1,13.83,15,1,13.26,100,1,13.92,2,1,13.03,100,1,14.11,100,1,12.91,2,1,14.28,100,1,12.73,100,1,14.45,100,1,12.71,100,1,14.51,100,1,12.5,700,1,14.56,800,2,12.46,200,2,14.6,700,1,12.43,700,1,14.63,100,1,12.42,700,1,14.64,100,1
2025-07-17T16:02:20.669536385Z,2025-07-17T16:02:20.669701452Z,160,2,1108,C,A,0,14.11,100,130,165067,271676398,ARL,325714905,13.27,10,1,13.83,15,1,13.26,100,1,13.92,2,1,13.03,100,1,14.28,100,1,12.91,2,1,14.45,100,1,12.73,100,1,14.51,100,1,12.71,100,1,14.56,800,2,12.5,700,1,14.6,700,1,12.46,200,2,14.63,100,1,12.43,700,1,14.64,100,1,12.42,700,1,14.68,700,1
2025-07-17T16:02:20.669583810Z,2025-07-17T16:02:20.669748954Z,160,2,1108,A,A,0,14.26,100,130,165144,271676399,ARL,325715045,13.27,10,1,13.83,15,1,13.26,100,1,13.92,2,1,13.03,100,1,14.26,100,1,12.91,2,1,14.28,100,1,12.73,100,1,14.45,100,1,12.71,100,1,14.51,100,1,12.5,700,1,14.56,800,2,12.46,200,2,14.6,700,1,12.43,700,1,14.63,100,1,12.42,700,1,14.64,100,1
2025-07-17T16:02:20.669587514Z,2025-07-17T16:02:20.669752979Z,160,2,1108,C,A,0,14.51,100,0,165465,271676400,ARL,325177757,13.27,10,1,13.83,15,1,13.26,100,1,13.92,2,1,13.03,100,1,14.26,100,1,12.91,2,1,14.28,100,1,12.73,100,1,14.45,100,1,12.71,100,1,14.56,800,2,12.5,700,1,14.6,700,1,12.46,200,2,14.63,100,1,12.43,700,1,14.64,100,1,12.42,700,1,14.68,700,1
2025-07-17T16:02:20.669587514Z,2025-07-17T16:02:20.669752979Z,160,2,1108,A,A,0,14.96,100,130,165465,271676400,ARL,325715053,13.27,10,1,13.83,15,1,13.26,100,1,13.92,2,1,13.03,100,1,14.26,100,1,12.91,2,1,14.28,100,1,12.73,100,1,14.45,100,1,12.71,100,1,14.56,800,2,12.5,700,1,14.6,700,1,12.46,200,2,14.63,100,1,12.43,700,1,14.64,100,1,12.42,700,1,14.68,700,1
2025-07-17T16:02:20.685086585Z,2025-07-17T16:02:20.685252049Z,160,2,1108,C,A,0,14.64,100,0,165464,271676621,ARL,325714169,13.27,10,1,13.83,15,1,13.26,100,1,13.92,2,1,13.03,100,1,14.26,100,1,12.91,2,1,14.28,100,1,12.73,100,1,14.45,100,1,12.71,100,1,14.56,800,2,12.5,700,1,14.6,700,1,12.46,200,2,14.63,100,1,12.43,700,1,14.68,700,1,12.42,700,1,14.73,200,2
2025-07-17T16:02:20.685086585Z,2025-07-17T16:02:20.685252049Z,160,2,1108,A,A,0,15.06,100,130,165464,271676621,ARL,325715113,13.27,10,1,13.83,15,1,13.26,100,1,13.92,2,1,13.03,100,1,14.26,100,1,12.91,2,1,14.28,100,1,12.73,100,1,14.45,100,1,12.71,100,1,14.56,800,2,12.5,700,1,14.6,700,1,12.46,200,2,14.63,100,1,12.43,700,1,14.68,700,1,12.42,700,1,14.73,200,2
2025-07-17T16:02:20.831947250Z,2025-07-17T16:02:20.832112637Z,160,2,1108,A,A,0,14.68,700,130,165387,271678584,ARL,325716945,13.27,10,1,13.83,15,1,13.26,100,1,13.92,2,1,13.03,100,1,14.26,100,1,12.91,2,1,14.28,100,1,12.73,100,1,14.45,100,1,12.71,100,1,14.56,800,2,12.5,700,1,14.6,700,1,12.46,200,2,14.63,100,1,12.43,700,1,14.68,1400,2,12.42,700,1,14.73,200,2
2025-07-17T16:02:20.936622241Z,2025-07-17T16:02:20.936787418Z,160,2,1108,C,B,0,13.26,100,130,165177,271679553,ARL,325714729,13.27,10,1,13.83,15,1,13.03,100,1,13.92,2,1,12.91,2,1,14.26,100,1,12.73,100,1,14.28,100,1,12.71,100,1,14.45,100,1,12.5,700,1,14.56,800,2,12.46,200,2,14.6,700,1,12.43,700,1,14.63,100,1,12.42,700,1,14.68,1400,2,12.37,700,1,14.73,200,2
2025-07-17T16:02:20.936672130Z,2025-07-17T16:02:20.936837611Z,160,2,1108,A,A,0,13.91,5,130,165481,271679555,ARL,325718477,13.27,10,1,13.83,15,1,13.03,100,1,13.91,5,1,12.91,2,1,13.92,2,1,12.73,100,1,14.26,100,1,12.71,100,1,14.28,100,1,12.5,700,1,14.45,100,1,12.46,200,2,14.56,800,2,12.43,700,1,14.6,700,1,12.42,700,1,14.63,100,1,12.37,700,1,14.68,1400,2
2025-07-17T16:02:20.936833988Z,2025-07-17T16:02:20.936999211Z,160,2,1108,A,A,0,13.84,100,130,165223,271679558,ARL,325718485,13.27,10,1,13.83,15,1,13.03,100,1,13.84,100,1,12.91,2,1,13.91,5,1,12.73,100,1,13.92,2,1,12.71,100,1,14.26,100,1,12.5,700,1,14.28,100,1,12.46,200,2,14.45,100,1,12.43,700,1,14.56,800,2,12.42,700,1,14.6,700,1,12.37,700,1,14.63,100,1
2025-07-17T16:02:20.937578907Z,2025-07-17T16:02:20.937744264Z,160,2,1108,C,A,0,15.06,100,0,165357,271679565,ARL,325715113,13.27,10,1,13.83,15,1,13.03,100,1,13.84,100,1,12.91,2,1,13.91,5,1,12.73,100,1,13.92,2,1,12.71,100,1,14.26,100,1,12.5,700,1,14.28,100,1,12.46,200,2,14.45,100,1,12.43,700,1,14.56,800,2,12.42,700,1,14.6,700,1,12.37,700,1,14.63,100,1
2025-07-17T16:02:20.937578907Z,2025-07-17T16:02:20.937744264Z,160,2,1108,A,A,0,14.91,100,130,165357,271679565,ARL,325718509,13.27,10,1,13.83,15,1,13.03,100,1,13.84,100,1,12.91,2,1,13.91,5,1,12.73,100,1,13.92,2,1,12.71,100,1,14.26,100,1,12.5,700,1,14.28,100,1,12.46,200,2,14.45,100,1,12.43,700,1,14.56,800,2,12.42,700,1,14.6,700,1,12.37,700,1,14.63,100,1
2025-07-17T16:02:20.937736247Z,2025-07-17T16:02:20.937901293Z,160,2,1108,C,A,0,13.91,5,130,165046,271679567,ARL,325718477,13.27,10,1,13.83,15,1,13.03,100,1,13.84,100,1,12.91,2,1,13.92,2,1,12.73,100,1,14.26,100,1,12.71,100,1,14.28,100,1,12.5,700,1,14.45,100,1,12.46,200,2,14.56,800,2,12.43,700,1,14.6,700,1,12.42,700,1,14.63,100,1,12.37,700,1,14.68,1400,2
2025-07-17T16:02:20.937927380Z,2025-07-17T16:02:20.938093286Z,160,2,1108,C,A,0,14.96,100,0,165906,271679569,ARL,325715053,13.27,10,1,13.83,15,1,13.03,100,1,13.84,100,1,12.91,2,1,13.92,2,1,12.73,100,1,14.26,100,1,12.71,100,1,14.28,100,1,12.5,700,1,14.45,100,1,12.46,200,2,14.56,800,2,12.43,700,1,14.6,700,1,12.42,700,1,14.63,100,1,12.37,700,1,14.68,1400,2
2025-07-17T16:02:20.937927380Z,2025-07-17T16:02:20.938093286Z,160,2,1108,A,A,0,14.81,100,130,165906,271679569,ARL,325718517,13.27,10,1,13.83,15,1,13.03,100,1,13.84,100,1,12.91,2,1,13.92,2,1,12.73,100,1,14.26,100,1,12.71,100,1,14.28,100,1,12.5,700,1,14.45,100,1,12.46,200,2,14.56,800,2,12.43,700,1,14.6,700,1,12.42,700,1,14.63,100,1,12.37,700,1,14.68,1400,2
2025-07-17T16:02:20.938132716Z,2025-07-17T16:02:20.938297839Z,160,2,1108,C,A,0,16.08,100,0,165123,271679571,ARL,325714957,13.27,10,1,13.83,15,1,13.03,100,1,13.84,100,1,12.91,2,1,13.92,2,1,12.73,100,1,14.26,100,1,12.71,100,1,14.28,100,1,12.5,700,1,14.45,100,1,12.46,200,2,14.56,800,2,12.43,700,1,14.6,700,1,12.42,700,1,14.63,100,1,12.37,700,1,14.68,1400,2
2025-07-17T16:02:20.938132716Z,2025-07-17T16:02:20.938297839Z,160,2,1108,A,A,0,15.92,100,130,165123,271679571,ARL,325718525,13.27,10,1,13.83,15,1,13.03,100,1,13.84,100,1,12.91,2,1,13.92,2,1,12.73,100,1,14.26,100,1,12.71,100,1,14.28,100,1,12.5,700,1,14.45,100,1,12.46,200,2,14.56,800,2,12.43,700,1,14.6,700,1,12.42,700,1,14.63,100,1,12.37,700,1,14.68,1400,2
2025-07-17T16:02:20.938451331Z,2025-07-17T16:02:20.938616654Z,160,2,1108,C,A,0,14.96,100,0,165323,271679575,ARL,325714953,13.27,10,1,13.83,15,1,13.03,100,1,13.84,100,1,12.91,2,1,13.92,2,1,12.73,100,1,14.26,100,1,12.71,100,1,14.28,100,1,12.5,700,1,14.45,100,1,12.46,200,2,14.56,800,2,12.43,700,1,14.6,700,1,12.42,700,1,14.63,100,1,12.37,700,1,14.68,1400,2
2025-07-17T16:02:20.938451331Z,2025-07-17T16:02:20.938616654Z,160,2,1108,A,A,0,14.81,100,130,165323,271679575,ARL,325718549,13.27,10,1,13.83,15,1,13.03,100,1,13.84,100,1,12.91,2,1,13.92,2,1,12.73,100,1,14.26,100,1,12.71,100,1,14.28,100,1,12.5,700,1,14.45,100,1,12.46,200,2,14.56,800,2,12.43,700,1,14.6,700,1,12.42,700,1,14.63,100,1,12.37,700,1,14.68,1400,2
2025-07-17T16:02:20.938724516Z,2025-07-17T16:02:20.938889819Z,160,2,1108,C,A,0,17.76,100,0,165303,271679576,ARL,325714949,13.27,10,1,13.83,15,1,13.03,100,1,13.84,100,1,12.91,2,1,13.92,2,1,12.73,100,1,14.26,100,1,12.71,100,1,14.28,100,1,12.5,700,1,14.45,100,1,12.46,200,2,14.56,800,2,12.43,700,1,14.6,700,1,12.42,700,1,14.63,100,1,12.37,700,1,14.68,1400,2
2025-07-17T16:02:20.938724516Z,2025-07-17T16:02:20.938889819Z,160,2,1108,A,A,0,17.58,100,130,165303,271679576,ARL,325718557,13.27,10,1,13.83,15,1,13.03,100,1,13.84,100,1,12.91,2,1,13.92,2,1,12.73,100,1,14.26,100,1,12.71,100,1,14.28,100,1,12.5,700,1,14.45,100,1,12.46,200,2,14.56,800,2,12.43,700,1,14.6,700,1,12.42,700,1,14.63,100,1,12.37,700,1,14.68,1400,2
2025-07-17T16:02:20.939389367Z,2025-07-17T16:02:20.939554686Z,160,2,1108,A,B,0,13.02,100,130,165319,271679578,ARL,325718561,13.27,10,1,13.83,15,1,13.03,100,1,13.84,100,1,13.02,100,1,13.92,2,1,12.91,2,1,14.26,100,1,12.73,100,1,14.28,100,1,12.71,100,1,14.45,100,1,12.5,700,1,14.56,800,2,12.46,200,2,14.6,700,1,12.43,700,1,14.63,100,1,12.42,700,1,14.68,1400,2
2025-07-17T16:02:20.946240970Z,2025-07-17T16:02:20.946406202Z,160,2,1108,C,A,0,14.26,100,130,165232,271679616,ARL,325715045,13.27,10,1,13.83,15,1,13.03,100,1,13.84,100,1,13.02,100,1,13.92,2,1,12.91,2,1,14.28,100,1,12.73,100,1,14.45,100,1,12.71,100,1,14.56,800,2,12.5,700,1,14.6,700,1,12.46,200,2,14.63,100,1,12.43,700,1,14.68,1400,2,12.42,700,1,14.73,200,2
2025-07-17T16:02:20.946291345Z,2025-07-17T16:02:20.946456786Z,160,2,1108,A,A,0,14.12,100,130,165441,271679617,ARL,325718637,13.27,10,1,13.83,15,1,13.03,100,1,13.84,100,1,13.02,100,1,13.92,2,1,12.91,2,1,14.12,100,1,12.73,100,1,14.28,100,1,12.71,100,1,14.45,100,1,12.5,700,1,14.56,800,2,12.46,200,2,14.6,700,1,12.43,700,1,14.63,100,1,12.42,700,1,14.68,1400,2
2025-07-17T16:02:20.956886401Z,2025-07-17T16:02:20.957051613Z,160,2,1108,C,B,0,13.02,100,0,165212,271679685,ARL,325718561,13.27,10,1,13.83,15,1,13.03,100,1,13.84,100,1,12.91,2,1,13.92,2,1,12.73,100,1,14.12,100,1,12.71,100,1,14.28,100,1,12.5,700,1,14.45,100,1,12.46,200,2,14.56,800,2,12.43,700,1,14.6,700,1,12.42,700,1,14.63,100,1,12.37,700,1,14.68,1400,2
2025-07-17T16:02:20.956886401Z,2025-07-17T16:02:20.957051613Z,160,2,1108,A,B,0,13.26,100,130,165212,271679685,ARL,325718821,13.27,10,1,13.83,15,1,13.26,100,1,13.84,100,1,13.03,100,1,13.92,2,1,12.91,2,1,14.12,100,1,12.73,100,1,14.28,100,1,12.71,100,1,14.45,100,1,12.5,700,1,14.56,800,2,12.46,200,2,14.6,700,1,12.43,700,1,14.63,100,1,12.42,700,1,14.68,1400,2
2025-07-17T16:02:20.956923753Z,2025-07-17T16:02:20.957089143Z,160,2,1108,A,B,0,13.12,100,130,165390,271679686,ARL,325718833,13.27,10,1,13.83,15,1,13.26,100,1,13.84,100,1,13.12,100,1,13.92,2,1,13.03,100,1,14.12,100,1,12.91,2,1,14.28,100,1,12.73,100,1,14.45,100,1,12.71,100,1,14.56,800,2,12.5,700,1,14.6,700,1,12.46,200,2,14.63,100,1,12.43,700,1,14.68,1400,2
2025-07-17T16:02:20.956925447Z,2025-07-17T16:02:20.957090484Z,160,2,1108,A,B,0,13.12,100,130,165037,271679687,ARL,325718837,13.27,10,1,13.83,15,1,13.26,100,1,13.84,100,1,13.12,200,2,13.92,2,1,13.03,100,1,14.12,100,1,12.91,2,1,14.28,100,1,12.73,100,1,14.45,100,1,12.71,100,1,14.56,800,2,12.5,700,1,14.6,700,1,12.46,200,2,14.63,100,1,12.43,700,1,14.68,1400,2
2025-07-17T16:02:20.988490644Z,2025-07-17T16:02:20.988655870Z,160,2,1108,A,A,0,13.98,100,130,165226,271679923,ARL,325719353,13.27,10,1,13.83,15,1,13.26,100,1,13.84,100,1,13.12,200,2,13.92,2,1,13.03,100,1,13.98,100,1,12.91,2,1,14.12,100,1,12.73,100,1,14.28,100,1,12.71,100,1,14.45,100,1,12.5,700,1,14.56,800,2,12.46,200,2,14.6,700,1,12.43,700,1,14.63,100,1
2025-07-17T16:02:20.988491826Z,2025-07-17T16:02:20.988656944Z,160,2,1108,A,A,0,13.98,100,130,165118,271679924,ARL,325719357,13.27,10,1,13.83,15,1,13.26,100,1,13.84,100,1,13.12,200,2,13.92,2,1,13.03,100,1,13.98,200,2,12.91,2,1,14.12,100,1,12.73,100,1,14.28,100,1,12.71,100,1,14.45,100,1,12.5,700,1,14.56,800,2,12.46,200,2,14.6,700,1,12.43,700,1,14.63,100,1
2025-07-17T16:02:30.805028316Z,2025-07-17T16:02:30.805193695Z,160,2,1108,C,B,0,13.27,10,130,165379,271818376,ARL,325714717,13.26,100,1,13.83,15,1,13.12,200,2,13.84,100,1,13.03,100,1,13.92,2,1,12.91,2,1,13.98,200,2,12.73,100,1,14.12,100,1,12.71,100,1,14.28,100,1,12.5,700,1,14.45,100,1,12.46,200,2,14.56,800,2,12.43,700,1,14.6,700,1,12.42,700,1,14.63,100,1
2025-07-17T16:02:34.987005787Z,2025-07-17T16:02:34.987171397Z,160,2,1108,C,B,0,12.91,2,0,165610,271871706,ARL,325714741,13.26,100,1,13.83,15,1,13.12,200,2,13.84,100,1,13.03,100,1,13.92,2,1,12.73,100,1,13.98,200,2,12.71,100,1,14.12,100,1,12.5,700,1,14.28,100,1,12.46,200,2,14.45,100,1,12.43,700,1,14.56,800,2,12.42,700,1,14.6,700,1,12.37,700,1,14.63,100,1
2025-07-17T16:02:34.987005787Z,2025-07-17T16:02:34.987171397Z,160,2,1108,A,B,0,13,2,130,165610,271871706,ARL,325967705,13.26,100,1,13.83,15,1,13.12,200,2,13.84,100,1,13.03,100,1,13.92,2,1,13,2,1,13.98,200,2,12.73,100,1,14.12,100,1,12.71,100,1,14.28,100,1,12.5,700,1,14.45,100,1,12.46,200,2,14.56,800,2,12.43,700,1,14.6,700,1,12.42,700,1,14.63,100,1
2025-07-17T16:02:39.809299504Z,2025-07-17T16:02:39.809464961Z,160,2,1108,A,A,0,13.79,15,130,165457,271952021,ARL,326077141,13.26,100,1,13.79,15,1,13.12,200,2,13.83,15,1,13.03,100,1,13.84,100,1,13,2,1,13.92,2,1,12.73,100,1,13.98,200,2,12.71,100,1,14.12,100,1,12.5,700,1,14.28,100,1,12.46,200,2,14.45,100,1,12.43,700,1,14.56,800,2,12.42,700,1,14.6,700,1
2025-07-17T16:02:40.007306432Z,2025-07-17T16:02:40.007472020Z,160,2,1108,C,A,0,13.84,100,0,165588,271957331,ARL,325718485,13.26,100,1,13.79,15,1,13.12,200,2,13.83,15,1,13.03,100,1,13.92,2,1,13,2,1,13.98,200,2,12.73,100,1,14.12,100,1,12.71,100,1,14.28,100,1,12.5,700,1,14.45,100,1,12.46,200,2,14.56,800,2,12.43,700,1,14.6,700,1,12.42,700,1,14.63,100,1
2025-07-17T16:02:40.007306432Z,2025-07-17T16:02:40.007472020Z,160,2,1108,A,A,0,13.8,100,130,165588,271957331,ARL,326082329,13.26,100,1,13.79,15,1,13.12,200,2,13.8,100,1,13.03,100,1,13.83,15,1,13,2,1,13.92,2,1,12.73,100,1,13.98,200,2,12.71,100,1,14.12,100,1,12.5,700,1,14.28,100,1,12.46,200,2,14.45,100,1,12.43,700,1,14.56,800,2,12.42,700,1,14.6,700,1
2025-07-17T16:02:40.008048023Z,2025-07-17T16:02:40.008213654Z,160,2,1108,C,A,0,14.91,100,0,165631,271957349,ARL,325718509,13.26,100,1,13.79,15,1,13.12,200,2,13.8,100,1,13.03,100,1,13.83,15,1,13,2,1,13.92,2,1,12.73,100,1,13.98,200,2,12.71,100,1,14.12,100,1,12.5,700,1,14.28,100,1,12.46,200,2,14.45,100,1,12.43,700,1,14.56,800,2,12.42,700,1,14.6,700,1
2025-07-17T16:02:40.008048023Z,2025-07-17T16:02:40.008213654Z,160,2,1108,A,A,0,14.87,100,130,165631,271957349,ARL,326082353,13.26,100,1,13.79,15,1,13.12,200,2,13.8,100,1,13.03,100,1,13.83,15,1,13,2,1,13.92,2,1,12.73,100,1,13.98,200,2,12.71,100,1,14.12,100,1,12.5,700,1,14.28,100,1,12.46,200,2,14.45,100,1,12.43,700,1,14.56,800,2,12.42,700,1,14.6,700,1
2025-07-17T16:02:40.794847674Z,2025-07-17T16:02:40.795014471Z,160,2,1108,C,A,0,13.79,15,130,166797,271972417,ARL,326077141,13.26,100,1,13.8,100,1,13.12,200,2,13.83,15,1,13.03,100,1,13.92,2,1,13,2,1,13.98,200,2,12.73,100,1,14.12,100,1,12.71,100,1,14.28,100,1,12.5,700,1,14.45,100,1,12.46,200,2,14.56,800,2,12.43,700,1,14.6,700,1,12.42,700,1,14.63,100,1
2025-07-17T16:02:40.806140621Z,2025-07-17T16:02:40.806305895Z,160,2,1108,C,A,0,13.83,15,130,165274,271973288,ARL,325714721,13.26,100,1,13.8,100,1,13.12,200,2,13.92,2,1,13.03,100,1,13.98,200,2,13,2,1,14.12,100,1,12.73,100,1,14.28,100,1,12.71,100,1,14.45,100,1,12.5,700,1,14.56,800,2,12.46,200,2,14.6,700,1,12.43,700,1,14.63,100,1,12.42,700,1,14.68,1400,2
2025-07-17T16:02:43.841686908Z,2025-07-17T16:02:43.841852430Z,160,2,1108,C,B,0,13.26,100,130,165522,272014658,ARL,325718821,13.12,200,2,13.8,100,1,13.03,100,1,13.92,2,1,13,2,1,13.98,200,2,12.73,100,1,14.12,100,1,12.71,100,1,14.28,100,1,12.5,700,1,14.45,100,1,12.46,200,2,14.56,800,2,12.43,700,1,14.6,700,1,12.42,700,1,14.63,100,1,12.37,700,1,14.68,1400,2
2025-07-17T16:02:43.841746626Z,2025-07-17T16:02:43.841912053Z,160,2,1108,A,A,0,13.9,4,130,165427,272014659,ARL,326158809,13.12,200,2,13.8,100,1,13.03,100,1,13.9,4,1,13,2,1,13.92,2,1,12.73,100,1,13.98,200,2,12.71,100,1,14.12,100,1,12.5,700,1,14.28,100,1,12.46,200,2,14.45,100,1,12.43,700,1,14.56,800,2,12.42,700,1,14.6,700,1,12.37,700,1,14.63,100,1
2025-07-17T16:02:43.842130114Z,2025-07-17T16:02:43.842295427Z,160,2,1108,C,A,0,13.8,100,130,165313,272014661,ARL,326082329,13.12,200,2,13.9,4,1,13.03,100,1,13.92,2,1,13,2,1,13.98,200,2,12.73,100,1,14.12,100,1,12.71,100,1,14.28,100,1,12.5,700,1,14.45,100,1,12.46,200,2,14.56,800,2,12.43,700,1,14.6,700,1,12.42,700,1,14.63,100,1,12.37,700,1,14.68,1400,2
2025-07-17T16:02:43.842871428Z,2025-07-17T16:02:43.843036936Z,160,2,1108,C,A,0,14.87,100,0,165508,272014673,ARL,326082353,13.12,200,2,13.9,4,1,13.03,100,1,13.92,2,1,13,2,1,13.98,200,2,12.73,100,1,14.12,100,1,12.71,100,1,14.28,100,1,12.5,700,1,14.45,100,1,12.46,200,2,14.56,800,2,12.43,700,1,14.6,700,1,12.42,700,1,14.63,100,1,12.37,700,1,14.68,1400,2
2025-07-17T16:02:43.842871428Z,2025-07-17T16:02:43.843036936Z,160,2,1108,A,A,0,14.92,100,130,165508,272014673,ARL,326158869,13.12,200,2,13.9,4,1,13.03,100,1,13.92,2,1,13,2,1,13.98,200,2,12.73,100,1,14.12,100,1,12.71,100,1,14.28,100,1,12.5,700,1,14.45,100,1,12.46,200,2,14.56,800,2,12.43,700,1,14.6,700,1,12.42,700,1,14.63,100,1,12.37,700,1,14.68,1400,2
2025-07-17T16:02:43.842941514Z,2025-07-17T16:02:43.843106749Z,160,2,1108,A,B,0,13.11,100,130,165235,272014674,ARL,326158877,13.12,200,2,13.9,4,1,13.11,100,1,13.92,2,1,13.03,100,1,13.98,200,2,13,2,1,14.12,100,1,12.73,100,1,14.28,100,1,12.71,100,1,14.45,100,1,12.5,700,1,14.56,800,2,12.46,200,2,14.6,700,1,12.43,700,1,14.63,100,1,12.42,700,1,14.68,1400,2
2025-07-17T16:02:43.842943173Z,2025-07-17T16:02:43.843109026Z,160,2,1108,C,A,0,14.81,100,0,165853,272014675,ARL,325718549,13.12,200,2,13.9,4,1,13.11,100,1,13.92,2,1,13.03,100,1,13.98,200,2,13,2,1,14.12,100,1,12.73,100,1,14.28,100,1,12.71,100,1,14.45,100,1,12.5,700,1,14.56,800,2,12.46,200,2,14.6,700,1,12.43,700,1,14.63,100,1,12.42,700,1,14.68,1400,2
2025-07-17T16:02:43.842943173Z,2025-07-17T16:02:43.843109026Z,160,2,1108,A,A,0,14.96,100,130,165853,272014675,ARL,326158881,13.12,200,2,13.9,4,1,13.11,100,1,13.92,2,1,13.03,100,1,13.98,200,2,13,2,1,14.12,100,1,12.73,100,1,14.28,100,1,12.71,100,1,14.45,100,1,12.5,700,1,14.56,800,2,12.46,200,2,14.6,700,1,12.43,700,1,14.63,100,1,12.42,700,1,14.68,1400,2
2025-07-17T16:02:43.843039530Z,2025-07-17T16:02:43.843204692Z,160,2,1108,C,A,0,13.9,4,130,165162,272014681,ARL,326158809,13.12,200,2,13.92,2,1,13.11,100,1,13.98,200,2,13.03,100,1,14.12,100,1,13,2,1,14.28,100,1,12.73,100,1,14.45,100,1,12.71,100,1,14.56,800,2,12.5,700,1,14.6,700,1,12.46,200,2,14.63,100,1,12.43,700,1,14.68,1400,2,12.42,700,1,14.73,200,2
2025-07-17T16:02:43.843791297Z,2025-07-17T16:02:43.843956820Z,160,2,1108,C,A,0,17.58,100,0,165523,272014689,ARL,325718557,13.12,200,2,13.92,2,1,13.11,100,1,13.98,200,2,13.03,100,1,14.12,100,1,13,2,1,14.28,100,1,12.73,100,1,14.45,100,1,12.71,100,1,14.56,800,2,12.5,700,1,14.6,700,1,12.46,200,2,14.63,100,1,12.43,700,1,14.68,1400,2,12.42,700,1,14.73,200,2
2025-07-17T16:02:43.843791297Z,2025-07-17T16:02:43.843956820Z,160,2,1108,A,A,0,17.76,100,130,165523,272014689,ARL,326158953,13.12,200,2,13.92,2,1,13.11,100,1,13.98,200,2,13.03,100,1,14.12,100,1,13,2,1,14.28,100,1,12.73,100,1,14.45,100,1,12.71,100,1,14.56,800,2,12.5,700,1,14.6,700,1,12.46,200,2,14.63,100,1,12.43,700,1,14.68,1400,2,12.42,700,1,14.73,200,2
2025-07-17T16:02:43.844487204Z,2025-07-17T16:02:43.844653014Z,160,2,1108,C,A,0,15.92,100,0,165810,272014697,ARL,325718525,13.12,200,2,13.92,2,1,13.11,100,1,13.98,200,2,13.03,100,1,14.12,100,1,13,2,1,14.28,100,1,12.73,100,1,14.45,100,1,12.71,100,1,14.56,800,2,12.5,700,1,14.6,700,1,12.46,200,2,14.63,100,1,12.43,700,1,14.68,1400,2,12.42,700,1,14.73,200,2
2025-07-17T16:02:43.844487204Z,2025-07-17T16:02:43.844653014Z,160,2,1108,A,A,0,16.08,100,130,165810,272014697,ARL,326158989,13.12,200,2,13.92,2,1,13.11,100,1,13.98,200,2,13.03,100,1,14.12,100,1,13,2,1,14.28,100,1,12.73,100,1,14.45,100,1,12.71,100,1,14.56,800,2,12.5,700,1,14.6,700,1,12.46,200,2,14.63,100,1,12.43,700,1,14.68,1400,2,12.42,700,1,14.73,200,2
